File: MPMS/NiCl2btd/NiCl2btd_MvH_4K_14T.dat
[Header]
; ACMS II Data File (default extension .dat)
; Copyright (c) 2014, Quantum Design, Inc. All rights reserved.
TITLE,
FILEOPENTIME,3875428005.809,10/20/2022,11:47 am
BYAPP,ACMS II,1.0,1.2
INFO,DYNACOOL ACMS II Option Release 1.0.8 Build 33,APPNAME
INFO,Quantum Design Linear Motor Servo Controller,MOTOR_MODULE_NAME
INFO,3101-100 K0,MOTOR_HW_VERSION
INFO,MMC794,MOTOR_SERIAL_NUMBER
INFO,SRV No X-over 01.03.11,MOTOR_SOFTWARE_VERSION
INFO,ACMS,ACMS_MODULE_NAME
INFO,3101-430 A0,ACMS_HW_VERSION
INFO,ACMSII028,ACMS_SERIAL_NUMBER
INFO,00.14.14,ACMS_SOFTWARE_VERSION
INFO,WF046,COIL_SERIAL_NUMBER
INFO,0,MOMENT_UNITS
INFO,NiCl2-btdm,SAMPLE_MATERIAL
INFO,4.8mg cling film,SAMPLE_COMMENT
INFO,22.1,SAMPLE_MASS
INFO,,SAMPLE_VOLUME
INFO,,SAMPLE_MOLECULAR_WEIGHT
INFO,,SAMPLE_SIZE
INFO,,SAMPLE_SHAPE
DATATYPE,COMMENT,1
DATATYPE,TIME,2
STARTUPAXIS,X,2
STARTUPAXIS,Y1,5
STARTUPGROUP, AC
FIELDGROUP, AC, 2,3,4,5,6,7,8,9,10,11,12,13,14,15,16,20,21,22,23,24,25,35,43,44,45,46,47,48,49
FIELDGROUP, DC, 2,3,4,17,18,19,20,21,23,24,25,35,36,37,43,44,45,46,47,48,49,50,51
FIELDGROUP, Diagnostic, 26,27,28,29,30,31,32,33,34,38,39,40,41,42,52,53,54,55,56,57,58,59,60,61,62,63,64,65,66,67,68,69
[Data]
Comment,Time Stamp (sec),Temperature (K),Magnetic Field (Oe),AC Moment (emu),AC Std. Dev. (emu),AC Phase (deg),AC Phase Std. Dev. (deg),AC Suscept. (emu/Oe),AC Suscept. Std. Dev. (emu/Oe),AC X'  (emu/Oe),AC X" (emu/Oe),AC X' Std. Dev. (emu/Oe),AC X" Std. Dev. (emu/Oe),AC Drive (Oe),AC Frequency (Hz),DC Moment (emu),DC Std. Err. (emu),DC Quad. Moment (emu),Range (mV),"AC=1 DC=2 Locate=3",Measure Type,Measure Count,Measure Time (sec),Measure Number,AC X' Raw (emu/Oe),AC X" Raw (emu/Oe),DC M. Raw' (emu),DC M. Raw" (emu),Coil InPhase (V),Coil Quadrature (V),Null Status,Trim Ratio,Trim Phase (deg.),Max. Signal (mV),Motor Frequency (Hz),Motor Ampl. (mm),System Temp. (K),Min. Temperature (K),Max. Temperature (K),Min. Field (Oe),Max. Field (Oe),Pressure (Torr),Temp. Status (code),Field Status (code),Chamber Status (code),Measure Status (code),Center Position (mm),Transport Action,Motor Lag (deg),Motor Current (amps),Motor Heatsink Temp. (C),Motor Board Temp. (C),QMap 01,QMap 02,QMap 03,QMap 04,QMap 05,QMap 06,QMap 07,QMap 08,QMap 09,QMap 10,QMap 11,QMap 12,QMap 13,QMap 14,QMap 15,QMap 16
sample offset = 25.15 mm,3875428540.45273,4.00049047470093,0.613626092672348,,,,,,,,,,,,,0.0394050997975412,2.89592113378204E-6,-5.66867503597469E-5,1,2,,80,2,1,,,0.0379506871356847,0.000140456566009445,0.000229231707635336,-8.01824717200361E-5,,,,0.00951218574196658,39.995735168457,1.97456221448096,4.00164794921875,4.00034523010254,4.00063467025757,0.569160401821136,0.65809178352356,0.125599205493927,1,4,3,4,23.1730000402331,1,20.6775628111325,1.11358642578125,32.2580642700195,32.2580642700195,,,,,,,,,,,,,,,,
,3875428686.32175,4.00036525726318,1530.1298828125,,,,,,,,,,,,,0.0444082910844037,1.15775001636784E-5,-0.000118641919383174,1,2,,80,2,69,,,0.0427705602657663,0.00011002984358734,0.000258449523244053,-9.01315725059249E-5,,,,0.0107200218123533,39.995735168457,1.97472769629785,4.00081586837769,4.00028657913208,4.00047588348389,1475.25476074219,1585.00500488281,0.126756727695465,1,6,3,4,23.1730000402331,1,20.6886848549906,1.11534118652344,40.5669593811035,33.7243423461914,,,,,,,,,,,,,,,,
,3875428831.85827,4.0009693145752,8805.71923828125,,,,,,,,,,,,,0.0699173935998714,1.1766108201592E-5,-0.000152313462628073,1,2,,80,2,137,,,0.0673517945978956,0.00025658676403504,0.000406773528084159,-0.000142450371640734,,,,0.0168795661607627,39.995735168457,1.97457860247476,3.99843835830688,4.00091934204102,4.00101947784424,8753.1865234375,8858.251953125,0.126680240035057,1,6,3,4,23.1730000402331,1,20.6921600126628,1.11557006835938,42.0332374572754,34.7018585205078,,,,,,,,,,,,,,,,
,3875428976.13785,4.00067729949951,16018.931640625,,,,,,,,,,,,,0.0951150161954196,1.26427716001791E-5,-0.00014519663506263,1,2,,80,2,205,,,0.09164856617821,0.000489195118307542,0.000553201825823635,-0.000194668435142376,,,,0.022968181466114,39.995735168457,1.97449435224937,3.99596667289734,4.00052356719971,4.00081348419189,15968.93359375,16068.9296875,0.126607775688171,1,6,3,4,23.1730000402331,1,20.691238261231,1.11366271972656,42.5219955444336,36.6568908691406,,,,,,,,,,,,,,,,
,3875429118.25029,4.00026350021362,23136.830078125,,,,,,,,,,,,,0.120811474119076,1.49532128062443E-5,-0.000130738478434873,1,2,,80,2,273,,,0.116445683340262,0.000781426229232919,0.00070248928386718,-0.00024831565679051,,,,0.0291806278110444,39.995735168457,1.97435842142022,3.9946117401123,4.00011396408081,4.00040340423584,23084.16015625,23189.5,0.126670807600021,1,6,3,4,23.1730000402331,1,20.6933753124431,1.11007690429688,43.0107536315918,38.1231689453125,,,,,,,,,,,,,,,,
,3875429257.68642,3.99995269775391,30127.181640625,,,,,,,,,,,,,0.146612706923373,1.60741040448617E-5,-0.000120112570366198,1,2,,80,2,341,,,0.141367432262035,0.00111952221995865,0.00085250404663384,-0.000302450498566031,,,,0.0354269687433288,39.995735168457,1.9743793276766,3.99378514289856,3.99987697601318,4.00001621246338,30074.529296875,30179.833984375,0.126738801598549,1,6,3,4,23.1730000402331,1,20.6902820835318,1.11740112304688,43.49951171875,37.6344108581543,,,,,,,,,,,,,,,,
,3875429399.20007,3.99964599609375,37225.08984375,,,,,,,,,,,,,0.172492260251022,1.60880074700973E-5,-4.2220456452714E-5,10,2,,80,2,410,,,0.166393842285074,0.00157575307740142,0.00100283685605973,-0.000357552606146783,,,,0.0416995885601204,39.995735168457,1.97429431604793,3.99431371688843,3.99950885772705,3.99973773956299,37175.08203125,37275.09765625,0.126486271619797,1,6,3,4,23.1730000402331,1,20.6910640799099,1.11640930175781,43.49951171875,38.6119270324707,,,,,,,,,,,,,,,,
,3875429538.60946,3.99913614988327,44214.36328125,,,,,,,,,,,,,0.198073992338011,1.74604303465623E-5,-5.67472620354724E-5,10,2,,80,2,478,,,0.191165721542122,0.0019865891528953,0.00115177605766803,-0.000411844259360805,,,,0.0479089731368407,39.995735168457,1.97430807083169,3.99598789215088,3.9990770816803,3.99921035766602,44164.296875,44264.4296875,0.126474171876907,1,6,3,4,23.1730000402331,1,20.6906914326533,1.11541748046875,43.49951171875,38.1231689453125,,,,,,,,,,,,,,,,
,3875429677.99829,3.9989070892334,51204.333984375,,,,,,,,,,,,,0.223930637111259,1.79898721699784E-5,-9.2952335185411E-5,10,2,,80,2,546,,,0.216240127085515,0.00242591290219091,0.00130250223446637,-0.000466888654045761,,,,0.0541931324580733,39.995735168457,1.97431660624629,3.99854350090027,3.99887633323669,3.99895739555359,51154.15234375,51254.515625,0.126606225967407,1,6,3,4,23.1730000402331,1,20.6881257623669,1.11076354980469,43.49951171875,39.1006851196289,,,,,,,,,,,,,,,,
,3875429817.43285,3.99883580207825,58197.318359375,,,,,,,,,,,,,0.250279207071521,1.69814874855181E-5,-0.000132399548783347,10,2,,80,2,614,,,0.241830861922537,0.00291227762819493,0.00145615555811673,-0.00052331411279738,,,,0.0606036178695897,39.995735168457,1.97421190276688,4.00153350830078,3.99878191947937,3.99891304969788,58144.74609375,58249.890625,0.126659318804741,1,6,3,4,23.1730000402331,1,20.687893859344,1.11160278320312,43.49951171875,39.1006851196289,,,,,,,,,,,,,,,,
,3875429956.85056,3.99865517616272,65189.55078125,,,,,,,,,,,,,0.277301235786517,1.80512111345319E-5,-0.000250859965229284,10,2,,80,2,682,,,0.268118709329088,0.00337271005322327,0.00161414861213416,-0.000581081258133054,,,,0.067191635996453,39.995735168457,1.97422166536122,4.0057635307312,3.99837470054626,3.99876236915588,65139.37109375,65239.73046875,0.12674705684185,1,6,3,4,23.1730000402331,1,20.6881936630459,1.11534118652344,43.49951171875,39.5894432067871,,,,,,,,,,,,,,,,
,3875430096.24741,3.99861187934876,72178.00390625,,,,,,,,,,,,,0.305279935525024,2.18421985117022E-5,-0.000405567999017791,10,2,,80,2,750,,,0.295381576305175,0.00385019283147876,0.00177792087197304,-0.000640891958028078,,,,0.0740203106849908,39.995735168457,1.97411283203817,4.00961780548096,3.99850058555603,3.99872612953186,72125.546875,72230.4609375,0.126914903521538,1,6,3,4,23.1730000402331,1,20.686459262225,1.11503601074219,43.9882698059082,40.5669593811035,,,,,,,,,,,,,,,,
,3875430235.70141,3.99873881340027,79196.63671875,,,,,,,,,,,,,0.334671335250746,2.01896152464391E-5,-0.000603625193505436,10,2,,80,2,818,,,0.324067024227174,0.00434389591610114,0.00195042102131993,-0.000703824101947248,,,,0.0812118249903598,39.995735168457,1.97418595240781,4.01299905776978,3.99856734275818,3.99891543388367,79143.4296875,79249.84375,0.126977026462555,1,6,3,4,23.1730000402331,1,20.6847925823461,1.11679077148438,43.9882698059082,39.5894432067871,,,,,,,,,,,,,,,,
,3875430375.10703,3.99896659851074,86263.66015625,,,,,,,,,,,,,0.368755968933536,2.38678433848992E-5,-0.000851048627718463,10,2,,80,2,886,,,0.357360854286168,0.00489833729044997,0.00215051649138331,-0.000776777800638229,,,,0.0895542211602929,39.995735168457,1.97413348558126,4.01697444915771,3.99884581565857,3.99913215637207,86210.4140625,86316.90625,0.126953035593033,1,6,3,4,23.1730000402331,1,20.6850790605427,1.11198425292969,44.4770278930664,40.0782012939453,,,,,,,,,,,,,,,,
,3875430514.54042,3.99890303611755,93334.8359375,,,,,,,,,,,,,0.404239943946902,3.00252160895064E-5,-0.00113749422391553,10,2,,80,2,954,,,0.392080107717187,0.005473635423102,0.00235918466933072,-0.000852798053529113,,,,0.0982522735426014,39.995735168457,1.97407740630074,4.01995134353638,3.99885106086731,3.9989321231842,93284.21875,93385.453125,0.127112835645676,1,6,3,4,23.1730000402331,1,20.6844805560198,1.11259460449219,43.9882698059082,40.0782012939453,,,,,,,,,,,,,,,,
,3875430653.9371,3.99931488037109,100402.453125,,,,,,,,,,,,,0.439064306204573,2.87108858998906E-5,-0.00143907412590041,10,2,,80,2,1022,,,0.426230411596424,0.0060546469783366,0.00256457645446062,-0.000927640998270363,,,,0.106814917226987,39.995735168457,1.974147055926,4.02236795425415,3.99926090240479,3.99938631057739,100351.734375,100453.171875,0.12717741727829,1,6,3,4,23.1730000402331,1,20.6822824536323,1.11160278320312,44.4770278930664,40.5669593811035,,,,,,,,,,,,,,,,
,3875430793.35225,3.99931316375732,107472.59765625,,,,,,,,,,,,,0.472957114481326,2.72367106440983E-5,-0.00159539099820446,10,2,,80,2,1090,,,0.459544122851514,0.00678517024429426,0.0027643006760627,-0.00100168376229703,,,,0.115157512219763,39.995735168457,1.97402535545952,4.0245041847229,3.99924659729004,3.99938344955444,107419.3515625,107525.84375,0.127190783619881,1,6,3,4,23.1730000402331,1,20.6831925027666,1.11053466796875,44.4770278930664,38.6119270324707,,,,,,,,,,,,,,,,
,3875430932.7726,3.99972839355469,114538.1640625,,,,,,,,,,,,,0.505855450178048,3.59024858615509E-5,-0.00173333427604298,10,2,,80,2,1158,,,0.491959230170533,0.00753307981866822,0.00295868306420743,-0.00107381551060826,,,,0.123277034550298,39.995735168457,1.97396680702305,4.02554321289063,3.9996452331543,3.99981832504272,114487.4296875,114588.8984375,0.127248406410217,1,6,3,4,23.1730000402331,1,20.6808364613518,1.11473083496094,43.9882698059082,40.0782012939453,,,,,,,,,,,,,,,,
,3875431072.20395,3.99990129470825,121609.41015625,,,,,,,,,,,,,0.537764000981803,3.11254875089675E-5,-0.00187538526080918,10,2,,80,2,1226,,,0.52347797088159,0.00826975242968606,0.00314777926541865,-0.00114413828123361,,,,0.131178605014003,39.995735168457,1.97400490268418,4.0260853767395,3.99981546401978,3.99998807907105,121556.203125,121662.6171875,0.127254962921143,1,6,3,4,23.1730000402331,1,20.6802581840482,1.11236572265625,44.4770278930664,40.0782012939453,,,,,,,,,,,,,,,,
,3875431211.62166,4.00020055770874,128679.5078125,,,,,,,,,,,,,0.568843372899694,3.13811668556897E-5,-0.00226268396577595,10,2,,80,2,1294,,,0.554257064514818,0.0087563322251446,0.00333273527212441,-0.00121146056335419,,,,0.138887637128284,39.995735168457,1.97394773420364,4.02505826950073,4.00013589859009,4.00033664703369,128628.78125,128730.234375,0.127189695835114,1,6,3,4,23.1730000402331,1,20.6816723368849,1.1163330078125,44.4770278930664,40.0782012939453,,,,,,,,,,,,,,,,
,3875431351.03071,4.00065603256226,135751.109375,,,,,,,,,,,,,0.599211688151207,2.98510637270488E-5,-0.00270065179317654,10,2,,80,2,1362,,,0.584404308420828,0.00917845744881507,0.00351417274214327,-0.00127684790641069,,,,0.146442334856181,39.995735168457,1.97393984122262,4.02389144897461,4.00060701370239,4.00070428848267,135697.8125,135804.40625,0.127109214663506,1,6,3,4,23.1730000402331,1,20.6788314679124,1.11244201660156,43.9882698059082,40.0782012939453,,,,,,,,,,,,,,,,
,3875431490.45155,4.00033473968506,140000.4765625,,,,,,,,,,,,,0.61716556650081,3.4259689612389E-5,-0.00301002519661974,10,2,,80,2,1430,,,0.602260964040266,0.00937852279898255,0.00362173095345497,-0.00131539988797158,,,,0.15091862450115,39.995735168457,1.97395073633339,4.02260828018188,4.00029802322388,4.00042295455933,140000.46875,140000.484375,0.126991346478462,1,4,3,4,23.1730000402331,1,20.6790911937879,1.11251831054688,44.4770278930664,40.0782012939453,,,,,,,,,,,,,,,,
,3875431629.84788,3.99959411621094,136536.953125,,,,,,,,,,,,,0.602691220669256,3.02962936261179E-5,-0.00287526913289838,10,2,,80,2,1498,,,0.587862735199782,0.00910430254164479,0.00353525881655514,-0.00128363305702806,,,,0.147310111978908,39.995735168457,1.97395157309448,4.02306318283081,3.99940824508667,3.99968957901001,136485.03125,136588.875,0.127102375030518,1,6,3,4,23.1730000402331,1,20.6788027943871,1.11198425292969,44.4770278930664,40.5669593811035,,,,,,,,,,,,,,,,
,3875431769.2801,3.99954915046692,129638.22265625,,,,,,,,,,,,,0.573406995804592,3.24701371525188E-5,-0.00260137134153556,10,2,,80,2,1566,,,0.558781264226467,0.00855023493692664,0.00336065492592752,-0.00121945783030242,,,,0.140023797251611,39.995735168457,1.97397863088324,4.02447271347046,3.99950313568115,3.99959802627563,129588.5546875,129687.890625,0.127285853028297,1,6,3,4,23.1730000402331,1,20.6777186094821,1.1114501953125,44.4770278930664,40.5669593811035,,,,,,,,,,,,,,,,
,3875431908.71293,3.99958884716034,122740.65625,,,,,,,,,,,,,0.543527263596922,3.49515304031585E-5,-0.00228940343900903,10,2,,80,2,1634,,,0.529174746496388,0.00801967219730093,0.00318254739977419,-0.00115446210838854,,,,0.132596829635671,39.995735168457,1.97387906681016,4.02537250518799,3.99942255020142,3.99972629547119,122688.5546875,122792.7578125,0.127358883619308,1,6,3,4,23.1730000402331,1,20.68027217766,1.11602783203125,44.4770278930664,40.0782012939453,,,,,,,,,,,,,,,,
,3875432048.12137,4.00005836486816,115844.60546875,,,,,,,,,,,,,0.512902674630626,3.38619027014258E-5,-0.00201581244385629,10,2,,80,2,1702,,,0.49890275099089,0.00744048236983771,0.00300092319957912,-0.00108768627978861,,,,0.125017684984611,39.995735168457,1.97398798592866,4.02617073059082,4.00000762939453,4.00012445449829,115792.484375,115896.7265625,0.127451986074448,1,6,3,4,23.1730000402331,1,20.6790455395958,1.11244201660156,43.9882698059082,40.0782012939453,,,,,,,,,,,,,,,,
,3875432187.54249,4.00037574768066,108945.921875,,,,,,,,,,,,,0.481416420426428,2.93143227946604E-5,-0.00170624181892575,10,2,,80,2,1770,,,0.467853426030605,0.00688856380926905,0.00281423074193299,-0.00101950438693166,,,,0.117232877644666,39.995735168457,1.97392596863436,4.02559089660645,4.0003228187561,4.00040626525879,108896.375,108995.46875,0.127455487847328,1,6,3,4,23.1730000402331,1,20.6806551788894,1.11251831054688,44.4770278930664,40.0782012939453,,,,,,,,,,,,,,,,
,3875432326.96533,4.00073671340942,102050.2734375,,,,,,,,,,,,,0.449009970154616,2.62452819568551E-5,-0.00143637338385894,10,2,,80,2,1838,,,0.435974727233581,0.00629605386989157,0.00262287119403481,-0.00094928324688226,,,,0.109249905178784,39.995735168457,1.97401881227466,4.02430534362793,4.000657081604,4.00082206726074,102000.765625,102099.78125,0.127398237586021,1,6,3,4,23.1730000402331,1,20.6794955634284,1.11152648925781,44.4770278930664,40.0782012939453,,,,,,,,,,,,,,,,
,3875432466.37196,4.00052099227905,95154.28515625,,,,,,,,,,,,,0.415575726213162,2.68941955351088E-5,-0.00120442995738788,10,2,,80,2,1906,,,0.403164522254729,0.0056699039322244,0.00242578843608499,-0.000876979087479413,,,,0.101028050527679,39.995735168457,1.97402565381964,4.02264308929443,4.00044536590576,4.00058460235596,95104.84375,95203.7265625,0.127418383955956,1,6,3,4,23.1730000402331,1,20.6807760458825,1.11618041992188,43.9882698059082,40.0782012939453,,,,,,,,,,,,,,,,
,3875432605.79122,4.00094327926636,88255.33984375,,,,,,,,,,,,,0.380978063024224,2.60394794706939E-5,-0.000943112552567738,10,2,,80,2,1974,,,0.369292183677655,0.00508082742027818,0.00222221505828202,-0.000802675378508866,,,,0.0925408042863938,39.995735168457,1.97403972947348,4.02006912231445,4.00082206726074,4.00105285644531,88203.4921875,88307.1875,0.127411007881165,1,6,3,4,23.1730000402331,1,20.6821325959429,1.11061096191406,43.9882698059082,41.5444793701172,,,,,,,,,,,,,,,,
,3875432745.22486,4.00086605548859,81357.578125,,,,,,,,,,,,,0.345638525474215,2.49722996508439E-5,-0.000641933101032823,10,2,,80,2,2042,,,0.334767653174903,0.00455361743024864,0.00201455550268292,-0.000727332604583353,,,,0.0838883250164321,39.995735168457,1.97402869648808,4.0169095993042,4.00080490112305,4.00095558166504,81308.15625,81407,0.127426654100418,1,6,3,4,23.1730000402331,1,20.6826362688138,1.11030578613281,43.9882698059082,40.0782012939453,,,,,,,,,,,,,,,,
,3875432884.6337,4.00101795196533,74462.171875,,,,,,,,,,,,,0.314737445769856,1.62682434186474E-5,-0.000347071546038846,10,2,,80,2,2110,,,0.304604870935444,0.00412431623507846,0.00183319405186921,-0.000661737809423357,,,,0.0763344217901072,39.995735168457,1.97415622826448,4.01390409469604,4.00092506408691,4.00110006332397,74412.875,74511.46875,0.127220749855042,1,6,3,4,23.1730000402331,1,20.6829973963594,1.11495971679688,44.4770278930664,40.0782012939453,,,,,,,,,,,,,,,,
,3875433024.03402,4.00129728317261,67568.18359375,,,,,,,,,,,,,0.286784126605754,2.0068161892062E-5,-0.00011803094132794,10,2,,80,2,2178,,,0.277351009797801,0.00370973385302624,0.00166925240773708,-0.00060230097733438,,,,0.0695041446715982,39.995735168457,1.97415713782751,4.01035451889038,4.00125122070313,4.00136852264404,67516.265625,67620.1015625,0.127078622579575,1,6,3,4,23.1730000402331,1,20.6845757939317,1.11396789550781,43.9882698059082,40.5669593811035,,,,,,,,,,,,,,,,
,3875433163.45772,4.00107555389404,60668.318359375,,,,,,,,,,,,,0.259842880730989,2.03979778904152E-5,-4.53657265509174E-5,10,2,,80,2,2246,,,0.251127579885939,0.00319503898919572,0.00151170650497079,-0.000544438022188842,,,,0.062931034261382,39.995735168457,1.97411661169082,4.00669574737549,4.00094175338745,4.00139093399048,60616.38671875,60720.25,0.12697796523571,1,6,3,4,23.1730000402331,1,20.687856489297,1.1163330078125,44.4770278930664,40.0782012939453,,,,,,,,,,,,,,,,
,3875433302.87286,4.00109853744507,53773.076171875,,,,,,,,,,,,,0.233636627411203,1.68678876854598E-5,-3.69603939071837E-5,10,2,,80,2,2314,,,0.225660978304275,0.00266789454895164,0.00135888950899243,-0.000488013058202341,,,,0.0565511723517006,39.995735168457,1.97420089865918,4.0030083656311,4.00086879730225,4.00132894515991,53721.30078125,53824.8515625,0.126962319016457,1,6,3,4,23.1730000402331,1,20.6875965649941,1.112060546875,44.4770278930664,40.5669593811035,,,,,,,,,,,,,,,,
,3875433442.27208,4.00104351043701,46877.82421875,,,,,,,,,,,,,0.208014057309478,1.83146301200774E-5,-5.20335643049006E-5,10,2,,80,2,2382,,,0.200799893819383,0.00216740435485349,0.00120955018792301,-0.000433062872616574,,,,0.0503192608874716,39.995735168457,1.97414214710617,3.99996733665466,4.00099992752075,4.00113964080811,46825.7109375,46929.9375,0.126923412084579,1,6,3,4,23.1730000402331,1,20.6911898961303,1.11320495605469,43.9882698059082,40.5669593811035,,,,,,,,,,,,,,,,
,3875433581.73519,4.00069284439087,39977.59375,,,,,,,,,,,,,0.182690826806407,1.60059749562586E-5,-6.10385394511932E-5,10,2,,80,2,2450,,,0.176265099745205,0.00172044571522412,0.00106218899600208,-0.000379074219381437,,,,0.0441726694484338,39.995735168457,1.97423761937579,3.99757051467895,4.00054836273193,4.00081634521484,39925.70703125,40029.48046875,0.126885071396828,1,6,3,4,23.1730000402331,1,20.6916522621798,1.11251831054688,44.4770278930664,40.0782012939453,,,,,,,,,,,,,,,,
,3875433721.12795,4.00014591217041,33053.099609375,,,,,,,,,,,,,0.157475987894092,1.10053439883029E-5,-9.05761818121598E-5,10,2,,80,2,2518,,,0.151868323219417,0.00130070055633304,0.000915552489459515,-0.000325561210047454,,,,0.0380592341929901,39.995735168457,1.97427575407602,3.99623155593872,4.00006914138794,4.00018310546875,33000.91015625,33105.2890625,0.12684965133667,1,6,3,4,23.1730000402331,1,20.6945626071447,1.11549377441406,44.4770278930664,40.0782012939453,,,,,,,,,,,,,,,,
,3875433860.55381,3.99993524551392,26120.57421875,,,,,,,,,,,,,0.132107025637762,1.4554328447676E-5,-0.00013178893338298,10,2,,80,2,2586,,,0.127352498645506,0.000916422353029356,0.000768103753216565,-0.000271947996225208,,,,0.0319144719289766,39.995735168457,1.97423131079364,3.99620318412781,3.99987411499023,3.99999094009399,26068.37890625,26172.76953125,0.126811414957047,1,6,3,4,23.1730000402331,1,20.6946726255979,1.11564636230469,43.9882698059082,40.0782012939453,,,,,,,,,,,,,,,,
,3875433999.97204,3.99958915710449,19185.1640625,,,,,,,,,,,,,0.106797831700238,1.25017524575099E-5,-0.000170220384691117,10,2,,80,2,2654,,,0.102919638016453,0.000584346389894692,0.000621087965555489,-0.000218844957998954,,,,0.025792519359246,39.995735168457,1.9743043690932,3.99698615074158,3.99954509735107,3.99964809417725,19135.537109375,19234.791015625,0.126897156238556,1,6,3,4,23.1730000402331,1,20.6953805422009,1.11412048339844,43.9882698059082,40.0782012939453,,,,,,,,,,,,,,,,
,3875434139.39061,3.99937677383423,12253.5434570312,,,,,,,,,,,,,0.0822508063871378,1.14079796064275E-5,-0.000175159835464048,10,2,,80,2,2722,,,0.0792419605129499,0.000338083436413786,0.000478429661598057,-0.000167833510204218,,,,0.0198577817157509,39.995735168457,1.97430221245473,3.99789023399353,3.99926090240479,3.99946403503418,12203.798828125,12303.2880859375,0.126969575881958,1,6,3,4,23.1730000402331,1,20.6968594273085,1.1126708984375,43.9882698059082,40.5669593811035,,,,,,,,,,,,,,,,
,3875434278.87102,3.99954833984375,5313.13525390625,,,,,,,,,,,,,0.0582016413842249,1.17679202084342E-5,-0.000193420610946256,1,2,,80,2,2790,,,0.0560605060339528,0.000127858149585686,0.000338689773343503,-0.000118061907414813,,,,0.0140475035317958,39.995735168457,1.97423268349648,3.99971342086792,3.999436378479,3.99972629547119,5260.79833984375,5365.47216796875,0.127064064145088,1,6,3,4,23.1730000402331,1,20.6974701539133,1.1175537109375,43.9882698059082,40.5669593811035,,,,,,,,,,,,,,,,
,3875434418.29567,4.00014162063599,-1638.61297607422,,,,,,,,,,,,,0.0340893081095202,1.08038234349412E-5,-0.000119309019848974,1,2,,80,2,2858,,,0.0328323447588592,5.75628961913214E-5,0.00019840311142616,-6.90441156621091E-5,,,,0.00822751066369643,39.995735168457,1.9743399149217,4.00091791152954,4.0000524520874,4.00018310546875,-1690.837890625,-1586.38806152344,0.127064436674118,1,6,3,4,23.1730000402331,1,20.6977977322081,1.11495971679688,43.9882698059082,40.0782012939453,,,,,,,,,,,,,,,,
,3875434557.69055,4.0011568069458,-8589.4921875,,,,,,,,,,,,,0.00561102284898909,1.74348047130844E-5,-1.72330383318925E-5,1,2,,80,2,2926,,,0.00540511949022735,1.563209792105E-5,3.26483386743348E-5,-1.14018912427127E-5,,,,0.00135451898514418,39.995735168457,1.97422212409879,3.99809765815735,4.00113964080811,4.00116729736328,-8641.779296875,-8537.205078125,0.12703163921833,1,6,3,4,23.1730000402331,1,20.6956017679279,1.11259460449219,43.9882698059082,40.0782012939453,,,,,,,,,,,,,,,,
,3875434697.10077,4.00068407058716,-15540.0151367188,,,,,,,,,,,,,-0.0467065653410622,2.50653691684369E-5,0.00011658599815837,1,2,,80,2,2994,,,-0.0450037728034546,-0.000193853154079743,-0.00027170532848686,9.53384223976173E-5,,,,0.0112772500785386,39.995735168457,1.9742940315633,3.99568152427673,4.00051784515381,4.00080251693726,-15592.4658203125,-15487.564453125,0.126914709806442,1,6,3,4,23.1730000402331,1,20.6990109041063,1.11625671386719,44.4770278930664,40.0782012939453,,,,,,,,,,,,,,,,
,3875434836.53546,4.00020399093628,-22502.4814453125,,,,,,,,,,,,,-0.0939145462568389,1.97932962548585E-5,0.000142845455167953,1,2,,80,2,3062,,,-0.090518215220421,-0.000560064100019002,-0.000546114519238472,0.00019278225954622,,,,0.0226822614328388,39.995735168457,1.97421157528947,3.99442267417908,4.00015592575073,4.00030040740967,-22552.5234375,-22452.439453125,0.126812741160393,1,6,3,4,23.1730000402331,1,20.6992845334409,1.11167907714844,43.9882698059082,40.0782012939453,,,,,,,,,,,,,,,,
,3875434975.93406,4.00002336502075,-29472.166015625,,,,,,,,,,,,,-0.130868797963673,1.65666116133124E-5,0.000104268696440734,1,2,,80,2,3130,,,-0.126181990893626,-0.000990810728501976,-0.000760875293053687,0.000270001037279144,,,,0.0316202359338325,39.995735168457,1.97428524841549,3.99413132667542,3.99991035461426,4.00018882751465,-29522.296875,-29422.03515625,0.126699730753899,1,6,3,4,23.1730000402331,1,20.698032863101,1.11228942871094,43.9882698059082,40.0782012939453,,,,,,,,,,,,,,,,
,3875435117.44976,3.99955291748047,-36548.21875,,,,,,,,,,,,,-0.162772039227928,1.57354343267874E-5,2.99538496699427E-6,10,2,,80,2,3199,,,-0.157009901980821,-0.00150776762790778,-0.000946226005908102,0.000337710574967787,,,,0.0393493434740272,39.995735168457,1.97440566471341,3.99449920654297,3.99942541122437,3.99970388412476,-36598.234375,-36498.203125,0.126671090722084,1,6,3,4,23.1730000402331,1,20.7018196356029,1.11610412597656,43.49951171875,40.0782012939453,,,,,,,,,,,,,,,,
,3875435256.85743,3.99911770820618,-43518.8359375,,,,,,,,,,,,,-0.191587770276343,1.89532461875015E-5,5.82538409704038E-6,10,2,,80,2,3267,,,-0.184895643007515,-0.00195109471340432,-0.00111385015770793,0.000398709496948868,,,,0.0463364010585856,39.995735168457,1.97428054701236,3.99605274200439,3.99839425086975,3.99938344955444,-43568.53125,-43469.140625,0.126806542277336,1,6,3,4,23.1730000402331,1,20.7009506133349,1.11167907714844,43.49951171875,39.5894432067871,,,,,,,,,,,,,,,,
,3875435396.27623,3.99897456169128,-50491.4296875,,,,,,,,,,,,,-0.21911836267729,1.94639657149666E-5,3.46730406063275E-5,10,2,,80,2,3335,,,-0.211580048172576,-0.00240751368879098,-0.00127425161190331,0.000457277783425525,,,,0.0530244822540498,39.995735168457,1.97428571598974,3.99829506874084,3.9988124370575,3.99906849861145,-50543.7890625,-50439.0703125,0.126834124326706,1,6,3,4,23.1730000402331,1,20.6994978078304,1.11595153808594,43.9882698059082,39.5894432067871,,,,,,,,,,,,,,,,
,3875435535.6913,3.99864954948425,-57464.953125,,,,,,,,,,,,,-0.246238338183768,1.84470189149066E-5,9.44461233554256E-5,10,2,,80,2,3403,,,-0.237910246401103,-0.00287655820159022,-0.00143249612301588,0.000515235355123878,,,,0.0596249852364738,39.995735168457,1.97432788720567,4.00128412246704,3.99853348731995,3.99884867668152,-57514.9296875,-57414.9765625,0.12691642343998,1,6,3,4,23.1730000402331,1,20.7001429969856,1.11518859863281,43.9882698059082,39.5894432067871,,,,,,,,,,,,,,,,
,3875435675.09836,3.99835772514343,-64435.255859375,,,,,,,,,,,,,-0.273590988950031,1.80598434063356E-5,0.00019088406273465,10,2,,80,2,3471,,,-0.264511143557731,-0.00335643110094833,-0.00159240665379912,0.000573781377170235,,,,0.0662942801792866,39.995735168457,1.97440234359269,4.00470495223999,3.99827194213867,3.99850058555603,-64485.1484375,-64385.36328125,0.127025544643402,1,6,3,4,23.1730000402331,1,20.6986775297425,1.11160278320312,43.9882698059082,39.5894432067871,,,,,,,,,,,,,,,,
,3875435814.50536,3.99844470024109,-71405.28515625,,,,,,,,,,,,,-0.301644735103736,2.20809971004468E-5,0.000340793411644407,10,2,,80,2,3539,,,-0.291839919445365,-0.00383417587140898,-0.00175660906825215,0.0006338483071886,,,,0.0731420557045535,39.995735168457,1.97435104515541,4.00877714157105,3.99837183952332,3.99853682518005,-71455.1796875,-71355.390625,0.127230495214462,1,6,3,4,23.1730000402331,1,20.6989755983229,1.11282348632812,43.9882698059082,40.5669593811035,,,,,,,,,,,,,,,,
,3875435953.95672,3.99864621162415,-78395.61328125,,,,,,,,,,,,,-0.330908750167086,1.76215080016799E-5,0.000528509483742019,10,2,,80,2,3607,,,-0.32039434496102,-0.00433061622860043,-0.00192806881386787,0.000696495000738651,,,,0.0802914403363047,39.995735168457,1.97416975977514,4.01296186447144,3.99858117103577,3.99867844581604,-78446.09375,-78345.1328125,0.127237290143967,1,6,3,4,23.1730000402331,1,20.6977366562757,1.11724853515625,43.9882698059082,39.5894432067871,,,,,,,,,,,,,,,,
,3875436093.37921,3.99882769584656,-85442.78125,,,,,,,,,,,,,-0.364393751083623,2.78867665233029E-5,0.000757759885175703,10,2,,80,2,3675,,,-0.35309857863346,-0.0048883142768114,-0.00212480593472719,0.000768195895943791,,,,0.0884927139211177,39.995735168457,1.97428575627091,4.01616907119751,3.99875044822693,3.99890112876892,-85493.2890625,-85392.2734375,0.127303019165993,1,6,3,4,23.1730000402331,1,20.6940387567813,1.11076354980469,43.9882698059082,40.0782012939453,,,,,,,,,,,,,,,,
,3875436232.77487,3.99903738498688,-92489.734375,,,,,,,,,,,,,-0.399902118041282,2.91170363399521E-5,0.00105639065526437,10,2,,80,2,3743,,,-0.387832122932139,-0.00544697075345427,-0.00233367481268942,0.00084402464563027,,,,0.0971961021110812,39.995735168457,1.97424289837593,4.01917839050293,3.99900221824646,3.99905467033386,-92540.2890625,-92439.1796875,0.127337843179703,1,6,3,4,23.1730000402331,1,20.6893847384748,1.11557006835938,43.9882698059082,39.5894432067871,,,,,,,,,,,,,,,,
,3875436372.1902,3.99921669960022,-99537.41015625,,,,,,,,,,,,,-0.434752062257327,2.68419654669112E-5,0.00137147184992045,10,2,,80,2,3811,,,-0.421997817666578,-0.0060110317316113,-0.0025389832444489,0.000918760080821812,,,,0.105753905268427,39.995735168457,1.97414134632361,4.02186346054077,3.99863123893738,3.99941635131836,-99587.859375,-99486.9609375,0.127395302057266,1,6,3,4,23.1730000402331,1,20.687553964927,1.11320495605469,43.9882698059082,39.5894432067871,,,,,,,,,,,,,,,,
,3875436511.6117,3.9994992017746,-106585.34765625,,,,,,,,,,,,,-0.468681033829588,2.71634403997767E-5,0.00170769171596949,10,2,,80,2,3879,,,-0.4553398795723,-0.00656384411358679,-0.00273932563140988,0.000991694279946387,,,,0.11410509801281,39.995735168457,1.97404599461495,4.02403259277344,3.99917459487915,4.00006341934204,-106638.3671875,-106532.328125,0.127494946122169,1,6,3,4,23.1730000402331,1,20.6858566385321,1.11312866210938,43.9882698059082,40.0782012939453,,,,,,,,,,,,,,,,
,3875436651.02604,3.99994850158691,-113635.28125,,,,,,,,,,,,,-0.5016164291672,3.05788345062738E-5,0.00200692430662521,10,2,,80,2,3947,,,-0.487784482600131,-0.00715297232107834,-0.00293431198224425,0.00106275512371212,,,,0.122233040838783,39.995735168457,1.97400463368335,4.02534246444702,3.99971771240234,4.00009393692017,-113685.7265625,-113584.8359375,0.127449661493301,1,6,3,4,23.1730000402331,1,20.679737812969,1.11137390136719,43.9882698059082,40.0782012939453,,,,,,,,,,,,,,,,
,3875436790.46188,4.0001255273819,-120685.81640625,,,,,,,,,,,,,-0.533535570537102,2.63581391450806E-5,0.00209284993416109,10,2,,80,2,4015,,,-0.519302852340455,-0.00794230983000233,-0.00312314787879586,0.00113318290095776,,,,0.130125782982233,39.995735168457,1.97391204845965,4.02557754516602,4.0000467300415,4.00022840499878,-120738.828125,-120632.8046875,0.127501755952835,1,6,3,4,23.1730000402331,1,20.6766450348534,1.11244201660156,44.4770278930664,40.0782012939453,,,,,,,,,,,,,,,,
,3875436929.8882,4.000048828125,-127733.04296875,,,,,,,,,,,,,-0.564654498676849,3.4038505039211E-5,0.0022730184380145,10,2,,80,2,4083,,,-0.550106764429677,-0.00863004029106967,-0.00330796628259122,0.00120145734399557,,,,0.137842403389982,39.995735168457,1.9738693099117,4.0253701210022,3.99974298477173,4.00025272369385,-127786.1328125,-127679.953125,0.12749008834362,1,6,3,4,23.1730000402331,1,20.6727009318714,1.11289978027344,43.9882698059082,40.0782012939453,,,,,,,,,,,,,,,,
,3875437069.286,4.00039100646973,-134779.8359375,,,,,,,,,,,,,-0.594989778584822,2.93164933622034E-5,0.00259546357704766,10,2,,80,2,4151,,,-0.580209716976764,-0.00916365717525544,-0.00348883727565408,0.00126732932403684,,,,0.145380986788678,39.995735168457,1.97381382654796,4.02412223815918,4.00002431869507,4.00055694580078,-134832.828125,-134726.84375,0.127438217401505,1,6,3,4,23.1730000402331,1,20.6692458287142,1.1114501953125,44.4770278930664,40.5669593811035,,,,,,,,,,,,,,,,
,3875437208.69767,4.00044364929199,-139999.78125,,,,,,,,,,,,,-0.617035465236902,2.57748091498984E-5,0.00288233176136775,10,2,,80,2,4219,,,-0.60213141334052,-0.00950050054807594,-0.00362055609002709,0.00131503294687718,,,,0.150868847777249,39.995735168457,1.97373410365477,4.02264356613159,4.00037813186646,4.00050401687622,-139999.796875,-139999.765625,0.127355068922043,1,4,3,4,23.1730000402331,1,20.6681309077159,1.11213684082031,44.4770278930664,40.0782012939453,,,,,,,,,,,,,,,,
,3875437348.11015,3.99942960739136,-137459.3984375,,,,,,,,,,,,,-0.606479430463621,2.50809961379509E-5,0.00284903122434792,10,2,,80,2,4287,,,-0.591629804020164,-0.00923679266178831,-0.00355767831206322,0.00129139889031649,,,,0.148238762054338,39.995735168457,1.97374616133073,4.02208948135376,3.99938344955444,3.99946165084839,-137509,-137409.796875,0.127513393759727,1,6,3,4,23.1730000402331,1,20.6662938438988,1.11091613769531,44.4770278930664,40.5669593811035,,,,,,,,,,,,,,,,
,3875437487.53233,3.99912637472153,-130546.69921875,,,,,,,,,,,,,-0.577209063876038,2.98821851832368E-5,0.00256812178437854,10,2,,80,2,4355,,,-0.562553550877311,-0.0086899186811763,-0.00338320108130574,0.00122745626140386,,,,0.140960966325976,39.995735168457,1.97385472702185,4.02461528778076,3.99903559684753,3.99919939041138,-130598.6328125,-130494.765625,0.127579391002655,1,6,3,4,23.1730000402331,1,20.6666381065435,1.11183166503906,46.9208221435547,40.0782012939453,,,,,,,,,,,,,,,,
,3875437626.9589,3.99943809509277,-123634.1484375,,,,,,,,,,,,,-0.547359045179141,2.946662162736E-5,0.00224408904197961,10,2,,80,2,4423,,,-0.53296729003085,-0.00817109481238193,-0.00320519926026463,0.00116261770017445,,,,0.133540802577615,39.995735168457,1.97376222083288,4.02544593811035,3.99938631057739,3.99962329864502,-123683.796875,-123584.5,0.127682238817215,1,6,3,4,23.1730000402331,1,20.6692062612625,1.10969543457031,44.4770278930664,40.0782012939453,,,,,,,,,,,,,,,,
,3875437766.37988,3.99989023208618,-116724.171875,,,,,,,,,,,,,-0.51677952099031,2.21531594632236E-5,0.00198632017411844,10,2,,80,2,4491,,,-0.502730877431736,-0.00757612117658485,-0.00302370055578649,0.00109589111525565,,,,0.125966395745253,39.995735168457,1.9738060340144,4.02600622177124,3.99971532821655,3.99998569488525,-116773.8515625,-116674.4921875,0.12771387398243,1,6,3,4,23.1730000402331,1,20.6692442505687,1.11251831054688,44.4770278930664,40.5669593811035,,,,,,,,,,,,,,,,
,3875437905.79662,4.00021386146545,-109811.42578125,,,,,,,,,,,,,-0.485339105323825,2.50403078893543E-5,0.00168279829637059,10,2,,80,2,4559,,,-0.471717503270236,-0.00701720539567582,-0.00283751194365323,0.0010277742985636,,,,0.118200942310303,39.995735168457,1.97391107303453,4.0256609916687,4.00016927719116,4.00026941299438,-109863.4609375,-109759.390625,0.12773559987545,1,6,3,4,23.1730000402331,1,20.6690130522495,1.11259460449219,43.9882698059082,40.5669593811035,,,,,,,,,,,,,,,,
,3875438045.20361,4.00039787292481,-102903.22265625,,,,,,,,,,,,,-0.45297437198604,2.62364961927369E-5,0.00144222103060356,10,2,,80,2,4627,,,-0.439871132686193,-0.00639434170215825,-0.00264630513265729,0.000957486918196082,,,,0.110221885249113,39.995735168457,1.97394265456448,4.0247073173523,4.00000762939453,4.00061511993408,-102952.890625,-102853.5546875,0.127798393368721,1,6,3,4,23.1730000402331,1,20.6687079120117,1.11557006835938,44.4770278930664,39.5894432067871,,,,,,,,,,,,,,,,
,3875438184.63177,4.00058352947235,-95989.24609375,,,,,,,,,,,,,-0.419645165288515,2.23879373476873E-5,0.00123406370601997,10,2,,80,2,4695,,,-0.407154260439518,-0.00574323768109497,-0.0024498023558408,0.000885321933310479,,,,0.102023035451861,39.995735168457,1.97394190053231,4.0225625038147,4.00045919418335,4.000657081604,-96041.3203125,-95937.171875,0.127752274274826,1,6,3,4,23.1730000402331,1,20.6713456154155,1.11160278320312,44.4770278930664,40.5669593811035,,,,,,,,,,,,,,,,
,3875438324.04665,4.00113039016724,-89075.3984375,,,,,,,,,,,,,-0.385112619270185,2.96012894816107E-5,0.000982255477773284,10,2,,80,2,4763,,,-0.373336443086205,-0.00514167803009449,-0.00224656565114856,0.00081114168278873,,,,0.0935497528052945,39.995735168457,1.97395758805919,4.02025747299194,4.00097179412842,4.00122308731079,-89125.078125,-89025.71875,0.127684578299522,1,6,3,4,23.1730000402331,1,20.6739049874156,1.11167907714844,44.9657897949219,40.0782012939453,,,,,,,,,,,,,,,,
,3875438463.47318,4.00097608566284,-82163.26953125,,,,,,,,,,,,,-0.349672832232138,2.23021192765203E-5,0.000773214884761803,10,2,,80,2,4831,,,-0.338707693028805,-0.00451869397468359,-0.0020384481176734,0.000735091743990779,,,,0.0848724455625903,39.995735168457,1.97394221202411,4.01720285415649,4.00088882446289,4.00106716156006,-82212.7734375,-82113.765625,0.127601265907288,1,6,3,4,23.1730000402331,1,20.6760446256839,1.11488342285156,44.4770278930664,40.0782012939453,,,,,,,,,,,,,,,,
,3875438602.89169,4.00126342773438,-75248.25390625,,,,,,,,,,,,,-0.317973125082755,1.49892539952249E-5,0.000547041530512116,10,2,,80,2,4899,,,-0.307765043441902,-0.00400627066638107,-0.00185247336048633,0.000667342392262071,,,,0.0771196375020542,39.995735168457,1.97398292538992,4.01374197006226,4.00106143951416,4.00145483016968,-75300.2421875,-75196.265625,0.127476468682289,1,6,3,4,23.1730000402331,1,20.6758538370388,1.11442565917969,44.4770278930664,40.5669593811035,,,,,,,,,,,,,,,,
,3875438742.30404,4.00139608383179,-68335.8515625,,,,,,,,,,,,,-0.289824116732016,2.00455295934916E-5,0.000295923835232013,10,2,,80,2,4967,,,-0.280314998271559,-0.00360570296763277,-0.00168743799440563,0.00060767465038225,,,,0.0702460922683242,39.995735168457,1.97413202694188,4.01032066345215,4.00125360488892,4.00154399871826,-68387.875,-68283.828125,0.127395361661911,1,6,3,4,23.1730000402331,1,20.6782367984717,1.11434936523438,44.4770278930664,40.5669593811035,,,,,,,,,,,,,,,,
,3875438881.72668,4.00128784179688,-61420.16015625,,,,,,,,,,,,,-0.262720607646774,2.13405703274485E-5,0.000113689035772712,10,2,,80,2,5035,,,-0.253927494902991,-0.00319008883528631,-0.0015287259593606,0.00055002752924338,,,,0.0636316830064018,39.995735168457,1.97411116835192,4.00663900375366,4.00116443634033,4.00138235092163,-61469.71875,-61370.6015625,0.127427577972412,1,6,3,4,23.1730000402331,1,20.6790921277076,1.11465454101562,44.4770278930664,40.5669593811035,,,,,,,,,,,,,,,,
,3875439021.13738,4.00109815597534,-54507.32421875,,,,,,,,,,,,,-0.236400424250152,2.01692799034874E-5,5.41064069105093E-6,10,2,,80,2,5103,,,-0.228344497695948,-0.00275305930849247,-0.00137491547502577,0.000493997300509363,,,,0.0572207815221816,39.995735168457,1.97410581169453,4.00322914123535,4.00101661682129,4.00117826461792,-54556.96875,-54457.6796875,0.127152666449547,1,6,3,4,23.1730000402331,1,20.6826382078924,1.11198425292969,44.4770278930664,40.5669593811035,,,,,,,,,,,,,,,,
,3875439160.57723,4.00133335590363,-47589.6953125,,,,,,,,,,,,,-0.210625250623398,1.49068816569609E-5,2.37710728890318E-5,10,2,,80,2,5171,,,-0.203331561025333,-0.00224245571393186,-0.00122474820818752,0.000438678864156827,,,,0.050953390053581,39.995735168457,1.97414278423341,4.00047492980957,4.00120878219604,4.00140190124512,-47639.31640625,-47540.07421875,0.126953527331352,1,6,3,4,23.1730000402331,1,20.6849808615127,1.11564636230469,44.4770278930664,40.5669593811035,,,,,,,,,,,,,,,,
,3875439299.97812,4.00048627853394,-40679.357421875,,,,,,,,,,,,,-0.185235495597504,1.67990339927646E-5,3.47316466447823E-5,10,2,,80,2,5239,,,-0.178728815821901,-0.00178800358603182,-0.00107693392783403,0.000384577142540365,,,,0.0447885024801741,39.995735168457,1.97418510280511,3.9979133605957,4.0003924369812,4.00061321258545,-40731.36328125,-40627.3515625,0.126960709691048,1,6,3,4,23.1730000402331,1,20.6890659094177,1.11663818359375,44.9657897949219,40.5669593811035,,,,,,,,,,,,,,,,
,3875439439.40913,4.00036172866821,-33736.810546875,,,,,,,,,,,,,-0.159956815514244,1.25595119442841E-5,6.68415978646869E-5,10,2,,80,2,5307,,,-0.154267126204607,-0.00136002403326608,-0.000929881585761905,0.000330826092977077,,,,0.0386568778344602,39.995735168457,1.97410023205298,3.99650692939758,4.00026655197144,4.00049018859863,-33786.71875,-33686.90234375,0.12700591981411,1,6,3,4,23.1730000402331,1,20.689437704648,1.11557006835938,44.4770278930664,40.5669593811035,,,,,,,,,,,,,,,,
,3875439578.81238,4.00009288787842,-26785.2685546875,,,,,,,,,,,,,-0.134539094178468,1.42082370623372E-5,0.000112454510594559,10,2,,80,2,5375,,,-0.129701487897188,-0.000965968859291871,-0.000782273011282086,0.000277109647868201,,,,0.0325053398350284,39.995735168457,1.97434996596508,3.99560761451721,3.99989891052246,4.00031137466431,-26835.134765625,-26735.40234375,0.126890957355499,1,6,3,4,23.1730000402331,1,20.6896904956638,1.11305236816406,44.9657897949219,40.5669593811035,,,,,,,,,,,,,,,,
,3875439718.21995,3.99967861175537,-19831.111328125,,,,,,,,,,,,,-0.109100004210294,1.35123930131706E-5,0.000142648433836859,10,2,,80,2,5443,,,-0.105141062801616,-0.000635933555706458,-0.000634420313872397,0.000223773793550208,,,,0.0263490197115463,39.995735168457,1.97429744987257,3.99709916114807,3.99963712692261,3.99974822998047,-19883.265625,-19778.95703125,0.126976683735847,1,6,3,4,23.1730000402331,1,20.6927049712469,1.11236572265625,44.9657897949219,40.5669593811035,,,,,,,,,,,,,,,,
,3875439857.63546,3.99948053359985,-12882.0327148438,,,,,,,,,,,,,-0.0844139936499293,1.13599982516428E-5,0.000165997642053788,10,2,,80,2,5511,,,-0.0813278100112066,-0.000366486148520379,-0.000490990583784878,0.000172318788827397,,,,0.0203805681569866,39.995735168457,1.97426753398159,3.99809765815735,3.99941968917847,3.99955081939697,-12931.9287109375,-12832.13671875,0.12696684896946,1,6,3,4,23.1730000402331,1,20.6913169603479,1.11175537109375,44.4770278930664,41.055721282959,,,,,,,,,,,,,,,,
,3875439997.14004,3.9993931055069,-5918.92041015625,,,,,,,,,,,,,-0.0602833691478089,1.12356513340898E-5,0.000183199060725509,1,2,,80,2,5579,,,-0.0580665323062765,-0.000152655563673429,-0.000350754387909546,0.000122404875583015,,,,0.0145496832436194,39.995735168457,1.97416148246896,3.99965023994446,3.99934148788452,3.99946403503418,-5971.34912109375,-5866.49169921875,0.127102702856064,1,6,3,4,23.1730000402331,1,20.697531541187,1.11541748046875,44.4770278930664,41.055721282959,,,,,,,,,,,,,,,,
,3875440136.53404,3.99985733032227,1046.10641479492,,,,,,,,,,,,,-0.0361465656348292,1.11017415069721E-5,0.000123439615190024,1,2,,80,2,5647,,,-0.0348133306906974,-6.23472491771814E-5,-0.000210374579182826,7.32029802748002E-5,,,,0.008723927653927,39.995735168457,1.97432347143954,4.00051975250244,3.9997878074646,3.99996614456177,993.640319824219,1098.57250976562,0.127105265855789,1,6,3,4,23.1730000402331,1,20.6938915692538,1.11251831054688,44.9657897949219,40.5669593811035,,,,,,,,,,,,,,,,
,3875440275.96266,4.00102443695068,8019.46728515625,,,,,,,,,,,,,-0.00866674145328702,1.65368697568266E-5,2.71488752514572E-5,1,2,,80,2,5715,,,-0.00834855813492056,-2.30932680896022E-5,-5.04293748235796E-5,1.76050707523245E-5,,,,0.00209188164584565,39.995735168457,1.97421706633905,3.99882984161377,4.00084638595581,4.00110292434692,7969.462890625,8069.4716796875,0.126930728554726,1,6,3,4,23.1730000402331,1,20.6961823871303,1.11213684082031,44.4770278930664,40.5669593811035,,,,,,,,,,,,,,,,
,3875440415.36675,4.00074157714844,14987.671875,,,,,,,,,,,,,0.0422957181413554,2.5268855131715E-5,-0.000115405053230797,1,2,,80,2,5783,,,0.0407528924249331,0.000163237145501443,0.000246069015702233,-8.62737724673934E-5,,,,0.0102125394709657,39.995735168457,1.97434841745897,3.99602127075195,3.99995756149292,4.00147724151611,14935.1201171875,15040.2236328125,0.126979976892471,1,6,3,4,23.1730000402331,1,20.7019740807098,1.11053466796875,44.4770278930664,40.5669593811035,,,,,,,,,,,,,,,,
,3875440554.77239,4.00032842159271,21968.2421875,,,,,,,,,,,,,0.0907811381915286,1.98944814478875E-5,-0.000189600112015366,1,2,,80,2,5851,,,0.0874962326400002,0.000485502478659642,0.00052803271682933,-0.000185984856216237,,,,0.0219258459851891,39.995735168457,1.97429751085176,3.99473667144775,4.00024509429932,4.00040340423584,21918.0703125,22018.4140625,0.126829355955124,1,6,3,4,23.1730000402331,1,20.6958717788236,1.11129760742188,44.9657897949219,40.5669593811035,,,,,,,,,,,,,,,,
,3875440694.18655,4.00002937316895,28960.7802734375,,,,,,,,,,,,,0.128399712486058,1.60470264069758E-5,-0.000171012159687592,1,2,,80,2,5919,,,0.123798291954811,0.000897202536650849,0.000746770354453474,-0.000264476519078016,,,,0.0310276129593684,39.995735168457,1.97457921234713,3.99385190010071,3.99997138977051,4.00009393692017,28908.25390625,29013.306640625,0.126783311367035,1,6,3,4,23.1730000402331,1,20.6972967531982,1.11534118652344,44.4770278930664,40.0782012939453,,,,,,,,,,,,,,,,
,3875440833.63214,3.9996994972229,35952.669921875,,,,,,,,,,,,,0.16021885825256,1.78480614497223E-5,-0.000115053924301568,1,2,,80,2,5987,,,0.154542117614885,0.00136323119199649,0.000931640330236405,-0.000331625429680571,,,,0.0387300854180016,39.995735168457,1.97443848985702,3.99405384063721,3.99960660934448,3.99977397918701,35902.45703125,36002.8828125,0.126748442649841,1,6,3,4,23.1730000402331,1,20.6986251180003,1.11557006835938,44.9657897949219,40.0782012939453,,,,,,,,,,,,,,,,
,3875440975.11303,3.99913773536682,43047.427734375,,,,,,,,,,,,,0.189696938964258,1.92824103239257E-5,2.79300668469821E-5,10,2,,80,2,6056,,,0.183064151632543,0.0019524117055198,0.00110283622052521,-0.000394881120882928,,,,0.045879964360152,39.995735168457,1.97437993729534,3.99552989006042,3.9989902973175,3.99919128417969,42997.31640625,43097.5390625,0.126905485987663,1,6,3,4,23.1730000402331,1,20.6997460455452,1.11549377441406,44.4770278930664,40.5669593811035,,,,,,,,,,,,,,,,
,3875441114.5404,3.99901909828186,50037.728515625,,,,,,,,,,,,,0.217376720707664,1.71534039975698E-5,9.97069249711646E-7,10,2,,80,2,6124,,,0.209890139758758,0.00240952059870923,0.00126405071932822,-0.000453846441814676,,,,0.0526031950276831,39.995735168457,1.97436265467963,3.99828267097473,3.9987952709198,3.99922466278076,49987.609375,50087.84765625,0.126750811934471,1,6,3,4,23.1730000402331,1,20.7029107725222,1.11747741699219,44.4770278930664,40.0782012939453,,,,,,,,,,,,,,,,
,3875441253.94931,3.99876379966736,57030.095703125,,,,,,,,,,,,,0.244556080456984,1.93941568451272E-5,-7.00835672979073E-5,10,2,,80,2,6192,,,0.236275398237263,0.00286604787158266,0.00142263132147491,-0.000511830439791083,,,,0.0592163330425398,39.995735168457,1.97436172827969,4.0012788772583,3.99873423576355,3.99880385398865,56977.4375,57082.75390625,0.126756638288498,1,6,3,4,23.1730000402331,1,20.7030059925459,1.11122131347656,44.4770278930664,40.0782012939453,,,,,,,,,,,,,,,,
,3875441393.3708,3.99858832359314,64020.5859375,,,,,,,,,,,,,0.271981338007937,1.88117928114956E-5,-0.000153714458976079,10,2,,80,2,6260,,,0.262943887797635,0.00335734048620079,0.00158289587125182,-0.000570631003938615,,,,0.0659022107467694,39.995735168457,1.9744164149655,4.00489234924316,3.99852252006531,3.99864220619202,63968.15625,64073.015625,0.126951634883881,1,6,3,4,23.1730000402331,1,20.7030071856023,1.11297607421875,44.4770278930664,40.0782012939453,,,,,,,,,,,,,,,,
,3875441532.77054,3.99863448143005,71011.046875,,,,,,,,,,,,,0.300068870581471,2.47630635001856E-5,-0.000287005448930721,10,2,,80,2,6328,,,0.290302701912348,0.00385011324259976,0.00174716301262379,-0.000630882161203772,,,,0.072755099712906,39.995735168457,1.9742874267739,4.00854110717773,3.99856114387512,3.99874567985535,70958.3828125,71063.7109375,0.126966446638107,1,6,3,4,23.1730000402331,1,20.7046789575853,1.11686706542969,43.9882698059082,40.5669593811035,,,,,,,,,,,,,,,,
,3875441672.20082,3.9988290309906,78013.97265625,,,,,,,,,,,,,0.329323751649684,1.78056244411267E-5,-0.000441073389875647,10,2,,80,2,6396,,,0.318845107604763,0.00437750291036251,0.00191864219959825,-0.000693806447088718,,,,0.0799091003324047,39.995735168457,1.97429605957673,4.01264095306396,3.9986617565155,3.99894595146179,77963.078125,78064.8671875,0.127089589834213,1,6,3,4,23.1730000402331,1,20.7044807106873,1.11289978027344,44.4770278930664,40.5669593811035,,,,,,,,,,,,,,,,
,3875441811.63301,3.99860272407532,85081.11328125,,,,,,,,,,,,,0.362659871020722,2.2937687131661E-5,-0.00069803361798071,10,2,,80,2,6464,,,0.35140291765047,0.00490501324817257,0.00211433763615787,-0.000765067699830979,,,,0.0880647188985916,39.995735168457,1.97423046884898,4.01584625244141,3.99848628044128,3.99870371818542,85030.34375,85131.8828125,0.127148613333702,1,6,3,4,23.1730000402331,1,20.7032214654948,1.11160278320312,43.9882698059082,40.0782012939453,,,,,,,,,,,,,,,,
,3875441951.04429,3.99913768768311,92151.5859375,,,,,,,,,,,,,0.398287067479044,3.04920630658035E-5,-0.000949883802369223,10,2,,80,2,6532,,,0.386248466205845,0.00551019483464306,0.0023237164132297,-0.000841410306748003,,,,0.0967939572788333,39.995735168457,1.97413814423653,4.01977491378784,3.99901032447815,3.99922180175781,92098.3203125,92204.8515625,0.127321422100067,1,6,3,4,23.1730000402331,1,20.6982349819926,1.11618041992188,44.4770278930664,40.0782012939453,,,,,,,,,,,,,,,,
,3875442090.44286,3.99917793273926,99222.4921875,,,,,,,,,,,,,0.433283114836988,2.57205935413328E-5,-0.00129683500858933,10,2,,80,2,6600,,,0.420554321175144,0.00604550353929531,0.00252992426976562,-0.000916480203159153,,,,0.105388634113253,39.995735168457,1.97409403585747,4.02197360992432,3.99907422065735,3.99938631057739,99171.796875,99273.1875,0.12730772793293,1,6,3,4,23.1730000402331,1,20.7000446551938,1.11305236816406,44.4770278930664,40.0782012939453,,,,,,,,,,,,,,,,
,3875442229.86687,3.99956595897675,106289.640625,,,,,,,,,,,,,0.467341041381635,3.40620382563038E-5,-0.00159045083995805,10,2,,80,2,6668,,,0.454018925836509,0.00664189361698125,0.00273103709332645,-0.000989877036772668,,,,0.11377460351674,39.995735168457,1.97406730385535,4.0239372253418,3.99948644638062,3.99966526031494,106238.9296875,106340.3515625,0.127377659082413,1,6,3,4,23.1730000402331,1,20.6955535889989,1.11740112304688,44.4770278930664,40.0782012939453,,,,,,,,,,,,,,,,
,3875442369.28504,3.9995379447937,113357.81640625,,,,,,,,,,,,,0.50041828389938,3.34737362330517E-5,-0.0020411264613981,10,2,,80,2,6736,,,0.48660250276247,0.00708660333289293,0.00292704533785582,-0.00106065906584263,,,,0.121937215845017,39.995735168457,1.97401813367937,4.02505540847778,3.99947834014893,3.99960660934448,113307.078125,113408.5546875,0.127368733286858,1,6,3,4,23.1730000402331,1,20.6947815489379,1.11106872558594,44.4770278930664,40.5669593811035,,,,,,,,,,,,,,,,
,3875442508.70721,4.0000054359436,120429.2578125,,,,,,,,,,,,,0.532515399524699,2.38008990064471E-5,-0.00233133683912969,10,2,,80,2,6804,,,0.51829687198221,0.00768095507011099,0.00311743817292154,-0.00113029987551272,,,,0.129878009834692,39.995735168457,1.97397853212212,4.02559328079224,3.99958419799805,4.00018882751465,120376.0078125,120482.5078125,0.127296596765518,1,6,3,4,23.1730000402331,1,20.6906515443026,1.11305236816406,43.9882698059082,40.5669593811035,,,,,,,,,,,,,,,,
,3875442648.12169,4.00018811225891,127496.875,,,,,,,,,,,,,0.563725442433357,2.7612722882014E-5,-0.0025122397631724,10,2,,80,2,6872,,,0.549189038107782,0.00837023737343515,0.00330268801189959,-0.00119899038691074,,,,0.137616220660455,39.995735168457,1.97392235231694,4.0257077217102,3.99995756149292,4.00066804885864,127443.703125,127550.046875,0.127292707562447,1,6,3,4,23.1730000402331,1,20.6898692931369,1.11297607421875,44.4770278930664,40.5669593811035,,,,,,,,,,,,,,,,
,3875442787.54459,4.00059375762939,134568.703125,,,,,,,,,,,,,0.594212578873857,3.3167108474989E-5,-0.00271297173545215,10,2,,80,2,6940,,,0.579437850847123,0.00902631501516155,0.00348412711173296,-0.00126596831250936,,,,0.145190385273091,39.995735168457,1.97384585045525,4.02451276779175,4.00050115585327,4.00069379806519,134517.96875,134619.4375,0.127179577946663,1,6,3,4,23.1730000402331,1,20.6867020841693,1.11488342285156,43.9882698059082,40.0782012939453,,,,,,,,,,,,,,,,
,3875442926.96098,4.00045318603516,140000.28125,,,,,,,,,,,,,0.617181437500313,4.11894024301915E-5,-0.0027487039746882,10,2,,80,2,7008,,,0.60227121982196,0.00963381782116432,0.00362085946835577,-0.00131722411606461,,,,0.150909340059868,39.995735168457,1.97380015728069,4.02305364608765,4.00035047531128,4.00062084197998,140000.28125,140000.28125,0.127098143100739,1,4,3,4,23.1730000402331,1,20.68474686978,1.11236572265625,43.9882698059082,40.0782012939453,,,,,,,,,,,,,,,,
,3875443015.11424,4.00000643730164,140000.5703125,,,,,,,,,,,,,0.617186774561096,3.00376304348093E-5,-0.0028018883317292,10,2,,80,2,7051,,,0.602277512025753,0.00958203923126114,0.00362097984179854,-0.00131694437004626,,,,0.150909601464664,39.995735168457,1.9737910016099,4.02248334884644,3.99992990493774,4.00008296966553,140000.53125,140000.609375,0.127080023288727,1,4,3,4,23.1730000402331,1,20.6851597721714,1.11328125,44.9657897949219,40.0782012939453,,,,,,,,,,,,,,,,