File: MPMS/NiCl2btd/NiCl2btd_MvH_3K_14T.dat
[Header]
; ACMS II Data File (default extension .dat)
; Copyright (c) 2014, Quantum Design, Inc. All rights reserved.
TITLE,
FILEOPENTIME,3875411424.845,10/20/2022,7:11 am
BYAPP,ACMS II,1.0,1.2
INFO,DYNACOOL ACMS II Option Release 1.0.8 Build 33,APPNAME
INFO,Quantum Design Linear Motor Servo Controller,MOTOR_MODULE_NAME
INFO,3101-100 K0,MOTOR_HW_VERSION
INFO,MMC794,MOTOR_SERIAL_NUMBER
INFO,SRV No X-over 01.03.11,MOTOR_SOFTWARE_VERSION
INFO,ACMS,ACMS_MODULE_NAME
INFO,3101-430 A0,ACMS_HW_VERSION
INFO,ACMSII028,ACMS_SERIAL_NUMBER
INFO,00.14.14,ACMS_SOFTWARE_VERSION
INFO,WF046,COIL_SERIAL_NUMBER
INFO,0,MOMENT_UNITS
INFO,NiCl2-btdm,SAMPLE_MATERIAL
INFO,4.8mg cling film,SAMPLE_COMMENT
INFO,22.1,SAMPLE_MASS
INFO,,SAMPLE_VOLUME
INFO,,SAMPLE_MOLECULAR_WEIGHT
INFO,,SAMPLE_SIZE
INFO,,SAMPLE_SHAPE
DATATYPE,COMMENT,1
DATATYPE,TIME,2
STARTUPAXIS,X,2
STARTUPAXIS,Y1,5
STARTUPGROUP, AC
FIELDGROUP, AC, 2,3,4,5,6,7,8,9,10,11,12,13,14,15,16,20,21,22,23,24,25,35,43,44,45,46,47,48,49
FIELDGROUP, DC, 2,3,4,17,18,19,20,21,23,24,25,35,36,37,43,44,45,46,47,48,49,50,51
FIELDGROUP, Diagnostic, 26,27,28,29,30,31,32,33,34,38,39,40,41,42,52,53,54,55,56,57,58,59,60,61,62,63,64,65,66,67,68,69
[Data]
Comment,Time Stamp (sec),Temperature (K),Magnetic Field (Oe),AC Moment (emu),AC Std. Dev. (emu),AC Phase (deg),AC Phase Std. Dev. (deg),AC Suscept. (emu/Oe),AC Suscept. Std. Dev. (emu/Oe),AC X'  (emu/Oe),AC X" (emu/Oe),AC X' Std. Dev. (emu/Oe),AC X" Std. Dev. (emu/Oe),AC Drive (Oe),AC Frequency (Hz),DC Moment (emu),DC Std. Err. (emu),DC Quad. Moment (emu),Range (mV),"AC=1 DC=2 Locate=3",Measure Type,Measure Count,Measure Time (sec),Measure Number,AC X' Raw (emu/Oe),AC X" Raw (emu/Oe),DC M. Raw' (emu),DC M. Raw" (emu),Coil InPhase (V),Coil Quadrature (V),Null Status,Trim Ratio,Trim Phase (deg.),Max. Signal (mV),Motor Frequency (Hz),Motor Ampl. (mm),System Temp. (K),Min. Temperature (K),Max. Temperature (K),Min. Field (Oe),Max. Field (Oe),Pressure (Torr),Temp. Status (code),Field Status (code),Chamber Status (code),Measure Status (code),Center Position (mm),Transport Action,Motor Lag (deg),Motor Current (amps),Motor Heatsink Temp. (C),Motor Board Temp. (C),QMap 01,QMap 02,QMap 03,QMap 04,QMap 05,QMap 06,QMap 07,QMap 08,QMap 09,QMap 10,QMap 11,QMap 12,QMap 13,QMap 14,QMap 15,QMap 16
sample offset = 25.15 mm,3875411962.48217,3.00101881027222,0.355725258588791,,,,,,,,,,,,,0.0394363874577664,2.93962260383816E-6,-6.79680130594468E-5,1,2,,80,2,1,,,0.03798087215137,0.000129746464821362,0.000229447658057325,-8.01137357484549E-5,,,,0.00951907416386279,39.995735168457,1.97446471080915,3.00215840339661,3.00092172622681,3.00115180015564,0.355725258588791,0.355725258588791,0.0948842689394951,1,4,3,4,23.1730000402331,1,20.6617822646666,1.11343383789062,31.7693061828613,32.7468223571777,,,,,,,,,,,,,,,,
,3875412110.58691,3.00050133466721,1647.97033691406,,,,,,,,,,,,,0.0451105929087343,1.21461915455791E-5,-0.000119951906148742,1,2,,80,2,70,,,0.0434470579062726,0.000112738334311439,0.000262522371485829,-9.14887132239528E-5,,,,0.0108885683274044,39.995735168457,1.97446067928089,3.00093412399292,3.00044202804565,3.00056147575378,1595.44775390625,1700.49291992187,0.0959249287843704,1,6,3,4,23.1730000402331,1,20.6751049749083,1.10893249511719,40.0782012939453,33.2355842590332,,,,,,,,,,,,,,,,
,3875412258.65012,3.00095176696777,9048.92138671875,,,,,,,,,,,,,0.0721247802621061,1.25898967127295E-5,-0.000156762344719518,1,2,,80,2,139,,,0.0694787169594489,0.000266979440779243,0.000419596210122108,-0.000146831996971741,,,,0.0174108356352806,39.995735168457,1.97430445373536,2.99827671051025,3.00089144706726,3.00100946426392,8993.8603515625,9103.982421875,0.095957413315773,1,6,3,4,23.1730000402331,1,20.6770340727123,1.11175537109375,41.5444793701172,34.2131004333496,,,,,,,,,,,,,,,,
,3875412406.63659,3.00136232376099,16449.49609375,,,,,,,,,,,,,0.0987344255697825,1.36229961158646E-5,-0.000152535429939713,1,2,,80,2,208,,,0.0951377597198325,0.000511279662067952,0.00057426153216511,-0.000201933507923968,,,,0.0238410303665215,39.995735168457,1.97432823220696,2.99491715431213,3.00120544433594,3.00147986412048,16394.513671875,16504.478515625,0.0958667397499084,1,6,3,4,23.1730000402331,1,20.6762171373062,1.11152648925781,42.5219955444336,36.6568908691406,,,,,,,,,,,,,,,,
,3875412551.79634,3.00096778869629,23721.376953125,,,,,,,,,,,,,0.125400739021621,1.12645039455011E-5,-0.000138691463651033,1,2,,80,2,277,,,0.120872647339018,0.000817693420233412,0.000729208055417985,-0.000257608946412802,,,,0.0302889308158053,39.995735168457,1.97425912318472,2.99075055122375,3.00087213516235,3.00110721588135,23671.185546875,23771.568359375,0.0957378894090652,1,6,3,4,23.1730000402331,1,20.6797012176298,1.11564636230469,43.0107536315918,37.6344108581543,,,,,,,,,,,,,,,,
,3875412693.24817,3.00056538581848,30812.0419921875,,,,,,,,,,,,,0.151727082065711,1.48989917802285E-5,-0.000123597312575473,1,2,,80,2,346,,,0.146304676100116,0.00117301527266701,0.000882255146279931,-0.000312887859763578,,,,0.0366617353645368,39.995735168457,1.97424123949622,2.98817825317383,3.00045275688171,3.00073623657227,30761.841796875,30862.2421875,0.0956165418028831,1,6,3,4,23.1730000402331,1,20.6778558904506,1.11679077148438,43.49951171875,38.1231689453125,,,,,,,,,,,,,,,,
,3875412836.81436,3.00009503364563,38013.1328125,,,,,,,,,,,,,0.178007055577878,1.811326479696E-5,-5.18198204536719E-7,10,2,,80,2,416,,,0.171722313981191,0.00168642626214112,0.00103488995227963,-0.000369086483260617,,,,0.0430338948407703,39.995735168457,1.97423363793103,2.98652029037476,3.00000357627869,3.00015139579773,37963.08203125,38063.18359375,0.0955298021435738,1,6,3,4,23.1730000402331,1,20.6761641812775,1.11053466796875,43.49951171875,38.6119270324707,,,,,,,,,,,,,,,,
,3875412978.28982,2.99976050853729,45107.3125,,,,,,,,,,,,,0.204008974083985,1.85613455182185E-5,5.07260628917052E-6,10,2,,80,2,485,,,0.196906283871077,0.00213172335898711,0.00118617690168321,-0.000424371915869415,,,,0.049342467901802,39.995735168457,1.9741042955642,2.98660635948181,2.9996931552887,2.99988198280334,45057.09765625,45157.52734375,0.0955844670534134,1,6,3,4,23.1730000402331,1,20.6755358738703,1.11091613769531,43.49951171875,38.6119270324707,,,,,,,,,,,,,,,,
,3875413119.74767,2.99950675964355,52198.330078125,,,,,,,,,,,,,0.230228921921132,1.86542316008793E-5,-1.08703433840367E-5,10,2,,80,2,554,,,0.222339573057416,0.00260607140631287,0.00133912079036236,-0.000480367743875831,,,,0.0557217158507602,39.995735168457,1.97429179047724,2.9878990650177,2.9994421005249,2.99958443641663,52148.14453125,52248.515625,0.0955654084682465,1,6,3,4,23.1730000402331,1,20.6727188892641,1.11724853515625,43.0107536315918,38.6119270324707,,,,,,,,,,,,,,,,
,3875413261.21405,2.99925452470779,59294.40234375,,,,,,,,,,,,,0.25687995109115,2.15904820019605E-5,-3.5241347614402E-5,10,2,,80,2,623,,,0.24823236294475,0.00312264127328067,0.0014944194117561,-0.000537543150130659,,,,0.0622029662565914,39.995735168457,1.97402296525598,2.98922681808472,2.99920153617859,2.99929428100586,59244.1640625,59344.640625,0.0955103039741516,1,6,3,4,23.1730000402331,1,20.6733572128824,1.11648559570312,43.9882698059082,39.5894432067871,,,,,,,,,,,,,,,,
,3875413402.67094,2.99921498298645,66386.53515625,,,,,,,,,,,,,0.284196890268215,2.03383418422657E-5,-0.000100051185310564,10,2,,80,2,692,,,0.274816303255495,0.00365092113621593,0.0016541660297662,-0.0005962970899418,,,,0.0688689428293854,39.995735168457,1.97414742978737,2.99100208282471,2.99905705451965,2.99932456016541,66333.875,66439.1953125,0.0955625995993614,1,6,3,4,23.1730000402331,1,20.6725913606586,1.11412048339844,43.49951171875,39.1006851196289,,,,,,,,,,,,,,,,
,3875413544.14579,2.99941158294678,73482.7578125,,,,,,,,,,,,,0.312440807546016,1.90136046646427E-5,-0.000217113923140705,10,2,,80,2,761,,,0.302348925123174,0.00418103121214357,0.00181953643914312,-0.000656979216728359,,,,0.0757677442511903,39.995735168457,1.97411943087423,2.99285125732422,2.99931526184082,2.99947214126587,73430.2890625,73535.2265625,0.0955753102898598,1,6,3,4,23.1730000402331,1,20.6712412987388,1.11549377441406,43.49951171875,39.5894432067871,,,,,,,,,,,,,,,,
,3875413685.63545,2.99953532218933,80617.1328125,,,,,,,,,,,,,0.342358008891691,1.90514650685945E-5,-0.000326027096559315,10,2,,80,2,830,,,0.331558150755185,0.00478162845194249,0.00199478957802057,-0.000721596996299922,,,,0.0830830014748047,39.995735168457,1.97400134742809,2.99458265304565,2.99945425987244,2.99961137771606,80563.953125,80670.3125,0.0957353487610817,1,6,3,4,23.1730000402331,1,20.6712826123001,1.11579895019531,43.49951171875,39.5894432067871,,,,,,,,,,,,,,,,
,3875413827.09244,2.99966268539429,87790.30078125,,,,,,,,,,,,,0.377414397616395,2.56033601185164E-5,-0.000543859967320102,10,2,,80,2,899,,,0.365811703177644,0.00539286952425277,0.00220081373117864,-0.000796874286606908,,,,0.091673802830191,39.995735168457,1.97415781090507,2.99567437171936,2.99951648712158,2.99974679946899,87737.0546875,87843.546875,0.0958177968859673,1,6,3,4,23.1730000402331,1,20.6701850012696,1.11343383789062,43.9882698059082,39.5894432067871,,,,,,,,,,,,,,,,
,3875413968.55578,2.9996817111969,94962.62109375,,,,,,,,,,,,,0.413076752992161,1.93750712353989E-5,-0.000793516915632107,10,2,,80,2,968,,,0.40072414792179,0.00601942006011164,0.00241045816801488,-0.00087351119145751,,,,0.100416142761538,39.995735168457,1.97401183579357,2.9962854385376,2.9989058971405,2.99993777275085,94911.9140625,95013.328125,0.0956678166985512,1,6,3,4,23.1730000402331,1,20.6695017536902,1.11160278320312,43.9882698059082,40.5669593811035,,,,,,,,,,,,,,,,
,3875414110.03249,3.00026979446411,102133.8671875,,,,,,,,,,,,,0.447945338416227,2.38034015833188E-5,-0.00105194594083615,10,2,,80,2,1037,,,0.43493900334958,0.00665457779484291,0.00261608208529651,-0.000948790984693915,,,,0.108992710826214,39.995735168457,1.9740480476645,2.9966127872467,3.00017642974854,3.00035667419434,102080.6328125,102187.1015625,0.0957265198230743,1,6,3,4,23.1730000402331,1,20.6683471501862,1.11198425292969,43.9882698059082,40.0782012939453,,,,,,,,,,,,,,,,
,3875414251.48698,3.00039262771606,109306.0625,,,,,,,,,,,,,0.48191160804179,3.17516768586728E-5,-0.00138093849026507,10,2,,80,2,1106,,,0.468350508617017,0.00722849582537977,0.00281682703644037,-0.00102210813201964,,,,0.117364402106685,39.995735168457,1.97400418739751,2.99553322792053,3.00022959709167,3.00062775611877,109254.9921875,109357.1328125,0.0956538468599319,1,6,3,4,23.1730000402331,1,20.6698739568017,1.11572265625,43.9882698059082,40.0782012939453,,,,,,,,,,,,,,,,
,3875414392.96114,3.00046815872192,116481.16796875,,,,,,,,,,,,,0.515065606863731,3.28259319789756E-5,-0.00172247860916814,10,2,,80,2,1175,,,0.501042822580895,0.00779138636036733,0.0030134052503854,-0.00109380204230547,,,,0.125559918209914,39.995735168457,1.97404860205249,2.99391579627991,3.00040483474731,3.00057411193848,116430.5078125,116531.828125,0.0955161824822426,1,6,3,4,23.1730000402331,1,20.6693210523244,1.11602783203125,43.9882698059082,40.0782012939453,,,,,,,,,,,,,,,,
,3875414534.45596,3.00098285675049,123657.97265625,,,,,,,,,,,,,0.547402408773014,2.82669469424638E-5,-0.0020291226133457,10,2,,80,2,1244,,,0.533007078380001,0.00838214138393187,0.00320547935552895,-0.00116407033056021,,,,0.133570278045365,39.995735168457,1.97404859849062,2.99169039726257,3.00085425376892,3.00111293792725,123604.65625,123711.2890625,0.0954420194029808,1,6,3,4,23.1730000402331,1,20.6679287930846,1.11083984375,43.9882698059082,39.5894432067871,,,,,,,,,,,,,,,,
,3875414675.90213,3.00125012397766,130828.24609375,,,,,,,,,,,,,0.579055038124607,3.31874254789463E-5,-0.00237618550444635,10,2,,80,2,1313,,,0.564369923702601,0.00892316960069922,0.00339389010332525,-0.00123294873628765,,,,0.141426402312104,39.995735168457,1.97401181363986,2.98871088027954,3.00107359886169,3.00143909454346,130774.984375,130881.5078125,0.0953482165932655,1,6,3,4,23.1730000402331,1,20.6698921456453,1.11175537109375,43.9882698059082,40.0782012939453,,,,,,,,,,,,,,,,
,3875414817.35754,3.00119299888611,138000.8203125,,,,,,,,,,,,,0.609991294204565,3.45145178766006E-5,-0.00271487721076461,10,2,,80,2,1382,,,0.595095697189927,0.00945591157996667,0.00357906869612634,-0.00130029278807342,,,,0.149144148027475,39.995735168457,1.97425162159573,2.98545432090759,3.00108742713928,3.00128030776978,137950.203125,138051.4375,0.0952841639518738,1,6,3,4,23.1730000402331,1,20.6663846639035,1.11099243164062,44.4770278930664,40.0782012939453,,,,,,,,,,,,,,,,
,3875414958.82373,3.00006709098816,140000.7109375,,,,,,,,,,,,,0.618387915046291,2.56301203745227E-5,-0.00280137725471776,10,2,,80,2,1451,,,0.603449474637405,0.00960651057881495,0.00362897524610162,-0.00131838244851679,,,,0.151223650363626,39.995735168457,1.97405654291485,2.98338770866394,2.99989676475525,3.00017285346985,140000.6875,140000.734375,0.0951612368226051,1,4,3,4,23.1730000402331,1,20.6641087567003,1.1102294921875,43.0107536315918,40.0782012939453,,,,,,,,,,,,,,,,
,3875415100.29139,2.99892253875732,134090.0234375,,,,,,,,,,,,,0.593568033469834,3.24405029114296E-5,-0.0025588893014745,10,2,,80,2,1520,,,0.578769292778614,0.00914682450168136,0.00348055805079639,-0.00126436783466488,,,,0.145037996907111,39.995735168457,1.97404385874502,2.98517656326294,2.9988112449646,2.99897885322571,134040.359375,134139.6875,0.0952515676617622,1,6,3,4,23.1730000402331,1,20.6693286138424,1.11473083496094,44.4770278930664,40.0782012939453,,,,,,,,,,,,,,,,
,3875415241.75874,2.99879384040833,127092.6328125,,,,,,,,,,,,,0.563369788464769,2.90290649043153E-5,-0.00225382281521945,10,2,,80,2,1589,,,0.548808047393244,0.0085997939622707,0.00330051663331687,-0.00119834765791893,,,,0.13752757497718,39.995735168457,1.97401087265431,2.98862886428833,2.99864029884338,2.99887347221375,127040.703125,127144.5625,0.0955045446753502,1,6,3,4,23.1730000402331,1,20.6675356808448,1.11183166503906,44.4770278930664,40.0782012939453,,,,,,,,,,,,,,,,
,3875415383.2477,2.99889183044434,120094.10546875,,,,,,,,,,,,,0.532591565738704,2.22126734734928E-5,-0.00181274066163876,10,2,,80,2,1658,,,0.518338344852418,0.00817372425651616,0.00311711919493973,-0.00113212282303721,,,,0.129890628720772,39.995735168457,1.97398371468966,2.99121618270874,2.99877214431763,2.99898600578308,120042.2734375,120145.9375,0.0956270024180412,1,6,3,4,23.1730000402331,1,20.6677498267712,1.11442565917969,43.9882698059082,40.0782012939453,,,,,,,,,,,,,,,,
,3875415524.70732,2.99923676252365,113093.74609375,,,,,,,,,,,,,0.501204921061315,2.4504560977335E-5,-0.00153367990234511,10,2,,80,2,1727,,,0.487341385246547,0.00758337272825738,0.0029309568926692,-0.00106396991759539,,,,0.122125202568922,39.995735168457,1.97403874644122,2.99373507499695,2.99916052818298,2.999347448349,113041.640625,113145.8515625,0.0957978516817093,1,6,3,4,23.1730000402331,1,20.6703664251521,1.11534118652344,43.49951171875,39.5894432067871,,,,,,,,,,,,,,,,
,3875415666.17193,2.99945058822632,106096.171875,,,,,,,,,,,,,0.469116486268206,2.07112447955958E-5,-0.00120798950124635,10,2,,80,2,1796,,,0.455725676371408,0.00703639704122369,0.00274087372235954,-0.000994593952782452,,,,0.114199448456273,39.995735168457,1.97399788766642,2.99541568756103,2.9992995262146,2.99955582618713,106046.7890625,106145.5546875,0.0957797914743423,1,6,3,4,23.1730000402331,1,20.6703793207153,1.11358642578125,43.9882698059082,40.0782012939453,,,,,,,,,,,,,,,,
,3875415807.64268,2.99970799684525,99099.16796875,,,,,,,,,,,,,0.436265403511097,2.81436523751137E-5,-0.000950023727053185,10,2,,80,2,1865,,,0.423436482082805,0.00642717551140221,0.00254696770571172,-0.000923528103157878,,,,0.106110322446409,39.995735168457,1.97405830872572,2.99615240097046,2.99965739250183,2.99977016448975,99047.1796875,99151.15625,0.0958779528737068,1,6,3,4,23.1730000402331,1,20.6713910561095,1.11640930175781,43.9882698059082,39.5894432067871,,,,,,,,,,,,,,,,
,3875415949.10957,3.00025978088379,92098.546875,,,,,,,,,,,,,0.402251133713915,2.71013271258394E-5,-0.00072641738737121,10,2,,80,2,1934,,,0.390086435689594,0.00578869554973259,0.00234665023162961,-0.000850118580274284,,,,0.097754658562936,39.995735168457,1.97409847239117,2.99620795249939,3.00004935264587,3.00038838386536,92046.59375,92150.5,0.0958755612373352,1,6,3,4,23.1730000402331,1,20.6740982422063,1.11091613769531,43.9882698059082,40.0782012939453,,,,,,,,,,,,,,,,
,3875416090.60235,3.00017251968384,85101.3203125,,,,,,,,,,,,,0.366848248746456,2.53578702279571E-5,-0.000483127402709275,10,2,,80,2,2003,,,0.355458651811109,0.00517851797480562,0.00213849218562245,-0.00077398307621479,,,,0.0890745178626519,39.995735168457,1.97403137524938,2.9961256980896,3.0001392364502,3.00019955635071,85051.859375,85150.78125,0.0959083139896393,1,6,3,4,23.1730000402331,1,20.6724163829279,1.11610412597656,43.9882698059082,40.5669593811035,,,,,,,,,,,,,,,,
,3875416232.04485,3.00043835639954,78100.6875,,,,,,,,,,,,,0.331876600731728,1.79490750846668E-5,-0.00035111976305634,10,2,,80,2,2072,,,0.321318391644675,0.00450517756704487,0.00193354161456227,-0.00069865130353719,,,,0.08052248266441,39.995735168457,1.97412373573769,2.99526953697205,3.0003137588501,3.00056147575378,78050.7265625,78150.6484375,0.0958708748221397,1,6,3,4,23.1730000402331,1,20.6735423594373,1.11106872558594,43.9882698059082,40.0782012939453,,,,,,,,,,,,,,,,
,3875416373.51898,3.00064735412598,71103.1328125,,,,,,,,,,,,,0.302975430146003,1.88694903782007E-5,-0.000186791717341488,10,2,,80,2,2141,,,0.293116011749943,0.00399043442207654,0.00176390074193478,-0.000636738957837224,,,,0.0734496100568976,39.995735168457,1.97398734655386,2.99388265609741,3.00039958953857,3.00078272819519,71051.2578125,71155.0078125,0.0959334298968315,1,6,3,4,23.1730000402331,1,20.6791727415053,1.11534118652344,43.9882698059082,39.5894432067871,,,,,,,,,,,,,,,,
,3875416514.97224,3.00091069936752,64103.763671875,,,,,,,,,,,,,0.275467265149456,2.20450544753089E-5,-9.94874514224316E-5,10,2,,80,2,2210,,,0.26631537626963,0.00345758603699636,0.00160308426711708,-0.000577503815293312,,,,0.0667371737749018,39.995735168457,1.97411235649478,2.9921817779541,3.00084519386292,3.00096106529236,64051.9609375,64155.56640625,0.0958870425820351,1,6,3,4,23.1730000402331,1,20.6778901647522,1.11358642578125,43.9882698059082,39.5894432067871,,,,,,,,,,,,,,,,
,3875416656.44786,3.00091004371643,57105.94921875,,,,,,,,,,,,,0.248749842967458,2.12622951944128E-5,-1.98836966680029E-5,10,2,,80,2,2279,,,0.240328149807398,0.00296730256660117,0.00144697807263583,-0.000520280271302909,,,,0.0602249809843105,39.995735168457,1.97414168807209,2.99018239974976,3.00072193145752,3.00107145309448,57056.453125,57155.4453125,0.0959764122962952,1,6,3,4,23.1730000402331,1,20.6797340849394,1.11328125,43.9882698059082,39.5894432067871,,,,,,,,,,,,,,,,
,3875416797.91573,3.00040197372437,50109.7421875,,,,,,,,,,,,,0.222628911278985,2.24691234229914E-5,1.1726249449083E-5,10,2,,80,2,2348,,,0.214962566656127,0.00248019464409578,0.00129462569020689,-0.000464397919131443,,,,0.0538696557857868,39.995735168457,1.97419133093687,2.9888026714325,3.00036334991455,3.00042963027954,50057.86328125,50161.62109375,0.0959761664271355,1,6,3,4,23.1730000402331,1,20.6828845923486,1.11106872558594,44.4770278930664,40.0782012939453,,,,,,,,,,,,,,,,
,3875416939.38536,3.00010454654694,43109.71875,,,,,,,,,,,,,0.196844735441053,1.81347680731512E-5,1.45048326823992E-5,10,2,,80,2,2417,,,0.189963023578325,0.00201364560301839,0.00114449975080788,-0.000409316271543503,,,,0.0476071593007834,39.995735168457,1.97429195434353,2.9880051612854,3.00000500679016,3.00018882751465,43057.57421875,43161.86328125,0.0959037765860558,1,6,3,4,23.1730000402331,1,20.6820391494244,1.11656188964844,43.9882698059082,39.5894432067871,,,,,,,,,,,,,,,,
,3875417080.87727,2.9999363899231,36096.876953125,,,,,,,,,,,,,0.171258381368193,1.62366962332925E-5,-2.17234470987189E-5,10,2,,80,2,2486,,,0.165191102349939,0.00155813126765499,0.000995572307147086,-0.000354853982571512,,,,0.0413965079351227,39.995735168457,1.97419337828536,2.98793625831604,2.99975943565369,3.00013566017151,36045,36148.75390625,0.0958051308989525,1,6,3,4,23.1730000402331,1,20.6876845315633,1.11129760742188,43.9882698059082,40.0782012939453,,,,,,,,,,,,,,,,
,3875417222.33171,2.99946039915085,29059.0439453125,,,,,,,,,,,,,0.145585047934254,1.60596417147255E-5,-4.27069386405864E-5,10,2,,80,2,2555,,,0.140367280049859,0.00116494780313375,0.000846334674861282,-0.00030055534443818,,,,0.0351767113965996,39.995735168457,1.97426454135509,2.98941230773926,2.9993851184845,2.99957942962646,29006.884765625,29111.203125,0.0958840250968933,1,6,3,4,23.1730000402331,1,20.6861613440462,1.11114501953125,43.9882698059082,40.0782012939453,,,,,,,,,,,,,,,,
,3875417363.78235,2.99881472587585,22024.37109375,,,,,,,,,,,,,0.11949067237549,1.46235988165248E-5,-7.43305215003E-5,10,2,,80,2,2624,,,0.11516592650422,0.000808789050821344,0.000694672868121415,-0.000245714763877913,,,,0.0288605037355108,39.995735168457,1.97422319074329,2.9920072555542,2.99868631362915,2.99901413917542,21974.50390625,22074.23828125,0.0960870981216431,1,6,3,4,23.1730000402331,1,20.687370750291,1.11122131347656,43.9882698059082,39.5894432067871,,,,,,,,,,,,,,,,
,3875417505.26308,2.9983829498291,14989.1235351562,,,,,,,,,,,,,0.0938344993481144,1.27663542538824E-5,-0.000103178516232425,10,2,,80,2,2693,,,0.090410692912071,0.00050943692076779,0.000545590766705573,-0.000192153151147068,,,,0.0226559728675679,39.995735168457,1.97416504937109,2.99561238288879,2.99830889701843,2.9984655380249,14936.96875,15041.2783203125,0.0961818918585777,1,6,3,4,23.1730000402331,1,20.6894539768557,1.11343383789062,43.9882698059082,40.0782012939453,,,,,,,,,,,,,,,,
,3875417646.71967,2.99892058372498,7952.61059570312,,,,,,,,,,,,,0.0686138248375814,1.21844202260849E-5,-0.000114982358429304,10,2,,80,2,2762,,,0.066094085384008,0.000278610256588339,0.000399065291276202,-0.000139916824991815,,,,0.0165633405193014,39.995735168457,1.97426906268481,2.99976706504822,2.99886298179626,2.99909257888794,7902.78955078125,8002.431640625,0.096311904489994,1,6,3,4,23.1730000402331,1,20.6901223500391,1.11526489257812,43.9882698059082,40.0782012939453,,,,,,,,,,,,,,,,
,3875417788.25886,3.00003237724304,897.961791992188,,,,,,,,,,,,,0.0433136013962949,1.13324824822374E-5,-0.000112031118784553,1,2,,80,2,2831,,,0.0417157214713361,0.000108805725959869,0.000252019701292738,-8.79084982443601E-5,,,,0.0104535161606277,39.995735168457,1.97432856188682,3.00124859809876,2.9999463558197,3.00009226799011,848.044250488281,947.879333496094,0.0964487344026566,1,6,3,4,23.1730000402331,1,20.690542649795,1.11259460449219,43.0107536315918,40.0782012939453,,,,,,,,,,,,,,,,
,3875417929.7125,3.00074756145477,-6153.91528320312,,,,,,,,,,,,,0.0170299823595832,1.2647952528382E-5,-4.13479144085948E-5,1,2,,80,2,2900,,,0.0164037790912415,5.35606385108529E-5,9.90756889223121E-5,-3.46364467986859E-5,,,,0.00411044559703547,39.995735168457,1.97429614755752,2.99943113327026,3.00071501731873,3.00077366828918,-6206.1884765625,-6101.64208984375,0.0964223816990852,1,6,3,4,23.1730000402331,1,20.6927321904712,1.11282348632812,43.9882698059082,43.0107536315918,,,,,,,,,,,,,,,,
,3875418071.1831,3.00135378837585,-13209.1103515625,,,,,,,,,,,,,-0.0197441885801362,2.0587298365974E-5,3.08437820026087E-5,1,2,,80,2,2969,,,-0.0190225198399673,-9.41758549358376E-5,-0.000114821734314319,4.03636586270295E-5,,,,0.00476727957824075,39.995735168457,1.97426148344232,2.99622964859009,3.00128030776978,3.00143027305603,-13261.4765625,-13156.744140625,0.0962307006120682,1,6,3,4,23.1730000402331,1,20.6950130682256,1.11457824707031,43.9882698059082,40.0782012939453,,,,,,,,,,,,,,,,
,3875418212.65594,3.00137364864349,-20265.9287109375,,,,,,,,,,,,,-0.0697938495668034,2.22630432549437E-5,9.51923701175216E-5,1,2,,80,2,3038,,,-0.0672625850642974,-0.000406867911429774,-0.000405832019168884,0.000143193858093582,,,,0.0168551327309232,39.995735168457,1.97422388802114,2.99241542816162,3.00081133842468,3.00162482261658,-20315.91015625,-20215.947265625,0.0961604043841362,1,6,3,4,23.1730000402331,1,20.6987130985856,1.11587524414062,43.9882698059082,40.0782012939453,,,,,,,,,,,,,,,,
,3875418354.12082,3.00106377601624,-27339.263671875,,,,,,,,,,,,,-0.113584406651608,1.95361541953185E-5,0.000105234003320632,1,2,,80,2,3107,,,-0.109503636500842,-0.000813842577777189,-0.000660426914691925,0.0002339955244679,,,,0.027441333783558,39.995735168457,1.97431675902726,2.9893593788147,3.00091290473938,3.00120735168457,-27391.779296875,-27286.748046875,0.0960104092955589,1,6,3,4,23.1730000402331,1,20.6942961355145,1.11343383789062,43.9882698059082,40.0782012939453,,,,,,,,,,,,,,,,
,3875418495.6165,3.00062031745911,-34413.736328125,,,,,,,,,,,,,-0.150093503482608,1.79142218995133E-5,9.53063679642712E-5,1,2,,80,2,3176,,,-0.144761089132156,-0.00125827967639088,-0.000872707401867956,0.000310406147036701,,,,0.0362772424273532,39.995735168457,1.97433573509424,2.98688983917236,3.00040483474731,3.00080919265747,-34466.3203125,-34361.15234375,0.0959013998508453,1,6,3,4,23.1730000402331,1,20.6919358388981,1.11541748046875,44.4770278930664,39.5894432067871,,,,,,,,,,,,,,,,
,3875418639.14254,3.00019240379334,-41589.658203125,,,,,,,,,,,,,-0.182715821886026,2.09658435486434E-5,-1.79049040613675E-5,10,2,,80,2,3246,,,-0.176308546806311,-0.00183626529054171,-0.00106225197669119,0.000379898556275293,,,,0.0441853234798283,39.995735168457,1.9743293291872,2.9864227771759,3.00006413459778,3.00042748451233,-41642.1953125,-41537.12109375,0.0959427654743195,1,6,3,4,23.1730000402331,1,20.6925108397292,1.11083984375,43.9882698059082,40.0782012939453,,,,,,,,,,,,,,,,
,3875418780.60733,2.99957919120789,-48665.234375,,,,,,,,,,,,,-0.212523216130558,2.08186358760188E-5,-2.64864873640059E-5,10,2,,80,2,3315,,,-0.205180751074134,-0.00234172794178594,-0.00123566738329828,0.000443406432168558,,,,0.0514176547368459,39.995735168457,1.97419975784182,2.98659300804138,2.99953985214233,2.99961853027344,-48717.8671875,-48612.6015625,0.0958382189273834,1,6,3,4,23.1730000402331,1,20.6965071559935,1.11618041992188,43.9882698059082,40.5669593811035,,,,,,,,,,,,,,,,
,3875418922.07516,2.99960327148438,-55739.740234375,,,,,,,,,,,,,-0.240828896574539,1.98967497943391E-5,-1.38348044093649E-5,10,2,,80,2,3384,,,-0.232646812158005,-0.00286203789467007,-0.00140069657936692,0.000504025083500892,,,,0.0583038404098909,39.995735168457,1.97427197733745,2.98819804191589,2.99950265884399,2.99968647956848,-55792.171875,-55687.30859375,0.095862090587616,1,6,3,4,23.1730000402331,1,20.6962793136894,1.11228942871094,43.9882698059082,39.5894432067871,,,,,,,,,,,,,,,,
,3875419063.53573,2.99918537139893,-62815.390625,,,,,,,,,,,,,-0.268763639262564,1.78049858624665E-5,6.49485491146279E-5,10,2,,80,2,3453,,,-0.259801909257109,-0.00336075366350595,-0.00156394089572132,0.000563825538847595,,,,0.0651125107630458,39.995735168457,1.97437108388775,2.98978781700134,2.99911570549011,2.99923729896545,-62867.77734375,-62763.00390625,0.0958160012960434,1,6,3,4,23.1730000402331,1,20.6943089322778,1.11137390136719,44.4770278930664,39.1006851196289,,,,,,,,,,,,,,,,
,3875419205.00425,2.99926608800888,-69889.26171875,,,,,,,,,,,,,-0.297053914076645,1.9839529680687E-5,0.000150277457780306,10,2,,80,2,3522,,,-0.287350849734966,-0.00390030695511476,-0.00172928092069924,0.000624724722001702,,,,0.0720144645055535,39.995735168457,1.9742545953654,2.99184346199036,2.99913001060486,2.99937081336975,-69939.375,-69839.1484375,0.0958860591053963,1,6,3,4,23.1730000402331,1,20.6956488728505,1.11579895019531,43.9882698059082,40.0782012939453,,,,,,,,,,,,,,,,
,3875419346.47665,2.99954142570496,-76962.0078125,,,,,,,,,,,,,-0.326193185332323,1.29536289887703E-5,0.000258994973698176,10,2,,80,2,3591,,,-0.315775279325597,-0.00446810229332389,-0.00190014019608498,0.000687517458572984,,,,0.0791440335619313,39.995735168457,1.97438955885601,2.99372053146362,2.99939584732056,2.99962210655212,-77014.4140625,-76909.6015625,0.0960777550935745,1,6,3,4,23.1730000402331,1,20.6911073684768,1.11595153808594,44.4770278930664,40.0782012939453,,,,,,,,,,,,,,,,
,3875419487.95139,2.9995584487915,-84113.9453125,,,,,,,,,,,,,-0.358740589129661,2.35074036151245E-5,0.00043988209062305,10,2,,80,2,3660,,,-0.347562815071692,-0.00505644969378334,-0.00209105177782476,0.000757546280510724,,,,0.087108144167583,39.995735168457,1.9743187970353,2.99474382400513,2.99950265884399,2.99959564208984,-84167.0546875,-84060.8359375,0.0960150957107544,1,6,3,4,23.1730000402331,1,20.6913393620646,1.11579895019531,43.9882698059082,39.5894432067871,,,,,,,,,,,,,,,,
,3875419629.4095,2.9998058795929,-91267.4296875,,,,,,,,,,,,,-0.394580632523968,2.37430585244704E-5,0.000635417183708453,10,2,,80,2,3729,,,-0.382608590827626,-0.0057189827919705,-0.00230166967958212,0.00083461805479601,,,,0.0958917210169931,39.995735168457,1.9743222173791,2.99563717842102,2.99974679946899,2.9998927116394,-91320.515625,-91214.34375,0.0960336923599243,1,6,3,4,23.1730000402331,1,20.6854036076797,1.11648559570312,43.9882698059082,40.0782012939453,,,,,,,,,,,,,,,,
,3875419770.87991,3.00005192756653,-98420.21484375,,,,,,,,,,,,,-0.429843966550828,2.84771413996067E-5,0.000876627049010262,10,2,,80,2,3798,,,-0.417167788556248,-0.00636186892195994,-0.00250928732566535,0.000910541275516152,,,,0.104549826300763,39.995735168457,1.97425133922658,2.99628186225891,2.99990177154541,3.00016021728516,-98473.2578125,-98367.171875,0.0960790142416954,1,6,3,4,23.1730000402331,1,20.6809346884312,1.11541748046875,44.4770278930664,40.0782012939453,,,,,,,,,,,,,,,,
,3875419912.34571,3.00026297569275,-105570.828125,,,,,,,,,,,,,-0.464234560229397,2.39071098687087E-5,0.00115772525694006,10,2,,80,2,3867,,,-0.450952289963789,-0.00697783688315712,-0.00271231308579445,0.000984634854830802,,,,0.113015134734123,39.995735168457,1.97420376182245,2.9958074092865,3.00019240379334,3.00034189224243,-105621.4921875,-105520.1640625,0.0960953012108803,1,6,3,4,23.1730000402331,1,20.6760125304844,1.11480712890625,42.5219955444336,40.0782012939453,,,,,,,,,,,,,,,,
,3875420053.80284,3.00052804946899,-112718.77734375,,,,,,,,,,,,,-0.497717687064569,3.33971956926829E-5,0.00150108017637124,10,2,,80,2,3936,,,-0.483926633574154,-0.00753651363676927,-0.00291037303395569,0.00105693540535867,,,,0.121273331085354,39.995735168457,1.97410321170633,2.99485945701599,3.00045824050903,3.00060820579529,-112769.3125,-112668.2421875,0.0960166752338409,1,6,3,4,23.1730000402331,1,20.6772359234961,1.11228942871094,43.9882698059082,40.0782012939453,,,,,,,,,,,,,,,,
,3875420195.31077,3.00083434581757,-119874.61328125,,,,,,,,,,,,,-0.530392521901441,3.84114325231057E-5,0.00183703546560805,10,2,,80,2,4005,,,-0.51618380547943,-0.00810030189032412,-0.00310421804897487,0.00112752779386938,,,,0.129354153472015,39.995735168457,1.97404121855282,2.99266123771667,3.00073790550232,3.00091099739075,-119927.71875,-119821.5078125,0.0959390178322792,1,6,3,4,23.1730000402331,1,20.6736047757918,1.11114501953125,43.9882698059082,40.0782012939453,,,,,,,,,,,,,,,,
,3875420336.74116,3.00093865394592,-127024.03125,,,,,,,,,,,,,-0.562298435260456,2.98098194516711E-5,0.00220110579115628,10,2,,80,2,4074,,,-0.547758457920562,-0.00862800546178399,-0.00329427886754274,0.00119639933109283,,,,0.137272256250514,39.995735168457,1.97411619845143,2.9905321598053,3.0008237361908,3.00113749504089,-127074.765625,-126973.296875,0.0958206579089165,1,6,3,4,23.1730000402331,1,20.667728561982,1.11358642578125,43.9882698059082,40.0782012939453,,,,,,,,,,,,,,,,
,3875420478.21879,3.00118288993835,-134174.34375,,,,,,,,,,,,,-0.593510630833231,3.77642637963142E-5,0.00257588132938679,10,2,,80,2,4143,,,-0.578720179454886,-0.00913214773883747,-0.0034804402384907,0.00126365839969367,,,,0.145024206455211,39.995735168457,1.97402352828895,2.98750829696655,3.00114822387695,3.00122117996216,-134227.40625,-134121.28125,0.0956643521785736,1,6,3,4,23.1730000402331,1,20.6610089210972,1.1138916015625,43.9882698059082,40.0782012939453,,,,,,,,,,,,,,,,
,3875420619.69558,3.00093922615051,-139999.609375,,,,,,,,,,,,,-0.61832082422071,3.03548787948808E-5,0.00284327893382527,10,2,,80,2,4212,,,-0.603384758068053,-0.00956424915306323,-0.00362856616266072,0.00131774775218219,,,,0.151199905726655,39.995735168457,1.97396081995053,2.98423528671265,3.00083446502686,3.00106453895569,-139999.625,-139999.59375,0.0955283418297768,1,4,3,4,23.1730000402331,1,20.6612422841658,1.11366271972656,43.9882698059082,39.5894432067871,,,,,,,,,,,,,,,,
,3875420761.15098,2.99935302734375,-137850.4375,,,,,,,,,,,,,-0.609382973020803,3.54693982660372E-5,0.00270876538282554,10,2,,80,2,4281,,,-0.594490216055439,-0.00944463605797385,-0.00357492873445153,0.0012983923079446,,,,0.148966042339414,39.995735168457,1.97389817489479,2.98340964317322,2.99932098388672,2.99942421913147,-137900.078125,-137800.796875,0.0955495983362198,1,6,3,4,23.1730000402331,1,20.6609313483781,1.11228942871094,44.4770278930664,40.0782012939453,,,,,,,,,,,,,,,,
,3875420902.62791,2.9987847328186,-130836.6484375,,,,,,,,,,,,,-0.579534672030417,3.19826634095377E-5,0.00234401572914531,10,2,,80,2,4350,,,-0.56483736428793,-0.00896414044335986,-0.0033966179471463,0.00123363325838,,,,0.141535513652144,39.995735168457,1.97390196979353,2.98632907867432,2.9987256526947,2.99885368347168,-130886.15625,-130787.140625,0.0957320332527161,1,6,3,4,23.1730000402331,1,20.6619197322292,1.11595153808594,44.4770278930664,40.0782012939453,,,,,,,,,,,,,,,,
,3875421044.09355,2.9990674495697,-123823,,,,,,,,,,,,,-0.54901826129151,2.68530107061839E-5,0.0020480687696208,10,2,,80,2,4419,,,-0.534592380102332,-0.00840071605393811,-0.00321498163975775,0.00116703589446843,,,,0.133959443930335,39.995735168457,1.97393129339631,2.98976564407349,2.99888634681702,2.99920344352722,-123872.5546875,-123773.4453125,0.0959206819534302,1,6,3,4,23.1730000402331,1,20.6609700872018,1.11152648925781,43.49951171875,40.5669593811035,,,,,,,,,,,,,,,,
,3875421185.56212,2.99906973838806,-116811.890625,,,,,,,,,,,,,-0.517919679518194,3.2723535851551E-5,0.00172753984768061,10,2,,80,2,4488,,,-0.50384094654285,-0.00785239296244142,-0.00303009175695479,0.00109968497417867,,,,0.126253144695386,39.995735168457,1.97391555347721,2.99253273010254,2.99898242950439,2.99921774864197,-116863.9765625,-116759.8046875,0.0960632041096687,1,6,3,4,23.1730000402331,1,20.6644262920705,1.11114501953125,43.9882698059082,40.0782012939453,,,,,,,,,,,,,,,,
,3875421327.0372,2.99956021308899,-109797.51171875,,,,,,,,,,,,,-0.486112293749655,3.07170872199673E-5,0.00136185784858016,10,2,,80,2,4557,,,-0.472462331874759,-0.00734232146267635,-0.00284154200926423,0.00103118258994073,,,,0.118395560586612,39.995735168457,1.9740144526022,2.9942946434021,2.99944710731506,2.99968075752258,-109849.625,-109745.3984375,0.0960909947752953,1,6,3,4,23.1730000402331,1,20.6656641168909,1.11053466796875,44.4770278930664,40.0782012939453,,,,,,,,,,,,,,,,
,3875421468.48311,2.99985504150391,-102784.28515625,,,,,,,,,,,,,-0.453653435149274,2.85760795296948E-5,0.0011095948679551,10,2,,80,2,4626,,,-0.440518152903829,-0.00672399132873888,-0.00264969165436923,0.000960763893090189,,,,0.110391399185651,39.995735168457,1.9740358826171,2.99574828147888,2.99978756904602,2.99997138977051,-102833.9296875,-102734.640625,0.0961697921156883,1,6,3,4,23.1730000402331,1,20.6662837376018,1.11625671386719,44.4770278930664,40.0782012939453,,,,,,,,,,,,,,,,
,3875421609.96442,3.00015532970428,-95770.76953125,,,,,,,,,,,,,-0.420181716669705,2.45627363207803E-5,0.00081549244903883,10,2,,80,2,4695,,,-0.407656965314873,-0.00614901890576339,-0.00245230784639716,0.000888665206730366,,,,0.102160300133012,39.995735168457,1.9741279777672,2.9964759349823,3.00000858306885,3.00025463104248,-95822.65625,-95718.8828125,0.0961236953735352,1,6,3,4,23.1730000402331,1,20.6656841345562,1.11190795898438,44.4770278930664,40.5669593811035,,,,,,,,,,,,,,,,
,3875421751.41922,3.00018920898438,-88755.2890625,,,,,,,,,,,,,-0.385461026574301,2.07365459084142E-5,0.000570511685969742,10,2,,80,2,4764,,,-0.373653534709674,-0.00553316166424338,-0.00224792817607522,0.000813994964119047,,,,0.0936377686367662,39.995735168457,1.97411602777372,2.99634432792664,3.00011563301086,3.00025296211243,-88807.2890625,-88703.2890625,0.0962380319833756,1,6,3,4,23.1730000402331,1,20.6677840495387,1.11526489257812,44.4770278930664,40.0782012939453,,,,,,,,,,,,,,,,
,3875421892.90735,3.00041456222534,-81738.9765625,,,,,,,,,,,,,-0.349584510361074,2.20326918424406E-5,0.000387323725992533,10,2,,80,2,4833,,,-0.338600099463137,-0.00487439431040343,-0.0020373691804707,0.000736831862013787,,,,0.0848552212930918,39.995735168457,1.97415942557769,2.99573183059692,3.00040102005005,3.00045275688171,-81791.0390625,-81686.9140625,0.0961574986577034,1,6,3,4,23.1730000402331,1,20.6685939013957,1.10923767089844,44.4770278930664,40.0782012939453,,,,,,,,,,,,,,,,
,3875422034.36017,3.00031552314758,-74724.35546875,,,,,,,,,,,,,-0.317620999550212,1.4600693373629E-5,0.000262948252663829,10,2,,80,2,4902,,,-0.307402921660479,-0.0042564888295496,-0.00184992235153914,0.000668036052957177,,,,0.0770344759714232,39.995735168457,1.97411699622159,2.99475526809692,3.00019598007202,3.00041174888611,-74773.9296875,-74674.78125,0.0961779281497002,1,6,3,4,23.1730000402331,1,20.6725437537083,1.11602783203125,44.4770278930664,40.5669593811035,,,,,,,,,,,,,,,,
,3875422175.82388,3.00066828727722,-67710.37890625,,,,,,,,,,,,,-0.289500535979546,2.04484673696257E-5,0.000147860945340699,10,2,,80,2,4971,,,-0.279982415215526,-0.00372219856335652,-0.00168526801280677,0.000607601075898856,,,,0.0701657600791683,39.995735168457,1.97418999632927,2.99276804924011,3.00060820579529,3.00071859359741,-67762.890625,-67657.8671875,0.0961765646934509,1,6,3,4,23.1730000402331,1,20.6748265080158,1.11602783203125,44.4770278930664,40.5669593811035,,,,,,,,,,,,,,,,
,3875422317.30493,3.00054445266724,-60693.6875,,,,,,,,,,,,,-0.262357653366789,1.86756102447184E-5,6.46736580521115E-5,10,2,,80,2,5040,,,-0.253558817063843,-0.00320857538651456,-0.00152659078594297,0.000549372984096408,,,,0.0635459827143108,39.995735168457,1.97426845930008,2.99131989479065,3.00044202804565,3.00062918663025,-60745.8203125,-60641.5546875,0.0960166454315186,1,6,3,4,23.1730000402331,1,20.6776464885579,1.11106872558594,45.4545478820801,40.0782012939453,,,,,,,,,,,,,,,,
,3875422458.77264,3.00060474872589,-53676.41796875,,,,,,,,,,,,,-0.235889982689384,1.83236084866085E-5,9.78046959103684E-6,10,2,,80,2,5109,,,-0.227835184889005,-0.00271723496026977,-0.0013720472343266,0.000492647930514067,,,,0.057097742376815,39.995735168457,1.97425184869915,2.98965716361999,3.00052928924561,3.00067210197449,-53728.5,-53624.3359375,0.0960330367088318,1,6,3,4,23.1730000402331,1,20.6783091517139,1.11305236816406,44.4770278930664,40.5669593811035,,,,,,,,,,,,,,,,
,3875422600.25417,3.00039792060852,-46661.0859375,,,,,,,,,,,,,-0.209907979778999,1.76777823108396E-5,-1.39238428714478E-5,10,2,,80,2,5178,,,-0.202623989885419,-0.00224521216480481,-0.00122061127331108,0.000437109614722431,,,,0.0507803779172683,39.995735168457,1.97430265287575,2.98803496360779,3.00025463104248,3.00059199333191,-46710.67578125,-46611.49609375,0.0961020439863205,1,6,3,4,23.1730000402331,1,20.6783554045524,1.11587524414062,43.49951171875,40.5669593811035,,,,,,,,,,,,,,,,
,3875422741.71585,2.99987297058105,-39644.91015625,,,,,,,,,,,,,-0.184181710098148,1.89704501440433E-5,-3.20995624321012E-6,10,2,,80,2,5247,,,-0.177698781240066,-0.00178875496303586,-0.00107079790905118,0.000382377183996141,,,,0.0445332375512762,39.995735168457,1.97431158185137,2.98777008056641,2.99982166290283,2.99996066093445,-39694.35546875,-39595.46484375,0.096039392054081,1,6,3,4,23.1730000402331,1,20.6850856416718,1.11221313476562,44.4770278930664,40.5669593811035,,,,,,,,,,,,,,,,
,3875422883.18178,2.99947295188904,-32597.1201171875,,,,,,,,,,,,,-0.158515246076656,1.29463475218117E-5,1.87732365007558E-5,10,2,,80,2,5316,,,-0.152865651504269,-0.00136948637928992,-0.000921542814467102,0.000327941263094544,,,,0.0383107553517705,39.995735168457,1.97439323659027,2.98828911781311,2.99937582015991,2.99958443641663,-32649.533203125,-32544.70703125,0.0960512906312942,1,6,3,4,23.1730000402331,1,20.685779147836,1.11244201660156,44.9657897949219,40.5669593811035,,,,,,,,,,,,,,,,
,3875423024.65426,2.99904274940491,-25540.6279296875,,,,,,,,,,,,,-0.132555616068583,1.49087043363223E-5,4.68661148469299E-5,10,2,,80,2,5385,,,-0.127780345787966,-0.000991797593866216,-0.000770647078752518,0.000273226760327816,,,,0.0320247700726686,39.995735168457,1.97443755298137,2.99045562744141,2.99900531768799,2.99910140037537,-25593.041015625,-25488.21484375,0.0961426869034767,1,6,3,4,23.1730000402331,1,20.687245959485,1.11114501953125,44.4770278930664,40.5669593811035,,,,,,,,,,,,,,,,
,3875423166.10073,2.99849939346313,-18487.18359375,,,,,,,,,,,,,-0.106631796302172,1.32521704330015E-5,9.86791657180161E-5,10,2,,80,2,5454,,,-0.102755942426913,-0.000642787298185905,-0.000620045932009816,0.000218822751776315,,,,0.0257535543350778,39.995735168457,1.97447341597705,2.99382615089417,2.99844765663147,2.99852633476257,-18537.025390625,-18437.341796875,0.096190333366394,1,6,3,4,23.1730000402331,1,20.690628333142,1.11297607421875,44.4770278930664,41.055721282959,,,,,,,,,,,,,,,,
,3875423307.57469,2.99865703582764,-11432.7412109375,,,,,,,,,,,,,-0.0811091583081889,1.18165677754768E-5,0.000110798239860273,10,2,,80,2,5523,,,-0.0781393912470847,-0.000385294013894363,-0.000471738836495206,0.000165781631949358,,,,0.0195842451158398,39.995735168457,1.97454584350325,2.99793100357056,2.99857425689697,2.99880266189575,-11485.0771484375,-11380.4052734375,0.0963611751794815,1,6,3,4,23.1730000402331,1,20.6907201581747,1.11190795898438,44.4770278930664,40.5669593811035,,,,,,,,,,,,,,,,
,3875423449.11367,2.99963369369507,-4366.24145507812,,,,,,,,,,,,,-0.0557225155130984,1.13729064470278E-5,0.000133891815804879,1,2,,80,2,5592,,,-0.0536709572018319,-0.000166596051317674,-0.000324224238283932,0.000113273446913809,,,,0.01345060369067,39.995735168457,1.97453949692479,3.00092673301697,2.999347448349,2.99978947639465,-4416.287109375,-4316.19580078125,0.0964723229408264,1,6,3,4,23.1730000402331,1,20.6903108710286,1.11526489257812,44.4770278930664,40.5669593811035,,,,,,,,,,,,,,,,
,3875423590.56678,3.00083470344543,2704.07348632813,,,,,,,,,,,,,-0.0300100269701407,1.15903183585873E-5,7.64885200803333E-5,1,2,,80,2,5661,,,-0.0289039931106263,-8.08669312813339E-5,-0.000174618151504546,6.0950933402637E-5,,,,0.00724365140613684,39.995735168457,1.97446144727736,3.00053477287292,3.00070929527283,3.00093078613281,2654.09375,2754.05322265625,0.0964412465691566,1,6,3,4,23.1730000402331,1,20.6917745479533,1.11457824707031,44.9657897949219,40.5669593811035,,,,,,,,,,,,,,,,
,3875423732.04502,3.00137358903885,9778.35693359375,,,,,,,,,,,,,-0.000622062460643613,1.63158817320981E-5,6.90479500635656E-7,1,2,,80,2,5730,,,-0.000599251117067697,-2.99074848086165E-6,-3.61752177013841E-6,1.27164457808249E-6,,,,0.000150299381925539,39.995735168457,1.97447017687221,2.9979350566864,3.00129985809326,3.00143027305603,9725.873046875,9830.8408203125,0.0964523702859879,1,6,3,4,23.1730000402331,1,20.6922298381454,1.11221313476562,44.9657897949219,40.5669593811035,,,,,,,,,,,,,,,,
,3875423873.49917,3.00144305229187,16851.759765625,,,,,,,,,,,,,0.0451994291950568,2.34135583187454E-5,-6.516177390447E-5,1,2,,80,2,5799,,,0.0435536191411327,0.000240794628916578,0.000262868124991655,-9.25699205254205E-5,,,,0.0109150039603059,39.995735168457,1.97445054045203,2.99441933631897,3.0012640953064,3.00159955024719,16801.583984375,16901.935546875,0.0962074026465416,1,6,3,4,23.1730000402331,1,20.6935211400914,1.11328125,44.4770278930664,40.5669593811035,,,,,,,,,,,,,,,,
,3875424014.96119,3.00135487318039,23937.4228515625,,,,,,,,,,,,,0.0935937770526427,2.17627357351583E-5,-9.32517124384935E-5,1,2,,80,2,5868,,,0.0902151074191565,0.000622797997690137,0.000544257462024689,-0.000192501975107007,,,,0.022609732224431,39.995735168457,1.97453450794721,2.9904568195343,3.00120186805725,3.00156760215759,23884.75,23990.095703125,0.096082791686058,1,6,3,4,23.1730000402331,1,20.6933735919246,1.11610412597656,44.4770278930664,38.6119270324707,,,,,,,,,,,,,,,,
,3875424156.45018,3.00080065727234,31035.3203125,,,,,,,,,,,,,0.133330780856406,1.70530592404568E-5,-9.94381590292677E-5,1,2,,80,2,5937,,,0.128567436720125,0.0010435839027711,0.000775270920712501,-0.000275326980045065,,,,0.032221448903533,39.995735168457,1.97448953395836,2.98781704902649,3.00067782402039,3.00094151496887,30985.142578125,31085.498046875,0.0959815382957459,1,6,3,4,23.1730000402331,1,20.6971428393192,1.11602783203125,43.9882698059082,40.5669593811035,,,,,,,,,,,,,,,,
,3875424299.98888,3.00020589828491,38231.63671875,,,,,,,,,,,,,0.167871189126502,1.63514696891383E-5,-6.38097599192074E-7,10,2,,80,2,6007,,,0.161946700182264,0.00159516326815415,0.00097596162231639,-0.000348507513990626,,,,0.0405893246700913,39.995735168457,1.97448807941145,2.98633909225464,3.00005698204041,3.00027966499329,38181.4296875,38281.84375,0.0957384407520294,1,6,3,4,23.1730000402331,1,20.6972660244522,1.11061096191406,44.4770278930664,40.5669593811035,,,,,,,,,,,,,,,,
,3875424441.46156,2.99989566802978,45326.0625,,,,,,,,,,,,,0.198712562945177,1.99913896331835E-5,1.81486393105049E-5,10,2,,80,2,6076,,,0.19179732092586,0.00209492405138673,0.00115541787818074,-0.000413999456213787,,,,0.0480709377951985,39.995735168457,1.97448390313205,2.98639059066772,2.99978399276733,3.00005149841309,45276.09375,45376.03125,0.0957206711173058,1,6,3,4,23.1730000402331,1,20.6977869900857,1.11297607421875,44.4770278930664,40.5669593811035,,,,,,,,,,,,,,,,
,3875424582.9288,2.99953417778015,52422.2421875,,,,,,,,,,,,,0.227663907212724,1.9319941172935E-5,2.14368324196548E-5,10,2,,80,2,6145,,,0.219866228571243,0.0026148239518661,0.0013239603722468,-0.000475949695101008,,,,0.0551039371696636,39.995735168457,1.97438041919192,2.98726439476013,2.99943280220032,2.99965023994446,52372.04296875,52472.44140625,0.0957614183425903,1,6,3,4,23.1730000402331,1,20.701994794404,1.11480712890625,44.4770278930664,40.5669593811035,,,,,,,,,,,,,,,,
,3875424724.39327,2.99925379753113,59515.126953125,,,,,,,,,,,,,0.255760830430542,1.9745651964606E-5,-1.6035672120779E-5,10,2,,80,2,6214,,,0.247155690687442,0.00313470263379108,0.0014879684895277,-0.000536284293048084,,,,0.0619478956518426,39.995735168457,1.97452171831352,2.98885679244995,2.99914264678955,2.99935102462769,59462.5234375,59567.73046875,0.0958532840013504,1,6,3,4,23.1730000402331,1,20.7036070511335,1.11198425292969,44.4770278930664,40.5669593811035,,,,,,,,,,,,,,,,
,3875424865.84983,2.99947290420532,66610.16015625,,,,,,,,,,,,,0.283899455164365,2.13095571297181E-5,-8.68670971308947E-5,10,2,,80,2,6283,,,0.274534594271516,0.0036676513162797,0.00165233283769339,-0.000596755999140441,,,,0.068807468896373,39.995735168457,1.97441437644368,2.99087405204773,2.99940824508667,2.99953436851501,66557.609375,66662.7109375,0.0958750322461128,1,6,3,4,23.1730000402331,1,20.7026745197702,1.11648559570312,44.9657897949219,40.5669593811035,,,,,,,,,,,,,,,,
,3875425007.31838,2.99947810173035,73703.80078125,,,,,,,,,,,,,0.312661715248144,1.95061650565708E-5,-0.000212070244258305,10,2,,80,2,6352,,,0.302569695844497,0.00419728202487324,0.0018207737011835,-0.000658663106150925,,,,0.0758363015603477,39.995735168457,1.97445569201406,2.99290299415588,2.99935293197632,2.99959349632263,73653.6328125,73753.96875,0.0958609208464622,1,6,3,4,23.1730000402331,1,20.7031755259928,1.11640930175781,44.4770278930664,39.1006851196289,,,,,,,,,,,,,,,,
,3875425148.81028,2.9993510723114,80840.40234375,,,,,,,,,,,,,0.342969705406355,2.59106578471179E-5,-0.000364054489803774,10,2,,80,2,6421,,,0.332159399315928,0.00476263311834792,0.00199850415810943,-0.000723985489457846,,,,0.0832526730058751,39.995735168457,1.97444010653099,2.9941098690033,2.99922800064087,2.99952220916748,80789.640625,80891.1640625,0.0960114002227783,1,6,3,4,23.1730000402331,1,20.702536568511,1.11610412597656,43.9882698059082,40.5669593811035,,,,,,,,,,,,,,,,
,3875425290.25785,2.9996777176857,88011.60546875,,,,,,,,,,,,,0.378331588930477,2.3992427178341E-5,-0.000513644331475031,10,2,,80,2,6490,,,0.366709711239673,0.00544555468268215,0.00220598606392741,-0.000800309702754021,,,,0.0919117575830324,39.995735168457,1.97440215558665,2.99570465087891,2.99962735176086,2.99970388412476,87958.359375,88064.8515625,0.0959001034498215,1,6,3,4,23.1730000402331,1,20.6998962622021,1.11434936523438,44.4770278930664,41.055721282959,,,,,,,,,,,,,,,,
,3875425431.74517,2.99955320358276,95186.5,,,,,,,,,,,,,0.414095290351099,2.81015121564519E-5,-0.000725918408473167,10,2,,80,2,6559,,,0.40172203692562,0.00611108482665972,0.00241621863096952,-0.000877389684319496,,,,0.10068130978176,39.995735168457,1.97428365432275,2.9959774017334,2.99893951416016,3.00007295608521,95133.265625,95239.734375,0.0958826020359993,1,6,3,4,23.1730000402331,1,20.6960995121726,1.11709594726562,43.9882698059082,40.0782012939453,,,,,,,,,,,,,,,,
,3875425573.19376,3.0001237988472,102357.80859375,,,,,,,,,,,,,0.448989239079144,2.97948967823035E-5,-0.0010233997948121,10,2,,80,2,6628,,,0.435964329381115,0.00670960170511314,0.00262207444757223,-0.000952607777435332,,,,0.109264117734115,39.995735168457,1.97431672649817,2.99636626243591,2.99998545646667,3.00019955635071,102307.109375,102408.5078125,0.0958103388547897,1,6,3,4,23.1730000402331,1,20.6949103823651,1.11625671386719,44.4770278930664,40.0782012939453,,,,,,,,,,,,,,,,
,3875425714.6541,3.00023741722107,109533.015625,,,,,,,,,,,,,0.482967235628457,2.79337721319816E-5,-0.00131916983248614,10,2,,80,2,6697,,,0.469388990467237,0.00731675356310657,0.00282306829467416,-0.00102608453016728,,,,0.117645820754063,39.995735168457,1.97438915088059,2.99572610855103,3.00011229515076,3.00037264823914,109482.2421875,109583.7890625,0.0958774760365486,1,6,3,4,23.1730000402331,1,20.6917515803918,1.11083984375,43.9882698059082,40.5669593811035,,,,,,,,,,,,,,,,
,3875425856.11237,3.00079879760742,116705.1171875,,,,,,,,,,,,,0.516137103531453,3.45563993591308E-5,-0.00163994028915337,10,2,,80,2,6766,,,0.502098297314019,0.00790046656428026,0.00301929260604084,-0.00109799986239523,,,,0.125831752057241,39.995735168457,1.97417720769356,2.9942512512207,3.00073075294495,3.00089502334595,116651.8828125,116758.3515625,0.0957494005560875,1,6,3,4,23.1730000402331,1,20.6932964027331,1.11587524414062,44.4770278930664,40.0782012939453,,,,,,,,,,,,,,,,
,3875425997.60705,3.0009407043457,123879.5546875,,,,,,,,,,,,,0.548472324400117,3.40844695431474E-5,-0.00200234969108644,10,2,,80,2,6835,,,0.534063966290275,0.00843709789700517,0.00321151362732053,-0.00116770132444799,,,,0.133841174313649,39.995735168457,1.97413458750902,2.99196410179138,3.00085067749023,3.00101804733276,123826.3203125,123932.7890625,0.0956755504012108,1,6,3,4,23.1730000402331,1,20.6865056084954,1.11251831054688,44.4770278930664,40.0782012939453,,,,,,,,,,,,,,,,
,3875426139.06666,3.00121355056763,131052.48046875,,,,,,,,,,,,,0.580102326282923,3.09931380828953E-5,-0.002382749560724,10,2,,80,2,6904,,,0.565407614215159,0.00894537127957037,0.00339992623776197,-0.00123625306878239,,,,0.141694417828705,39.995735168457,1.97410223637312,2.9887113571167,3.00110030174255,3.00128746032715,131001.8984375,131103.0625,0.0955232307314873,1,6,3,4,23.1730000402331,1,20.685850510518,1.11190795898438,43.9882698059082,40.0782012939453,,,,,,,,,,,,,,,,
,3875426280.54047,3.0013599395752,138226.8359375,,,,,,,,,,,,,0.610977475881068,3.44660794177252E-5,-0.00275628987384589,10,2,,80,2,6973,,,0.596076534661142,0.0094428405590794,0.00358434044755995,-0.0013032415881753,,,,0.149379670942685,39.995735168457,1.97408665492466,2.98566770553589,3.00129270553589,3.00144815444946,138176.140625,138277.53125,0.0953057259321213,1,6,3,4,23.1730000402331,1,20.6837320034309,1.11656188964844,43.9882698059082,41.055721282959,,,,,,,,,,,,,,,,
,3875426422.00813,3.00014600753784,140000.453125,,,,,,,,,,,,,0.618458718393279,3.16444518991149E-5,-0.00278915865128107,10,2,,80,2,7042,,,0.603518296592648,0.00961983714332598,0.00362900621257722,-0.00131975288968533,,,,0.151243582297387,39.995735168457,1.97408567136299,2.98326110839844,3.00002503395081,3.00025296211243,140000.453125,140000.453125,0.0953546836972237,1,4,3,4,23.1730000402331,1,20.681902886985,1.11236572265625,44.4770278930664,40.0782012939453,,,,,,,,,,,,,,,,
,3875426436.3635,2.9998507976532,140000.5703125,,,,,,,,,,,,,0.618489955010903,2.93182411042386E-5,-0.00284386500082676,10,2,,80,2,7049,,,0.603549876875953,0.00956708454601821,0.00362927722744644,-0.00131963740568608,,,,0.151252425463446,39.995735168457,1.97409539369725,2.98310089111328,2.99973082542419,2.99998545646667,140000.53125,140000.609375,0.0952650085091591,1,4,3,4,23.1730000402331,1,20.6839727899766,1.11259460449219,44.4770278930664,42.0332374572754,,,,,,,,,,,,,,,,