File: MPMS/NiCl2btd/NiCl2btd-d4_2-300K_FC.rso.dat
[Header]
TITLE,MPMS RSO Measurement
BYAPP,MPMS Measurement,1.1,Summary
FILEOPENTIME, 1666827622.280000 10/27/2022, 12:40:22 AM

INFO, APPNAME, MPMS MultiVu Application, Revision 1.61,  Build 082

INFO, NAME, NiCl2btd-d4_tefeyo
INFO, WEIGHT, 8.630
INFO, AREA, 1.000
INFO, LENGTH, 1.000
INFO, SHAPE, -
INFO, COMMENT, evioseme9.22mg
INFO, SEQUENCE FILE: JP_ZFC_MH_FC_221026_NiCl2btd-d4_tefeyo.seq


INFO, BACKGROUND DATA FILE:, None


STARTUPAXIS,X,4,LINEAR,AUTO,0.000000,0.000000
STARTUPAXIS,Y1,5,LINEAR,AUTO,0.000000,0.000000


STARTUPGROUP,Longitudinal
FIELDGROUP,Longitudinal,1,2,3,4,5,6,7,8,9,10,11,19,20,21,22,23,35
FIELDGROUP,Transverse,1,2,3,4,12,13,14,15,16,17,18,24,25,26,27,28,35

PLOT_APPEARANCE,ALL,HORZ_GRID_ON,VERT_GRID_ON,MARKERS_AND_LINES

[Data]
Time,Comment,Field (Oe),Temperature (K),Long Moment (emu),Long Scan Std Dev,Long Offset (cm),Long Offset Std Dev,Long Algorithm,Long Reg Fit,Long Reg Factor,Trans Moment (emu),Trans Scan Std Dev,Trans Offset (cm),Trans Offset Std Dev,Trans Algorithm,Trans Reg Fit,Trans Reg Factor,Long Moment [w/o ABS] (emu),Long Scan Std Dev [w/o ABS],Long Offset [w/o ABS] (cm),Long Offset Std Dev [w/o ABS],Long Reg Fit [w/o ABS],Trans Moment [w/o ABS] (emu),Trans Scan Std Dev [w/o ABS],Trans Offset [w/o ABS] (cm),Trans Offset Std Dev [w/o ABS],Trans Reg Fit [w/o ABS],RSO Position (deg),Amplitude (cm),Frequency,Cycles to Average,Scans per Measurement,Delta Temp (K),Error,EC Comp. Running,Using ABS,
1666827622.280,,1.000000e+002,3.000058e+002,1.485921e-005,1.814318e-008,1.709956e-001,4.390347e-004,3,9.121954e-001,1.825000e+000,,,,,,,,,,,,,,,,,,0,5.000000e+000,1.000000e+000,4,4,9.887695e-003,0,,0,
1666828128.033,,1.000000e+002,2.902625e+002,1.548160e-005,1.497852e-008,1.685393e-001,3.297548e-004,3,9.159577e-001,1.825000e+000,,,,,,,,,,,,,,,,,,0,5.000000e+000,1.000000e+000,4,4,8.297729e-002,0,,0,
1666828367.462,,1.000000e+002,2.794575e+002,1.620132e-005,1.473250e-008,1.568756e-001,5.880866e-004,3,9.197829e-001,1.825000e+000,,,,,,,,,,,,,,,,,,0,5.000000e+000,1.000000e+000,4,4,3.400879e-001,0,,0,
1666828584.381,,1.000000e+002,2.695822e+002,1.689145e-005,1.159784e-008,1.469350e-001,4.977086e-004,3,9.230331e-001,1.825000e+000,,,,,,,,,,,,,,,,,,0,5.000000e+000,1.000000e+000,4,4,2.911072e-001,0,,0,
1666828802.469,,1.000000e+002,2.595654e+002,1.766503e-005,1.478028e-008,1.378073e-001,1.379279e-004,3,9.260323e-001,1.825000e+000,,,,,,,,,,,,,,,,,,0,5.000000e+000,1.000000e+000,4,4,2.539978e-001,0,,0,
1666829021.743,,1.000000e+002,2.495991e+002,1.847871e-005,8.648624e-009,1.292327e-001,3.008395e-004,3,9.290545e-001,1.825000e+000,,,,,,,,,,,,,,,,,,0,5.000000e+000,1.000000e+000,4,4,2.546082e-001,0,,0,
1666829241.313,,1.000000e+002,2.396095e+002,1.937051e-005,1.097883e-008,1.214000e-001,1.425766e-004,3,9.322759e-001,1.825000e+000,,,,,,,,,,,,,,,,,,0,5.000000e+000,1.000000e+000,4,4,2.279968e-001,0,,0,
1666829461.804,,1.000000e+002,2.295911e+002,2.037711e-005,1.128818e-008,1.144628e-001,4.208022e-004,3,9.353523e-001,1.825000e+000,,,,,,,,,,,,,,,,,,0,5.000000e+000,1.000000e+000,4,4,2.485962e-001,0,,0,
1666829685.103,,1.000000e+002,2.196152e+002,2.144737e-005,2.503414e-009,1.073167e-001,2.030328e-004,3,9.382646e-001,1.825000e+000,,,,,,,,,,,,,,,,,,0,5.000000e+000,1.000000e+000,4,4,2.323914e-001,0,,0,
1666829908.932,,1.000000e+002,2.096171e+002,2.262266e-005,9.591703e-009,1.004697e-001,1.050645e-004,3,9.411623e-001,1.825000e+000,,,,,,,,,,,,,,,,,,0,5.000000e+000,1.000000e+000,4,4,2.301025e-001,0,,0,
1666830135.710,,1.000000e+002,1.996242e+002,2.394547e-005,2.244660e-008,9.377304e-002,4.193095e-004,3,9.444140e-001,1.825000e+000,,,,,,,,,,,,,,,,,,0,5.000000e+000,1.000000e+000,4,4,2.298889e-001,0,,0,
1666830367.479,,1.000000e+002,1.896605e+002,2.539730e-005,1.285092e-008,8.743062e-002,4.908529e-004,3,9.470180e-001,1.825000e+000,,,,,,,,,,,,,,,,,,0,5.000000e+000,1.000000e+000,4,4,2.498932e-001,0,,0,
1666830603.274,,1.000000e+002,1.796803e+002,2.703331e-005,5.328719e-009,8.133798e-002,2.941498e-004,3,9.498271e-001,1.825000e+000,,,,,,,,,,,,,,,,,,0,5.000000e+000,1.000000e+000,4,4,2.452087e-001,0,,0,
1666830844.559,,1.000000e+002,1.697422e+002,2.886260e-005,2.427656e-008,7.568986e-002,2.599683e-004,3,9.521878e-001,1.825000e+000,,,,,,,,,,,,,,,,,,0,5.000000e+000,1.000000e+000,4,4,2.317047e-001,0,,0,
1666831093.317,,1.000000e+002,1.597782e+002,3.093519e-005,1.174242e-008,6.986459e-002,2.129784e-004,3,9.549090e-001,1.825000e+000,,,,,,,,,,,,,,,,,,0,5.000000e+000,1.000000e+000,4,4,2.415924e-001,0,,0,
1666831352.122,,1.000000e+002,1.498614e+002,3.327563e-005,7.824094e-009,6.445178e-002,2.921230e-004,3,9.574702e-001,1.825000e+000,,,,,,,,,,,,,,,,,,0,5.000000e+000,1.000000e+000,4,4,2.185059e-001,0,,0,
1666831615.949,,1.000000e+002,1.399136e+002,3.596285e-005,1.078154e-008,5.955736e-002,9.036166e-005,3,9.600176e-001,1.825000e+000,,,,,,,,,,,,,,,,,,0,5.000000e+000,1.000000e+000,4,4,1.786957e-001,0,,0,
1666831882.975,,1.000000e+002,1.299636e+002,3.907509e-005,2.263588e-008,5.457130e-002,3.449791e-005,3,9.624835e-001,1.825000e+000,,,,,,,,,,,,,,,,,,0,5.000000e+000,1.000000e+000,4,4,1.662903e-001,0,,0,
1666832150.266,,1.000000e+002,1.199883e+002,4.274402e-005,8.601831e-009,4.991689e-002,1.897519e-004,3,9.649493e-001,1.825000e+000,,,,,,,,,,,,,,,,,,0,5.000000e+000,1.000000e+000,4,4,1.396942e-001,0,,0,
1666832553.059,,1.000000e+002,1.100694e+002,4.700812e-005,1.222281e-008,4.519276e-002,1.780764e-004,3,9.672233e-001,1.825000e+000,,,,,,,,,,,,,,,,,,0,5.000000e+000,1.000000e+000,4,4,2.160645e-002,0,,0,
1666832863.296,,1.000000e+002,9.994860e+001,5.230531e-005,1.864921e-008,4.114225e-002,8.830756e-005,3,9.696282e-001,1.825000e+000,,,,,,,,,,,,,,,,,,0,5.000000e+000,1.000000e+000,4,4,1.308441e-001,0,,0,
1666833086.346,,1.000000e+002,9.493379e+001,5.534226e-005,4.495310e-008,3.876299e-002,1.918799e-004,3,9.708130e-001,1.825000e+000,,,,,,,,,,,,,,,,,,0,5.000000e+000,1.000000e+000,4,4,1.922226e-001,0,,0,
1666833305.620,,1.000000e+002,8.995649e+001,5.866215e-005,4.295530e-008,3.678200e-002,6.047691e-005,3,9.719979e-001,1.825000e+000,,,,,,,,,,,,,,,,,,0,5.000000e+000,1.000000e+000,4,4,1.788254e-001,0,,0,
1666833644.031,,1.000000e+002,8.506782e+001,6.224011e-005,2.887042e-008,3.449089e-002,1.799990e-004,3,9.728150e-001,1.825000e+000,,,,,,,,,,,,,,,,,,0,5.000000e+000,1.000000e+000,4,4,1.992035e-002,0,,0,
1666833976.546,,1.000000e+002,8.006877e+001,6.636131e-005,1.024988e-008,3.266568e-002,1.034404e-004,3,9.739367e-001,1.825000e+000,,,,,,,,,,,,,,,,,,0,5.000000e+000,1.000000e+000,4,4,1.929474e-002,0,,0,
1666834296.331,,1.000000e+002,7.507024e+001,7.097884e-005,2.388080e-008,3.061653e-002,1.765869e-004,3,9.749783e-001,1.825000e+000,,,,,,,,,,,,,,,,,,0,5.000000e+000,1.000000e+000,4,4,2.497101e-002,0,,0,
1666834537.647,,1.000000e+002,7.009806e+001,7.628996e-005,1.489687e-008,2.880170e-002,1.546412e-004,3,9.760646e-001,1.825000e+000,,,,,,,,,,,,,,,,,,0,5.000000e+000,1.000000e+000,4,4,6.896973e-003,0,,0,
1666834779.229,,1.000000e+002,6.509145e+001,8.224754e-005,1.564594e-008,2.692865e-002,1.343967e-004,3,9.770986e-001,1.825000e+000,,,,,,,,,,,,,,,,,,0,5.000000e+000,1.000000e+000,4,4,1.399994e-002,0,,0,
1666835003.636,,1.000000e+002,6.009237e+001,8.901236e-005,1.463545e-008,2.514051e-002,1.384132e-004,3,9.780312e-001,1.825000e+000,,,,,,,,,,,,,,,,,,0,5.000000e+000,1.000000e+000,4,4,5.149841e-003,0,,0,
1666835220.523,,1.000000e+002,5.508760e+001,9.677348e-005,2.476415e-008,2.351893e-002,1.244159e-004,3,9.788846e-001,1.825000e+000,,,,,,,,,,,,,,,,,,0,5.000000e+000,1.000000e+000,4,4,1.597977e-002,0,,0,
1666835520.902,,1.000000e+002,5.001838e+001,1.057852e-004,5.648410e-009,2.180197e-002,1.025500e-004,3,9.797572e-001,1.825000e+000,,,,,,,,,,,,,,,,,,0,5.000000e+000,1.000000e+000,4,4,9.719849e-003,0,,0,
1666835714.077,,1.000000e+002,4.806406e+001,1.095905e-004,1.756831e-008,2.118532e-002,6.312383e-005,3,9.800617e-001,1.825000e+000,,,,,,,,,,,,,,,,,,0,5.000000e+000,1.000000e+000,4,4,1.806259e-002,0,,0,
1666835913.632,,1.000000e+002,4.606429e+001,1.137061e-004,2.092321e-008,2.048920e-002,8.072099e-005,3,9.803923e-001,1.825000e+000,,,,,,,,,,,,,,,,,,0,5.000000e+000,1.000000e+000,4,4,3.118896e-002,0,,0,
1666836111.238,,1.000000e+002,4.406206e+001,1.180926e-004,3.412215e-008,1.992418e-002,5.756279e-005,3,9.807441e-001,1.825000e+000,,,,,,,,,,,,,,,,,,0,5.000000e+000,1.000000e+000,4,4,3.435898e-002,0,,0,
1666836314.085,,1.000000e+002,4.205402e+001,1.227576e-004,2.704189e-008,1.937173e-002,4.390019e-005,3,9.810429e-001,1.825000e+000,,,,,,,,,,,,,,,,,,0,5.000000e+000,1.000000e+000,4,4,2.967072e-002,0,,0,
1666836520.941,,1.000000e+002,4.004561e+001,1.276309e-004,4.342895e-008,1.878589e-002,1.524442e-004,3,9.813809e-001,1.825000e+000,,,,,,,,,,,,,,,,,,0,5.000000e+000,1.000000e+000,4,4,2.946854e-002,0,,0,
1666836730.418,,1.000000e+002,3.803983e+001,1.327848e-004,4.360119e-008,1.832362e-002,9.443807e-005,3,9.815982e-001,1.825000e+000,,,,,,,,,,,,,,,,,,0,5.000000e+000,1.000000e+000,4,4,2.603912e-002,0,,0,
1666836942.080,,1.000000e+002,3.603487e+001,1.381671e-004,3.444105e-008,1.771265e-002,1.577867e-004,3,9.818608e-001,1.825000e+000,,,,,,,,,,,,,,,,,,0,5.000000e+000,1.000000e+000,4,4,2.120209e-002,0,,0,
1666837157.953,,1.000000e+002,3.402972e+001,1.438474e-004,3.990560e-008,1.720145e-002,1.104110e-004,3,9.821873e-001,1.825000e+000,,,,,,,,,,,,,,,,,,0,5.000000e+000,1.000000e+000,4,4,1.753998e-002,0,,0,
1666837376.462,,1.000000e+002,3.202635e+001,1.497071e-004,5.766687e-008,1.689604e-002,1.777968e-004,3,9.823987e-001,1.825000e+000,,,,,,,,,,,,,,,,,,0,5.000000e+000,1.000000e+000,4,4,1.824951e-002,0,,0,
1666837597.343,,1.000000e+002,3.002121e+001,1.557376e-004,2.452750e-008,1.636486e-002,5.007977e-005,3,9.826286e-001,1.825000e+000,,,,,,,,,,,,,,,,,,0,5.000000e+000,1.000000e+000,4,4,1.272964e-002,0,,0,
1666837818.614,,1.000000e+002,2.801752e+001,1.619210e-004,2.112751e-008,1.596042e-002,3.535315e-005,3,9.828898e-001,1.825000e+000,,,,,,,,,,,,,,,,,,0,5.000000e+000,1.000000e+000,4,4,1.214981e-002,0,,0,
1666838034.986,,1.000000e+002,2.600845e+001,1.681463e-004,2.658155e-008,1.560301e-002,1.309538e-004,3,9.830460e-001,1.825000e+000,,,,,,,,,,,,,,,,,,0,5.000000e+000,1.000000e+000,4,4,5.281448e-003,0,,0,
1666838229.800,,1.000000e+002,2.498530e+001,1.714074e-004,2.741547e-008,1.544290e-002,8.040136e-005,3,9.830953e-001,1.825000e+000,,,,,,,,,,,,,,,,,,0,5.000000e+000,1.000000e+000,4,4,4.079056e-002,0,,0,
1666838414.083,,1.000000e+002,2.401331e+001,1.745247e-004,6.493277e-008,1.519802e-002,4.461706e-005,3,9.832644e-001,1.825000e+000,,,,,,,,,,,,,,,,,,0,5.000000e+000,1.000000e+000,4,4,3.560066e-002,0,,0,
1666838596.743,,1.000000e+002,2.301021e+001,1.778655e-004,3.964135e-008,1.499517e-002,5.722818e-005,3,9.834073e-001,1.825000e+000,,,,,,,,,,,,,,,,,,0,5.000000e+000,1.000000e+000,4,4,2.865028e-002,0,,0,
1666838777.610,,1.000000e+002,2.200764e+001,1.815479e-004,2.304860e-008,1.492739e-002,1.018049e-004,3,9.834231e-001,1.825000e+000,,,,,,,,,,,,,,,,,,0,5.000000e+000,1.000000e+000,4,4,2.054977e-002,0,,0,
1666838959.974,,1.000000e+002,2.100555e+001,1.861203e-004,2.789868e-008,1.475580e-002,1.062040e-004,3,9.834778e-001,1.825000e+000,,,,,,,,,,,,,,,,,,0,5.000000e+000,1.000000e+000,4,4,1.470947e-002,0,,0,
1666839149.031,,1.000000e+002,2.000004e+001,1.933495e-004,3.749117e-008,1.450870e-002,2.183418e-005,3,9.837446e-001,1.825000e+000,,,,,,,,,,,,,,,,,,0,5.000000e+000,1.000000e+000,4,4,6.401062e-003,0,,0,
1666839355.045,,1.000000e+002,1.950149e+001,1.997753e-004,3.163539e-008,1.443061e-002,3.963489e-005,3,9.838567e-001,1.825000e+000,,,,,,,,,,,,,,,,,,0,5.000000e+000,1.000000e+000,4,4,7.110596e-003,0,,0,
1666839553.945,,1.000000e+002,1.900290e+001,2.118869e-004,8.717412e-008,1.430488e-002,7.186687e-005,3,9.840892e-001,1.825000e+000,,,,,,,,,,,,,,,,,,0,5.000000e+000,1.000000e+000,4,4,6.769180e-003,0,,0,
1666839748.634,,1.000000e+002,1.850341e+001,2.463643e-004,2.587265e-007,1.443180e-002,8.232237e-005,3,9.846501e-001,1.825000e+000,,,,,,,,,,,,,,,,,,0,5.000000e+000,1.000000e+000,4,4,6.881714e-003,0,,0,
1666839945.693,,1.000000e+002,1.800238e+001,4.510821e-004,1.024413e-006,1.551162e-002,1.049772e-004,3,9.859263e-001,1.825000e+000,,,,,,,,,,,,,,,,,,0,5.000000e+000,1.000000e+000,4,4,3.040314e-003,0,,0,
1666840146.871,,1.000000e+002,1.750195e+001,2.753191e-003,6.905155e-006,1.442717e-002,6.755262e-005,3,9.868959e-001,1.825000e+000,,,,,,,,,,,,,,,,,,0,5.000000e+000,1.000000e+000,4,4,2.048492e-003,0,,0,
1666840336.724,,1.000000e+002,1.700284e+001,7.491211e-003,2.250923e-006,1.336914e-002,8.062002e-005,3,9.869869e-001,1.825000e+000,,,,,,,,,,,,,,,,,,0,5.000000e+000,1.000000e+000,4,4,1.550674e-003,0,,0,
1666840532.176,,1.000000e+002,1.650248e+001,9.720610e-003,2.093129e-006,1.348087e-002,4.439328e-005,3,9.871005e-001,1.825000e+000,,,,,,,,,,,,,,,,,,0,5.000000e+000,1.000000e+000,4,4,1.459122e-003,0,,0,
1666840718.097,,1.000000e+002,1.600287e+001,1.100636e-002,1.505210e-006,1.347605e-002,7.630743e-005,3,9.870417e-001,1.825000e+000,,,,,,,,,,,,,,,,,,0,5.000000e+000,1.000000e+000,4,4,2.059937e-003,0,,0,
1666840903.753,,1.000000e+002,1.550288e+001,1.194564e-002,9.951060e-007,1.353895e-002,1.099880e-004,3,9.871503e-001,1.825000e+000,,,,,,,,,,,,,,,,,,0,5.000000e+000,1.000000e+000,4,4,2.249718e-003,0,,0,
1666841088.302,,1.000000e+002,1.500279e+001,1.268042e-002,1.800156e-006,1.343934e-002,1.066239e-004,3,9.871760e-001,1.825000e+000,,,,,,,,,,,,,,,,,,0,5.000000e+000,1.000000e+000,4,4,2.409935e-003,0,,0,
1666841271.306,,1.000000e+002,1.450277e+001,1.326550e-002,1.116049e-006,1.344358e-002,4.844107e-005,3,9.871899e-001,1.825000e+000,,,,,,,,,,,,,,,,,,0,5.000000e+000,1.000000e+000,4,4,1.689911e-003,0,,0,
1666842765.804,,1.000000e+002,1.407544e+001,1.367176e-002,2.029088e-006,1.346732e-002,5.238717e-005,3,9.871312e-001,1.825000e+000,,,,,,,,,,,,,,,,,,0,5.000000e+000,1.000000e+000,4,4,9.659767e-003,0,,0,
1666842946.951,,1.000000e+002,1.356281e+001,1.407959e-002,2.087762e-006,1.348423e-002,7.712362e-005,3,9.870145e-001,1.825000e+000,,,,,,,,,,,,,,,,,,0,5.000000e+000,1.000000e+000,4,4,8.839607e-003,0,,0,
1666843127.600,,1.000000e+002,1.305105e+001,1.443306e-002,3.941749e-006,1.341444e-002,7.857767e-005,3,9.871119e-001,1.825000e+000,,,,,,,,,,,,,,,,,,0,5.000000e+000,1.000000e+000,4,4,8.999825e-003,0,,0,
1666843305.019,,1.000000e+002,1.253733e+001,1.475015e-002,2.176227e-006,1.341132e-002,6.478162e-005,3,9.871036e-001,1.825000e+000,,,,,,,,,,,,,,,,,,0,5.000000e+000,1.000000e+000,4,4,8.250237e-003,0,,0,
1666843478.491,,1.000000e+002,1.202345e+001,1.504076e-002,2.545962e-006,1.339037e-002,1.124487e-004,3,9.871514e-001,1.825000e+000,,,,,,,,,,,,,,,,,,0,5.000000e+000,1.000000e+000,4,4,6.980896e-003,0,,0,
1666843687.999,,1.000000e+002,1.154600e+001,1.528782e-002,1.968647e-006,1.336800e-002,1.256795e-004,3,9.871155e-001,1.825000e+000,,,,,,,,,,,,,,,,,,0,5.000000e+000,1.000000e+000,4,4,4.670143e-003,0,,0,
1666843890.659,,1.000000e+002,1.103184e+001,1.553457e-002,3.302742e-006,1.335373e-002,1.143681e-004,3,9.870965e-001,1.825000e+000,,,,,,,,,,,,,,,,,,0,5.000000e+000,1.000000e+000,4,4,6.050110e-003,0,,0,
1666844090.855,,1.000000e+002,1.051729e+001,1.576390e-002,2.232260e-006,1.331965e-002,8.715851e-005,3,9.871616e-001,1.825000e+000,,,,,,,,,,,,,,,,,,0,5.000000e+000,1.000000e+000,4,4,5.499840e-003,0,,0,
1666844283.718,,1.000000e+002,1.000343e+001,1.597769e-002,1.907881e-006,1.330470e-002,9.646141e-005,3,9.871859e-001,1.825000e+000,,,,,,,,,,,,,,,,,,0,5.000000e+000,1.000000e+000,4,4,5.425453e-003,0,,0,
1666844474.100,,1.000000e+002,9.503232e+000,1.617504e-002,2.763837e-006,1.332950e-002,4.898190e-005,3,9.871410e-001,1.825000e+000,,,,,,,,,,,,,,,,,,0,5.000000e+000,1.000000e+000,4,4,4.345894e-003,0,,0,
1666844660.989,,1.000000e+002,9.003256e+000,1.636240e-002,3.027225e-006,1.327734e-002,6.506814e-005,3,9.871902e-001,1.825000e+000,,,,,,,,,,,,,,,,,,0,5.000000e+000,1.000000e+000,4,4,4.961014e-003,0,,0,
1666844848.376,,1.000000e+002,8.503613e+000,1.653448e-002,2.888301e-006,1.332273e-002,6.457273e-006,3,9.871489e-001,1.825000e+000,,,,,,,,,,,,,,,,,,0,5.000000e+000,1.000000e+000,4,4,6.025314e-003,0,,0,
1666845033.283,,1.000000e+002,8.003709e+000,1.669734e-002,1.914706e-006,1.328925e-002,1.134083e-004,3,9.872218e-001,1.825000e+000,,,,,,,,,,,,,,,,,,0,5.000000e+000,1.000000e+000,4,4,5.338669e-003,0,,0,
1666845218.128,,1.000000e+002,7.503458e+000,1.684416e-002,2.714646e-006,1.333984e-002,5.214637e-005,3,9.871768e-001,1.825000e+000,,,,,,,,,,,,,,,,,,0,5.000000e+000,1.000000e+000,4,4,6.236076e-003,0,,0,
1666845400.025,,1.000000e+002,7.003828e+000,1.697765e-002,2.485137e-006,1.336022e-002,1.220545e-004,3,9.871847e-001,1.825000e+000,,,,,,,,,,,,,,,,,,0,5.000000e+000,1.000000e+000,4,4,5.808353e-003,0,,0,
1666845577.927,,1.000000e+002,6.503904e+000,1.709879e-002,1.276395e-006,1.331191e-002,7.606710e-005,3,9.871778e-001,1.825000e+000,,,,,,,,,,,,,,,,,,0,5.000000e+000,1.000000e+000,4,4,3.930092e-003,0,,0,
1666845700.465,,1.000000e+002,6.011998e+000,1.720494e-002,2.491814e-006,1.325160e-002,3.973283e-005,3,9.872240e-001,1.825000e+000,,,,,,,,,,,,,,,,,,0,5.000000e+000,1.000000e+000,4,4,7.202625e-003,0,,0,
1666845902.299,,1.000000e+002,5.753888e+000,1.725348e-002,3.074994e-006,1.325359e-002,8.269634e-005,3,9.871532e-001,1.825000e+000,,,,,,,,,,,,,,,,,,0,5.000000e+000,1.000000e+000,4,4,5.253792e-003,0,,0,
1666846098.890,,1.000000e+002,5.504347e+000,1.730103e-002,2.209028e-006,1.323057e-002,3.958678e-005,3,9.871868e-001,1.825000e+000,,,,,,,,,,,,,,,,,,0,5.000000e+000,1.000000e+000,4,4,5.692005e-003,0,,0,
1666846291.706,,1.000000e+002,5.255754e+000,1.734295e-002,1.724737e-006,1.329838e-002,9.538719e-005,3,9.871658e-001,1.825000e+000,,,,,,,,,,,,,,,,,,0,5.000000e+000,1.000000e+000,4,4,7.338047e-003,0,,0,
1666846478.423,,1.000000e+002,5.007034e+000,1.738258e-002,1.522163e-006,1.320211e-002,7.395152e-005,3,9.872268e-001,1.825000e+000,,,,,,,,,,,,,,,,,,0,5.000000e+000,1.000000e+000,4,4,6.354332e-003,0,,0,
1666846661.692,,1.000000e+002,4.754668e+000,1.741745e-002,1.006060e-006,1.320206e-002,9.807031e-005,3,9.872395e-001,1.825000e+000,,,,,,,,,,,,,,,,,,0,5.000000e+000,1.000000e+000,4,4,6.632328e-003,0,,0,
1666846840.203,,1.000000e+002,4.504086e+000,1.744858e-002,2.378192e-006,1.319265e-002,1.118358e-004,3,9.872096e-001,1.825000e+000,,,,,,,,,,,,,,,,,,0,5.000000e+000,1.000000e+000,4,4,6.970882e-003,0,,0,
1666847019.245,,1.000000e+002,4.251620e+000,1.747954e-002,4.886915e-007,1.318767e-002,5.477717e-005,3,9.872332e-001,1.825000e+000,,,,,,,,,,,,,,,,,,0,5.000000e+000,1.000000e+000,4,4,6.875038e-003,0,,0,
1666847166.696,,1.000000e+002,4.001223e+000,1.750085e-002,2.489763e-006,1.328964e-002,5.624985e-005,3,9.870672e-001,1.825000e+000,,,,,,,,,,,,,,,,,,0,5.000000e+000,1.000000e+000,4,4,1.022482e-002,0,,0,
1666847363.241,,1.000000e+002,3.750815e+000,1.752317e-002,1.539618e-006,1.316703e-002,7.456326e-005,3,9.871731e-001,1.825000e+000,,,,,,,,,,,,,,,,,,0,5.000000e+000,1.000000e+000,4,4,2.383184e-002,0,,0,
1666847512.845,,1.000000e+002,3.500678e+000,1.754425e-002,3.647849e-006,1.315477e-002,1.166286e-004,3,9.871879e-001,1.825000e+000,,,,,,,,,,,,,,,,,,0,5.000000e+000,1.000000e+000,4,4,7.032871e-003,0,,0,
1666847659.018,,1.000000e+002,3.250095e+000,1.756104e-002,2.331149e-006,1.320644e-002,1.075853e-004,3,9.871520e-001,1.825000e+000,,,,,,,,,,,,,,,,,,0,5.000000e+000,1.000000e+000,4,4,7.713795e-003,0,,0,
1666847836.437,,1.000000e+002,3.002481e+000,1.757417e-002,2.183045e-006,1.328523e-002,9.370423e-006,3,9.871267e-001,1.825000e+000,,,,,,,,,,,,,,,,,,0,5.000000e+000,1.000000e+000,4,4,6.532907e-003,0,,0,
1666848020.158,,1.000000e+002,2.752810e+000,1.758573e-002,3.659575e-006,1.315303e-002,6.312168e-005,3,9.871731e-001,1.825000e+000,,,,,,,,,,,,,,,,,,0,5.000000e+000,1.000000e+000,4,4,6.381989e-003,0,,0,
1666848217.577,,1.000000e+002,2.503112e+000,1.759479e-002,2.931341e-006,1.318322e-002,9.938435e-005,3,9.871817e-001,1.825000e+000,,,,,,,,,,,,,,,,,,0,5.000000e+000,1.000000e+000,4,4,5.985975e-003,0,,0,
1666848430.267,,1.000000e+002,2.253022e+000,1.760271e-002,1.732398e-006,1.321752e-002,1.497497e-004,3,9.871362e-001,1.825000e+000,,,,,,,,,,,,,,,,,,0,5.000000e+000,1.000000e+000,4,4,6.476164e-003,0,,0,
1666848707.683,,1.000000e+002,2.000501e+000,1.761038e-002,2.125552e-006,1.327060e-002,7.046610e-005,3,9.871075e-001,1.825000e+000,,,,,,,,,,,,,,,,,,0,5.000000e+000,1.000000e+000,4,4,5.848050e-003,0,,0,