File: MPMS/NiCl2btd/NiCl2btd_MvH_16K_14T.dat
[Header]
; ACMS II Data File (default extension .dat)
; Copyright (c) 2014, Quantum Design, Inc. All rights reserved.
TITLE,
FILEOPENTIME,3875461208.837,10/20/2022,9:01 pm
BYAPP,ACMS II,1.0,1.2
INFO,DYNACOOL ACMS II Option Release 1.0.8 Build 33,APPNAME
INFO,Quantum Design Linear Motor Servo Controller,MOTOR_MODULE_NAME
INFO,3101-100 K0,MOTOR_HW_VERSION
INFO,MMC794,MOTOR_SERIAL_NUMBER
INFO,SRV No X-over 01.03.11,MOTOR_SOFTWARE_VERSION
INFO,ACMS,ACMS_MODULE_NAME
INFO,3101-430 A0,ACMS_HW_VERSION
INFO,ACMSII028,ACMS_SERIAL_NUMBER
INFO,00.14.14,ACMS_SOFTWARE_VERSION
INFO,WF046,COIL_SERIAL_NUMBER
INFO,0,MOMENT_UNITS
INFO,NiCl2-btdm,SAMPLE_MATERIAL
INFO,4.8mg cling film,SAMPLE_COMMENT
INFO,22.1,SAMPLE_MASS
INFO,,SAMPLE_VOLUME
INFO,,SAMPLE_MOLECULAR_WEIGHT
INFO,,SAMPLE_SIZE
INFO,,SAMPLE_SHAPE
DATATYPE,COMMENT,1
DATATYPE,TIME,2
STARTUPAXIS,X,2
STARTUPAXIS,Y1,5
STARTUPGROUP, AC
FIELDGROUP, AC, 2,3,4,5,6,7,8,9,10,11,12,13,14,15,16,20,21,22,23,24,25,35,43,44,45,46,47,48,49
FIELDGROUP, DC, 2,3,4,17,18,19,20,21,23,24,25,35,36,37,43,44,45,46,47,48,49,50,51
FIELDGROUP, Diagnostic, 26,27,28,29,30,31,32,33,34,38,39,40,41,42,52,53,54,55,56,57,58,59,60,61,62,63,64,65,66,67,68,69
[Data]
Comment,Time Stamp (sec),Temperature (K),Magnetic Field (Oe),AC Moment (emu),AC Std. Dev. (emu),AC Phase (deg),AC Phase Std. Dev. (deg),AC Suscept. (emu/Oe),AC Suscept. Std. Dev. (emu/Oe),AC X'  (emu/Oe),AC X" (emu/Oe),AC X' Std. Dev. (emu/Oe),AC X" Std. Dev. (emu/Oe),AC Drive (Oe),AC Frequency (Hz),DC Moment (emu),DC Std. Err. (emu),DC Quad. Moment (emu),Range (mV),"AC=1 DC=2 Locate=3",Measure Type,Measure Count,Measure Time (sec),Measure Number,AC X' Raw (emu/Oe),AC X" Raw (emu/Oe),DC M. Raw' (emu),DC M. Raw" (emu),Coil InPhase (V),Coil Quadrature (V),Null Status,Trim Ratio,Trim Phase (deg.),Max. Signal (mV),Motor Frequency (Hz),Motor Ampl. (mm),System Temp. (K),Min. Temperature (K),Max. Temperature (K),Min. Field (Oe),Max. Field (Oe),Pressure (Torr),Temp. Status (code),Field Status (code),Chamber Status (code),Measure Status (code),Center Position (mm),Transport Action,Motor Lag (deg),Motor Current (amps),Motor Heatsink Temp. (C),Motor Board Temp. (C),QMap 01,QMap 02,QMap 03,QMap 04,QMap 05,QMap 06,QMap 07,QMap 08,QMap 09,QMap 10,QMap 11,QMap 12,QMap 13,QMap 14,QMap 15,QMap 16
sample offset = 25.15 mm,3875463019.48711,16.0005524953206,0.569160431623459,,,,,,,,,,,,,0.02588435681987,1.32648732063216E-6,-3.4261111487971E-5,1,2,,80,2,1,,,0.0249285820312017,9.50420050772269E-5,0.000152448614244349,-5.32714220753405E-5,,,,0.00632550139910325,39.995735168457,1.99949434114881,16.0018882751465,16.0003967285156,16.0007591247559,0.533587872982025,0.604732990264893,0.40720546245575,1,4,3,4,23.1730000402331,1,20.6533368638839,1.12358093261719,31.2805480957031,33.2355842590332,,,,,,,,,,,,,,,,
,3875463165.41686,16.0002479553223,1535.31652832031,,,,,,,,,,,,,0.0313981599974089,1.17433419981693E-5,-7.43778279551351E-5,1,2,,80,2,69,,,0.0302397131861588,8.68594349069593E-5,0.000184995456947945,-6.45065811113454E-5,,,,0.00767323164128814,39.995735168457,1.99976815685046,16.0002918243408,16.0000419616699,16.0003852844238,1480.40222167969,1590.23083496094,0.407822400331497,1,6,3,4,23.1730000402331,1,20.6691182069364,1.12846374511719,40.0782012939453,32.2580642700195,,,,,,,,,,,,,,,,
,3875463311.45056,16.0012084960938,8832.7392578125,,,,,,,,,,,,,0.0572037704462367,1.16458218219707E-5,-0.000109149035541381,1,2,,80,2,137,,,0.0551037898515182,0.000224819490675095,0.000336939003318548,-0.000117955256428104,,,,0.0139822351337476,39.995735168457,1.99963638218217,15.9995050430298,16.0009384155273,16.0013618469238,8777.734375,8887.744140625,0.408278703689575,1,6,3,4,23.1730000402331,1,20.6707123854408,1.12266540527344,41.5444793701172,34.7018585205078,,,,,,,,,,,,,,,,
,3875463457.31793,16.0013542175293,16125.6362304687,,,,,,,,,,,,,0.0826040622693474,1.3261269520291E-5,-0.000115219164415643,1,2,,80,2,205,,,0.079592595192121,0.000436161747625462,0.000486470147734508,-0.000171045452589169,,,,0.0201958766814688,39.995735168457,1.99972065296185,15.9948759078979,16.001220703125,16.0016021728516,16073.0537109375,16178.21875,0.408674657344818,1,6,3,4,23.1730000402331,1,20.6683649408118,1.12190246582031,42.5219955444336,36.1681327819824,,,,,,,,,,,,,,,,
,3875463600.74254,16.0010704040527,23311.525390625,,,,,,,,,,,,,0.107840467258343,1.27231117976528E-5,-0.000105505223746167,1,2,,80,2,273,,,0.103942586625206,0.000710441402049622,0.000634945230558515,-0.000224242772674188,,,,0.0263729809575274,39.995735168457,1.99957182455082,15.9919891357422,16.0008659362793,16.001220703125,23258.89453125,23364.15625,0.408942073583603,1,6,3,4,23.1730000402331,1,20.6704154432398,1.12159729003906,43.0107536315918,37.1456527709961,,,,,,,,,,,,,,,,
,3875463740.16846,16.0006950378418,30301.5732421875,,,,,,,,,,,,,0.132859968586939,1.50366010647055E-5,-7.33698254312372E-5,1,2,,80,2,341,,,0.12810568299583,0.00105142470784805,0.000782195304054767,-0.000277443963568658,,,,0.0325041308965903,39.995735168457,1.99961252314957,15.9895248413086,16.0006446838379,16.0007820129395,30248.919921875,30354.2265625,0.409154266119003,1,6,3,4,23.1730000402331,1,20.6697034973531,1.12480163574219,43.0107536315918,38.1231689453125,,,,,,,,,,,,,,,,
,3875463879.61457,16.0004745483398,37294.798828125,,,,,,,,,,,,,0.158539076219539,1.56981153820383E-5,-4.75925038919909E-5,1,2,,80,2,409,,,0.152932325676807,0.00144089405781593,0.000933393661398441,-0.000332347524818033,,,,0.0388037231240711,39.995735168457,1.99961763304641,15.9874744415283,16.0003776550293,16.0005378723145,37244.578125,37345.01953125,0.40922749042511,1,6,3,4,23.1730000402331,1,20.6695496899248,1.12220764160156,43.49951171875,38.1231689453125,,,,,,,,,,,,,,,,
,3875464021.09933,16.0000190734863,44389.337890625,,,,,,,,,,,,,0.185476079863204,1.75635966974866E-5,6.78386958915031E-5,10,2,,80,2,478,,,0.179005431018732,0.00198089995167572,0.00109190389048308,-0.000390769739169627,,,,0.0454218143488232,39.995735168457,1.9995940602989,15.9876146316528,15.9998626708984,16.0003318786621,44339.34765625,44439.328125,0.409581810235977,1,6,3,4,23.1730000402331,1,20.6676140527021,1.12297058105469,43.9882698059082,38.1231689453125,,,,,,,,,,,,,,,,
,3875464160.51008,15.999997138977,51379.54296875,,,,,,,,,,,,,0.21298975024603,1.77585062014494E-5,6.03974780300105E-5,10,2,,80,2,546,,,0.20567301709524,0.00245555615601639,0.00125412980560213,-0.000450060935690999,,,,0.0521872451638601,39.995735168457,1.99949178530352,15.987135887146,15.9998626708984,16.0001411437988,51329.38671875,51429.69921875,0.409816265106201,1,6,3,4,23.1730000402331,1,20.6675585887426,1.12136840820312,43.49951171875,39.1006851196289,,,,,,,,,,,,,,,,
,3875464299.92821,15.9993492126465,58373.236328125,,,,,,,,,,,,,0.241447925373295,2.00423241170278E-5,3.81131008995672E-5,10,2,,80,2,614,,,0.233295664849514,0.002974779033542,0.00142215064261109,-0.000511623686179519,,,,0.0591956206481777,39.995735168457,1.99945626308745,15.9873914718628,15.9991874694824,15.9995346069336,58320.58203125,58425.890625,0.410018980503082,1,6,3,4,23.1730000402331,1,20.6662247845171,1.12167358398438,43.9882698059082,40.0782012939453,,,,,,,,,,,,,,,,
,3875464439.3408,15.9998718261719,65365.140625,,,,,,,,,,,,,0.270666629110075,1.96073059702428E-5,-1.20864982638251E-5,10,2,,80,2,682,,,0.261701088511512,0.00352256691074233,0.00159496383275837,-0.000575043202843517,,,,0.0664051717641589,39.995735168457,1.99950714342866,15.9891672134399,15.999641418457,16.0002098083496,65315.04296875,65415.23828125,0.410295993089676,1,6,3,4,23.1730000402331,1,20.6653280149675,1.11381530761719,43.9882698059082,39.1006851196289,,,,,,,,,,,,,,,,
,3875464578.75982,15.9993583679199,72355.703125,,,,,,,,,,,,,0.300514528008315,2.17265402022967E-5,-9.81816382499591E-5,10,2,,80,2,750,,,0.290767274368855,0.00408736303912721,0.00177162489853799,-0.000639921694528312,,,,0.0737759511664254,39.995735168457,1.9993665551538,15.9907341003418,15.9992141723633,15.9995155334473,72305.4765625,72405.9296875,0.410470932722092,1,6,3,4,23.1730000402331,1,20.6650622129289,1.11358642578125,43.9882698059082,39.5894432067871,,,,,,,,,,,,,,,,
,3875464718.19401,15.9991340637207,79371.48046875,,,,,,,,,,,,,0.330936269331422,1.88726333143526E-5,-0.000218491641280435,10,2,,80,2,818,,,0.320445855157956,0.0046680347325623,0.00195213418919593,-0.000706238904967904,,,,0.0813072554223178,39.995735168457,1.99939002049366,15.9920024871826,15.9988975524902,15.9994354248047,79320.9453125,79422.015625,0.410611182451248,1,6,3,4,23.1730000402331,1,20.6648122396809,1.11465454101562,44.4770278930664,39.5894432067871,,,,,,,,,,,,,,,,
,3875464857.59064,15.9990966796875,86438.1953125,,,,,,,,,,,,,0.361869180664852,2.11036845674205E-5,-0.000369081190944256,10,2,,80,2,886,,,0.350681219829964,0.0052649804953836,0.00213601929135621,-0.000773784937337041,,,,0.0889791612912537,39.995735168457,1.99939565826642,15.9928560256958,15.9989738464355,15.9992027282715,86387.578125,86488.8125,0.41102597117424,1,6,3,4,23.1730000402331,1,20.663449718596,1.12274169921875,44.4770278930664,40.0782012939453,,,,,,,,,,,,,,,,
,3875464997.01058,15.9996612548828,93508.796875,,,,,,,,,,,,,0.392998381521877,2.28519201075211E-5,-0.000573475116615274,10,2,,80,2,954,,,0.381170072857308,0.00584437998032437,0.00232141185551882,-0.0008416663040407,,,,0.0967116485185318,39.995735168457,1.99931033591673,15.9942436218262,15.9995613098145,15.9997749328613,93455.5234375,93562.0703125,0.41108649969101,1,6,3,4,23.1730000402331,1,20.6609160851508,1.11373901367188,43.9882698059082,40.5669593811035,,,,,,,,,,,,,,,,
,3875465136.4347,15.9998008728027,100580.140625,,,,,,,,,,,,,0.424112775423406,2.22539760612496E-5,-0.000799584756166485,10,2,,80,2,1022,,,0.411708610682556,0.00642849642470703,0.0025071045383811,-0.000909871538169682,,,,0.104460192486044,39.995735168457,1.99929159845532,15.9958839416504,15.9996490478516,16.0000228881836,100529.4765625,100630.8046875,0.411404252052307,1,6,3,4,23.1730000402331,1,20.662551650289,1.11373901367188,44.4770278930664,40.0782012939453,,,,,,,,,,,,,,,,
,3875465275.84492,15.999472618103,107649.21875,,,,,,,,,,,,,0.455017362638692,3.19727740818828E-5,-0.00108655870175413,10,2,,80,2,1090,,,0.442108399177608,0.0069701471647606,0.00269218650646508,-0.00097725004889071,,,,0.112175060894583,39.995735168457,1.99930889139403,15.9964256286621,15.9991989135742,15.9996681213379,107595.9609375,107702.4765625,0.411760807037354,1,6,3,4,23.1730000402331,1,20.6578045639703,1.1224365234375,43.0107536315918,40.0782012939453,,,,,,,,,,,,,,,,
,3875465415.25751,15.999945640564,114718.1640625,,,,,,,,,,,,,0.485666825939725,2.63383972074263E-5,-0.00138981694660643,10,2,,80,2,1158,,,0.472324050191284,0.00750600303003823,0.00287594343535602,-0.00104432145599276,,,,0.11983750263023,39.995735168457,1.99921881858954,15.9983749389648,15.9996604919434,16.0000762939453,114664.9140625,114771.4140625,0.412044525146484,1,6,3,4,23.1730000402331,1,20.6570781983511,1.12152099609375,44.4770278930664,37.6344108581543,,,,,,,,,,,,,,,,
,3875465554.69761,15.9997711181641,121789.23046875,,,,,,,,,,,,,0.515804019322424,2.93212549960433E-5,-0.00168095997787761,10,2,,80,2,1226,,,0.502103456220838,0.00805331038084139,0.00305716460570693,-0.00111059856135398,,,,0.127394814694573,39.995735168457,1.99924616777942,15.9979228973389,15.9996604919434,15.9999160766602,121738.5703125,121839.890625,0.412198781967163,1,6,3,4,23.1730000402331,1,20.6564358440005,1.12190246582031,44.4770278930664,40.5669593811035,,,,,,,,,,,,,,,,
,3875465694.11375,15.9999954223633,128859.66015625,,,,,,,,,,,,,0.545208611822112,3.11366223984363E-5,-0.00199286810479249,10,2,,80,2,1294,,,0.531229699296919,0.00857005876803818,0.00323436665348709,-0.0011753385188058,,,,0.134783629074027,39.995735168457,1.99922935795446,15.9973192214966,15.999828338623,16.0001220703125,128806.546875,128912.7734375,0.412630289793015,1,6,3,4,23.1730000402331,1,20.656823753819,1.11419677734375,44.9657897949219,40.0782012939453,,,,,,,,,,,,,,,,
,3875465833.52908,16.0003814697266,135926.375,,,,,,,,,,,,,0.573762996821913,3.03673528847276E-5,-0.00230363004671805,10,2,,80,2,1362,,,0.55958366387724,0.00906967422375343,0.00340696889907122,-0.00123822153545916,,,,0.141978255112556,39.995735168457,1.99924017945655,15.9970579147339,16.0002708435059,16.0005226135254,135875.65625,135977.09375,0.412877976894379,1,6,3,4,23.1730000402331,1,20.6548958874369,1.11396789550781,44.4770278930664,40.0782012939453,,,,,,,,,,,,,,,,
,3875465972.94552,15.999813079834,140000.2421875,,,,,,,,,,,,,0.589778748633239,2.93319965740209E-5,-0.0024761165087763,10,2,,80,2,1430,,,0.575518972871614,0.00935280622769799,0.00350366532802582,-0.00127372867427766,,,,0.146012353964539,39.995735168457,1.99911767979421,15.9965486526489,15.9996070861816,15.9999732971191,140000.203125,140000.28125,0.413106113672256,1,4,3,4,23.1730000402331,1,20.6576799361581,1.1212158203125,44.4770278930664,40.5669593811035,,,,,,,,,,,,,,,,
,3875466112.33665,15.9994926452637,136363.390625,,,,,,,,,,,,,0.57549509077022,3.30443797196169E-5,-0.00231311884558949,10,2,,80,2,1498,,,0.561305784731171,0.0091092333415205,0.00341734895482659,-0.00124220235738903,,,,0.142413444458066,39.995735168457,1.99921671514387,15.998010635376,15.9993553161621,15.9996757507324,136311.546875,136415.234375,0.413425266742706,1,6,3,4,23.1730000402331,1,20.6567924020265,1.11434936523438,44.9657897949219,40.5669593811035,,,,,,,,,,,,,,,,
,3875466251.76169,15.999772644043,129464.71484375,,,,,,,,,,,,,0.547698650707688,2.57684854825281E-5,-0.00203456977629126,10,2,,80,2,1566,,,0.53369956465044,0.00859914324535771,0.00324939657002687,-0.00118073809426278,,,,0.135409512371107,39.995735168457,1.99921257769888,15.9994535446167,15.9996604919434,15.9998626708984,129415.2421875,129514.1875,0.413409382104874,1,6,3,4,23.1730000402331,1,20.6570105367547,1.12258911132812,44.4770278930664,41.055721282959,,,,,,,,,,,,,,,,
,3875466391.18398,15.9999244689941,122569.390625,,,,,,,,,,,,,0.519075224222592,2.75162735067685E-5,-0.00171019954913245,10,2,,80,2,1634,,,0.505340279118556,0.00811580512997656,0.0030771205201745,-0.00111796450801194,,,,0.128229197183981,39.995735168457,1.9994352180698,15.9988231658936,15.9998016357422,16.0000419616699,122519.8515625,122618.9296875,0.413631170988083,1,6,3,4,23.1730000402331,1,20.6571516255542,1.12174987792969,44.9657897949219,40.5669593811035,,,,,,,,,,,,,,,,
,3875466530.59288,16.0001129150391,115671.1640625,,,,,,,,,,,,,0.489783480490511,2.81699177552811E-5,-0.00140198171203583,10,2,,80,2,1702,,,0.476386917571539,0.00760670993079238,0.00290081254206598,-0.00105359335429966,,,,0.120876843060064,39.995735168457,1.99936318294766,15.9993896484375,15.9999351501465,16.0003051757813,115619.2265625,115723.1015625,0.413758784532547,1,6,3,4,23.1730000402331,1,20.6569441556976,1.12953186035156,44.4770278930664,40.5669593811035,,,,,,,,,,,,,,,,
,3875466670.00538,16.0000885009766,108773.6796875,,,,,,,,,,,,,0.459994896056284,2.57855624700708E-5,-0.00109331854780005,10,2,,80,2,1770,,,0.447009086045165,0.00709667997423788,0.00272189849056303,-0.000988417072221637,,,,0.113418342611187,39.995735168457,1.99929935497164,15.9981679916382,15.9999237060547,16.0002517700195,108721.71875,108825.640625,0.413583427667618,1,6,3,4,23.1730000402331,1,20.6585903494458,1.12144470214844,44.4770278930664,40.5669593811035,,,,,,,,,,,,,,,,
,3875466809.42407,16.0001502990723,101877.40234375,,,,,,,,,,,,,0.429806274130876,2.4359144927928E-5,-0.000840400165844908,10,2,,80,2,1838,,,0.417303838673275,0.00653843426196854,0.00254121073521674,-0.000922159932088107,,,,0.105879880807729,39.995735168457,1.99929417044772,15.9964637756348,15.9999732971191,16.0003967285156,101825.3359375,101929.46875,0.413546204566956,1,6,3,4,23.1730000402331,1,20.6576733632836,1.12075805664062,44.4770278930664,40.5669593811035,,,,,,,,,,,,,,,,
,3875466948.81624,16.0001815795898,94978.92578125,,,,,,,,,,,,,0.399473705553977,2.4488039054177E-5,-0.0006158114841886,10,2,,80,2,1906,,,0.387520132340518,0.00596850411925748,0.00236024055629969,-0.000855877879075706,,,,0.0983314672208588,39.995735168457,1.99948009548107,15.9959011077881,15.9999618530273,16.000431060791,94929.2578125,95028.59375,0.413484066724777,1,6,3,4,23.1730000402331,1,20.6598264917841,1.12052917480469,44.4770278930664,41.055721282959,,,,,,,,,,,,,,,,
,3875467088.24916,16.0001058578491,88082.5234375,,,,,,,,,,,,,0.36913844696027,2.12573837570336E-5,-0.000419404675435405,10,2,,80,2,1974,,,0.35779506145647,0.00539487930790412,0.00217927736230195,-0.000789530575275421,,,,0.0907828781770237,39.995735168457,1.99934794711052,15.9949827194214,16.0000228881836,16.0002517700195,88033,88132.046875,0.413501441478729,1,6,3,4,23.1730000402331,1,20.6614990747827,1.12113952636719,44.4770278930664,40.5669593811035,,,,,,,,,,,,,,,,
,3875467227.68553,16.000365447998,81184.19921875,,,,,,,,,,,,,0.338913056249581,2.33794087942734E-5,-0.000267425716972961,10,2,,80,2,2042,,,0.328236711796234,0.00480852659472886,0.00199968996457756,-0.000723445846233517,,,,0.0832883007207723,39.995735168457,1.99948497894191,15.9928407669067,16.0001411437988,16.0005111694336,81132.140625,81236.2578125,0.413373112678528,1,6,3,4,23.1730000402331,1,20.6601588804,1.12197875976562,44.4770278930664,40.0782012939453,,,,,,,,,,,,,,,,
,3875467367.08633,16.0005767822266,74288.87890625,,,,,,,,,,,,,0.308923333482519,1.69846501501379E-5,-0.000155293190170166,10,2,,80,2,2110,,,0.298965047941285,0.00422069939763484,0.00182163750287145,-0.000657955592032522,,,,0.0758585461806982,39.995735168457,1.99942577348804,15.9921026229858,16.0004501342773,16.0007057189941,74236.796875,74340.9609375,0.413428992033005,1,6,3,4,23.1730000402331,1,20.6607329092182,1.12205505371094,44.4770278930664,40.5669593811035,,,,,,,,,,,,,,,,
,3875467506.51192,16.0001594543457,67390.69140625,,,,,,,,,,,,,0.279352528519584,2.07720991978167E-5,-4.97470761811095E-5,10,2,,80,2,2178,,,0.270153888928759,0.00367007657093556,0.00164637016132474,-0.000593711447436362,,,,0.0685474542583226,39.995735168457,1.99942007081171,15.9907636642456,15.9999961853027,16.0003051757813,67341.21875,67440.1640625,0.413409680128098,1,6,3,4,23.1730000402331,1,20.6623133090912,1.11358642578125,44.4770278930664,40.0782012939453,,,,,,,,,,,,,,,,
,3875467645.93214,16.0004730224609,60495.0234375,,,,,,,,,,,,,0.25035190371725,2.04608863287855E-5,3.82022690487773E-5,10,2,,80,2,2246,,,0.24194615343097,0.0031514882978869,0.00147476070560515,-0.000530940422322601,,,,0.0613904127818412,39.995735168457,1.99945139404927,15.9896516799927,16.0003280639648,16.000659942627,60445.48828125,60544.55859375,0.413442403078079,1,6,3,4,23.1730000402331,1,20.6639189084692,1.12106323242188,43.9882698059082,40.5669593811035,,,,,,,,,,,,,,,,
,3875467785.32992,16.0001663208008,53598.173828125,,,,,,,,,,,,,0.22204266117277,1.86802324821341E-5,5.93689633144508E-5,10,2,,80,2,2314,,,0.214455065458031,0.00262123012128977,0.00130752741824836,-0.000469611957669258,,,,0.0544138351701886,39.995735168457,1.99943938507934,15.9884653091431,16.0000038146973,16.0003967285156,53546.1953125,53650.15234375,0.413458675146103,1,6,3,4,23.1730000402331,1,20.6663944383718,1.11434936523438,44.4770278930664,40.5669593811035,,,,,,,,,,,,,,,,
,3875467924.75232,15.9999847412109,46702.7734375,,,,,,,,,,,,,0.194592466972436,1.68858992153136E-5,6.53159921575946E-5,10,2,,80,2,2382,,,0.187837007322131,0.0021326284119185,0.00114561489317566,-0.000410366628784686,,,,0.0476615334597441,39.995735168457,1.99951383000483,15.9884824752808,15.9995002746582,16.0002784729004,46650.765625,46754.78125,0.413542151451111,1,6,3,4,23.1730000402331,1,20.6677620592236,1.1224365234375,44.4770278930664,40.5669593811035,,,,,,,,,,,,,,,,
,3875468064.19722,15.9993812561035,39806.017578125,,,,,,,,,,,,,0.16811042673852,1.73052449131499E-5,4.86835506060142E-5,10,2,,80,2,2450,,,0.16219198513959,0.00168003131911618,0.000989544205367565,-0.000353344425093383,,,,0.0411541419100426,39.995735168457,1.99950257069971,15.9874982833862,15.999153137207,15.9995002746582,39756.51171875,39855.5234375,0.413636267185211,1,6,3,4,23.1730000402331,1,20.6674584353456,1.12258911132812,44.4770278930664,40.5669593811035,,,,,,,,,,,,,,,,
,3875468203.60898,15.9998092651367,32879.9140625,,,,,,,,,,,,,0.14241017026403,1.34626593158964E-5,3.79458316922631E-6,10,2,,80,2,2518,,,0.137334594195584,0.00125525805576011,0.000838260923046619,-0.000298208498861641,,,,0.0348480685757291,39.995735168457,1.99957692787951,15.9891262054443,15.9997024536133,15.9999351501465,32830.33203125,32929.49609375,0.413721978664398,1,6,3,4,23.1730000402331,1,20.6695643940761,1.12220764160156,44.4770278930664,40.0782012939453,,,,,,,,,,,,,,,,
,3875468343.0158,15.9989795684814,25944.3837890625,,,,,,,,,,,,,0.117408416043148,1.31777565142348E-5,-2.40429021805146E-5,10,2,,80,2,2586,,,0.113179305897119,0.000901159206003414,0.000691092340275645,-0.000244958704570308,,,,0.0287183783723253,39.995735168457,1.99956177447782,15.9909400939941,15.998908996582,15.999153137207,25892.08203125,25996.685546875,0.413756370544434,1,6,3,4,23.1730000402331,1,20.671152040657,1.123046875,44.4770278930664,40.5669593811035,,,,,,,,,,,,,,,,
,3875468482.43093,15.9994079589844,19011.9921875,,,,,,,,,,,,,0.0929309650289067,1.22510146182725E-5,-5.42867517410115E-5,10,2,,80,2,2654,,,0.0895535625922738,0.000596597694853849,0.000547089613974094,-0.000193100684555247,,,,0.0227236668123212,39.995735168457,1.99959490737601,15.993537902832,15.999340057373,15.999568939209,18960.013671875,19063.970703125,0.413847535848618,1,6,3,4,23.1730000402331,1,20.6696913056309,1.12136840820312,44.4770278930664,40.0782012939453,,,,,,,,,,,,,,,,
,3875468621.83801,15.998949432373,12076.8178710938,,,,,,,,,,,,,0.0688080624487369,1.16119477018641E-5,-7.63400834771085E-5,10,2,,80,2,2722,,,0.0662890739844793,0.000348812994015703,0.000405157392378896,-0.000142385237268172,,,,0.0168203363253683,39.995735168457,1.99960393645041,15.9970064163208,15.9987907409668,15.999153137207,12027.1806640625,12126.455078125,0.414036870002747,1,6,3,4,23.1730000402331,1,20.6720123530282,1.12266540527344,44.4770278930664,40.0782012939453,,,,,,,,,,,,,,,,
,3875468761.33103,15.9987762451172,5135.30493164063,,,,,,,,,,,,,0.0447696634016823,1.09658464606694E-5,-9.81421450087029E-5,1,2,,80,2,2790,,,0.0431215130401486,0.000146182348417996,0.000263728376012295,-9.21259779715911E-5,,,,0.0109408691010313,39.995735168457,1.99959706844982,16.0003108978271,15.9986915588379,15.998908996582,5082.681640625,5187.92822265625,0.414107352495193,1,6,3,4,23.1730000402331,1,20.6715681871429,1.12289428710938,44.4770278930664,40.5669593811035,,,,,,,,,,,,,,,,
,3875468900.74533,16.0010696411133,-1813.50433349609,,,,,,,,,,,,,-0.0229990996977547,4.92274509703631E-5,4.66362654791155E-5,1,2,,80,2,2858,,,-0.0221506244349099,-7.16948007837784E-5,-0.000135474954731762,4.73049767606426E-5,,,,0.00562015143721406,39.995735168457,1.999555121921,16.0017757415771,16.0009536743164,16.001220703125,-1863.24975585938,-1763.75891113281,0.414220005273819,1,6,3,4,23.1730000402331,1,20.6730658488958,1.1236572265625,43.9882698059082,40.0782012939453,,,,,,,,,,,,,,,,
,3875469040.16528,16.0008857727051,-8764.2275390625,,,,,,,,,,,,,-0.0567897103761303,1.18404013422196E-5,0.000104771616870789,1,2,,80,2,2926,,,-0.0547047897588599,-0.000226217252215423,-0.000334469601511955,0.000117118295747787,,,,0.0138791010776427,39.995735168457,1.99950687841229,15.9991159439087,16.000804901123,16.0011138916016,-8813.94921875,-8714.505859375,0.414076387882233,1,6,3,4,23.1730000402331,1,20.6717437152919,1.12312316894531,43.9882698059082,39.5894432067871,,,,,,,,,,,,,,,,
,3875469179.56461,16.0013122558594,-15715.6499023438,,,,,,,,,,,,,-0.0811419770612807,1.1856229360996E-5,0.000116709908937087,1,2,,80,2,2994,,,-0.0781825271441542,-0.000420969429009637,-0.000477834837511182,0.000168003709404729,,,,0.0198369894016813,39.995735168457,1.99964159096993,15.9951868057251,16.001106262207,16.0015487670898,-15765.5068359375,-15665.79296875,0.414082497358322,1,6,3,4,23.1730000402331,1,20.6732462861369,1.1224365234375,43.49951171875,40.0782012939453,,,,,,,,,,,,,,,,
,3875469318.99863,16.0009819030762,-22680.70703125,,,,,,,,,,,,,-0.105594772073762,1.32919049386575E-5,0.000101998793869948,1,2,,80,2,3062,,,-0.101774879308236,-0.000688327794797404,-0.000621715851593763,0.000219557681703009,,,,0.0258238584064529,39.995735168457,1.99960003553131,15.9919013977051,16.0007820129395,16.0011749267578,-22730.73828125,-22630.67578125,0.414133876562119,1,6,3,4,23.1730000402331,1,20.673467405493,1.12251281738281,43.9882698059082,40.0782012939453,,,,,,,,,,,,,,,,
,3875469458.40161,16.0007415771484,-29648.4453125,,,,,,,,,,,,,-0.130511785390782,1.42419560143035E-5,7.52642708078228E-5,1,2,,80,2,3130,,,-0.12583679898236,-0.00101848729101284,-0.000768331694416702,0.000272493809461594,,,,0.0319279782423518,39.995735168457,1.99955995727808,15.9896621704102,16.0005798339844,16.0008392333984,-29700.830078125,-29596.060546875,0.414279818534851,1,6,3,4,23.1730000402331,1,20.6740522609429,1.12152099609375,43.9882698059082,40.0782012939453,,,,,,,,,,,,,,,,
,3875469597.84321,16.0003845214844,-36624.853515625,,,,,,,,,,,,,-0.15605403326168,1.68277616867848E-5,4.27540321464629E-5,1,2,,80,2,3198,,,-0.150528445663608,-0.00140827473984458,-0.000918701407499611,0.000327132001984864,,,,0.038193627312645,39.995735168457,1.99958410717303,15.9873867034912,16.0002975463867,16.0005226135254,-36677.3125,-36572.39453125,0.414059817790985,1,6,3,4,23.1730000402331,1,20.6742219460806,1.12236022949219,43.9882698059082,39.5894432067871,,,,,,,,,,,,,,,,
,3875469739.32733,16.000121307373,-43696.533203125,,,,,,,,,,,,,-0.182821573366693,1.54464959062647E-5,-5.27930803362772E-5,10,2,,80,2,3267,,,-0.176434558894776,-0.00192205008651616,-0.00107625313103199,0.000385127525078133,,,,0.0447701330026303,39.995735168457,1.99963235267737,15.9871263504028,16.0000038146973,16.0002517700195,-43746.625,-43646.44140625,0.414243251085281,1,6,3,4,23.1730000402331,1,20.6755439688296,1.12503051757812,43.9882698059082,40.0782012939453,,,,,,,,,,,,,,,,
,3875469878.75842,15.9997459411621,-50669.55859375,,,,,,,,,,,,,-0.210175292998612,1.82721557952597E-5,-6.72830672218383E-5,10,2,,80,2,3335,,,-0.20294325316878,-0.00241083373763022,-0.00123748206533492,0.00044420623453334,,,,0.0514950907515596,39.995735168457,1.99955201172843,15.9872198104858,15.9995956420898,15.9999084472656,-50722.1796875,-50616.9375,0.414200723171234,1,6,3,4,23.1730000402331,1,20.6758869985057,1.11534118652344,43.49951171875,40.0782012939453,,,,,,,,,,,,,,,,
,3875470018.15593,16.0000190734863,-57641.009765625,,,,,,,,,,,,,-0.238465704472814,1.71225481016288E-5,-5.54171647542994E-5,10,2,,80,2,3403,,,-0.230398686286237,-0.00293264529318608,-0.00140450359322131,0.000505472940858454,,,,0.0584627184356722,39.995735168457,1.9995672215907,15.9876880645752,15.999828338623,16.0001220703125,-57693.59765625,-57588.421875,0.414354503154755,1,6,3,4,23.1730000402331,1,20.6746619177992,1.11564636230469,44.4770278930664,39.5894432067871,,,,,,,,,,,,,,,,
,3875470157.57287,15.9994934082031,-64613.517578125,,,,,,,,,,,,,-0.267542257720944,2.08585968585135E-5,1.36331075492347E-6,10,2,,80,2,3471,,,-0.25866110836873,-0.00346690646599995,-0.00157644448336214,0.000568601419217885,,,,0.0656367623634745,39.995735168457,1.99961670079041,15.9890947341919,15.9993209838867,15.9997138977051,-64663.60546875,-64563.4296875,0.41438102722168,1,6,3,4,23.1730000402331,1,20.6761549747071,1.11488342285156,43.49951171875,39.5894432067871,,,,,,,,,,,,,,,,
,3875470297.01106,15.9997093200684,-71584.40234375,,,,,,,,,,,,,-0.297243188233421,2.22525187384178E-5,9.68742984531354E-5,10,2,,80,2,3539,,,-0.287578916914067,-0.00401539614063778,-0.00175233115442097,0.000633078103419393,,,,0.0729741959427245,39.995735168457,1.99957112944951,15.9903507232666,15.9994201660156,15.9998741149902,-71634.5625,-71534.2421875,0.414506018161774,1,6,3,4,23.1730000402331,1,20.6740975778173,1.12358093261719,43.9882698059082,39.5894432067871,,,,,,,,,,,,,,,,
,3875470436.42009,15.9992034912109,-78571.9140625,,,,,,,,,,,,,-0.327489576266978,1.61771976333558E-5,0.000192932196812503,10,2,,80,2,3607,,,-0.317080102756451,-0.00461173140311819,-0.00193170493002981,0.000699049851391464,,,,0.0804596718230131,39.995735168457,1.99953827640231,15.9914398193359,15.9990348815918,15.9993476867676,-78622.5625,-78521.265625,0.414337903261185,1,6,3,4,23.1730000402331,1,20.671418860363,1.11495971679688,43.9882698059082,39.1006851196289,,,,,,,,,,,,,,,,
,3875470575.83994,15.9998893737793,-85621.4921875,,,,,,,,,,,,,-0.358316615253183,2.38601766082535E-5,0.000346651603389519,10,2,,80,2,3675,,,-0.347205355407878,-0.00519950534368042,-0.00211496232077479,0.000766238139476627,,,,0.0881036238471359,39.995735168457,1.9995330584921,15.9942798614502,15.999755859375,16.0000038146973,-85674.515625,-85568.46875,0.414582014083862,1,6,3,4,23.1730000402331,1,20.6675870715991,1.12556457519531,43.9882698059082,40.0782012939453,,,,,,,,,,,,,,,,
,3875470715.25632,15.9991903305054,-92671.19140625,,,,,,,,,,,,,-0.389342544280856,2.32606920267912E-5,0.000538642853798721,10,2,,80,2,3743,,,-0.37758565246739,-0.00578509023364167,-0.00229963753372431,0.000834012869745493,,,,0.0958085370360287,39.995735168457,1.99942901655445,15.9944067001343,15.9990272521973,15.9994010925293,-92721.796875,-92620.5859375,0.414739847183228,1,6,3,4,23.1730000402331,1,20.6668843921047,1.12174987792969,43.9882698059082,39.5894432067871,,,,,,,,,,,,,,,,
,3875470854.66477,15.9999732971191,-99718.6875,,,,,,,,,,,,,-0.420362326482997,2.1883868823867E-5,0.000766828432478359,10,2,,80,2,3811,,,-0.408023622814936,-0.00636186762946897,-0.00248475326225162,0.000901665654964745,,,,0.103527237562485,39.995735168457,1.99934033448433,15.9956245422363,15.9998817443848,16.0001411437988,-99769.2109375,-99668.1640625,0.414835274219513,1,6,3,4,23.1730000402331,1,20.6619081119149,1.12236022949219,43.9882698059082,39.5894432067871,,,,,,,,,,,,,,,,
,3875470994.08368,15.9995212554932,-106767.52734375,,,,,,,,,,,,,-0.451241916792117,2.42756290469931E-5,0.00103038429150711,10,2,,80,2,3879,,,-0.438389814487329,-0.00692286861871561,-0.00266939029097557,0.000969141954556108,,,,0.111227040454673,39.995735168457,1.99923239767011,15.9965829849243,15.9993705749512,15.9997367858887,-106820.5,-106714.5546875,0.414980232715607,1,6,3,4,23.1730000402331,1,20.659485473203,1.11457824707031,43.9882698059082,39.5894432067871,,,,,,,,,,,,,,,,
,3875471133.51484,15.9997901916504,-113814.453125,,,,,,,,,,,,,-0.481802226593039,3.10460400217877E-5,0.00132840476584561,10,2,,80,2,3947,,,-0.468509510741158,-0.0074598717335006,-0.00285272067412734,0.001035874360241,,,,0.118868598746637,39.995735168457,1.99921713248619,15.9972839355469,15.9996948242187,15.9999351501465,-113867.4765625,-113761.4296875,0.41522753238678,1,6,3,4,23.1730000402331,1,20.6550517742417,1.11457824707031,43.9882698059082,39.5894432067871,,,,,,,,,,,,,,,,
,3875471272.94574,16.0001686096191,-120864.046875,,,,,,,,,,,,,-0.511878371465559,2.95010113887403E-5,0.00163560372319156,10,2,,80,2,4015,,,-0.498220557846309,-0.00798877966290495,-0.00303354952484369,0.00110133667476475,,,,0.126401458936783,39.995735168457,1.99911649963572,15.9980230331421,15.9999732971191,16.0003776550293,-120914.5390625,-120813.5546875,0.415528625249863,1,6,3,4,23.1730000402331,1,20.6452967947673,1.12129211425781,43.9882698059082,39.5894432067871,,,,,,,,,,,,,,,,
,3875471412.34481,16.0000625610352,-127909.52734375,,,,,,,,,,,,,-0.5413067133929,2.89059044956884E-5,0.00195370023613075,10,2,,80,2,4083,,,-0.527360611849916,-0.0084988796624757,-0.00321070663630962,0.00116600445471704,,,,0.133788418678439,39.995735168457,1.99901343895668,15.9972686767578,15.999828338623,16.0002250671387,-127959.9453125,-127859.109375,0.415706396102905,1,6,3,4,23.1730000402331,1,20.6461687887242,1.11427307128906,43.9882698059082,39.5894432067871,,,,,,,,,,,,,,,,
,3875471551.76984,16.0001993179321,-134958.984375,,,,,,,,,,,,,-0.569891797318193,2.90239699185182E-5,0.00223682092161022,10,2,,80,2,4151,,,-0.555735276854947,-0.00902595733888464,-0.00338338012807071,0.00122859375551343,,,,0.140981216461042,39.995735168457,1.99893854183892,15.9971075057983,16.0001640319824,16.0002517700195,-135012,-134905.96875,0.415719121694565,1,6,3,4,23.1730000402331,1,20.6371939775981,1.12136840820312,43.9882698059082,39.5894432067871,,,,,,,,,,,,,,,,
,3875471691.17584,15.9997596740723,-139999.7265625,,,,,,,,,,,,,-0.589724728460369,2.61381419194999E-5,0.00244153610234099,10,2,,80,2,4219,,,-0.575465533696568,-0.00938545317062434,-0.00350337522104383,0.00127259292639792,,,,0.145986560194219,39.995735168457,1.99894309222362,15.9962406158447,15.9995803833008,15.9999160766602,-139999.734375,-139999.71875,0.415813058614731,1,4,3,4,23.1730000402331,1,20.6394597301779,1.1224365234375,43.9882698059082,40.0782012939453,,,,,,,,,,,,,,,,
,3875471830.59443,15.9991088867188,-137295.53125,,,,,,,,,,,,,-0.57912038168517,3.27783326303798E-5,0.00230425201760871,10,2,,80,2,4287,,,-0.564911594441607,-0.00922054753665491,-0.00343914330005646,0.00124914152547717,,,,0.143307835043797,39.995735168457,1.99893141513435,15.9971151351929,15.9989929199219,15.9992256164551,-137345.0625,-137246,0.41607666015625,1,6,3,4,23.1730000402331,1,20.6369715111055,1.11473083496094,44.4770278930664,40.0782012939453,,,,,,,,,,,,,,,,
,3875471970.02634,15.9996482849121,-130385.875,,,,,,,,,,,,,-0.551426120932863,3.26147655040457E-5,0.00203068405131909,10,2,,80,2,4355,,,-0.537397430909073,-0.00870781393371986,-0.00327161815948784,0.00118824606761336,,,,0.136326438942009,39.995735168457,1.99891268574986,15.9988956451416,15.9993324279785,15.9998817443848,-130435.4140625,-130336.3359375,0.41614842414856,1,6,3,4,23.1730000402331,1,20.6430103285478,1.12220764160156,43.9882698059082,40.0782012939453,,,,,,,,,,,,,,,,
,3875472109.43416,15.9999786376953,-123473.875,,,,,,,,,,,,,-0.522829512548498,2.65363702033131E-5,0.00175745521305916,10,2,,80,2,4423,,,-0.509056869837824,-0.00817457526483495,-0.00309936446137726,0.00112505559809506,,,,0.129140833465692,39.995735168457,1.99896971270908,15.9993295669556,15.9997138977051,16.0001564025879,-123525.8515625,-123421.8984375,0.416124552488327,1,6,3,4,23.1730000402331,1,20.6410782671192,1.12129211425781,43.9882698059082,39.5894432067871,,,,,,,,,,,,,,,,
,3875472248.84566,15.9999942779541,-116563.71875,,,,,,,,,,,,,-0.493568452080126,2.60182018409808E-5,0.00146909255451517,10,2,,80,2,4491,,,-0.480125484665224,-0.0076456792830889,-0.00292331888340414,0.00106073950883001,,,,0.121801068250682,39.995735168457,1.99895262070689,15.9990720748901,15.9994201660156,16.000316619873,-116615.71875,-116511.71875,0.415981531143188,1,6,3,4,23.1730000402331,1,20.6416096833395,1.12251281738281,43.9882698059082,40.5669593811035,,,,,,,,,,,,,,,,
,3875472388.25677,16.000325012207,-109651.08203125,,,,,,,,,,,,,-0.463756965609409,2.72059605073961E-5,0.00111277051563306,10,2,,80,2,4559,,,-0.450716002478536,-0.00717972373659498,-0.00274429889395833,0.000995654729194939,,,,0.114339948712862,39.995735168457,1.99895517130297,15.9984931945801,16.0002365112305,16.0004043579102,-109700.6171875,-109601.546875,0.416093200445175,1,6,3,4,23.1730000402331,1,20.6389733282728,1.11457824707031,44.4770278930664,40.0782012939453,,,,,,,,,,,,,,,,
,3875472527.6844,16.0002815246582,-102739.7578125,,,,,,,,,,,,,-0.433569150637508,2.09011085593337E-5,0.000841299941035416,10,2,,80,2,4627,,,-0.421002766754641,-0.00663697293106308,-0.00256354501470923,0.00092962896451354,,,,0.106803200777271,39.995735168457,1.9989760966093,15.9969663619995,16.0001220703125,16.0004119873047,-102794.296875,-102685.21875,0.415790975093842,1,6,3,4,23.1730000402331,1,20.6395963225025,1.12136840820312,44.4770278930664,40.5669593811035,,,,,,,,,,,,,,,,
,3875472667.09176,16.0002946853638,-95825.84765625,,,,,,,,,,,,,-0.403206887644403,2.30736920139705E-5,0.000631082754575041,10,2,,80,2,4695,,,-0.391182169398409,-0.00604939488310002,-0.0023823375813663,0.000863140798173845,,,,0.0992423051035438,39.995735168457,1.99909372334532,15.9961700439453,16.0001487731934,16.0004768371582,-95877.9140625,-95773.78125,0.415630280971527,1,6,3,4,23.1730000402331,1,20.6402980088364,1.12220764160156,42.5219955444336,40.0782012939453,,,,,,,,,,,,,,,,
,3875472806.53999,16.0006694793701,-88911.6953125,,,,,,,,,,,,,-0.372770760478854,2.12353038264099E-5,0.000440111232267692,10,2,,80,2,4763,,,-0.361351240431329,-0.00546501092665402,-0.00220092898234725,0.00079664186341688,,,,0.0916750058121874,39.995735168457,1.99912036375629,15.9946622848511,16.0004959106445,16.0008926391602,-88961.265625,-88862.125,0.415541291236877,1,6,3,4,23.1730000402331,1,20.6420147830363,1.121826171875,43.9882698059082,40.5669593811035,,,,,,,,,,,,,,,,
,3875472945.95273,16.0002418518066,-81996.70703125,,,,,,,,,,,,,-0.342443445353095,2.28908321473799E-5,0.000281537779318199,10,2,,80,2,4831,,,-0.331686362860304,-0.00487916002362844,-0.00202051759697497,0.000730668660253286,,,,0.0841514288370043,39.995735168457,1.99919111231784,15.9937191009521,16.0001220703125,16.0003280639648,-82048.796875,-81944.6171875,0.415418237447739,1,6,3,4,23.1730000402331,1,20.6488594938781,1.12075805664062,44.4770278930664,40.5669593811035,,,,,,,,,,,,,,,,
,3875473085.36115,16.0007034301758,-75086.69921875,,,,,,,,,,,,,-0.31236134650951,1.4374407141827E-5,0.000154125656536125,10,2,,80,2,4899,,,-0.302317924935198,-0.00430008541026396,-0.0018418743275106,0.000665053084958345,,,,0.0766980903629147,39.995735168457,1.99913327794358,15.9923753738403,16.000545501709,16.0008392333984,-75136.2890625,-75037.109375,0.415424823760986,1,6,3,4,23.1730000402331,1,20.6488305884198,1.12190246582031,44.4770278930664,40.5669593811035,,,,,,,,,,,,,,,,
,3875473224.76653,16.0007629394531,-68174.29296875,,,,,,,,,,,,,-0.282678154137118,1.9112549054634E-5,5.10264007521281E-5,10,2,,80,2,4967,,,-0.27339149974637,-0.003740506384091,-0.00166596891358495,0.000600550323724747,,,,0.069360180113675,39.995735168457,1.99916562633791,15.990984916687,16.000617980957,16.0008583068848,-68223.9609375,-68124.625,0.415387600660324,1,6,3,4,23.1730000402331,1,20.6498083783419,1.12167358398438,44.4770278930664,40.0782012939453,,,,,,,,,,,,,,,,
,3875473364.17143,16.0004783630371,-61258.623046875,,,,,,,,,,,,,-0.253509962199985,1.92882717111822E-5,-1.56825816604653E-5,10,2,,80,2,5035,,,-0.245015926122889,-0.00319375215455998,-0.00149337353650481,0.000537227489985526,,,,0.0621604557284276,39.995735168457,1.99913509898393,15.989312171936,16.0002784729004,16.0005722045898,-61310.75,-61206.49609375,0.415327996015549,1,6,3,4,23.1730000402331,1,20.649327554794,1.12129211425781,44.4770278930664,40.0782012939453,,,,,,,,,,,,,,,,
,3875473503.58637,15.9998344421387,-54345.466796875,,,,,,,,,,,,,-0.225053242634662,2.01196811354974E-5,-5.14684245178581E-5,10,2,,80,2,5103,,,-0.217376826027792,-0.00267038519536936,-0.00132526818197221,0.000475750071927905,,,,0.0551494054239124,39.995735168457,1.99921005255445,15.9881410598755,15.999755859375,15.9999084472656,-54397.515625,-54293.41796875,0.415235221385956,1,6,3,4,23.1730000402331,1,20.6539033123876,1.12075805664062,44.4770278930664,40.5669593811035,,,,,,,,,,,,,,,,
,3875473643.05348,16.0000862121582,-47428.173828125,,,,,,,,,,,,,-0.197428460550522,1.80289226399152E-5,-6.95928160861787E-5,10,2,,80,2,5171,,,-0.190585307824565,-0.00218597072613234,-0.00116229779087007,0.000416235765442252,,,,0.0483540693672179,39.995735168457,1.99931236536396,15.9883155822754,15.9998893737793,16.0002784729004,-47480.30859375,-47376.0390625,0.415112316608429,1,6,3,4,23.1730000402331,1,20.6564417164734,1.12091064453125,44.4770278930664,40.5669593811035,,,,,,,,,,,,,,,,
,3875473782.44606,15.9996513366699,-40517.841796875,,,,,,,,,,,,,-0.170779970852969,1.48887165062823E-5,-4.79961040479071E-5,10,2,,80,2,5239,,,-0.164775771914876,-0.00172157335104456,-0.00100525526795536,0.00035889123682864,,,,0.0418059697108315,39.995735168457,1.99935234466343,15.9890174865723,15.9993019104004,15.9999160766602,-40567.4296875,-40468.25390625,0.415158689022064,1,6,3,4,23.1730000402331,1,20.6591222133262,1.12228393554688,44.9657897949219,40.5669593811035,,,,,,,,,,,,,,,,
,3875473921.85545,15.9994049072266,-33574.361328125,,,,,,,,,,,,,-0.144955293380491,1.44811068689598E-5,-1.74833057147744E-5,10,2,,80,2,5307,,,-0.139794878694506,-0.00130423790557718,-0.000853125820867717,0.000303558568703011,,,,0.0354653841036888,39.995735168457,1.99925519369946,15.9889602661133,15.9993019104004,15.9995269775391,-33626.703125,-33522.01953125,0.415138691663742,1,6,3,4,23.1730000402331,1,20.6623992451963,1.12190246582031,44.4770278930664,40.5669593811035,,,,,,,,,,,,,,,,
,3875474061.27079,15.9995178222656,-26623.4384765625,,,,,,,,,,,,,-0.119803186609925,1.37618862833908E-5,1.99300495352738E-5,10,2,,80,2,5375,,,-0.11549196046584,-0.000934617619748952,-0.000705186859704554,0.000249909178819507,,,,0.0293029905908589,39.995735168457,1.99943994288722,15.9908885955811,15.9993019104004,15.9997634887695,-26675.791015625,-26571.0859375,0.414951533079147,1,6,3,4,23.1730000402331,1,20.6604155105114,1.12190246582031,44.4770278930664,40.5669593811035,,,,,,,,,,,,,,,,
,3875474200.69432,15.9989433288574,-19669.0419921875,,,,,,,,,,,,,-0.0952218051828424,1.29721326561951E-5,5.58517460950468E-5,10,2,,80,2,5443,,,-0.0917638556925639,-0.000618967227469347,-0.000560539192520082,0.000197835324797779,,,,0.023282075593576,39.995735168457,1.99938484586387,15.9935913085938,15.9987373352051,15.9991874694824,-19718.9296875,-19619.154296875,0.415112763643265,1,6,3,4,23.1730000402331,1,20.6637801593993,1.12220764160156,44.4770278930664,40.0782012939453,,,,,,,,,,,,,,,,
,3875474340.1018,15.9989261627197,-12717.2919921875,,,,,,,,,,,,,-0.0710042673794574,1.15989928145755E-5,7.48406224800457E-5,10,2,,80,2,5511,,,-0.0684064503018672,-0.000369082482443737,-0.000418060430092737,0.000146908772876486,,,,0.0173556085611048,39.995735168457,1.99939796756672,15.9974117279053,15.9988059997559,15.9990348815918,-12767.015625,-12667.568359375,0.415234565734863,1,6,3,4,23.1730000402331,1,20.6630249775879,1.121826171875,44.9657897949219,40.5669593811035,,,,,,,,,,,,,,,,
,3875474479.60665,15.9989799499512,-5753.3984375,,,,,,,,,,,,,-0.0469050347580277,1.10566392615277E-5,9.94931344670798E-5,1,2,,80,2,5579,,,-0.0451790180596913,-0.000159295743231518,-0.000276283069979399,9.65152139542624E-5,,,,0.0114618208899353,39.995735168457,1.99939049192517,16.0004501342773,15.9988899230957,15.9990921020508,-5805.82861328125,-5700.96826171875,0.415148884057999,1,6,3,4,23.1730000402331,1,20.6644511683076,1.12129211425781,44.4770278930664,39.5894432067871,,,,,,,,,,,,,,,,
,3875474619.01291,16.00068359375,1211.73266601562,,,,,,,,,,,,,0.00795860548555225,0.000111427017001227,-1.40268396758462E-5,1,2,,80,2,5647,,,0.00766489743377763,2.64653423285533E-5,4.68739999632817E-5,-1.63713175425073E-5,,,,0.00194479388064291,39.995735168457,1.99938350664059,16.0017929077148,16.0006065368652,16.0007934570313,1159.22521972656,1264.24011230469,0.415071249008179,1,6,3,4,23.1730000402331,1,20.6649465372728,1.12037658691406,44.4770278930664,40.5669593811035,,,,,,,,,,,,,,,,
,3875474758.42443,16.0013252258301,8182.51196289063,,,,,,,,,,,,,0.0547457195530507,1.17503379695115E-5,-0.000109106041870106,1,2,,80,2,5715,,,0.0527349192943892,0.000206768308676327,0.000322435313137248,-0.000112797490146477,,,,0.0133781031900234,39.995735168457,1.99935843236217,15.9999322891235,16.0011672973633,16.0015754699707,8129.97705078125,8235.046875,0.415228575468063,1,6,3,4,23.1730000402331,1,20.6671070151838,1.12098693847656,44.4770278930664,40.0782012939453,,,,,,,,,,,,,,,,
,3875474897.83585,16.000959777832,15155.8564453125,,,,,,,,,,,,,0.0791975867167963,1.1937107906508E-5,-0.000113047704534616,1,2,,80,2,5783,,,0.0763073290876433,0.000406316414605878,0.000466357538243756,-0.000163855758728459,,,,0.019359564442238,39.995735168457,1.99941520221061,15.995192527771,16.0006713867187,16.0013236999512,15105.8466796875,15205.8662109375,0.415142267942429,1,6,3,4,23.1730000402331,1,20.6643538707327,1.11343383789062,44.4770278930664,40.0782012939453,,,,,,,,,,,,,,,,
,3875475037.25272,16.0010459899902,22132.2451171875,,,,,,,,,,,,,0.103694091291187,1.22933356893562E-5,-9.69212364571982E-5,1,2,,80,2,5851,,,0.0999402624824594,0.000671758711188686,0.000610520539339632,-0.000215467094676569,,,,0.0253560801195041,39.995735168457,1.99949623535765,15.9916791915894,16.0008506774902,16.0012817382813,22079.578125,22184.912109375,0.41502434015274,1,6,3,4,23.1730000402331,1,20.6644218465757,1.12228393554688,44.4770278930664,40.0782012939453,,,,,,,,,,,,,,,,
,3875475176.65568,16.0007507324219,29124.669921875,,,,,,,,,,,,,0.128638635513432,1.24293885248971E-5,-7.63528693444325E-5,1,2,,80,2,5919,,,0.124027051697732,0.000992878154363268,0.000757302972488105,-0.000268399249762297,,,,0.0314670219098275,39.995735168457,1.99946276915032,15.9897766113281,16.0005226135254,16.0009002685547,29074.505859375,29174.833984375,0.414998471736908,1,6,3,4,23.1730000402331,1,20.6668061564311,1.12144470214844,43.9882698059082,40.0782012939453,,,,,,,,,,,,,,,,
,3875475316.10569,16.0001287460327,36117.013671875,,,,,,,,,,,,,0.154201524730494,1.67840615678347E-5,-5.55743266976619E-5,1,2,,80,2,5987,,,0.148736702255033,0.00136823299876546,0.000907836074475199,-0.000322997133480385,,,,0.0377382646095852,39.995735168457,1.99955546530483,15.9881792068481,16.0000419616699,16.0002517700195,36064.4453125,36169.58203125,0.414833545684814,1,6,3,4,23.1730000402331,1,20.6682922615774,1.12129211425781,43.9882698059082,40.0782012939453,,,,,,,,,,,,,,,,
,3875475457.59104,16.0002021789551,43212.654296875,,,,,,,,,,,,,0.180980779855663,1.69004306241395E-5,4.65363491941605E-5,10,2,,80,2,6056,,,0.174651887558601,0.00188547023985237,0.00106535758823156,-0.000380994577426463,,,,0.0443147824448063,39.995735168457,1.99945108017023,15.9875755310059,16.0000686645508,16.0004119873047,43160.00390625,43265.3046875,0.414744049310684,1,6,3,4,23.1730000402331,1,20.6700121375651,1.11465454101562,43.9882698059082,40.0782012939453,,,,,,,,,,,,,,,,
,3875475597.01615,16.0000205993652,50204.955078125,,,,,,,,,,,,,0.208358633030487,1.77614578364486E-5,6.76595575590519E-5,10,2,,80,2,6124,,,0.201181432839746,0.00237812717385143,0.00122677499894053,-0.000440124538727105,,,,0.0510467752259175,39.995735168457,1.99948698490343,15.9867849349976,15.9999237060547,16.0002632141113,50154.765625,50255.14453125,0.414736747741699,1,6,3,4,23.1730000402331,1,20.6693811900438,1.11457824707031,43.49951171875,40.0782012939453,,,,,,,,,,,,,,,,
,3875475736.41478,15.9997207641602,57195.125,,,,,,,,,,,,,0.236665352378349,2.08155492986044E-5,5.42233649241578E-5,10,2,,80,2,6192,,,0.228650106031508,0.0028960890071616,0.00139391794800758,-0.000501432514283806,,,,0.0580192628640938,39.995735168457,1.99956907139356,15.9871807098389,15.9994812011719,15.9998817443848,57144.65625,57245.59375,0.414786010980606,1,6,3,4,23.1730000402331,1,20.6698482937063,1.12167358398438,43.9882698059082,40.0782012939453,,,,,,,,,,,,,,,,
,3875475875.82838,16.000358581543,64185.01171875,,,,,,,,,,,,,0.265773214140304,1.98748705186989E-5,1.41760162934816E-5,10,2,,80,2,6260,,,0.256939914557614,0.00344466746058891,0.00156604789663106,-0.000564592715818435,,,,0.0652003921246126,39.995735168457,1.99963083031854,15.989520072937,16.0002098083496,16.000545501709,64134.859375,64235.1640625,0.414704620838165,1,6,3,4,23.1730000402331,1,20.6675908127264,1.12136840820312,43.9882698059082,40.0782012939453,,,,,,,,,,,,,,,,
,3875476015.25747,15.9994064331055,71178.16796875,,,,,,,,,,,,,0.295531508404089,2.27387906682225E-5,-9.08621023653319E-5,10,2,,80,2,6328,,,0.285910769842738,0.00398299271452676,0.00174225866794586,-0.000629300309810787,,,,0.0725525618054778,39.995735168457,1.99962824650107,15.9900932312012,15.9992408752441,15.9995803833008,71125.53125,71230.8046875,0.414791822433472,1,6,3,4,23.1730000402331,1,20.6718846121586,1.12281799316406,43.49951171875,39.5894432067871,,,,,,,,,,,,,,,,
,3875476154.70001,15.999137878418,78183.6640625,,,,,,,,,,,,,0.325838078877516,1.8459208034879E-5,-0.000193933418278276,10,2,,80,2,6396,,,0.315467674260353,0.00457189717592357,0.00192197947762907,-0.000695383932907134,,,,0.0800524642889093,39.995735168457,1.9995940171137,15.9911365509033,15.9987907409668,15.9996337890625,78132.90625,78234.421875,0.414768099784851,1,6,3,4,23.1730000402331,1,20.6705333108808,1.1151123046875,42.5219955444336,40.0782012939453,,,,,,,,,,,,,,,,
,3875476294.10913,15.9993804931641,85252.87109375,,,,,,,,,,,,,0.356773898241467,2.26650285309203E-5,-0.000374054711994808,10,2,,80,2,6464,,,0.345696219279003,0.0051346650645589,0.00210577482357621,-0.000762717449106276,,,,0.0877191937252319,39.995735168457,1.99948206526394,15.9927911758423,15.9991989135742,15.9995536804199,85199.6796875,85306.0625,0.414648830890655,1,6,3,4,23.1730000402331,1,20.669965592645,1.11404418945312,44.4770278930664,39.5894432067871,,,,,,,,,,,,,,,,
,3875476433.51151,15.9998237609863,92318.24609375,,,,,,,,,,,,,0.387876443970004,2.21619663308901E-5,-0.000539976236225608,10,2,,80,2,6532,,,0.37614791914316,0.00574589254276724,0.00229093385860324,-0.000830811564810574,,,,0.0954453690114454,39.995735168457,1.99946469184771,15.9946069717407,15.9996070861816,16.0000305175781,92267.53125,92368.9609375,0.414753645658493,1,6,3,4,23.1730000402331,1,20.6685104585323,1.12220764160156,43.9882698059082,40.0782012939453,,,,,,,,,,,,,,,,
,3875476572.9093,15.9993064880371,99388.57421875,,,,,,,,,,,,,0.4189837578816,2.53259089498018E-5,-0.000737317574013811,10,2,,80,2,6600,,,0.406668379085566,0.00635386407010846,0.00247654784470797,-0.000898884260095656,,,,0.103188718477468,39.995735168457,1.99943069856769,15.9954061508179,15.9991264343262,15.9995613098145,99335.3046875,99441.84375,0.414806038141251,1,6,3,4,23.1730000402331,1,20.6640695581312,1.11503601074219,43.9882698059082,40.0782012939453,,,,,,,,,,,,,,,,
,3875476712.33885,15.9996658325195,106456.02734375,,,,,,,,,,,,,0.449962583058634,2.73552447003308E-5,-0.00101424913677456,10,2,,80,2,6668,,,0.437129310993533,0.00690356855469593,0.00266187777742743,-0.000966506719123572,,,,0.110914689821691,39.995735168457,1.99938030894456,15.99684715271,15.999382019043,15.9998893737793,106402.921875,106509.1328125,0.4149090051651,1,6,3,4,23.1730000402331,1,20.6611603102534,1.11427307128906,45.4545478820801,40.0782012939453,,,,,,,,,,,,,,,,
,3875476851.77768,15.9997718811035,113528.88671875,,,,,,,,,,,,,0.480672171356975,2.83242275488739E-5,-0.00130070476404296,10,2,,80,2,6736,,,0.467392812206337,0.00745504258870949,0.00284600513987243,-0.00103378936182708,,,,0.118592332073848,39.995735168457,1.99935821645877,15.9974451065063,15.9994277954102,15.9998970031738,113475.703125,113582.0703125,0.415016680955887,1,6,3,4,23.1730000402331,1,20.6597524512561,1.12251281738281,43.9882698059082,40.0782012939453,,,,,,,,,,,,,,,,
,3875476991.19082,15.9995796203613,120596.6640625,,,,,,,,,,,,,0.51088996977665,2.35872822574521E-5,-0.00160223182283207,10,2,,80,2,6804,,,0.497240412217915,0.0079925959469879,0.00302752782590687,-0.0011000435333699,,,,0.126160815646359,39.995735168457,1.99927257006229,15.9982347488403,15.9994010925293,15.9997138977051,120543.453125,120649.875,0.415226429700851,1,6,3,4,23.1730000402331,1,20.6579779494498,1.1224365234375,43.9882698059082,40.0782012939453,,,,,,,,,,,,,,,,
,3875477130.60304,16.0003479003906,127664.69921875,,,,,,,,,,,,,0.540425962550276,2.50371490525403E-5,-0.00193040671288359,10,2,,80,2,6872,,,0.526485002831526,0.00849578799575815,0.00320532056502998,-0.00116470165085047,,,,0.133571474792454,39.995735168457,1.99911140122407,15.9979019165039,16.000244140625,16.0004577636719,127611.4609375,127717.9375,0.415472567081451,1,6,3,4,23.1730000402331,1,20.6552849449847,1.12213134765625,43.9882698059082,40.0782012939453,,,,,,,,,,,,,,,,
,3875477270.02033,16.0000396728516,134733.9609375,,,,,,,,,,,,,0.569104725913284,3.40221278770115E-5,-0.00225714720930154,10,2,,80,2,6940,,,0.554951530991927,0.00898302832452863,0.00337842898443341,-0.00122777139768004,,,,0.140788331332747,39.995735168457,1.99902120516998,15.9968328475952,15.999942779541,16.000171661377,134680.71875,134787.203125,0.415465712547302,1,6,3,4,23.1730000402331,1,20.6549267107689,1.12213134765625,44.4770278930664,40.0782012939453,,,,,,,,,,,,,,,,
,3875477409.43687,15.9995491027832,140000.3828125,,,,,,,,,,,,,0.589898617291125,3.75914951585069E-5,-0.00252290625020182,10,2,,80,2,7008,,,0.575636878242626,0.00930954813964391,0.00350433960556984,-0.00127328687813133,,,,0.146032468299358,39.995735168457,1.99896605998386,15.9962940216064,15.9992942810059,15.9999084472656,140000.3125,140000.453125,0.415680170059204,1,4,3,4,23.1730000402331,1,20.6522544144514,1.11373901367188,43.9882698059082,40.0782012939453,,,,,,,,,,,,,,,,
,3875477495.53676,15.9999588012695,140000.6640625,,,,,,,,,,,,,0.58989794037676,3.02268332359248E-5,-0.00248458867391502,10,2,,80,2,7050,,,0.575635474099037,0.00934693156607416,0.00350464414805174,-0.00127348850946873,,,,0.146045647778017,39.995735168457,1.99916382862846,15.9979877471924,15.9998893737793,16.0001029968262,140000.65625,140000.671875,0.41568461060524,1,4,3,4,23.1730000402331,1,20.6498460508413,1.12045288085938,43.9882698059082,40.0782012939453,,,,,,,,,,,,,,,,