File: MPMS/NiCl2btd/NiCl2btd_MvH_8K_14T.dat
[Header]
; ACMS II Data File (default extension .dat)
; Copyright (c) 2014, Quantum Design, Inc. All rights reserved.
TITLE,
FILEOPENTIME,3875444584.879,10/20/2022,4:24 pm
BYAPP,ACMS II,1.0,1.2
INFO,DYNACOOL ACMS II Option Release 1.0.8 Build 33,APPNAME
INFO,Quantum Design Linear Motor Servo Controller,MOTOR_MODULE_NAME
INFO,3101-100 K0,MOTOR_HW_VERSION
INFO,MMC794,MOTOR_SERIAL_NUMBER
INFO,SRV No X-over 01.03.11,MOTOR_SOFTWARE_VERSION
INFO,ACMS,ACMS_MODULE_NAME
INFO,3101-430 A0,ACMS_HW_VERSION
INFO,ACMSII028,ACMS_SERIAL_NUMBER
INFO,00.14.14,ACMS_SOFTWARE_VERSION
INFO,WF046,COIL_SERIAL_NUMBER
INFO,0,MOMENT_UNITS
INFO,NiCl2-btdm,SAMPLE_MATERIAL
INFO,4.8mg cling film,SAMPLE_COMMENT
INFO,22.1,SAMPLE_MASS
INFO,,SAMPLE_VOLUME
INFO,,SAMPLE_MOLECULAR_WEIGHT
INFO,,SAMPLE_SIZE
INFO,,SAMPLE_SHAPE
DATATYPE,COMMENT,1
DATATYPE,TIME,2
STARTUPAXIS,X,2
STARTUPAXIS,Y1,5
STARTUPGROUP, AC
FIELDGROUP, AC, 2,3,4,5,6,7,8,9,10,11,12,13,14,15,16,20,21,22,23,24,25,35,43,44,45,46,47,48,49
FIELDGROUP, DC, 2,3,4,17,18,19,20,21,23,24,25,35,36,37,43,44,45,46,47,48,49,50,51
FIELDGROUP, Diagnostic, 26,27,28,29,30,31,32,33,34,38,39,40,41,42,52,53,54,55,56,57,58,59,60,61,62,63,64,65,66,67,68,69
[Data]
Comment,Time Stamp (sec),Temperature (K),Magnetic Field (Oe),AC Moment (emu),AC Std. Dev. (emu),AC Phase (deg),AC Phase Std. Dev. (deg),AC Suscept. (emu/Oe),AC Suscept. Std. Dev. (emu/Oe),AC X'  (emu/Oe),AC X" (emu/Oe),AC X' Std. Dev. (emu/Oe),AC X" Std. Dev. (emu/Oe),AC Drive (Oe),AC Frequency (Hz),DC Moment (emu),DC Std. Err. (emu),DC Quad. Moment (emu),Range (mV),"AC=1 DC=2 Locate=3",Measure Type,Measure Count,Measure Time (sec),Measure Number,AC X' Raw (emu/Oe),AC X" Raw (emu/Oe),DC M. Raw' (emu),DC M. Raw" (emu),Coil InPhase (V),Coil Quadrature (V),Null Status,Trim Ratio,Trim Phase (deg.),Max. Signal (mV),Motor Frequency (Hz),Motor Ampl. (mm),System Temp. (K),Min. Temperature (K),Max. Temperature (K),Min. Field (Oe),Max. Field (Oe),Pressure (Torr),Temp. Status (code),Field Status (code),Chamber Status (code),Measure Status (code),Center Position (mm),Transport Action,Motor Lag (deg),Motor Current (amps),Motor Heatsink Temp. (C),Motor Board Temp. (C),QMap 01,QMap 02,QMap 03,QMap 04,QMap 05,QMap 06,QMap 07,QMap 08,QMap 09,QMap 10,QMap 11,QMap 12,QMap 13,QMap 14,QMap 15,QMap 16
sample offset = 25.15 mm,3875445282.44752,8.00010681152344,0.640305459499359,,,,,,,,,,,,,0.0378083354416911,2.43973153205261E-6,-6.84905013893798E-5,1,2,,80,2,1,,,0.036412866444879,0.000121184581391655,0.000219943409319967,-7.68280078773387E-5,,,,0.00912480228944625,39.995735168457,1.97426771122663,7.99921941757202,7.99983787536621,8.00063705444336,0.640305459499359,0.640305459499359,0.242023378610611,1,4,3,4,23.1730000402331,1,20.6744339216673,1.11160278320312,32.2580642700195,32.2580642700195,,,,,,,,,,,,,,,,
,3875445428.43017,8.00036544799805,1534.66412353516,,,,,,,,,,,,,0.0424879166383664,1.0897498493904E-5,-0.00011012518563094,1,2,,80,2,69,,,0.0409209246495668,0.000108548098496157,0.000247228832449764,-8.62273809616454E-5,,,,0.0102546433580431,39.995735168457,1.97439109331131,7.99869632720947,8.00021934509277,8.00051689147949,1479.73596191406,1589.59228515625,0.243258833885193,1,6,3,4,23.1730000402331,1,20.6859376014533,1.11473083496094,40.0782012939453,33.7243423461914,,,,,,,,,,,,,,,,
,3875445574.38686,8.00122032165527,8832.6728515625,,,,,,,,,,,,,0.0664860906985178,1.13518200409066E-5,-0.000147805655151955,1,2,,80,2,137,,,0.0640463665288646,0.000241333974815936,0.00038677771226503,-0.000135397698613815,,,,0.0160493074649205,39.995735168457,1.97432695597379,7.99553871154785,8.00108909606934,8.00144958496094,8777.634765625,8887.7109375,0.243369847536087,1,6,3,4,23.1730000402331,1,20.6879124947368,1.11473083496094,42.0332374572754,34.7018585205078,,,,,,,,,,,,,,,,
,3875445720.14691,8.00084543228149,16118.666015625,,,,,,,,,,,,,0.0908480303145374,1.23516982197207E-5,-0.000147350047890596,1,2,,80,2,205,,,0.0875373576266771,0.000460007333800201,0.00052834372036159,-0.000185833472642116,,,,0.0219353739374577,39.995735168457,1.97422846348495,7.99260187149048,8.00071334838867,8.00106430053711,16063.662109375,16173.669921875,0.243379548192024,1,6,3,4,23.1730000402331,1,20.6875311549375,1.11114501953125,42.0332374572754,36.6568908691406,,,,,,,,,,,,,,,,
,3875445863.53317,7.99981918334961,23302.16015625,,,,,,,,,,,,,0.115301656634609,1.38828507698731E-5,-0.000131388609419381,1,2,,80,2,273,,,0.111135750882039,0.000741871006631208,0.000670424138661474,-0.000236867184867151,,,,0.027847767128011,39.995735168457,1.97415571507023,7.99143028259277,7.99971008300781,8.00007629394531,23249.5078125,23354.8125,0.243613958358765,1,6,3,4,23.1730000402331,1,20.6867289541752,1.11686706542969,42.5219955444336,37.6344108581543,,,,,,,,,,,,,,,,
,3875446002.93982,7.9991641998291,30292.3076171875,,,,,,,,,,,,,0.139489176088268,1.47893968410198E-5,-0.000109920921934425,1,2,,80,2,341,,,0.134499784093826,0.0010723738142689,0.00081102637341246,-0.000287723290966824,,,,0.0337030233470245,39.995735168457,1.974212466256,7.9921088218689,7.99883651733398,7.99931907653809,30239.669921875,30344.9453125,0.243673011660576,1,6,3,4,23.1730000402331,1,20.6864583495015,1.116943359375,43.49951171875,38.1231689453125,,,,,,,,,,,,,,,,
,3875446144.46542,7.99908590316772,37390.33203125,,,,,,,,,,,,,0.164414209953575,1.45171082867816E-5,-3.87769738327438E-6,10,2,,80,2,410,,,0.158602527498961,0.00154066921823197,0.000955774507019669,-0.000340882252203301,,,,0.0397438864132485,39.995735168457,1.97414079629998,7.99458837509155,7.99895477294922,7.99917221069336,37340.23828125,37440.42578125,0.243867367506027,1,6,3,4,23.1730000402331,1,20.6828983677519,1.11701965332031,43.0107536315918,38.6119270324707,,,,,,,,,,,,,,,,
,3875446283.87861,7.99845924377441,44381.458984375,,,,,,,,,,,,,0.189425149235692,1.65865970170051E-5,6.10024161943675E-6,10,2,,80,2,478,,,0.18281988423085,0.00196233064037749,0.00110129849053919,-0.000394115137169138,,,,0.0458134257164673,39.995735168457,1.97413165804594,7.99856567382813,7.99839019775391,7.99853515625,44328.76953125,44434.1484375,0.243796139955521,1,6,3,4,23.1730000402331,1,20.6858886655275,1.11137390136719,43.49951171875,39.5894432067871,,,,,,,,,,,,,,,,
,3875446423.31106,7.99838924407959,51371.7890625,,,,,,,,,,,,,0.215025372238194,2.03296161237082E-5,-1.33324509051353E-6,10,2,,80,2,546,,,0.207642244292339,0.00241908509443035,0.00125042023137212,-0.000448737817350775,,,,0.0520325913900699,39.995735168457,1.97409862455227,8.00374126434326,7.99835014343262,7.99847412109375,51319.36328125,51424.21484375,0.244020774960518,1,6,3,4,23.1730000402331,1,20.684436655593,1.11679077148438,43.9882698059082,39.1006851196289,,,,,,,,,,,,,,,,
,3875446562.71368,7.99780282974243,58361.490234375,,,,,,,,,,,,,0.241387117316637,1.81128076028383E-5,-2.78306050829389E-5,10,2,,80,2,614,,,0.233240794224887,0.00291041076146213,0.0014041286194697,-0.000505160889588296,,,,0.0584459765290667,39.995735168457,1.9740147211364,8.00821685791016,7.99768114089966,7.99785470962524,58308.796875,58414.18359375,0.244148075580597,1,6,3,4,23.1730000402331,1,20.6826100321015,1.11412048339844,43.49951171875,39.5894432067871,,,,,,,,,,,,,,,,
,3875446702.11658,7.99763116836548,65350.9453125,,,,,,,,,,,,,0.268682598591771,2.16263104052941E-5,-9.21139163274311E-5,10,2,,80,2,682,,,0.259787165117622,0.00341925908971166,0.00156367651652545,-0.000563653302378953,,,,0.0651012186085223,39.995735168457,1.97410651284672,8.01552867889404,7.99747323989868,7.99785089492798,65298.34375,65403.546875,0.244373634457588,1,6,3,4,23.1730000402331,1,20.6788713150262,1.11274719238281,44.4770278930664,39.5894432067871,,,,,,,,,,,,,,,,
,3875446841.53325,7.9975757598877,72341.92578125,,,,,,,,,,,,,0.297172787569744,2.07593304033864E-5,-0.0001803065139102,10,2,,80,2,750,,,0.287538754108481,0.00396134476599388,0.00173022912349552,-0.000624964421149343,,,,0.0720523173016092,39.995735168457,1.97399739483752,8.0217456817627,7.99739503860474,7.99767351150513,72289.2890625,72394.5625,0.244471088051796,1,6,3,4,23.1730000402331,1,20.6809839625926,1.11282348632812,43.49951171875,40.5669593811035,,,,,,,,,,,,,,,,
,3875446980.97477,7.99748659133911,79362.3125,,,,,,,,,,,,,0.327359040567142,1.83013741062487E-5,-0.000309734416498549,10,2,,80,2,818,,,0.316987565783772,0.00452702274830029,0.00190723338164389,-0.000689759675879031,,,,0.0794340229449169,39.995735168457,1.97406234014645,8.02845573425293,7.99728059768677,7.99759149551392,79308.921875,79415.703125,0.24471877515316,1,6,3,4,23.1730000402331,1,20.6749451480731,1.11045837402344,43.9882698059082,39.5894432067871,,,,,,,,,,,,,,,,
,3875447120.37521,7.99756059646606,86429.4140625,,,,,,,,,,,,,0.361495332474301,2.92242554808625E-5,-0.000475493939648191,10,2,,80,2,886,,,0.350325162457658,0.00515611427322618,0.00210733339190483,-0.000763263029512018,,,,0.0877828274571368,39.995735168457,1.97393438110555,8.03532028198242,7.99742555618286,7.99769639968872,86376.1953125,86482.6328125,0.24494281411171,1,6,3,4,23.1730000402331,1,20.6772454789809,1.11572265625,43.9882698059082,40.0782012939453,,,,,,,,,,,,,,,,
,3875447259.80048,7.99780225753784,93496.9921875,,,,,,,,,,,,,0.396274706422294,2.40780614360775E-5,-0.000718650848438856,10,2,,80,2,954,,,0.384354901068872,0.00575684136820694,0.00231182225979865,-0.000837842759210616,,,,0.0963078990097871,39.995735168457,1.97388516363881,8.04180526733398,7.99773645401001,7.9978814125061,93443.7421875,93550.2421875,0.24504591524601,1,6,3,4,23.1730000402331,1,20.6736460646913,1.11366271972656,43.9882698059082,40.0782012939453,,,,,,,,,,,,,,,,
,3875447399.22456,7.99784440994263,100567.04296875,,,,,,,,,,,,,0.430529072321063,2.83083954453261E-5,-0.00098150560451859,10,2,,80,2,1022,,,0.417945251080885,0.00636071288621384,0.00251364381983876,-0.00091165368212387,,,,0.104724876713025,39.995735168457,1.97387445042359,8.0476655960083,7.99774599075317,7.99794816970825,100516.421875,100617.6640625,0.245248720049858,1,6,3,4,23.1730000402331,1,20.6732826099289,1.11213684082031,43.9882698059082,40.0782012939453,,,,,,,,,,,,,,,,
,3875447538.63649,7.99816579818726,107634.4375,,,,,,,,,,,,,0.464070530696801,2.91769277785437E-5,-0.00127027913447204,10,2,,80,2,1090,,,0.450912940048617,0.00695104167932739,0.00271179154515266,-0.000984120648354292,,,,0.112989369554428,39.995735168457,1.97391574898925,8.05392551422119,7.9980263710022,7.99829292297363,107583.7890625,107685.0859375,0.245271936058998,1,6,3,4,23.1730000402331,1,20.6732740822267,1.11244201660156,43.9882698059082,39.5894432067871,,,,,,,,,,,,,,,,
,3875447678.04679,7.99823538462321,114705.06640625,,,,,,,,,,,,,0.496984986880721,2.96851213442614E-5,-0.00159936921562091,10,2,,80,2,1158,,,0.483340267468238,0.00750839009237197,0.00290663447231054,-0.00105510407593101,,,,0.121111565204873,39.995735168457,1.97385143952799,8.05993461608887,7.99809312820435,7.99839210510254,114651.8515625,114758.28125,0.245478168129921,1,6,3,4,23.1730000402331,1,20.6712379039032,1.11686706542969,44.4770278930664,40.0782012939453,,,,,,,,,,,,,,,,
,3875447817.47855,7.99832201004028,121776.12890625,,,,,,,,,,,,,0.529299082939533,2.79106972826388E-5,-0.00190191703067415,10,2,,80,2,1226,,,0.515249468541673,0.00809147559019188,0.00309830554760993,-0.00112530158367008,,,,0.129106039046947,39.995735168457,1.97383298960913,8.06378364562988,7.99829864501953,7.99836158752441,121725.453125,121826.8046875,0.245607063174248,1,6,3,4,23.1730000402331,1,20.671671122363,1.11244201660156,44.4770278930664,40.0782012939453,,,,,,,,,,,,,,,,
,3875447956.90646,7.999072265625,128843.73046875,,,,,,,,,,,,,0.561045461168217,3.13041063022226E-5,-0.00224505785924859,10,2,,80,2,1294,,,0.546670405334884,0.00862930439094772,0.00328726274892688,-0.00119406939484179,,,,0.136981654682178,39.995735168457,1.97386782325156,8.06772518157959,7.99886322021484,7.99921417236328,128792.9609375,128894.5,0.245629385113716,1,6,3,4,23.1730000402331,1,20.6691556572074,1.10786437988281,44.4770278930664,40.0782012939453,,,,,,,,,,,,,,,,
,3875448096.30057,7.99904289245606,135915.6484375,,,,,,,,,,,,,0.592413743855285,3.73163589211584E-5,-0.00256451770753241,10,2,,80,2,1362,,,0.577784000425988,0.00918289805933475,0.00347406370565295,-0.00126233347691596,,,,0.144770761896406,39.995735168457,1.97377074865559,8.07075119018555,7.99886703491211,7.99915313720703,135862.46875,135968.828125,0.24575375020504,1,6,3,4,23.1730000402331,1,20.6689408898898,1.1126708984375,44.4770278930664,40.0782012939453,,,,,,,,,,,,,,,,
,3875448235.72469,7.99982452392578,140000.6640625,,,,,,,,,,,,,0.610352820503773,2.65607301609729E-5,-0.00277858951383115,10,2,,80,2,1430,,,0.595607800045617,0.00946838837317346,0.00358130061067641,-0.00130133144557476,,,,0.149240086587872,39.995735168457,1.97381433178568,8.07325267791748,7.99966430664062,8.00003433227539,140000.65625,140000.671875,0.245797142386436,1,4,3,4,23.1730000402331,1,20.6691866682639,1.11274719238281,44.4770278930664,40.0782012939453,,,,,,,,,,,,,,,,
,3875448375.12957,8.00064506530762,136368.2890625,,,,,,,,,,,,,0.594404307726164,2.87490578567004E-5,-0.0026285451530083,10,2,,80,2,1498,,,0.579761569467098,0.00917537388229742,0.00348600465804338,-0.00126649800222367,,,,0.14526682488415,39.995735168457,1.97376965265726,8.072678565979,8.00055503845215,8.00072860717773,136316.578125,136420,0.246018797159195,1,6,3,4,23.1730000402331,1,20.6702584802677,1.11541748046875,44.4770278930664,40.0782012939453,,,,,,,,,,,,,,,,
,3875448514.5516,8.00086069107056,129469.36328125,,,,,,,,,,,,,0.563886506288306,2.9721485987304E-5,-0.00228342378157361,10,2,,80,2,1566,,,0.549484999505816,0.00866978858445822,0.0033039606641978,-0.00120000389870256,,,,0.137676177936189,39.995735168457,1.97370364913769,8.06980991363525,8.00079536437988,8.00090408325195,129419.953125,129518.7734375,0.246110931038857,1,6,3,4,23.1730000402331,1,20.6675619460128,1.11686706542969,43.9882698059082,40.5669593811035,,,,,,,,,,,,,,,,
,3875448653.98758,8.00120162963867,122574.38671875,,,,,,,,,,,,,0.532977123713857,3.3596393165911E-5,-0.0019258358860805,10,2,,80,2,1634,,,0.51888487935663,0.00816826178532279,0.00312003260478377,-0.00113324506673962,,,,0.13001327007212,39.995735168457,1.97375624330187,8.06692981719971,8.00100135803223,8.00133323669434,122524.8984375,122623.875,0.24603371322155,1,6,3,4,23.1730000402331,1,20.6703443108405,1.11129760742188,43.9882698059082,40.0782012939453,,,,,,,,,,,,,,,,
,3875448793.39866,8.00176086425781,115675.69140625,,,,,,,,,,,,,0.501642662974143,2.9397658346453E-5,-0.00159233513953622,10,2,,80,2,1702,,,0.487931530491096,0.00763922448888277,0.002934027928859,-0.0010653241770342,,,,0.122256203052843,39.995735168457,1.97375940365949,8.06325531005859,8.0016975402832,8.00180816650391,115623.6484375,115727.734375,0.246063232421875,1,6,3,4,23.1730000402331,1,20.6690188978859,1.11160278320312,43.9882698059082,40.0782012939453,,,,,,,,,,,,,,,,
,3875448932.80311,8.00170850753784,108779.171875,,,,,,,,,,,,,0.469720476322754,3.60691341326415E-5,-0.00128575012270593,10,2,,80,2,1770,,,0.456469710076854,0.00708272864811424,0.0027450614143163,-0.000996246002614498,,,,0.114375971334987,39.995735168457,1.97381545380371,8.05851364135742,8.00162887573242,8.00179100036621,108727.0703125,108831.2734375,0.246144071221352,1,6,3,4,23.1730000402331,1,20.6684494859996,1.11244201660156,43.9882698059082,39.5894432067871,,,,,,,,,,,,,,,,
,3875449072.22865,8.00190963745117,101880.82421875,,,,,,,,,,,,,0.437202162655492,2.79449253865217E-5,-0.00101636033196576,10,2,,80,2,1838,,,0.424493419779132,0.00649463424608934,0.00255285832099617,-0.000925948843359947,,,,0.106359541885411,39.995735168457,1.97375742657838,8.05306720733643,8.00173187255859,8.00209808349609,101831.28125,101930.3671875,0.245893523097038,1,6,3,4,23.1730000402331,1,20.670102039288,1.11259460449219,44.4770278930664,40.5669593811035,,,,,,,,,,,,,,,,
,3875449211.63877,8.00228500366211,94987.734375,,,,,,,,,,,,,0.404007332341086,3.02570409227426E-5,-0.000775626376662191,10,2,,80,2,1906,,,0.391926501515672,0.00588872783393113,0.00235746474936605,-0.000854326877743006,,,,0.0982090653905803,39.995735168457,1.97395428235769,8.0474271774292,8.00214958190918,8.00248527526855,94935.578125,95039.890625,0.245841264724731,1,6,3,4,23.1730000402331,1,20.6697103872446,1.11099243164062,43.9882698059082,40.5669593811035,,,,,,,,,,,,,,,,
,3875449351.06243,8.00212593078613,88086.05078125,,,,,,,,,,,,,0.370149725644512,2.42895580686419E-5,-0.000571210135477284,10,2,,80,2,1974,,,0.358782821824527,0.00526417868286745,0.00215820642188191,-0.000781436450779438,,,,0.0898993920540754,39.995735168457,1.97385739826841,8.04135513305664,8.00200843811035,8.00232124328613,88033.9765625,88138.125,0.245754271745682,1,6,3,4,23.1730000402331,1,20.6739409398924,1.11526489257812,43.9882698059082,40.0782012939453,,,,,,,,,,,,,,,,
,3875449490.49153,8.00189895629883,81190.6484375,,,,,,,,,,,,,0.33613301322448,2.445693074338E-5,-0.000394590093961623,10,2,,80,2,2042,,,0.325551014826239,0.00464447110616793,0.00195864192210138,-0.000708233448676765,,,,0.0815742008091131,39.995735168457,1.97390455622313,8.03431510925293,8.0017261505127,8.00200271606445,81138.5859375,81242.7109375,0.24582140147686,1,6,3,4,23.1730000402331,1,20.6727365130701,1.11068725585938,43.9882698059082,40.5669593811035,,,,,,,,,,,,,,,,
,3875449629.89335,8.00271186828613,74292.4375,,,,,,,,,,,,,0.305443517897086,2.36101625068702E-5,-0.000244577721195629,10,2,,80,2,2110,,,0.295603001429548,0.00408562636023671,0.00177871133200824,-0.000642327591776848,,,,0.07406944890007,39.995735168457,1.97389287604484,8.02840328216553,8.00260162353516,8.00280284881592,74242.8515625,74342.0234375,0.245637074112892,1,6,3,4,23.1730000402331,1,20.6741903221956,1.11114501953125,43.9882698059082,40.0782012939453,,,,,,,,,,,,,,,,
,3875449769.32018,8.00205917358398,67395.41796875,,,,,,,,,,,,,0.276955776141455,1.98911438563587E-5,-0.000143798721971649,10,2,,80,2,2178,,,0.267841256273487,0.00354783410749902,0.00161211006343365,-0.000581078580580652,,,,0.0671174897255225,39.995735168457,1.97403505732654,8.02130699157715,8.00188636779785,8.00222396850586,67345.859375,67444.9765625,0.245385691523552,1,6,3,4,23.1730000402331,1,20.672993645758,1.11473083496094,45.4545478820801,40.0782012939453,,,,,,,,,,,,,,,,
,3875449908.7307,8.00230550765991,60497.958984375,,,,,,,,,,,,,0.249735021663918,1.92881998035539E-5,-6.43718513277798E-5,10,2,,80,2,2246,,,0.241354768967278,0.0030452318523629,0.00145292025990784,-0.000522781745530665,,,,0.0604771027300037,39.995735168457,1.97396426926963,8.01516819000244,8.00224304199219,8.00235939025879,60446.09375,60549.82421875,0.245220899581909,1,6,3,4,23.1730000402331,1,20.6769864819126,1.11351013183594,43.9882698059082,40.0782012939453,,,,,,,,,,,,,,,,
,3875450048.14779,8.00191068649292,53602.841796875,,,,,,,,,,,,,0.223459008958111,2.00475239935404E-5,-1.38514933551617E-7,10,2,,80,2,2314,,,0.215826874463205,0.00258069811634615,0.00129958312027156,-0.000466652738396078,,,,0.0540816767969534,39.995735168457,1.97403154096009,8.00904560089111,8.0018367767334,8.00195121765137,53551.06640625,53654.6171875,0.245150625705719,1,6,3,4,23.1730000402331,1,20.6774662943811,1.1114501953125,43.9882698059082,40.0782012939453,,,,,,,,,,,,,,,,
,3875450187.57947,8.00183258056641,46704.5,,,,,,,,,,,,,0.197992612660618,1.80032252314054E-5,4.67474758829249E-6,10,2,,80,2,2382,,,0.191122525133527,0.00211073847885925,0.00115116126835346,-0.000412260444136336,,,,0.0478912405473852,39.995735168457,1.97402593832974,8.00384998321533,8.00176239013672,8.00189781188965,46655.0703125,46753.9296875,0.2449811398983,1,6,3,4,23.1730000402331,1,20.6814053464012,1.11038208007812,44.4770278930664,40.5669593811035,,,,,,,,,,,,,,,,
,3875450326.9897,8.00119285583496,39809.83984375,,,,,,,,,,,,,0.17316673789351,1.74047677872782E-5,-5.6277243090846E-6,10,2,,80,2,2450,,,0.167073252868648,0.00167725640959403,0.00100665132049471,-0.000359369383659214,,,,0.0418640727695806,39.995735168457,1.97401082304396,7.99939203262329,8.00100135803223,8.00126838684082,39760.41796875,39859.26171875,0.244982689619064,1,6,3,4,23.1730000402331,1,20.6815265823825,1.11175537109375,43.9882698059082,40.5669593811035,,,,,,,,,,,,,,,,
,3875450466.42318,8.00132131576538,32881.33984375,,,,,,,,,,,,,0.148712022893423,1.6011731542965E-5,-2.82887320787906E-5,10,2,,80,2,2518,,,0.14341417935364,0.00128011835698415,0.000864458561409265,-0.000307525449898094,,,,0.035937107039507,39.995735168457,1.97406975486054,7.99587392807007,8.00114059448242,8.00150489807129,32829.18359375,32933.49609375,0.244902640581131,1,6,3,4,23.1730000402331,1,20.6816686212224,1.11236572265625,44.4770278930664,40.0782012939453,,,,,,,,,,,,,,,,
,3875450605.81852,8.00046844482422,25948.2333984375,,,,,,,,,,,,,0.124622579550408,1.37294756937321E-5,-6.22278754482244E-5,10,2,,80,2,2586,,,0.120135625344675,0.000921555424187856,0.000724462268408388,-0.000256735715083778,,,,0.0301044864971024,39.995735168457,1.97411550695342,7.99375343322754,8.00037002563477,8.00055694580078,25895.875,26000.591796875,0.244811177253723,1,6,3,4,23.1730000402331,1,20.6842553555053,1.11557006835938,44.9657897949219,40.0782012939453,,,,,,,,,,,,,,,,
,3875450745.24438,7.99985008239746,19015.6416015625,,,,,,,,,,,,,0.100889085637965,1.214877400123E-5,-8.95821122419424E-5,10,2,,80,2,2654,,,0.0972240592135777,0.000618498934564338,0.00058654003078118,-0.000207007280550897,,,,0.0243619530420963,39.995735168457,1.97404934560083,7.99278593063354,7.99970626831055,7.99996185302734,18963.509765625,19067.7734375,0.244740232825279,1,6,3,4,23.1730000402331,1,20.6853502155169,1.11228942871094,44.4770278930664,40.5669593811035,,,,,,,,,,,,,,,,
,3875450884.64209,7.99950370788574,12080.5454101562,,,,,,,,,,,,,0.0775721701246276,1.12301741107456E-5,-0.000110474703203662,10,2,,80,2,2722,,,0.0747335436236927,0.00036999922378372,0.000451109110144898,-0.000158486756845377,,,,0.0187273668277541,39.995735168457,1.97417741720195,7.99380445480347,7.99936485290527,7.99972724914551,12030.8212890625,12130.26953125,0.244756951928139,1,6,3,4,23.1730000402331,1,20.684479313701,1.11190795898438,44.4770278930664,40.0782012939453,,,,,,,,,,,,,,,,
,3875451024.14587,7.99887990951538,5133.70629882812,,,,,,,,,,,,,0.0548059783297299,1.05271248912834E-5,-0.000134569734120496,1,2,,80,2,2790,,,0.0527891613700351,0.000165226604483308,0.000318843231070787,-0.000111368841317017,,,,0.0132274266156874,39.995735168457,1.97414781306234,7.99593162536621,7.99882125854492,7.99895477294922,5081.0771484375,5186.33544921875,0.244843065738678,1,6,3,4,23.1730000402331,1,20.6848776778223,1.11129760742188,44.4770278930664,40.5669593811035,,,,,,,,,,,,,,,,
,3875451163.54774,8.00000915527344,-1809.80035400391,,,,,,,,,,,,,0.0322202666335202,1.02406577751686E-5,-8.62066808966221E-5,1,2,,80,2,2858,,,0.0310321415915618,8.04338062784949E-5,0.000187468845979311,-6.53632159810513E-5,,,,0.00777587094841201,39.995735168457,1.97415093052872,7.99844551086426,7.99996757507324,8.00002861022949,-1859.5986328125,-1760.00207519531,0.244979530572891,1,6,3,4,23.1730000402331,1,20.6835990748006,1.11259460449219,44.4770278930664,39.5894432067871,,,,,,,,,,,,,,,,
,3875451302.97685,8.00122165679932,-8762.9580078125,,,,,,,,,,,,,-0.0309832472737545,3.00942297747343E-5,6.55067306644763E-5,1,2,,80,2,2926,,,-0.0298462230431754,-0.00011547389852056,-0.000180199087481014,6.3097664678935E-5,,,,0.00747741334949649,39.995735168457,1.97389992258717,7.99533128738403,8.00112533569336,8.00131797790527,-8815.296875,-8710.619140625,0.244954615831375,1,6,3,4,23.1730000402331,1,20.6866956700578,1.11251831054688,45.4545478820801,40.0782012939453,,,,,,,,,,,,,,,,
,3875451442.37222,8.00076904296875,-15714.095703125,,,,,,,,,,,,,-0.077746567387979,1.66559815241216E-5,0.000136392979894594,1,2,,80,2,2994,,,-0.074912165800838,-0.000379902955668133,-0.000452141248388216,0.000158928683958948,,,,0.0187701091372448,39.995735168457,1.97408121413797,7.99294757843018,8.00062561035156,8.00083351135254,-15766.482421875,-15661.708984375,0.244846001267433,1,6,3,4,23.1730000402331,1,20.686526548859,1.1126708984375,44.4770278930664,40.0782012939453,,,,,,,,,,,,,,,,
,3875451581.79438,8.00006332397461,-22674.486328125,,,,,,,,,,,,,-0.108293149760544,1.51679387023675E-5,0.000130756504703103,1,2,,80,2,3062,,,-0.104377280475382,-0.000680934793935987,-0.0006296630599536,0.000222347545786761,,,,0.0261533991783853,39.995735168457,1.97406817049435,7.99174642562866,7.99998474121094,8.0001335144043,-22726.93359375,-22622.0390625,0.244820103049278,1,6,3,4,23.1730000402331,1,20.6858373621171,1.11114501953125,43.9882698059082,40.0782012939453,,,,,,,,,,,,,,,,
,3875451721.21256,7.9986198425293,-29647.958984375,,,,,,,,,,,,,-0.134895927040999,1.39069490532525E-5,0.000111795313527481,1,2,,80,2,3130,,,-0.130066025171469,-0.00102026816258338,-0.000784322677645832,0.000278105580946431,,,,0.0325917567800568,39.995735168457,1.97417898709231,7.99132966995239,7.99851226806641,7.99871253967285,-29697.828125,-29598.08984375,0.244999051094055,1,6,3,4,23.1730000402331,1,20.6844824510526,1.1151123046875,43.9882698059082,40.0782012939453,,,,,,,,,,,,,,,,
,3875451860.64477,7.99919166564941,-36620.833984375,,,,,,,,,,,,,-0.160447722783196,1.54602063059315E-5,9.5353850329227E-5,1,2,,80,2,3198,,,-0.154769202842245,-0.00139866196324167,-0.000932845810893923,0.00033206949592568,,,,0.0387804149703777,39.995735168457,1.97409079311125,7.99472856521606,7.99909400939941,7.99928665161133,-36673.34375,-36568.32421875,0.244697749614716,1,6,3,4,23.1730000402331,1,20.6870669337838,1.11396789550781,43.9882698059082,40.0782012939453,,,,,,,,,,,,,,,,
,3875452002.13515,7.99853591918945,-43696.259765625,,,,,,,,,,,,,-0.186281593315813,1.78251511294468E-5,-1.27096444005413E-5,10,2,,80,2,3267,,,-0.1797766827553,-0.00191920070260942,-0.00108289590571076,0.000387512554880232,,,,0.0450468658218837,39.995735168457,1.97399139916966,7.99802303314209,7.99831581115723,7.99873161315918,-43748.90625,-43643.61328125,0.244824603199959,1,6,3,4,23.1730000402331,1,20.6884281691606,1.11236572265625,43.9882698059082,41.055721282959,,,,,,,,,,,,,,,,
,3875452141.5452,7.99807024002075,-50666.033203125,,,,,,,,,,,,,-0.212045982147896,1.85948381953216E-5,-2.62633281202114E-5,10,2,,80,2,3335,,,-0.204752902839517,-0.00239245260943326,-0.00123311288189143,0.000442663062131032,,,,0.051314045039929,39.995735168457,1.97431997921094,8.00222110748291,7.99798440933228,7.99815988540649,-50718.62890625,-50613.4375,0.24496591091156,1,6,3,4,23.1730000402331,1,20.6880814018922,1.11724853515625,43.9882698059082,40.0782012939453,,,,,,,,,,,,,,,,
,3875452280.95895,7.9978756904602,-57636.998046875,,,,,,,,,,,,,-0.238430627955739,1.85048863148855E-5,1.27964079158446E-5,10,2,,80,2,3403,,,-0.230368826700831,-0.00286664593903732,-0.00138706516008824,0.000499111949466169,,,,0.0577362521924408,39.995735168457,1.974386564457,8.0079402923584,7.9977765083313,7.99803018569946,-57689.5390625,-57584.45703125,0.245146259665489,1,6,3,4,23.1730000402331,1,20.687871263384,1.11625671386719,43.9882698059082,39.5894432067871,,,,,,,,,,,,,,,,
,3875452420.37383,7.99777746200562,-64609.087890625,,,,,,,,,,,,,-0.26562668740574,2.04166723116168E-5,8.00618042687573E-5,10,2,,80,2,3471,,,-0.256813697550712,-0.00336629398828173,-0.0015459043206647,0.000557438295800239,,,,0.064363743743916,39.995735168457,1.97435147466737,8.01434230804443,7.99773073196411,7.99780702590942,-64664.23046875,-64553.9453125,0.245198532938957,1,6,3,4,23.1730000402331,1,20.6882299184803,1.11160278320312,43.9882698059082,40.0782012939453,,,,,,,,,,,,,,,,
,3875452559.78168,7.99751329421997,-71579.24609375,,,,,,,,,,,,,-0.2939408383572,2.10196018032187E-5,0.000175140036428966,10,2,,80,2,3539,,,-0.284388924075373,-0.00389428504487094,-0.00171147321816534,0.000618301040958613,,,,0.0712730918282196,39.995735168457,1.97427520610579,8.02122974395752,7.99738359451294,7.99762964248657,-71629.390625,-71529.1015625,0.245330169796944,1,6,3,4,23.1730000402331,1,20.6890472861275,1.11183166503906,43.9882698059082,40.0782012939453,,,,,,,,,,,,,,,,
,3875452699.23651,7.99756097793579,-78572.11328125,,,,,,,,,,,,,-0.323842448195611,1.47646978034358E-5,0.000272655789714097,10,2,,80,2,3607,,,-0.313554547002916,-0.00448154148443596,-0.0018866261234507,0.000682740937918425,,,,0.0785823467538347,39.995735168457,1.97426244602267,8.02804565429688,7.99746179580689,7.99779748916626,-78622.765625,-78521.4609375,0.245441123843193,1,6,3,4,23.1730000402331,1,20.6859513294809,1.11495971679688,44.4770278930664,39.5894432067871,,,,,,,,,,,,,,,,
,3875452838.64166,7.99773416519165,-85617.94140625,,,,,,,,,,,,,-0.357465100381448,2.9506487085531E-5,0.000445314575962759,10,2,,80,2,3675,,,-0.346386519125338,-0.00509102144350282,-0.00208392576314509,0.000754877750296146,,,,0.0868096874998902,39.995735168457,1.97423986513886,8.0344409942627,7.99759149551392,7.99783754348755,-85668.4296875,-85567.453125,0.245579853653908,1,6,3,4,23.1730000402331,1,20.6806795029601,1.11648559570312,43.9882698059082,40.0782012939453,,,,,,,,,,,,,,,,
,3875452978.05534,7.99757719039917,-92667.65625,,,,,,,,,,,,,-0.392178659927216,2.59054952328937E-5,0.000655944402086376,10,2,,80,2,3743,,,-0.380343124182173,-0.00571752337480992,-0.00228791893459857,0.000829457712825388,,,,0.095316206887067,39.995735168457,1.97416235669598,8.04098129272461,7.99749231338501,7.99762582778931,-92720.859375,-92614.453125,0.245886817574501,1,6,3,4,23.1730000402331,1,20.6766694277271,1.11297607421875,43.9882698059082,39.5894432067871,,,,,,,,,,,,,,,,
,3875453117.46925,7.99787530899048,-99714.6796875,,,,,,,,,,,,,-0.426409155176215,2.44606955161663E-5,0.000896922217454453,10,2,,80,2,3811,,,-0.413900518850903,-0.00633800845989602,-0.00248942244797945,0.000903180916793644,,,,0.10372028950663,39.995735168457,1.9740377482287,8.0472354888916,7.99780702590942,7.99793481826782,-99767.890625,-99661.46875,0.245989352464676,1,6,3,4,23.1730000402331,1,20.6742492807039,1.11442565917969,44.4770278930664,40.0782012939453,,,,,,,,,,,,,,,,
,3875453256.8898,7.99783029556274,-106761.08984375,,,,,,,,,,,,,-0.459963626281744,3.13587176903696E-5,0.00121681861344343,10,2,,80,2,3879,,,-0.446871831021014,-0.00689496224353231,-0.00268760579638183,0.00097524473676458,,,,0.111980270024451,39.995735168457,1.97397981464714,8.05306529998779,7.99771928787231,7.99798822402954,-106814.0625,-106708.1171875,0.246093928813934,1,6,3,4,23.1730000402331,1,20.6706160636437,1.11122131347656,43.9882698059082,40.0782012939453,,,,,,,,,,,,,,,,
,3875453396.30229,7.99806604385376,-113808.1015625,,,,,,,,,,,,,-0.492810061771815,3.22196940811347E-5,0.00152315029833814,10,2,,80,2,3947,,,-0.479222781671486,-0.00747048406968179,-0.00288217957131565,0.00104606943204999,,,,0.120090732938755,39.995735168457,1.9740289219027,8.05886650085449,7.99799203872681,7.998131275177,-113861.1484375,-113755.0546875,0.246329888701439,1,6,3,4,23.1730000402331,1,20.665355944193,1.11175537109375,44.4770278930664,39.5894432067871,,,,,,,,,,,,,,,,
,3875453535.73805,7.99860038757324,-120860.01171875,,,,,,,,,,,,,-0.525122914611901,2.9306943697381E-5,0.00186072561099263,10,2,,80,2,4015,,,-0.511121782235329,-0.00801765797674303,-0.0030737763736397,0.00111571874003857,,,,0.128075501549279,39.995735168457,1.9738830497399,8.06333827972412,7.99844551086426,7.99874877929688,-120912.8359375,-120807.1875,0.246385544538498,1,6,3,4,23.1730000402331,1,20.6615813604964,1.11419677734375,43.9882698059082,40.0782012939453,,,,,,,,,,,,,,,,
,3875453675.15008,7.99889106750488,-127905.828125,,,,,,,,,,,,,-0.556828285625435,2.73132022521699E-5,0.00219266082793576,10,2,,80,2,4083,,,-0.542492812727212,-0.00856443525230546,-0.00326228933408856,0.00118429900612682,,,,0.13593227701428,39.995735168457,1.97382021292627,8.06698989868164,7.99877738952637,7.99904060363769,-127958.78125,-127852.875,0.246592923998833,1,6,3,4,23.1730000402331,1,20.6581956069009,1.1163330078125,44.4770278930664,40.5669593811035,,,,,,,,,,,,,,,,
,3875453814.56172,7.99839143753052,-134954.75,,,,,,,,,,,,,-0.588131636379455,3.77607282370746E-5,0.00254834856032597,10,2,,80,2,4151,,,-0.573534035793307,-0.00908090900538883,-0.00344872265122831,0.0012520095333457,,,,0.143700130695441,39.995735168457,1.97368761532963,8.07056522369385,7.997642993927,7.99865341186523,-135005.21875,-134904.28125,0.246586620807648,1,6,3,4,23.1730000402331,1,20.6560002892351,1.11244201660156,43.9882698059082,39.5894432067871,,,,,,,,,,,,,,,,
,3875453953.98093,7.9998025894165,-139999.71875,,,,,,,,,,,,,-0.610282676432328,3.05894390250938E-5,0.00278144542212479,10,2,,80,2,4219,,,-0.595539338737896,-0.00946417068683128,-0.00358113553375006,0.00129988044500351,,,,0.149214377731501,39.995735168457,1.97370184297124,8.07249546051025,7.99966430664062,7.99995994567871,-139999.734375,-139999.703125,0.246605291962624,1,4,3,4,23.1730000402331,1,20.6498256511393,1.11297607421875,43.49951171875,40.0782012939453,,,,,,,,,,,,,,,,
,3875454093.38256,8.00058059692383,-137292.765625,,,,,,,,,,,,,-0.598415774608746,3.10483004529783E-5,0.00263177377121476,10,2,,80,2,4287,,,-0.583746046865803,-0.00928325647906333,-0.00351003906689584,0.00127425941172987,,,,0.146254431449102,39.995735168457,1.97363199477694,8.0723934173584,8.00035285949707,8.00086784362793,-137344.84375,-137240.6875,0.246749311685562,1,6,3,4,23.1730000402331,1,20.6518639276288,1.11068725585938,43.9882698059082,40.0782012939453,,,,,,,,,,,,,,,,
,3875454232.80536,8.0006778717041,-130378.6640625,,,,,,,,,,,,,-0.567847233759547,2.80723233739297E-5,0.00232404940389528,10,2,,80,2,4355,,,-0.553412154064931,-0.00874010846299533,-0.00332791800610721,0.00120762304868549,,,,0.13865924775753,39.995735168457,1.97370129403956,8.07060050964355,8.00060272216797,8.00077819824219,-130430.8046875,-130326.5234375,0.246744677424431,1,6,3,4,23.1730000402331,1,20.6502347606006,1.11190795898438,44.4770278930664,40.5669593811035,,,,,,,,,,,,,,,,
,3875454372.2352,8.0013632774353,-123468.7109375,,,,,,,,,,,,,-0.536936742786792,2.27261070480366E-5,0.00199311638824338,10,2,,80,2,4423,,,-0.522802733335492,-0.00821190754766385,-0.00314398016780615,0.00114056130405515,,,,0.130991933620198,39.995735168457,1.97372295270236,8.0677375793457,8.00117111206055,8.00155639648438,-123520.8359375,-123416.5859375,0.246832683682442,1,6,3,4,23.1730000402331,1,20.6500680703106,1.11167907714844,43.9882698059082,40.5669593811035,,,,,,,,,,,,,,,,
,3875454511.66108,8.00163307189942,-116556.46484375,,,,,,,,,,,,,-0.505595378249525,3.26427955764035E-5,0.00164456287716593,10,2,,80,2,4491,,,-0.491833637804489,-0.00769610143741831,-0.00295765744522214,0.00107286078855395,,,,0.123228047269106,39.995735168457,1.97364418412319,8.0637092590332,8.0015754699707,8.00171661376953,-116605.9453125,-116506.984375,0.246759563684463,1,6,3,4,23.1730000402331,1,20.6516547377799,1.11122131347656,44.4770278930664,40.0782012939453,,,,,,,,,,,,,,,,
,3875454651.06507,8.00187492370605,-109646.01171875,,,,,,,,,,,,,-0.473718558666303,2.50858334625342E-5,0.00132201271416981,10,2,,80,2,4559,,,-0.460406796234527,-0.00715392374875179,-0.00276881689205766,0.00100406201090664,,,,0.115355413515618,39.995735168457,1.97368412078788,8.05908298492432,8.0018367767334,8.00193214416504,-109695.6640625,-109596.359375,0.246783643960953,1,6,3,4,23.1730000402331,1,20.6524640914623,1.11175537109375,43.9882698059082,40.5669593811035,,,,,,,,,,,,,,,,
,3875454790.49499,8.00189094543457,-102731.6640625,,,,,,,,,,,,,-0.44120096454259,2.52488317215669E-5,0.00105403022637254,10,2,,80,2,4627,,,-0.428422280841897,-0.00656162830953941,-0.00257681543007493,0.000933787145186216,,,,0.10734725983735,39.995735168457,1.97380132045653,8.05352210998535,8.00175285339356,8.00201797485352,-102783.703125,-102679.625,0.246627703309059,1,6,3,4,23.1730000402331,1,20.6524539111935,1.11030578613281,44.4770278930664,40.5669593811035,,,,,,,,,,,,,,,,
,3875454929.90456,8.00203323364258,-95821.68359375,,,,,,,,,,,,,-0.408033195049063,2.95090600940958E-5,0.000800247700265515,10,2,,80,2,4695,,,-0.39587253358431,-0.00596522110081626,-0.00238112593069673,0.000862373504787683,,,,0.0991879290294053,39.995735168457,1.97374634042012,8.04758739471436,8.00197792053223,8.00211334228516,-95871.3828125,-95771.984375,0.246486246585846,1,6,3,4,23.1730000402331,1,20.6559900248282,1.10984802246094,44.9657897949219,40.5669593811035,,,,,,,,,,,,,,,,
,3875455069.33093,8.00215492248535,-88905.13671875,,,,,,,,,,,,,-0.37416095091518,2.79756124019349E-5,0.000585558426183336,10,2,,80,2,4763,,,-0.362705929149964,-0.00534613279207513,-0.0021819993853569,0.000789450714364648,,,,0.0908822531389994,39.995735168457,1.97385713881661,8.04204654693603,8.00210571289063,8.00218391418457,-88954.671875,-88855.6015625,0.246399343013763,1,6,3,4,23.1730000402331,1,20.6561439850769,1.11259460449219,44.4770278930664,40.0782012939453,,,,,,,,,,,,,,,,
,3875455208.76187,8.00216245651245,-81989.7734375,,,,,,,,,,,,,-0.339992857554661,2.63150588154193E-5,0.000400084204627925,10,2,,80,2,4831,,,-0.329318961405492,-0.00472762678701732,-0.00198133010417223,0.00071610405575484,,,,0.0825149047761114,39.995735168457,1.97381244128856,8.03549289703369,8.00193786621094,8.00235557556152,-82041.84375,-81937.703125,0.246232524514198,1,6,3,4,23.1730000402331,1,20.6590979671439,1.11122131347656,44.4770278930664,40.5669593811035,,,,,,,,,,,,,,,,
,3875455348.17411,8.00206260681152,-75079.25390625,,,,,,,,,,,,,-0.308730095616908,2.03221537566824E-5,0.000262351425680056,10,2,,80,2,4899,,,-0.298808998739529,-0.00414378225875668,-0.0017981706187129,0.00064892356749624,,,,0.0748740343341798,39.995735168457,1.97392569671112,8.0291166305542,8.00196838378906,8.00214958190918,-75128.890625,-75029.6171875,0.245939329266548,1,6,3,4,23.1730000402331,1,20.6593820251853,1.11480712890625,43.9882698059082,40.5669593811035,,,,,,,,,,,,,,,,
,3875455487.57856,8.00280475616455,-68166.44140625,,,,,,,,,,,,,-0.280039900071018,1.71737852041938E-5,0.000172247659158194,10,2,,80,2,4967,,,-0.270845192045679,-0.00358807463124484,-0.00163027679082006,0.000587248126976192,,,,0.0678689391255278,39.995735168457,1.97399238668456,8.0228385925293,8.0027494430542,8.00284481048584,-68216.0859375,-68116.796875,0.245963841676712,1,6,3,4,23.1730000402331,1,20.6611223496749,1.11160278320312,44.4770278930664,40.5669593811035,,,,,,,,,,,,,,,,
,3875455626.98975,8.00193023681641,-61248.544921875,,,,,,,,,,,,,-0.25261559563585,1.81874163771771E-5,7.26322702257738E-5,10,2,,80,2,5035,,,-0.244155885809995,-0.00309731203505213,-0.0014699111925438,0.000528676784597337,,,,0.0611822397480068,39.995735168457,1.97404362437342,8.01608371734619,8.00178337097168,8.00202941894531,-61298.140625,-61198.94921875,0.245992705225945,1,6,3,4,23.1730000402331,1,20.6655167102951,1.11587524414062,44.4770278930664,40.5669593811035,,,,,,,,,,,,,,,,
,3875455766.40213,8.00219535827637,-54335.46875,,,,,,,,,,,,,-0.226191091764465,1.42382799035439E-5,2.76477537718626E-5,10,2,,80,2,5103,,,-0.218479719979554,-0.00260737325495927,-0.00131570862140506,0.000472141371574253,,,,0.0547495961229844,39.995735168457,1.97411761081542,8.01016330718994,8.00208473205566,8.00232124328613,-54385.046875,-54285.890625,0.245539098978043,1,6,3,4,23.1730000402331,1,20.6671510264415,1.11000061035156,44.4770278930664,41.055721282959,,,,,,,,,,,,,,,,
,3875455905.8365,8.00209140777588,-47420.935546875,,,,,,,,,,,,,-0.20058358349845,1.54215786985775E-5,-7.11544173938214E-6,10,2,,80,2,5171,,,-0.19363440679645,-0.00215976661387619,-0.00116638431791216,0.000417561386711895,,,,0.0485222317774832,39.995735168457,1.97410267049654,8.0043420791626,8.00199699401855,8.00222778320312,-47473.0703125,-47368.80078125,0.245421528816223,1,6,3,4,23.1730000402331,1,20.6685404440228,1.11572265625,44.9657897949219,40.5669593811035,,,,,,,,,,,,,,,,
,3875456045.26333,8.00157775878906,-40508.470703125,,,,,,,,,,,,,-0.175631767429931,1.72261469717332E-5,1.02306434306288E-6,10,2,,80,2,5239,,,-0.169459789421325,-0.00172207101141827,-0.00102112651802599,0.000364436360541731,,,,0.0424647411663541,39.995735168457,1.97413487298097,8.00034046173096,8.00147247314453,8.00174522399902,-40560.60546875,-40456.3359375,0.245331406593323,1,6,3,4,23.1730000402331,1,20.6694691710532,1.11473083496094,44.4770278930664,40.5669593811035,,,,,,,,,,,,,,,,
,3875456184.67872,8.00128707885742,-33564.548828125,,,,,,,,,,,,,-0.151095223845206,1.47425894974563E-5,2.4932187120325E-5,10,2,,80,2,5307,,,-0.145718593164373,-0.00131805521350542,-0.000878345337696374,0.000312459655106068,,,,0.0365140030724628,39.995735168457,1.97405511571218,7.99660062789917,8.0009822845459,8.00142478942871,-33614.390625,-33514.70703125,0.245318278670311,1,6,3,4,23.1730000402331,1,20.6744972916322,1.11557006835938,44.4770278930664,40.5669593811035,,,,,,,,,,,,,,,,
,3875456324.08484,8.00083875656128,-26613.40625,,,,,,,,,,,,,-0.12690321564864,1.34813581233199E-5,6.13037344632754E-5,10,2,,80,2,5375,,,-0.122338474837867,-0.000951445195564504,-0.000737763417419046,0.000261400971794501,,,,0.0306563418874201,39.995735168457,1.97411907644419,7.99412250518799,8.00078582763672,8.00088310241699,-26663.265625,-26563.546875,0.245108023285866,1,6,3,4,23.1730000402331,1,20.6748303702714,1.10984802246094,44.9657897949219,40.5669593811035,,,,,,,,,,,,,,,,
,3875456463.50322,8.00004768371582,-19658.7001953125,,,,,,,,,,,,,-0.103069208377397,1.21512856717992E-5,8.39145940575372E-5,10,2,,80,2,5443,,,-0.0993278016119987,-0.00064753808028923,-0.00059927033726126,0.000211494072573259,,,,0.0248909382474716,39.995735168457,1.97417131411775,7.99264669418335,7.99991416931152,8.00017356872559,-19711.08984375,-19606.310546875,0.245030984282494,1,6,3,4,23.1730000402331,1,20.6758002906332,1.11549377441406,44.9657897949219,40.5669593811035,,,,,,,,,,,,,,,,
,3875456602.92139,7.99936819076538,-12707.736328125,,,,,,,,,,,,,-0.079652577513899,1.09220276125361E-5,0.000102738989791826,10,2,,80,2,5511,,,-0.0767395115124335,-0.000396098227688355,-0.000463214877527207,0.000162775584612973,,,,0.0192303084651707,39.995735168457,1.97421215025152,7.99326658248901,7.99930572509766,7.99946784973145,-12760.0078125,-12655.46484375,0.244989410042763,1,6,3,4,23.1730000402331,1,20.6763440621825,1.11602783203125,44.4770278930664,39.5894432067871,,,,,,,,,,,,,,,,
,3875456742.40867,7.99912166595459,-5746.45092773438,,,,,,,,,,,,,-0.0567678303369249,1.04777114231497E-5,0.000135094801517659,1,2,,80,2,5579,,,-0.0546797123875718,-0.000178793311439832,-0.000330253387801349,0.000115362250653561,,,,0.0137009254090698,39.995735168457,1.97410912038323,7.99611759185791,7.99908638000488,7.99917602539063,-5798.90478515625,-5693.9970703125,0.245141431689262,1,6,3,4,23.1730000402331,1,20.6780920294636,1.114501953125,44.4770278930664,40.5669593811035,,,,,,,,,,,,,,,,
,3875456881.80463,7.99979667663574,1218.77813720703,,,,,,,,,,,,,-0.03416845790741,1.07032996593571E-5,8.69861495677006E-5,1,2,,80,2,5647,,,-0.0329080850638309,-8.79765045176863E-5,-0.000198809269932099,6.93013353156857E-5,,,,0.00824595556927886,39.995735168457,1.97417792979258,7.99844360351562,7.9996452331543,7.99995994567871,1166.26379394531,1271.29248046875,0.245157763361931,1,6,3,4,23.1730000402331,1,20.6748588190054,1.11236572265625,44.4770278930664,43.0107536315918,,,,,,,,,,,,,,,,
,3875457021.21947,8.00120162963867,8189.3564453125,,,,,,,,,,,,,0.0252376290327693,3.31311442518655E-5,-5.7423454215139E-5,1,2,,80,2,5715,,,0.024311040722999,8.85545220468435E-5,0.000146818085340783,-5.13461600348819E-5,,,,0.00609104196143242,39.995735168457,1.97415620743602,7.99570083618164,8.00103759765625,8.00130653381348,8137.0048828125,8241.7080078125,0.245121970772743,1,6,3,4,23.1730000402331,1,20.6777740750438,1.11503601074219,44.4770278930664,40.5669593811035,,,,,,,,,,,,,,,,
,3875457160.63504,8.00079841613769,15162.4555664062,,,,,,,,,,,,,0.0749675667000418,1.67731171374594E-5,-0.000125183555779908,1,2,,80,2,5783,,,0.0722328321468329,0.000367391527524213,0.0004359683371149,-0.000153214306919836,,,,0.0180981641395387,39.995735168457,1.974031371239,7.99263477325439,8.00060272216797,8.00094413757324,15112.4365234375,15212.474609375,0.2450140863657,1,6,3,4,23.1730000402331,1,20.6822149328929,1.11373901367188,44.4770278930664,41.055721282959,,,,,,,,,,,,,,,,
,3875457300.0498,8.0001163482666,22143.9296875,,,,,,,,,,,,,0.106179886206452,1.49371630492584E-5,-0.000127624551297742,1,2,,80,2,5851,,,0.102337781434084,0.000660973669828119,0.000617462443187833,-0.000217882814467885,,,,0.0256445315473374,39.995735168457,1.97424475177694,7.99135446548462,7.99992179870605,8.00032615661621,22091.2734375,22196.5859375,0.244926273822784,1,6,3,4,23.1730000402331,1,20.6766562950317,1.10786437988281,44.4770278930664,40.5669593811035,,,,,,,,,,,,,,,,
,3875457439.4625,7.99943351745606,29134.2490234375,,,,,,,,,,,,,0.133012177623193,1.28972900015733E-5,-0.000122594573868942,1,2,,80,2,5919,,,0.128246057086842,0.000985079762059401,0.000773390929680318,-0.000274043093668297,,,,0.0321355532047316,39.995735168457,1.97414063220387,7.99164485931396,7.99929428100586,7.99954605102539,29081.5859375,29186.912109375,0.244898587465286,1,6,3,4,23.1730000402331,1,20.6815632800817,1.11106872558594,44.4770278930664,40.5669593811035,,,,,,,,,,,,,,,,
,3875457578.90857,7.99891891479492,36126.56640625,,,,,,,,,,,,,0.158662093982165,1.74092601681472E-5,-9.3398174975695E-5,1,2,,80,2,5987,,,0.153041799306411,0.00137347920772805,0.000922551960684359,-0.000328212190652266,,,,0.0383500861629973,39.995735168457,1.97421642412499,7.99423217773437,7.99877738952637,7.99907875061035,36076.5,36176.6328125,0.244912564754486,1,6,3,4,23.1730000402331,1,20.6800136618497,1.11503601074219,44.9657897949219,40.0782012939453,,,,,,,,,,,,,,,,
,3875457720.39955,7.99845123291016,43219.056640625,,,,,,,,,,,,,0.184548433821818,1.82843545287938E-5,1.00327851029777E-5,10,2,,80,2,6056,,,0.178097786706575,0.00188711099727169,0.00107295566704124,-0.000383752310881391,,,,0.0446312433547635,39.995735168457,1.9741969837415,7.99755859375,7.99837684631348,7.99853324890137,43166.47265625,43271.640625,0.245004504919052,1,6,3,4,23.1730000402331,1,20.6833681226668,1.11648559570312,43.9882698059082,40.5669593811035,,,,,,,,,,,,,,,,
,3875457859.81359,7.99830493927002,50214.291015625,,,,,,,,,,,,,0.210374104345395,1.82353840393466E-5,2.09950922455833E-5,10,2,,80,2,6124,,,0.203131060456231,0.0023561468444353,0.00122327881399542,-0.000438956602010876,,,,0.0509033046336302,39.995735168457,1.97411943213779,8.00250720977783,7.99821138381958,7.99847412109375,50161.6796875,50266.90234375,0.24506764113903,1,6,3,4,23.1730000402331,1,20.6856639137641,1.11251831054688,43.9882698059082,40.0782012939453,,,,,,,,,,,,,,,,
,3875457999.23732,7.99804468154907,57202.328125,,,,,,,,,,,,,0.236771833896028,1.96581574435444E-5,-3.58578197545581E-5,10,2,,80,2,6192,,,0.228757478564078,0.00281101240664078,0.00137736019678414,-0.000495320884510875,,,,0.0573287509683052,39.995735168457,1.97424649145144,8.00775814056397,7.99791574478149,7.99817323684692,57151.88671875,57252.76953125,0.245011955499649,1,6,3,4,23.1730000402331,1,20.6857729989899,1.11671447753906,43.9882698059082,40.5669593811035,,,,,,,,,,,,,,,,
,3875458138.65641,7.99756631851196,64195.068359375,,,,,,,,,,,,,0.264024397312964,2.05441658501459E-5,-7.6449835819488E-5,10,2,,80,2,6260,,,0.255254279108548,0.0033352653369934,0.00153634895104915,-0.000553895777557045,,,,0.0639646764688838,39.995735168457,1.97409049901071,8.0141487121582,7.9975266456604,7.99761056900024,64142.375,64247.76171875,0.245156958699226,1,6,3,4,23.1730000402331,1,20.6874067094663,1.11557006835938,44.4770278930664,40.0782012939453,,,,,,,,,,,,,,,,
,3875458278.05855,7.99751138687134,71187.921875,,,,,,,,,,,,,0.292332488470449,2.29959247873923E-5,-0.000176124105068197,10,2,,80,2,6328,,,0.282821386229863,0.00385723263673084,0.00170197465922683,-0.000614729418884963,,,,0.0708753368683534,39.995735168457,1.97414642805374,8.02067279815674,7.99732637405395,7.997642993927,71137.78125,71238.0625,0.245293498039246,1,6,3,4,23.1730000402331,1,20.688032673082,1.11579895019531,44.4770278930664,40.0782012939453,,,,,,,,,,,,,,,,
,3875458417.49661,7.99755716323853,78193.01171875,,,,,,,,,,,,,0.322194991455842,1.54158528513486E-5,-0.000289338193712634,10,2,,80,2,6396,,,0.311946697917969,0.00442709459876629,0.00187693163752556,-0.000679007265716791,,,,0.0781757152462351,39.995735168457,1.97416596207829,8.02733898162842,7.99747705459595,7.99766397476196,78139.8359375,78246.1875,0.245527908205986,1,6,3,4,23.1730000402331,1,20.6856458760082,1.11213684082031,44.4770278930664,40.0782012939453,,,,,,,,,,,,,,,,
,3875458556.92612,7.99757280349731,85260.0234375,,,,,,,,,,,,,0.355766670275802,2.53975920529476E-5,-0.00045239724076841,10,2,,80,2,6464,,,0.344726629424654,0.00504393017310949,0.00207371823489666,-0.000751207524444908,,,,0.0863854055668169,39.995735168457,1.9740347333467,8.03388786315918,7.99746561050415,7.99766397476196,85206.8359375,85313.2109375,0.245590433478355,1,6,3,4,23.1730000402331,1,20.6851183177208,1.11251831054688,43.9882698059082,40.5669593811035,,,,,,,,,,,,,,,,
,3875458696.31156,7.99797439575195,92327.26171875,,,,,,,,,,,,,0.390596083706418,2.66923087874908E-5,-0.000647931670720095,10,2,,80,2,6532,,,0.378792720022631,0.00568591622499308,0.00227846275083721,-0.000826195173431188,,,,0.094924699856846,39.995735168457,1.97409494829358,8.04054737091064,7.99790811538696,7.99801111221314,92274.1875,92380.3359375,0.245691284537315,1,6,3,4,23.1730000402331,1,20.681607085011,1.112060546875,43.9882698059082,40.5669593811035,,,,,,,,,,,,,,,,
,3875458835.74268,7.99788331985474,99395.37109375,,,,,,,,,,,,,0.424963519099499,2.78737555961443E-5,-0.000922777580722593,10,2,,80,2,6600,,,0.412481407148961,0.00627539302330643,0.00248089758679271,-0.000900009355973452,,,,0.103363502169372,39.995735168457,1.97402877126843,8.04634952545166,7.99785089492798,7.99792718887329,99342.1796875,99448.5625,0.245858699083328,1,6,3,4,23.1730000402331,1,20.6783213484486,1.11244201660156,44.4770278930664,40.5669593811035,,,,,,,,,,,,,,,,
,3875458975.14249,7.99778747558594,106465.08203125,,,,,,,,,,,,,0.458631819268692,2.78529945068918E-5,-0.00117400458463067,10,2,,80,2,6668,,,0.445560410081317,0.00690105977461991,0.00267951027490199,-0.000972822832409292,,,,0.11164857323156,39.995735168457,1.97394563491978,8.0529260635376,7.99773073196411,7.99785852432251,106414.3984375,106515.765625,0.245883002877235,1,6,3,4,23.1730000402331,1,20.6769742591704,1.11488342285156,44.4770278930664,40.0782012939453,,,,,,,,,,,,,,,,
,3875459114.55938,7.99802398681641,113533.19140625,,,,,,,,,,,,,0.491631282993649,3.24287708999483E-5,-0.00149012176194674,10,2,,80,2,6736,,,0.478058860397131,0.00747013162635271,0.00287466449663043,-0.00104402168653905,,,,0.119785682137283,39.995735168457,1.97381917432364,8.05763721466065,7.99796342849731,7.99807786941528,113482.484375,113583.8984375,0.246131733059883,1,6,3,4,23.1730000402331,1,20.6751955113887,1.11343383789062,44.4770278930664,40.0782012939453,,,,,,,,,,,,,,,,
,3875459254.00673,7.99864273071289,120606.875,,,,,,,,,,,,,0.524030575340598,3.06020694811419E-5,-0.00181991874104911,10,2,,80,2,6804,,,0.510040831290645,0.0080270673762915,0.00306694535538554,-0.00111400510650128,,,,0.127800453326592,39.995735168457,1.97382562919793,8.06336116790771,7.99856185913086,7.99875259399414,120556.1796875,120657.5703125,0.246108263731003,1,6,3,4,23.1730000402331,1,20.6712616856284,1.11289978027344,43.9882698059082,40.0782012939453,,,,,,,,,,,,,,,,
,3875459393.4086,7.99857759475708,127672.15234375,,,,,,,,,,,,,0.555885650831526,2.98122232804141E-5,-0.00219382802947116,10,2,,80,2,6872,,,0.541557689041566,0.00853649500577841,0.00325637706555426,-0.00118273356929421,,,,0.135694218647143,39.995735168457,1.97375739531854,8.06668567657471,7.99843978881836,7.99873733520508,127619.1484375,127725.15625,0.246184721589088,1,6,3,4,23.1730000402331,1,20.6686192563468,1.11488342285156,44.4770278930664,40.0782012939453,,,,,,,,,,,,,,,,
,3875459532.84658,7.99902458190918,134746.3828125,,,,,,,,,,,,,0.587308656029112,2.38859109605647E-5,-0.00255625881264223,10,2,,80,2,6940,,,0.572715760970429,0.00904972692712699,0.00344385392963886,-0.00125092500820756,,,,0.143507555904913,39.995735168457,1.97384744898499,8.07026481628418,7.99896430969238,7.99908638000488,134693.171875,134799.59375,0.246278569102287,1,6,3,4,23.1730000402331,1,20.6678624342237,1.11297607421875,44.4770278930664,40.0782012939453,,,,,,,,,,,,,,,,
,3875459672.2535,7.99969902038574,140000.609375,,,,,,,,,,,,,0.610418403676616,3.09150469694144E-5,-0.00277793955240731,10,2,,80,2,7008,,,0.595671775625972,0.00947032947628351,0.00358148664236069,-0.00130117603112012,,,,0.149245832413974,39.995735168457,1.97366188664685,8.07261562347412,7.99962615966797,7.99977684020996,140000.609375,140000.609375,0.246389299631119,1,4,3,4,23.1730000402331,1,20.6659461655189,1.11259460449219,44.4770278930664,41.055721282959,,,,,,,,,,,,,,,,
,3875459758.36194,7.9998104095459,140000.4609375,,,,,,,,,,,,,0.610414508261039,2.5640685594202E-5,-0.00279454770544062,10,2,,80,2,7050,,,0.595668294221858,0.00945404140456463,0.00358155206777155,-0.00130109908059239,,,,0.149246819328334,39.995735168457,1.97369323287365,8.07253360748291,7.99974632263184,7.99994850158691,140000.453125,140000.46875,0.246305257081985,1,4,3,4,23.1730000402331,1,20.6660837520751,1.11579895019531,44.4770278930664,40.5669593811035,,,,,,,,,,,,,,,,