File: MPMS/NiCl2btd/NiCl2btd_MvH_32K_14T.dat
[Header]
; ACMS II Data File (default extension .dat)
; Copyright (c) 2014, Quantum Design, Inc. All rights reserved.
TITLE,
FILEOPENTIME,3875479064.880,10/21/2022,1:58 am
BYAPP,ACMS II,1.0,1.2
INFO,DYNACOOL ACMS II Option Release 1.0.8 Build 33,APPNAME
INFO,Quantum Design Linear Motor Servo Controller,MOTOR_MODULE_NAME
INFO,3101-100 K0,MOTOR_HW_VERSION
INFO,MMC794,MOTOR_SERIAL_NUMBER
INFO,SRV No X-over 01.03.11,MOTOR_SOFTWARE_VERSION
INFO,ACMS,ACMS_MODULE_NAME
INFO,3101-430 A0,ACMS_HW_VERSION
INFO,ACMSII028,ACMS_SERIAL_NUMBER
INFO,00.14.14,ACMS_SOFTWARE_VERSION
INFO,WF046,COIL_SERIAL_NUMBER
INFO,0,MOMENT_UNITS
INFO,NiCl2-btdm,SAMPLE_MATERIAL
INFO,4.8mg cling film,SAMPLE_COMMENT
INFO,22.1,SAMPLE_MASS
INFO,,SAMPLE_VOLUME
INFO,,SAMPLE_MOLECULAR_WEIGHT
INFO,,SAMPLE_SIZE
INFO,,SAMPLE_SHAPE
DATATYPE,COMMENT,1
DATATYPE,TIME,2
STARTUPAXIS,X,2
STARTUPAXIS,Y1,5
STARTUPGROUP, AC
FIELDGROUP, AC, 2,3,4,5,6,7,8,9,10,11,12,13,14,15,16,20,21,22,23,24,25,35,43,44,45,46,47,48,49
FIELDGROUP, DC, 2,3,4,17,18,19,20,21,23,24,25,35,36,37,43,44,45,46,47,48,49,50,51
FIELDGROUP, Diagnostic, 26,27,28,29,30,31,32,33,34,38,39,40,41,42,52,53,54,55,56,57,58,59,60,61,62,63,64,65,66,67,68,69
[Data]
Comment,Time Stamp (sec),Temperature (K),Magnetic Field (Oe),AC Moment (emu),AC Std. Dev. (emu),AC Phase (deg),AC Phase Std. Dev. (deg),AC Suscept. (emu/Oe),AC Suscept. Std. Dev. (emu/Oe),AC X'  (emu/Oe),AC X" (emu/Oe),AC X' Std. Dev. (emu/Oe),AC X" Std. Dev. (emu/Oe),AC Drive (Oe),AC Frequency (Hz),DC Moment (emu),DC Std. Err. (emu),DC Quad. Moment (emu),Range (mV),"AC=1 DC=2 Locate=3",Measure Type,Measure Count,Measure Time (sec),Measure Number,AC X' Raw (emu/Oe),AC X" Raw (emu/Oe),DC M. Raw' (emu),DC M. Raw" (emu),Coil InPhase (V),Coil Quadrature (V),Null Status,Trim Ratio,Trim Phase (deg.),Max. Signal (mV),Motor Frequency (Hz),Motor Ampl. (mm),System Temp. (K),Min. Temperature (K),Max. Temperature (K),Min. Field (Oe),Max. Field (Oe),Pressure (Torr),Temp. Status (code),Field Status (code),Chamber Status (code),Measure Status (code),Center Position (mm),Transport Action,Motor Lag (deg),Motor Current (amps),Motor Heatsink Temp. (C),Motor Board Temp. (C),QMap 01,QMap 02,QMap 03,QMap 04,QMap 05,QMap 06,QMap 07,QMap 08,QMap 09,QMap 10,QMap 11,QMap 12,QMap 13,QMap 14,QMap 15,QMap 16
sample offset = 25.15 mm,3875480941.46076,31.9998474121094,0.542481034994125,,,,,,,,,,,,,-4.25176556282694E-5,8.93479009055812E-7,-1.86401678626319E-6,1,2,,80,2,1,,,-4.09827934451366E-5,-2.16975744809952E-6,-2.46362276357104E-7,9.98143079300462E-8,,,,1.05475705265265E-5,39.995735168457,1.99916019324312,32.0049934387207,31.999641418457,31.9999389648438,0.533587872982025,0.551374197006226,0.623196244239807,1,4,3,4,23.1730000402331,1,20.6352651811077,1.12075805664062,31.2805480957031,32.2580642700195,,,,,,,,,,,,,,,,
,3875481087.05532,31.9988189697266,1490.13879394531,,,,,,,,,,,,,0.00451995129720228,1.09438678988975E-5,-1.19445357251858E-5,1,2,,80,2,69,,,0.00435878210032797,2.84160959359921E-5,2.6629908461473E-5,-9.38276934903115E-6,,,,0.00110584489143776,39.995735168457,1.99933478141254,32.0048446655273,31.9976806640625,32.0006103515625,1435.23303222656,1545.04455566406,0.624386370182037,1,6,3,4,23.1730000402331,1,20.6462510649277,1.12159729003906,39.1006851196289,32.2580642700195,,,,,,,,,,,,,,,,
,3875481233.12142,32.0005981445313,8790.3271484375,,,,,,,,,,,,,0.0286583642820232,1.07336513059309E-5,-6.15784182600525E-5,1,2,,80,2,137,,,0.0276441064050533,0.00021039723746717,0.000168824364664033,-5.96973732172046E-5,,,,0.00701315651700029,39.995735168457,1.99932248184788,32.0039405822754,31.9983444213867,32.0013427734375,8737.8212890625,8842.8330078125,0.62564092874527,1,6,3,4,23.1730000402331,1,20.6482512324287,1.12380981445312,41.055721282959,34.2131004333496,,,,,,,,,,,,,,,,
,3875481379.01048,32.0020706176758,16085.7338867188,,,,,,,,,,,,,0.052580978469643,1.13468258029134E-5,-8.17683712002333E-5,1,2,,80,2,205,,,0.0507379897679421,0.000452085494208193,0.000309734576148912,-0.000109978529508226,,,,0.0128724051866603,39.995735168457,1.99941574645585,32.0040969848633,32.0008392333984,32.0034484863281,16033.2255859375,16138.2421875,0.626636266708374,1,6,3,4,23.1730000402331,1,20.6484944223877,1.1212158203125,41.5444793701172,35.6793746948242,,,,,,,,,,,,,,,,
,3875481522.4667,32.0014892578125,23271.388671875,,,,,,,,,,,,,0.0761139458350774,1.12480752139165E-5,-8.78372919310708E-5,1,2,,80,2,273,,,0.0734759873614781,0.000738441156921083,0.000448346312623471,-0.000159776202053763,,,,0.0186408013187936,39.995735168457,1.99934290966925,32.0022583007812,32.0006103515625,32.002799987793,23218.681640625,23324.095703125,0.627627491950989,1,6,3,4,23.1730000402331,1,20.6490199793986,1.11503601074219,42.0332374572754,36.1681327819824,,,,,,,,,,,,,,,,
,3875481661.88844,31.9987289428711,30264.427734375,,,,,,,,,,,,,0.0989946014148121,1.29564175058059E-5,-7.25991175132426E-5,1,2,,80,2,341,,,0.0956061379929111,0.00107176230412945,0.000583125569391996,-0.000208552170079201,,,,0.0242545541509992,39.995735168457,1.9992414312313,32.0018119812012,31.9981994628906,31.9992218017578,30214.3359375,30314.51953125,0.628379106521606,1,6,3,4,23.1730000402331,1,20.6474836429759,1.12098693847656,42.0332374572754,37.1456527709961,,,,,,,,,,,,,,,,
,3875481801.32841,31.9984085083008,37254.6640625,,,,,,,,,,,,,0.121845082820853,1.28192678235013E-5,-5.83058944857893E-5,1,2,,80,2,409,,,0.117732379886285,0.00143762176858803,0.000717834976967424,-0.000257548526860774,,,,0.0298679494759132,39.995735168457,1.99926236941564,32.0005493164063,31.9973373413086,31.9995727539063,37204.54296875,37304.78515625,0.629243195056915,1,6,3,4,23.1730000402331,1,20.6480296863998,1.12281799316406,42.5219955444336,37.6344108581543,,,,,,,,,,,,,,,,
,3875481940.72523,32.0006942749023,44243.958984375,,,,,,,,,,,,,0.144635898160368,1.55689233331441E-5,-4.69268793149985E-5,1,2,,80,2,477,,,0.139829030445223,0.00183301297390374,0.000852296594530344,-0.000306623667711392,,,,0.0354737774138295,39.995735168457,1.99923752703818,32.0018882751465,32.0005798339844,32.0009002685547,44193.921875,44293.99609375,0.630175411701202,1,6,3,4,23.1730000402331,1,20.6461402935179,1.12144470214844,42.5219955444336,38.1231689453125,,,,,,,,,,,,,,,,
,3875482082.21444,32.0043823242188,51339.220703125,,,,,,,,,,,,,0.167707712563808,1.45900156505183E-5,3.3179228346926E-5,10,2,,80,2,546,,,0.162228404484339,0.00233202491540025,0.000988394720479846,-0.000356984848622233,,,,0.0411590250558712,39.995735168457,1.99923075202882,32.0020942687988,32.0033493041992,32.0052185058594,51289.06640625,51389.375,0.630686461925507,1,6,3,4,23.1730000402331,1,20.6453536726331,1.11984252929688,43.0107536315918,41.055721282959,,,,,,,,,,,,,,,,
,3875482221.63437,32.0000289916992,58329.046875,,,,,,,,,,,,,0.19038293440572,1.7067115076707E-5,1.73048278505817E-5,10,2,,80,2,614,,,0.184276568154953,0.00276051075430338,0.00112248852383345,-0.000406158826081082,,,,0.0467534175412875,39.995735168457,1.99921312343578,31.9975070953369,31.9993591308594,32.0011749267578,58278.9140625,58379.1796875,0.630990147590637,1,6,3,4,23.1730000402331,1,20.6441968527278,1.12205505371094,43.0107536315918,38.1231689453125,,,,,,,,,,,,,,,,
,3875482361.04766,31.9999771118164,65321.392578125,,,,,,,,,,,,,0.212952120531571,1.5556980715796E-5,9.10527432903757E-6,10,2,,80,2,682,,,0.206256532457948,0.00322235810369501,0.00125616393052042,-0.000455398723715916,,,,0.0523324462076098,39.995735168457,1.99930253091603,31.9978675842285,31.9992980957031,32.0014038085937,65268.80859375,65373.9765625,0.631386041641235,1,6,3,4,23.1730000402331,1,20.6424995607474,1.12060546875,43.0107536315918,39.1006851196289,,,,,,,,,,,,,,,,
,3875482500.45199,32.0008972167969,72311.90234375,,,,,,,,,,,,,0.23539999655942,1.69178112749848E-5,-4.12997129653839E-5,10,2,,80,2,750,,,0.228155444936025,0.00366609109014193,0.00138920138124377,-0.000504353200085461,,,,0.0578842669340799,39.995735168457,1.99913890214766,32.0005073547363,32.0003814697266,32.0021438598633,72259.203125,72364.6015625,0.63197249174118,1,6,3,4,23.1730000402331,1,20.6433863712818,1.12136840820312,43.0107536315918,38.6119270324707,,,,,,,,,,,,,,,,
,3875482639.89984,32.0008605957031,79329.3828125,,,,,,,,,,,,,0.257784739594357,1.89644426724467E-5,-0.000112097377960523,10,2,,80,2,818,,,0.250031188425845,0.00411149402656107,0.00152221252210438,-0.000553234363906086,,,,0.0634338155866851,39.995735168457,1.99913044705557,31.9995079040527,32,32.0021667480469,79278.6328125,79380.1328125,0.632526099681854,1,6,3,4,23.1730000402331,1,20.6415316931796,1.12113952636719,43.49951171875,38.6119270324707,,,,,,,,,,,,,,,,
,3875482779.29656,32.0002212524414,86398.390625,,,,,,,,,,,,,0.280143004432118,1.99696466972915E-5,-0.00019535086687832,10,2,,80,2,886,,,0.271920927585769,0.00456452984962616,0.00165541307069361,-0.000602174259256572,,,,0.0689918539537119,39.995735168457,1.99924720742487,31.9951152801514,31.9995346069336,32.0010757446289,86345.140625,86451.640625,0.633028566837311,1,6,3,4,23.1730000402331,1,20.638106319353,1.12205505371094,43.49951171875,39.1006851196289,,,,,,,,,,,,,,,,
,3875482918.72558,32.0014343261719,93469.0390625,,,,,,,,,,,,,0.302322550811507,1.95936631162709E-5,-0.00033682716857567,10,2,,80,2,954,,,0.29367727510737,0.00497423717693685,0.00178760592825711,-0.000650580041110516,,,,0.0745047993129911,39.995735168457,1.99906577419678,31.9945373535156,32.0010757446289,32.0018768310547,93418.328125,93519.75,0.633605420589447,1,6,3,4,23.1730000402331,1,20.6384620746379,1.11434936523438,43.49951171875,39.1006851196289,,,,,,,,,,,,,,,,
,3875483058.14132,32.0008850097656,100537.296875,,,,,,,,,,,,,0.324270810278129,1.56271376820453E-5,-0.000512614913652469,10,2,,80,2,1022,,,0.315248596608618,0.00535950589742108,0.00191884872037917,-0.000698470859788358,,,,0.0799770513405267,39.995735168457,1.99904155261654,31.9934844970703,31.9998474121094,32.0014190673828,100486.6328125,100587.9609375,0.634032547473907,1,6,3,4,23.1730000402331,1,20.6381795451139,1.11465454101562,43.49951171875,39.1006851196289,,,,,,,,,,,,,,,,
,3875483197.55025,32.0025482177734,107604.22265625,,,,,,,,,,,,,0.34590738829217,1.87966083801559E-5,-0.000685505344922981,10,2,,80,2,1090,,,0.336555597169084,0.00575182785924544,0.00204849126748741,-0.000745949568226934,,,,0.0853852085840393,39.995735168457,1.99908256212586,31.9947509765625,32.0014801025391,32.00341796875,107553.546875,107654.8984375,0.634404242038727,1,6,3,4,23.1730000402331,1,20.6401757128642,1.12167358398438,43.49951171875,39.1006851196289,,,,,,,,,,,,,,,,
,3875483336.9736,31.9997970581055,114675.765625,,,,,,,,,,,,,0.36730096761875,2.59585718856281E-5,-0.000916423288777395,10,2,,80,2,1158,,,0.357664877415965,0.00608976098778902,0.00217696628533304,-0.000792502774856985,,,,0.0907371907868118,39.995735168457,1.99900622607154,31.9917182922363,31.9986419677734,32.0005798339844,114622.578125,114728.953125,0.634853005409241,1,6,3,4,23.1730000402331,1,20.6384769268211,1.12060546875,43.9882698059082,39.1006851196289,,,,,,,,,,,,,,,,
,3875483476.39933,32.0006851196289,121744.4921875,,,,,,,,,,,,,0.388407928618904,2.53362766014222E-5,-0.00113359423834746,10,2,,80,2,1226,,,0.378531921517109,0.0064396156527019,0.00230398378334939,-0.000838723382912576,,,,0.0960315611771382,39.995735168457,1.99900841625223,31.9882640838623,31.9988784790039,32.0019454956055,121691.265625,121797.71875,0.63531881570816,1,6,3,4,23.1730000402331,1,20.6388859396009,1.11328125,43.49951171875,39.5894432067871,,,,,,,,,,,,,,,,
,3875483615.81133,32.0010375976562,128814.71875,,,,,,,,,,,,,0.40910022871637,1.39008844592414E-5,-0.00129976093517488,10,2,,80,2,1294,,,0.399029535075118,0.00683237496853609,0.00242850347422063,-0.000884371052961796,,,,0.101225219021005,39.995735168457,1.99888717166257,31.9889125823975,31.9998168945313,32.0016403198242,128764.1640625,128865.2734375,0.635638773441315,1,6,3,4,23.1730000402331,1,20.6391981102768,1.12159729003906,43.9882698059082,39.5894432067871,,,,,,,,,,,,,,,,
,3875483755.22895,32.0020401000977,135886.65625,,,,,,,,,,,,,0.429404887477057,1.7652710774289E-5,-0.00152710573561756,10,2,,80,2,1362,,,0.419184226829578,0.00715645471549972,0.00255128205753863,-0.000928797002416104,,,,0.106339124602829,39.995735168457,1.99890887534096,31.9864807128906,32.0005645751953,32.0037155151367,135833.4375,135939.875,0.636126101016998,1,6,3,4,23.1730000402331,1,20.6364097289235,1.11358642578125,43.9882698059082,39.5894432067871,,,,,,,,,,,,,,,,
,3875483894.65611,32.0003326416016,140000.4296875,,,,,,,,,,,,,0.441076675469868,1.98242845423657E-5,-0.00167565610003904,10,2,,80,2,1430,,,0.430787410459301,0.00732470682032801,0.00262204557657242,-0.000954325485508889,,,,0.1092851807854,39.995735168457,1.9989644708085,31.9908638000488,31.9992752075195,32.0013427734375,140000.1875,140000.671875,0.636490046977997,1,4,3,4,23.1730000402331,1,20.6358808070229,1.11351013183594,43.9882698059082,39.5894432067871,,,,,,,,,,,,,,,,
,3875484034.0669,31.9939987182617,136378.7421875,,,,,,,,,,,,,0.430879478225044,2.01209198472435E-5,-0.00154314419433535,10,2,,80,2,1498,,,0.420647580806364,0.00717970298714224,0.00256020133383572,-0.000931971240788698,,,,0.106709896217353,39.995735168457,1.99890058499237,31.9957656860352,31.9936294555664,31.9950866699219,136326.875,136430.609375,0.636880397796631,1,6,3,4,23.1730000402331,1,20.6352066824361,1.12228393554688,43.9882698059082,39.5894432067871,,,,,,,,,,,,,,,,
,3875484173.47184,31.9982624053955,129479.57421875,,,,,,,,,,,,,0.411062346915327,1.76202605617673E-5,-0.00132699585847181,10,2,,80,2,1566,,,0.400974830827527,0.00685822777961874,0.0024405182339251,-0.000888545182533562,,,,0.101724119104268,39.995735168457,1.99898088216629,31.9953689575195,31.9968338012695,32.0002670288086,129430.0390625,129529.109375,0.63725072145462,1,6,3,4,23.1730000402331,1,20.6360925041943,1.12068176269531,43.49951171875,39.5894432067871,,,,,,,,,,,,,,,,
,3875484312.92096,31.9996765136719,122581.8515625,,,,,,,,,,,,,0.390902048657244,1.72936291918798E-5,-0.00109841902951868,10,2,,80,2,1634,,,0.380998895111986,0.00654038066962995,0.00231897202320397,-0.000844405847601593,,,,0.0966593475519964,39.995735168457,1.99904311198308,31.9983959197998,31.998664855957,32.0008163452148,122529.8125,122633.890625,0.637610375881195,1,6,3,4,23.1730000402331,1,20.6349826939393,1.12098693847656,43.9882698059082,40.0782012939453,,,,,,,,,,,,,,,,
,3875484452.31461,31.9990139007568,115686.1015625,,,,,,,,,,,,,0.370425291287147,1.76191976415E-5,-0.000891780915987963,10,2,,80,2,1702,,,0.36074875099448,0.00619584122711753,0.00219571799971163,-0.000799553003162146,,,,0.0915220578807842,39.995735168457,1.99905075793311,31.9992065429687,31.9987106323242,31.9992980957031,115634.0078125,115738.1953125,0.638173341751099,1,6,3,4,23.1730000402331,1,20.6351283543399,1.11419677734375,43.0107536315918,39.5894432067871,,,,,,,,,,,,,,,,
,3875484591.75554,32.0004920959473,108786.57421875,,,,,,,,,,,,,0.349614741251001,2.43008523917896E-5,-0.000701269212800318,10,2,,80,2,1770,,,0.340208622879491,0.00583245710481145,0.00207060249522328,-0.000753950618673116,,,,0.0863061217056361,39.995735168457,1.99894260008589,31.9991703033447,31.9994277954102,32.0019607543945,108736.9375,108836.2109375,0.638341307640076,1,6,3,4,23.1730000402331,1,20.6358740820665,1.12220764160156,43.49951171875,39.1006851196289,,,,,,,,,,,,,,,,
,3875484731.16693,32.0002182006836,101891.3046875,,,,,,,,,,,,,0.328514473863072,1.59824718222021E-5,-0.000533458358275598,10,2,,80,2,1838,,,0.319423136764582,0.00544769280525541,0.00194421398919076,-0.000707816565409303,,,,0.081035854301291,39.995735168457,1.99903121302799,32.0015144348145,31.9981689453125,32.0009613037109,101841.8125,101940.796875,0.638809859752655,1,6,3,4,23.1730000402331,1,20.6380228089596,1.12251281738281,43.49951171875,39.5894432067871,,,,,,,,,,,,,,,,
,3875484870.55961,31.9996547698975,94995.390625,,,,,,,,,,,,,0.307181836578088,2.04915202424671E-5,-0.000399692569587311,10,2,,80,2,1906,,,0.298448909293605,0.00503437099837017,0.00181673199404031,-0.000661079655401409,,,,0.0757181494172548,39.995735168457,1.99912333126718,32.0021324157715,31.9987564086914,32.0007095336914,94945.734375,95045.046875,0.639120519161224,1,6,3,4,23.1730000402331,1,20.6396333562797,1.12213134765625,43.49951171875,39.5894432067871,,,,,,,,,,,,,,,,
,3875485009.97631,31.9997817993164,88096.2734375,,,,,,,,,,,,,0.285616218936519,1.70692179213673E-5,-0.000269955096120155,10,2,,80,2,1974,,,0.277285332686805,0.00462462186661879,0.00168798002414405,-0.000613847107160836,,,,0.0703469462167606,39.995735168457,1.99907321437689,32.0036811828613,31.9990768432617,32.0008163452148,88044.2421875,88148.3046875,0.639602661132813,1,6,3,4,23.1730000402331,1,20.6390863996886,1.12167358398438,43.9882698059082,39.5894432067871,,,,,,,,,,,,,,,,
,3875485149.41172,31.9997985839844,81200.04296875,,,,,,,,,,,,,0.263825242910769,1.68803235580477E-5,-0.000151737704404645,10,2,,80,2,2042,,,0.255940433399964,0.00421452196166294,0.00155813246965408,-0.000566263275686651,,,,0.0649309049566869,39.995735168457,1.99904510820928,32.003849029541,31.9995040893555,32.0000610351562,81148.046875,81252.0390625,0.639825224876404,1,6,3,4,23.1730000402331,1,20.6393806924208,1.12228393554688,43.9882698059082,39.5894432067871,,,,,,,,,,,,,,,,
,3875485288.83346,31.9996547698975,74302.21875,,,,,,,,,,,,,0.241881576416192,1.68820756947016E-5,-9.56650491060597E-5,10,2,,80,2,2110,,,0.23448520391046,0.00375908040652856,0.00142779713496566,-0.000518149870913476,,,,0.0594899318114721,39.995735168457,1.99911966372353,32.0022621154785,31.9977264404297,32.0010604858398,74252.6875,74351.75,0.640259206295013,1,6,3,4,23.1730000402331,1,20.6378712251587,1.12342834472656,43.49951171875,39.5894432067871,,,,,,,,,,,,,,,,
,3875485428.23771,31.9987182617188,67406.0625,,,,,,,,,,,,,0.219780549577896,1.79097956621747E-5,-2.08968788469766E-5,10,2,,80,2,2178,,,0.212913376883123,0.00333967672817816,0.00129649054724723,-0.000470148137537762,,,,0.0540141993459503,39.995735168457,1.99902587072105,32.0037727355957,31.997802734375,31.999641418457,67356.6015625,67455.5234375,0.640502333641052,1,6,3,4,23.1730000402331,1,20.6439843642579,1.1212158203125,43.49951171875,39.1006851196289,,,,,,,,,,,,,,,,
,3875485567.65718,31.9993072509766,60510.837890625,,,,,,,,,,,,,0.197557089010909,1.51816676146944E-5,7.74560393980523E-6,10,2,,80,2,2246,,,0.19125897196602,0.00289693132620204,0.00116485997568816,-0.000421714619733393,,,,0.0485210453339057,39.995735168457,1.99905180353121,32.0020294189453,31.9985961914063,31.9999771118164,60461.44140625,60560.234375,0.6409712433815,1,6,3,4,23.1730000402331,1,20.644416311535,1.11412048339844,43.9882698059082,39.5894432067871,,,,,,,,,,,,,,,,
,3875485707.08623,31.9997062683105,53613.736328125,,,,,,,,,,,,,0.175255845021844,1.53693800517943E-5,3.24827033560995E-5,10,2,,80,2,2314,,,0.169563100450165,0.00247481833132953,0.00103296106681228,-0.000373312417650595,,,,0.0430183681519994,39.995735168457,1.9991306863013,32.0046195983887,31.9989318847656,32.0005187988281,53561.88671875,53665.5859375,0.641209661960602,1,6,3,4,23.1730000402331,1,20.6440793238906,1.12213134765625,43.9882698059082,41.055721282959,,,,,,,,,,,,,,,,
,3875485846.48006,31.9998336791992,46717.94140625,,,,,,,,,,,,,0.152839055582134,1.49559688525506E-5,3.85577479909196E-5,10,2,,80,2,2382,,,0.147787991755051,0.00206106985236494,0.000900518905837089,-0.000324776337947696,,,,0.0374938988390053,39.995735168457,1.99913859964272,32.0051040649414,31.9992752075195,32.0003128051758,46666.1015625,46769.78125,0.641372621059418,1,6,3,4,23.1730000402331,1,20.6434699592678,1.11396789550781,43.9882698059082,39.5894432067871,,,,,,,,,,,,,,,,
,3875485985.92752,32.0017776489258,39820.48828125,,,,,,,,,,,,,0.130374004551832,1.49293760699428E-5,1.02040782337524E-5,10,2,,80,2,2450,,,0.125996968451588,0.00164340959429587,0.000767953519243747,-0.000276262551778927,,,,0.0319653503986799,39.995735168457,1.99913673273493,32.007984161377,32.0016174316406,32.0021362304687,39771.12890625,39869.84765625,0.641838490962982,1,6,3,4,23.1730000402331,1,20.648734856822,1.11480712890625,43.9882698059082,40.0782012939453,,,,,,,,,,,,,,,,
,3875486125.34303,32.0031829833984,32892.13671875,,,,,,,,,,,,,0.107768717952386,1.38023240428022E-5,-1.00078552898994E-5,10,2,,80,2,2518,,,0.104098073485795,0.00126301537216127,0.000634675147011876,-0.000227683500270359,,,,0.0264097138900606,39.995735168457,1.99914131671624,32.0075302124023,32.0025405883789,32.0038223266602,32840.00390625,32944.26953125,0.642102122306824,1,6,3,4,23.1730000402331,1,20.6502169950134,1.12190246582031,43.49951171875,39.5894432067871,,,,,,,,,,,,,,,,
,3875486264.76328,32.0003845214844,25958.880859375,,,,,,,,,,,,,0.0851115828559648,1.24037244161511E-5,-3.37647146506802E-5,10,2,,80,2,2586,,,0.0821748150570863,0.000911346112732927,0.000501195783726871,-0.000179204012965783,,,,0.0208466656842312,39.995735168457,1.99914815597687,32.0044364929199,31.9999389648438,32.0008163452148,25906.361328125,26011.400390625,0.64229142665863,1,6,3,4,23.1730000402331,1,20.6496520458962,1.12228393554688,43.9882698059082,39.5894432067871,,,,,,,,,,,,,,,,
,3875486404.24236,32.0007736206055,19021.0673828125,,,,,,,,,,,,,0.0624099778366216,1.04824096709271E-5,-9.01347365197738E-5,1,2,,80,2,2654,,,0.060232108732941,0.000561275304506878,0.000367588800145313,-0.000130716478452086,,,,0.0152793889863888,39.995735168457,1.99917538882961,32.0045280456543,31.9989318847656,32.0019149780273,18968.90625,19073.228515625,0.642481505870819,1,6,3,4,23.1730000402331,1,20.6521491710677,1.12174987792969,43.49951171875,40.0782012939453,,,,,,,,,,,,,,,,
,3875486543.66613,32.0003707885742,12085.7202148438,,,,,,,,,,,,,0.039736898382033,1.04811598852223E-5,-7.26001500877008E-5,1,2,,80,2,2722,,,0.0383363505730563,0.000316019606625135,0.000234049162827432,-8.29376804176718E-5,,,,0.00972517181230085,39.995735168457,1.99915536299508,32.0078811645508,31.9990539550781,32.0023422241211,12035.9931640625,12135.447265625,0.642791867256165,1,6,3,4,23.1730000402331,1,20.6503938782977,1.12258911132812,43.49951171875,39.5894432067871,,,,,,,,,,,,,,,,
,3875486683.05438,31.9981552124023,5146.38256835937,,,,,,,,,,,,,0.0170909581570832,1.03436295393374E-5,-4.05079309160575E-5,1,2,,80,2,2790,,,0.0164835986997394,0.00011652168216204,0.000100676021247637,-3.55381089320872E-5,,,,0.00418113045646394,39.995735168457,1.99913271632481,32.0040397644043,31.9977798461914,31.9983749389648,5096.24169921875,5196.5234375,0.64300149679184,1,6,3,4,23.1730000402331,1,20.6481484183306,1.12159729003906,43.49951171875,40.0782012939453,,,,,,,,,,,,,,,,
,3875486822.4858,31.9986228942871,-1802.64874267578,,,,,,,,,,,,,-0.00557523403912102,1.04307194951337E-5,1.18442207485183E-5,1,2,,80,2,2858,,,-0.00537646185244156,-3.79498696811422E-5,-3.28389905916993E-5,1.15934644782101E-5,,,,0.00136368968197913,39.995735168457,1.9992522712742,32.0056838989258,31.9979400634766,31.9999694824219,-1854.70495605469,-1750.59252929687,0.643102765083313,1,6,3,4,23.1730000402331,1,20.6510302751717,1.12205505371094,43.49951171875,40.0782012939453,,,,,,,,,,,,,,,,
,3875486961.90225,32.0021423339844,-8753.669921875,,,,,,,,,,,,,-0.0285034384413393,1.06599576325557E-5,5.53237169977616E-5,1,2,,80,2,2926,,,-0.027494579824015,-0.000214914993114313,-0.000167883728863671,5.94225457462017E-5,,,,0.00697465906900841,39.995735168457,1.99920589315957,32.0049667358398,32.0014495849609,32.0027084350586,-8806.001953125,-8701.337890625,0.643427073955536,1,6,3,4,23.1730000402331,1,20.6539938856863,1.12274169921875,43.9882698059082,39.5894432067871,,,,,,,,,,,,,,,,
,3875487101.3143,31.9991958618164,-15705.4462890625,,,,,,,,,,,,,-0.0513256249387676,1.09549941844444E-5,7.85362232265874E-5,1,2,,80,2,2994,,,-0.0495255962666755,-0.000440578990197742,-0.000302297150483355,0.000107345091237221,,,,0.0125631172224227,39.995735168457,1.99918624884053,32.0031356811523,31.9980163574219,32.0001449584961,-15757.9072265625,-15652.9853515625,0.643463134765625,1,6,3,4,23.1730000402331,1,20.6505531683551,1.12228393554688,43.49951171875,40.0782012939453,,,,,,,,,,,,,,,,
,3875487240.76098,32.000910949707,-22667.4384765625,,,,,,,,,,,,,-0.0741489020185411,1.15117913228226E-5,8.31973581700035E-5,1,2,,80,2,3062,,,-0.0715764085217591,-0.000717127766388437,-0.000436727190390229,0.000155635992996395,,,,0.0181577472880436,39.995735168457,1.9992130059666,32.0027351379395,32.0002670288086,32.0013198852539,-22717.40625,-22617.470703125,0.643653154373169,1,6,3,4,23.1730000402331,1,20.6508538011573,1.12045288085938,43.49951171875,39.5894432067871,,,,,,,,,,,,,,,,
,3875487380.17777,32.0019683837891,-29637.208984375,,,,,,,,,,,,,-0.0969832994508953,1.24102003575176E-5,7.25438170212728E-5,1,2,,80,2,3130,,,-0.0936598113541725,-0.00104243131055579,-0.000571238808333874,0.000204313866561279,,,,0.0237604204519242,39.995735168457,1.99920195502081,32.0020446777344,32.0017242431641,32.0024032592773,-29687.111328125,-29587.306640625,0.643894016742706,1,6,3,4,23.1730000402331,1,20.6532295334561,1.11328125,43.49951171875,40.0782012939453,,,,,,,,,,,,,,,,
,3875487519.58749,31.9979919433594,-36611.375,,,,,,,,,,,,,-0.119782424018852,1.3423166559227E-5,6.17604958567342E-5,1,2,,80,2,3198,,,-0.115733951113807,-0.00140104297138685,-0.000705629703588784,0.00025316679966636,,,,0.0293607453439103,39.995735168457,1.99920306015284,32.0022506713867,31.9967193603516,31.9994506835937,-36663.99609375,-36558.75390625,0.643993556499481,1,6,3,4,23.1730000402331,1,20.6538656673379,1.12190246582031,43.49951171875,39.5894432067871,,,,,,,,,,,,,,,,
,3875487661.07744,31.9996490478516,-43684.55078125,,,,,,,,,,,,,-0.142879013045159,1.55577290862909E-5,-3.0393457410694E-5,10,2,,80,2,3267,,,-0.138123314321894,-0.00187660886532833,-0.000841725210193545,0.0003034234396182,,,,0.0350438855141169,39.995735168457,1.9992674139074,32.0009841918945,31.9983596801758,32.0002670288086,-43734.62890625,-43634.47265625,0.644227206707001,1,6,3,4,23.1730000402331,1,20.655116459645,1.12075805664062,42.5219955444336,39.5894432067871,,,,,,,,,,,,,,,,
,3875487800.49514,32.0018539428711,-50656.322265625,,,,,,,,,,,,,-0.165573112470648,1.37166576364575E-5,-4.2615215389776E-5,10,2,,80,2,3335,,,-0.160153968910166,-0.00230028336712565,-0.000975723203737289,0.000352558417944238,,,,0.0406335423015197,39.995735168457,1.99926303330304,32.0014572143555,32.0014495849609,32.0024337768555,-50708.84765625,-50603.796875,0.64422744512558,1,6,3,4,23.1730000402331,1,20.6538439397916,1.12258911132812,43.49951171875,39.5894432067871,,,,,,,,,,,,,,,,
,3875487939.90148,32.0000717163086,-57627.44140625,,,,,,,,,,,,,-0.188197426861057,1.60838247818596E-5,-4.47473995877278E-5,10,2,,80,2,3403,,,-0.182149157200969,-0.00274250002834884,-0.00110947177745402,0.000401790952309966,,,,0.0462146485100889,39.995735168457,1.99930578971067,32.0024490356445,31.9996719360352,32.0006103515625,-57679.83203125,-57575.05078125,0.644384980201721,1,6,3,4,23.1730000402331,1,20.6554576258614,1.12167358398438,43.49951171875,39.1006851196289,,,,,,,,,,,,,,,,
,3875488079.31772,32.0012302398682,-64602.322265625,,,,,,,,,,,,,-0.210716072933963,1.60406208598826E-5,-8.03390075155339E-6,10,2,,80,2,3471,,,-0.204076870923574,-0.00317317395777258,-0.0012428107438609,0.000450744002591819,,,,0.0517781091429399,39.995735168457,1.99927407104293,31.996639251709,32.0005187988281,32.0019760131836,-64654.80859375,-64549.8359375,0.644565343856812,1,6,3,4,23.1730000402331,1,20.6543344184877,1.11465454101562,43.49951171875,39.1006851196289,,,,,,,,,,,,,,,,
,3875488218.73468,32.0019088745117,-71570.6875,,,,,,,,,,,,,-0.233126143139995,1.87089822281383E-5,3.59031199000927E-5,10,2,,80,2,3539,,,-0.225934849636709,-0.00361974025745741,-0.00137574970722198,0.000499605957884342,,,,0.0573256423715814,39.995735168457,1.99930849719675,32.0002059936523,32.0013427734375,32.0028381347656,-71620.703125,-71520.671875,0.644753932952881,1,6,3,4,23.1730000402331,1,20.6511111716199,1.12594604492188,43.49951171875,39.5894432067871,,,,,,,,,,,,,,,,
,3875488358.1562,31.998966217041,-78560.54296875,,,,,,,,,,,,,-0.255427158745856,2.02913864880482E-5,0.000110913475509998,10,2,,80,2,3607,,,-0.24772463159784,-0.00405675986200664,-0.00150827143806964,0.000548324780538678,,,,0.0628557121646736,39.995735168457,1.99933890316057,31.9970264434814,31.99853515625,31.999382019043,-78613.5703125,-78507.515625,0.64479011297226,1,6,3,4,23.1730000402331,1,20.6506914939448,1.11457824707031,43.49951171875,39.1006851196289,,,,,,,,,,,,,,,,
,3875488497.57592,32.0023712158203,-85609.53515625,,,,,,,,,,,,,-0.277762600317665,1.87206089493787E-5,0.000214234162817292,10,2,,80,2,3675,,,-0.269588116789265,-0.00448781819632771,-0.00164128467440605,0.000597082835156471,,,,0.0684041338438687,39.995735168457,1.99936273091917,31.995885848999,32.0018768310547,32.0027313232422,-85659.75,-85559.3203125,0.645063161849976,1,6,3,4,23.1730000402331,1,20.6475628603911,1.12197875976562,43.49951171875,39.1006851196289,,,,,,,,,,,,,,,,
,3875488636.9739,32.0009841918945,-92656.4296875,,,,,,,,,,,,,-0.299918360460502,1.85253972408542E-5,0.000322924745294164,10,2,,80,2,3743,,,-0.29131568023418,-0.00492672023693959,-0.00177331932354718,0.000645515567157417,,,,0.0739122004102462,39.995735168457,1.99921874545501,31.995096206665,32.0006637573242,32.0017395019531,-92707,-92605.859375,0.645098686218262,1,6,3,4,23.1730000402331,1,20.6437911434937,1.11419677734375,43.49951171875,39.1006851196289,,,,,,,,,,,,,,,,
,3875488776.40414,32.0010356903076,-99705.93359375,,,,,,,,,,,,,-0.321808078093105,1.6499456212847E-5,0.000465338059681048,10,2,,80,2,3811,,,-0.312824401458218,-0.00534163061396976,-0.00190421880688518,0.000693451846018434,,,,0.0793714289623487,39.995735168457,1.99927986926937,31.9957370758057,32.0006103515625,32.0013427734375,-99758.9921875,-99652.875,0.645284831523895,1,6,3,4,23.1730000402331,1,20.6420451103958,1.12052917480469,43.49951171875,40.5669593811035,,,,,,,,,,,,,,,,
,3875488915.84312,32.0012149810791,-106752.25390625,,,,,,,,,,,,,-0.343450270553837,1.73657596495894E-5,0.000617740225807204,10,2,,80,2,3879,,,-0.334131008949534,-0.00575243640845839,-0.00203380244784057,0.00074076687451452,,,,0.0847744799261707,39.995735168457,1.99920113549709,31.9931221008301,32.0008392333984,32.001838684082,-106805.203125,-106699.3046875,0.645290732383728,1,6,3,4,23.1730000402331,1,20.6371013460837,1.12167358398438,43.49951171875,39.5894432067871,,,,,,,,,,,,,,,,
,3875489055.24283,31.999446105957,-113802.12109375,,,,,,,,,,,,,-0.364820187313812,2.08531774176249E-5,0.000824991390733782,10,2,,80,2,3947,,,-0.355211631119364,-0.00611201225308954,-0.0021620886400342,0.000787331198807806,,,,0.0901201212483855,39.995735168457,1.99912573402776,31.9903621673584,31.9992218017578,31.9997177124023,-113852.6328125,-113751.609375,0.64561527967453,1,6,3,4,23.1730000402331,1,20.6338737584471,1.12106323242188,43.49951171875,39.5894432067871,,,,,,,,,,,,,,,,
,3875489194.66121,32.0010009765625,-120848.984375,,,,,,,,,,,,,-0.385842250568455,2.27423648736798E-5,0.00104211108354498,10,2,,80,2,4015,,,-0.375990617668532,-0.00645960043112316,-0.00228843628428876,0.000833096099086106,,,,0.0953841049163547,39.995735168457,1.99894075423173,31.9916801452637,31.9992294311523,32.0031433105469,-120899.3203125,-120798.6484375,0.645612239837646,1,6,3,4,23.1730000402331,1,20.6299737544834,1.12136840820312,43.9882698059082,39.5894432067871,,,,,,,,,,,,,,,,
,3875489334.06745,32.0021484375,-127897.125,,,,,,,,,,,,,-0.406519702292822,2.43937917265488E-5,0.00129155453005652,10,2,,80,2,4083,,,-0.396470073878313,-0.00677050843603154,-0.00241309753619134,0.000878137012477964,,,,0.100575707883898,39.995735168457,1.99886375108646,31.9878311157227,32.0018463134766,32.0025405883789,-127949.9609375,-127844.2890625,0.645754039287567,1,6,3,4,23.1730000402331,1,20.6287272082534,1.11259460449219,43.49951171875,40.5669593811035,,,,,,,,,,,,,,,,
,3875489473.49513,32.0022445678711,-134944.109375,,,,,,,,,,,,,-0.426826130923782,2.08923106741389E-5,0.00150170543097231,10,2,,80,2,4151,,,-0.416620726026743,-0.00711125547270197,-0.002535714302212,0.00092251761816442,,,,0.105682908694539,39.995735168457,1.9987781067091,31.9836597442627,32.0014419555664,32.0030975341797,-134997.109375,-134891.109375,0.645849406719208,1,6,3,4,23.1730000402331,1,20.6243972508285,1.11442565917969,43.9882698059082,39.5894432067871,,,,,,,,,,,,,,,,
,3875489612.91145,31.9975814819336,-139999.71875,,,,,,,,,,,,,-0.441205665734658,2.57891437406028E-5,0.00166008600979216,10,2,,80,2,4219,,,-0.430912776412365,-0.0073424252330451,-0.00262264581397176,0.000953974842559546,,,,0.109303174931055,39.995735168457,1.99869345577705,31.9890766143799,31.9970550537109,31.9982376098633,-139999.734375,-139999.703125,0.645961463451385,1,4,3,4,23.1730000402331,1,20.6228294708118,1.11404418945312,43.49951171875,39.5894432067871,,,,,,,,,,,,,,,,
,3875489752.36228,31.99426612854,-137298.59375,,,,,,,,,,,,,-0.433603969708835,2.21608937140941E-5,0.00155200935814566,10,2,,80,2,4287,,,-0.42335281607443,-0.00724348221246585,-0.00257667270489037,0.000937341595999897,,,,0.10738747346625,39.995735168457,1.99874454170335,31.9908924102783,31.9914569854736,31.9956130981445,-137350.671875,-137246.515625,0.645986318588257,1,6,3,4,23.1730000402331,1,20.6205404045527,1.11366271972656,43.49951171875,37.6344108581543,,,,,,,,,,,,,,,,
,3875489891.76051,31.9945724487305,-130389.40234375,,,,,,,,,,,,,-0.413809396219337,2.58581675096018E-5,0.00133076120424593,10,2,,80,2,4355,,,-0.403696876934395,-0.0069273740973652,-0.00245700217783451,0.0008940200204961,,,,0.102402346498075,39.995735168457,1.99876821583643,31.9966697692871,31.993782043457,31.9954986572266,-130441.453125,-130337.3515625,0.646040320396423,1,6,3,4,23.1730000402331,1,20.6220430646336,1.12144470214844,43.9882698059082,39.5894432067871,,,,,,,,,,,,,,,,
,3875490031.18733,31.9980422973633,-123477.078125,,,,,,,,,,,,,-0.393596652708686,2.28800541359916E-5,0.00110207190226682,10,2,,80,2,4423,,,-0.383665109100928,-0.00660846700237384,-0.0023351029958576,0.000849702395498753,,,,0.0973227433147929,39.995735168457,1.99879334880811,32.000431060791,31.9975814819336,31.9988784790039,-123526.5859375,-123427.5703125,0.646151006221771,1,6,3,4,23.1730000402331,1,20.6191450104406,1.12136840820312,43.9882698059082,40.0782012939453,,,,,,,,,,,,,,,,
,3875490170.57986,31.9996047973633,-116566.84375,,,,,,,,,,,,,-0.373103746648655,2.64507101313972E-5,0.000923621784570526,10,2,,80,2,4491,,,-0.363394819734546,-0.00623562735300183,-0.0022116731852293,0.000804835406597704,,,,0.0921793794509005,39.995735168457,1.99875533190843,31.9996433258057,31.9990539550781,32.0007400512695,-116616.3984375,-116517.2890625,0.646307706832886,1,6,3,4,23.1730000402331,1,20.623952878886,1.11396789550781,43.49951171875,40.0782012939453,,,,,,,,,,,,,,,,
,3875490310.00145,32.0005920410156,-109656.38671875,,,,,,,,,,,,,-0.35227895789578,2.51232000385005E-5,0.000729355433758131,10,2,,80,2,4559,,,-0.342835838553356,-0.00587483686607881,-0.00208662892691791,0.000759315094910562,,,,0.0869683723485853,39.995735168457,1.99883013514508,31.9996280670166,31.9992599487305,32.0021667480469,-109705.9296875,-109606.84375,0.646578550338745,1,6,3,4,23.1730000402331,1,20.6248965975008,1.12205505371094,43.9882698059082,39.5894432067871,,,,,,,,,,,,,,,,
,3875490449.4253,31.9983291625977,-102742.5,,,,,,,,,,,,,-0.331176271459632,1.68863533389361E-5,0.00053870531069868,10,2,,80,2,4627,,,-0.322042158103612,-0.00551079483057407,-0.00196012295782566,0.000713183078914881,,,,0.081694272607228,39.995735168457,1.99885297700238,32.0000991821289,31.9972839355469,31.9992980957031,-102794.578125,-102690.421875,0.646535396575928,1,6,3,4,23.1730000402331,1,20.623764791016,1.12167358398438,43.9882698059082,39.5894432067871,,,,,,,,,,,,,,,,
,3875490588.86042,32.0000171661377,-95830.546875,,,,,,,,,,,,,-0.309831743151781,1.78991799477259E-5,0.0004037488443179,10,2,,80,2,4695,,,-0.301051325207467,-0.00509682295572798,-0.00183251139242202,0.000666441395878792,,,,0.0763709676551289,39.995735168457,1.9989153793826,32.0022201538086,31.9994812011719,32.0005187988281,-95882.59375,-95778.5,0.646716415882111,1,6,3,4,23.1730000402331,1,20.6256071253075,1.12152099609375,44.4770278930664,40.0782012939453,,,,,,,,,,,,,,,,
,3875490728.26851,31.9975173950195,-88918.49609375,,,,,,,,,,,,,-0.288231417168301,1.90596891979846E-5,0.000260790236400598,10,2,,80,2,4763,,,-0.279848792641375,-0.00469732190776673,-0.00170355930458754,0.000619271653704345,,,,0.070993088032236,39.995735168457,1.99894553166229,32.0022468566895,31.9970855712891,31.9984130859375,-88970.5859375,-88866.40625,0.646912038326263,1,6,3,4,23.1730000402331,1,20.6257984364587,1.12228393554688,43.9882698059082,39.5894432067871,,,,,,,,,,,,,,,,
,3875490867.67741,31.9982330322266,-82000.75390625,,,,,,,,,,,,,-0.26639457169378,1.94675454602539E-5,0.000163259078477932,10,2,,80,2,4831,,,-0.258454772761168,-0.00426400812714572,-0.00157341139856726,0.000571592128835618,,,,0.0655644004814833,39.995735168457,1.99891408893514,32.0014724731445,31.9971771240234,31.9992218017578,-82052.90625,-81948.6015625,0.646921038627624,1,6,3,4,23.1730000402331,1,20.6303874623162,1.12197875976562,43.9882698059082,40.0782012939453,,,,,,,,,,,,,,,,
,3875491007.1064,31.9981246948242,-75088.21875,,,,,,,,,,,,,-0.244408088892262,1.82039003396093E-5,7.1519639801782E-5,10,2,,80,2,4899,,,-0.236952878143603,-0.00383996778969538,-0.00144271005410701,0.000523636408615857,,,,0.0601114230644818,39.995735168457,1.99898765106526,32.0025901794434,31.9976196289063,31.9994583129883,-75140.296875,-75036.140625,0.647032082080841,1,6,3,4,23.1730000402331,1,20.6304991006168,1.12136840820312,43.9882698059082,40.5669593811035,,,,,,,,,,,,,,,,
,3875491146.5127,31.9985702514648,-68175.796875,,,,,,,,,,,,,-0.222286622707103,1.57897052969795E-5,1.16601943995482E-5,10,2,,80,2,4967,,,-0.215357071463848,-0.0034029800064167,-0.00131143163889647,0.000475426553748548,,,,0.0546347847486787,39.995735168457,1.99904706394995,32.0014381408691,31.9978561401367,31.9999465942383,-68227.859375,-68123.734375,0.647172808647156,1,6,3,4,23.1730000402331,1,20.6319481157215,1.12907409667969,44.4770278930664,40.0782012939453,,,,,,,,,,,,,,,,
,3875491285.91391,32.0004913330078,-61261.01171875,,,,,,,,,,,,,-0.200012179861003,1.56602313364946E-5,-1.60067091136009E-5,10,2,,80,2,5035,,,-0.193649179902446,-0.00295551724297962,-0.00117940211202949,0.000426953280111775,,,,0.0491265927229042,39.995735168457,1.99900703665579,32.0054512023926,31.9997024536133,32.0011520385742,-61310.625,-61211.3984375,0.647108733654022,1,6,3,4,23.1730000402331,1,20.6366773184724,1.12442016601562,43.9882698059082,39.5894432067871,,,,,,,,,,,,,,,,
,3875491425.35846,32.0000534057617,-54347.939453125,,,,,,,,,,,,,-0.177640829428674,1.50642325243149E-5,-2.25085677165003E-5,10,2,,80,2,5103,,,-0.171881874011485,-0.0025115729401312,-0.00104710250161588,0.000378323195036501,,,,0.0436057086101217,39.995735168457,1.99909843422694,32.0060348510742,31.9997177124023,32.0010070800781,-54397.5390625,-54298.33984375,0.64734935760498,1,6,3,4,23.1730000402331,1,20.6382719813734,1.12197875976562,43.9882698059082,40.0782012939453,,,,,,,,,,,,,,,,
,3875491564.7716,31.9987228393555,-47435.1484375,,,,,,,,,,,,,-0.15517280405066,1.21975531584931E-5,-2.65740901115955E-5,10,2,,80,2,5171,,,-0.150053599491478,-0.00209174904745951,-0.000914371281396598,0.000329699192661792,,,,0.0380693642344558,39.995735168457,1.99919249325258,32.003532409668,31.9982376098633,31.9993057250977,-47484.76953125,-47385.52734375,0.647417843341827,1,6,3,4,23.1730000402331,1,20.6397684191688,1.12037658691406,44.4770278930664,40.0782012939453,,,,,,,,,,,,,,,,
,3875491704.19597,31.9989715576172,-40519.701171875,,,,,,,,,,,,,-0.13266968972619,1.42206278836531E-5,-1.56820313503224E-5,10,2,,80,2,5239,,,-0.128222274430263,-0.00168695554665743,-0.000781514507252723,0.000281145214103162,,,,0.0325292020864197,39.995735168457,1.9991312524101,32.0044364929199,31.9977264404297,32,-40571.63671875,-40467.765625,0.64752858877182,1,6,3,4,23.1730000402331,1,20.642523362966,1.12396240234375,43.9882698059082,40.0782012939453,,,,,,,,,,,,,,,,
,3875491843.60529,32.0017425537109,-33579.341796875,,,,,,,,,,,,,-0.110025141899151,1.43091800465853E-5,2.38561816859775E-6,10,2,,80,2,5307,,,-0.106282647069623,-0.00130482376896691,-0.000648011628072709,0.000232475678785704,,,,0.0269640394575888,39.995735168457,1.99920044555056,32.0055541992188,32.0010299682617,32.0024185180664,-33631.6796875,-33527.00390625,0.647622227668762,1,6,3,4,23.1730000402331,1,20.6425831490235,1.12068176269531,43.9882698059082,39.5894432067871,,,,,,,,,,,,,,,,
,3875491983.03202,31.9981079101562,-26626.265625,,,,,,,,,,,,,-0.0872964232955343,1.26677720905267E-5,3.03756095055894E-5,10,2,,80,2,5375,,,-0.0842877638385527,-0.000944760819332691,-0.000514115497935563,0.000183830765308812,,,,0.0213847103507009,39.995735168457,1.99928420619992,32.005558013916,31.9975738525391,31.9984359741211,-26676.169921875,-26576.361328125,0.647744655609131,1,6,3,4,23.1730000402331,1,20.6435863461752,1.114501953125,44.4770278930664,40.0782012939453,,,,,,,,,,,,,,,,
,3875492122.42678,31.9993629455566,-19671.9482421875,,,,,,,,,,,,,-0.0645449983546535,1.27676928564264E-5,5.0187383734611E-5,10,2,,80,2,5443,,,-0.0622944651884059,-0.000626163080685908,-0.00038010798743926,0.000135438604047522,,,,0.0158045755578802,39.995735168457,1.99925926677723,32.0067520141602,31.9992065429687,31.9995346069336,-19724.400390625,-19619.49609375,0.647657036781311,1,6,3,4,23.1730000402331,1,20.646301655034,1.12159729003906,43.0107536315918,40.0782012939453,,,,,,,,,,,,,,,,
,3875492261.92513,32.0017303466797,-12715.6772460938,,,,,,,,,,,,,-0.0417825359301389,1.07557086465692E-5,7.5134823317546E-5,1,2,,80,2,5511,,,-0.0403111314362105,-0.000335927180272847,-0.000246125331614166,8.72175223776139E-5,,,,0.0102268212169863,39.995735168457,1.99932020748577,32.0088768005371,32.0012054443359,32.0021133422852,-12767.951171875,-12663.4033203125,0.647863566875458,1,6,3,4,23.1730000402331,1,20.6453460781206,1.12113952636719,44.4770278930664,40.0782012939453,,,,,,,,,,,,,,,,
,3875492401.34931,32.0018920898438,-5758.92919921875,,,,,,,,,,,,,-0.0190725006976426,1.02581991375124E-5,4.33818579511091E-5,1,2,,80,2,5579,,,-0.0183951676695308,-0.000132775358084167,-0.000112354959128425,3.96785580960568E-5,,,,0.00466684220938213,39.995735168457,1.99930088074048,32.006404876709,32.0010375976562,32.002685546875,-5811.357421875,-5706.5009765625,0.647840142250061,1,6,3,4,23.1730000402331,1,20.6477032388974,1.12060546875,44.4770278930664,40.5669593811035,,,,,,,,,,,,,,,,
,3875492540.74366,31.9997444152832,1205.68884277344,,,,,,,,,,,,,0.00361883540778618,1.04064868415362E-5,-1.0482290871797E-5,1,2,,80,2,5647,,,0.0034897779258427,2.18030367190526E-5,2.13220646401169E-5,-7.50666185922455E-6,,,,0.00088532374403287,39.995735168457,1.99928653892065,32.0032081604004,31.99853515625,32.0013809204102,1153.20935058594,1258.16833496094,0.64779657125473,1,6,3,4,23.1730000402331,1,20.6476007351716,1.12350463867188,43.9882698059082,40.0782012939453,,,,,,,,,,,,,,,,
,3875492680.15674,32.0025634765625,8176.25927734375,,,,,,,,,,,,,0.0266370951716669,1.06895014004143E-5,-5.68340149266149E-5,1,2,,80,2,5715,,,0.025693686812531,0.000194535539588118,0.000156909241923131,-5.54812977497932E-5,,,,0.00651780071735537,39.995735168457,1.99926221435045,32.0019989013672,32.0010757446289,32.0034942626953,8123.9677734375,8228.55078125,0.647895395755768,1,6,3,4,23.1730000402331,1,20.6496067201378,1.12274169921875,43.9882698059082,39.5894432067871,,,,,,,,,,,,,,,,
,3875492819.56444,32.0004547119141,15149.3559570313,,,,,,,,,,,,,0.049524533603135,1.07916183887133E-5,-8.16627491394809E-5,1,2,,80,2,5783,,,0.0477863302145459,0.000416776355224441,0.000291705597192049,-0.000103510959888808,,,,0.0121226660179901,39.995735168457,1.9992008747228,32.0026931762695,31.9997177124023,32.0010375976562,15099.333984375,15199.3779296875,0.647747218608856,1,6,3,4,23.1730000402331,1,20.6477901964856,1.12174987792969,43.9882698059082,40.5669593811035,,,,,,,,,,,,,,,,
,3875492958.99952,32.0005432128906,22130.904296875,,,,,,,,,,,,,0.0724220952553974,1.14881184854213E-5,-8.15054791370826E-5,1,2,,80,2,5851,,,0.0699072487538536,0.000696228239298068,0.000426555663580075,-0.000151974803884514,,,,0.0177342406595907,39.995735168457,1.99922112962562,32.0016937255859,31.9996185302734,32.0012817382812,22078.2265625,22183.58203125,0.647861063480377,1,6,3,4,23.1730000402331,1,20.6499409288855,1.12167358398438,43.9882698059082,39.5894432067871,,,,,,,,,,,,,,,,
,3875493098.42727,32.000471496582,29121.1630859375,,,,,,,,,,,,,0.0953347584188455,1.23205512013747E-5,-7.41082305698374E-5,1,2,,80,2,5919,,,0.0920645789150681,0.00101685018920057,0.000561548629775643,-0.000200751441298053,,,,0.023355772935893,39.995735168457,1.99923546076946,32.0016288757324,31.9987945556641,32.0016555786133,29068.515625,29173.810546875,0.647791445255279,1,6,3,4,23.1730000402331,1,20.649364457446,1.11358642578125,43.9882698059082,40.0782012939453,,,,,,,,,,,,,,,,
,3875493237.84899,31.9999328613281,36113.0703125,,,,,,,,,,,,,0.118191475627552,1.32796484600462E-5,-6.93180814473371E-5,1,2,,80,2,5987,,,0.114192760470418,0.00136829014541032,0.000696338945999742,-0.000249695149250329,,,,0.0289719941804688,39.995735168457,1.99938818551561,32.0003852844238,31.9989318847656,32.0024642944336,36063,36163.140625,0.647571563720703,1,6,3,4,23.1730000402331,1,20.6508546904236,1.12220764160156,43.9882698059082,40.0782012939453,,,,,,,,,,,,,,,,
,3875493379.32624,32.0003051757812,43208.28515625,,,,,,,,,,,,,0.141355120527325,1.40752594061833E-5,2.23491699204311E-5,10,2,,80,2,6056,,,0.136645138998175,0.00184225007213999,0.000832793011795729,-0.000300058891298249,,,,0.0346701494272784,39.995735168457,1.99934325162767,32.0025596618652,32.0001983642578,32.0005798339844,43158.171875,43258.3984375,0.647805631160736,1,6,3,4,23.1730000402331,1,20.6522910416894,1.12098693847656,43.9882698059082,40.0782012939453,,,,,,,,,,,,,,,,
,3875493518.74356,32.0018310546875,50197.994140625,,,,,,,,,,,,,0.164111479784074,1.40824586307894E-5,2.35513606326972E-5,10,2,,80,2,6124,,,0.158734275022706,0.00225429228371156,0.000967169879004359,-0.000349306792486459,,,,0.0402751379084389,39.995735168457,1.99936208741989,32.0001373291016,32.0010070800781,32.003662109375,50147.84375,50248.14453125,0.647673428058624,1,6,3,4,23.1730000402331,1,20.6546431621499,1.11419677734375,43.9882698059082,39.5894432067871,,,,,,,,,,,,,,,,
,3875493658.15428,31.9983024597168,57187.8046875,,,,,,,,,,,,,0.186800293545496,1.77469032661098E-5,1.85398838609984E-5,10,2,,80,2,6192,,,0.180790102394304,0.00268893483718877,0.00110127159859985,-0.00039861528784968,,,,0.0458711801757628,39.995735168457,1.99933351201544,31.9987545013428,31.9978408813477,31.9987564086914,57137.421875,57238.1875,0.647666692733765,1,6,3,4,23.1730000402331,1,20.6564706426271,1.12449645996094,43.9882698059082,40.0782012939453,,,,,,,,,,,,,,,,
,3875493797.59209,32.0007724761963,64180.19921875,,,,,,,,,,,,,0.20942994060418,1.71315699513928E-5,8.45838364520836E-6,10,2,,80,2,6260,,,0.202823071563116,0.00314574455121871,0.00123516260646284,-0.000447960628662258,,,,0.0514592821230775,39.995735168457,1.99924935449082,31.9992084503174,31.9997177124023,32.0020141601562,64127.5,64232.8984375,0.647540032863617,1,6,3,4,23.1730000402331,1,20.656184173756,1.12281799316406,43.9882698059082,39.5894432067871,,,,,,,,,,,,,,,,
,3875493937.01026,32.0010894775391,71172.48046875,,,,,,,,,,,,,0.231902150269636,2.04745780027493E-5,-3.61030963200596E-5,10,2,,80,2,6328,,,0.224739629764785,0.00359177122869886,0.00136839295737445,-0.000497044937219471,,,,0.0570202703876641,39.995735168457,1.9992448627816,31.9979228973389,32.0002975463867,32.0016555786133,71122.328125,71222.6328125,0.647636711597443,1,6,3,4,23.1730000402331,1,20.6574503497371,1.11434936523438,43.9882698059082,39.5894432067871,,,,,,,,,,,,,,,,
,3875494076.42515,32.00107421875,78178.01953125,,,,,,,,,,,,,0.254273128153743,1.97963062927216E-5,-0.000114616401812919,10,2,,80,2,6396,,,0.246595841461046,0.00402592685507527,0.00150142714846879,-0.000545870105270296,,,,0.0625706812271654,39.995735168457,1.99939391568482,31.9986839294434,32.0006790161133,32.0018463134766,78124.78125,78231.2578125,0.647496521472931,1,6,3,4,23.1730000402331,1,20.6546899718017,1.12358093261719,43.9882698059082,39.5894432067871,,,,,,,,,,,,,,,,
,3875494215.82536,32.00146484375,85244.64453125,,,,,,,,,,,,,0.276689962173679,1.93352206491596E-5,-0.000226323229419631,10,2,,80,2,6464,,,0.268536773849833,0.0044495483010186,0.00163480616174638,-0.000594792945776135,,,,0.068134774552591,39.995735168457,1.99929485096665,31.9969692230225,32.0007781982422,32.0026168823242,85191.46875,85297.8203125,0.647417366504669,1,6,3,4,23.1730000402331,1,20.6540642991,1.1212158203125,43.9882698059082,39.5894432067871,,,,,,,,,,,,,,,,
,3875494355.24582,32.0025650024414,92312.5,,,,,,,,,,,,,0.298898102254382,1.85868850345809E-5,-0.000343552815020475,10,2,,80,2,6532,,,0.290314241197036,0.00488093634612222,0.00176723743788898,-0.000643337494693697,,,,0.0736603017238443,39.995735168457,1.99925190631512,31.9954833984375,32.0014801025391,32.00341796875,92259.21875,92365.78125,0.647501826286316,1,6,3,4,23.1730000402331,1,20.6505084795183,1.12197875976562,43.9882698059082,39.1006851196289,,,,,,,,,,,,,,,,
,3875494494.65686,32.00185546875,99383.68359375,,,,,,,,,,,,,0.320880915036963,1.61114553234977E-5,-0.000467853685919985,10,2,,80,2,6600,,,0.311912008100937,0.00531502825065734,0.00189851492177695,-0.000691494904458523,,,,0.0791359879174306,39.995735168457,1.99916107454063,31.9963264465332,32.001594543457,32.0021438598633,99332.96875,99434.3984375,0.647374987602234,1,6,3,4,23.1730000402331,1,20.6472725855824,1.11396789550781,43.9882698059082,39.5894432067871,,,,,,,,,,,,,,,,
,3875494634.09534,32.0006164550781,106451.21484375,,,,,,,,,,,,,0.342607294475858,2.53462444138938E-5,-0.000650951781461603,10,2,,80,2,6668,,,0.333300112445659,0.00569758936739033,0.0020285751670599,-0.000739137176424265,,,,0.0845605970937435,39.995735168457,1.99912312059858,31.99365234375,32.0004806518555,32.0008163452148,106400.4765625,106501.953125,0.647473990917206,1,6,3,4,23.1730000402331,1,20.65090644976,1.12281799316406,43.49951171875,39.5894432067871,,,,,,,,,,,,,,,,
,3875494773.51272,31.9991104125977,113519.6640625,,,,,,,,,,,,,0.36404949522182,2.8408811835071E-5,-0.000826880649866695,10,2,,80,2,6736,,,0.35444969223685,0.00608916994095973,0.00215715635567904,-0.000786059710662812,,,,0.089920876988543,39.995735168457,1.99900732455222,31.9915008544922,31.9988174438477,31.9993591308594,113469.0546875,113570.2734375,0.647399008274078,1,6,3,4,23.1730000402331,1,20.6477482915204,1.12236022949219,43.9882698059082,38.6119270324707,,,,,,,,,,,,,,,,
,3875494912.92156,31.9985305786133,120587.95703125,,,,,,,,,,,,,0.385170056047095,2.50881776994201E-5,-0.0010345055297325,10,2,,80,2,6804,,,0.375323992255855,0.00644828145269408,0.00228428398258984,-0.000832214078400284,,,,0.0952181027567971,39.995735168457,1.99903706979122,31.989013671875,31.9970092773438,32.0002212524414,120537.2734375,120638.640625,0.647386491298676,1,6,3,4,23.1730000402331,1,20.6438962935904,1.1236572265625,43.9882698059082,39.5894432067871,,,,,,,,,,,,,,,,
,3875495052.34171,32.0000869750977,127660.94921875,,,,,,,,,,,,,0.405940011506656,1.79652368017174E-5,-0.00124180369453883,10,2,,80,2,6872,,,0.395892620715496,0.0068025974106127,0.00240935292094946,-0.000877708196640015,,,,0.100430665999896,39.995735168457,1.99891972038325,31.9906597137451,31.9983215332031,32.0010604858398,127610.2265625,127711.671875,0.647251009941101,1,6,3,4,23.1730000402331,1,20.6422661656089,1.12152099609375,43.9882698059082,40.0782012939453,,,,,,,,,,,,,,,,
,3875495191.75938,32.0020523071289,134730.7109375,,,,,,,,,,,,,0.426308993212104,2.69717339906593E-5,-0.00149656117853566,10,2,,80,2,6940,,,0.416105368331866,0.00710169438464633,0.00253254710696638,-0.000922170584090054,,,,0.105561054754544,39.995735168457,1.99896264146599,31.988842010498,31.9998550415039,32.0030517578125,134680.046875,134781.375,0.647275984287262,1,6,3,4,23.1730000402331,1,20.6405886727152,1.12197875976562,43.9882698059082,40.0782012939453,,,,,,,,,,,,,,,,
,3875495331.17152,31.9974479675293,140000.234375,,,,,,,,,,,,,0.441328054026594,2.54717590799955E-5,-0.00166945750929005,10,2,,80,2,7008,,,0.431032363435568,0.0073357116792287,0.00262340367771685,-0.000954957329668105,,,,0.109344725151792,39.995735168457,1.99889477354069,31.9861164093018,31.9963150024414,31.9986114501953,140000.21875,140000.25,0.64721816778183,1,4,3,4,23.1730000402331,1,20.637624477265,1.12174987792969,43.9882698059082,39.5894432067871,,,,,,,,,,,,,,,,
,3875495415.25629,31.9991836547852,140000.5234375,,,,,,,,,,,,,0.441316177179432,2.80718766973777E-5,-0.00168839605099947,10,2,,80,2,7049,,,0.431021284180808,0.00731702547770727,0.00262339762412012,-0.000954814546275884,,,,0.109342757144643,39.995735168457,1.99890890175982,31.9883365631103,31.9981994628906,32.000114440918,140000.515625,140000.53125,0.647194504737854,1,4,3,4,23.1730000402331,1,20.6373715478825,1.12228393554688,43.9882698059082,39.5894432067871,,,,,,,,,,,,,,,,