File: MPMS/NiCl2btd/NiCl2btd_MvH_1p8K_14T.dat
[Header]
; ACMS II Data File (default extension .dat)
; Copyright (c) 2014, Quantum Design, Inc. All rights reserved.
TITLE,
FILEOPENTIME,3875393061.808,10/20/2022,2:05 am
BYAPP,ACMS II,1.0,1.2
INFO,DYNACOOL ACMS II Option Release 1.0.8 Build 33,APPNAME
INFO,Quantum Design Linear Motor Servo Controller,MOTOR_MODULE_NAME
INFO,3101-100 K0,MOTOR_HW_VERSION
INFO,MMC794,MOTOR_SERIAL_NUMBER
INFO,SRV No X-over 01.03.11,MOTOR_SOFTWARE_VERSION
INFO,ACMS,ACMS_MODULE_NAME
INFO,3101-430 A0,ACMS_HW_VERSION
INFO,ACMSII028,ACMS_SERIAL_NUMBER
INFO,00.14.14,ACMS_SOFTWARE_VERSION
INFO,WF046,COIL_SERIAL_NUMBER
INFO,0,MOMENT_UNITS
INFO,NiCl2-btdm,SAMPLE_MATERIAL
INFO,4.8mg cling film,SAMPLE_COMMENT
INFO,22.1,SAMPLE_MASS
INFO,,SAMPLE_VOLUME
INFO,,SAMPLE_MOLECULAR_WEIGHT
INFO,,SAMPLE_SIZE
INFO,,SAMPLE_SHAPE
DATATYPE,COMMENT,1
DATATYPE,TIME,2
STARTUPAXIS,X,2
STARTUPAXIS,Y1,5
STARTUPGROUP, AC
FIELDGROUP, AC, 2,3,4,5,6,7,8,9,10,11,12,13,14,15,16,20,21,22,23,24,25,35,43,44,45,46,47,48,49
FIELDGROUP, DC, 2,3,4,17,18,19,20,21,23,24,25,35,36,37,43,44,45,46,47,48,49,50,51
FIELDGROUP, Diagnostic, 26,27,28,29,30,31,32,33,34,38,39,40,41,42,52,53,54,55,56,57,58,59,60,61,62,63,64,65,66,67,68,69
[Data]
Comment,Time Stamp (sec),Temperature (K),Magnetic Field (Oe),AC Moment (emu),AC Std. Dev. (emu),AC Phase (deg),AC Phase Std. Dev. (deg),AC Suscept. (emu/Oe),AC Suscept. Std. Dev. (emu/Oe),AC X'  (emu/Oe),AC X" (emu/Oe),AC X' Std. Dev. (emu/Oe),AC X" Std. Dev. (emu/Oe),AC Drive (Oe),AC Frequency (Hz),DC Moment (emu),DC Std. Err. (emu),DC Quad. Moment (emu),Range (mV),"AC=1 DC=2 Locate=3",Measure Type,Measure Count,Measure Time (sec),Measure Number,AC X' Raw (emu/Oe),AC X" Raw (emu/Oe),DC M. Raw' (emu),DC M. Raw" (emu),Coil InPhase (V),Coil Quadrature (V),Null Status,Trim Ratio,Trim Phase (deg.),Max. Signal (mV),Motor Frequency (Hz),Motor Ampl. (mm),System Temp. (K),Min. Temperature (K),Max. Temperature (K),Min. Field (Oe),Max. Field (Oe),Pressure (Torr),Temp. Status (code),Field Status (code),Chamber Status (code),Measure Status (code),Center Position (mm),Transport Action,Motor Lag (deg),Motor Current (amps),Motor Heatsink Temp. (C),Motor Board Temp. (C),QMap 01,QMap 02,QMap 03,QMap 04,QMap 05,QMap 06,QMap 07,QMap 08,QMap 09,QMap 10,QMap 11,QMap 12,QMap 13,QMap 14,QMap 15,QMap 16
sample offset = 25.15 mm,3875395381.44331,1.80202688773473,0.0622519198805094,,,,,,,,,,,,,-0.037056677750688,2.71248438568571E-6,5.17935662946162E-5,1,2,,80,2,1,,,-0.0356889192286994,-0.000133544339826621,-0.000218293251236901,7.62102354201488E-5,,,,0.00905626680794191,39.995735168457,1.99967287061417,1.79967892169952,1.80136215686798,1.80236434936523,0.0533587895333767,0.0711450502276421,0.0563083216547966,1,4,3,4,23.1730000402331,1,20.6410479666044,1.12106323242188,29.8142719268799,30.7917900085449,,,,,,,,,,,,,,,,
,3875395529.16669,1.80078468322754,1619.2431640625,,,,,,,,,,,,,-0.0306041721386814,1.36803608771214E-5,7.34363174692852E-5,1,2,,80,2,70,,,-0.0294755192439222,-8.40632826609473E-5,-0.000180336035555229,6.28257112111896E-5,,,,0.00747918553287785,39.995735168457,1.99974763931341,1.79886257648468,1.80069804191589,1.80091989040375,1564.38549804687,1674.10083007813,0.0572945177555084,1,6,3,4,23.1730000402331,1,20.6543755031813,1.12434387207031,38.6119270324707,31.7693061828613,,,,,,,,,,,,,,,,
,3875395676.69401,1.80245814323425,8992.62158203125,,,,,,,,,,,,,0.00684476621786376,1.78103219148824E-5,-1.50155475129823E-5,1,2,,80,2,139,,,0.00659363655104341,2.51605383354021E-5,4.03265221393667E-5,-1.40936608659104E-5,,,,0.00167296030418684,39.995735168457,1.99971416389498,1.7940810918808,1.80233883857727,1.80252075195313,8937.748046875,9047.4951171875,0.0571707114577293,1,6,3,4,23.1730000402331,1,20.6557043667783,1.12167358398438,40.5669593811035,33.7243423461914,,,,,,,,,,,,,,,,
,3875395822.39997,1.80308825969696,16280.2529296875,,,,,,,,,,,,,0.0467214888441838,1.8138076916648E-5,-7.03772287645179E-5,1,2,,80,2,208,,,0.0450191889411118,0.000242705143378694,0.000275163707556203,-9.66688094194978E-5,,,,0.0114223533692305,39.995735168457,1.99958191921101,1.78519761562347,1.80297958850861,1.80315685272217,16227.7548828125,16332.7509765625,0.0567749366164207,1,6,3,4,23.1730000402331,1,20.658589451495,1.12098693847656,41.055721282959,35.190616607666,,,,,,,,,,,,,,,,
,3875395966.24607,1.80269122123718,23484.228515625,,,,,,,,,,,,,0.085813360158077,1.91694612619286E-5,-8.05592967723126E-5,1,2,,80,2,277,,,0.0827136037450443,0.000570759583856804,0.000505303731188178,-0.000178368776687421,,,,0.0209868759501084,39.995735168457,1.99961281175832,1.77641022205353,1.802659034729,1.80276596546173,23434.091796875,23534.365234375,0.0565350390970707,1,6,3,4,23.1730000402331,1,20.6577227333455,1.12091064453125,42.0332374572754,34.7018585205078,,,,,,,,,,,,,,,,
,3875396107.72973,1.80177691578865,30578.921875,,,,,,,,,,,,,0.123944384313346,1.69481603409008E-5,-9.33302315262068E-5,1,2,,80,2,346,,,0.119513125541261,0.000961758404047233,0.000729824125301093,-0.000258597254287452,,,,0.0303247287397582,39.995735168457,1.99963910128737,1.77007174491882,1.80161333084106,1.8018878698349,30528.76171875,30629.08203125,0.0563240796327591,1,6,3,4,23.1730000402331,1,20.6600013383317,1.11358642578125,42.0332374572754,36.6568908691406,,,,,,,,,,,,,,,,
,3875396251.27005,1.8013042807579,37777.3828125,,,,,,,,,,,,,0.159839129500518,1.74276051748366E-5,2.08446317834975E-5,10,2,,80,2,416,,,0.154193118904739,0.00152982003537451,0.000940949772484601,-0.00033536899718456,,,,0.0391246860715386,39.995735168457,1.99953321111013,1.7656307220459,1.80121898651123,1.80136442184448,37724.6953125,37830.0703125,0.0561384223401546,1,6,3,4,23.1730000402331,1,20.6588090411418,1.12159729003906,42.5219955444336,37.1456527709961,,,,,,,,,,,,,,,,
,3875396392.73394,1.80082023143768,44868.873046875,,,,,,,,,,,,,0.192771685982307,1.96734572501049E-5,4.19445035294472E-5,10,2,,80,2,485,,,0.186056411619816,0.00204402936702754,0.00113491981755942,-0.000405867758672684,,,,0.0472080274105989,39.995735168457,1.9994372331455,1.76276218891144,1.80062699317932,1.80102503299713,44818.79296875,44918.953125,0.0560472346842289,1,6,3,4,23.1730000402331,1,20.6589315210682,1.12167358398438,42.5219955444336,37.6344108581543,,,,,,,,,,,,,,,,
,3875396534.21502,1.80036244392395,51964.681640625,,,,,,,,,,,,,0.223488611774525,1.77721102352562E-5,5.0107449213805E-5,10,2,,80,2,554,,,0.215825237770085,0.00258148260281568,0.0013161291135475,-0.000472085492219776,,,,0.0547637388358019,39.995735168457,1.99952674114342,1.76083612442017,1.80020296573639,1.80047810077667,51914.5078125,52014.85546875,0.0558949559926987,1,6,3,4,23.1730000402331,1,20.6576395535098,1.121826171875,42.5219955444336,37.6344108581543,,,,,,,,,,,,,,,,
,3875396675.66565,1.8006468296051,59055.484375,,,,,,,,,,,,,0.252967994165375,2.1102060940525E-5,2.38107912309027E-5,10,2,,80,2,623,,,0.244445939075952,0.00312385709976148,0.00149017607327551,-0.000535886967554688,,,,0.0620236716701146,39.995735168457,1.99943863628667,1.75935840606689,1.80050492286682,1.80077385902405,59005.33203125,59105.63671875,0.0558766685426235,1,6,3,4,23.1730000402331,1,20.6574889003064,1.12236022949219,43.0107536315918,36.6568908691406,,,,,,,,,,,,,,,,
,3875396817.13222,1.80072276592255,66150.38671875,,,,,,,,,,,,,0.282079911238807,1.98751841046577E-5,-4.19651867528561E-5,10,2,,80,2,692,,,0.272761975684349,0.00367086859665547,0.00166237645316869,-0.000599001068621874,,,,0.0692063701227265,39.995735168457,1.99937207001851,1.75749254226685,1.80056524276733,1.80081486701965,66100.25,66200.5234375,0.0557975433766842,1,6,3,4,23.1730000402331,1,20.6548693750123,1.12144470214844,43.0107536315918,38.1231689453125,,,,,,,,,,,,,,,,
,3875396958.58649,1.80054132938385,73246.84765625,,,,,,,,,,,,,0.311225834697982,2.48585222776715E-5,-0.000134311713431377,10,2,,80,2,761,,,0.301164434045971,0.00423528587890654,0.00183514726813883,-0.000662415404804051,,,,0.0764144589843107,39.995735168457,1.99939890658631,1.75555229187012,1.80042397975922,1.80070054531097,73196.765625,73296.9296875,0.0557488165795803,1,6,3,4,23.1730000402331,1,20.6522703703737,1.12106323242188,43.0107536315918,38.6119270324707,,,,,,,,,,,,,,,,
,3875397100.08655,1.80077104568481,80378.65625,,,,,,,,,,,,,0.341420826971227,2.32376938519444E-5,-0.000292158838008139,10,2,,80,2,830,,,0.330641117032275,0.00479117835262527,0.00201444909907877,-0.000728030630853027,,,,0.0838921683224548,39.995735168457,1.99935721307487,1.75306105613709,1.80054128170013,1.80118656158447,80328.2421875,80429.0703125,0.0556437075138092,1,6,3,4,23.1730000402331,1,20.6502819951633,1.11419677734375,42.0332374572754,38.6119270324707,,,,,,,,,,,,,,,,
,3875397241.5559,1.80070608854294,87549.84765625,,,,,,,,,,,,,0.376123170646595,2.24740318348072E-5,-0.00047542008158489,10,2,,80,2,899,,,0.364548733357301,0.00542919310455559,0.00222057569772005,-0.000803533301223069,,,,0.0924901141010381,39.995735168457,1.9992205530002,1.75069296360016,1.80054593086243,1.80097794532776,87496.625,87603.0703125,0.0555570162832737,1,6,3,4,23.1730000402331,1,20.6502264581225,1.12152099609375,43.49951171875,37.1456527709961,,,,,,,,,,,,,,,,
,3875397383.00797,1.801207280159,94721.59765625,,,,,,,,,,,,,0.411777045875652,2.43562059862357E-5,-0.000736750532164074,10,2,,80,2,968,,,0.399450550462951,0.00604309223228816,0.00243301200680435,-0.000881057523656636,,,,0.101347648594402,39.995735168457,1.9992534369302,1.74762845039368,1.80104660987854,1.80148422718048,94670.90625,94772.2890625,0.0553260520100594,1,6,3,4,23.1730000402331,1,20.6503148767054,1.11351013183594,43.49951171875,39.1006851196289,,,,,,,,,,,,,,,,
,3875397524.47205,1.80128264427185,101896.0234375,,,,,,,,,,,,,0.446663837001786,3.01832817273714E-5,-0.000989712516119299,10,2,,80,2,1037,,,0.433680582702226,0.00668306137899619,0.00264142523519695,-0.000957112060859799,,,,0.110036936929799,39.995735168457,1.99932850278167,1.74436891078949,1.80110085010529,1.80147874355316,101845.5703125,101946.4765625,0.0552390180528164,1,6,3,4,23.1730000402331,1,20.6453569031643,1.12190246582031,43.49951171875,39.1006851196289,,,,,,,,,,,,,,,,
,3875397665.93482,1.80113551020622,109070.15625,,,,,,,,,,,,,0.480525928035398,2.42664422218619E-5,-0.00124877182013989,10,2,,80,2,1106,,,0.466987194411913,0.00732248113609268,0.00284380721859634,-0.00103134056553245,,,,0.118480266504311,39.995735168457,1.99918170082718,1.74036836624146,1.80106055736542,1.80121207237244,109019.453125,109120.859375,0.05506631731987,1,6,3,4,23.1730000402331,1,20.6458377080481,1.12174987792969,43.49951171875,38.1231689453125,,,,,,,,,,,,,,,,
,3875397807.40109,1.80157308578491,116242.578125,,,,,,,,,,,,,0.513415439093504,2.86826106843253E-5,-0.00157244990883953,10,2,,80,2,1175,,,0.499419130752938,0.007897312958214,0.00304124876856804,-0.00110339291859418,,,,0.126711720712299,39.995735168457,1.99923441194497,1.73658096790314,1.8014749288559,1.80167138576508,116189.359375,116295.796875,0.0549650005996227,1,6,3,4,23.1730000402331,1,20.6456901913771,1.12213134765625,43.49951171875,39.1006851196289,,,,,,,,,,,,,,,,
,3875397948.89101,1.80166234970093,123414.21875,,,,,,,,,,,,,0.545578477421556,3.171787847268E-5,-0.00189678200354278,10,2,,80,2,1244,,,0.53121137180272,0.00846698221738096,0.0032346723601222,-0.00117396039422601,,,,0.134775617080204,39.995735168457,1.9991974278371,1.73227083683014,1.80152440071106,1.80179738998413,123363.5,123464.9375,0.0547517165541649,1,6,3,4,23.1730000402331,1,20.6446018108697,1.11381530761719,43.49951171875,39.5894432067871,,,,,,,,,,,,,,,,
,3875398090.35631,1.80171698331833,130589.72265625,,,,,,,,,,,,,0.577110312690935,3.46838710282689E-5,-0.00222607268896648,10,2,,80,2,1313,,,0.562453646338019,0.00902292372708502,0.00342461466789246,-0.001243153703399,,,,0.142693873809757,39.995735168457,1.9990645100819,1.72737812995911,1.80153059959412,1.8018786907196,130539.03125,130640.4140625,0.054607093334198,1,6,3,4,23.1730000402331,1,20.642504655914,1.12236022949219,43.9882698059082,39.1006851196289,,,,,,,,,,,,,,,,
,3875398231.81925,1.80201601982117,137762.2421875,,,,,,,,,,,,,0.608159216778175,3.58216822596027E-5,-0.0025482924264541,10,2,,80,2,1382,,,0.593286075041204,0.00957386434282922,0.00361230154521763,-0.00131157774012536,,,,0.150519196365208,39.995735168457,1.99909038476914,1.72240126132965,1.80192184448242,1.80215239524841,137708.96875,137815.515625,0.0544205419719219,1,6,3,4,23.1730000402331,1,20.6411683077829,1.12228393554688,43.49951171875,39.5894432067871,,,,,,,,,,,,,,,,
,3875398373.28819,1.80024712085724,140000.359375,,,,,,,,,,,,,0.617743904392582,3.52117454296967E-5,-0.00265624621934054,10,2,,80,2,1451,,,0.602817925608368,0.00973525578912127,0.00367021933197975,-0.00133259175345302,,,,0.152932619769894,39.995735168457,1.99902136316006,1.7191789150238,1.8000785112381,1.80037367343903,140000.3125,140000.40625,0.0542109757661819,1,4,3,4,23.1730000402331,1,20.6402394735889,1.12197875976562,43.0107536315918,39.5894432067871,,,,,,,,,,,,,,,,
,3875398514.74538,1.79838213920593,134308.5625,,,,,,,,,,,,,0.59370035922446,2.83129919012765E-5,-0.00234141839761301,10,2,,80,2,1520,,,0.578910722526034,0.00936926389669873,0.00352463708259165,-0.00127980578690767,,,,0.146867780558361,39.995735168457,1.9990193335238,1.72119438648224,1.79814302921295,1.79852175712585,134259.140625,134357.984375,0.0543577186763287,1,6,3,4,23.1730000402331,1,20.6392901891122,1.12129211425781,43.9882698059082,39.5894432067871,,,,,,,,,,,,,,,,
,3875398656.21051,1.79844136238098,127308.0234375,,,,,,,,,,,,,0.563697192712128,3.7784593498002E-5,-0.00205140099001839,10,2,,80,2,1589,,,0.549138614542117,0.00881143925986891,0.00334358285181224,-0.00121367035899311,,,,0.139317685794626,39.995735168457,1.99907513896924,1.72591698169708,1.79834127426147,1.79861736297607,127258.578125,127357.46875,0.05459288880229,1,6,3,4,23.1730000402331,1,20.6412489353588,1.12167358398438,43.9882698059082,39.5894432067871,,,,,,,,,,,,,,,,
,3875398797.70375,1.79835436344147,120310.8203125,,,,,,,,,,,,,0.533332025533619,3.9115465931616E-5,-0.00168864642419105,10,2,,80,2,1658,,,0.519071263188268,0.0083169645248031,0.00316056585870683,-0.00114714726805687,,,,0.131689639074695,39.995735168457,1.9990936054057,1.73047721385956,1.79827558994293,1.79844152927399,120258.765625,120362.875,0.0546735674142838,1,6,3,4,23.1730000402331,1,20.6411225833841,1.11427307128906,43.49951171875,39.5894432067871,,,,,,,,,,,,,,,,
,3875398939.17157,1.79855861663818,113311.79296875,,,,,,,,,,,,,0.502487034721417,2.74548921935281E-5,-0.00139375953372294,10,2,,80,2,1727,,,0.488599095448022,0.00775164597614308,0.00297503266483545,-0.00107948633376509,,,,0.123954181096212,39.995735168457,1.99903379949316,1.73506438732147,1.79840075969696,1.79862821102142,113259.96875,113363.6171875,0.054927434772253,1,6,3,4,23.1730000402331,1,20.6447038359226,1.12060546875,43.9882698059082,39.5894432067871,,,,,,,,,,,,,,,,
,3875399080.64853,1.79848337173462,106311.8828125,,,,,,,,,,,,,0.47106991077741,2.27535056916444E-5,-0.00114356641575906,10,2,,80,2,1796,,,0.457634530017946,0.00714226972856041,0.0027869725599885,-0.00101042876485735,,,,0.116107528137331,39.995735168457,1.99920168948994,1.73925745487213,1.79838514328003,1.79861199855804,106259.9453125,106363.8203125,0.0550835020840168,1,6,3,4,23.1730000402331,1,20.6445868270285,1.12144470214844,43.9882698059082,39.5894432067871,,,,,,,,,,,,,,,,
,3875399222.09772,1.79861960411072,99314.59765625,,,,,,,,,,,,,0.438880544383461,2.6206986836944E-5,-0.000845190416623405,10,2,,80,2,1865,,,0.425984084959316,0.00658212345893511,0.00259431544691324,-0.000940014142543078,,,,0.108074009449267,39.995735168457,1.99913662656781,1.74317693710327,1.79851639270782,1.79876482486725,99265.109375,99364.0859375,0.0551972575485706,1,6,3,4,23.1730000402331,1,20.6424379561231,1.12159729003906,43.9882698059082,39.5894432067871,,,,,,,,,,,,,,,,
,3875399363.55973,1.79911172389984,92316.82421875,,,,,,,,,,,,,0.405630877424323,3.05646742879067E-5,-0.000658053649882114,10,2,,80,2,1934,,,0.393372925219011,0.00591871702666549,0.00239611766301095,-0.000867193972226232,,,,0.099804796718754,39.995735168457,1.99922420560613,1.74670159816742,1.79905807971954,1.79915523529053,92264.8828125,92368.765625,0.0553306676447391,1,6,3,4,23.1730000402331,1,20.6444002937876,1.11412048339844,43.9882698059082,40.0782012939453,,,,,,,,,,,,,,,,
,3875399505.05031,1.79894316196442,85314.5859375,,,,,,,,,,,,,0.370767654142983,2.48909551836935E-5,-0.000448596498208591,10,2,,80,2,2003,,,0.359264451527742,0.00528100622634016,0.00218843785114586,-0.000791359809227288,,,,0.0911457436864759,39.995735168457,1.99911064719243,1.74962329864502,1.79869294166565,1.79915452003479,85265.0078125,85364.1640625,0.0553729496896267,1,6,3,4,23.1730000402331,1,20.6487080743454,1.12113952636719,43.49951171875,39.5894432067871,,,,,,,,,,,,,,,,
,3875399646.51148,1.79892959594727,78320.23828125,,,,,,,,,,,,,0.335137223091938,2.23294264976877E-5,-0.000256317230201609,10,2,,80,2,2072,,,0.324481539550166,0.00465310023950828,0.00197685323655605,-0.000714010850060731,,,,0.0823220822686021,39.995735168457,1.9991478080521,1.7522577047348,1.79874861240387,1.79909193515778,78270.8203125,78369.65625,0.055536899715662,1,6,3,4,23.1730000402331,1,20.6478138253324,1.12174987792969,43.49951171875,39.5894432067871,,,,,,,,,,,,,,,,
,3875399787.97769,1.79924204945564,71319.5703125,,,,,,,,,,,,,0.305802381597409,2.24591938910858E-5,-0.000119914169783512,10,2,,80,2,2141,,,0.295856541054821,0.00410208425299456,0.00180279475171119,-0.000650234112981707,,,,0.0750617218985187,39.995735168457,1.99921206073299,1.75481474399567,1.79907965660095,1.79939591884613,71270.125,71369.015625,0.0555708967149258,1,6,3,4,23.1730000402331,1,20.6494547195318,1.121826171875,43.49951171875,39.5894432067871,,,,,,,,,,,,,,,,
,3875399929.43884,1.7991584777832,64319.796875,,,,,,,,,,,,,0.278358666648746,1.81860779558318E-5,-4.16350838860757E-5,10,2,,80,2,2210,,,0.269115479602779,0.00355838697504907,0.00164027407299727,-0.000590487383306026,,,,0.0682794283696863,39.995735168457,1.99931156799693,1.75664746761322,1.79908037185669,1.79927098751068,64270.22265625,64369.37109375,0.0557311810553074,1,6,3,4,23.1730000402331,1,20.6513737236209,1.12228393554688,43.49951171875,39.5894432067871,,,,,,,,,,,,,,,,
,3875400070.89957,1.7990996837616,57323.369140625,,,,,,,,,,,,,0.251577945366301,2.10587952006639E-5,3.41690920275895E-5,10,2,,80,2,2279,,,0.243064486684543,0.00306056545489196,0.00148180185351521,-0.000532451958861202,,,,0.0616699105713537,39.995735168457,1.99932259709845,1.75864517688751,1.79899394512177,1.79916763305664,57271.421875,57375.31640625,0.0558050200343132,1,6,3,4,23.1730000402331,1,20.6537426648916,1.11396789550781,43.9882698059082,40.0782012939453,,,,,,,,,,,,,,,,
,3875400212.36188,1.79941778182983,50326.80859375,,,,,,,,,,,,,0.225455068683555,2.11257732899967E-5,5.33605973407867E-5,10,2,,80,2,2348,,,0.217694722148557,0.00255820459739901,0.00132748112082481,-0.00047583322157152,,,,0.05523213079495,39.995735168457,1.99929844879759,1.76068258285522,1.79932880401611,1.7995480298996,50277.3203125,50376.296875,0.0559115260839462,1,6,3,4,23.1730000402331,1,20.6572529061147,1.12159729003906,43.9882698059082,39.5894432067871,,,,,,,,,,,,,,,,
,3875400353.86641,1.79896557331085,43327.564453125,,,,,,,,,,,,,0.199805506667005,1.72465349091921E-5,5.49560598383829E-5,10,2,,80,2,2417,,,0.192822896550821,0.00208857520938101,0.00117621885146946,-0.000420396449044347,,,,0.048922761636983,39.995735168457,1.99935033939206,1.76265430450439,1.79881417751312,1.79924094676971,43278.02734375,43377.1015625,0.0559741295874119,1,6,3,4,23.1730000402331,1,20.6573914218886,1.11473083496094,43.9882698059082,39.5894432067871,,,,,,,,,,,,,,,,
,3875400495.32742,1.79888067245483,36316.306640625,,,,,,,,,,,,,0.174417066111536,1.56339351394234E-5,2.52190211559393E-5,10,2,,80,2,2486,,,0.168239792543556,0.0016376502311836,0.00102661724667996,-0.000365743413567543,,,,0.0426851884256638,39.995735168457,1.99933495530046,1.76551592350006,1.79881107807159,1.79897928237915,36266.59765625,36366.015625,0.0561101250350475,1,6,3,4,23.1730000402331,1,20.6616832866914,1.12152099609375,43.9882698059082,39.5894432067871,,,,,,,,,,,,,,,,
,3875400636.7759,1.79857248067856,29281.876953125,,,,,,,,,,,,,0.149142697535427,1.40826084216179E-5,-3.10918172042814E-6,10,2,,80,2,2555,,,0.143798852481855,0.0012369873795929,0.000877840269822627,-0.000311637908453122,,,,0.0364847779537313,39.995735168457,1.99939442839707,1.76943695545197,1.79849934577942,1.79870069026947,29229.55859375,29334.1953125,0.0562379881739616,1,6,3,4,23.1730000402331,1,20.6626689199,1.12266540527344,43.9882698059082,40.0782012939453,,,,,,,,,,,,,,,,
,3875400778.24133,1.7975225687027,22244.2216796875,,,,,,,,,,,,,0.123343764300885,1.33030696602899E-5,-5.30447287491239E-5,10,2,,80,2,2624,,,0.118880605422997,0.000861171415346022,0.000726076774299145,-0.00025668230955489,,,,0.0301626536392125,39.995735168457,1.99945586438844,1.77475225925446,1.79748547077179,1.79759347438812,22191.99609375,22296.447265625,0.0563602559268475,1,6,3,4,23.1730000402331,1,20.6648490393046,1.123046875,43.9882698059082,39.5894432067871,,,,,,,,,,,,,,,,
,3875400919.71879,1.79637956619263,15209.9184570313,,,,,,,,,,,,,0.0977525897191988,1.34591876864323E-5,-9.04478942911418E-5,10,2,,80,2,2693,,,0.0941865016644066,0.000549744801616653,0.000575504265725613,-0.000202550814719871,,,,0.0238955202345648,39.995735168457,1.99935689260156,1.78307616710663,1.79625034332275,1.79652750492096,15160.3232421875,15259.513671875,0.0566387921571732,1,6,3,4,23.1730000402331,1,20.6656832850827,1.11366271972656,43.9882698059082,39.5894432067871,,,,,,,,,,,,,,,,
,3875401061.17584,1.79649674892426,8173.13208007812,,,,,,,,,,,,,0.0715952866217867,1.21730060172018E-5,-9.57220603295531E-5,10,2,,80,2,2762,,,0.0689663637869903,0.000315801315527407,0.000421637698309496,-0.000147776590893045,,,,0.0174989001017911,39.995735168457,1.99957044735009,1.7941722869873,1.79635906219482,1.79666090011597,8120.76708984375,8225.4970703125,0.0570691265165806,1,6,3,4,23.1730000402331,1,20.6627035112234,1.12091064453125,43.9882698059082,39.5894432067871,,,,,,,,,,,,,,,,
,3875401202.70924,1.80004711151123,1118.64117431641,,,,,,,,,,,,,0.0444961796663059,1.2438270715236E-5,-0.000105552123698008,1,2,,80,2,2831,,,0.0428547808314872,0.000121675962602359,0.000262142566498369,-9.13828916964121E-5,,,,0.0108728973174438,39.995735168457,1.99949652604832,1.79982113838196,1.79995584487915,1.80021071434021,1066.38122558594,1170.90112304688,0.0572683066129684,1,6,3,4,23.1730000402331,1,20.6662733414908,1.11419677734375,43.9882698059082,39.5894432067871,,,,,,,,,,,,,,,,
,3875401344.16228,1.80174403190613,-5931.50610351562,,,,,,,,,,,,,0.0164827231763943,1.24109761299225E-5,-4.29815945723435E-5,1,2,,80,2,2900,,,0.0158765533494758,4.86077903794771E-5,9.71035697148182E-5,-3.38805220962968E-5,,,,0.00402775751767911,39.995735168457,1.99941375214333,1.79687333106995,1.80157864093781,1.80192112922668,-5981.32470703125,-5881.6875,0.0571878589689732,1,6,3,4,23.1730000402331,1,20.669431720869,1.12205505371094,43.9882698059082,39.5894432067871,,,,,,,,,,,,,,,,
,3875401485.63037,1.80322661995888,-12984.2998046875,,,,,,,,,,,,,-0.0151829090321397,1.71291941545608E-5,2.37787386713345E-5,1,2,,80,2,2969,,,-0.014627831269492,-7.19564988169155E-5,-8.94112235982902E-5,3.13819473376498E-5,,,,0.00371124738847918,39.995735168457,1.99946382792313,1.78951776027679,1.80319178104401,1.80325448513031,-13036.6298828125,-12931.9697265625,0.0569041073322296,1,6,3,4,23.1730000402331,1,20.6688319580202,1.12220764160156,43.49951171875,39.5894432067871,,,,,,,,,,,,,,,,
,3875401627.11503,1.80286023616791,-20042.525390625,,,,,,,,,,,,,-0.0559757148231607,1.92150480224202E-5,6.27303886677332E-5,1,2,,80,2,3038,,,-0.0539449307840473,-0.000337851783442131,-0.000329581496771425,0.00011618020653259,,,,0.0136869754589562,39.995735168457,1.9994825799445,1.7802722454071,1.80274975299835,1.80296099185944,-20095.017578125,-19990.033203125,0.0566163025796413,1,6,3,4,23.1730000402331,1,20.669540164619,1.12205505371094,43.49951171875,40.0782012939453,,,,,,,,,,,,,,,,
,3875401768.55749,1.8018923997879,-27115.4140625,,,,,,,,,,,,,-0.0976983988607574,2.01471113587738E-5,7.57342600056785E-5,1,2,,80,2,3107,,,-0.0941870633823727,-0.000711399181887451,-0.000575167417991906,0.000203606541617773,,,,0.0238963986764673,39.995735168457,1.99943442508275,1.7723400592804,1.80138146877289,1.80211687088013,-27165.552734375,-27065.275390625,0.0562986172735691,1,6,3,4,23.1730000402331,1,20.6713696776943,1.13006591796875,43.49951171875,39.5894432067871,,,,,,,,,,,,,,,,
,3875401912.09959,1.80142421722412,-34292.896484375,,,,,,,,,,,,,-0.13794512539283,2.0476859655737E-5,-1.56392756921428E-5,10,2,,80,2,3177,,,-0.133042316542297,-0.00125377532458318,-0.000811896461527795,0.000289151765173301,,,,0.0337560194490344,39.995735168457,1.99941148470311,1.76707696914673,1.8013573884964,1.80148732662201,-34345.390625,-34240.40234375,0.0561187863349915,1,6,3,4,23.1730000402331,1,20.673498070221,1.11358642578125,43.49951171875,39.5894432067871,,,,,,,,,,,,,,,,
,3875402053.60391,1.80101628303528,-41368.767578125,,,,,,,,,,,,,-0.173815511065027,1.8285354674411E-5,-5.38801818622439E-5,10,2,,80,2,3246,,,-0.167717259845701,-0.0017772369109271,-0.00102309556677938,0.000365731393685564,,,,0.0425542448663754,39.995735168457,1.99943762517143,1.76392304897308,1.80091297626495,1.80114257335663,-41421.31640625,-41316.21875,0.0558867007493973,1,6,3,4,23.1730000402331,1,20.6739931109116,1.12312316894531,43.49951171875,40.0782012939453,,,,,,,,,,,,,,,,
,3875402195.07023,1.80069599151611,-48442.4140625,,,,,,,,,,,,,-0.206675787915973,1.72523673910508E-5,-4.8556648091852E-5,10,2,,80,2,3315,,,-0.199531472329201,-0.00229319881590997,-0.00121676991693676,0.00043618498602882,,,,0.0506263382873525,39.995735168457,1.9994020991116,1.76164519786835,1.80054903030396,1.80077159404755,-48492.43359375,-48392.39453125,0.0557923838496208,1,6,3,4,23.1730000402331,1,20.6735593952663,1.12228393554688,43.9882698059082,39.5894432067871,,,,,,,,,,,,,,,,
,3875402336.52868,1.80062057971954,-55516.650390625,,,,,,,,,,,,,-0.23726330909985,2.12754395963617E-5,-4.30094344521692E-5,10,2,,80,2,3384,,,-0.229197443646312,-0.0028411496842102,-0.00139720272272825,0.000502344686537981,,,,0.0581533007508487,39.995735168457,1.99937413407953,1.7600679397583,1.80051505565643,1.80077230930328,-55566.6640625,-55466.63671875,0.0557089895009994,1,6,3,4,23.1730000402331,1,20.6755286149727,1.12205505371094,43.49951171875,38.6119270324707,,,,,,,,,,,,,,,,
,3875402477.98607,1.80068719387054,-62589.93359375,,,,,,,,,,,,,-0.266830940748029,1.87845032014351E-5,5.60319993257097E-6,10,2,,80,2,3453,,,-0.257927269524164,-0.00338587337248215,-0.00157201488036662,0.000566422299016267,,,,0.0654457062923448,39.995735168457,1.99943844837587,1.75822257995605,1.80050802230835,1.80109453201294,-62642.5625,-62537.3046875,0.0556059665977955,1,6,3,4,23.1730000402331,1,20.6732138137763,1.12312316894531,42.5219955444336,39.5894432067871,,,,,,,,,,,,,,,,
,3875402619.43978,1.80067247152328,-69662.890625,,,,,,,,,,,,,-0.296050796748919,2.24999221097271E-5,6.43597527249229E-5,10,2,,80,2,3522,,,-0.286372602129646,-0.00396155448800797,-0.00174497033003718,0.000630073016509414,,,,0.0726634742207081,39.995735168457,1.99943312652069,1.75612807273865,1.80039918422699,1.80088436603546,-69712.7890625,-69612.9921875,0.0556209571659565,1,6,3,4,23.1730000402331,1,20.6714549144075,1.11442565917969,43.9882698059082,39.5894432067871,,,,,,,,,,,,,,,,
,3875402760.94456,1.80045883655548,-76740.76953125,,,,,,,,,,,,,-0.325579065681212,1.92114420517692E-5,0.000182030500506496,10,2,,80,2,3591,,,-0.315171977821456,-0.00452528550196785,-0.00192000612150878,0.000694372633006424,,,,0.0799664131834824,39.995735168457,1.99931335352288,1.754065990448,1.8002724647522,1.80087292194366,-76793.3671875,-76688.171875,0.0555579997599125,1,6,3,4,23.1730000402331,1,20.6703802484478,1.12319946289062,43.9882698059082,40.0782012939453,,,,,,,,,,,,,,,,
,3875402902.40996,1.80108165740967,-83888.41796875,,,,,,,,,,,,,-0.357736841702172,2.51115424150661E-5,0.000348845156535312,10,2,,80,2,3660,,,-0.346579903313233,-0.00512033829758973,-0.00211108708754182,0.000764278578571975,,,,0.087935360386737,39.995735168457,1.9993033017447,1.75164341926575,1.80095314979553,1.80119276046753,-83938.9921875,-83837.84375,0.0553674697875977,1,6,3,4,23.1730000402331,1,20.6657933827995,1.11465454101562,43.49951171875,39.5894432067871,,,,,,,,,,,,,,,,
,3875403043.88425,1.80118656158447,-91038.78125,,,,,,,,,,,,,-0.393446405867129,3.00772525142128E-5,0.000543161079423722,10,2,,80,2,3729,,,-0.381496771028377,-0.00578081196618602,-0.00232351780869067,0.00084213784430176,,,,0.096796574047831,39.995735168457,1.99933597124969,1.74879109859467,1.80103659629822,1.80138754844666,-91091.8515625,-90985.7109375,0.0553612634539604,1,6,3,4,23.1730000402331,1,20.6648487666134,1.1224365234375,43.9882698059082,40.0782012939453,,,,,,,,,,,,,,,,
,3875403185.33899,1.80116121768951,-98191.6796875,,,,,,,,,,,,,-0.428704915024922,2.34041722438026E-5,0.000806820248030258,10,2,,80,2,3798,,,-0.416049283682754,-0.0064009301425926,-0.00253354315645993,0.00091877457452938,,,,0.105553244875062,39.995735168457,1.99912450076472,1.74570751190186,1.80079853534698,1.8013242483139,-98239.78125,-98143.578125,0.0551784634590149,1,6,3,4,23.1730000402331,1,20.661849162034,1.12190246582031,43.9882698059082,39.1006851196289,,,,,,,,,,,,,,,,
,3875403326.80485,1.80131995677948,-105344.953125,,,,,,,,,,,,,-0.463017457145247,1.87156717809848E-5,0.0010742011486415,10,2,,80,2,3867,,,-0.449755521153416,-0.00702826711479199,-0.0027386078145355,0.000993573339655995,,,,0.114102975144712,39.995735168457,1.9990783499065,1.74265158176422,1.80107605457306,1.80155289173126,-105397.984375,-105291.921875,0.0549314022064209,1,6,3,4,23.1730000402331,1,20.6560071901768,1.11351013183594,43.49951171875,39.1006851196289,,,,,,,,,,,,,,,,
,3875403468.25462,1.80129247903824,-112492.0390625,,,,,,,,,,,,,-0.496329199136548,3.00098609848826E-5,0.00142014019834903,10,2,,80,2,3936,,,-0.48256084218404,-0.00758077340254978,-0.00293832877650857,0.00106613570824265,,,,0.122426163282809,39.995735168457,1.99907503341627,1.73840761184692,1.80122065544128,1.80136358737946,-112545.1328125,-112438.9453125,0.0548573508858681,1,6,3,4,23.1730000402331,1,20.6530525531259,1.11495971679688,43.9882698059082,39.5894432067871,,,,,,,,,,,,,,,,
,3875403609.75453,1.80165009498596,-119647.72265625,,,,,,,,,,,,,-0.528757775099612,3.78696464556016E-5,0.00174243259526917,10,2,,80,2,4005,,,-0.514575610242132,-0.00815284083899631,-0.00313311349600554,0.00113703508395702,,,,0.13054503932114,39.995735168457,1.99901688838413,1.73425161838531,1.80156922340393,1.80171692371368,-119698.359375,-119597.0859375,0.0546655654907227,1,6,3,4,23.1730000402331,1,20.6489795561281,1.12159729003906,42.5219955444336,39.5894432067871,,,,,,,,,,,,,,,,
,3875403751.22069,1.80156011581421,-126797.94140625,,,,,,,,,,,,,-0.560476980470382,3.36710843498523E-5,0.0020341181819446,10,2,,80,2,4074,,,-0.545964411057555,-0.00874716792691385,-0.00332397012971342,0.00120659510139376,,,,0.138500766947598,39.995735168457,1.99890868369477,1.72984564304352,1.80145180225372,1.80165350437164,-126851.015625,-126744.8671875,0.0544956550002098,1,6,3,4,23.1730000402331,1,20.643316445496,1.1138916015625,43.0107536315918,39.5894432067871,,,,,,,,,,,,,,,,
,3875403892.68522,1.80191261768341,-133947.953125,,,,,,,,,,,,,-0.591697781054668,2.98732279879193E-5,0.00237944444348797,10,2,,80,2,4143,,,-0.576931139122723,-0.00928001594604985,-0.00351218855939806,0.0012751369504258,,,,0.146345516166169,39.995735168457,1.99876402706656,1.725217461586,1.80182456970215,1.80207812786102,-133998.4375,-133897.46875,0.0543749183416367,1,6,3,4,23.1730000402331,1,20.6428264184035,1.12220764160156,43.49951171875,39.5894432067871,,,,,,,,,,,,,,,,
,3875404034.1586,1.80101804733276,-139999.7109375,,,,,,,,,,,,,-0.617742237244573,3.65260551145495E-5,0.00263925706686518,10,2,,80,2,4212,,,-0.60281590781629,-0.00975177797344914,-0.0036698910407722,0.00133240118157119,,,,0.152916688661814,39.995735168457,1.99883145339637,1.72020494937897,1.80086731910706,1.80115568637848,-139999.734375,-139999.6875,0.0541203841567039,1,4,3,4,23.1730000402331,1,20.6376818534534,1.11434936523438,44.4770278930664,39.1006851196289,,,,,,,,,,,,,,,,
,3875404175.60514,1.79908037185669,-138075.921875,,,,,,,,,,,,,-0.609633279126664,4.29518688143134E-5,0.00256276559634531,10,2,,80,2,4281,,,-0.59474917901265,-0.00959976481559679,-0.00362073164433241,0.00131452281493694,,,,0.150868095179491,39.995735168457,1.99879895722521,1.71986162662506,1.79899168014526,1.79912054538727,-138127.921875,-138023.921875,0.0541130416095257,1,6,3,4,23.1730000402331,1,20.6393289633313,1.12342834472656,43.9882698059082,40.5669593811035,,,,,,,,,,,,,,,,
,3875404317.06252,1.79847886562347,-131065.25,,,,,,,,,,,,,-0.579822760632162,3.40184193515839E-5,0.00224542714440567,10,2,,80,2,4350,,,-0.565133232435362,-0.00907424075571067,-0.00344054098241031,0.00124880112707615,,,,0.14335676225982,39.995735168457,1.99880713771915,1.7238130569458,1.79840075969696,1.79853796958923,-131114.828125,-131015.671875,0.0542822629213333,1,6,3,4,23.1730000402331,1,20.6396897733102,1.11488342285156,43.9882698059082,39.5894432067871,,,,,,,,,,,,,,,,
,3875404458.56785,1.79815158843994,-124051.51953125,,,,,,,,,,,,,-0.549626279456861,2.87115346150565E-5,0.00190555468354094,10,2,,80,2,4419,,,-0.535197694039952,-0.00855989919902514,-0.0032583640422672,0.00118254718836397,,,,0.135764676227198,39.995735168457,1.99882773632018,1.72859108448029,1.79784071445465,1.79833829402924,-124101.15625,-124001.8828125,0.0544647872447968,1,6,3,4,23.1730000402331,1,20.6412766788427,1.12136840820312,43.9882698059082,40.0782012939453,,,,,,,,,,,,,,,,
,3875404600.02557,1.79826724529266,-117037.02734375,,,,,,,,,,,,,-0.518988198827182,2.54591172391406E-5,0.00155226643816808,10,2,,80,2,4488,,,-0.504891837113147,-0.0080517162799201,-0.00307395169511437,0.00111565657425672,,,,0.128080769945673,39.995735168457,1.99890003687129,1.73313665390015,1.79805755615234,1.79841065406799,-117086.6328125,-116987.421875,0.0547016113996506,1,6,3,4,23.1730000402331,1,20.6445581964549,1.12106323242188,44.4770278930664,39.5894432067871,,,,,,,,,,,,,,,,
,3875404741.48767,1.79865489006042,-110025.3125,,,,,,,,,,,,,-0.487799447180201,2.82488553160984E-5,0.00123722804525653,10,2,,80,2,4557,,,-0.474113542932119,-0.00750305229894052,-0.00288682919926941,0.00104720355011523,,,,0.120276536920719,39.995735168457,1.99897017013271,1.73741149902344,1.79852557182312,1.79893910884857,-110077.3515625,-109973.2734375,0.0548334158957005,1,6,3,4,23.1730000402331,1,20.6420920270011,1.11335754394531,43.9882698059082,40.0782012939453,,,,,,,,,,,,,,,,
,3875404882.95782,1.79888625144958,-103009.73046875,,,,,,,,,,,,,-0.455993665527472,2.72108171272845E-5,0.000978944528653081,10,2,,80,2,4626,,,-0.442800681299422,-0.00690065996530717,-0.00269636395387352,0.000977508956566453,,,,0.112332299909006,39.995735168457,1.9989797209134,1.74125838279724,1.79878866672516,1.79901707172394,-103061.6796875,-102957.78125,0.0549926683306694,1,6,3,4,23.1730000402331,1,20.6445922597573,1.12083435058594,44.4770278930664,40.0782012939453,,,,,,,,,,,,,,,,
,3875405024.41546,1.79846566915512,-95996.41015625,,,,,,,,,,,,,-0.423293666324737,2.72507457184507E-5,0.000745739188461862,10,2,,80,2,4695,,,-0.410686074615141,-0.00627764597063496,-0.00250099552795291,0.000905937282368541,,,,0.104183364587,39.995735168457,1.99894797684863,1.74498689174652,1.79833197593689,1.79854881763458,-96046.0078125,-95946.8125,0.0551586970686913,1,6,3,4,23.1730000402331,1,20.6465964524463,1.1224365234375,44.4770278930664,40.0782012939453,,,,,,,,,,,,,,,,
,3875405165.88709,1.79895231127739,-88982.5859375,,,,,,,,,,,,,-0.389248961866761,2.14715486443489E-5,0.000517351375053728,10,2,,80,2,4764,,,-0.377334470877115,-0.00565394475574532,-0.0022983883973211,0.000831777928397059,,,,0.0957333026917277,39.995735168457,1.99918118954466,1.74832952022552,1.79889440536499,1.79906260967255,-89034.6953125,-88930.4765625,0.0552106127142906,1,6,3,4,23.1730000402331,1,20.6469421741455,1.12281799316406,43.9882698059082,40.0782012939453,,,,,,,,,,,,,,,,
,3875405307.38201,1.79941573143005,-81963.06640625,,,,,,,,,,,,,-0.353554391528258,2.53901767180432E-5,0.000354884531259259,10,2,,80,2,4833,,,-0.342453204295599,-0.00497437807275254,-0.00208622589707375,0.000754104054067284,,,,0.0868847704314958,39.995735168457,1.9992124433811,1.751131772995,1.79915916919708,1.79993498325348,-82012.703125,-81913.4296875,0.0554305948317051,1,6,3,4,23.1730000402331,1,20.6514988094317,1.12174987792969,43.9882698059082,40.5669593811035,,,,,,,,,,,,,,,,
,3875405448.8262,1.79918100833893,-74951.3671875,,,,,,,,,,,,,-0.320428114211386,1.66888579268922E-5,0.000200235493902365,10,2,,80,2,4902,,,-0.310126208226148,-0.00436568149080631,-0.00188944698311388,0.000682112528011203,,,,0.0786787770822375,39.995735168457,1.99909743852688,1.75383079051971,1.79915297031403,1.79922080039978,-75001,-74901.734375,0.0554851330816746,1,6,3,4,23.1730000402331,1,20.6540683801435,1.12213134765625,44.4770278930664,40.0782012939453,,,,,,,,,,,,,,,,
,3875405590.29681,1.79914536476135,-67934.9921875,,,,,,,,,,,,,-0.29250970119243,2.18357424875119E-5,0.000100708545285922,10,2,,80,2,4971,,,-0.282898263818822,-0.00381609852557245,-0.00172402919270098,0.000621254788711667,,,,0.0717747214037494,39.995735168457,1.99923863884336,1.75600576400757,1.79910123348236,1.79920542240143,-67984.5546875,-67885.4296875,0.055426262319088,1,6,3,4,23.1730000402331,1,20.6542170023543,1.12228393554688,44.4770278930664,40.0782012939453,,,,,,,,,,,,,,,,
,3875405731.76289,1.79927629232407,-60917.375,,,,,,,,,,,,,-0.265294336810849,2.11211755492517E-5,6.97224861820725E-6,10,2,,80,2,5040,,,-0.256401534475041,-0.00330853875874,-0.00156285113189369,0.000562278204597533,,,,0.0650523107750939,39.995735168457,1.99926999790576,1.75790691375732,1.79923331737518,1.79931807518005,-60966.8828125,-60867.8671875,0.0555902905762196,1,6,3,4,23.1730000402331,1,20.6586830217331,1.12098693847656,44.4770278930664,40.5669593811035,,,,,,,,,,,,,,,,
,3875405873.22129,1.79961875081062,-53903.52734375,,,,,,,,,,,,,-0.238771905759001,1.93623875820808E-5,-2.90141904372805E-5,10,2,,80,2,5109,,,-0.23062265280482,-0.00279511912137258,-0.00140614656265825,0.000504725438077003,,,,0.0585138062206029,39.995735168457,1.99936658365461,1.75974369049072,1.79943764209747,1.79984378814697,-53955.61328125,-53851.44140625,0.0556512847542763,1,6,3,4,23.1730000402331,1,20.6612210069341,1.12144470214844,43.9882698059082,39.5894432067871,,,,,,,,,,,,,,,,
,3875406014.68699,1.79916360378265,-46886.333984375,,,,,,,,,,,,,-0.212852849048919,1.93901389116054E-5,-4.61549836956782E-5,10,2,,80,2,5178,,,-0.20546985039458,-0.00231401347214652,-0.00125325436238199,0.000448590581072494,,,,0.0521349932415452,39.995735168457,1.99950172934628,1.76171886920929,1.79888200759888,1.79933977127075,-46938.6484375,-46834.01953125,0.055715411901474,1,6,3,4,23.1730000402331,1,20.6595051236231,1.124267578125,44.4770278930664,40.0782012939453,,,,,,,,,,,,,,,,
,3875406156.17685,1.79903811216354,-39871.962890625,,,,,,,,,,,,,-0.187245879761019,1.6306750266205E-5,-4.38543292892181E-5,10,2,,80,2,5247,,,-0.180657486712612,-0.0018633653577045,-0.00110225030221045,0.000393459835322574,,,,0.0458389872002116,39.995735168457,1.99951434617217,1.7639422416687,1.79898083209991,1.79913055896759,-39921.5859375,-39822.33984375,0.0559095330536366,1,6,3,4,23.1730000402331,1,20.6640070674047,1.12281799316406,44.4770278930664,40.5669593811035,,,,,,,,,,,,,,,,
,3875406297.64867,1.79856017231941,-32825.248046875,,,,,,,,,,,,,-0.161933750979153,1.43343140194868E-5,-1.01725829265967E-5,10,2,,80,2,5316,,,-0.15616417868416,-0.00143224068602944,-0.000953231006860733,0.000339053920470178,,,,0.039626039099347,39.995735168457,1.9996215215819,1.76679944992065,1.79846704006195,1.798663854599,-32872.6796875,-32777.81640625,0.0559892393648624,1,6,3,4,23.1730000402331,1,20.6648512194433,1.12220764160156,44.4770278930664,40.0782012939453,,,,,,,,,,,,,,,,
,3875406439.11752,1.79811763763428,-25768.3095703125,,,,,,,,,,,,,-0.136355917068386,1.47042204333475E-5,3.3802039772155E-5,10,2,,80,2,5385,,,-0.13144515262577,-0.00103816952978502,-0.00080263678682968,0.000284414330963045,,,,0.0333530206079028,39.995735168457,1.99952299431567,1.77174067497253,1.79807066917419,1.79825103282928,-25820.6015625,-25716.017578125,0.0560592338442802,1,6,3,4,23.1730000402331,1,20.6696582112763,1.12174987792969,43.9882698059082,41.055721282959,,,,,,,,,,,,,,,,
,3875406580.57758,1.79690344333649,-18715.2939453125,,,,,,,,,,,,,-0.110571284883462,1.33297017733791E-5,7.18706619005284E-5,10,2,,80,2,5454,,,-0.106553057032888,-0.000699040955661326,-0.000650933536235243,0.000229715718887746,,,,0.0270363116873015,39.995735168457,1.99953610299498,1.7786853313446,1.79678738117218,1.79699754714966,-18765.181640625,-18665.40625,0.0563437268137932,1,6,3,4,23.1730000402331,1,20.6725504201637,1.11495971679688,44.4770278930664,40.5669593811035,,,,,,,,,,,,,,,,
,3875406722.0329,1.79628989100456,-11659.2094726563,,,,,,,,,,,,,-0.0846547770778028,1.2558976368821E-5,9.43612176903801E-5,10,2,,80,2,5523,,,-0.0815556824552384,-0.000424863210914801,-0.0004984614206478,0.00017517180822324,,,,0.0206942426612813,39.995735168457,1.99957890724279,1.78851819038391,1.79604864120483,1.79643595218658,-11709.1474609375,-11609.271484375,0.0566534548997879,1,6,3,4,23.1730000402331,1,20.6746688206363,1.12960815429688,44.4770278930664,40.5669593811035,,,,,,,,,,,,,,,,
,3875406863.57726,1.79804259538651,-4593.22119140625,,,,,,,,,,,,,-0.057957035367826,1.22589490915329E-5,0.000128134057628559,1,2,,80,2,5592,,,-0.0558234551438735,-0.000185275980332616,-0.000341402104822919,0.000119259981147479,,,,0.0141633871901196,39.995735168457,1.99953612562771,1.79853665828705,1.79795026779175,1.79811370372772,-4645.7265625,-4540.7158203125,0.0570239312946796,1,6,3,4,23.1730000402331,1,20.675774007583,1.1224365234375,44.4770278930664,40.5669593811035,,,,,,,,,,,,,,,,
,3875407005.0382,1.80110445618629,2477.06567382813,,,,,,,,,,,,,-0.0300920252712492,1.23269460977001E-5,7.32298318346377E-5,1,2,,80,2,5661,,,-0.0289827926616476,-8.38291260147044E-5,-0.000177268899278715,6.18472549831495E-5,,,,0.00735282488439313,39.995735168457,1.99946389177694,1.79848504066467,1.80102503299713,1.80114483833313,2424.53686523438,2529.59448242187,0.0571323595941067,1,6,3,4,23.1730000402331,1,20.6780192940931,1.12129211425781,44.4770278930664,40.0782012939453,,,,,,,,,,,,,,,,
,3875407146.51086,1.80258224010468,9550.67626953125,,,,,,,,,,,,,-0.00161655993066031,1.37087793126624E-5,5.08935835516327E-6,1,2,,80,2,5730,,,-0.00155728685364592,-4.55654441224734E-6,-9.52549362409627E-6,3.32306717609754E-6,,,,0.000395255358132603,39.995735168457,1.99957033607393,1.79369521141052,1.80241465568542,1.80272102355957,9500.677734375,9600.6748046875,0.0569150447845459,1,6,3,4,23.1730000402331,1,20.6746081607378,1.123046875,44.4770278930664,40.5669593811035,,,,,,,,,,,,,,,,
,3875407287.96273,1.80334465503693,16624.427734375,,,,,,,,,,,,,0.0358334311663904,1.84139106694705E-5,-5.04182109792919E-5,1,2,,80,2,5799,,,0.0345283076784117,0.000191089814063893,0.000211011749343015,-7.42369302315638E-5,,,,0.00876068842953574,39.995735168457,1.99960792736389,1.78442943096161,1.80325675010681,1.80342233181,16571.93359375,16676.921875,0.0566391758620739,1,6,3,4,23.1730000402331,1,20.6759048359785,1.1224365234375,44.4770278930664,39.5894432067871,,,,,,,,,,,,,,,,
,3875407429.42726,1.80309250354767,23711.67578125,,,,,,,,,,,,,0.0774045606532688,1.99360181401001E-5,-7.27690686195458E-5,1,2,,80,2,5868,,,0.0746093994367049,0.00051700578992963,0.000455743953352794,-0.000161064686835743,,,,0.0189314769052233,39.995735168457,1.99965350180548,1.77596414089203,1.80294787883759,1.8032785654068,23659.025390625,23764.326171875,0.0563811436295509,1,6,3,4,23.1730000402331,1,20.6773141156577,1.12434387207031,43.9882698059082,40.0782012939453,,,,,,,,,,,,,,,,
,3875407570.89192,1.80168633460999,30804.615234375,,,,,,,,,,,,,0.118815687498269,1.99631801191729E-5,-6.90481311588406E-5,1,2,,80,2,5937,,,0.114569135446706,0.000945205025647981,0.000699493160936981,-0.000248279946390539,,,,0.0290708417460099,39.995735168457,1.99962293929877,1.76985704898834,1.80152595043182,1.8018354177475,30754.42578125,30854.8046875,0.0559872016310692,1,6,3,4,23.1730000402331,1,20.6796562980829,1.12152099609375,43.9882698059082,40.5669593811035,,,,,,,,,,,,,,,,
,3875407712.38288,1.8012309551239,37900.556640625,,,,,,,,,,,,,0.156562767623425,2.10686777464333E-5,-5.30273001278466E-5,1,2,,80,2,6006,,,0.151034434512561,0.00143019098659192,0.000921814236789942,-0.000328464870108292,,,,0.0383262695489399,39.995735168457,1.99979434920768,1.76560235023499,1.80111312866211,1.80140995979309,37850.3828125,37950.73046875,0.0559090636670589,1,6,3,4,23.1730000402331,1,20.6800842271376,1.12136840820312,43.9882698059082,40.0782012939453,,,,,,,,,,,,,,,,
,3875407855.91797,1.80075907707214,45094.63671875,,,,,,,,,,,,,0.191476292612414,1.88133764836257E-5,4.14855768524282E-5,10,2,,80,2,6076,,,0.184809304064468,0.00203588885611254,0.00112722883932292,-0.000403762998757884,,,,0.0468968325274356,39.995735168457,1.99965645047416,1.76266312599182,1.80062091350555,1.80092990398407,45044.4609375,45144.8125,0.0558199100196362,1,6,3,4,23.1730000402331,1,20.6863001067709,1.11427307128906,44.4770278930664,40.5669593811035,,,,,,,,,,,,,,,,
,3875407997.39833,1.80041697025299,52192.8125,,,,,,,,,,,,,0.223075077412147,1.95304332899357E-5,2.4639819738588E-5,10,2,,80,2,6145,,,0.215430290715166,0.00255889782701844,0.00131365144625306,-0.00047179643297568,,,,0.0546687203740299,39.995735168457,1.99971804063638,1.7605265378952,1.80030333995819,1.8005576133728,52140.15234375,52245.47265625,0.0556521564722061,1,6,3,4,23.1730000402331,1,20.6855589302212,1.11480712890625,43.9882698059082,40.0782012939453,,,,,,,,,,,,,,,,
,3875408138.83476,1.80043654441834,59283.453125,,,,,,,,,,,,,0.253070951715811,2.02645555558302E-5,2.80962445945814E-5,10,2,,80,2,6214,,,0.244550479007819,0.00313668179345133,0.0014906944707036,-0.00053697731345892,,,,0.0620575659994024,39.995735168457,1.99966970920088,1.75909125804901,1.80038058757782,1.80059993267059,59230.76953125,59336.13671875,0.0555434338748455,1,6,3,4,23.1730000402331,1,20.6855560639308,1.12495422363281,43.49951171875,39.5894432067871,,,,,,,,,,,,,,,,
,3875408280.31842,1.80081775188446,66378.40234375,,,,,,,,,,,,,0.282508824885393,1.98101933373518E-5,-4.30485727552194E-5,10,2,,80,2,6283,,,0.273182888879921,0.00368349403665458,0.00166490883566439,-0.000601017032749951,,,,0.0693276514955382,39.995735168457,1.99976396883235,1.75738310813904,1.8007321357727,1.80087435245514,66330.7578125,66426.046875,0.0554789751768112,1,6,3,4,23.1730000402331,1,20.687013461693,1.11564636230469,44.4770278930664,38.6119270324707,,,,,,,,,,,,,,,,
,3875408421.77975,1.80089411735535,73474.62109375,,,,,,,,,,,,,0.311903041195371,1.53496867716922E-5,-0.000165764414868833,10,2,,80,2,6352,,,0.301827438068685,0.00422285832909147,0.00183907861355692,-0.000665025087073445,,,,0.076595586002967,39.995735168457,1.9997035849695,1.7552627325058,1.80067348480225,1.80110454559326,73421.9140625,73527.328125,0.0554245337843895,1,6,3,4,23.1730000402331,1,20.6892093383738,1.11488342285156,43.9882698059082,42.5219955444336,,,,,,,,,,,,,,,,
,3875408563.27358,1.80100975036621,80606.63671875,,,,,,,,,,,,,0.342279098407035,2.21232699263551E-5,-0.000272305052373747,10,2,,80,2,6421,,,0.331480416120993,0.00483206854090786,0.00201945030130446,-0.000731479958631098,,,,0.0841238420927409,39.995735168457,1.99977336742997,1.75309586524963,1.80078387260437,1.80120742321014,80555.9609375,80657.3125,0.0552582629024982,1,6,3,4,23.1730000402331,1,20.6865083579697,1.12335205078125,44.4770278930664,40.0782012939453,,,,,,,,,,,,,,,,
,3875408704.72827,1.80112910270691,87780.15234375,,,,,,,,,,,,,0.37722512557618,2.22428044184016E-5,-0.000451981336091406,10,2,,80,2,6490,,,0.36562623947356,0.00547853800365966,0.00222701160237193,-0.000807701086159796,,,,0.0927838766724788,39.995735168457,1.99964191941553,1.75036644935608,1.80101346969604,1.80126082897186,87729.5703125,87830.734375,0.0552014634013176,1,6,3,4,23.1730000402331,1,20.6868315603133,1.12312316894531,44.4770278930664,41.055721282959,,,,,,,,,,,,,,,,
,3875408846.18252,1.8010262966156,94952.00390625,,,,,,,,,,,,,0.412953367406204,2.59396202125159E-5,-0.000689322888148281,10,2,,80,2,6559,,,0.400602073375334,0.00611802203265713,0.0024398984387517,-0.000885536370333284,,,,0.101660837555733,39.995735168457,1.99967581075504,1.74734270572662,1.80095160007477,1.80118656158447,94898.734375,95005.2734375,0.0550869703292847,1,6,3,4,23.1730000402331,1,20.6832921574719,1.12342834472656,43.9882698059082,39.1006851196289,,,,,,,,,,,,,,,,
,3875408987.6573,1.80139214992523,102125.7890625,,,,,,,,,,,,,0.44784292368411,2.65839718838449E-5,-0.00093904236798976,10,2,,80,2,6628,,,0.434837025159834,0.00676210164301949,0.00264813052490354,-0.000961846206337214,,,,0.110346835815867,39.995735168457,1.999633713727,1.74408948421478,1.80116713047028,1.80160391330719,102072.5546875,102179.0234375,0.054924800992012,1,6,3,4,23.1730000402331,1,20.6813543004395,1.12281799316406,44.4770278930664,40.0782012939453,,,,,,,,,,,,,,,,
,3875409129.11822,1.80155117511749,109298.02734375,,,,,,,,,,,,,0.481697165532412,2.80288967593888E-5,-0.00123161628199637,10,2,,80,2,6697,,,0.468138793842101,0.00736945744569253,0.00285071833059192,-0.00103602453600615,,,,0.118797366096987,39.995735168457,1.99960824908427,1.74010252952576,1.80140769481659,1.8017942905426,109241.8828125,109354.171875,0.0547389686107636,1,6,3,4,23.1730000402331,1,20.680968903528,1.11488342285156,44.4770278930664,40.0782012939453,,,,,,,,,,,,,,,,
,3875409270.59742,1.80142024159431,116470.19140625,,,,,,,,,,,,,0.514550081929794,2.60164527454298E-5,-0.00155841135204884,10,2,,80,2,6766,,,0.500537438992541,0.00794105297614411,0.00304780318401754,-0.00110795290675014,,,,0.127014973127414,39.995735168457,1.99953129542677,1.73595750331879,1.80135047435761,1.80146872997284,116416.9375,116523.4453125,0.0544932782649994,1,6,3,4,23.1730000402331,1,20.6789479185622,1.12228393554688,44.4770278930664,40.5669593811035,,,,,,,,,,,,,,,,
,3875409412.06682,1.80137348175049,123644.4921875,,,,,,,,,,,,,0.546750485827621,3.48520804043947E-5,-0.00193283570207299,10,2,,80,2,6835,,,0.532369369280535,0.00846302544727165,0.0032416416797787,-0.00117848860099912,,,,0.13509438373671,39.995735168457,1.99955209333684,1.73153555393219,1.80120360851288,1.80151736736298,123591.109375,123697.875,0.0543462447822094,1,6,3,4,23.1730000402331,1,20.6782246067636,1.12174987792969,44.4770278930664,40.0782012939453,,,,,,,,,,,,,,,,
,3875409553.53205,1.80176687240601,130819.7421875,,,,,,,,,,,,,0.578261555553993,3.49278800757505E-5,-0.0022679456135625,10,2,,80,2,6904,,,0.563593672713243,0.00901293826742941,0.00343154929578304,-0.00124772603157908,,,,0.143011943243871,39.995735168457,1.99945563493059,1.72728168964386,1.80167138576508,1.80186009407043,130766.5703125,130872.9140625,0.0542360097169876,1,6,3,4,23.1730000402331,1,20.6756896683976,1.11465454101562,43.9882698059082,40.0782012939453,,,,,,,,,,,,,,,,
,3875409695.00828,1.80165120959282,137994.5390625,,,,,,,,,,,,,0.60931879339724,3.57959925589522E-5,-0.00260653300699714,10,2,,80,2,6973,,,0.594436802803872,0.00954803666123111,0.00361913070082665,-0.0013161008246243,,,,0.150831776682093,39.995735168457,1.99936363077063,1.72221434116364,1.80155766010284,1.80189788341522,137941.375,138047.703125,0.0540609396994114,1,6,3,4,23.1730000402331,1,20.6740246648051,1.12213134765625,44.4770278930664,40.0782012939453,,,,,,,,,,,,,,,,
,3875409836.46479,1.80005466938019,140000.6875,,,,,,,,,,,,,0.617915085681545,4.21973356693049E-5,-0.00267275497069252,10,2,,80,2,7042,,,0.602985311933758,0.00972257427445744,0.00367096392437816,-0.00133518676739186,,,,0.152994148644341,39.995735168457,1.99928524040643,1.71947777271271,1.79990410804749,1.8003466129303,140000.6875,140000.6875,0.053959533572197,1,4,3,4,23.1730000402331,1,20.67375139471,1.11518859863281,44.4770278930664,40.0782012939453,,,,,,,,,,,,,,,,
,3875409854.91152,1.79999415874481,140000.28125,,,,,,,,,,,,,0.617899443113433,4.42875433744617E-5,-0.00270025295923926,10,2,,80,2,7051,,,0.602970564641826,0.00969541727659776,0.00367113063111901,-0.00133497279603034,,,,0.152997214244456,39.995735168457,1.99938055949731,1.71945750713348,1.79988479614258,1.80012261867523,140000.265625,140000.296875,0.0539662800729275,1,4,3,4,23.1730000402331,1,20.6725234989841,1.11351013183594,44.4770278930664,40.5669593811035,,,,,,,,,,,,,,,,