File: MPMS/NiCl2btd/NiCl2btd-d4_2-300K_ZFC.rso.dat
[Header]
TITLE,MPMS RSO Measurement
BYAPP,MPMS Measurement,1.1,Summary
FILEOPENTIME, 1666809220.566000 10/26/2022, 7:33:40 PM

INFO, APPNAME, MPMS MultiVu Application, Revision 1.61,  Build 082

INFO, NAME, NiCl2btd-d4_tefeyo
INFO, WEIGHT, 8.630
INFO, AREA, 1.000
INFO, LENGTH, 1.000
INFO, SHAPE, -
INFO, COMMENT, evioseme9.22mg
INFO, SEQUENCE FILE: JP_ZFC_MH_FC_221026_NiCl2btd-d4_tefeyo.seq


INFO, BACKGROUND DATA FILE:, None


STARTUPAXIS,X,4,LINEAR,AUTO,0.000000,0.000000
STARTUPAXIS,Y1,5,LINEAR,AUTO,0.000000,0.000000


STARTUPGROUP,Longitudinal
FIELDGROUP,Longitudinal,1,2,3,4,5,6,7,8,9,10,11,19,20,21,22,23,35
FIELDGROUP,Transverse,1,2,3,4,12,13,14,15,16,17,18,24,25,26,27,28,35

PLOT_APPEARANCE,ALL,HORZ_GRID_ON,VERT_GRID_ON,MARKERS_AND_LINES

[Data]
Time,Comment,Field (Oe),Temperature (K),Long Moment (emu),Long Scan Std Dev,Long Offset (cm),Long Offset Std Dev,Long Algorithm,Long Reg Fit,Long Reg Factor,Trans Moment (emu),Trans Scan Std Dev,Trans Offset (cm),Trans Offset Std Dev,Trans Algorithm,Trans Reg Fit,Trans Reg Factor,Long Moment [w/o ABS] (emu),Long Scan Std Dev [w/o ABS],Long Offset [w/o ABS] (cm),Long Offset Std Dev [w/o ABS],Long Reg Fit [w/o ABS],Trans Moment [w/o ABS] (emu),Trans Scan Std Dev [w/o ABS],Trans Offset [w/o ABS] (cm),Trans Offset Std Dev [w/o ABS],Trans Reg Fit [w/o ABS],RSO Position (deg),Amplitude (cm),Frequency,Cycles to Average,Scans per Measurement,Delta Temp (K),Error,EC Comp. Running,Using ABS,
1666809220.566,,1.000000e+002,2.003289e+000,-5.779400e-003,1.237169e-006,2.322392e-002,1.110697e-004,3,9.870172e-001,1.825000e+000,,,,,,,,,,,,,,,,,,0,5.000000e+000,1.000000e+000,4,4,8.358955e-004,0,,0,
1666809413.928,,1.000000e+002,2.253191e+000,-5.773794e-003,6.056730e-007,2.307894e-002,2.843452e-005,3,9.870969e-001,1.825000e+000,,,,,,,,,,,,,,,,,,0,5.000000e+000,1.000000e+000,4,4,3.621101e-003,0,,0,
1666809605.933,,1.000000e+002,2.503033e+000,-5.761605e-003,7.685470e-007,2.320377e-002,5.846607e-005,3,9.870006e-001,1.825000e+000,,,,,,,,,,,,,,,,,,0,5.000000e+000,1.000000e+000,4,4,4.406929e-003,0,,0,
1666809811.152,,1.000000e+002,2.752549e+000,-5.749057e-003,1.001502e-006,2.308847e-002,1.041857e-004,3,9.870618e-001,1.825000e+000,,,,,,,,,,,,,,,,,,0,5.000000e+000,1.000000e+000,4,4,4.746199e-003,0,,0,
1666810044.528,,1.000000e+002,3.001921e+000,-5.735647e-003,1.401870e-006,2.317853e-002,1.560853e-004,3,9.870727e-001,1.825000e+000,,,,,,,,,,,,,,,,,,0,5.000000e+000,1.000000e+000,4,4,5.016088e-003,0,,0,
1666810328.558,,1.000000e+002,3.251709e+000,-5.721060e-003,9.535852e-007,2.320482e-002,5.852135e-005,3,9.869747e-001,1.825000e+000,,,,,,,,,,,,,,,,,,0,5.000000e+000,1.000000e+000,4,4,6.043911e-003,0,,0,
1666810654.785,,1.000000e+002,3.512717e+000,-5.709788e-003,2.646738e-006,2.328690e-002,1.303783e-004,3,9.869416e-001,1.825000e+000,,,,,,,,,,,,,,,,,,0,5.000000e+000,1.000000e+000,4,4,3.036404e-002,0,,0,
1666810875.807,,1.000000e+002,3.763282e+000,-5.697535e-003,1.333788e-006,2.325111e-002,4.616025e-005,3,9.870547e-001,1.825000e+000,,,,,,,,,,,,,,,,,,0,5.000000e+000,1.000000e+000,4,4,1.336884e-002,0,,0,
1666811134.408,,1.000000e+002,4.006975e+000,-5.681326e-003,1.117253e-006,2.329023e-002,5.903972e-005,3,9.869969e-001,1.825000e+000,,,,,,,,,,,,,,,,,,0,5.000000e+000,1.000000e+000,4,4,1.396084e-002,0,,0,
1666811483.631,,1.000000e+002,4.257868e+000,-5.663299e-003,6.223360e-007,2.333392e-002,1.178488e-004,3,9.869562e-001,1.825000e+000,,,,,,,,,,,,,,,,,,0,5.000000e+000,1.000000e+000,4,4,1.857138e-002,0,,0,
1666811721.250,,1.000000e+002,4.506890e+000,-5.645578e-003,4.953986e-007,2.334644e-002,9.616429e-005,3,9.870284e-001,1.825000e+000,,,,,,,,,,,,,,,,,,0,5.000000e+000,1.000000e+000,4,4,8.457184e-003,0,,0,
1666811874.536,,1.000000e+002,4.755588e+000,-5.631072e-003,5.067258e-007,2.327721e-002,6.606760e-005,3,9.870229e-001,1.825000e+000,,,,,,,,,,,,,,,,,,0,5.000000e+000,1.000000e+000,4,4,6.577969e-003,0,,0,
1666812027.978,,1.000000e+002,5.004742e+000,-5.609939e-003,9.089293e-007,2.339997e-002,1.125438e-004,3,9.869995e-001,1.825000e+000,,,,,,,,,,,,,,,,,,0,5.000000e+000,1.000000e+000,4,4,5.228996e-003,0,,0,
1666812180.843,,1.000000e+002,5.254610e+000,-5.589741e-003,4.627935e-007,2.337953e-002,8.369031e-005,3,9.870824e-001,1.825000e+000,,,,,,,,,,,,,,,,,,0,5.000000e+000,1.000000e+000,4,4,4.860878e-003,0,,0,
1666812333.910,,1.000000e+002,5.505001e+000,-5.564823e-003,4.141270e-007,2.348228e-002,1.723019e-005,3,9.869803e-001,1.825000e+000,,,,,,,,,,,,,,,,,,0,5.000000e+000,1.000000e+000,4,4,4.201889e-003,0,,0,
1666812487.477,,1.000000e+002,5.753218e+000,-5.538803e-003,1.277808e-006,2.335611e-002,4.248866e-005,3,9.871055e-001,1.825000e+000,,,,,,,,,,,,,,,,,,0,5.000000e+000,1.000000e+000,4,4,7.455349e-003,0,,0,
1666812640.232,,1.000000e+002,5.998630e+000,-5.510975e-003,1.293080e-006,2.343150e-002,6.292737e-005,3,9.870692e-001,1.825000e+000,,,,,,,,,,,,,,,,,,0,5.000000e+000,1.000000e+000,4,4,1.210022e-002,0,,0,
1666812744.986,,1.000000e+002,6.503195e+000,-5.455983e-003,1.659704e-006,2.343952e-002,1.266908e-005,3,9.871045e-001,1.825000e+000,,,,,,,,,,,,,,,,,,0,5.000000e+000,1.000000e+000,4,4,6.114960e-003,0,,0,
1666812898.335,,1.000000e+002,7.002772e+000,-5.392229e-003,1.305613e-006,2.357247e-002,5.717629e-005,3,9.870477e-001,1.825000e+000,,,,,,,,,,,,,,,,,,0,5.000000e+000,1.000000e+000,4,4,5.279064e-003,0,,0,
1666813052.151,,1.000000e+002,7.502574e+000,-5.323197e-003,1.924581e-006,2.357780e-002,8.253244e-005,3,9.870993e-001,1.825000e+000,,,,,,,,,,,,,,,,,,0,5.000000e+000,1.000000e+000,4,4,6.443024e-003,0,,0,
1666813206.981,,1.000000e+002,8.003649e+000,-5.247931e-003,1.330860e-006,2.354829e-002,6.392513e-005,3,9.871385e-001,1.825000e+000,,,,,,,,,,,,,,,,,,0,5.000000e+000,1.000000e+000,4,4,7.280350e-003,0,,0,
1666813363.980,,1.000000e+002,8.503551e+000,-5.164798e-003,1.059333e-006,2.368594e-002,9.517059e-005,3,9.870589e-001,1.825000e+000,,,,,,,,,,,,,,,,,,0,5.000000e+000,1.000000e+000,4,4,1.290512e-002,0,,0,
1666813519.918,,1.000000e+002,9.003361e+000,-5.075691e-003,9.291722e-007,2.377274e-002,8.645497e-005,3,9.870180e-001,1.825000e+000,,,,,,,,,,,,,,,,,,0,5.000000e+000,1.000000e+000,4,4,2.882004e-003,0,,0,
1666813674.561,,1.000000e+002,9.502985e+000,-4.980669e-003,1.196318e-006,2.381008e-002,5.772832e-005,3,9.871154e-001,1.825000e+000,,,,,,,,,,,,,,,,,,0,5.000000e+000,1.000000e+000,4,4,3.261566e-003,0,,0,
1666813829.656,,1.000000e+002,1.000342e+001,-4.877019e-003,1.672127e-006,2.396679e-002,5.084401e-005,3,9.870655e-001,1.825000e+000,,,,,,,,,,,,,,,,,,0,5.000000e+000,1.000000e+000,4,4,6.669998e-003,0,,0,
1666813984.268,,1.000000e+002,1.051480e+001,-4.763023e-003,2.046281e-006,2.391519e-002,4.903876e-005,3,9.871485e-001,1.825000e+000,,,,,,,,,,,,,,,,,,0,5.000000e+000,1.000000e+000,4,4,3.740311e-003,0,,0,
1666814139.941,,1.000000e+002,1.102683e+001,-4.639335e-003,1.787046e-006,2.397316e-002,6.165302e-005,3,9.871416e-001,1.825000e+000,,,,,,,,,,,,,,,,,,0,5.000000e+000,1.000000e+000,4,4,5.499840e-003,0,,0,
1666814295.083,,1.000000e+002,1.153887e+001,-4.501039e-003,1.490731e-006,2.415863e-002,6.040744e-005,3,9.870973e-001,1.825000e+000,,,,,,,,,,,,,,,,,,0,5.000000e+000,1.000000e+000,4,4,6.350517e-003,0,,0,
1666814453.096,,1.000000e+002,1.202491e+001,-4.350138e-003,2.338706e-006,2.425175e-002,1.258367e-004,3,9.871459e-001,1.825000e+000,,,,,,,,,,,,,,,,,,0,5.000000e+000,1.000000e+000,4,4,5.279541e-003,0,,0,
1666814604.837,,1.000000e+002,1.253339e+001,-4.179035e-003,2.784043e-006,2.440976e-002,6.431950e-005,3,9.871689e-001,1.825000e+000,,,,,,,,,,,,,,,,,,0,5.000000e+000,1.000000e+000,4,4,1.280022e-002,0,,0,
1666814756.501,,1.000000e+002,1.304756e+001,-3.980343e-003,3.134664e-006,2.466638e-002,2.644663e-005,3,9.871669e-001,1.825000e+000,,,,,,,,,,,,,,,,,,0,5.000000e+000,1.000000e+000,4,4,1.347065e-002,0,,0,
1666814905.309,,1.000000e+002,1.355892e+001,-3.747748e-003,3.988179e-006,2.484477e-002,1.151127e-004,3,9.872688e-001,1.825000e+000,,,,,,,,,,,,,,,,,,0,5.000000e+000,1.000000e+000,4,4,1.192951e-002,0,,0,
1666815071.871,,1.000000e+002,1.407154e+001,-3.452432e-003,8.483783e-006,2.523907e-002,8.580210e-005,3,9.872306e-001,1.825000e+000,,,,,,,,,,,,,,,,,,0,5.000000e+000,1.000000e+000,4,4,1.442051e-002,0,,0,
1666815218.261,,1.000000e+002,1.450150e+001,-3.123794e-003,4.092496e-006,2.564010e-002,1.249583e-004,3,9.873464e-001,1.825000e+000,,,,,,,,,,,,,,,,,,0,5.000000e+000,1.000000e+000,4,4,6.750107e-003,0,,0,
1666815374.075,,1.000000e+002,1.500185e+001,-2.588771e-003,5.092962e-006,2.657226e-002,3.179166e-005,3,9.875183e-001,1.825000e+000,,,,,,,,,,,,,,,,,,0,5.000000e+000,1.000000e+000,4,4,7.230759e-003,0,,0,
1666815538.624,,1.000000e+002,1.550276e+001,-1.814981e-003,5.055429e-006,2.904643e-002,7.157087e-005,3,9.875641e-001,1.825000e+000,,,,,,,,,,,,,,,,,,0,5.000000e+000,1.000000e+000,4,4,1.929283e-003,0,,0,
1666815693.236,,1.000000e+002,1.600201e+001,-7.135554e-004,6.204109e-006,4.112447e-002,2.080579e-004,3,9.884760e-001,1.825000e+000,,,,,,,,,,,,,,,,,,0,5.000000e+000,1.000000e+000,4,4,6.869316e-003,0,,0,
1666815847.582,,1.000000e+002,1.650179e+001,8.811036e-004,4.840641e-006,5.659414e-003,4.990802e-005,3,9.838700e-001,1.825000e+000,,,,,,,,,,,,,,,,,,0,5.000000e+000,1.000000e+000,4,4,6.568909e-003,0,,0,
1666816010.712,,1.000000e+002,1.700255e+001,4.037754e-003,3.106130e-006,1.717601e-002,1.001577e-004,3,9.864684e-001,1.825000e+000,,,,,,,,,,,,,,,,,,0,5.000000e+000,1.000000e+000,4,4,1.550674e-003,0,,0,
1666816165.854,,1.000000e+002,1.750159e+001,2.593895e-003,1.959477e-005,2.019626e-002,1.585732e-004,3,9.866390e-001,1.825000e+000,,,,,,,,,,,,,,,,,,0,5.000000e+000,1.000000e+000,4,4,8.209229e-003,0,,0,
1666816330.309,,1.000000e+002,1.800238e+001,4.290742e-004,5.131503e-007,2.163192e-002,7.169574e-005,3,9.856379e-001,1.825000e+000,,,,,,,,,,,,,,,,,,0,5.000000e+000,1.000000e+000,4,4,2.609253e-003,0,,0,
1666816485.452,,1.000000e+002,1.850060e+001,2.451187e-004,2.760604e-007,2.072230e-002,1.114354e-004,3,9.841368e-001,1.825000e+000,,,,,,,,,,,,,,,,,,0,5.000000e+000,1.000000e+000,4,4,7.339478e-003,0,,0,
1666816649.314,,1.000000e+002,1.900230e+001,2.125196e-004,4.213262e-008,2.060995e-002,6.833257e-005,3,9.837177e-001,1.825000e+000,,,,,,,,,,,,,,,,,,0,5.000000e+000,1.000000e+000,4,4,3.870010e-003,0,,0,
1666816804.987,,1.000000e+002,1.950149e+001,2.006324e-004,1.762803e-008,2.062322e-002,4.691959e-005,3,9.835078e-001,1.825000e+000,,,,,,,,,,,,,,,,,,0,5.000000e+000,1.000000e+000,4,4,6.088257e-003,0,,0,
1666816960.348,,1.000000e+002,2.000125e+001,1.942163e-004,1.071119e-008,2.080144e-002,8.945625e-005,3,9.832639e-001,1.825000e+000,,,,,,,,,,,,,,,,,,0,5.000000e+000,1.000000e+000,4,4,3.740311e-003,0,,0,
1666817071.732,,1.000000e+002,2.099386e+001,1.869750e-004,3.928746e-008,2.089658e-002,8.746036e-005,3,9.831691e-001,1.825000e+000,,,,,,,,,,,,,,,,,,0,5.000000e+000,1.000000e+000,4,4,1.644135e-002,0,,0,
1666817229.511,,1.000000e+002,2.199905e+001,1.822937e-004,1.496936e-008,2.118264e-002,4.552581e-005,3,9.829383e-001,1.825000e+000,,,,,,,,,,,,,,,,,,0,5.000000e+000,1.000000e+000,4,4,3.210068e-003,0,,0,
1666817386.463,,1.000000e+002,2.300008e+001,1.785976e-004,2.539504e-008,2.131436e-002,8.798408e-005,3,9.828933e-001,1.825000e+000,,,,,,,,,,,,,,,,,,0,5.000000e+000,1.000000e+000,4,4,7.680893e-003,0,,0,
1666817545.052,,1.000000e+002,2.400063e+001,1.752145e-004,2.871345e-008,2.148363e-002,6.524508e-005,3,9.827499e-001,1.825000e+000,,,,,,,,,,,,,,,,,,0,5.000000e+000,1.000000e+000,4,4,1.436996e-002,0,,0,
1666817701.567,,1.000000e+002,2.500255e+001,1.719532e-004,2.769186e-008,2.167773e-002,3.894764e-005,3,9.827176e-001,1.825000e+000,,,,,,,,,,,,,,,,,,0,5.000000e+000,1.000000e+000,4,4,2.042961e-002,0,,0,
1666817815.073,,1.000000e+002,2.600152e+001,1.688135e-004,6.217324e-009,2.183004e-002,1.511976e-004,3,9.826612e-001,1.825000e+000,,,,,,,,,,,,,,,,,,0,5.000000e+000,1.000000e+000,4,4,8.792877e-004,0,,0,
1666817974.724,,1.000000e+002,2.801030e+001,1.624622e-004,2.231115e-008,2.227391e-002,9.728310e-005,3,9.824123e-001,1.825000e+000,,,,,,,,,,,,,,,,,,0,5.000000e+000,1.000000e+000,4,4,5.060196e-003,0,,0,
1666818133.844,,1.000000e+002,3.001297e+001,1.562711e-004,1.124983e-008,2.268775e-002,5.155327e-005,3,9.821882e-001,1.825000e+000,,,,,,,,,,,,,,,,,,0,5.000000e+000,1.000000e+000,4,4,9.229660e-003,0,,0,
1666818295.882,,1.000000e+002,3.201462e+001,1.502154e-004,3.055381e-008,2.315834e-002,1.571507e-004,3,9.819239e-001,1.825000e+000,,,,,,,,,,,,,,,,,,0,5.000000e+000,1.000000e+000,4,4,9.117126e-003,0,,0,
1666818460.041,,1.000000e+002,3.401748e+001,1.443194e-004,2.231234e-008,2.374703e-002,1.089082e-004,3,9.815980e-001,1.825000e+000,,,,,,,,,,,,,,,,,,0,5.000000e+000,1.000000e+000,4,4,1.021957e-002,0,,0,
1666818625.791,,1.000000e+002,3.602122e+001,1.386832e-004,2.211652e-008,2.422742e-002,1.107129e-004,3,9.814370e-001,1.825000e+000,,,,,,,,,,,,,,,,,,0,5.000000e+000,1.000000e+000,4,4,1.304245e-002,0,,0,
1666818794.459,,1.000000e+002,3.802410e+001,1.332806e-004,1.351278e-008,2.466482e-002,5.410411e-005,3,9.812621e-001,1.825000e+000,,,,,,,,,,,,,,,,,,0,5.000000e+000,1.000000e+000,4,4,1.808167e-002,0,,0,
1666818964.717,,1.000000e+002,4.002761e+001,1.281282e-004,2.889624e-008,2.532606e-002,6.575335e-005,3,9.809287e-001,1.825000e+000,,,,,,,,,,,,,,,,,,0,5.000000e+000,1.000000e+000,4,4,1.591110e-002,0,,0,
1666819137.363,,1.000000e+002,4.203041e+001,1.231976e-004,4.342899e-008,2.594335e-002,1.326218e-004,3,9.805418e-001,1.825000e+000,,,,,,,,,,,,,,,,,,0,5.000000e+000,1.000000e+000,4,4,1.961899e-002,0,,0,
1666819310.227,,1.000000e+002,4.403547e+001,1.185242e-004,3.630925e-008,2.640722e-002,1.463632e-004,3,9.803593e-001,1.825000e+000,,,,,,,,,,,,,,,,,,0,5.000000e+000,1.000000e+000,4,4,2.191925e-002,0,,0,
1666819482.139,,1.000000e+002,4.604026e+001,1.140834e-004,2.986059e-008,2.698515e-002,5.814906e-005,3,9.799864e-001,1.825000e+000,,,,,,,,,,,,,,,,,,0,5.000000e+000,1.000000e+000,4,4,2.285767e-002,0,,0,
1666819652.928,,1.000000e+002,4.804557e+001,1.099346e-004,2.059886e-008,2.759691e-002,7.655225e-005,3,9.797576e-001,1.825000e+000,,,,,,,,,,,,,,,,,,0,5.000000e+000,1.000000e+000,4,4,2.482224e-002,0,,0,
1666819821.908,,1.000000e+002,5.004939e+001,1.060091e-004,2.450546e-008,2.816385e-002,2.818563e-005,3,9.793354e-001,1.825000e+000,,,,,,,,,,,,,,,,,,0,5.000000e+000,1.000000e+000,4,4,1.945877e-002,0,,0,
1666820011.791,,1.000000e+002,5.505565e+001,9.696830e-005,2.674096e-008,2.954376e-002,1.739602e-004,3,9.783037e-001,1.825000e+000,,,,,,,,,,,,,,,,,,0,5.000000e+000,1.000000e+000,4,4,2.903748e-002,0,,0,
1666820212.813,,1.000000e+002,6.007495e+001,8.909812e-005,3.040930e-008,3.071721e-002,4.235675e-005,3,9.777034e-001,1.825000e+000,,,,,,,,,,,,,,,,,,0,5.000000e+000,1.000000e+000,4,4,4.301071e-002,0,,0,
1666820416.253,,1.000000e+002,6.508995e+001,8.226243e-005,3.615141e-008,3.212590e-002,9.541333e-005,3,9.767011e-001,1.825000e+000,,,,,,,,,,,,,,,,,,0,5.000000e+000,1.000000e+000,4,4,4.600525e-002,0,,0,
1666820623.375,,1.000000e+002,7.010295e+001,7.623936e-005,3.669298e-008,3.375472e-002,7.303595e-005,3,9.757228e-001,1.825000e+000,,,,,,,,,,,,,,,,,,0,5.000000e+000,1.000000e+000,4,4,5.059814e-002,0,,0,
1666820831.822,,1.000000e+002,7.511581e+001,7.095439e-005,2.090203e-008,3.550826e-002,1.289189e-004,3,9.747708e-001,1.825000e+000,,,,,,,,,,,,,,,,,,0,5.000000e+000,1.000000e+000,4,4,7.102966e-002,0,,0,
1666821041.065,,1.000000e+002,8.012900e+001,6.631005e-005,1.226629e-008,3.738761e-002,1.125125e-004,3,9.737142e-001,1.825000e+000,,,,,,,,,,,,,,,,,,0,5.000000e+000,1.000000e+000,4,4,6.246185e-002,0,,0,
1666821261.197,,1.000000e+002,8.512758e+001,6.215674e-005,1.741754e-008,3.939195e-002,1.390826e-004,3,9.726390e-001,1.825000e+000,,,,,,,,,,,,,,,,,,0,5.000000e+000,1.000000e+000,4,4,8.645630e-002,0,,0,
1666821474.418,,1.000000e+002,9.015580e+001,5.840605e-005,1.870549e-008,4.128478e-002,3.261530e-005,3,9.715011e-001,1.825000e+000,,,,,,,,,,,,,,,,,,0,5.000000e+000,1.000000e+000,4,4,7.778931e-002,0,,0,
1666821686.594,,1.000000e+002,9.516544e+001,5.506751e-005,2.784672e-008,4.353346e-002,4.058895e-005,3,9.703304e-001,1.825000e+000,,,,,,,,,,,,,,,,,,0,5.000000e+000,1.000000e+000,4,4,9.452057e-002,0,,0,
1666821898.490,,1.000000e+002,1.001822e+002,5.207895e-005,3.811492e-008,4.562251e-002,1.821850e-004,3,9.690949e-001,1.825000e+000,,,,,,,,,,,,,,,,,,0,5.000000e+000,1.000000e+000,4,4,1.087952e-001,0,,0,
1666822161.272,,1.000000e+002,1.102175e+002,4.685576e-005,1.527426e-008,4.974905e-002,1.360838e-004,3,9.664915e-001,1.825000e+000,,,,,,,,,,,,,,,,,,0,5.000000e+000,1.000000e+000,4,4,1.352997e-001,0,,0,
1666822425.786,,1.000000e+002,1.202386e+002,4.245766e-005,2.107774e-008,5.398443e-002,8.474637e-005,3,9.640517e-001,1.825000e+000,,,,,,,,,,,,,,,,,,0,5.000000e+000,1.000000e+000,4,4,1.499023e-001,0,,0,
1666822684.045,,1.000000e+002,1.302651e+002,3.880213e-005,2.650859e-008,5.870526e-002,3.797378e-004,3,9.614151e-001,1.825000e+000,,,,,,,,,,,,,,,,,,0,5.000000e+000,1.000000e+000,4,4,1.708069e-001,0,,0,
1666822939.869,,1.000000e+002,1.402874e+002,3.569437e-005,2.209404e-008,6.321779e-002,1.363238e-004,3,9.586546e-001,1.825000e+000,,,,,,,,,,,,,,,,,,0,5.000000e+000,1.000000e+000,4,4,1.882019e-001,0,,0,
1666823192.964,,1.000000e+002,1.503099e+002,3.300495e-005,1.564471e-008,6.806308e-002,2.737351e-004,3,9.559297e-001,1.825000e+000,,,,,,,,,,,,,,,,,,0,5.000000e+000,1.000000e+000,4,4,2.050934e-001,0,,0,
1666823442.502,,1.000000e+002,1.603348e+002,3.065230e-005,1.819983e-008,7.299459e-002,1.264007e-004,3,9.529902e-001,1.825000e+000,,,,,,,,,,,,,,,,,,0,5.000000e+000,1.000000e+000,4,4,2.099915e-001,0,,0,
1666823689.888,,1.000000e+002,1.703603e+002,2.859570e-005,1.717602e-008,7.844054e-002,2.535122e-004,3,9.503820e-001,1.825000e+000,,,,,,,,,,,,,,,,,,0,5.000000e+000,1.000000e+000,4,4,2.301941e-001,0,,0,
1666823936.290,,1.000000e+002,1.803707e+002,2.679571e-005,1.416597e-008,8.355241e-002,2.015837e-004,3,9.475552e-001,1.825000e+000,,,,,,,,,,,,,,,,,,0,5.000000e+000,1.000000e+000,4,4,2.435913e-001,0,,0,
1666824181.819,,1.000000e+002,1.903852e+002,2.517933e-005,9.903963e-009,8.915015e-002,2.022298e-004,3,9.446030e-001,1.825000e+000,,,,,,,,,,,,,,,,,,0,5.000000e+000,1.000000e+000,4,4,2.789001e-001,0,,0,
1666824432.168,,1.000000e+002,2.003378e+002,2.375185e-005,1.690387e-008,9.480047e-002,1.501665e-004,3,9.418775e-001,1.825000e+000,,,,,,,,,,,,,,,,,,0,5.000000e+000,1.000000e+000,4,4,2.743988e-001,0,,0,
1666824672.658,,1.000000e+002,2.104227e+002,2.245387e-005,3.552950e-008,1.010168e-001,3.149960e-004,3,9.389808e-001,1.825000e+000,,,,,,,,,,,,,,,,,,0,5.000000e+000,1.000000e+000,4,4,3.028870e-001,0,,0,
1666824911.853,,1.000000e+002,2.204373e+002,2.126805e-005,8.358453e-009,1.075720e-001,5.116633e-004,3,9.361209e-001,1.825000e+000,,,,,,,,,,,,,,,,,,0,5.000000e+000,1.000000e+000,4,4,3.226013e-001,0,,0,
1666825151.329,,1.000000e+002,2.304375e+002,2.021017e-005,1.031768e-008,1.140055e-001,2.843214e-004,3,9.331363e-001,1.825000e+000,,,,,,,,,,,,,,,,,,0,5.000000e+000,1.000000e+000,4,4,3.188019e-001,0,,0,
1666825388.980,,1.000000e+002,2.404492e+002,1.922731e-005,1.212429e-008,1.210101e-001,3.668650e-004,3,9.297022e-001,1.825000e+000,,,,,,,,,,,,,,,,,,0,5.000000e+000,1.000000e+000,4,4,3.662872e-001,0,,0,
1666825623.948,,1.000000e+002,2.504857e+002,1.832191e-005,1.387801e-008,1.280276e-001,5.946773e-005,3,9.272454e-001,1.825000e+000,,,,,,,,,,,,,,,,,,0,5.000000e+000,1.000000e+000,4,4,3.847046e-001,0,,0,
1666825859.446,,1.000000e+002,2.604855e+002,1.751385e-005,2.501298e-008,1.352955e-001,3.206589e-004,3,9.243470e-001,1.825000e+000,,,,,,,,,,,,,,,,,,0,5.000000e+000,1.000000e+000,4,4,3.800049e-001,0,,0,
1666826095.958,,1.000000e+002,2.704940e+002,1.673994e-005,1.944420e-008,1.437244e-001,2.847867e-004,3,9.207242e-001,1.825000e+000,,,,,,,,,,,,,,,,,,0,5.000000e+000,1.000000e+000,4,4,4.042053e-001,0,,0,
1666826332.532,,1.000000e+002,2.804850e+002,1.603399e-005,1.781821e-008,1.528677e-001,4.407331e-004,3,9.179422e-001,1.825000e+000,,,,,,,,,,,,,,,,,,0,5.000000e+000,1.000000e+000,4,4,3.857117e-001,0,,0,
1666826570.963,,1.000000e+002,2.904737e+002,1.539890e-005,1.054503e-008,1.629866e-001,2.432045e-004,3,9.141212e-001,1.825000e+000,,,,,,,,,,,,,,,,,,0,5.000000e+000,1.000000e+000,4,4,4.065857e-001,0,,0,
1666826810.439,,1.000000e+002,3.004672e+002,1.481670e-005,1.633480e-008,1.737890e-001,5.705676e-004,3,9.117569e-001,1.825000e+000,,,,,,,,,,,,,,,,,,0,5.000000e+000,1.000000e+000,4,4,3.875732e-001,0,,0,