File: MPMS/FeCl2btd/FeCl2btd_2-300K_FC.rso.dat
[Header]
TITLE,MPMS RSO Measurement
BYAPP,MPMS Measurement,1.1,Summary
FILEOPENTIME, 1627930469.197000 8/2/2021, 7:54:29 PM

INFO, APPNAME, MPMS MultiVu Application, Revision 1.61,  Build 082

INFO, NAME, FeCl2btd
INFO, WEIGHT, 11.850
INFO, AREA, 1.000
INFO, LENGTH, 1.000
INFO, SHAPE, -
INFO, COMMENT, 10.23 mg eicosane
INFO, SEQUENCE FILE: JP_ZFC_MH_FC_210802_FeCl2btd_jedimu.seq


INFO, BACKGROUND DATA FILE:, None


STARTUPAXIS,X,4,LINEAR,AUTO,0.000000,0.000000
STARTUPAXIS,Y1,5,LINEAR,AUTO,0.000000,0.000000


STARTUPGROUP,Longitudinal
FIELDGROUP,Longitudinal,1,2,3,4,5,6,7,8,9,10,11,19,20,21,22,23,35
FIELDGROUP,Transverse,1,2,3,4,12,13,14,15,16,17,18,24,25,26,27,28,35

PLOT_APPEARANCE,ALL,HORZ_GRID_ON,VERT_GRID_ON,MARKERS_AND_LINES

[Data]
Time,Comment,Field (Oe),Temperature (K),Long Moment (emu),Long Scan Std Dev,Long Offset (cm),Long Offset Std Dev,Long Algorithm,Long Reg Fit,Long Reg Factor,Trans Moment (emu),Trans Scan Std Dev,Trans Offset (cm),Trans Offset Std Dev,Trans Algorithm,Trans Reg Fit,Trans Reg Factor,Long Moment [w/o ABS] (emu),Long Scan Std Dev [w/o ABS],Long Offset [w/o ABS] (cm),Long Offset Std Dev [w/o ABS],Long Reg Fit [w/o ABS],Trans Moment [w/o ABS] (emu),Trans Scan Std Dev [w/o ABS],Trans Offset [w/o ABS] (cm),Trans Offset Std Dev [w/o ABS],Trans Reg Fit [w/o ABS],RSO Position (deg),Amplitude (cm),Frequency,Cycles to Average,Scans per Measurement,Delta Temp (K),Error,EC Comp. Running,Using ABS,
1627930469.182,,1.000000e+002,3.000086e+002,9.116570e-005,3.184336e-008,1.782211e-001,2.603195e-004,3,9.822504e-001,1.825000e+000,,,,,,,,,,,,,,,,,,0,5.000000e+000,1.000000e+000,4,4,9.887695e-003,0,,0,
1627930976.931,,1.000000e+002,2.902622e+002,9.348836e-005,3.184600e-008,1.770915e-001,2.163663e-004,3,9.826651e-001,1.825000e+000,,,,,,,,,,,,,,,,,,0,5.000000e+000,1.000000e+000,4,4,6.469727e-002,0,,0,
1627931219.917,,1.000000e+002,2.794824e+002,9.635841e-005,2.908595e-008,1.657340e-001,8.809347e-005,3,9.830025e-001,1.825000e+000,,,,,,,,,,,,,,,,,,0,5.000000e+000,1.000000e+000,4,4,3.403015e-001,0,,0,
1627931438.988,,1.000000e+002,2.695724e+002,9.912559e-005,2.918685e-008,1.565766e-001,4.530449e-005,3,9.833409e-001,1.825000e+000,,,,,,,,,,,,,,,,,,0,5.000000e+000,1.000000e+000,4,4,2.832947e-001,0,,0,
1627931660.883,,1.000000e+002,2.595874e+002,1.021424e-004,5.743238e-009,1.481973e-001,5.423778e-005,3,9.838148e-001,1.825000e+000,,,,,,,,,,,,,,,,,,0,5.000000e+000,1.000000e+000,4,4,2.322998e-001,0,,0,
1627931880.844,,1.000000e+002,2.495890e+002,1.052958e-004,1.949699e-008,1.409044e-001,1.121079e-004,3,9.840069e-001,1.825000e+000,,,,,,,,,,,,,,,,,,0,5.000000e+000,1.000000e+000,4,4,2.478943e-001,0,,0,
1627932102.816,,1.000000e+002,2.395880e+002,1.086790e-004,2.684771e-008,1.341461e-001,1.340356e-004,3,9.845074e-001,1.825000e+000,,,,,,,,,,,,,,,,,,0,5.000000e+000,1.000000e+000,4,4,2.404022e-001,0,,0,
1627932326.864,,1.000000e+002,2.296092e+002,1.121747e-004,1.856735e-008,1.275632e-001,1.329611e-004,3,9.847865e-001,1.825000e+000,,,,,,,,,,,,,,,,,,0,5.000000e+000,1.000000e+000,4,4,2.657013e-001,0,,0,
1627932551.707,,1.000000e+002,2.196066e+002,1.158829e-004,3.255364e-008,1.210937e-001,1.670765e-004,3,9.852204e-001,1.825000e+000,,,,,,,,,,,,,,,,,,0,5.000000e+000,1.000000e+000,4,4,2.427979e-001,0,,0,
1627932779.499,,1.000000e+002,2.096344e+002,1.198340e-004,3.062216e-008,1.146222e-001,3.188514e-004,3,9.856730e-001,1.825000e+000,,,,,,,,,,,,,,,,,,0,5.000000e+000,1.000000e+000,4,4,2.302094e-001,0,,0,
1627933007.259,,1.000000e+002,1.996214e+002,1.241065e-004,1.729710e-008,1.085412e-001,9.099983e-005,3,9.862728e-001,1.825000e+000,,,,,,,,,,,,,,,,,,0,5.000000e+000,1.000000e+000,4,4,2.427979e-001,0,,0,
1627933237.672,,1.000000e+002,1.896633e+002,1.287871e-004,3.637983e-008,1.028856e-001,1.010198e-004,3,9.866074e-001,1.825000e+000,,,,,,,,,,,,,,,,,,0,5.000000e+000,1.000000e+000,4,4,2.192993e-001,0,,0,
1627933472.858,,1.000000e+002,1.796776e+002,1.339822e-004,3.753640e-008,9.751897e-002,6.783925e-005,3,9.870089e-001,1.825000e+000,,,,,,,,,,,,,,,,,,0,5.000000e+000,1.000000e+000,4,4,2.349854e-001,0,,0,
1627933713.098,,1.000000e+002,1.697107e+002,1.397027e-004,2.666418e-008,9.231453e-002,1.207668e-004,3,9.873494e-001,1.825000e+000,,,,,,,,,,,,,,,,,,0,5.000000e+000,1.000000e+000,4,4,2.534027e-001,0,,0,
1627933961.544,,1.000000e+002,1.597814e+002,1.460775e-004,3.570734e-008,8.750549e-002,7.108179e-005,3,9.877074e-001,1.825000e+000,,,,,,,,,,,,,,,,,,0,5.000000e+000,1.000000e+000,4,4,2.306976e-001,0,,0,
1627934217.946,,1.000000e+002,1.498564e+002,1.531894e-004,4.742733e-008,8.274875e-002,2.368622e-004,3,9.880823e-001,1.825000e+000,,,,,,,,,,,,,,,,,,0,5.000000e+000,1.000000e+000,4,4,2.136993e-001,0,,0,
1627934482.039,,1.000000e+002,1.399350e+002,1.612843e-004,2.701852e-008,7.794021e-002,3.241148e-005,3,9.883990e-001,1.825000e+000,,,,,,,,,,,,,,,,,,0,5.000000e+000,1.000000e+000,4,4,1.789093e-001,0,,0,
1627934747.536,,1.000000e+002,1.299816e+002,1.706172e-004,3.280505e-008,7.382874e-002,1.264040e-004,3,9.887210e-001,1.825000e+000,,,,,,,,,,,,,,,,,,0,5.000000e+000,1.000000e+000,4,4,1.627960e-001,0,,0,
1627935011.894,,1.000000e+002,1.200039e+002,1.815386e-004,3.988973e-008,7.005497e-002,7.154788e-005,3,9.889733e-001,1.825000e+000,,,,,,,,,,,,,,,,,,0,5.000000e+000,1.000000e+000,4,4,1.399002e-001,0,,0,
1627935291.899,,1.000000e+002,1.099963e+002,1.944199e-004,3.415873e-008,6.615956e-002,1.008621e-004,3,9.893513e-001,1.825000e+000,,,,,,,,,,,,,,,,,,0,5.000000e+000,1.000000e+000,4,4,1.213989e-001,0,,0,
1627935588.658,,1.000000e+002,1.000946e+002,2.096536e-004,2.581070e-008,6.264590e-002,1.390580e-004,3,9.895193e-001,1.825000e+000,,,,,,,,,,,,,,,,,,0,5.000000e+000,1.000000e+000,4,4,2.719879e-002,0,,0,
1627935871.923,,1.000000e+002,9.011534e+001,2.282687e-004,7.262828e-008,5.920212e-002,1.337479e-004,3,9.898640e-001,1.825000e+000,,,,,,,,,,,,,,,,,,0,5.000000e+000,1.000000e+000,4,4,2.035522e-002,0,,0,
1627936150.446,,1.000000e+002,8.012275e+001,2.515289e-004,4.723961e-008,5.588384e-002,9.057573e-005,3,9.902282e-001,1.825000e+000,,,,,,,,,,,,,,,,,,0,5.000000e+000,1.000000e+000,4,4,1.488495e-002,0,,0,
1627936420.155,,1.000000e+002,7.012054e+001,2.814557e-004,7.598085e-008,5.259747e-002,9.844888e-005,3,9.904302e-001,1.825000e+000,,,,,,,,,,,,,,,,,,0,5.000000e+000,1.000000e+000,4,4,2.531433e-002,0,,0,
1627936682.657,,1.000000e+002,6.007974e+001,3.212921e-004,4.994816e-008,4.961531e-002,1.388780e-004,3,9.906814e-001,1.825000e+000,,,,,,,,,,,,,,,,,,0,5.000000e+000,1.000000e+000,4,4,8.609772e-003,0,,0,
1627936936.906,,1.000000e+002,5.005376e+001,3.768688e-004,4.768042e-008,4.682605e-002,4.403944e-005,3,9.908793e-001,1.825000e+000,,,,,,,,,,,,,,,,,,0,5.000000e+000,1.000000e+000,4,4,2.070236e-002,0,,0,
1627937276.706,,1.000000e+002,4.500434e+001,4.139988e-004,5.821829e-008,4.537641e-002,7.968174e-005,3,9.908032e-001,1.825000e+000,,,,,,,,,,,,,,,,,,0,5.000000e+000,1.000000e+000,4,4,4.970551e-003,0,,0,
1627937568.426,,1.000000e+002,4.000270e+001,4.601703e-004,9.363291e-008,4.424926e-002,4.723884e-005,3,9.908513e-001,1.825000e+000,,,,,,,,,,,,,,,,,,0,5.000000e+000,1.000000e+000,4,4,1.590729e-003,0,,0,
1627937760.478,,1.000000e+002,3.500535e+001,5.193099e-004,3.349054e-008,4.312179e-002,9.611149e-005,3,9.910311e-001,1.825000e+000,,,,,,,,,,,,,,,,,,0,5.000000e+000,1.000000e+000,4,4,3.078461e-003,0,,0,
1627937960.767,,1.000000e+002,2.999810e+001,5.983121e-004,7.501305e-008,4.211603e-002,1.246456e-004,3,9.911880e-001,1.825000e+000,,,,,,,,,,,,,,,,,,0,5.000000e+000,1.000000e+000,4,4,3.459930e-003,0,,0,
1627938206.280,,1.000000e+002,2.499045e+001,7.087275e-004,2.703553e-007,4.126772e-002,1.056486e-004,3,9.912841e-001,1.825000e+000,,,,,,,,,,,,,,,,,,0,5.000000e+000,1.000000e+000,4,4,3.103065e-002,0,,0,
1627938469.468,,1.000000e+002,2.000073e+001,8.723062e-004,1.415595e-007,4.070042e-002,7.233601e-005,3,9.913574e-001,1.825000e+000,,,,,,,,,,,,,,,,,,0,5.000000e+000,1.000000e+000,4,4,3.210068e-003,0,,0,
1627938642.847,,1.000000e+002,1.800534e+001,9.628134e-004,2.940060e-007,4.043180e-002,3.848955e-005,3,9.914569e-001,1.825000e+000,,,,,,,,,,,,,,,,,,0,5.000000e+000,1.000000e+000,4,4,1.086998e-002,0,,0,
1627938814.806,,1.000000e+002,1.600381e+001,1.076303e-003,1.863793e-007,4.022004e-002,6.808014e-005,3,9.914209e-001,1.825000e+000,,,,,,,,,,,,,,,,,,0,5.000000e+000,1.000000e+000,4,4,5.149841e-003,0,,0,
1627938980.697,,1.000000e+002,1.404119e+001,1.219371e-003,3.391155e-007,4.001194e-002,5.118367e-005,3,9.915844e-001,1.825000e+000,,,,,,,,,,,,,,,,,,0,5.000000e+000,1.000000e+000,4,4,7.500648e-003,0,,0,
1627939149.427,,1.000000e+002,1.200713e+001,1.412722e-003,3.688845e-007,3.999145e-002,5.942905e-005,3,9.915305e-001,1.825000e+000,,,,,,,,,,,,,,,,,,0,5.000000e+000,1.000000e+000,4,4,3.450394e-003,0,,0,
1627939288.127,,1.000000e+002,1.001395e+001,1.684011e-003,6.724100e-007,3.984008e-002,3.990525e-005,3,9.916058e-001,1.825000e+000,,,,,,,,,,,,,,,,,,0,5.000000e+000,1.000000e+000,4,4,1.436043e-002,0,,0,
1627939462.363,,1.000000e+002,9.001733e+000,1.881932e-003,4.006721e-007,3.976072e-002,8.123687e-005,3,9.916604e-001,1.825000e+000,,,,,,,,,,,,,,,,,,0,5.000000e+000,1.000000e+000,4,4,2.399445e-003,0,,0,
1627939639.985,,1.000000e+002,8.002296e+000,2.170325e-003,2.164391e-007,3.974932e-002,3.663868e-005,3,9.916622e-001,1.825000e+000,,,,,,,,,,,,,,,,,,0,5.000000e+000,1.000000e+000,4,4,1.699448e-003,0,,0,
1627939808.762,,1.000000e+002,7.003129e+000,2.559707e-003,3.252248e-007,3.975219e-002,8.321399e-005,3,9.916461e-001,1.825000e+000,,,,,,,,,,,,,,,,,,0,5.000000e+000,1.000000e+000,4,4,2.113342e-003,0,,0,
1627939977.476,,1.000000e+002,6.006084e+000,3.159948e-003,1.057650e-006,3.983248e-002,9.947900e-005,3,9.915681e-001,1.825000e+000,,,,,,,,,,,,,,,,,,0,5.000000e+000,1.000000e+000,4,4,4.597664e-003,0,,0,
1627940146.659,,1.000000e+002,5.003361e+000,4.407937e-003,7.995093e-006,3.967517e-002,3.540792e-005,3,9.917793e-001,1.825000e+000,,,,,,,,,,,,,,,,,,0,5.000000e+000,1.000000e+000,4,4,6.345272e-003,0,,0,
1627940283.720,,1.000000e+002,4.501982e+000,5.757521e-003,6.689887e-006,3.981893e-002,6.383126e-005,3,9.917037e-001,1.825000e+000,,,,,,,,,,,,,,,,,,0,5.000000e+000,1.000000e+000,4,4,4.821777e-003,0,,0,
1627940461.358,,1.000000e+002,4.396757e+000,6.276040e-003,1.162219e-005,3.981201e-002,5.706407e-005,3,9.917350e-001,1.825000e+000,,,,,,,,,,,,,,,,,,0,5.000000e+000,1.000000e+000,4,4,4.868984e-003,0,,0,
1627940605.362,,1.000000e+002,4.287112e+000,6.773333e-003,2.334627e-005,3.973292e-002,5.400897e-005,3,9.917576e-001,1.825000e+000,,,,,,,,,,,,,,,,,,0,5.000000e+000,1.000000e+000,4,4,1.169491e-002,0,,0,
1627940746.714,,1.000000e+002,4.188558e+000,7.285075e-003,1.807832e-005,3.980695e-002,9.297064e-005,3,9.916742e-001,1.825000e+000,,,,,,,,,,,,,,,,,,0,5.000000e+000,1.000000e+000,4,4,8.949280e-003,0,,0,
1627940889.173,,1.000000e+002,4.089807e+000,7.831686e-003,1.107728e-005,3.973655e-002,9.888517e-005,3,9.917920e-001,1.825000e+000,,,,,,,,,,,,,,,,,,0,5.000000e+000,1.000000e+000,4,4,3.214836e-003,0,,0,
1627941083.331,,1.000000e+002,4.010977e+000,8.286444e-003,1.881583e-005,3.978431e-002,6.888268e-005,3,9.917567e-001,1.825000e+000,,,,,,,,,,,,,,,,,,0,5.000000e+000,1.000000e+000,4,4,1.003981e-002,0,,0,
1627941239.534,,1.000000e+002,3.889702e+000,8.785196e-003,1.157671e-005,3.964987e-002,1.316080e-004,3,9.917928e-001,1.825000e+000,,,,,,,,,,,,,,,,,,0,5.000000e+000,1.000000e+000,4,4,1.043415e-002,0,,0,
1627941382.477,,1.000000e+002,3.798206e+000,8.869008e-003,4.860174e-006,3.965857e-002,6.348838e-005,3,9.917840e-001,1.825000e+000,,,,,,,,,,,,,,,,,,0,5.000000e+000,1.000000e+000,4,4,8.167982e-003,0,,0,
1627941529.663,,1.000000e+002,3.700655e+000,8.517659e-003,1.006791e-005,3.983869e-002,8.757960e-005,3,9.916557e-001,1.825000e+000,,,,,,,,,,,,,,,,,,0,5.000000e+000,1.000000e+000,4,4,5.976915e-003,0,,0,
1627941676.881,,1.000000e+002,3.601276e+000,7.775879e-003,1.280153e-005,4.012758e-002,1.109172e-004,3,9.915646e-001,1.825000e+000,,,,,,,,,,,,,,,,,,0,5.000000e+000,1.000000e+000,4,4,5.008936e-003,0,,0,
1627941769.966,,1.000000e+002,3.500964e+000,6.833876e-003,1.695998e-005,4.035118e-002,3.102873e-005,3,9.915473e-001,1.825000e+000,,,,,,,,,,,,,,,,,,0,5.000000e+000,1.000000e+000,4,4,6.792068e-003,0,,0,
1627941916.092,,1.000000e+002,3.249528e+000,4.597372e-003,1.169649e-005,4.056475e-002,1.240967e-004,3,9.914669e-001,1.825000e+000,,,,,,,,,,,,,,,,,,0,5.000000e+000,1.000000e+000,4,4,8.678913e-003,0,,0,
1627942095.367,,1.000000e+002,3.002383e+000,3.205836e-003,3.667199e-006,4.065847e-002,1.030773e-004,3,9.913899e-001,1.825000e+000,,,,,,,,,,,,,,,,,,0,5.000000e+000,1.000000e+000,4,4,6.201982e-003,0,,0,
1627942294.860,,1.000000e+002,2.752736e+000,2.487593e-003,2.069502e-006,4.071336e-002,1.309400e-004,3,9.915032e-001,1.825000e+000,,,,,,,,,,,,,,,,,,0,5.000000e+000,1.000000e+000,4,4,3.006935e-003,0,,0,
1627942495.617,,1.000000e+002,2.502649e+000,2.143311e-003,8.349034e-007,4.081635e-002,1.635199e-004,3,9.915283e-001,1.825000e+000,,,,,,,,,,,,,,,,,,0,5.000000e+000,1.000000e+000,4,4,5.793095e-003,0,,0,
1627942714.142,,1.000000e+002,2.251890e+000,1.984435e-003,4.920930e-007,4.106907e-002,9.778861e-005,3,9.914443e-001,1.825000e+000,,,,,,,,,,,,,,,,,,0,5.000000e+000,1.000000e+000,4,4,5.253077e-003,0,,0,
1627943010.855,,1.000000e+002,2.000109e+000,1.929397e-003,3.908960e-007,4.125627e-002,6.582525e-005,3,9.916112e-001,1.825000e+000,,,,,,,,,,,,,,,,,,0,5.000000e+000,1.000000e+000,4,4,4.908085e-003,0,,0,