File: MPMS/FeCl2btd/FeCl2btd-d4_MH_DC.dc.dat
[Header]
TITLE,MPMS DC Measurement
BYAPP,MPMS Measurement,2.1,Summary
FILEOPENTIME, 1667528719.530000 11/4/2022, 2:25:19 AM

INFO, APPNAME, MPMS MultiVu Application, Revision 1.61,  Build 082

INFO, NAME, FeCl2btd-d4_seruzi
INFO, WEIGHT, 18.820
INFO, AREA, 1.000
INFO, LENGTH, 1.000
INFO, SHAPE, -
INFO, COMMENT, eicosane 14.73mg
INFO, SEQUENCE FILE: JP_ZFC_MH_FC_221104_FeCl2btd-d4_seruzi.seq


INFO, BACKGROUND DATA FILE:, None


STARTUPAXIS,X,4,LINEAR,AUTO,0.000000,0.000000
STARTUPAXIS,Y1,5,LINEAR,AUTO,0.000000,0.000000


STARTUPGROUP,Longitudinal
FIELDGROUP,Longitudinal,1,2,3,4,5,6,7,8,9,15,16,17,18,27,28
FIELDGROUP,Transverse,1,2,3,4,10,11,12,13,14,19,20,21,22,27,28

PLOT_APPEARANCE,ALL,HORZ_GRID_ON,VERT_GRID_ON,MARKERS_AND_LINES

[Data]
Time,Comment,Field (Oe),Temperature (K),Long Moment (emu),Long Scan Std Dev,Long Algorithm,Long Reg Fit,Long Percent Error (%),Trans Moment (emu),Trans Scan Std Dev,Trans Algorithm,Trans Reg Fit,Trans Percent Error (%),Long Moment [w/o ABS] (emu),Long Scan Std Dev [w/o ABS],Long Reg Fit [w/o ABS],Long Percent Error [w/o ABS] (%),Trans Moment [w/o ABS] (emu),Trans Scan Std Dev [w/o ABS],Trans Reg Fit [w/o ABS],Trans Percent Error [w/o ABS] (%),Points per Scan,Scans per Measurement,Scan Length (cm),Delta Temp (K),Rot Position (deg),Error,EC Comp. Running,Using ABS,
1667528719.530,,0.000000e+000,1.999672e+000,4.456035e-004,0.000000e+000,3,9.946910e-001,0.000000e+000,,,,,,,,,,,,,,32,1,8.000000e+000,5.110502e-004,0.000000e+000,0,,0,
1667528774.894,,1.005028e+002,1.997170e+000,2.522346e-003,0.000000e+000,3,9.956359e-001,0.000000e+000,,,,,,,,,,,,,,32,1,8.000000e+000,1.090765e-004,0.000000e+000,0,,0,
1667528805.840,,2.006895e+002,1.999549e+000,4.143161e-003,0.000000e+000,3,9.845636e-001,0.000000e+000,,,,,,,,,,,,,,32,1,8.000000e+000,5.362868e-003,0.000000e+000,0,,0,
1667528837.458,,3.011186e+002,2.000046e+000,5.863817e-003,0.000000e+000,3,9.905475e-001,0.000000e+000,,,,,,,,,,,,,,32,1,8.000000e+000,5.036950e-003,0.000000e+000,0,,0,
1667528870.741,,4.013475e+002,1.999962e+000,7.871669e-003,0.000000e+000,3,9.916595e-001,0.000000e+000,,,,,,,,,,,,,,32,1,8.000000e+000,4.400015e-003,0.000000e+000,0,,0,
1667528954.751,,5.016396e+002,1.998071e+000,1.632991e-002,0.000000e+000,3,9.953935e-001,0.000000e+000,,,,,,,,,,,,,,32,1,8.000000e+000,1.789331e-004,0.000000e+000,0,,0,
1667528986.443,,6.017842e+002,1.999770e+000,5.400469e-002,0.000000e+000,3,9.954230e-001,0.000000e+000,,,,,,,,,,,,,,32,1,8.000000e+000,5.144000e-003,0.000000e+000,0,,0,
1667529066.391,,7.022239e+002,1.997962e+000,1.046090e-001,0.000000e+000,3,9.951549e-001,0.000000e+000,,,,,,,,,,,,,,32,1,8.000000e+000,6.902218e-005,0.000000e+000,0,,0,
1667529098.347,,8.024846e+002,2.000530e+000,1.506736e-001,0.000000e+000,3,9.952103e-001,0.000000e+000,,,,,,,,,,,,,,32,1,8.000000e+000,6.636024e-003,0.000000e+000,0,,0,
1667529130.901,,9.028294e+002,1.999950e+000,1.890938e-001,0.000000e+000,3,9.951714e-001,0.000000e+000,,,,,,,,,,,,,,32,1,8.000000e+000,5.063891e-003,0.000000e+000,0,,0,
1667529161.957,,1.003005e+003,2.000771e+000,2.196303e-001,0.000000e+000,3,9.950212e-001,0.000000e+000,,,,,,,,,,,,,,32,1,8.000000e+000,6.127000e-003,0.000000e+000,0,,0,
1667529264.368,,2.007949e+003,1.999314e+000,3.355811e-001,0.000000e+000,3,9.950539e-001,0.000000e+000,,,,,,,,,,,,,,32,1,8.000000e+000,1.119018e-003,0.000000e+000,0,,0,
1667529301.929,,3.012767e+003,2.000384e+000,3.684623e-001,0.000000e+000,3,9.945344e-001,0.000000e+000,,,,,,,,,,,,,,32,1,8.000000e+000,4.335046e-003,0.000000e+000,0,,0,
1667529338.306,,4.014634e+003,2.000040e+000,3.878090e-001,0.000000e+000,3,9.948700e-001,0.000000e+000,,,,,,,,,,,,,,32,1,8.000000e+000,4.994988e-003,0.000000e+000,0,,0,
1667529375.162,,5.017766e+003,1.999859e+000,4.037920e-001,0.000000e+000,3,9.949136e-001,0.000000e+000,,,,,,,,,,,,,,32,1,8.000000e+000,4.634023e-003,0.000000e+000,0,,0,
1667529411.763,,6.019211e+003,1.999969e+000,4.191152e-001,0.000000e+000,3,9.948108e-001,0.000000e+000,,,,,,,,,,,,,,32,1,8.000000e+000,4.414082e-003,0.000000e+000,0,,0,
1667529448.222,,7.023926e+003,2.000267e+000,4.354592e-001,0.000000e+000,3,9.948616e-001,0.000000e+000,,,,,,,,,,,,,,32,1,8.000000e+000,4.652023e-003,0.000000e+000,0,,0,
1667529484.726,,8.026111e+003,1.999926e+000,4.550004e-001,0.000000e+000,3,9.948343e-001,0.000000e+000,,,,,,,,,,,,,,32,1,8.000000e+000,3.969908e-003,0.000000e+000,0,,0,
1667529521.642,,9.029766e+003,2.000190e+000,4.803536e-001,0.000000e+000,3,9.946582e-001,0.000000e+000,,,,,,,,,,,,,,32,1,8.000000e+000,4.498959e-003,0.000000e+000,0,,0,
1667529557.699,,1.003195e+004,2.000114e+000,5.108587e-001,0.000000e+000,3,9.946490e-001,0.000000e+000,,,,,,,,,,,,,,32,1,8.000000e+000,4.345894e-003,0.000000e+000,0,,0,
1667529651.136,,1.504329e+004,1.999017e+000,6.824011e-001,0.000000e+000,3,9.946729e-001,0.000000e+000,,,,,,,,,,,,,,32,1,8.000000e+000,3.869534e-004,0.000000e+000,0,,0,
1667529705.632,,2.005526e+004,1.999957e+000,8.033131e-001,0.000000e+000,3,9.945600e-001,0.000000e+000,,,,,,,,,,,,,,32,1,8.000000e+000,1.631975e-003,0.000000e+000,0,,0,
1667529760.811,,2.507355e+004,1.999045e+000,8.830272e-001,0.000000e+000,3,9.944569e-001,0.000000e+000,,,,,,,,,,,,,,32,1,8.000000e+000,1.518965e-003,0.000000e+000,0,,0,
1667529816.507,,3.009079e+004,1.998865e+000,9.413570e-001,0.000000e+000,3,9.944662e-001,0.000000e+000,,,,,,,,,,,,,,32,1,8.000000e+000,1.352072e-003,0.000000e+000,0,,0,
1667529873.685,,3.510277e+004,1.999024e+000,9.879356e-001,0.000000e+000,3,9.944988e-001,0.000000e+000,,,,,,,,,,,,,,32,1,8.000000e+000,1.255989e-003,0.000000e+000,0,,0,
1667529930.302,,4.012000e+004,1.999231e+000,1.027300e+000,0.000000e+000,3,9.945388e-001,0.000000e+000,,,,,,,,,,,,,,32,1,8.000000e+000,1.368046e-003,0.000000e+000,0,,0,
1667529984.332,,4.513830e+004,1.999210e+000,1.061760e+000,0.000000e+000,3,9.945803e-001,0.000000e+000,,,,,,,,,,,,,,32,1,8.000000e+000,1.435995e-003,0.000000e+000,0,,0,
1667530038.856,,5.015448e+004,1.999245e+000,1.092652e+000,0.000000e+000,3,9.946292e-001,0.000000e+000,,,,,,,,,,,,,,32,1,8.000000e+000,1.478076e-003,0.000000e+000,0,,0,
1667530117.114,,5.012919e+004,1.999099e+000,1.091861e+000,0.000000e+000,3,9.948536e-001,0.000000e+000,,,,,,,,,,,,,,32,1,8.000000e+000,1.940727e-004,0.000000e+000,0,,0,
1667530173.787,,4.511511e+004,1.999722e+000,1.062256e+000,0.000000e+000,3,9.942714e-001,0.000000e+000,,,,,,,,,,,,,,32,1,8.000000e+000,1.464963e-003,0.000000e+000,0,,0,
1667530230.589,,4.009788e+004,1.999176e+000,1.027629e+000,0.000000e+000,3,9.943475e-001,0.000000e+000,,,,,,,,,,,,,,32,1,8.000000e+000,1.532912e-003,0.000000e+000,0,,0,
1667530289.549,,3.508170e+004,1.998824e+000,9.881377e-001,0.000000e+000,3,9.943773e-001,0.000000e+000,,,,,,,,,,,,,,32,1,8.000000e+000,1.049042e-003,0.000000e+000,0,,0,
1667530345.874,,3.006761e+004,1.999093e+000,9.415230e-001,0.000000e+000,3,9.942893e-001,0.000000e+000,,,,,,,,,,,,,,32,1,8.000000e+000,1.228929e-003,0.000000e+000,0,,0,
1667530400.841,,2.505195e+004,1.999273e+000,8.832461e-001,0.000000e+000,3,9.942940e-001,0.000000e+000,,,,,,,,,,,,,,32,1,8.000000e+000,1.366973e-003,0.000000e+000,0,,0,
1667530456.752,,2.003419e+004,1.999356e+000,8.036047e-001,0.000000e+000,3,9.942763e-001,0.000000e+000,,,,,,,,,,,,,,32,1,8.000000e+000,1.451015e-003,0.000000e+000,0,,0,
1667530509.435,,1.502011e+004,1.999293e+000,6.827262e-001,0.000000e+000,3,9.941931e-001,0.000000e+000,,,,,,,,,,,,,,32,1,8.000000e+000,1.492143e-003,0.000000e+000,0,,0,
1667530602.258,,1.002879e+004,1.998747e+000,5.112773e-001,0.000000e+000,3,9.940281e-001,0.000000e+000,,,,,,,,,,,,,,32,1,8.000000e+000,1.239777e-004,0.000000e+000,0,,0,
1667530639.030,,9.026187e+003,2.000928e+000,4.807632e-001,0.000000e+000,3,9.942689e-001,0.000000e+000,,,,,,,,,,,,,,32,1,8.000000e+000,2.717853e-003,0.000000e+000,0,,0,
1667530677.052,,8.022739e+003,2.000804e+000,4.555019e-001,0.000000e+000,3,9.942014e-001,0.000000e+000,,,,,,,,,,,,,,32,1,8.000000e+000,3.243923e-003,0.000000e+000,0,,0,
1667530713.551,,7.020132e+003,2.000264e+000,4.359844e-001,0.000000e+000,3,9.944308e-001,0.000000e+000,,,,,,,,,,,,,,32,1,8.000000e+000,3.239989e-003,0.000000e+000,0,,0,
1667530752.767,,6.015314e+003,1.999647e+000,4.196853e-001,0.000000e+000,3,9.944272e-001,0.000000e+000,,,,,,,,,,,,,,32,1,8.000000e+000,2.972960e-003,0.000000e+000,0,,0,
1667530789.940,,5.013973e+003,1.999557e+000,4.046378e-001,0.000000e+000,3,9.941744e-001,0.000000e+000,,,,,,,,,,,,,,32,1,8.000000e+000,2.765059e-003,0.000000e+000,0,,0,
1667530827.080,,4.010841e+003,1.999716e+000,3.888216e-001,0.000000e+000,3,9.942729e-001,0.000000e+000,,,,,,,,,,,,,,32,1,8.000000e+000,2.614021e-003,0.000000e+000,0,,0,
1667530864.407,,3.008974e+003,1.999847e+000,3.699887e-001,0.000000e+000,3,9.942191e-001,0.000000e+000,,,,,,,,,,,,,,32,1,8.000000e+000,2.378941e-003,0.000000e+000,0,,0,
1667530900.872,,2.004577e+003,1.999937e+000,3.392995e-001,0.000000e+000,3,9.941689e-001,0.000000e+000,,,,,,,,,,,,,,32,1,8.000000e+000,2.393961e-003,0.000000e+000,0,,0,
1667530979.758,,1.003152e+003,1.998713e+000,2.321560e-001,0.000000e+000,3,9.941998e-001,0.000000e+000,,,,,,,,,,,,,,32,1,8.000000e+000,2.801418e-005,0.000000e+000,0,,0,
1667531035.645,,9.029348e+002,1.999914e+000,2.030397e-001,0.000000e+000,3,9.949301e-001,0.000000e+000,,,,,,,,,,,,,,32,1,8.000000e+000,5.248785e-004,0.000000e+000,0,,0,
1667531068.108,,8.026320e+002,2.000803e+000,1.670524e-001,0.000000e+000,3,9.946398e-001,0.000000e+000,,,,,,,,,,,,,,32,1,8.000000e+000,2.799988e-003,0.000000e+000,0,,0,
1667531099.772,,7.023500e+002,2.000248e+000,1.221147e-001,0.000000e+000,3,9.944986e-001,0.000000e+000,,,,,,,,,,,,,,32,1,8.000000e+000,2.436996e-003,0.000000e+000,0,,0,
1667531157.486,,6.019106e+002,1.998637e+000,7.178236e-002,0.000000e+000,3,9.948714e-001,0.000000e+000,,,,,,,,,,,,,,32,1,8.000000e+000,3.440380e-004,0.000000e+000,0,,0,
1667531190.455,,5.017555e+002,1.999605e+000,3.335838e-002,0.000000e+000,3,9.925222e-001,0.000000e+000,,,,,,,,,,,,,,32,1,8.000000e+000,2.059937e-003,0.000000e+000,0,,0,
1667531247.791,,4.014845e+002,1.998878e+000,2.023825e-002,0.000000e+000,3,9.951050e-001,0.000000e+000,,,,,,,,,,,,,,32,1,8.000000e+000,4.138947e-004,0.000000e+000,0,,0,
1667531280.649,,3.012556e+002,1.999888e+000,1.551516e-002,0.000000e+000,3,9.887523e-001,0.000000e+000,,,,,,,,,,,,,,32,1,8.000000e+000,1.798034e-003,0.000000e+000,0,,0,
1667531312.923,,2.008160e+002,1.999971e+000,1.201049e-002,0.000000e+000,3,9.909340e-001,0.000000e+000,,,,,,,,,,,,,,32,1,8.000000e+000,1.853943e-003,0.000000e+000,0,,0,
1667531371.528,,1.006503e+002,1.999147e+000,8.905914e-003,0.000000e+000,3,9.945669e-001,0.000000e+000,,,,,,,,,,,,,,32,1,8.000000e+000,2.070665e-004,0.000000e+000,0,,0,
1667531428.944,,1.369679e-001,1.999265e+000,2.286600e-003,0.000000e+000,3,9.925501e-001,0.000000e+000,,,,,,,,,,,,,,32,1,8.000000e+000,3.319979e-004,0.000000e+000,0,,0,
1667531502.452,,1.580398e-001,1.998782e+000,2.213600e-003,0.000000e+000,3,9.947378e-001,0.000000e+000,,,,,,,,,,,,,,32,1,8.000000e+000,4.140139e-004,0.000000e+000,0,,0,
1667531540.963,,-1.006503e+002,2.000316e+000,-4.853718e-003,0.000000e+000,3,9.948207e-001,0.000000e+000,,,,,,,,,,,,,,32,1,8.000000e+000,1.356959e-003,0.000000e+000,0,,0,
1667531624.470,,-2.008687e+002,1.999832e+000,-7.541247e-003,0.000000e+000,3,9.950198e-001,0.000000e+000,,,,,,,,,,,,,,32,1,8.000000e+000,0.000000e+000,0.000000e+000,0,,0,
1667531656.487,,-3.012977e+002,2.000407e+000,-9.881755e-003,0.000000e+000,3,9.942337e-001,0.000000e+000,,,,,,,,,,,,,,32,1,8.000000e+000,2.090931e-003,0.000000e+000,0,,0,
1667531688.976,,-4.015266e+002,1.999923e+000,-1.231472e-002,0.000000e+000,3,9.947500e-001,0.000000e+000,,,,,,,,,,,,,,32,1,8.000000e+000,1.866937e-003,0.000000e+000,0,,0,
1667531722.050,,-5.018187e+002,1.999501e+000,-2.174070e-002,0.000000e+000,3,9.951819e-001,0.000000e+000,,,,,,,,,,,,,,32,1,8.000000e+000,1.852036e-003,0.000000e+000,0,,0,
1667531780.975,,-6.019423e+002,1.998802e+000,-6.030004e-002,0.000000e+000,3,9.949117e-001,0.000000e+000,,,,,,,,,,,,,,32,1,8.000000e+000,3.169775e-004,0.000000e+000,0,,0,
1667531813.049,,-7.023500e+002,1.999825e+000,-1.095469e-001,0.000000e+000,3,9.941266e-001,0.000000e+000,,,,,,,,,,,,,,32,1,8.000000e+000,1.507163e-003,0.000000e+000,0,,0,
1667531846.501,,-8.026320e+002,1.999916e+000,-1.550393e-001,0.000000e+000,3,9.940857e-001,0.000000e+000,,,,,,,,,,,,,,32,1,8.000000e+000,1.577020e-003,0.000000e+000,0,,0,
1667531877.897,,-9.029554e+002,2.000123e+000,-1.926501e-001,0.000000e+000,3,9.938228e-001,0.000000e+000,,,,,,,,,,,,,,32,1,8.000000e+000,1.440048e-003,0.000000e+000,0,,0,
1667531909.585,,-1.003152e+003,2.000185e+000,-2.225036e-001,0.000000e+000,3,9.936228e-001,0.000000e+000,,,,,,,,,,,,,,32,1,8.000000e+000,1.453996e-003,0.000000e+000,0,,0,
1667532012.725,,-2.009213e+003,1.998955e+000,-3.361198e-001,0.000000e+000,3,9.948668e-001,0.000000e+000,,,,,,,,,,,,,,32,1,8.000000e+000,1.117945e-003,0.000000e+000,0,,0,
1667532050.352,,-3.013083e+003,2.000310e+000,-3.687478e-001,0.000000e+000,3,9.946953e-001,0.000000e+000,,,,,,,,,,,,,,32,1,8.000000e+000,1.453876e-003,0.000000e+000,0,,0,
1667532087.710,,-4.014950e+003,2.000275e+000,-3.881520e-001,0.000000e+000,3,9.947723e-001,0.000000e+000,,,,,,,,,,,,,,32,1,8.000000e+000,1.412034e-003,0.000000e+000,0,,0,
1667532123.474,,-5.018082e+003,2.000178e+000,-4.040390e-001,0.000000e+000,3,9.947777e-001,0.000000e+000,,,,,,,,,,,,,,32,1,8.000000e+000,1.412034e-003,0.000000e+000,0,,0,
1667532161.137,,-6.019633e+003,1.999977e+000,-4.193443e-001,0.000000e+000,3,9.947499e-001,0.000000e+000,,,,,,,,,,,,,,32,1,8.000000e+000,1.756907e-003,0.000000e+000,0,,0,
1667532198.103,,-7.024344e+003,1.999770e+000,-4.357750e-001,0.000000e+000,3,9.947598e-001,0.000000e+000,,,,,,,,,,,,,,32,1,8.000000e+000,1.451969e-003,0.000000e+000,0,,0,
1667532235.879,,-8.026528e+003,1.999722e+000,-4.552699e-001,0.000000e+000,3,9.948339e-001,0.000000e+000,,,,,,,,,,,,,,32,1,8.000000e+000,1.410961e-003,0.000000e+000,0,,0,
1667532273.271,,-9.029977e+003,1.999770e+000,-4.805808e-001,0.000000e+000,3,9.946959e-001,0.000000e+000,,,,,,,,,,,,,,32,1,8.000000e+000,1.147985e-003,0.000000e+000,0,,0,
1667532310.492,,-1.003216e+004,1.999804e+000,-5.111259e-001,0.000000e+000,3,9.946414e-001,0.000000e+000,,,,,,,,,,,,,,32,1,8.000000e+000,1.273036e-003,0.000000e+000,0,,0,
1667532404.546,,-1.504592e+004,1.999044e+000,-6.825574e-001,0.000000e+000,3,9.946904e-001,0.000000e+000,,,,,,,,,,,,,,32,1,8.000000e+000,1.660585e-004,0.000000e+000,0,,0,
1667532459.302,,-2.006000e+004,2.000136e+000,-8.035119e-001,0.000000e+000,3,9.945194e-001,0.000000e+000,,,,,,,,,,,,,,32,1,8.000000e+000,1.052141e-003,0.000000e+000,0,,0,
1667532516.003,,-2.507777e+004,2.000040e+000,-8.830557e-001,0.000000e+000,3,9.944953e-001,0.000000e+000,,,,,,,,,,,,,,32,1,8.000000e+000,1.329064e-003,0.000000e+000,0,,0,
1667532572.957,,-3.009289e+004,1.999867e+000,-9.414686e-001,0.000000e+000,3,9.945058e-001,0.000000e+000,,,,,,,,,,,,,,32,1,8.000000e+000,1.286030e-003,0.000000e+000,0,,0,
1667532629.952,,-3.511014e+004,1.999743e+000,-9.881923e-001,0.000000e+000,3,9.944364e-001,0.000000e+000,,,,,,,,,,,,,,32,1,8.000000e+000,1.397133e-003,0.000000e+000,0,,0,
1667532685.817,,-4.012632e+004,1.999624e+000,-1.027527e+000,0.000000e+000,3,9.945131e-001,0.000000e+000,,,,,,,,,,,,,,32,1,8.000000e+000,1.189113e-003,0.000000e+000,0,,0,
1667532741.928,,-4.514356e+004,1.999673e+000,-1.061966e+000,0.000000e+000,3,9.944980e-001,0.000000e+000,,,,,,,,,,,,,,32,1,8.000000e+000,1.064062e-003,0.000000e+000,0,,0,
1667532798.918,,-5.016186e+004,1.999784e+000,-1.093137e+000,0.000000e+000,3,9.945320e-001,0.000000e+000,,,,,,,,,,,,,,32,1,8.000000e+000,1.037121e-003,0.000000e+000,0,,0,
1667532877.825,,-5.012604e+004,1.999320e+000,-1.092252e+000,0.000000e+000,3,9.947969e-001,0.000000e+000,,,,,,,,,,,,,,32,1,8.000000e+000,4.700422e-004,0.000000e+000,0,,0,
1667532936.061,,-4.510563e+004,1.999776e+000,-1.062385e+000,0.000000e+000,3,9.942770e-001,0.000000e+000,,,,,,,,,,,,,,32,1,8.000000e+000,8.289814e-004,0.000000e+000,0,,0,
1667532994.136,,-4.008734e+004,1.999852e+000,-1.027663e+000,0.000000e+000,3,9.943574e-001,0.000000e+000,,,,,,,,,,,,,,32,1,8.000000e+000,1.202941e-003,0.000000e+000,0,,0,
1667533051.140,,-3.507115e+004,1.999694e+000,-9.880542e-001,0.000000e+000,3,9.944240e-001,0.000000e+000,,,,,,,,,,,,,,32,1,8.000000e+000,1.188993e-003,0.000000e+000,0,,0,
1667533108.472,,-3.006340e+004,1.999604e+000,-9.415576e-001,0.000000e+000,3,9.943585e-001,0.000000e+000,,,,,,,,,,,,,,32,1,8.000000e+000,1.146913e-003,0.000000e+000,0,,0,
1667533164.869,,-2.504774e+004,1.999645e+000,-8.832613e-001,0.000000e+000,3,9.942273e-001,0.000000e+000,,,,,,,,,,,,,,32,1,8.000000e+000,1.008987e-003,0.000000e+000,0,,0,
1667533220.115,,-2.002892e+004,1.999673e+000,-8.037383e-001,0.000000e+000,3,9.942615e-001,0.000000e+000,,,,,,,,,,,,,,32,1,8.000000e+000,9.820461e-004,0.000000e+000,0,,0,
1667533274.479,,-1.501642e+004,1.999652e+000,-6.828518e-001,0.000000e+000,3,9.941673e-001,0.000000e+000,,,,,,,,,,,,,,32,1,8.000000e+000,9.400845e-004,0.000000e+000,0,,0,
1667533368.148,,-1.002647e+004,1.999134e+000,-5.113582e-001,0.000000e+000,3,9.939346e-001,0.000000e+000,,,,,,,,,,,,,,32,1,8.000000e+000,1.240969e-004,0.000000e+000,0,,0,
1667533406.498,,-9.025130e+003,2.000351e+000,-4.808679e-001,0.000000e+000,3,9.941722e-001,0.000000e+000,,,,,,,,,,,,,,32,1,8.000000e+000,1.037955e-003,0.000000e+000,0,,0,
1667533442.710,,-8.021475e+003,2.000496e+000,-4.555317e-001,0.000000e+000,3,9.943274e-001,0.000000e+000,,,,,,,,,,,,,,32,1,8.000000e+000,1.190901e-003,0.000000e+000,0,,0,
1667533480.198,,-7.019076e+003,2.000421e+000,-4.360487e-001,0.000000e+000,3,9.943680e-001,0.000000e+000,,,,,,,,,,,,,,32,1,8.000000e+000,1.371026e-003,0.000000e+000,0,,0,
1667533517.146,,-6.014787e+003,2.000171e+000,-4.196948e-001,0.000000e+000,3,9.943709e-001,0.000000e+000,,,,,,,,,,,,,,32,1,8.000000e+000,1.260042e-003,0.000000e+000,0,,0,
1667533554.609,,-5.013341e+003,1.999908e+000,-4.045900e-001,0.000000e+000,3,9.943778e-001,0.000000e+000,,,,,,,,,,,,,,32,1,8.000000e+000,1.368999e-003,0.000000e+000,0,,0,
1667533592.153,,-4.010104e+003,1.999839e+000,-3.887973e-001,0.000000e+000,3,9.944334e-001,0.000000e+000,,,,,,,,,,,,,,32,1,8.000000e+000,1.147985e-003,0.000000e+000,0,,0,
1667533630.332,,-3.008236e+003,1.999659e+000,-3.698896e-001,0.000000e+000,3,9.943279e-001,0.000000e+000,,,,,,,,,,,,,,32,1,8.000000e+000,1.120090e-003,0.000000e+000,0,,0,
1667533667.246,,-2.004051e+003,1.999693e+000,-3.392558e-001,0.000000e+000,3,9.942654e-001,0.000000e+000,,,,,,,,,,,,,,32,1,8.000000e+000,9.669065e-004,0.000000e+000,0,,0,
1667533743.217,,-1.003174e+003,1.999141e+000,-2.323740e-001,0.000000e+000,3,9.943263e-001,0.000000e+000,,,,,,,,,,,,,,32,1,8.000000e+000,3.309250e-004,0.000000e+000,0,,0,
1667533800.600,,-9.030189e+002,1.999922e+000,-2.032757e-001,0.000000e+000,3,9.949627e-001,0.000000e+000,,,,,,,,,,,,,,32,1,8.000000e+000,4.839897e-004,0.000000e+000,0,,0,
1667533832.993,,-8.026741e+002,2.000690e+000,-1.673353e-001,0.000000e+000,3,9.946517e-001,0.000000e+000,,,,,,,,,,,,,,32,1,8.000000e+000,1.275063e-003,0.000000e+000,0,,0,
1667533864.712,,-7.023921e+002,2.000531e+000,-1.223575e-001,0.000000e+000,3,9.946167e-001,0.000000e+000,,,,,,,,,,,,,,32,1,8.000000e+000,1.232982e-003,0.000000e+000,0,,0,
1667533922.156,,-6.019422e+002,1.999604e+000,-7.208794e-002,0.000000e+000,3,9.949548e-001,0.000000e+000,,,,,,,,,,,,,,32,1,8.000000e+000,1.790524e-004,0.000000e+000,0,,0,
1667533953.229,,-5.017871e+002,2.000061e+000,-3.352322e-002,0.000000e+000,3,9.922083e-001,0.000000e+000,,,,,,,,,,,,,,32,1,8.000000e+000,1.287103e-003,0.000000e+000,0,,0,
1667534010.525,,-4.015161e+002,1.999244e+000,-2.026726e-002,0.000000e+000,3,9.952178e-001,0.000000e+000,,,,,,,,,,,,,,32,1,8.000000e+000,1.406670e-005,0.000000e+000,0,,0,
1667534043.797,,-3.012977e+002,1.999687e+000,-1.555368e-002,0.000000e+000,3,9.918606e-001,0.000000e+000,,,,,,,,,,,,,,32,1,8.000000e+000,1.119971e-003,0.000000e+000,0,,0,
1667534099.830,,-2.008476e+002,1.999313e+000,-1.194907e-002,0.000000e+000,3,9.952376e-001,0.000000e+000,,,,,,,,,,,,,,32,1,8.000000e+000,2.620220e-004,0.000000e+000,0,,0,
1667534132.165,,-1.006819e+002,1.999915e+000,-9.005741e-003,0.000000e+000,3,9.897536e-001,0.000000e+000,,,,,,,,,,,,,,32,1,8.000000e+000,8.019209e-004,0.000000e+000,0,,0,
1667534189.702,,-2.001838e-001,1.999659e+000,-2.466689e-003,0.000000e+000,3,9.921709e-001,0.000000e+000,,,,,,,,,,,,,,32,1,8.000000e+000,2.080202e-004,0.000000e+000,0,,0,
1667534262.993,,-1.896478e-001,1.999321e+000,-2.385230e-003,0.000000e+000,3,9.940915e-001,0.000000e+000,,,,,,,,,,,,,,32,1,8.000000e+000,3.590584e-004,0.000000e+000,0,,0,
1667534302.310,,1.007452e+002,2.000032e+000,4.864438e-003,0.000000e+000,3,9.931026e-001,0.000000e+000,,,,,,,,,,,,,,32,1,8.000000e+000,7.050037e-004,0.000000e+000,0,,0,
1667534385.462,,2.008687e+002,2.000039e+000,7.535568e-003,0.000000e+000,3,9.946180e-001,0.000000e+000,,,,,,,,,,,,,,32,1,8.000000e+000,1.380444e-004,0.000000e+000,0,,0,
1667534416.606,,3.013083e+002,2.000572e+000,9.886481e-003,0.000000e+000,3,9.902031e-001,0.000000e+000,,,,,,,,,,,,,,32,1,8.000000e+000,1.232982e-003,0.000000e+000,0,,0,
1667534448.519,,4.015266e+002,2.000192e+000,1.232303e-002,0.000000e+000,3,9.945652e-001,0.000000e+000,,,,,,,,,,,,,,32,1,8.000000e+000,1.108050e-003,0.000000e+000,0,,0,
1667534481.706,,5.018293e+002,1.999991e+000,2.163589e-002,0.000000e+000,3,9.936099e-001,0.000000e+000,,,,,,,,,,,,,,32,1,8.000000e+000,9.540319e-004,0.000000e+000,0,,0,
1667534538.343,,6.019422e+002,1.999389e+000,6.002409e-002,0.000000e+000,3,9.944533e-001,0.000000e+000,,,,,,,,,,,,,,32,1,8.000000e+000,1.660585e-004,0.000000e+000,0,,0,
1667534569.853,,7.023710e+002,1.999846e+000,1.092534e-001,0.000000e+000,3,9.937535e-001,0.000000e+000,,,,,,,,,,,,,,32,1,8.000000e+000,8.569956e-004,0.000000e+000,0,,0,
1667534602.746,,8.026530e+002,1.999922e+000,1.546559e-001,0.000000e+000,3,9.943781e-001,0.000000e+000,,,,,,,,,,,,,,32,1,8.000000e+000,9.551048e-004,0.000000e+000,0,,0,
1667534635.245,,9.029765e+002,1.999970e+000,1.924408e-001,0.000000e+000,3,9.936597e-001,0.000000e+000,,,,,,,,,,,,,,32,1,8.000000e+000,9.130239e-004,0.000000e+000,0,,0,
1667534667.474,,1.003153e+003,1.999936e+000,2.223581e-001,0.000000e+000,3,9.938757e-001,0.000000e+000,,,,,,,,,,,,,,32,1,8.000000e+000,7.889271e-004,0.000000e+000,0,,0,
1667534771.389,,2.008582e+003,1.999610e+000,3.362346e-001,0.000000e+000,3,9.947098e-001,0.000000e+000,,,,,,,,,,,,,,32,1,8.000000e+000,6.910563e-004,0.000000e+000,0,,0,
1667534808.841,,3.013715e+003,2.000468e+000,3.687367e-001,0.000000e+000,3,9.946440e-001,0.000000e+000,,,,,,,,,,,,,,32,1,8.000000e+000,6.651878e-004,0.000000e+000,0,,0,
1667534846.403,,4.015477e+003,2.000483e+000,3.881230e-001,0.000000e+000,3,9.947842e-001,0.000000e+000,,,,,,,,,,,,,,32,1,8.000000e+000,8.308887e-004,0.000000e+000,0,,0,
1667534882.755,,5.018609e+003,2.000420e+000,4.041170e-001,0.000000e+000,3,9.948021e-001,0.000000e+000,,,,,,,,,,,,,,32,1,8.000000e+000,9.280443e-004,0.000000e+000,0,,0,
1667534920.916,,6.019949e+003,2.000365e+000,4.193802e-001,0.000000e+000,3,9.947169e-001,0.000000e+000,,,,,,,,,,,,,,32,1,8.000000e+000,8.169413e-004,0.000000e+000,0,,0,
1667534957.093,,7.024558e+003,2.000503e+000,4.358346e-001,0.000000e+000,3,9.947710e-001,0.000000e+000,,,,,,,,,,,,,,32,1,8.000000e+000,8.180141e-004,0.000000e+000,0,,0,
1667534993.104,,8.026950e+003,2.000649e+000,4.554335e-001,0.000000e+000,3,9.947380e-001,0.000000e+000,,,,,,,,,,,,,,32,1,8.000000e+000,9.698868e-004,0.000000e+000,0,,0,
1667535029.275,,9.030398e+003,2.000607e+000,4.807113e-001,0.000000e+000,3,9.946975e-001,0.000000e+000,,,,,,,,,,,,,,32,1,8.000000e+000,1.163960e-003,0.000000e+000,0,,0,
1667535067.439,,1.003258e+004,2.000234e+000,5.112649e-001,0.000000e+000,3,9.946225e-001,0.000000e+000,,,,,,,,,,,,,,32,1,8.000000e+000,1.301050e-003,0.000000e+000,0,,0,
1667535161.248,,1.504329e+004,1.998637e+000,6.825205e-001,0.000000e+000,3,9.946699e-001,0.000000e+000,,,,,,,,,,,,,,32,1,8.000000e+000,4.279613e-004,0.000000e+000,0,,0,
1667535214.593,,2.005579e+004,1.999417e+000,8.034340e-001,0.000000e+000,3,9.946194e-001,0.000000e+000,,,,,,,,,,,,,,32,1,8.000000e+000,6.080866e-004,0.000000e+000,0,,0,
1667535271.327,,2.507355e+004,1.999777e+000,8.830531e-001,0.000000e+000,3,9.944839e-001,0.000000e+000,,,,,,,,,,,,,,32,1,8.000000e+000,7.749796e-004,0.000000e+000,0,,0,
1667535326.536,,3.009079e+004,2.000185e+000,9.416372e-001,0.000000e+000,3,9.944347e-001,0.000000e+000,,,,,,,,,,,,,,32,1,8.000000e+000,8.999109e-004,0.000000e+000,0,,0,
1667535385.006,,3.510382e+004,2.000108e+000,9.880351e-001,0.000000e+000,3,9.945119e-001,0.000000e+000,,,,,,,,,,,,,,32,1,8.000000e+000,1.134872e-003,0.000000e+000,0,,0,
1667535442.013,,4.011895e+004,1.999936e+000,1.027487e+000,0.000000e+000,3,9.945374e-001,0.000000e+000,,,,,,,,,,,,,,32,1,8.000000e+000,1.147985e-003,0.000000e+000,0,,0,
1667535497.709,,4.513619e+004,1.999818e+000,1.062032e+000,0.000000e+000,3,9.945360e-001,0.000000e+000,,,,,,,,,,,,,,32,1,8.000000e+000,1.188993e-003,0.000000e+000,0,,0,
1667535554.100,,5.015237e+004,1.999631e+000,1.092823e+000,0.000000e+000,3,9.945865e-001,0.000000e+000,,,,,,,,,,,,,,32,1,8.000000e+000,1.091957e-003,0.000000e+000,0,,0,