File: MPMS/FeCl2btd/FeCl2btd_2-300K_ZFC.rso.dat
[Header]
TITLE,MPMS RSO Measurement
BYAPP,MPMS Measurement,1.1,Summary
FILEOPENTIME, 1627915754.159000 8/2/2021, 3:49:14 PM

INFO, APPNAME, MPMS MultiVu Application, Revision 1.61,  Build 082

INFO, NAME, FeCl2btd
INFO, WEIGHT, 11.850
INFO, AREA, 1.000
INFO, LENGTH, 1.000
INFO, SHAPE, -
INFO, COMMENT, 10.23 mg eicosane
INFO, SEQUENCE FILE: JP_ZFC_MH_FC_210802_FeCl2btd_jedimu.seq


INFO, BACKGROUND DATA FILE:, None


STARTUPAXIS,X,4,LINEAR,AUTO,0.000000,0.000000
STARTUPAXIS,Y1,5,LINEAR,AUTO,0.000000,0.000000


STARTUPGROUP,Longitudinal
FIELDGROUP,Longitudinal,1,2,3,4,5,6,7,8,9,10,11,19,20,21,22,23,35
FIELDGROUP,Transverse,1,2,3,4,12,13,14,15,16,17,18,24,25,26,27,28,35

PLOT_APPEARANCE,ALL,HORZ_GRID_ON,VERT_GRID_ON,MARKERS_AND_LINES

[Data]
Time,Comment,Field (Oe),Temperature (K),Long Moment (emu),Long Scan Std Dev,Long Offset (cm),Long Offset Std Dev,Long Algorithm,Long Reg Fit,Long Reg Factor,Trans Moment (emu),Trans Scan Std Dev,Trans Offset (cm),Trans Offset Std Dev,Trans Algorithm,Trans Reg Fit,Trans Reg Factor,Long Moment [w/o ABS] (emu),Long Scan Std Dev [w/o ABS],Long Offset [w/o ABS] (cm),Long Offset Std Dev [w/o ABS],Long Reg Fit [w/o ABS],Trans Moment [w/o ABS] (emu),Trans Scan Std Dev [w/o ABS],Trans Offset [w/o ABS] (cm),Trans Offset Std Dev [w/o ABS],Trans Reg Fit [w/o ABS],RSO Position (deg),Amplitude (cm),Frequency,Cycles to Average,Scans per Measurement,Delta Temp (K),Error,EC Comp. Running,Using ABS,
1627915754.159,,1.000000e+002,2.001542e+000,1.846903e-003,3.376694e-005,3.323808e-002,2.827387e-004,3,9.899021e-001,1.825000e+000,,,,,,,,,,,,,,,,,,0,5.000000e+000,1.000000e+000,4,4,2.012968e-003,0,,0,
1627915949.877,,1.000000e+002,2.252213e+000,1.951905e-003,7.483242e-005,3.446274e-002,4.055809e-004,3,9.898723e-001,1.825000e+000,,,,,,,,,,,,,,,,,,0,5.000000e+000,1.000000e+000,4,4,3.642797e-003,0,,0,
1627916146.921,,1.000000e+002,2.502227e+000,2.186328e-003,1.273435e-004,3.573155e-002,7.109407e-004,3,9.898001e-001,1.825000e+000,,,,,,,,,,,,,,,,,,0,5.000000e+000,1.000000e+000,4,4,3.940821e-003,0,,0,
1627916354.526,,1.000000e+002,2.751842e+000,2.681023e-003,1.974094e-004,3.787671e-002,5.760521e-004,3,9.897907e-001,1.825000e+000,,,,,,,,,,,,,,,,,,0,5.000000e+000,1.000000e+000,4,4,4.527092e-003,0,,0,
1627916589.806,,1.000000e+002,3.001407e+000,3.327189e-003,2.200675e-004,3.869399e-002,1.329491e-004,3,9.898012e-001,1.825000e+000,,,,,,,,,,,,,,,,,,0,5.000000e+000,1.000000e+000,4,4,4.500151e-003,0,,0,
1627916880.731,,1.000000e+002,3.250911e+000,4.159282e-003,3.296321e-004,3.894246e-002,1.149986e-004,3,9.899065e-001,1.825000e+000,,,,,,,,,,,,,,,,,,0,5.000000e+000,1.000000e+000,4,4,5.174160e-003,0,,0,
1627917201.343,,1.000000e+002,3.509441e+000,5.120044e-003,3.608916e-004,3.895836e-002,1.202036e-004,3,9.899651e-001,1.825000e+000,,,,,,,,,,,,,,,,,,0,5.000000e+000,1.000000e+000,4,4,2.660298e-002,0,,0,
1627917468.790,,1.000000e+002,3.612695e+000,6.116411e-003,3.471290e-004,3.884278e-002,3.258174e-004,3,9.898394e-001,1.825000e+000,,,,,,,,,,,,,,,,,,0,5.000000e+000,1.000000e+000,4,4,2.330995e-002,0,,0,
1627917659.469,,1.000000e+002,3.708108e+000,7.064237e-003,2.134731e-004,3.928375e-002,1.594479e-004,3,9.901218e-001,1.825000e+000,,,,,,,,,,,,,,,,,,0,5.000000e+000,1.000000e+000,4,4,1.204300e-002,0,,0,
1627917852.800,,1.000000e+002,3.801959e+000,7.730318e-003,1.829792e-004,3.906628e-002,1.105730e-004,3,9.900849e-001,1.825000e+000,,,,,,,,,,,,,,,,,,0,5.000000e+000,1.000000e+000,4,4,1.060414e-002,0,,0,
1627918081.075,,1.000000e+002,3.903944e+000,8.393597e-003,1.899197e-004,3.863265e-002,1.816718e-004,3,9.902785e-001,1.825000e+000,,,,,,,,,,,,,,,,,,0,5.000000e+000,1.000000e+000,4,4,1.298308e-002,0,,0,
1627918313.952,,1.000000e+002,4.002937e+000,8.703749e-003,3.271392e-005,3.850162e-002,9.915968e-005,3,9.902398e-001,1.825000e+000,,,,,,,,,,,,,,,,,,0,5.000000e+000,1.000000e+000,4,4,1.327181e-002,0,,0,
1627918565.097,,1.000000e+002,4.098735e+000,8.633748e-003,6.864229e-005,3.849708e-002,5.870477e-005,3,9.900876e-001,1.825000e+000,,,,,,,,,,,,,,,,,,0,5.000000e+000,1.000000e+000,4,4,1.455402e-002,0,,0,
1627918821.546,,1.000000e+002,4.208140e+000,8.203222e-003,1.534132e-004,3.859958e-002,2.076776e-004,3,9.901937e-001,1.825000e+000,,,,,,,,,,,,,,,,,,0,5.000000e+000,1.000000e+000,4,4,1.641321e-002,0,,0,
1627919085.982,,1.000000e+002,4.309576e+000,7.577096e-003,1.949440e-004,3.858534e-002,2.060039e-004,3,9.901642e-001,1.825000e+000,,,,,,,,,,,,,,,,,,0,5.000000e+000,1.000000e+000,4,4,1.856995e-002,0,,0,
1627919249.611,,1.000000e+002,4.411007e+000,6.880813e-003,2.036082e-004,3.842269e-002,1.040103e-004,3,9.901481e-001,1.825000e+000,,,,,,,,,,,,,,,,,,0,5.000000e+000,1.000000e+000,4,4,4.664898e-003,0,,0,
1627919407.935,,1.000000e+002,4.503416e+000,6.225570e-003,1.869019e-004,3.835618e-002,6.355114e-005,3,9.902017e-001,1.825000e+000,,,,,,,,,,,,,,,,,,0,5.000000e+000,1.000000e+000,4,4,3.754139e-003,0,,0,
1627920728.103,,1.000000e+002,5.003829e+000,5.450267e-003,1.616221e-004,3.849974e-002,7.120929e-005,3,9.901738e-001,1.825000e+000,,,,,,,,,,,,,,,,,,0,5.000000e+000,1.000000e+000,4,4,2.885818e-003,0,,0,
1627920888.019,,1.000000e+002,6.003888e+000,4.347065e-003,1.742826e-004,3.828791e-002,1.355319e-004,3,9.901450e-001,1.825000e+000,,,,,,,,,,,,,,,,,,0,5.000000e+000,1.000000e+000,4,4,4.123211e-003,0,,0,
1627921052.428,,1.000000e+002,7.003679e+000,2.522527e-003,9.969410e-007,3.838826e-002,3.385996e-005,3,9.901394e-001,1.825000e+000,,,,,,,,,,,,,,,,,,0,5.000000e+000,1.000000e+000,4,4,3.523827e-003,0,,0,
1627921208.366,,1.000000e+002,8.001812e+000,2.155370e-003,1.506652e-006,3.825336e-002,7.338733e-005,3,9.902148e-001,1.825000e+000,,,,,,,,,,,,,,,,,,0,5.000000e+000,1.000000e+000,4,4,6.067753e-003,0,,0,
1627921362.915,,1.000000e+002,8.999787e+000,1.871478e-003,1.189805e-006,3.816464e-002,7.288227e-005,3,9.902749e-001,1.825000e+000,,,,,,,,,,,,,,,,,,0,5.000000e+000,1.000000e+000,4,4,8.636475e-003,0,,0,
1627921520.070,,1.000000e+002,9.999625e+000,1.672518e-003,4.193022e-007,3.822495e-002,1.112541e-004,3,9.901857e-001,1.825000e+000,,,,,,,,,,,,,,,,,,0,5.000000e+000,1.000000e+000,4,4,3.267288e-003,0,,0,
1627921636.228,,1.000000e+002,1.199799e+001,1.395192e-003,3.931893e-007,3.813967e-002,1.252455e-004,3,9.902700e-001,1.825000e+000,,,,,,,,,,,,,,,,,,0,5.000000e+000,1.000000e+000,4,4,9.002686e-004,0,,0,
1627921799.342,,1.000000e+002,1.401030e+001,1.202828e-003,2.025164e-007,3.827527e-002,1.458776e-004,3,9.901910e-001,1.825000e+000,,,,,,,,,,,,,,,,,,0,5.000000e+000,1.000000e+000,4,4,5.009651e-003,0,,0,
1627921955.841,,1.000000e+002,1.599351e+001,1.058877e-003,1.867545e-007,3.833135e-002,2.665777e-005,3,9.902508e-001,1.825000e+000,,,,,,,,,,,,,,,,,,0,5.000000e+000,1.000000e+000,4,4,5.490303e-003,0,,0,
1627922124.228,,1.000000e+002,1.799497e+001,9.457979e-004,1.084738e-007,3.843936e-002,2.080771e-005,3,9.902940e-001,1.825000e+000,,,,,,,,,,,,,,,,,,0,5.000000e+000,1.000000e+000,4,4,4.339218e-003,0,,0,
1627922282.287,,1.000000e+002,1.999339e+001,8.551715e-004,1.623210e-007,3.872890e-002,7.621176e-005,3,9.903175e-001,1.825000e+000,,,,,,,,,,,,,,,,,,0,5.000000e+000,1.000000e+000,4,4,5.350113e-003,0,,0,
1627922441.407,,1.000000e+002,2.497595e+001,6.923429e-004,1.416705e-007,3.922176e-002,1.204558e-004,3,9.902864e-001,1.825000e+000,,,,,,,,,,,,,,,,,,0,5.000000e+000,1.000000e+000,4,4,1.550102e-002,0,,0,
1627922622.586,,1.000000e+002,3.000170e+001,5.817956e-004,1.020578e-007,3.982398e-002,1.228512e-004,3,9.902331e-001,1.825000e+000,,,,,,,,,,,,,,,,,,0,5.000000e+000,1.000000e+000,4,4,2.309799e-003,0,,0,
1627922822.282,,1.000000e+002,3.500593e+001,5.032359e-004,1.028552e-007,4.044435e-002,6.960988e-004,3,9.903542e-001,1.825000e+000,,,,,,,,,,,,,,,,,,0,5.000000e+000,1.000000e+000,4,4,3.078461e-003,0,,0,
1627923040.230,,1.000000e+002,4.000842e+001,4.450126e-004,6.290512e-008,4.195288e-002,1.456144e-004,3,9.901939e-001,1.825000e+000,,,,,,,,,,,,,,,,,,0,5.000000e+000,1.000000e+000,4,4,5.958557e-003,0,,0,
1627923263.217,,1.000000e+002,4.501627e+001,3.993962e-004,7.306570e-008,4.391763e-002,8.654773e-005,3,9.902898e-001,1.825000e+000,,,,,,,,,,,,,,,,,,0,5.000000e+000,1.000000e+000,4,4,1.294327e-002,0,,0,
1627923464.504,,1.000000e+002,5.004296e+001,3.628150e-004,8.592285e-008,4.521281e-002,1.135233e-004,3,9.902999e-001,1.825000e+000,,,,,,,,,,,,,,,,,,0,5.000000e+000,1.000000e+000,4,4,2.919769e-002,0,,0,
1627923704.198,,1.000000e+002,6.007501e+001,3.075755e-004,7.371029e-008,4.779492e-002,3.871712e-005,3,9.901196e-001,1.825000e+000,,,,,,,,,,,,,,,,,,0,5.000000e+000,1.000000e+000,4,4,4.819107e-002,0,,0,
1627923965.624,,1.000000e+002,7.008516e+001,2.678449e-004,6.500991e-008,4.827018e-002,9.043504e-005,3,9.899116e-001,1.825000e+000,,,,,,,,,,,,,,,,,,0,5.000000e+000,1.000000e+000,4,4,5.980682e-002,0,,0,
1627924224.459,,1.000000e+002,8.012544e+001,2.386435e-004,6.688526e-008,5.060227e-002,1.633322e-005,3,9.898967e-001,1.825000e+000,,,,,,,,,,,,,,,,,,0,5.000000e+000,1.000000e+000,4,4,7.141876e-002,0,,0,
1627924486.477,,1.000000e+002,9.016051e+001,2.160091e-004,5.202189e-008,5.360393e-002,1.567870e-004,3,9.897629e-001,1.825000e+000,,,,,,,,,,,,,,,,,,0,5.000000e+000,1.000000e+000,4,4,8.895111e-002,0,,0,
1627924749.026,,1.000000e+002,1.001908e+002,1.980849e-004,5.571577e-008,5.692569e-002,1.165689e-004,3,9.896855e-001,1.825000e+000,,,,,,,,,,,,,,,,,,0,5.000000e+000,1.000000e+000,4,4,1.134949e-001,0,,0,
1627925010.202,,1.000000e+002,1.102205e+002,1.834319e-004,8.166931e-008,6.111815e-002,8.774659e-005,3,9.896386e-001,1.825000e+000,,,,,,,,,,,,,,,,,,0,5.000000e+000,1.000000e+000,4,4,1.299973e-001,0,,0,
1627925271.767,,1.000000e+002,1.202412e+002,1.710699e-004,4.585329e-008,6.471693e-002,5.675213e-005,3,9.895958e-001,1.825000e+000,,,,,,,,,,,,,,,,,,0,5.000000e+000,1.000000e+000,4,4,1.466980e-001,0,,0,
1627925539.401,,1.000000e+002,1.302239e+002,1.607940e-004,7.553944e-008,6.852210e-002,8.000815e-005,3,9.896070e-001,1.825000e+000,,,,,,,,,,,,,,,,,,0,5.000000e+000,1.000000e+000,4,4,1.670990e-001,0,,0,
1627925796.022,,1.000000e+002,1.402861e+002,1.519202e-004,8.624342e-008,7.243964e-002,8.145520e-005,3,9.894862e-001,1.825000e+000,,,,,,,,,,,,,,,,,,0,5.000000e+000,1.000000e+000,4,4,1.882935e-001,0,,0,
1627926049.351,,1.000000e+002,1.503148e+002,1.442810e-004,5.851830e-008,7.624954e-002,3.679954e-005,3,9.893856e-001,1.825000e+000,,,,,,,,,,,,,,,,,,0,5.000000e+000,1.000000e+000,4,4,2.100983e-001,0,,0,
1627926301.291,,1.000000e+002,1.603221e+002,1.375982e-004,6.234132e-008,8.047428e-002,1.453893e-004,3,9.890423e-001,1.825000e+000,,,,,,,,,,,,,,,,,,0,5.000000e+000,1.000000e+000,4,4,2.321930e-001,0,,0,
1627926550.049,,1.000000e+002,1.703550e+002,1.317002e-004,8.291843e-008,8.467516e-002,4.683359e-005,3,9.890188e-001,1.825000e+000,,,,,,,,,,,,,,,,,,0,5.000000e+000,1.000000e+000,4,4,2.303009e-001,0,,0,
1627926795.937,,1.000000e+002,1.803732e+002,1.264332e-004,5.951402e-008,8.889630e-002,1.869043e-004,3,9.889160e-001,1.825000e+000,,,,,,,,,,,,,,,,,,0,5.000000e+000,1.000000e+000,4,4,2.507935e-001,0,,0,
1627927040.420,,1.000000e+002,1.903850e+002,1.216810e-004,4.239530e-008,9.349318e-002,1.807408e-004,3,9.887820e-001,1.825000e+000,,,,,,,,,,,,,,,,,,0,5.000000e+000,1.000000e+000,4,4,2.713928e-001,0,,0,
1627927283.032,,1.000000e+002,2.004013e+002,1.173719e-004,4.125373e-008,9.820918e-002,1.093185e-004,3,9.885365e-001,1.825000e+000,,,,,,,,,,,,,,,,,,0,5.000000e+000,1.000000e+000,4,4,2.919006e-001,0,,0,
1627927523.007,,1.000000e+002,2.104241e+002,1.134437e-004,5.091932e-008,1.033946e-001,6.186520e-005,3,9.884223e-001,1.825000e+000,,,,,,,,,,,,,,,,,,0,5.000000e+000,1.000000e+000,4,4,3.126068e-001,0,,0,
1627927762.280,,1.000000e+002,2.204329e+002,1.099031e-004,4.664348e-008,1.087858e-001,1.423096e-004,3,9.879454e-001,1.825000e+000,,,,,,,,,,,,,,,,,,0,5.000000e+000,1.000000e+000,4,4,3.332062e-001,0,,0,
1627928001.756,,1.000000e+002,2.304312e+002,1.066657e-004,3.928212e-008,1.141938e-001,1.727058e-004,3,9.878293e-001,1.825000e+000,,,,,,,,,,,,,,,,,,0,5.000000e+000,1.000000e+000,4,4,3.303986e-001,0,,0,
1627928239.594,,1.000000e+002,2.404506e+002,1.036565e-004,6.973840e-008,1.199010e-001,1.757087e-004,3,9.875985e-001,1.825000e+000,,,,,,,,,,,,,,,,,,0,5.000000e+000,1.000000e+000,4,4,3.603058e-001,0,,0,
1627928471.863,,1.000000e+002,2.505166e+002,1.008545e-004,6.033253e-008,1.259135e-001,1.422398e-004,3,9.873093e-001,1.825000e+000,,,,,,,,,,,,,,,,,,0,5.000000e+000,1.000000e+000,4,4,3.781891e-001,0,,0,
1627928708.375,,1.000000e+002,2.604890e+002,9.829780e-005,5.226153e-008,1.322916e-001,1.464225e-004,3,9.869693e-001,1.825000e+000,,,,,,,,,,,,,,,,,,0,5.000000e+000,1.000000e+000,4,4,3.801880e-001,0,,0,
1627928944.700,,1.000000e+002,2.704937e+002,9.591439e-005,3.168792e-008,1.396033e-001,4.341041e-004,3,9.866327e-001,1.825000e+000,,,,,,,,,,,,,,,,,,0,5.000000e+000,1.000000e+000,4,4,4.042969e-001,0,,0,
1627929181.212,,1.000000e+002,2.805053e+002,9.389601e-005,3.197426e-008,1.479121e-001,8.347655e-005,3,9.860729e-001,1.825000e+000,,,,,,,,,,,,,,,,,,0,5.000000e+000,1.000000e+000,4,4,3.772888e-001,0,,0,
1627929419.315,,1.000000e+002,2.904909e+002,9.212730e-005,1.904050e-008,1.584860e-001,1.915819e-004,3,9.855289e-001,1.825000e+000,,,,,,,,,,,,,,,,,,0,5.000000e+000,1.000000e+000,4,4,3.975830e-001,0,,0,
1627929657.684,,1.000000e+002,3.004827e+002,9.042584e-005,6.308644e-008,1.714204e-001,1.115003e-004,3,9.844236e-001,1.825000e+000,,,,,,,,,,,,,,,,,,0,5.000000e+000,1.000000e+000,4,4,4.076843e-001,0,,0,