File: MPMS/NiCl2pym/NiCl2pym_MvH_3K_14T.dat
[Header]
; ACMS II Data File (default extension .dat)
; Copyright (c) 2014, Quantum Design, Inc. All rights reserved.
TITLE,
FILEOPENTIME,3875339809.840,10/19/2022,11:17 am
BYAPP,ACMS II,1.0,1.2
INFO,DYNACOOL ACMS II Option Release 1.0.8 Build 33,APPNAME
INFO,Quantum Design Linear Motor Servo Controller,MOTOR_MODULE_NAME
INFO,3101-100 K0,MOTOR_HW_VERSION
INFO,MMC794,MOTOR_SERIAL_NUMBER
INFO,SRV No X-over 01.03.11,MOTOR_SOFTWARE_VERSION
INFO,ACMS,ACMS_MODULE_NAME
INFO,3101-430 A0,ACMS_HW_VERSION
INFO,ACMSII028,ACMS_SERIAL_NUMBER
INFO,00.14.14,ACMS_SOFTWARE_VERSION
INFO,WF046,COIL_SERIAL_NUMBER
INFO,0,MOMENT_UNITS
INFO,NiCl2pym,SAMPLE_MATERIAL
INFO,7.3mg cling film,SAMPLE_COMMENT
INFO,17.2,SAMPLE_MASS
INFO,,SAMPLE_VOLUME
INFO,,SAMPLE_MOLECULAR_WEIGHT
INFO,,SAMPLE_SIZE
INFO,,SAMPLE_SHAPE
DATATYPE,COMMENT,1
DATATYPE,TIME,2
STARTUPAXIS,X,2
STARTUPAXIS,Y1,5
STARTUPGROUP, AC
FIELDGROUP, AC, 2,3,4,5,6,7,8,9,10,11,12,13,14,15,16,20,21,22,23,24,25,35,43,44,45,46,47,48,49
FIELDGROUP, DC, 2,3,4,17,18,19,20,21,23,24,25,35,36,37,43,44,45,46,47,48,49,50,51
FIELDGROUP, Diagnostic, 26,27,28,29,30,31,32,33,34,38,39,40,41,42,52,53,54,55,56,57,58,59,60,61,62,63,64,65,66,67,68,69
[Data]
Comment,Time Stamp (sec),Temperature (K),Magnetic Field (Oe),AC Moment (emu),AC Std. Dev. (emu),AC Phase (deg),AC Phase Std. Dev. (deg),AC Suscept. (emu/Oe),AC Suscept. Std. Dev. (emu/Oe),AC X'  (emu/Oe),AC X" (emu/Oe),AC X' Std. Dev. (emu/Oe),AC X" Std. Dev. (emu/Oe),AC Drive (Oe),AC Frequency (Hz),DC Moment (emu),DC Std. Err. (emu),DC Quad. Moment (emu),Range (mV),"AC=1 DC=2 Locate=3",Measure Type,Measure Count,Measure Time (sec),Measure Number,AC X' Raw (emu/Oe),AC X" Raw (emu/Oe),DC M. Raw' (emu),DC M. Raw" (emu),Coil InPhase (V),Coil Quadrature (V),Null Status,Trim Ratio,Trim Phase (deg.),Max. Signal (mV),Motor Frequency (Hz),Motor Ampl. (mm),System Temp. (K),Min. Temperature (K),Max. Temperature (K),Min. Field (Oe),Max. Field (Oe),Pressure (Torr),Temp. Status (code),Field Status (code),Chamber Status (code),Measure Status (code),Center Position (mm),Transport Action,Motor Lag (deg),Motor Current (amps),Motor Heatsink Temp. (C),Motor Board Temp. (C),QMap 01,QMap 02,QMap 03,QMap 04,QMap 05,QMap 06,QMap 07,QMap 08,QMap 09,QMap 10,QMap 11,QMap 12,QMap 13,QMap 14,QMap 15,QMap 16
sample offset = 27.08 mm,3875341672.96894,3.00234065055847,0.640305489301682,,,,,,,,,,,,,-4.94792188563013E-5,8.95058898750924E-7,6.28421697439995E-7,1,2,,80,2,1,,,-4.7655732030096E-5,3.60306233627308E-7,-2.93920891181187E-7,9.91289965668329E-8,,,,1.21198653902442E-5,39.995735168457,2.00921242343474,3.00377726554871,3.0017511844635,3.002610206604,0.586946725845337,0.693664252758026,0.0949041321873665,1,4,3,4,23.3230000458956,1,20.6809892604875,1.1285400390625,30.3030319213867,31.2805480957031,,,,,,,,,,,,,,,,
,3875341820.2875,3.00036495923996,1599.70684814453,,,,,,,,,,,,,0.00442858585318575,9.89321299253812E-6,-1.03499327393825E-5,1,2,,80,2,70,,,0.00426526234934465,1.24239881306276E-5,2.62050871242536E-5,-9.15242253540782E-6,,,,0.0010878143243828,39.995735168457,2.00890467054821,3.00079774856567,3.00025653839111,3.0005042552948,1544.83190917969,1654.58178710938,0.0963375419378281,1,6,3,4,23.3230000458956,1,20.6958362891891,1.12640380859375,39.1006851196289,32.2580642700195,,,,,,,,,,,,,,,,
,3875341966.73192,3.00108594894409,8919.96875,,,,,,,,,,,,,0.026471280748001,1.06375336352543E-5,-4.62456585797646E-5,1,2,,80,2,139,,,0.0254999497142053,0.000108482953172652,0.000156568552483805,-5.49412070540711E-5,,,,0.0065007689625639,39.995735168457,2.00865048274907,2.99796080589294,3.0010232925415,3.00126099586487,8867.4580078125,8972.4794921875,0.0964408665895462,1,6,3,4,23.3230000458956,1,20.703044798531,1.12739562988281,40.5669593811035,33.7243423461914,,,,,,,,,,,,,,,,
,3875342112.39169,3.00137224197388,16203.203125,,,,,,,,,,,,,0.0477322122695788,1.12235982693335E-5,-5.19002827215084E-5,1,2,,80,2,208,,,0.0459928251750057,0.000266774790216858,0.000282256456557661,-9.95423179119825E-5,,,,0.0117266786071565,39.995735168457,2.0087651335743,2.99420118331909,3.00123047828674,3.00152325630188,16153.138671875,16253.267578125,0.0963380336761475,1,6,3,4,23.3230000458956,1,20.7040898186757,1.12762451171875,41.5444793701172,35.190616607666,,,,,,,,,,,,,,,,
,3875342256.79183,3.00102777481079,23434.2255859375,,,,,,,,,,,,,0.0685159095432568,1.290919034685E-5,-3.64783777490675E-5,1,2,,80,2,277,,,0.0660406227226879,0.000482105628848803,0.000405069877160713,-0.000143527169711888,,,,0.0168378913773394,39.995735168457,2.00870526099511,2.99040627479553,3.00092172622681,3.00112891197205,23384.166015625,23484.28515625,0.0961530134081841,1,6,3,4,23.3230000458956,1,20.702745093866,1.12777709960938,42.0332374572754,36.1681327819824,,,,,,,,,,,,,,,,
,3875342400.34768,3.00090961456299,30634.947265625,,,,,,,,,,,,,0.0900799769741865,1.42589476644233E-5,5.58446076331655E-5,10,2,,80,2,347,,,0.086858706381971,0.000818906009270808,0.000529186276253313,-0.000188839927432127,,,,0.0220154640761102,39.995735168457,1.99649729443045,2.98710870742798,3.00083637237549,3.00098395347595,30584.849609375,30685.044921875,0.0960130840539932,1,6,3,4,23.3230000458956,1,20.7091497492817,1.12899780273438,42.0332374572754,37.1456527709961,,,,,,,,,,,,,,,,
,3875342541.84037,3.00044441223145,37730.958984375,,,,,,,,,,,,,0.115142540245186,1.8779164258804E-5,0.000103580130664216,10,2,,80,2,416,,,0.111074210884564,0.00118675023880124,0.00067639775807038,-0.000242359194089659,,,,0.0281534973543976,39.995735168457,1.99644607416602,2.98580050468445,3.00041341781616,3.00052046775818,37680.7578125,37781.16015625,0.0959663614630699,1,6,3,4,23.3230000458956,1,20.7112983244935,1.12007141113281,42.5219955444336,37.6344108581543,,,,,,,,,,,,,,,,
,3875342683.30803,2.99994707107544,44822.568359375,,,,,,,,,,,,,0.148801742095522,2.23854066546805E-5,0.000184884744431727,10,2,,80,2,485,,,0.143616145478058,0.00172407596464302,0.00087420322233811,-0.000314462115056813,,,,0.0364023520004712,39.995735168457,1.99648204041559,2.9858067035675,2.99986958503723,3.00000715255737,44769.96484375,44875.171875,0.0960325375199318,1,6,3,4,23.3230000458956,1,20.70691781961,1.12083435058594,42.5219955444336,37.6344108581543,,,,,,,,,,,,,,,,
,3875342824.7497,2.99960060119629,51915.357421875,,,,,,,,,,,,,0.180908621266947,2.25333010670357E-5,0.000203277720834695,10,2,,80,2,554,,,0.174702807943346,0.00224561100339312,0.00106309249531478,-0.000383438251446933,,,,0.0442811805633246,39.995735168457,1.99644267108343,2.98636174201965,2.9994900226593,2.99972009658814,51865.171875,51965.54296875,0.0959695056080818,1,6,3,4,23.3230000458956,1,20.7074217204451,1.12037658691406,42.5219955444336,37.6344108581543,,,,,,,,,,,,,,,,
,3875342966.22295,2.99938530921936,59011.103515625,,,,,,,,,,,,,0.206949370676665,2.11625277367831E-5,0.00023492852289864,10,2,,80,2,623,,,0.199974228809543,0.00276259074152511,0.00121655769180506,-0.000440032017650083,,,,0.0506895977475492,39.995735168457,1.99655361215637,2.98788833618164,2.99930500984192,2.99946331977844,58960.95703125,59061.25,0.0960420593619347,1,6,3,4,23.3230000458956,1,20.7041080241995,1.11862182617188,42.5219955444336,37.6344108581543,,,,,,,,,,,,,,,,
,3875343107.68522,2.99922233819962,66103.98828125,,,,,,,,,,,,,0.229856712847413,1.95989959593837E-5,0.000205902414223445,10,2,,80,2,692,,,0.222259773680836,0.00322209452634141,0.00135153683368117,-0.000490029866341502,,,,0.0563290326775736,39.995735168457,1.99620100816846,2.98918724060059,2.99907326698303,2.99936175346375,66051.3125,66156.6640625,0.0961063951253891,1,6,3,4,23.3230000458956,1,20.7090835698333,1.12190246582031,43.0107536315918,38.6119270324707,,,,,,,,,,,,,,,,
,3875343249.15934,2.9994017124176,73197.0703125,,,,,,,,,,,,,0.256984833856035,1.97622840585482E-5,0.000157442849838156,10,2,,80,2,761,,,0.248671980394789,0.00375528865821746,0.00151204620487988,-0.00054907874437049,,,,0.0630303647727644,39.995735168457,1.99641669612968,2.99113941192627,2.99931383132935,2.99948120117188,73146.921875,73247.21875,0.0961363911628723,1,6,3,4,23.3230000458956,1,20.7030110024473,1.1199951171875,43.0107536315918,38.6119270324707,,,,,,,,,,,,,,,,
,3875343390.63663,2.9995025396347,80328.48046875,,,,,,,,,,,,,0.286467098828568,2.09631079547407E-5,0.000120332687871678,10,2,,80,2,830,,,0.27741557230951,0.00437228997710999,0.00168646278325468,-0.000613615906331688,,,,0.0703171347880352,39.995735168457,1.9964286089155,2.99262404441833,2.99942064285278,2.99964880943298,80277.765625,80379.1953125,0.0961404293775559,1,6,3,4,23.3230000458956,1,20.7012542709862,1.11946105957031,43.0107536315918,38.6119270324707,,,,,,,,,,,,,,,,
,3875343532.105,2.99957766532898,87501.96875,,,,,,,,,,,,,0.314803646713102,1.67557122729982E-5,-1.35410672091193E-5,10,2,,80,2,899,,,0.305108586297342,0.00491497670197022,0.00185460585635155,-0.000675491348374635,,,,0.0773374544833938,39.995735168457,1.99643483349718,2.9938313961029,2.99949550628662,2.99967169761658,87451.34375,87552.59375,0.0961364284157753,1,6,3,4,23.3230000458956,1,20.7003236387562,1.11953735351562,43.0107536315918,40.0782012939453,,,,,,,,,,,,,,,,
,3875343673.57717,3.00001645088196,94676.2734375,,,,,,,,,,,,,0.341549891889335,2.52540085942688E-5,-0.00015186137487019,10,2,,80,2,968,,,0.331316403602874,0.00545637472193328,0.00201368355192244,-0.000734261004254222,,,,0.0839829535713645,39.995735168457,1.99646361672629,2.99443817138672,2.99983954429626,3.00012135505676,94625.6484375,94726.8984375,0.096203438937664,1,6,3,4,23.3230000458956,1,20.7005546007104,1.11984252929688,43.0107536315918,39.1006851196289,,,,,,,,,,,,,,,,
,3875343815.02933,2.99989190101624,101847.82421875,,,,,,,,,,,,,0.366898694348507,2.57101488524952E-5,-0.000349076321181836,10,2,,80,2,1037,,,0.356224031763184,0.00593832942590026,0.00216475082561374,-0.00078985036816448,,,,0.0902904981447736,39.995735168457,1.99631098550623,2.99419069290161,2.99973964691162,3.00005507469177,101794.890625,101900.7578125,0.0962149426341057,1,6,3,4,23.3230000458956,1,20.7008091208996,1.119384765625,43.0107536315918,39.1006851196289,,,,,,,,,,,,,,,,
,3875343956.50466,3.00028581619263,109019.30859375,,,,,,,,,,,,,0.391018733240682,3.00203389174993E-5,-0.00050794732213155,10,2,,80,2,1106,,,0.379990483847535,0.00645067838448875,0.00230877171270549,-0.000843253452330828,,,,0.096308588718536,39.995735168457,1.99618442429097,2.99377822875977,3.00020313262939,3.00042748451233,108968.6640625,109069.953125,0.0961343720555305,1,6,3,4,23.3230000458956,1,20.7020081011618,1.11991882324219,43.49951171875,39.1006851196289,,,,,,,,,,,,,,,,
,3875344097.97242,3.00069632530212,116194.5859375,,,,,,,,,,,,,0.414095949635615,3.30686147933362E-5,-0.000710981116548313,10,2,,80,2,1175,,,0.402794599697564,0.00691007261452171,0.00244724401272833,-0.000894393946509808,,,,0.102092389858292,39.995735168457,1.99626138457434,2.99250817298889,3.00045418739319,3.00089502334595,116143.8671875,116245.3046875,0.0960257425904274,1,6,3,4,23.3230000458956,1,20.7034008679648,1.11953735351562,43.9882698059082,39.1006851196289,,,,,,,,,,,,,,,,
,3875344239.44939,3.00106625556946,123366.06640625,,,,,,,,,,,,,0.436092284514904,3.67054740339064E-5,-0.000890202259049791,10,2,,80,2,1244,,,0.424593978222591,0.00737574323918075,0.00257941987365484,-0.000943258637562394,,,,0.107614079775202,39.995735168457,1.99618267704905,2.98975253105164,3.0009593963623,3.00122690200806,123313.046875,123419.0859375,0.0959843099117279,1,6,3,4,23.3230000458956,1,20.7019721864196,1.12022399902344,43.49951171875,39.1006851196289,,,,,,,,,,,,,,,,
,3875344380.91882,3.00112009048462,130541.15625,,,,,,,,,,,,,0.457412846564917,4.10825731317155E-5,-0.00115091230936916,10,2,,80,2,1313,,,0.445781480579655,0.00774790041206216,0.00270820711739361,-0.000990344095043838,,,,0.112987820718536,39.995735168457,1.9962346350649,2.98694634437561,3.00107145309448,3.00114464759827,130487.90625,130594.40625,0.0959068015217781,1,6,3,4,23.3230000458956,1,20.7012531634115,1.11923217773438,43.49951171875,39.1006851196289,,,,,,,,,,,,,,,,
,3875344522.37477,3.00131664276123,137714.21875,,,,,,,,,,,,,0.477863478545116,4.04282231415657E-5,-0.0013144970994517,10,2,,80,2,1382,,,0.466160397608821,0.008192356000811,0.00283176801167428,-0.00103604781907052,,,,0.118150898705373,39.995735168457,1.99617197571052,2.98318839073181,3.00115036964417,3.00147986412048,137663.5,137764.9375,0.0957408845424652,1,6,3,4,23.3230000458956,1,20.6994363640354,1.12014770507812,43.49951171875,38.6119270324707,,,,,,,,,,,,,,,,
,3875344663.84263,2.99998559951782,140000.5859375,,,,,,,,,,,,,0.484395682619392,3.5005622850274E-5,-0.00141370878223905,10,2,,80,2,1451,,,0.472678515885239,0.00828670665823245,0.00287104374729097,-0.00105053163133562,,,,0.119791873590154,39.995735168457,1.99597220866941,2.98064875602722,2.99989986419678,3.00008010864258,140000.53125,140000.640625,0.0957148671150207,1,4,3,4,23.3230000458956,1,20.7038932219203,1.11831665039062,44.4770278930664,40.0782012939453,,,,,,,,,,,,,,,,
,3875344805.30232,2.99882001876831,134415.0625,,,,,,,,,,,,,0.469500699152952,3.12316854033517E-5,-0.00124476862742714,10,2,,80,2,1520,,,0.457799767556171,0.00800393921951229,0.00278112594969571,-0.00101709668524563,,,,0.116032514635041,39.995735168457,1.99618221748807,2.9827287197113,2.99876999855041,2.99889850616455,134363.078125,134467.046875,0.0957998260855675,1,6,3,4,23.3230000458956,1,20.6969422879482,1.12052917480469,43.49951171875,39.1006851196289,,,,,,,,,,,,,,,,
,3875344946.7689,2.99891390800476,127415.2890625,,,,,,,,,,,,,0.450291802337337,6.28958040664721E-5,-0.00103639430544877,10,2,,80,2,1589,,,0.438657014383121,0.00762871239809762,0.00266487360931933,-0.000974528666120023,,,,0.111180780848348,39.995735168457,1.99620276592384,2.98650026321411,2.99888777732849,2.99893951416016,127363.375,127467.203125,0.096080832183361,1,6,3,4,23.3230000458956,1,20.7012330554245,1.11984252929688,43.49951171875,39.5894432067871,,,,,,,,,,,,,,,,
,3875345088.24292,2.99925785064697,120416.2890625,,,,,,,,,,,,,0.429971194154351,2.99781757453973E-5,-0.000842808079508662,10,2,,80,2,1658,,,0.418470489692323,0.00721319874736584,0.002542290603742,-0.000929337868001312,,,,0.106060815299467,39.995735168457,1.9961556167911,2.98904824256897,2.99906969070435,2.99934220314026,120364.375,120468.203125,0.0961789786815643,1,6,3,4,23.3230000458956,1,20.7028399973964,1.12030029296875,43.49951171875,39.5894432067871,,,,,,,,,,,,,,,,
,3875345229.73617,2.99935781955719,113419.47265625,,,,,,,,,,,,,0.408899379563334,2.55927273557834E-5,-0.000645260029972728,10,2,,80,2,1727,,,0.397594908687375,0.00678691320304382,0.00241567171178758,-0.000882664986420423,,,,0.100772613847923,39.995735168457,1.99622878291183,2.99138855934143,2.99928522109985,2.99942064285278,113369.90625,113469.0390625,0.0961998030543327,1,6,3,4,23.3230000458956,1,20.7043123256162,1.12838745117188,43.49951171875,39.5894432067871,,,,,,,,,,,,,,,,
,3875345371.18781,2.99950461387634,106421.27734375,,,,,,,,,,,,,0.386858091291581,2.56139126416183E-5,-0.000444905345755047,10,2,,80,2,1796,,,0.375821236521009,0.00634937394711262,0.00228325463831425,-0.000833689700812101,,,,0.0952405837018678,39.995735168457,1.99595105240587,2.99361133575439,2.99940824508667,2.99956297874451,106369.421875,106473.1328125,0.0962689220905304,1,6,3,4,23.3230000458956,1,20.7012601768138,1.11892700195312,43.49951171875,39.5894432067871,,,,,,,,,,,,,,,,
,3875345512.65307,2.99959027767181,99421.32421875,,,,,,,,,,,,,0.36354935673672,2.28329946614846E-5,-0.000295775872888391,10,2,,80,2,1865,,,0.352864483621848,0.00584854588442013,0.00214448478072882,-0.000782305374741554,,,,0.0894432313050393,39.995735168457,1.99641074239047,2.99432468414307,2.99943113327026,2.99971795082092,99369.2421875,99473.40625,0.0964803919196129,1,6,3,4,23.3230000458956,1,20.7027427545396,1.12037658691406,43.49951171875,39.5894432067871,,,,,,,,,,,,,,,,
,3875345654.10714,3.00015840530396,92423.859375,,,,,,,,,,,,,0.338823751098294,2.38514880542794E-5,-0.000163339402420661,10,2,,80,2,1934,,,0.328582776564584,0.00532231555995041,0.00199720426462591,-0.000727704726159573,,,,0.0832891365827809,39.995735168457,1.99643082186574,2.99457478523254,3.00011777877808,3.00021934509277,92374.4453125,92473.2734375,0.0964348614215851,1,6,3,4,23.3230000458956,1,20.7022159248008,1.11839294433594,43.49951171875,39.5894432067871,,,,,,,,,,,,,,,,
,3875345795.59343,3.00033640861511,85423.53125,,,,,,,,,,,,,0.312497000937497,1.45133177963886E-5,-1.52140033690307E-5,10,2,,80,2,2003,,,0.302799989091144,0.00480639537017599,0.00184062228072435,-0.000670063891448081,,,,0.0767510863049874,39.995735168457,1.99637788041897,2.99403309822082,3.00028681755066,3.0003867149353,85374.3125,85472.75,0.0964589640498161,1,6,3,4,23.3230000458956,1,20.7046408197099,1.12083435058594,43.49951171875,39.5894432067871,,,,,,,,,,,,,,,,
,3875345937.06871,3.00035375356674,78424.3359375,,,,,,,,,,,,,0.284444649482281,2.08028958839737E-5,9.91077517730845E-5,10,2,,80,2,2072,,,0.27539935519799,0.00425929606705341,0.0016743642045185,-0.000608832982834429,,,,0.0698084578119954,39.995735168457,1.996482028564,2.99325585365295,3.00019240379334,3.00065612792969,78374.859375,78473.8125,0.0965240299701691,1,6,3,4,23.3230000458956,1,20.7066363306653,1.12716674804688,43.49951171875,39.5894432067871,,,,,,,,,,,,,,,,
,3875346078.53768,3.00065793991089,71426.46484375,,,,,,,,,,,,,0.255500395989156,2.63810899274983E-5,0.000159533943473222,10,2,,80,2,2141,,,0.247189812929666,0.003681914788079,0.00150315125938505,-0.000545634713489562,,,,0.0626572336097223,39.995735168457,1.99648927673292,2.99247646331787,3.00062203407288,3.00070786476135,71374.5546875,71478.375,0.096464715898037,1,6,3,4,23.3230000458956,1,20.7076219958569,1.11862182617188,43.49951171875,39.1006851196289,,,,,,,,,,,,,,,,
,3875346220.01171,3.00079739093781,64428.845703125,,,,,,,,,,,,,0.232329074896998,2.27496204366773E-5,0.000190293856306798,10,2,,80,2,2210,,,0.224613895434747,0.0031907310484644,0.00136616232339293,-0.000494956271722913,,,,0.0569343832180446,39.995735168457,1.99649352120432,2.99052572250366,3.00072407722473,3.00087380409241,64379.4140625,64478.27734375,0.0964539051055908,1,6,3,4,23.3230000458956,1,20.7118331864167,1.12052917480469,43.49951171875,39.5894432067871,,,,,,,,,,,,,,,,
,3875346361.45306,3.00064463615417,57429.994140625,,,,,,,,,,,,,0.21426446428971,2.26220342608449E-5,0.000218968680487576,10,2,,80,2,2279,,,0.207013472677013,0.00279303296648595,0.00125944695901126,-0.000455258443253115,,,,0.0524731880120018,39.995735168457,1.99652013895858,2.989173412323,3.00054907798767,3.00075793266296,57380.44140625,57479.546875,0.0963955223560333,1,6,3,4,23.3230000458956,1,20.7110579278924,1.11991882324219,43.49951171875,39.5894432067871,,,,,,,,,,,,,,,,
,3875346502.92458,3.00028800964355,50432.892578125,,,,,,,,,,,,,0.196493962413685,2.03174998644968E-5,0.000230191656248311,10,2,,80,2,2348,,,0.189730156587125,0.00240970768817979,0.00115455070044845,-0.000416402181144804,,,,0.0480903964173816,39.995735168457,1.99645923166991,2.98776721954346,3.00019240379334,3.0003833770752,50381.046875,50484.73828125,0.096355751156807,1,6,3,4,23.3230000458956,1,20.7151697339619,1.12968444824219,43.49951171875,39.5894432067871,,,,,,,,,,,,,,,,
,3875346644.40459,3.00040326118469,43433.826171875,,,,,,,,,,,,,0.17892278359718,1.78039865396998E-5,0.000195469586583112,10,2,,80,2,2417,,,0.172669891006962,0.00201397578323603,0.00105104979593307,-0.000377902440959588,,,,0.0437642164861004,39.995735168457,1.99637116814259,2.98699307441711,3.00018167495728,3.00064706802368,43381.82421875,43485.828125,0.0964681953191757,1,6,3,4,23.3230000458956,1,20.718071495789,1.11991882324219,43.9882698059082,39.5894432067871,,,,,,,,,,,,,,,,
,3875346785.87478,2.99972219467163,36422.9765625,,,,,,,,,,,,,0.161191691995877,1.63747159237472E-5,0.000150290088549822,10,2,,80,2,2486,,,0.155482786592338,0.00163825972352267,0.00094692938728258,-0.000339264486683533,,,,0.0394131611087748,39.995735168457,1.99664790960512,2.98684358596802,2.99969005584717,2.9997718334198,36370.48046875,36475.47265625,0.0964501574635506,1,6,3,4,23.3230000458956,1,20.7182296094331,1.11915588378906,43.49951171875,39.5894432067871,,,,,,,,,,,,,,,,
,3875346927.34776,2.9993293762207,29387.6982421875,,,,,,,,,,,,,0.142911642919806,1.60112685039398E-5,9.80952319345838E-5,10,2,,80,2,2555,,,0.137791101330096,0.00128475863351813,0.000839499465655535,-0.000299515551887453,,,,0.0349251893946549,39.995735168457,1.9964724152699,2.98807406425476,2.99915504455566,2.99950265884399,29338.15625,29437.240234375,0.0964051559567452,1,6,3,4,23.3230000458956,1,20.7115080952738,1.11923217773438,43.9882698059082,39.5894432067871,,,,,,,,,,,,,,,,
,3875347068.79351,2.99856841564178,22352.4345703125,,,,,,,,,,,,,0.123928623748203,1.29441505669312E-5,1.95254390797502E-5,10,2,,80,2,2624,,,0.119444434823801,0.000937163158465724,0.000728141982108355,-0.00025871949037537,,,,0.0302781909307149,39.995735168457,1.9967335920309,2.99129605293274,2.99847435951233,2.9986720085144,22300.140625,22404.728515625,0.0964733734726906,1,6,3,4,23.3230000458956,1,20.7217322240153,1.12014770507812,43.9882698059082,39.5894432067871,,,,,,,,,,,,,,,,
,3875347210.26042,2.99837785959244,15315.435546875,,,,,,,,,,,,,0.104054688754317,1.24179323237507E-5,-4.90422222369899E-5,10,2,,80,2,2693,,,0.100258848215904,0.000632035282725971,0.000611459836363792,-0.000216208820347674,,,,0.0254120503397098,39.995735168457,1.99656682126923,2.99506735801697,2.99828219413757,2.99847793579102,15263.3310546875,15367.5400390625,0.0967296436429024,1,6,3,4,23.3230000458956,1,20.7225204287408,1.12907409667969,43.49951171875,39.5894432067871,,,,,,,,,,,,,,,,
,3875347351.72941,2.99896020889282,8279.43115234375,,,,,,,,,,,,,0.0832009480579225,9.80990182296004E-6,-9.19390131210797E-5,10,2,,80,2,2762,,,0.0801460601869274,0.000386550662891671,0.000489074969664216,-0.000172112821019255,,,,0.0203149486335476,39.995735168457,1.99667410488953,2.99894642829895,2.99891638755798,2.99900341033936,8229.6455078125,8329.216796875,0.0967948958277702,1,6,3,4,23.3230000458956,1,20.7217928123556,1.12068176269531,43.49951171875,40.0782012939453,,,,,,,,,,,,,,,,
,3875347493.29145,2.99982023239136,1225.04754638672,,,,,,,,,,,,,0.0613498257727113,1.10249361099812E-5,-0.0001343444384576,1,2,,80,2,2831,,,0.0590868047545032,0.000179026297230198,0.000360730773536488,-0.000126236700452864,,,,0.0149741312365429,39.995735168457,1.99637029891905,3.00071334838867,2.99962210655212,2.99990701675415,1175.11437988281,1274.98071289062,0.0969477817416191,1,6,3,4,23.3230000458956,1,20.7241457644948,1.12152099609375,43.49951171875,39.1006851196289,,,,,,,,,,,,,,,,
,3875347634.77633,3.00108942985535,-5825.2822265625,,,,,,,,,,,,,0.0375632940325324,1.10796417405273E-5,-7.32105711050659E-5,1,2,,80,2,2900,,,0.03618163477893,0.000134197170228672,0.000220881018321961,-7.74674263084307E-5,,,,0.0091715012530912,39.995735168457,1.99675290955858,2.99949073791504,3.00092172622681,3.00146746635437,-5877.59375,-5772.970703125,0.0969447419047356,1,6,3,4,23.3230000458956,1,20.7246860659663,1.11984252929688,43.49951171875,39.5894432067871,,,,,,,,,,,,,,,,
,3875347776.2172,3.00151205062866,-12878.1469726563,,,,,,,,,,,,,0.0106986955230851,1.36564553387236E-5,-1.25160732929901E-5,1,2,,80,2,2969,,,0.010307494637253,5.46547261438286E-5,6.28862981102429E-5,-2.21694590436528E-5,,,,0.00261235833242673,39.995735168457,1.9966393744806,2.99630403518677,3.0014340877533,3.00159454345703,-12928.08984375,-12828.2041015625,0.0969266146421432,1,6,3,4,23.3230000458956,1,20.725799906497,1.11953735351562,43.49951171875,38.1231689453125,,,,,,,,,,,,,,,,
,3875347917.69153,3.00140414237976,-19935.84765625,,,,,,,,,,,,,-0.0238383133801297,1.86145337293936E-5,1.65783930638893E-5,1,2,,80,2,3038,,,-0.0229732902563908,-0.000153327567434609,-0.000140093441586941,4.95954336656723E-5,,,,0.0058229208444994,39.995735168457,1.99659511933056,2.99209141731262,3.00126099586487,3.00152993202209,-19985.8203125,-19885.875,0.0966790542006493,1,6,3,4,23.3230000458956,1,20.7228203636426,1.11862182617188,43.9882698059082,39.5894432067871,,,,,,,,,,,,,,,,
,3875348059.14904,3.0011869430542,-27009.037109375,,,,,,,,,,,,,-0.0624780755759063,1.7185815563747E-5,6.85994674366585E-6,1,2,,80,2,3107,,,-0.0602319197979389,-0.000494145701945666,-0.000367122935131192,0.000130594431539066,,,,0.0152670133904278,39.995735168457,1.99668428049782,2.98791670799255,3.00109314918518,3.00136232376099,-27061.41796875,-26956.65625,0.096515990793705,1,6,3,4,23.3230000458956,1,20.7220426005484,1.1212158203125,43.49951171875,39.1006851196289,,,,,,,,,,,,,,,,
,3875348202.69907,3.00053157806396,-34186.240234375,,,,,,,,,,,,,-0.0960698659415386,1.79560449371877E-5,-8.40955815820937E-5,10,2,,80,2,3177,,,-0.0926541333526923,-0.000942408719732252,-0.000564365298487246,0.000202059673028998,,,,0.0234880060751801,39.995735168457,1.99677780309323,2.98680877685547,3.00049042701721,3.00065064430237,-34236.10546875,-34136.375,0.0964630544185638,1,6,3,4,23.3230000458956,1,20.7265351974166,1.12144470214844,43.49951171875,40.0782012939453,,,,,,,,,,,,,,,,
,3875348344.17962,3.0000337600708,-41261.947265625,,,,,,,,,,,,,-0.129101154863789,2.17029798827226E-5,-0.000131985992600552,10,2,,80,2,3246,,,-0.124569875887356,-0.00140693457120346,-0.000758446170948446,0.000272537086857483,,,,0.031577878225203,39.995735168457,1.99673668795834,2.98492026329041,2.9998574256897,3.0001335144043,-41311.9765625,-41211.91796875,0.0964096412062645,1,6,3,4,23.3230000458956,1,20.7285012807272,1.12312316894531,43.9882698059082,39.5894432067871,,,,,,,,,,,,,,,,
,3875348485.6356,2.99978923797607,-48337.625,,,,,,,,,,,,,-0.164144447407427,2.27744937034243E-5,-0.000191742298815104,10,2,,80,2,3315,,,-0.158467419448703,-0.0019668872730689,-0.000964477891102433,0.000347780034644529,,,,0.0401722977657199,39.995735168457,1.99677525835097,2.98530268669128,2.99967575073242,2.99986100196838,-48387.6640625,-48287.5859375,0.0962709710001945,1,6,3,4,23.3230000458956,1,20.7280239304646,1.11968994140625,43.0107536315918,39.5894432067871,,,,,,,,,,,,,,,,
,3875348627.10395,2.99943345785141,-55409.474609375,,,,,,,,,,,,,-0.193665338627339,2.26063077858777E-5,-0.000211409471050017,10,2,,80,2,3384,,,-0.18707784230495,-0.00248668274252625,-0.00113820203114301,0.000411585526308045,,,,0.0474241678890379,39.995735168457,1.99668814729673,2.98656249046326,2.99932241439819,2.99950790405273,-55461.91796875,-55357.03125,0.0963768512010574,1,6,3,4,23.3230000458956,1,20.7293630687724,1.12785339355469,43.49951171875,39.1006851196289,,,,,,,,,,,,,,,,
,3875348768.57031,2.9996190071106,-62485.505859375,,,,,,,,,,,,,-0.218144478949145,2.14379058609501E-5,-0.000195756220453854,10,2,,80,2,3453,,,-0.210860831474979,-0.00295884203529589,-0.00128256867174059,0.000464897428173572,,,,0.0534540971653828,39.995735168457,1.9967039169444,2.98853969573975,2.99956870079041,2.99966859817505,-62538.015625,-62432.99609375,0.096450038254261,1,6,3,4,23.3230000458956,1,20.730713343159,1.12152099609375,43.9882698059082,39.5894432067871,,,,,,,,,,,,,,,,
,3875348910.03733,2.99918150901794,-69556.48046875,,,,,,,,,,,,,-0.242046652494226,2.90168319375789E-5,-0.000174056103740079,10,2,,80,2,3522,,,-0.234128376262962,-0.00345501639978582,-0.00142375589348376,0.000517202424816787,,,,0.0593536866914356,39.995735168457,1.99671615952048,2.98992705345154,2.9990553855896,2.999347448349,-69609.0703125,-69503.890625,0.0964859053492546,1,6,3,4,23.3230000458956,1,20.7293222021481,1.1199951171875,43.49951171875,39.5894432067871,,,,,,,,,,,,,,,,
,3875349051.50915,2.99944323301315,-76633.921875,,,,,,,,,,,,,-0.271377528696413,2.50155682989478E-5,-0.000138776797870013,10,2,,80,2,3591,,,-0.262695850787662,-0.00404974153384774,-0.00159705220721662,0.000581257627345622,,,,0.0665921019332873,39.995735168457,1.9966049981695,2.99149799346924,2.99938321113586,2.99950075149536,-76683.8671875,-76583.9765625,0.0964947268366814,1,6,3,4,23.3230000458956,1,20.7264987035958,1.12060546875,43.49951171875,39.1006851196289,,,,,,,,,,,,,,,,
,3875349192.98961,2.9996346950531,-83780.71484375,,,,,,,,,,,,,-0.300433121886515,2.34407001386869E-5,-6.26277502188828E-5,10,2,,80,2,3660,,,-0.291054456413736,-0.00464103627156655,-0.00176920904777944,0.000644871382974088,,,,0.0737827051247621,39.995735168457,1.99665615420739,2.99352478981018,2.99960589408874,2.9996645450592,-83833.859375,-83727.5703125,0.0965514332056046,1,6,3,4,23.3230000458956,1,20.72350551669,1.12083435058594,43.49951171875,39.5894432067871,,,,,,,,,,,,,,,,
,3875349334.45719,2.99998917579651,-90933.8515625,,,,,,,,,,,,,-0.327908961643828,1.70556779818785E-5,8.27967293444125E-5,10,2,,80,2,3729,,,-0.317940027607872,-0.00517292446662021,-0.00193233613390476,0.000704970851074904,,,,0.0805948993949462,39.995735168457,1.99654603681455,2.99439167976379,2.99986815452576,3.00005149841309,-90986.9296875,-90880.7734375,0.0965084955096245,1,6,3,4,23.3230000458956,1,20.7216689099204,1.12022399902344,43.9882698059082,40.0782012939453,,,,,,,,,,,,,,,,
,3875349475.90255,2.99994854927063,-98081.78515625,,,,,,,,,,,,,-0.353855305859397,2.33052161573718E-5,0.000239154471908842,10,2,,80,2,3798,,,-0.343397602558711,-0.00569373992804756,-0.00208684476092458,0.000761864008381963,,,,0.0870467496645995,39.995735168457,1.99649108977894,2.9941680431366,2.99981451034546,3.00009942054749,-98134.859375,-98028.7109375,0.0964440330862999,1,6,3,4,23.3230000458956,1,20.7165814451981,1.12152099609375,43.49951171875,39.1006851196289,,,,,,,,,,,,,,,,
,3875349617.37134,2.99991554021835,-105235.609375,,,,,,,,,,,,,-0.37845272536742,2.67615282949664E-5,0.000414973050733218,10,2,,80,2,3867,,,-0.367599893399065,-0.00619064046236092,-0.00223380816169083,0.000816084735561162,,,,0.0931854352650536,39.995735168457,1.99654414670742,2.99330544471741,2.99981451034546,2.99997138977051,-105288.7890625,-105182.4296875,0.0964877903461456,1,6,3,4,23.3230000458956,1,20.7145243282423,1.12129211425781,43.49951171875,39.1006851196289,,,,,,,,,,,,,,,,
,3875349758.83777,3.00058641433716,-112388.203125,,,,,,,,,,,,,-0.402009121924695,2.63907889038254E-5,0.00062404079367185,10,2,,80,2,3936,,,-0.39084262415822,-0.00664828267509071,-0.00237484183162451,0.000867908936925232,,,,0.0990726983365971,39.995735168457,1.99644392344875,2.99308347702026,3.00050783157349,3.00072574615479,-112441.2265625,-112335.1796875,0.0964695364236832,1,6,3,4,23.3230000458956,1,20.7112027913601,1.12045288085938,43.49951171875,39.5894432067871,,,,,,,,,,,,,,,,
,3875349900.29607,3.00066752433777,-119538.20703125,,,,,,,,,,,,,-0.42445752997435,2.87290649983112E-5,0.000846563086162172,10,2,,80,2,4005,,,-0.413056788344035,-0.00707845428613812,-0.00250983168371022,0.000917397963348776,,,,0.104706849544037,39.995735168457,1.99649009930736,2.99114465713501,3.00059723854065,3.00070571899414,-119588.7578125,-119487.65625,0.0963247269392014,1,6,3,4,23.3230000458956,1,20.7070845822695,1.12144470214844,43.9882698059082,39.5894432067871,,,,,,,,,,,,,,,,
,3875350041.79886,3.00103015899658,-126691.359375,,,,,,,,,,,,,-0.445915787796318,6.3914594085334E-5,0.000992339855130978,10,2,,80,2,4074,,,-0.434351608940113,-0.0075657658324027,-0.00263875350356102,0.000965249550063163,,,,0.11009448612072,39.995735168457,1.99629750161504,2.98899221420288,3.00088429450989,3.00112676620483,-126741.9609375,-126640.7578125,0.0962682515382767,1,6,3,4,23.3230000458956,1,20.7048854705302,1.12022399902344,43.0107536315918,39.5894432067871,,,,,,,,,,,,,,,,
,3875350183.27536,3.00116789340973,-133843.578125,,,,,,,,,,,,,-0.466779688472241,3.93249869566159E-5,0.00125123047413171,10,2,,80,2,4143,,,-0.455112113042331,-0.00792808283892435,-0.00276478566229343,0.00101106404326856,,,,0.115348876695478,39.995735168457,1.99616145743123,2.98557186126709,3.00098252296448,3.00129628181458,-133894.046875,-133793.109375,0.0962120294570923,1,6,3,4,23.3230000458956,1,20.6995376391935,1.12785339355469,43.9882698059082,40.0782012939453,,,,,,,,,,,,,,,,
,3875350324.71054,3.00093388557434,-139999.796875,,,,,,,,,,,,,-0.484188832709399,3.92100741085312E-5,0.00138281729517848,10,2,,80,2,4212,,,-0.472476015440726,-0.00831270059024944,-0.0028703270945698,0.00105019484180957,,,,0.119759499146514,39.995735168457,1.99631837541793,2.98237824440002,3.00088429450989,3.00097155570984,-139999.828125,-139999.765625,0.0959637463092804,1,4,3,4,23.3230000458956,1,20.6989989740969,1.12777709960938,43.49951171875,39.5894432067871,,,,,,,,,,,,,,,,
,3875350466.19343,2.99916310310364,-138165.3125,,,,,,,,,,,,,-0.479421823978352,3.6998632079793E-5,0.00143363792106474,10,2,,80,2,4281,,,-0.467711031475797,-0.00811926697092838,-0.00284130382351577,0.0010383864864707,,,,0.11853292005297,39.995735168457,1.99599640389558,2.98153901100159,2.99902701377869,2.9992995262146,-138217.421875,-138113.203125,0.0960721597075462,1,6,3,4,23.3230000458956,1,20.6912665677623,1.12205505371094,43.49951171875,39.5894432067871,,,,,,,,,,,,,,,,
,3875350607.64834,2.99867877960205,-131154.078125,,,,,,,,,,,,,-0.460509751222784,3.99869481089444E-5,0.00123111375333899,10,2,,80,2,4350,,,-0.448837721271623,-0.00774782173145988,-0.00272684171795845,0.000996319111436605,,,,0.113754724194705,39.995735168457,1.99608646978204,2.98451709747314,2.99850296974182,2.99880266189575,-131203.5625,-131104.59375,0.0962129682302475,1,6,3,4,23.3230000458956,1,20.6924847685415,1.12060546875,44.9657897949219,39.5894432067871,,,,,,,,,,,,,,,,
,3875350749.10213,2.99933252334595,-124142.953125,,,,,,,,,,,,,-0.440716785472471,4.84852429156639E-5,0.000932949294973031,10,2,,80,2,4419,,,-0.429141340341246,-0.00744595907986459,-0.00260817888192832,0.000953110633417964,,,,0.108807245745063,39.995735168457,1.99690410156726,2.98815584182739,2.999192237854,2.99950432777405,-124195,-124090.90625,0.0964848101139069,1,6,3,4,23.3230000458956,1,20.6902615308198,1.11915588378906,43.49951171875,39.5894432067871,,,,,,,,,,,,,,,,
,3875350890.59428,2.99926409721375,-117129.28125,,,,,,,,,,,,,-0.42007954231815,3.21283428516487E-5,0.000712868254863166,10,2,,80,2,4488,,,-0.408664743598587,-0.00704903672443599,-0.00248325988650322,0.000907193985767662,,,,0.103591508354297,39.995735168457,1.996450679828,2.99024152755737,2.99917650222778,2.99937796592712,-117181.3046875,-117077.2578125,0.0965195223689079,1,6,3,4,23.3230000458956,1,20.6906559934978,1.126708984375,43.9882698059082,40.0782012939453,,,,,,,,,,,,,,,,
,3875351032.06183,2.99979889392853,-110117.4453125,,,,,,,,,,,,,-0.398579641139005,3.41429924531897E-5,0.000508772734110876,10,2,,80,2,4557,,,-0.387392709016789,-0.00662192823986372,-0.00235419766977429,0.000859998865053058,,,,0.0982063895154697,39.995735168457,1.99661507907134,2.99269580841064,2.99978089332581,2.9998288154602,-110166.9921875,-110067.8984375,0.096566803753376,1,6,3,4,23.3230000458956,1,20.6985757436419,1.11991882324219,43.9882698059082,40.0782012939453,,,,,,,,,,,,,,,,
,3875351173.52257,2.99943490028381,-103101.9375,,,,,,,,,,,,,-0.375897998798665,2.72768034935316E-5,0.000351210244128047,10,2,,80,2,4626,,,-0.36501890235429,-0.00613435818469162,-0.00221848604269326,0.000809880264569074,,,,0.0925376376745641,39.995735168457,1.99669868275819,2.99400115013123,2.99928164482117,2.9997718334198,-103151.6171875,-103052.2578125,0.0966032594442368,1,6,3,4,23.3230000458956,1,20.7027083873332,1.11892700195312,44.9657897949219,39.5894432067871,,,,,,,,,,,,,,,,
,3875351315.0077,2.99978190660477,-96085.24609375,,,,,,,,,,,,,-0.351875647062166,2.14954729495726E-5,0.000193153646789252,10,2,,80,2,4695,,,-0.341391984111297,-0.00563565378796313,-0.00207518180832267,0.000756480381824076,,,,0.0865450994043126,39.995735168457,1.9966540402739,2.99454021453857,2.9996771812439,2.999844789505,-96134.796875,-96035.6953125,0.0966833382844925,1,6,3,4,23.3230000458956,1,20.6933172056038,1.12030029296875,44.4770278930664,39.5894432067871,,,,,,,,,,,,,,,,
,3875351456.44752,2.99990501403809,-89074.39453125,,,,,,,,,,,,,-0.326350663870586,1.59266296525598E-5,7.02716608188648E-5,10,2,,80,2,4764,,,-0.316359216403361,-0.00509587836667591,-0.00192316307220608,0.000700130243785679,,,,0.0801925988651861,39.995735168457,1.99650251274609,2.99426603317261,2.99978947639465,2.99999117851257,-89123.9609375,-89024.828125,0.0966871008276939,1,6,3,4,23.3230000458956,1,20.6916703356532,1.12762451171875,43.9882698059082,39.5894432067871,,,,,,,,,,,,,,,,
,3875351597.95337,3.0000415802002,-82057.48046875,,,,,,,,,,,,,-0.299128287722079,2.38158735691134E-5,-4.75751929302301E-5,10,2,,80,2,4833,,,-0.289733975775206,-0.00454871809454249,-0.00176162994466722,0.000640642829239368,,,,0.0734479146122061,39.995735168457,1.99663669924142,2.99390029907227,2.99996566772461,3.00011229515076,-82107.1015625,-82007.859375,0.0967715978622436,1,6,3,4,23.3230000458956,1,20.6954944688609,1.121826171875,43.9882698059082,40.0782012939453,,,,,,,,,,,,,,,,
,3875351739.41603,3.00029273033142,-75037.91015625,,,,,,,,,,,,,-0.270382748046366,2.40193812875289E-5,-0.000112319763489808,10,2,,80,2,4902,,,-0.261688339674803,-0.00395885119412435,-0.00159148522652686,0.000577828323002905,,,,0.0663416087980583,39.995735168457,1.99675235360561,2.9930055141449,3.00024247169495,3.00036907196045,-75090.0546875,-74985.765625,0.0966234058141708,1,6,3,4,23.3230000458956,1,20.6983745737123,1.12655639648438,43.9882698059082,39.5894432067871,,,,,,,,,,,,,,,,
,3875351880.86396,3.00029158592224,-68026.0234375,,,,,,,,,,,,,-0.24245351301282,1.89006776365075E-5,-0.000184630363726966,10,2,,80,2,4971,,,-0.234485492707617,-0.00342508710768849,-0.00142641144338995,0.000517121923621744,,,,0.0594504859988382,39.995735168457,1.99693397012014,2.99133777618408,3.00020503997803,3.00039768218994,-68078,-67974.046875,0.0966611206531525,1,6,3,4,23.3230000458956,1,20.7008244072837,1.12808227539062,44.4770278930664,40.0782012939453,,,,,,,,,,,,,,,,
,3875352022.35104,3.00056076049805,-61008.8203125,,,,,,,,,,,,,-0.223440892266288,1.86698034081955E-5,-0.000223124751583875,10,2,,80,2,5040,,,-0.215950102026924,-0.00301050955201088,-0.00131414760835469,0.000475412525702268,,,,0.0547575165437933,39.995735168457,1.99721253218909,2.98992323875427,3.00044560432434,3.00067210197449,-61060.93359375,-60956.70703125,0.0966767966747284,1,6,3,4,23.3230000458956,1,20.700049312952,1.11747741699219,43.9882698059082,40.0782012939453,,,,,,,,,,,,,,,,
,3875352163.81046,3.00070576667786,-53995.0703125,,,,,,,,,,,,,-0.205490416089895,2.11888818272405E-5,-0.000220007005662666,10,2,,80,2,5109,,,-0.198476429760627,-0.0025963642462383,-0.00120830396190286,0.000435918103903532,,,,0.0503312644398708,39.995735168457,1.99741637098124,2.98856329917908,3.00062918663025,3.00075435638428,-54044.7109375,-53945.4296875,0.0965491533279419,1,6,3,4,23.3230000458956,1,20.6987775108555,1.12648010253906,43.9882698059082,40.5669593811035,,,,,,,,,,,,,,,,
,3875352305.25726,3.00033082962036,-46978.14453125,,,,,,,,,,,,,-0.187805158041146,2.17460030584322E-5,-0.000191293202838451,10,2,,80,2,5178,,,-0.181290721374577,-0.00218935215172456,-0.00110419618431479,0.000397037074435502,,,,0.0459770638685674,39.995735168457,1.99761933097507,2.98742771148682,3.00025105476379,3.00045990943909,-47027.69140625,-46928.59765625,0.0964067280292511,1,6,3,4,23.3230000458956,1,20.6956203629304,1.11801147460938,44.4770278930664,40.0782012939453,,,,,,,,,,,,,,,,
,3875352446.75618,2.99986906051636,-39961.087890625,,,,,,,,,,,,,-0.17018346436377,2.1879451649144E-5,-0.000184682324595373,10,2,,80,2,5247,,,-0.164195098644188,-0.00183533003577292,-0.00100034940987825,0.000358815887011588,,,,0.0416413754223363,39.995735168457,1.99763700010769,2.98673415184021,2.99979114532471,2.99991250038147,-40015.68359375,-39906.4921875,0.0964594930410385,1,6,3,4,23.3230000458956,1,20.7024173971994,1.11892700195312,44.4770278930664,40.0782012939453,,,,,,,,,,,,,,,,
,3875352588.20342,2.99958729743958,-32914.447265625,,,,,,,,,,,,,-0.152142619990606,1.87172869769188E-5,-0.000127929894818374,10,2,,80,2,5316,,,-0.146721714949713,-0.00146160461349504,-0.00089422898599878,0.000319584447424859,,,,0.0372088995252199,39.995735168457,1.99758295327365,2.98744988441467,2.99950623512268,2.99964165687561,-32966.80078125,-32862.09375,0.0965260341763496,1,6,3,4,23.3230000458956,1,20.7058013754168,1.11900329589844,43.9882698059082,40.0782012939453,,,,,,,,,,,,,,,,
,3875352729.67526,2.99901956319809,-25860.048828125,,,,,,,,,,,,,-0.133500294442968,1.54955183813156E-5,-5.21168870249846E-5,10,2,,80,2,5385,,,-0.128692375185046,-0.0011001690840949,-0.000784657604526728,0.000279231549939141,,,,0.0326338371499078,39.995735168457,1.99744012806074,2.98948574066162,2.99899458885193,2.99904108047485,-25909.951171875,-25810.146484375,0.0966703742742538,1,6,3,4,23.3230000458956,1,20.7094208695554,1.11869812011719,44.4770278930664,40.0782012939453,,,,,,,,,,,,,,,,
,3875352871.15448,2.99835300445557,-18804.546875,,,,,,,,,,,,,-0.114012217647584,1.38227139882545E-5,1.16606374563533E-5,10,2,,80,2,5454,,,-0.109868985189311,-0.000782248470938753,-0.000670244742650539,0.000237444110098295,,,,0.0278619756912263,39.995735168457,1.99751910985934,2.99308466911316,2.99824810028076,2.99846196174622,-18854.3984375,-18754.6953125,0.09675482660532,1,6,3,4,23.3230000458956,1,20.7099114588062,1.119384765625,43.9882698059082,39.5894432067871,,,,,,,,,,,,,,,,
,3875353012.60563,2.99845662117004,-11750.6479492187,,,,,,,,,,,,,-0.0936082217058695,1.24455669921005E-5,5.84091623861829E-5,10,2,,80,2,5523,,,-0.090181401428288,-0.000515045043890962,-0.000550403201486915,0.000194115782505833,,,,0.0228690296557566,39.995735168457,1.99748721679984,2.99682521820068,2.99840831756592,2.99847793579102,-11803.083984375,-11698.2119140625,0.0967922955751419,1,6,3,4,23.3230000458956,1,20.7098606874882,1.11961364746094,43.9882698059082,40.0782012939453,,,,,,,,,,,,,,,,
,3875353154.07553,2.99958205223084,-4689.0234375,,,,,,,,,,,,,-0.0721642419764793,1.08556244920471E-5,9.01203858628156E-5,10,2,,80,2,5592,,,-0.0695074799617553,-0.000298239153863618,-0.00042444170685485,0.000149020881508477,,,,0.0176259234632241,39.995735168457,1.99753749955789,3.00047588348389,2.99946689605713,2.99973964691162,-4738.99462890625,-4639.05224609375,0.0968679040670395,1,6,3,4,23.3230000458956,1,20.710658817948,1.11885070800781,44.4770278930664,40.0782012939453,,,,,,,,,,,,,,,,
,3875353295.62232,3.0008237361908,2382.81591796875,,,,,,,,,,,,,-0.0494528543233464,1.08842793200351E-5,9.86988142727663E-5,1,2,,80,2,5661,,,-0.0476297634466253,-0.000158208408985675,-0.000290911499178037,0.000101849640486762,,,,0.0120764803169205,39.995735168457,1.99736261482144,3.00050187110901,3.00067210197449,3.00090932846069,2330.32299804687,2435.30883789062,0.0968847051262856,1,6,3,4,23.3230000458956,1,20.7155004010036,1.1187744140625,44.4770278930664,40.0782012939453,,,,,,,,,,,,,,,,
,3875353437.07181,3.00112164020538,9458.541015625,,,,,,,,,,,,,-0.0242753504697379,1.23909434863487E-5,3.67256555493346E-5,1,2,,80,2,5730,,,-0.0233849719440949,-0.000106416492355638,-0.000142762844916433,5.01893518958241E-5,,,,0.00592903914024421,39.995735168457,1.99731929728091,2.9979829788208,3.00106811523438,3.00123596191406,9405.9462890625,9511.1357421875,0.0968331545591354,1,6,3,4,23.3230000458956,1,20.7191749030922,1.12007141113281,44.4770278930664,40.0782012939453,,,,,,,,,,,,,,,,
,3875353578.54503,3.00149363279343,16534.818359375,,,,,,,,,,,,,0.0058662263764454,1.58948087836259E-5,-6.40678434981143E-6,1,2,,80,2,5799,,,0.0056525356807926,3.29980545658709E-5,3.44913714798167E-5,-1.2176092241134E-5,,,,0.00143318464445228,39.995735168457,1.99724750704272,2.9940664768219,3.00144624710083,3.00153756141663,16482.34765625,16587.2890625,0.096646673977375,1,6,3,4,23.3230000458956,1,20.7198972304734,1.11976623535156,43.9882698059082,40.5669593811035,,,,,,,,,,,,,,,,
,3875353719.992,3.00124144554138,23617.1396484375,,,,,,,,,,,,,0.044668498994194,1.84411225448292E-5,-1.97745059208516E-5,1,2,,80,2,5868,,,0.0430551154764226,0.000319223578127708,0.000262585585005581,-9.31614413275383E-5,,,,0.0109165698127345,39.995735168457,1.99732157106868,2.99029159545898,3.00100374221802,3.00134110450745,23564.447265625,23669.83203125,0.0964774787425995,1,6,3,4,23.3230000458956,1,20.7195213288801,1.11892700195312,44.9657897949219,40.0782012939453,,,,,,,,,,,,,,,,
,3875353861.47788,3.00081920623779,30712.4833984375,,,,,,,,,,,,,0.0803409884856668,1.80670510037533E-5,5.47085148562181E-7,1,2,,80,2,5937,,,0.0774687558538405,0.0006836970443195,0.000472235755296424,-0.000168293889146298,,,,0.0196425692445745,39.995735168457,1.99731879230967,2.98705530166626,3.00074863433838,3.00087571144104,30659.82421875,30765.142578125,0.0963615328073502,1,6,3,4,23.3230000458956,1,20.719639228283,1.12014770507812,43.9882698059082,39.5894432067871,,,,,,,,,,,,,,,,
,3875354004.9981,3.00025849342346,37914.171875,,,,,,,,,,,,,0.112916712685452,2.03894096034161E-5,0.000119944384450409,10,2,,80,2,6007,,,0.108928194562413,0.00118429591614017,0.000663508370053023,-0.000237978470977396,,,,0.027620312746444,39.995735168457,1.99722618890916,2.98548197746277,3.00008201599121,3.00044393539429,37861.52734375,37966.81640625,0.0963088497519493,1,6,3,4,23.3230000458956,1,20.7187154007223,1.11824035644531,43.9882698059082,39.5894432067871,,,,,,,,,,,,,,,,
,3875354146.50137,3.00007019042969,45006.166015625,,,,,,,,,,,,,0.148100315591107,2.26989676510243E-5,0.000167171201708542,10,2,,80,2,6076,,,0.142941319269982,0.00170332254086047,0.000870399526320398,-0.00031330669298768,,,,0.0362469571427402,39.995735168457,1.997357760047,2.98497772216797,2.99993562698364,3.00014781951904,44955.96484375,45056.3671875,0.0961708724498749,1,6,3,4,23.3230000458956,1,20.724391652959,1.12693786621094,43.9882698059082,40.5669593811035,,,,,,,,,,,,,,,,
,3875354287.96524,2.99953203201294,52101.818359375,,,,,,,,,,,,,0.180737032605048,2.16338439367871E-5,0.000224870728303618,10,2,,80,2,6145,,,0.1745395791282,0.00226895844198237,0.00106231507379562,-0.000383737002266571,,,,0.0442564763997289,39.995735168457,1.99721022829186,2.98627519607544,2.99943280220032,2.99961853027344,52051.60546875,52152.03125,0.0962648615241051,1,6,3,4,23.3230000458956,1,20.7267060221459,1.1181640625,43.9882698059082,39.5894432067871,,,,,,,,,,,,,,,,
,3875354429.42013,2.999307513237,59194.96875,,,,,,,,,,,,,0.207283383481139,2.18663975578714E-5,0.000225733827772202,10,2,,80,2,6214,,,0.200300465033032,0.00276270551484308,0.00121875654440373,-0.000441338081145659,,,,0.0507885318937638,39.995735168457,1.99718771831923,2.98721766471863,2.99927234649658,2.99933528900146,59142.30859375,59247.62890625,0.0962625220417976,1,6,3,4,23.3230000458956,1,20.7265938683499,1.11869812011719,43.9882698059082,40.0782012939453,,,,,,,,,,,,,,,,
,3875354570.89953,2.99942243099213,66287.1171875,,,,,,,,,,,,,0.230463726734051,2.53830493333488E-5,0.000203918007682867,10,2,,80,2,6283,,,0.222850782578241,0.00323342578881965,0.00135558703914285,-0.000492047751322389,,,,0.0565064009040383,39.995735168457,1.99715457728343,2.98904919624329,2.99937081336975,2.99949359893799,66236.9921875,66337.2421875,0.0963039547204971,1,6,3,4,23.3230000458956,1,20.7288934928401,1.11923217773438,43.49951171875,40.0782012939453,,,,,,,,,,,,,,,,
,3875354712.34656,2.99923281669617,73383.5703125,,,,,,,,,,,,,0.257933165889099,2.64934265497598E-5,0.000167093543791236,10,2,,80,2,6352,,,0.249594410543878,0.00378369320972499,0.00151791039388627,-0.000552116427570581,,,,0.0632885597007175,39.995735168457,1.99715157247359,2.99078035354614,2.99914073944092,2.99933528900146,73333.5,73433.640625,0.0962634831666946,1,6,3,4,23.3230000458956,1,20.7299701017869,1.11991882324219,43.9882698059082,39.1006851196289,,,,,,,,,,,,,,,,
,3875354853.84303,2.99984437227249,80514.47265625,,,,,,,,,,,,,0.287548235947802,2.71540437504946E-5,9.01400334647065E-5,10,2,,80,2,6421,,,0.278468773182391,0.00436522745200475,0.00169315806124359,-0.000616846198681742,,,,0.0706082374905754,39.995735168457,1.99709304341289,2.99282717704773,2.99975943565369,2.99989819526672,80461.203125,80567.7421875,0.0963000655174255,1,6,3,4,23.3230000458956,1,20.7298523099371,1.11900329589844,43.9882698059082,40.0782012939453,,,,,,,,,,,,,,,,
,3875354995.30615,2.99987254142761,87687.6015625,,,,,,,,,,,,,0.315849717146789,2.4719611704721E-5,-2.08522443168829E-5,10,2,,80,2,6490,,,0.306129192437341,0.00493060247320495,0.00186097493860871,-0.000678895798046142,,,,0.0776181363209648,39.995735168457,1.99699994250271,2.99365663528442,2.99980020523071,2.99999260902405,87634.328125,87740.875,0.0963334739208221,1,6,3,4,23.3230000458956,1,20.729954485508,1.12037658691406,43.9882698059082,39.5894432067871,,,,,,,,,,,,,,,,
,3875355136.7749,2.99970846176147,94862.3984375,,,,,,,,,,,,,0.342525880021652,3.10974281270717E-5,-0.000140210908283428,10,2,,80,2,6559,,,0.332270463121539,0.0054901470859814,0.00201961235143244,-0.000737610971555114,,,,0.0842457755742442,39.995735168457,1.99698089291259,2.99434280395508,2.99958992004395,2.99978756904602,94809.1484375,94915.6484375,0.0963160544633865,1,6,3,4,23.3230000458956,1,20.7271863809406,1.12037658691406,43.9882698059082,40.0782012939453,,,,,,,,,,,,,,,,
,3875355278.2281,3.00023407936096,102034.16015625,,,,,,,,,,,,,0.367849787263047,2.84300387406315E-5,-0.000370119734718882,10,2,,80,2,6628,,,0.357156141915117,0.00594062389112014,0.00217078486457467,-0.000793106039054692,,,,0.0905555138750895,39.995735168457,1.99698019111479,2.99419379234314,2.99999618530273,3.0004346370697,101983.4140625,102084.90625,0.0962956100702286,1,6,3,4,23.3230000458956,1,20.7274810713118,1.12007141113281,43.9882698059082,40.0782012939453,,,,,,,,,,,,,,,,
,3875355419.6934,3.00034432411194,109206.3828125,,,,,,,,,,,,,0.39190654488615,3.17471329955693E-5,-0.000512119629572444,10,2,,80,2,6697,,,0.380862463511135,0.00646875258418006,0.00231452682055533,-0.000846431124955416,,,,0.0965623564659731,39.995735168457,1.99689415526398,2.99320864677429,3.00019788742065,3.00045418739319,109153.09375,109259.671875,0.0963270366191864,1,6,3,4,23.3230000458956,1,20.7250068117436,1.11953735351562,43.9882698059082,40.0782012939453,,,,,,,,,,,,,,,,
,3875355561.16735,3.00029644966126,116381.31640625,,,,,,,,,,,,,0.414911165879703,2.57084232772608E-5,-0.000652658863311722,10,2,,80,2,6766,,,0.403596329641962,0.00698790656705894,0.00245258305221796,-0.000897581456229091,,,,0.102332536066472,39.995735168457,1.99697831076332,2.9920027256012,3.0002064704895,3.00040316581726,116328.078125,116434.5546875,0.0962622463703155,1,6,3,4,23.3230000458956,1,20.719780009145,1.11976623535156,43.9882698059082,40.0782012939453,,,,,,,,,,,,,,,,
,3875355702.65486,3.00075039863586,123555.8984375,,,,,,,,,,,,,0.436931832765158,6.79648418470292E-5,-0.00088866262210847,10,2,,80,2,6835,,,0.425422022925432,0.00739905435845126,0.00258502480573952,-0.000946315180044621,,,,0.10786287628242,39.995735168457,1.99689324703564,2.98935222625732,3.00059199333191,3.00093793869019,123502.6640625,123609.1328125,0.0961173102259636,1,6,3,4,23.3230000458956,1,20.7204527328844,1.11862182617188,43.9882698059082,39.5894432067871,,,,,,,,,,,,,,,,
,3875355844.11323,3.0009120464325,130729.2109375,,,,,,,,,,,,,0.458229641620524,3.04895208935987E-5,-0.0011376489008426,10,2,,80,2,6904,,,0.446588404944386,0.00778218925331939,0.00271365488879383,-0.000993246212601662,,,,0.113228382034017,39.995735168457,1.99686520573127,2.98715329170227,3.00072193145752,3.0011625289917,130678.421875,130780,0.0959392711520195,1,6,3,4,23.3230000458956,1,20.7155989699272,1.11763000488281,44.4770278930664,39.5894432067871,,,,,,,,,,,,,,,,
,3875355985.57666,3.0012571811676,137904.296875,,,,,,,,,,,,,0.478647094529797,3.64647099251532E-5,-0.00135123526326288,10,2,,80,2,6973,,,0.466937360657726,0.00817721547855124,0.00283757504075766,-0.00103846658021212,,,,0.118397481496055,39.995735168457,1.99702599745731,2.9828999042511,3.00122690200806,3.00132131576538,137853.640625,137954.953125,0.0958271995186806,1,6,3,4,23.3230000458956,1,20.7082069319554,1.11968994140625,44.4770278930664,40.0782012939453,,,,,,,,,,,,,,,,
,3875356127.03749,3.00034756660461,140000.609375,,,,,,,,,,,,,0.484570642701015,3.18333258706601E-5,-0.00144285673016069,10,2,,80,2,7042,,,0.472849816779477,0.00826175742975885,0.00287339254282415,-0.00105160241946578,,,,0.119892025072642,39.995735168457,1.99695378201231,2.98088598251343,3.00031185150146,3.00037407875061,140000.578125,140000.640625,0.0957391858100891,1,4,3,4,23.3230000458956,1,20.7109958438861,1.11907958984375,43.9882698059082,40.0782012939453,,,,,,,,,,,,,,,,
,3875356147.54343,3.00004988908768,140000.6796875,,,,,,,,,,,,,0.484640565782996,3.026798022931E-5,-0.00143757511239877,10,2,,80,2,7052,,,0.472917943423674,0.00826830815555171,0.00287357135675848,-0.00105198193341494,,,,0.119903732486605,39.995735168457,1.99685818597134,2.98105621337891,2.99994111061096,3.00009083747864,140000.625,140000.734375,0.0957240089774132,1,4,3,4,23.3230000458956,1,20.7158689576473,1.12037658691406,44.9657897949219,39.5894432067871,,,,,,,,,,,,,,,,