File: MPMS/NiCl2pym/NiCl2pym_2-300K_ZFC.rso.dat
[Header]
TITLE,MPMS RSO Measurement
BYAPP,MPMS Measurement,1.1,Summary
FILEOPENTIME, 1626353194.365000 7/15/2021, 1:46:34 PM

INFO, APPNAME, MPMS MultiVu Application, Revision 1.61,  Build 082

INFO, NAME, NiCl2pym
INFO, WEIGHT, 12.300
INFO, AREA, 1.000
INFO, LENGTH, 1.000
INFO, SHAPE, -
INFO, COMMENT, 10.7 mg eicosane
INFO, SEQUENCE FILE: JP_ZFC_MH_FC_210715_NiCl2pym.seq


INFO, BACKGROUND DATA FILE:, None


STARTUPAXIS,X,4,LINEAR,AUTO,0.000000,0.000000
STARTUPAXIS,Y1,5,LINEAR,AUTO,0.000000,0.000000


STARTUPGROUP,Longitudinal
FIELDGROUP,Longitudinal,1,2,3,4,5,6,7,8,9,10,11,19,20,21,22,23,35
FIELDGROUP,Transverse,1,2,3,4,12,13,14,15,16,17,18,24,25,26,27,28,35

PLOT_APPEARANCE,ALL,HORZ_GRID_ON,VERT_GRID_ON,MARKERS_AND_LINES

[Data]
Time,Comment,Field (Oe),Temperature (K),Long Moment (emu),Long Scan Std Dev,Long Offset (cm),Long Offset Std Dev,Long Algorithm,Long Reg Fit,Long Reg Factor,Trans Moment (emu),Trans Scan Std Dev,Trans Offset (cm),Trans Offset Std Dev,Trans Algorithm,Trans Reg Fit,Trans Reg Factor,Long Moment [w/o ABS] (emu),Long Scan Std Dev [w/o ABS],Long Offset [w/o ABS] (cm),Long Offset Std Dev [w/o ABS],Long Reg Fit [w/o ABS],Trans Moment [w/o ABS] (emu),Trans Scan Std Dev [w/o ABS],Trans Offset [w/o ABS] (cm),Trans Offset Std Dev [w/o ABS],Trans Reg Fit [w/o ABS],RSO Position (deg),Amplitude (cm),Frequency,Cycles to Average,Scans per Measurement,Delta Temp (K),Error,EC Comp. Running,Using ABS,
1626353194.365,,1.000000e+002,2.000938e+000,3.151778e-004,1.247306e-006,-5.269627e-002,7.298782e-005,3,9.894873e-001,1.825000e+000,,,,,,,,,,,,,,,,,,0,5.000000e+000,1.000000e+000,4,4,7.760525e-004,0,,0,
1626353394.050,,1.000000e+002,2.251966e+000,3.144415e-004,1.465603e-006,-5.324867e-002,6.222896e-004,3,9.895400e-001,1.825000e+000,,,,,,,,,,,,,,,,,,0,5.000000e+000,1.000000e+000,4,4,2.665043e-003,0,,0,
1626353592.972,,1.000000e+002,2.501926e+000,3.128435e-004,1.483396e-006,-5.201459e-002,1.386940e-004,3,9.894996e-001,1.825000e+000,,,,,,,,,,,,,,,,,,0,5.000000e+000,1.000000e+000,4,4,4.052162e-003,0,,0,
1626353802.671,,1.000000e+002,2.751792e+000,3.107162e-004,1.629445e-006,-5.317672e-002,6.922426e-004,3,9.894966e-001,1.825000e+000,,,,,,,,,,,,,,,,,,0,5.000000e+000,1.000000e+000,4,4,5.014181e-003,0,,0,
1626354042.045,,1.000000e+002,3.001597e+000,3.095508e-004,1.566977e-006,-5.506669e-002,2.496681e-004,3,9.892330e-001,1.825000e+000,,,,,,,,,,,,,,,,,,0,5.000000e+000,1.000000e+000,4,4,5.309105e-003,0,,0,
1626354330.495,,1.000000e+002,3.250936e+000,3.083827e-004,1.685759e-006,-5.397750e-002,3.932813e-004,3,9.891902e-001,1.825000e+000,,,,,,,,,,,,,,,,,,0,5.000000e+000,1.000000e+000,4,4,5.845070e-003,0,,0,
1626354543.572,,1.000000e+002,3.533598e+000,3.033601e-004,1.734923e-006,-5.381074e-002,2.198913e-004,3,9.890776e-001,1.825000e+000,,,,,,,,,,,,,,,,,,0,5.000000e+000,1.000000e+000,4,4,3.362703e-002,0,,0,
1626354751.130,,1.000000e+002,3.763747e+000,3.008146e-004,1.081528e-006,-5.354727e-002,1.142097e-004,3,9.889506e-001,1.825000e+000,,,,,,,,,,,,,,,,,,0,5.000000e+000,1.000000e+000,4,4,1.283503e-002,0,,0,
1626355005.333,,1.000000e+002,4.010678e+000,2.988087e-004,9.121117e-007,-5.354826e-002,2.672366e-004,3,9.890924e-001,1.825000e+000,,,,,,,,,,,,,,,,,,0,5.000000e+000,1.000000e+000,4,4,1.522827e-002,0,,0,
1626355325.068,,1.000000e+002,4.259007e+000,2.968108e-004,8.833049e-007,-5.314822e-002,1.703322e-004,3,9.890641e-001,1.825000e+000,,,,,,,,,,,,,,,,,,0,5.000000e+000,1.000000e+000,4,4,1.904011e-002,0,,0,
1626355607.465,,1.000000e+002,4.505502e+000,2.938796e-004,7.815755e-007,-5.323622e-002,1.842895e-004,3,9.891166e-001,1.825000e+000,,,,,,,,,,,,,,,,,,0,5.000000e+000,1.000000e+000,4,4,8.316040e-003,0,,0,
1626355761.239,,1.000000e+002,4.754503e+000,2.912668e-004,5.907641e-007,-5.362586e-002,7.857438e-004,3,9.891132e-001,1.825000e+000,,,,,,,,,,,,,,,,,,0,5.000000e+000,1.000000e+000,4,4,6.729126e-003,0,,0,
1626355914.014,,1.000000e+002,5.003779e+000,2.885311e-004,6.116755e-007,-5.441264e-002,3.802153e-004,3,9.893087e-001,1.825000e+000,,,,,,,,,,,,,,,,,,0,5.000000e+000,1.000000e+000,4,4,7.390022e-003,0,,0,
1626356066.742,,1.000000e+002,5.254108e+000,2.856046e-004,4.355553e-007,-5.459885e-002,1.356590e-004,3,9.894080e-001,1.825000e+000,,,,,,,,,,,,,,,,,,0,5.000000e+000,1.000000e+000,4,4,7.000923e-003,0,,0,
1626356219.484,,1.000000e+002,5.503212e+000,2.826385e-004,2.739097e-007,-5.137514e-002,1.446831e-003,3,9.896768e-001,1.825000e+000,,,,,,,,,,,,,,,,,,0,5.000000e+000,1.000000e+000,4,4,5.038738e-003,0,,0,
1626356373.008,,1.000000e+002,5.753081e+000,2.801049e-004,1.700450e-007,-4.994913e-002,4.784942e-004,3,9.900047e-001,1.825000e+000,,,,,,,,,,,,,,,,,,0,5.000000e+000,1.000000e+000,4,4,4.203796e-003,0,,0,
1626356526.001,,1.000000e+002,6.002447e+000,2.780478e-004,3.175558e-008,-4.945689e-002,3.419596e-004,3,9.898670e-001,1.825000e+000,,,,,,,,,,,,,,,,,,0,5.000000e+000,1.000000e+000,4,4,3.411293e-003,0,,0,
1626356637.874,,1.000000e+002,6.502192e+000,2.746180e-004,6.057975e-008,-4.929436e-002,2.386420e-004,3,9.899104e-001,1.825000e+000,,,,,,,,,,,,,,,,,,0,5.000000e+000,1.000000e+000,4,4,4.218102e-003,0,,0,
1626356791.867,,1.000000e+002,7.002681e+000,2.719644e-004,1.082811e-008,-4.853992e-002,1.837852e-004,3,9.899515e-001,1.825000e+000,,,,,,,,,,,,,,,,,,0,5.000000e+000,1.000000e+000,4,4,4.398346e-003,0,,0,
1626356946.438,,1.000000e+002,7.501683e+000,2.699955e-004,2.313388e-008,-4.748427e-002,3.880839e-004,3,9.898704e-001,1.825000e+000,,,,,,,,,,,,,,,,,,0,5.000000e+000,1.000000e+000,4,4,3.115177e-003,0,,0,
1626357100.728,,1.000000e+002,8.000528e+000,2.686209e-004,3.647384e-008,-4.702212e-002,3.843172e-004,3,9.899213e-001,1.825000e+000,,,,,,,,,,,,,,,,,,0,5.000000e+000,1.000000e+000,4,4,3.637791e-003,0,,0,
1626357254.517,,1.000000e+002,8.501591e+000,2.679075e-004,7.229229e-008,-4.728568e-002,5.061417e-004,3,9.903225e-001,1.825000e+000,,,,,,,,,,,,,,,,,,0,5.000000e+000,1.000000e+000,4,4,3.922462e-003,0,,0,
1626357410.116,,1.000000e+002,9.000938e+000,2.677396e-004,9.020295e-008,-4.601596e-002,1.008454e-004,3,9.904772e-001,1.825000e+000,,,,,,,,,,,,,,,,,,0,5.000000e+000,1.000000e+000,4,4,3.519058e-003,0,,0,
1626357563.640,,1.000000e+002,9.500816e+000,2.680415e-004,1.264963e-007,-4.430482e-002,6.510239e-004,3,9.908137e-001,1.825000e+000,,,,,,,,,,,,,,,,,,0,5.000000e+000,1.000000e+000,4,4,3.620148e-003,0,,0,
1626357717.977,,1.000000e+002,1.000009e+001,2.688692e-004,5.532816e-009,-4.390807e-002,3.282070e-004,3,9.911897e-001,1.825000e+000,,,,,,,,,,,,,,,,,,0,5.000000e+000,1.000000e+000,4,4,4.894257e-003,0,,0,
1626357872.827,,1.000000e+002,1.050671e+001,2.699753e-004,5.311455e-008,-4.400984e-002,2.944087e-004,3,9.911022e-001,1.825000e+000,,,,,,,,,,,,,,,,,,0,5.000000e+000,1.000000e+000,4,4,2.699852e-003,0,,0,
1626358028.518,,1.000000e+002,1.101212e+001,2.718795e-004,1.223917e-007,-4.414555e-002,4.014221e-004,3,9.912442e-001,1.825000e+000,,,,,,,,,,,,,,,,,,0,5.000000e+000,1.000000e+000,4,4,3.299713e-003,0,,0,
1626358183.869,,1.000000e+002,1.151790e+001,2.746347e-004,6.862044e-008,-4.286078e-002,3.023304e-004,3,9.913499e-001,1.825000e+000,,,,,,,,,,,,,,,,,,0,5.000000e+000,1.000000e+000,4,4,3.629684e-003,0,,0,
1626358338.672,,1.000000e+002,1.200002e+001,2.782401e-004,1.369680e-008,-4.204616e-002,8.211952e-005,3,9.913490e-001,1.825000e+000,,,,,,,,,,,,,,,,,,0,5.000000e+000,1.000000e+000,4,4,1.039505e-003,0,,0,
1626358493.181,,1.000000e+002,1.250452e+001,2.831253e-004,5.554417e-008,-4.239591e-002,4.548438e-004,3,9.913751e-001,1.825000e+000,,,,,,,,,,,,,,,,,,0,5.000000e+000,1.000000e+000,4,4,2.209663e-003,0,,0,
1626358646.970,,1.000000e+002,1.300867e+001,2.897358e-004,2.571019e-008,-4.219881e-002,3.335824e-004,3,9.913895e-001,1.825000e+000,,,,,,,,,,,,,,,,,,0,5.000000e+000,1.000000e+000,4,4,2.490044e-003,0,,0,
1626358802.101,,1.000000e+002,1.351359e+001,2.987762e-004,1.004415e-007,-4.211184e-002,8.265100e-005,3,9.912823e-001,1.825000e+000,,,,,,,,,,,,,,,,,,0,5.000000e+000,1.000000e+000,4,4,1.422977e-002,0,,0,
1626358953.769,,1.000000e+002,1.401968e+001,3.116129e-004,1.970700e-007,-4.180210e-002,1.220207e-004,3,9.911961e-001,1.825000e+000,,,,,,,,,,,,,,,,,,0,5.000000e+000,1.000000e+000,4,4,1.282024e-002,0,,0,
1626359105.702,,1.000000e+002,1.450037e+001,3.288758e-004,1.174578e-007,-4.140767e-002,1.233836e-004,3,9.911596e-001,1.825000e+000,,,,,,,,,,,,,,,,,,0,5.000000e+000,1.000000e+000,4,4,5.059242e-003,0,,0,
1626359260.817,,1.000000e+002,1.499999e+001,3.528514e-004,1.294213e-007,-4.113350e-002,1.888789e-004,3,9.910507e-001,1.825000e+000,,,,,,,,,,,,,,,,,,0,5.000000e+000,1.000000e+000,4,4,4.819870e-003,0,,0,
1626359415.183,,1.000000e+002,1.550025e+001,3.795349e-004,1.230510e-007,-4.138160e-002,2.994403e-004,3,9.910272e-001,1.825000e+000,,,,,,,,,,,,,,,,,,0,5.000000e+000,1.000000e+000,4,4,4.509926e-003,0,,0,
1626359571.141,,1.000000e+002,1.600024e+001,3.958558e-004,1.409560e-007,-4.118620e-002,3.709523e-004,3,9.908761e-001,1.825000e+000,,,,,,,,,,,,,,,,,,0,5.000000e+000,1.000000e+000,4,4,3.430367e-003,0,,0,
1626359725.460,,1.000000e+002,1.650052e+001,3.920521e-004,2.078522e-008,-4.087379e-002,1.363315e-004,3,9.908894e-001,1.825000e+000,,,,,,,,,,,,,,,,,,0,5.000000e+000,1.000000e+000,4,4,3.648758e-003,0,,0,
1626359883.727,,1.000000e+002,1.699962e+001,3.798708e-004,6.200028e-008,-4.088080e-002,2.293834e-004,3,9.909172e-001,1.825000e+000,,,,,,,,,,,,,,,,,,0,5.000000e+000,1.000000e+000,4,4,4.650116e-003,0,,0,
1626360038.094,,1.000000e+002,1.750022e+001,3.677683e-004,1.704184e-008,-4.120742e-002,3.777012e-004,3,9.910011e-001,1.825000e+000,,,,,,,,,,,,,,,,,,0,5.000000e+000,1.000000e+000,4,4,4.100800e-003,0,,0,
1626360192.944,,1.000000e+002,1.799994e+001,3.573026e-004,2.342346e-008,-4.213513e-002,6.427414e-004,3,9.910745e-001,1.825000e+000,,,,,,,,,,,,,,,,,,0,5.000000e+000,1.000000e+000,4,4,4.339218e-003,0,,0,
1626360351.181,,1.000000e+002,1.850020e+001,3.485476e-004,2.893407e-008,-4.238673e-002,3.712748e-004,3,9.912947e-001,1.825000e+000,,,,,,,,,,,,,,,,,,0,5.000000e+000,1.000000e+000,4,4,4.590988e-003,0,,0,
1626360506.608,,1.000000e+002,1.900006e+001,3.410963e-004,1.008389e-007,-4.231033e-002,1.960265e-004,3,9.912286e-001,1.825000e+000,,,,,,,,,,,,,,,,,,0,5.000000e+000,1.000000e+000,4,4,3.860474e-003,0,,0,
1626360662.301,,1.000000e+002,1.949979e+001,3.346518e-004,2.736731e-008,-4.130592e-002,3.352911e-004,3,9.912671e-001,1.825000e+000,,,,,,,,,,,,,,,,,,0,5.000000e+000,1.000000e+000,4,4,1.020432e-003,0,,0,
1626360817.960,,1.000000e+002,1.999966e+001,3.289642e-004,3.578619e-008,-4.044314e-002,9.820652e-005,3,9.912171e-001,1.825000e+000,,,,,,,,,,,,,,,,,,0,5.000000e+000,1.000000e+000,4,4,2.140045e-003,0,,0,
1626360974.620,,1.000000e+002,2.050011e+001,3.238994e-004,2.268210e-008,-3.998564e-002,1.920679e-004,3,9.911878e-001,1.825000e+000,,,,,,,,,,,,,,,,,,0,5.000000e+000,1.000000e+000,4,4,1.689911e-003,0,,0,
1626361129.735,,1.000000e+002,2.099959e+001,3.192530e-004,2.995865e-008,-3.993369e-002,1.335612e-004,3,9.912508e-001,1.825000e+000,,,,,,,,,,,,,,,,,,0,5.000000e+000,1.000000e+000,4,4,1.178741e-003,0,,0,
1626361286.129,,1.000000e+002,2.149997e+001,3.150129e-004,2.933706e-008,-3.954368e-002,1.876993e-004,3,9.913152e-001,1.825000e+000,,,,,,,,,,,,,,,,,,0,5.000000e+000,1.000000e+000,4,4,6.084442e-004,0,,0,
1626361442.882,,1.000000e+002,2.200033e+001,3.109579e-004,1.667210e-008,-3.948400e-002,2.841144e-004,3,9.913558e-001,1.825000e+000,,,,,,,,,,,,,,,,,,0,5.000000e+000,1.000000e+000,4,4,1.928329e-003,0,,0,
1626361598.793,,1.000000e+002,2.250021e+001,3.071094e-004,1.020698e-008,-3.943442e-002,1.550050e-004,3,9.913214e-001,1.825000e+000,,,,,,,,,,,,,,,,,,0,5.000000e+000,1.000000e+000,4,4,4.018784e-003,0,,0,
1626361755.171,,1.000000e+002,2.300018e+001,3.034313e-004,4.778446e-008,-3.899534e-002,1.084225e-004,3,9.913321e-001,1.825000e+000,,,,,,,,,,,,,,,,,,0,5.000000e+000,1.000000e+000,4,4,4.180908e-003,0,,0,
1626361911.566,,1.000000e+002,2.349997e+001,2.998928e-004,1.465529e-008,-3.887757e-002,3.335541e-004,3,9.912531e-001,1.825000e+000,,,,,,,,,,,,,,,,,,0,5.000000e+000,1.000000e+000,4,4,5.090714e-003,0,,0,
1626362068.476,,1.000000e+002,2.400040e+001,2.964943e-004,2.076257e-008,-3.821378e-002,2.365611e-004,3,9.913657e-001,1.825000e+000,,,,,,,,,,,,,,,,,,0,5.000000e+000,1.000000e+000,4,4,6.801605e-003,0,,0,
1626362226.259,,1.000000e+002,2.450035e+001,2.931160e-004,3.834034e-008,-3.883369e-002,9.167111e-005,3,9.913020e-001,1.825000e+000,,,,,,,,,,,,,,,,,,0,5.000000e+000,1.000000e+000,4,4,7.860184e-003,0,,0,
1626362382.116,,1.000000e+002,2.500083e+001,2.898560e-004,1.229967e-008,-3.895274e-002,5.031399e-004,3,9.914252e-001,1.825000e+000,,,,,,,,,,,,,,,,,,0,5.000000e+000,1.000000e+000,4,4,8.979797e-003,0,,0,
1626363712.288,,1.000000e+002,2.600163e+001,2.835627e-004,2.991247e-008,-3.860018e-002,1.136187e-004,3,9.914157e-001,1.825000e+000,,,,,,,,,,,,,,,,,,0,5.000000e+000,1.000000e+000,4,4,2.639771e-003,0,,0,
1626363871.678,,1.000000e+002,2.800993e+001,2.714607e-004,2.279929e-008,-3.810914e-002,2.083915e-004,3,9.913756e-001,1.825000e+000,,,,,,,,,,,,,,,,,,0,5.000000e+000,1.000000e+000,4,4,7.078171e-003,0,,0,
1626364031.346,,1.000000e+002,3.001248e+001,2.599953e-004,3.944667e-008,-3.772583e-002,1.566730e-004,3,9.914514e-001,1.825000e+000,,,,,,,,,,,,,,,,,,0,5.000000e+000,1.000000e+000,4,4,9.231567e-003,0,,0,
1626364193.697,,1.000000e+002,3.201455e+001,2.492843e-004,3.145912e-008,-3.710395e-002,1.655165e-004,3,9.915847e-001,1.825000e+000,,,,,,,,,,,,,,,,,,0,5.000000e+000,1.000000e+000,4,4,7.812500e-003,0,,0,
1626364357.239,,1.000000e+002,3.401799e+001,2.391908e-004,4.754068e-008,-3.599935e-002,2.697376e-004,3,9.915718e-001,1.825000e+000,,,,,,,,,,,,,,,,,,0,5.000000e+000,1.000000e+000,4,4,1.168060e-002,0,,0,
1626364524.219,,1.000000e+002,3.602130e+001,2.298513e-004,2.822939e-008,-3.539827e-002,2.026164e-004,3,9.917116e-001,1.825000e+000,,,,,,,,,,,,,,,,,,0,5.000000e+000,1.000000e+000,4,4,1.465988e-002,0,,0,
1626364693.608,,1.000000e+002,3.802325e+001,2.211674e-004,2.838531e-008,-3.509670e-002,2.077397e-004,3,9.917767e-001,1.825000e+000,,,,,,,,,,,,,,,,,,0,5.000000e+000,1.000000e+000,4,4,1.625824e-002,0,,0,
1626364864.854,,1.000000e+002,4.002692e+001,2.127969e-004,2.625333e-008,-3.404208e-002,1.753811e-004,3,9.917597e-001,1.825000e+000,,,,,,,,,,,,,,,,,,0,5.000000e+000,1.000000e+000,4,4,2.186966e-002,0,,0,
1626365038.315,,1.000000e+002,4.202972e+001,2.048297e-004,2.814749e-008,-3.313155e-002,1.484029e-004,3,9.918492e-001,1.825000e+000,,,,,,,,,,,,,,,,,,0,5.000000e+000,1.000000e+000,4,4,1.961136e-002,0,,0,
1626365210.948,,1.000000e+002,4.403339e+001,1.972366e-004,1.391203e-008,-3.316346e-002,6.500014e-004,3,9.918167e-001,1.825000e+000,,,,,,,,,,,,,,,,,,0,5.000000e+000,1.000000e+000,4,4,2.095795e-002,0,,0,
1626365382.694,,1.000000e+002,4.603958e+001,1.901522e-004,3.657499e-008,-3.217264e-002,2.405836e-004,3,9.918910e-001,1.825000e+000,,,,,,,,,,,,,,,,,,0,5.000000e+000,1.000000e+000,4,4,2.492142e-002,0,,0,
1626365552.661,,1.000000e+002,4.804420e+001,1.834384e-004,4.308676e-008,-3.115337e-002,5.825394e-005,3,9.918615e-001,1.825000e+000,,,,,,,,,,,,,,,,,,0,5.000000e+000,1.000000e+000,4,4,2.254868e-002,0,,0,
1626365722.551,,1.000000e+002,5.005001e+001,1.771497e-004,4.557305e-008,-3.045939e-002,2.037629e-004,3,9.919170e-001,1.825000e+000,,,,,,,,,,,,,,,,,,0,5.000000e+000,1.000000e+000,4,4,2.917862e-002,0,,0,
1626365924.371,,1.000000e+002,5.504296e+001,1.628061e-004,6.001020e-008,-2.977822e-002,5.186648e-004,3,9.921755e-001,1.825000e+000,,,,,,,,,,,,,,,,,,0,5.000000e+000,1.000000e+000,4,4,2.757263e-002,0,,0,
1626366127.469,,1.000000e+002,6.007369e+001,1.500751e-004,6.787548e-008,-2.778805e-002,5.494012e-004,3,9.922748e-001,1.825000e+000,,,,,,,,,,,,,,,,,,0,5.000000e+000,1.000000e+000,4,4,4.470825e-002,0,,0,
1626366332.925,,1.000000e+002,6.508949e+001,1.389509e-004,1.882975e-008,-2.653107e-002,1.386693e-004,3,9.922863e-001,1.825000e+000,,,,,,,,,,,,,,,,,,0,5.000000e+000,1.000000e+000,4,4,4.998779e-002,0,,0,
1626366541.236,,1.000000e+002,7.010086e+001,1.289635e-004,3.061371e-008,-2.803846e-002,3.295378e-005,3,9.920094e-001,1.825000e+000,,,,,,,,,,,,,,,,,,0,5.000000e+000,1.000000e+000,4,4,6.206512e-002,0,,0,
1626366750.530,,1.000000e+002,7.511282e+001,1.203705e-004,3.426976e-008,-2.879410e-002,5.240042e-004,3,9.919544e-001,1.825000e+000,,,,,,,,,,,,,,,,,,0,5.000000e+000,1.000000e+000,4,4,6.048584e-002,0,,0,
1626366961.026,,1.000000e+002,8.012104e+001,1.128746e-004,3.042552e-008,-2.774747e-002,4.144165e-004,3,9.920744e-001,1.825000e+000,,,,,,,,,,,,,,,,,,0,5.000000e+000,1.000000e+000,4,4,7.732391e-002,0,,0,
1626367172.582,,1.000000e+002,8.514030e+001,1.061556e-004,3.740075e-008,-2.620312e-002,1.063856e-004,3,9.920781e-001,1.825000e+000,,,,,,,,,,,,,,,,,,0,5.000000e+000,1.000000e+000,4,4,8.647156e-002,0,,0,
1626367385.199,,1.000000e+002,9.015485e+001,1.001183e-004,3.586203e-008,-2.503027e-002,1.002303e-004,3,9.921809e-001,1.825000e+000,,,,,,,,,,,,,,,,,,0,5.000000e+000,1.000000e+000,4,4,1.037064e-001,0,,0,
1626367597.818,,1.000000e+002,9.516570e+001,9.469615e-005,3.077022e-008,-2.337246e-002,2.321912e-004,3,9.922956e-001,1.825000e+000,,,,,,,,,,,,,,,,,,0,5.000000e+000,1.000000e+000,4,4,8.629608e-002,0,,0,
1626367809.639,,1.000000e+002,1.001750e+002,8.980482e-005,4.436087e-008,-2.105723e-002,3.563882e-004,3,9.921757e-001,1.825000e+000,,,,,,,,,,,,,,,,,,0,5.000000e+000,1.000000e+000,4,4,1.224060e-001,0,,0,
1626368072.135,,1.000000e+002,1.102111e+002,8.129603e-005,4.140785e-008,-1.787432e-002,4.626350e-004,3,9.920895e-001,1.825000e+000,,,,,,,,,,,,,,,,,,0,5.000000e+000,1.000000e+000,4,4,1.027985e-001,0,,0,
1626368336.466,,1.000000e+002,1.202344e+002,7.402137e-005,6.728398e-008,-1.387536e-002,1.350076e-003,3,9.917877e-001,1.825000e+000,,,,,,,,,,,,,,,,,,0,5.000000e+000,1.000000e+000,4,4,1.434021e-001,0,,0,
1626368595.465,,1.000000e+002,1.302597e+002,6.801747e-005,1.118447e-008,-6.831267e-003,1.364029e-003,3,9.912862e-001,1.825000e+000,,,,,,,,,,,,,,,,,,0,5.000000e+000,1.000000e+000,4,4,1.707916e-001,0,,0,
1626368852.354,,1.000000e+002,1.402789e+002,6.294071e-005,5.217191e-008,1.998138e-003,5.351809e-004,3,9.905960e-001,1.825000e+000,,,,,,,,,,,,,,,,,,0,5.000000e+000,1.000000e+000,4,4,1.882019e-001,0,,0,
1626369105.547,,1.000000e+002,1.503046e+002,5.848584e-005,6.334204e-008,6.418079e-003,2.170103e-004,3,9.896868e-001,1.825000e+000,,,,,,,,,,,,,,,,,,0,5.000000e+000,1.000000e+000,4,4,2.196960e-001,0,,0,
1626369355.324,,1.000000e+002,1.603327e+002,5.471155e-005,2.075581e-008,1.304380e-002,3.090451e-004,3,9.882361e-001,1.825000e+000,,,,,,,,,,,,,,,,,,0,5.000000e+000,1.000000e+000,4,4,1.988983e-001,0,,0,
1626369602.653,,1.000000e+002,1.703548e+002,5.124856e-005,3.038051e-008,1.760769e-002,4.951924e-005,3,9.870817e-001,1.825000e+000,,,,,,,,,,,,,,,,,,0,5.000000e+000,1.000000e+000,4,4,2.488098e-001,0,,0,
1626369848.998,,1.000000e+002,1.803631e+002,4.819448e-005,1.491522e-008,2.223392e-002,1.603079e-004,3,9.861604e-001,1.825000e+000,,,,,,,,,,,,,,,,,,0,5.000000e+000,1.000000e+000,4,4,2.575073e-001,0,,0,
1626370093.673,,1.000000e+002,1.903871e+002,4.545711e-005,2.655861e-008,2.687009e-002,1.349997e-004,3,9.850711e-001,1.825000e+000,,,,,,,,,,,,,,,,,,0,5.000000e+000,1.000000e+000,4,4,2.865906e-001,0,,0,
1626370332.374,,1.000000e+002,2.004201e+002,4.300487e-005,2.897804e-008,3.186172e-002,2.842930e-004,3,9.837658e-001,1.825000e+000,,,,,,,,,,,,,,,,,,0,5.000000e+000,1.000000e+000,4,4,3.088989e-001,0,,0,
1626370573.897,,1.000000e+002,2.104131e+002,4.082688e-005,6.020328e-008,3.865453e-002,1.867171e-003,3,9.826108e-001,1.825000e+000,,,,,,,,,,,,,,,,,,0,5.000000e+000,1.000000e+000,4,4,3.123016e-001,0,,0,
1626370814.906,,1.000000e+002,2.204284e+002,3.889657e-005,3.900638e-008,4.897529e-002,2.435383e-003,3,9.807075e-001,1.825000e+000,,,,,,,,,,,,,,,,,,0,5.000000e+000,1.000000e+000,4,4,3.327942e-001,0,,0,
1626371054.308,,1.000000e+002,2.304397e+002,3.710695e-005,1.442732e-008,5.815609e-002,2.763779e-004,3,9.792273e-001,1.825000e+000,,,,,,,,,,,,,,,,,,0,5.000000e+000,1.000000e+000,4,4,3.414001e-001,0,,0,
1626371292.667,,1.000000e+002,2.404548e+002,3.544176e-005,1.878202e-008,6.555326e-002,7.746971e-004,3,9.777496e-001,1.825000e+000,,,,,,,,,,,,,,,,,,0,5.000000e+000,1.000000e+000,4,4,3.414001e-001,0,,0,
1626371527.266,,1.000000e+002,2.504744e+002,3.388901e-005,1.606190e-008,7.222721e-002,1.389925e-004,3,9.765306e-001,1.825000e+000,,,,,,,,,,,,,,,,,,0,5.000000e+000,1.000000e+000,4,4,3.643036e-001,0,,0,
1626371764.330,,1.000000e+002,2.604610e+002,3.249014e-005,1.828802e-008,7.935648e-002,1.999191e-004,3,9.750050e-001,1.825000e+000,,,,,,,,,,,,,,,,,,0,5.000000e+000,1.000000e+000,4,4,4.237061e-001,0,,0,
1626372001.595,,1.000000e+002,2.704789e+002,3.121650e-005,3.801527e-009,8.682663e-002,3.317115e-004,3,9.735029e-001,1.825000e+000,,,,,,,,,,,,,,,,,,0,5.000000e+000,1.000000e+000,4,4,4.039917e-001,0,,0,
1626372238.565,,1.000000e+002,2.804922e+002,3.012059e-005,8.327131e-009,9.366416e-002,2.171974e-004,3,9.725212e-001,1.825000e+000,,,,,,,,,,,,,,,,,,0,5.000000e+000,1.000000e+000,4,4,3.941040e-001,0,,0,
1626372477.453,,1.000000e+002,2.904872e+002,2.902397e-005,1.682229e-008,1.047359e-001,1.707652e-004,3,9.715353e-001,1.825000e+000,,,,,,,,,,,,,,,,,,0,5.000000e+000,1.000000e+000,4,4,3.788147e-001,0,,0,
1626372716.059,,1.000000e+002,3.004869e+002,2.804765e-005,8.767312e-009,1.172839e-001,2.550142e-004,3,9.699171e-001,1.825000e+000,,,,,,,,,,,,,,,,,,0,5.000000e+000,1.000000e+000,4,4,3.973999e-001,0,,0,