File: MPMS/NiCl2pym/NiCl2pym_MvH_1p8K_14T.dat
[Header]
; ACMS II Data File (default extension .dat)
; Copyright (c) 2014, Quantum Design, Inc. All rights reserved.
TITLE,
FILEOPENTIME,3875287827.139,10/18/2022,8:51 pm
BYAPP,ACMS II,1.0,1.2
INFO,DYNACOOL ACMS II Option Release 1.0.8 Build 33,APPNAME
INFO,Quantum Design Linear Motor Servo Controller,MOTOR_MODULE_NAME
INFO,3101-100 K0,MOTOR_HW_VERSION
INFO,MMC794,MOTOR_SERIAL_NUMBER
INFO,SRV No X-over 01.03.11,MOTOR_SOFTWARE_VERSION
INFO,ACMS,ACMS_MODULE_NAME
INFO,3101-430 A0,ACMS_HW_VERSION
INFO,ACMSII028,ACMS_SERIAL_NUMBER
INFO,00.14.14,ACMS_SOFTWARE_VERSION
INFO,WF046,COIL_SERIAL_NUMBER
INFO,0,MOMENT_UNITS
INFO,NiCl2pym,SAMPLE_MATERIAL
INFO,7.3mg cling film,SAMPLE_COMMENT
INFO,17.2,SAMPLE_MASS
INFO,,SAMPLE_VOLUME
INFO,,SAMPLE_MOLECULAR_WEIGHT
INFO,,SAMPLE_SIZE
INFO,,SAMPLE_SHAPE
DATATYPE,COMMENT,1
DATATYPE,TIME,2
STARTUPAXIS,X,2
STARTUPAXIS,Y1,5
STARTUPGROUP, AC
FIELDGROUP, AC, 2,3,4,5,6,7,8,9,10,11,12,13,14,15,16,20,21,22,23,24,25,35,43,44,45,46,47,48,49
FIELDGROUP, DC, 2,3,4,17,18,19,20,21,23,24,25,35,36,37,43,44,45,46,47,48,49,50,51
FIELDGROUP, Diagnostic, 26,27,28,29,30,31,32,33,34,38,39,40,41,42,52,53,54,55,56,57,58,59,60,61,62,63,64,65,66,67,68,69
[Data]
Comment,Time Stamp (sec),Temperature (K),Magnetic Field (Oe),AC Moment (emu),AC Std. Dev. (emu),AC Phase (deg),AC Phase Std. Dev. (deg),AC Suscept. (emu/Oe),AC Suscept. Std. Dev. (emu/Oe),AC X'  (emu/Oe),AC X" (emu/Oe),AC X' Std. Dev. (emu/Oe),AC X" Std. Dev. (emu/Oe),AC Drive (Oe),AC Frequency (Hz),DC Moment (emu),DC Std. Err. (emu),DC Quad. Moment (emu),Range (mV),"AC=1 DC=2 Locate=3",Measure Type,Measure Count,Measure Time (sec),Measure Number,AC X' Raw (emu/Oe),AC X" Raw (emu/Oe),DC M. Raw' (emu),DC M. Raw" (emu),Coil InPhase (V),Coil Quadrature (V),Null Status,Trim Ratio,Trim Phase (deg.),Max. Signal (mV),Motor Frequency (Hz),Motor Ampl. (mm),System Temp. (K),Min. Temperature (K),Max. Temperature (K),Min. Field (Oe),Max. Field (Oe),Pressure (Torr),Temp. Status (code),Field Status (code),Chamber Status (code),Measure Status (code),Center Position (mm),Transport Action,Motor Lag (deg),Motor Current (amps),Motor Heatsink Temp. (C),Motor Board Temp. (C),QMap 01,QMap 02,QMap 03,QMap 04,QMap 05,QMap 06,QMap 07,QMap 08,QMap 09,QMap 10,QMap 11,QMap 12,QMap 13,QMap 14,QMap 15,QMap 16
sample offset = 27.08 mm,3875288833.97697,1.80462453365326,0.711450517177582,,,,,,,,,,,,,0.0573985432768195,4.24342703482045E-6,-8.17372683957908E-5,1,2,,80,2,1,,,0.0552799760669335,0.000205396266423047,0.00033780443482101,-0.000118326919618994,,,,0.0140253263534548,39.995735168457,1.99848566590251,1.79960310459137,1.8037406206131,1.80527281761169,0.711450517177582,0.711450517177582,0.0575042776763439,1,4,3,0,23.3230000458956,1,20.7019672290305,1.1163330078125,31.7693061828613,32.7468223571777,,,,,,,,,,,,,,,,
,3875288981.97859,1.80064329504967,1640.58868408203,,,,,,,,,,,,,0.0627000763823964,1.16147307894395E-5,-0.000147175507142436,1,2,,80,2,70,,,0.0603877663349465,0.000175486831383256,0.000369099405361339,-0.000129036750877276,,,,0.0153201256779297,39.995735168457,1.99851163982236,1.79783093929291,1.80061936378479,1.80068266391754,1585.59729003906,1695.580078125,0.058670911937952,1,6,3,0,23.3230000458956,1,20.7134670954347,1.12541198730469,40.0782012939453,33.7243423461914,,,,,,,,,,,,,,,,
,3875289129.67676,1.80256268382072,9023.576171875,,,,,,,,,,,,,0.0877074761704765,1.26609925617385E-5,-0.000154784068221227,1,2,,80,2,139,,,0.0844894169237126,0.000358945123390159,0.000516151078045368,-0.000181267663720064,,,,0.0214339319343473,39.995735168457,1.99848269126629,1.7930463552475,1.80246961116791,1.80266308784485,8968.505859375,9078.646484375,0.0587016232311726,1,6,3,0,23.3230000458956,1,20.7178039015359,1.11686706542969,41.5444793701172,35.190616607666,,,,,,,,,,,,,,,,
,3875289276.43281,1.80402526855469,16361.708984375,,,,,,,,,,,,,0.110405835960348,1.42523948988754E-5,-0.000116520773751254,1,2,,80,2,208,,,0.106383220470063,0.000622602952274162,0.000649560301098973,-0.000229303739615716,,,,0.0269896487149889,39.995735168457,1.99855936209071,1.78383183479309,1.80392265319824,1.80409860610962,16309.189453125,16414.228515625,0.0584303624927998,1,6,3,0,23.3230000458956,1,20.7188140866021,1.11808776855469,41.5444793701172,36.1681327819824,,,,,,,,,,,,,,,,
,3875289420.41889,1.8028989136219,23571.0654296875,,,,,,,,,,,,,0.130699554383771,1.32996034155151E-5,-5.76734037025877E-5,1,2,,80,2,277,,,0.125978471328947,0.000933446159723093,0.000768793921452016,-0.00027276822947897,,,,0.0319620061881984,39.995735168457,1.99859135485217,1.77457618713379,1.80284261703491,1.8029842376709,23521.12890625,23621.001953125,0.0580433458089828,1,6,3,0,23.3230000458956,1,20.7205626370055,1.12533569335938,42.5219955444336,37.6344108581543,,,,,,,,,,,,,,,,
,3875289563.94308,1.80154311656952,30771.7841796875,,,,,,,,,,,,,0.149492958124332,1.73057236143857E-5,9.28014565842777E-5,10,2,,80,2,347,,,0.144148172099975,0.00136185326512109,0.000879089988302439,-0.000313915981678292,,,,0.0365757218469727,39.995735168457,1.99867412686653,1.76738929748535,1.8013790845871,1.80197370052338,30721.623046875,30821.9453125,0.0579433254897594,1,6,3,0,23.3230000458956,1,20.7203446378008,1.11717224121094,43.0107536315918,37.6344108581543,,,,,,,,,,,,,,,,
,3875289705.43986,1.80116291046143,37867.572265625,,,,,,,,,,,,,0.167128459665079,1.8012304989422E-5,0.000160470300519079,10,2,,80,2,416,,,0.161224633797311,0.00173538044491021,0.000982756377197802,-0.000352405739249662,,,,0.0409081375082249,39.995735168457,1.99863057568814,1.76298594474792,1.80110168457031,1.80124759674072,37817.37890625,37917.765625,0.0576250702142715,1,6,3,0,23.3230000458956,1,20.7209849894985,1.11686706542969,43.0107536315918,38.1231689453125,,,,,,,,,,,,,,,,
,3875289846.90731,1.80086356401443,44959.208984375,,,,,,,,,,,,,0.184270492075874,2.14077979929335E-5,0.000191236256792556,10,2,,80,2,485,,,0.17785100229402,0.00210198633803614,0.00108370347879827,-0.000389851426007226,,,,0.0451265804608344,39.995735168457,1.99859996977425,1.76006650924683,1.80070054531097,1.80100655555725,44906.55859375,45011.859375,0.0575370639562607,1,6,3,0,23.3230000458956,1,20.7189455754682,1.12518310546875,43.0107536315918,38.1231689453125,,,,,,,,,,,,,,,,
,3875289988.36932,1.8010267496109,52055.02734375,,,,,,,,,,,,,0.201508725839957,2.31515729731635E-5,0.000216607673277851,10,2,,80,2,554,,,0.194598564308645,0.00249554430298362,0.00118533952627331,-0.000427669117925689,,,,0.0493756229407879,39.995735168457,1.99855402704826,1.7571827173233,1.80089128017426,1.80116581916809,52002.3046875,52107.75,0.0575556606054306,1,6,3,0,23.3230000458956,1,20.7150573459357,1.11709594726562,43.0107536315918,38.6119270324707,,,,,,,,,,,,,,,,
,3875290129.8312,1.80099244117737,59145.341796875,,,,,,,,,,,,,0.219028779233806,2.33305564964078E-5,0.00023483494729597,10,2,,80,2,623,,,0.211649188985258,0.00291428418427872,0.00128885183949023,-0.000466388213681057,,,,0.0537055538291978,39.995735168457,1.99867440963588,1.75528120994568,1.80083656311035,1.80114555358887,59092.671875,59198.01171875,0.0572969391942024,1,6,3,0,23.3230000458956,1,20.7148501816441,1.11709594726562,43.49951171875,39.1006851196289,,,,,,,,,,,,,,,,
,3875290271.28604,1.80055153369904,66239.9140625,,,,,,,,,,,,,0.237278571899758,2.07874560168754E-5,0.000184388517044202,10,2,,80,2,692,,,0.229439692487358,0.00330292488556989,0.00139688386116177,-0.000506437267176807,,,,0.0582195406468633,39.995735168457,1.99865897435322,1.75363993644714,1.80031728744507,1.80082869529724,66187.1875,66292.640625,0.0572689920663834,1,6,3,0,23.3230000458956,1,20.71365107919,1.11701965332031,43.49951171875,39.1006851196289,,,,,,,,,,,,,,,,
,3875290412.76899,1.80125772953033,73336.41796875,,,,,,,,,,,,,0.262052323905877,2.34615945629422E-5,0.000183816663591086,10,2,,80,2,761,,,0.253578846240875,0.00385623560194577,0.00154338241554797,-0.000560992571990937,,,,0.0643441255276356,39.995735168457,1.99862957915164,1.75108909606934,1.80115103721619,1.80135905742645,73283.7109375,73389.125,0.0571539737284183,1,6,3,0,23.3230000458956,1,20.7144757605745,1.11701965332031,43.49951171875,39.1006851196289,,,,,,,,,,,,,,,,
,3875290554.25135,1.80109071731567,80468.85546875,,,,,,,,,,,,,0.288761308257236,2.54057498990428E-5,7.7825293280321E-5,10,2,,80,2,830,,,0.279642202901788,0.00436984177025601,0.00170174881350249,-0.000619392842054367,,,,0.0709578153688075,39.995735168457,1.99862021701798,1.74855256080627,1.80086433887482,1.80133032798767,80415.6171875,80522.09375,0.057061892002821,1,6,3,0,23.3230000458956,1,20.7153408682878,1.11686706542969,43.49951171875,39.1006851196289,,,,,,,,,,,,,,,,
,3875290695.71196,1.80136922001839,87639.94140625,,,,,,,,,,,,,0.315354970273396,1.94979873863672E-5,-7.93856765359568E-6,10,2,,80,2,899,,,0.30564765140506,0.00493373855420823,0.00185980682726949,-0.000677616102620959,,,,0.0775578810535792,39.995735168457,1.99863246757233,1.74539113044739,1.8009740114212,1.80169296264648,87589.1796875,87690.703125,0.0569394044578075,1,6,3,0,23.3230000458956,1,20.7047023832091,1.12411499023438,43.0107536315918,39.5894432067871,,,,,,,,,,,,,,,,
,3875290837.17253,1.80075769424438,94812.09765625,,,,,,,,,,,,,0.341062490067812,2.69472722796378E-5,-0.000155124562892227,10,2,,80,2,968,,,0.330848994503931,0.00544990434958553,0.00201275758445263,-0.00073386135045439,,,,0.0839435516340105,39.995735168457,1.99838980505014,1.74282240867615,1.80045771598816,1.8011394739151,94758.875,94865.3203125,0.0569359101355076,1,6,3,0,23.3230000458956,1,20.6987839901781,1.11625671386719,43.49951171875,39.1006851196289,,,,,,,,,,,,,,,,
,3875290978.64164,1.80134410858154,101986.015625,,,,,,,,,,,,,0.365744625748136,2.94365285490597E-5,-0.000387185446394821,10,2,,80,2,1037,,,0.355110228067943,0.00588634186597527,0.0021602523047477,-0.000787588127423078,,,,0.0900949905205015,39.995735168457,1.99827499435749,1.73945081233978,1.80069267749786,1.80175089836121,101932.703125,102039.328125,0.0567662268877029,1,6,3,0,23.3230000458956,1,20.6916660504558,1.12472534179688,43.49951171875,39.5894432067871,,,,,,,,,,,,,,,,
,3875291120.08591,1.80165498256683,109157.421875,,,,,,,,,,,,,0.389408055038868,2.75908020608927E-5,-0.000545199066841633,10,2,,80,2,1106,,,0.378432503007429,0.00639053840127338,0.00230167270638049,-0.000839907967019826,,,,0.0960038878374232,39.995735168457,1.99807611044423,1.73570680618286,1.80143547058105,1.80189728736877,109106.6875,109208.15625,0.0564354173839092,1,6,3,0,23.3230000458956,1,20.6905752943857,1.11564636230469,43.9882698059082,39.5894432067871,,,,,,,,,,,,,,,,
,3875291261.58055,1.80151655673981,116332.5859375,,,,,,,,,,,,,0.412327841867986,5.69065060086064E-5,-0.00073562484261633,10,2,,80,2,1175,,,0.401082342998884,0.00685815165343397,0.00243930332362652,-0.000890627678018063,,,,0.101750930523871,39.995735168457,1.99809515049768,1.73132073879242,1.801309466362,1.80186009407043,116281.84375,116383.328125,0.0563542060554028,1,6,3,0,23.3230000458956,1,20.6887119994876,1.11854553222656,43.49951171875,39.5894432067871,,,,,,,,,,,,,,,,
,3875291403.04633,1.80193114280701,123504.19921875,,,,,,,,,,,,,0.434504063713034,2.97970682265938E-5,-0.000905943567418473,10,2,,80,2,1244,,,0.423055569728839,0.00733469882150839,0.00257268780842423,-0.000940007739700377,,,,0.107323339050798,39.995735168457,1.99806019615612,1.72628951072693,1.80173707008362,1.80212140083313,123451,123557.3984375,0.0560913421213627,1,6,3,0,23.3230000458956,1,20.6884090473555,1.12403869628906,44.9657897949219,39.5894432067871,,,,,,,,,,,,,,,,
,3875291544.51167,1.80170440673828,130677.1484375,,,,,,,,,,,,,0.455801935000589,3.8460603778627E-5,-0.00112812377002963,10,2,,80,2,1313,,,0.44421905349767,0.00774284509332002,0.00270126457326114,-0.000987215316854417,,,,0.112690866257473,39.995735168457,1.9980196781793,1.72145593166351,1.80139684677124,1.80214619636536,130626.5390625,130727.7578125,0.0559136122465134,1,6,3,0,23.3230000458956,1,20.6873642597919,1.11686706542969,43.49951171875,39.5894432067871,,,,,,,,,,,,,,,,
,3875291685.97436,1.80250723361969,137852.1875,,,,,,,,,,,,,0.476328074786708,3.87017050713164E-5,-0.00128919983695273,10,2,,80,2,1382,,,0.464670563146408,0.00819031620077321,0.00282540917396545,-0.00103303755167872,,,,0.117876123898452,39.995735168457,1.997959170141,1.71569514274597,1.80203783512115,1.80287051200867,137801.46875,137902.90625,0.0555962547659874,1,6,3,0,23.3230000458956,1,20.6842301278035,1.11785888671875,43.49951171875,39.5894432067871,,,,,,,,,,,,,,,,
,3875291827.44835,1.80037136077881,140000.390625,,,,,,,,,,,,,0.482499886933932,3.96583393707395E-5,-0.00136250297206145,10,2,,80,2,1451,,,0.470827475034509,0.00829883187592478,0.00286281830631197,-0.00104701146483421,,,,0.119441937499718,39.995735168457,1.9980076526274,1.7126556634903,1.79997670650482,1.80097472667694,140000.390625,140000.390625,0.0555723384022713,1,4,3,0,23.3230000458956,1,20.6894604064991,1.11709594726562,43.49951171875,39.5894432067871,,,,,,,,,,,,,,,,
,3875291968.91185,1.79782682657242,134281.5,,,,,,,,,,,,,0.467704514847152,4.06316645618762E-5,-0.00121456024292864,10,2,,80,2,1520,,,0.456039542022579,0.00799436097920006,0.00277303834445775,-0.00101380108390003,,,,0.115691266104441,39.995735168457,1.99802252945598,1.71507143974304,1.79733049869537,1.79822957515717,134229.546875,134333.453125,0.0556375607848167,1,6,3,0,23.3230000458956,1,20.688122668136,1.116943359375,43.9882698059082,39.5894432067871,,,,,,,,,,,,,,,,
,3875292110.37501,1.79774875640869,127281.35546875,,,,,,,,,,,,,0.448964556129071,3.64569825965378E-5,-0.00103445219259696,10,2,,80,2,1589,,,0.437356125929002,0.00760107720483261,0.00265980418771505,-0.000971781613770872,,,,0.110958140272764,39.995735168457,1.99816138054993,1.72074747085571,1.79753935337067,1.79801511764526,127229.4296875,127333.28125,0.0558704249560833,1,6,3,0,23.3230000458956,1,20.6849164874713,1.11778259277344,43.0107536315918,40.0782012939453,,,,,,,,,,,,,,,,
,3875292251.87223,1.79811102151871,120285.02734375,,,,,,,,,,,,,0.429645861870943,3.5603455809669E-5,-0.000862898882489053,10,2,,80,2,1658,,,0.418146851281558,0.00718333905008706,0.00254284217953682,-0.000928664754610509,,,,0.106073059540317,39.995735168457,1.99795648260179,1.72541546821594,1.79799807071686,1.79830884933472,120235.4296875,120334.625,0.0560714639723301,1,6,3,0,23.3230000458956,1,20.6887776236478,1.11671447753906,43.49951171875,39.5894432067871,,,,,,,,,,,,,,,,
,3875292393.32094,1.79838761687279,113287.84375,,,,,,,,,,,,,0.409574783258243,5.41663413108231E-5,-0.00058908754838386,10,2,,80,2,1727,,,0.39824363816718,0.00684933601394065,0.002421680605039,-0.000884332810528576,,,,0.101016972476255,39.995735168457,1.99782697722989,1.73028969764709,1.79823803901672,1.79847550392151,113235.9140625,113339.7734375,0.0562786422669888,1,6,3,0,23.3230000458956,1,20.6859100042424,1.11648559570312,43.49951171875,39.5894432067871,,,,,,,,,,,,,,,,
,3875292534.78631,1.79863204956055,106288.1953125,,,,,,,,,,,,,0.388479156196873,2.43087230182589E-5,-0.00044686050828524,10,2,,80,2,1796,,,0.377389513516107,0.00637125515534498,0.00229514040984213,-0.000837568542920053,,,,0.0957308094927026,39.995735168457,1.99792078147276,1.73455655574799,1.79834973812103,1.79885268211365,106236.3359375,106340.0546875,0.056505348533392,1,6,3,0,23.3230000458956,1,20.6918045301932,1.1175537109375,43.49951171875,39.5894432067871,,,,,,,,,,,,,,,,
,3875292676.27407,1.79861006736755,99288.9609375,,,,,,,,,,,,,0.366229975960852,2.66058646197828E-5,-0.000272980964351463,10,2,,80,2,1865,,,0.355459924270573,0.00591121825522524,0.00216204347088933,-0.000788437086157501,,,,0.0901715796011053,39.995735168457,1.9980147741744,1.73840379714966,1.79826879501343,1.79901099205017,99236.921875,99341,0.0565817579627037,1,6,3,0,23.3230000458956,1,20.6931745044046,1.11717224121094,43.49951171875,39.1006851196289,,,,,,,,,,,,,,,,
,3875292817.72804,1.79870134592056,92291.4921875,,,,,,,,,,,,,0.342470630589279,2.43655810996134E-5,-0.000104040248339641,10,2,,80,2,1934,,,0.332113039528825,0.00543411335535648,0.00202027591876686,-0.000736165035050362,,,,0.0842519492967205,39.995735168457,1.99807713216335,1.74185836315155,1.7985372543335,1.79887199401855,92242.0390625,92340.9453125,0.0567604340612888,1,6,3,0,23.3230000458956,1,20.6941452499154,1.11831665039062,43.49951171875,39.1006851196289,,,,,,,,,,,,,,,,
,3875292959.20309,1.79896408319473,85291.28125,,,,,,,,,,,,,0.316610816418398,2.87891359729244E-5,-3.05217289275922E-7,10,2,,80,2,2003,,,0.306781125577129,0.00487969774431135,0.00186644704081118,-0.00067910848883912,,,,0.0778231260452724,39.995735168457,1.9980320606706,1.74514627456665,1.798832654953,1.79905498027802,85241.8125,85340.75,0.0568951405584812,1,6,3,0,23.3230000458956,1,20.6930840953759,1.11763000488281,43.49951171875,37.1456527709961,,,,,,,,,,,,,,,,
,3875293100.68742,1.79904613494873,78292.375,,,,,,,,,,,,,0.288350923290593,2.44462336935741E-5,0.00010166024519448,10,2,,80,2,2072,,,0.279177244506112,0.00431452598385736,0.00169873819686472,-0.000617230485659093,,,,0.0708189050369407,39.995735168457,1.99799492010607,1.74821996688843,1.79895842075348,1.79910516738892,78242.90625,78341.84375,0.0568356774747372,1,6,3,0,23.3230000458956,1,20.6934279356422,1.1181640625,43.49951171875,39.1006851196289,,,,,,,,,,,,,,,,
,3875293242.12413,1.79960527420044,71294.453125,,,,,,,,,,,,,0.257944731771949,2.72298948293531E-5,0.00018412486998173,10,2,,80,2,2141,,,0.249550817949556,0.00373532025693409,0.00151874055154622,-0.000551066303160042,,,,0.0633050459389357,39.995735168457,1.99804863291627,1.75100469589233,1.79938530921936,1.79968929290771,71242.578125,71346.328125,0.057051494717598,1,6,3,0,23.3230000458956,1,20.6958608400171,1.1248779296875,43.49951171875,39.5894432067871,,,,,,,,,,,,,,,,
,3875293383.6117,1.79878346920013,64297.2109375,,,,,,,,,,,,,0.232145683074167,2.28049716978512E-5,0.000192501058194824,10,2,,80,2,2210,,,0.224433617900374,0.00318664311524873,0.00136633322108537,-0.000494857260491699,,,,0.0569393671531123,39.995735168457,1.99831448643964,1.75323855876923,1.79861354827881,1.79889059066772,64247.5546875,64346.8671875,0.0571502670645714,1,6,3,0,23.3230000458956,1,20.7062574108828,1.11640930175781,43.49951171875,39.5894432067871,,,,,,,,,,,,,,,,
,3875293525.06965,1.79933180809021,57298.513671875,,,,,,,,,,,,,0.214614630790903,2.23426101687281E-5,0.000235922242282319,10,2,,80,2,2279,,,0.207349070392934,0.00280997433680122,0.00126244756393135,-0.000456237990874797,,,,0.0525969689499654,39.995735168457,1.99801786478677,1.75585198402405,1.79898619651794,1.79972791671753,57248.9375,57348.08984375,0.0572187379002571,1,6,3,0,23.3230000458956,1,20.7034097617904,1.11740112304688,43.9882698059082,39.5894432067871,,,,,,,,,,,,,,,,
,3875293666.53937,1.79947633743286,50299.287109375,,,,,,,,,,,,,0.197433013562002,2.26931399184921E-5,0.000211017818972522,10,2,,80,2,2348,,,0.190634953608124,0.00239815901521903,0.00116111780516803,-0.000418421579524875,,,,0.0483596255809324,39.995735168457,1.99813608187255,1.7574098110199,1.79935431480408,1.79971098899841,50249.84765625,50348.7265625,0.0572996623814106,1,6,3,0,23.3230000458956,1,20.7068481393153,1.116943359375,43.9882698059082,39.1006851196289,,,,,,,,,,,,,,,,
,3875293808.01836,1.79924893379211,43303.4765625,,,,,,,,,,,,,0.180526657156915,2.21470759724357E-5,0.000216621826626376,10,2,,80,2,2417,,,0.174215775749065,0.00204760507568574,0.00106140412390232,-0.000381484453100711,,,,0.0441935375215612,39.995735168457,1.99810305366893,1.76008665561676,1.79905641078949,1.79938125610352,43251.44140625,43355.51171875,0.0573959685862064,1,6,3,0,23.3230000458956,1,20.7062084917208,1.11717224121094,43.49951171875,39.5894432067871,,,,,,,,,,,,,,,,
,3875293949.46368,1.79927053451538,36294.47265625,,,,,,,,,,,,,0.163524929621576,1.74368879580877E-5,0.000139078518880511,10,2,,80,2,2486,,,0.15773212667344,0.00164624975595667,0.00096142222173512,-0.000344111234880984,,,,0.0400119135955026,39.995735168457,1.99810582331239,1.76267278194427,1.79910206794739,1.79936814308166,36244.80859375,36344.13671875,0.0575098805129528,1,6,3,0,23.3230000458956,1,20.7056741675977,1.11732482910156,43.49951171875,40.0782012939453,,,,,,,,,,,,,,,,
,3875294090.93971,1.79805355072022,29257.1435546875,,,,,,,,,,,,,0.145931722826809,1.72628117900433E-5,9.30025311238532E-5,10,2,,80,2,2555,,,0.140701931932837,0.00130248225200173,0.000857925799209625,-0.000306018366245553,,,,0.0356904590481127,39.995735168457,1.99806989826405,1.76690053939819,1.79727959632874,1.79828894138336,29207.349609375,29306.9375,0.0576849319040775,1,6,3,0,23.3230000458956,1,20.7111177377483,1.12594604492188,44.4770278930664,39.5894432067871,,,,,,,,,,,,,,,,
,3875294232.40051,1.79756292700768,22222.462890625,,,,,,,,,,,,,0.127376245588596,1.67720987147344E-5,2.50168026884472E-5,10,2,,80,2,2624,,,0.122766453189538,0.000965878139769463,0.000748897320590913,-0.000266046816250309,,,,0.0311409939112754,39.995735168457,1.99806945187067,1.77317976951599,1.79738295078278,1.79765427112579,22170.3203125,22274.60546875,0.0579090863466263,1,6,3,0,23.3230000458956,1,20.7172788246978,1.12564086914062,44.4770278930664,40.0782012939453,,,,,,,,,,,,,,,,
,3875294373.88379,1.79638180732727,15185.2866210938,,,,,,,,,,,,,0.107326081765565,1.44151313154257E-5,-4.09475792661399E-5,10,2,,80,2,2693,,,0.103410263841261,0.000659492465668023,0.000631151546258479,-0.000223126626224257,,,,0.0262303600407172,39.995735168457,1.99804929551672,1.78211784362793,1.79617261886597,1.79651463031769,15133.0244140625,15237.548828125,0.0582347437739372,1,6,3,0,23.3230000458956,1,20.7146778112536,1.11854553222656,43.9882698059082,39.5894432067871,,,,,,,,,,,,,,,,
,3875294515.34302,1.79643278121948,8149.74365234375,,,,,,,,,,,,,0.0853518591060902,1.17709586391222E-5,-8.32205696196197E-5,10,2,,80,2,2762,,,0.0822175700009234,0.000406021855231045,0.000502043170854449,-0.000176673507667147,,,,0.0208535766269784,39.995735168457,1.99800251156974,1.79292869567871,1.7963582277298,1.7965008020401,8099.912109375,8199.5751953125,0.0585465840995312,1,6,3,0,23.3230000458956,1,20.714879979135,1.12716674804688,43.9882698059082,39.1006851196289,,,,,,,,,,,,,,,,
,3875294656.91424,1.80033586025238,1095.19909667969,,,,,,,,,,,,,0.0617221208639279,9.91763546572699E-6,-0.0001276131274071,1,2,,80,2,2831,,,0.0594451621795448,0.000186781473840346,0.000363200175343081,-0.000127097431686707,,,,0.0150766019938526,39.995735168457,1.9979495891396,1.79870164394379,1.80020606517792,1.80042159557343,1045.38342285156,1145.01477050781,0.0589026398956776,1,6,3,0,23.3230000458956,1,20.7172356819648,1.11862182617188,43.9882698059082,38.6119270324707,,,,,,,,,,,,,,,,
,3875294798.37816,1.80148823261261,-5958.64477539063,,,,,,,,,,,,,0.0374720942834068,1.10040592966997E-5,-7.48076566961163E-5,1,2,,80,2,2900,,,0.0360939202148727,0.000132675006993379,0.000220476315007545,-7.72929633967578E-5,,,,0.00915398573308148,39.995735168457,1.99787231199801,1.79559791088104,1.80136740207672,1.80175089836121,-6008.47509765625,-5908.814453125,0.0587227530777454,1,6,3,0,23.3230000458956,1,20.719058924677,1.11900329589844,43.49951171875,39.5894432067871,,,,,,,,,,,,,,,,
,3875294939.82613,1.80312385559082,-13010.8500976563,,,,,,,,,,,,,0.0144823338927531,1.09568483554216E-5,-1.94944779497832E-5,1,2,,80,2,2969,,,0.0139528626018843,7.17522970258826E-5,8.51847798912786E-5,-3.00067349598976E-5,,,,0.00353853958293854,39.995735168457,1.99785572944691,1.78844547271729,1.80300354957581,1.80327606201172,-13063.1728515625,-12958.52734375,0.0584256537258625,1,6,3,0,23.3230000458956,1,20.7208068767075,1.11930847167969,42.5219955444336,39.5894432067871,,,,,,,,,,,,,,,,
,3875295081.28993,1.80299371480942,-20065.9326171875,,,,,,,,,,,,,-0.00738515856389618,1.11503759181227E-5,5.75626222220167E-6,1,2,,80,2,3038,,,-0.00711721667699949,-4.70249973350484E-5,-4.34288886026479E-5,1.53707878780551E-5,,,,0.00180470649320396,39.995735168457,1.99782999172476,1.77889657020569,1.80291771888733,1.80308413505554,-20115.912109375,-20015.953125,0.0581871867179871,1,6,3,0,23.3230000458956,1,20.7222375077194,1.119384765625,43.49951171875,39.5894432067871,,,,,,,,,,,,,,,,
,3875295222.75866,1.80055596828461,-27139.2958984375,,,,,,,,,,,,,-0.0996135646037367,1.5182639898604E-5,9.78304549183073E-6,1,2,,80,2,3107,,,-0.0960329801191131,-0.000790668392174634,-0.000585661153309047,0.000208362122066319,,,,0.0243561264051314,39.995735168457,1.99785085522445,1.76927697658539,1.80038297176361,1.80068802833557,-27191.958984375,-27086.6328125,0.0579453371465206,5,6,3,0,23.3230000458956,1,20.7228335787232,1.11976623535156,43.49951171875,39.5894432067871,,,,,,,,,,,,,,,,
,3875295366.28062,1.80194978713989,-34317.09765625,,,,,,,,,,,,,-0.117524423957416,1.50533148067093E-5,-9.11301669540536E-5,10,2,,80,2,3177,,,-0.113346876210704,-0.00114359304994809,-0.000690789078362286,0.000247218471486121,,,,0.0287483212519719,39.995735168457,1.99781315691588,1.76573181152344,1.80181682109833,1.80205726623535,-34367.0703125,-34267.125,0.0576795861124992,1,6,3,0,23.3230000458956,1,20.7235313791307,1.11846923828125,43.49951171875,39.1006851196289,,,,,,,,,,,,,,,,
,3875295507.77936,1.80131988525391,-41392.87890625,,,,,,,,,,,,,-0.135129467915253,1.72927283749363E-5,-0.000148106944588869,10,2,,80,2,3246,,,-0.130387671859106,-0.00148460665819786,-0.000794242892879993,0.000285445334156975,,,,0.0330696976841641,39.995735168457,1.99773721574571,1.76152515411377,1.80120980739594,1.80138146877289,-41442.9140625,-41342.84375,0.057614877820015,1,6,3,0,23.3230000458956,1,20.7261319900617,1.11846923828125,44.4770278930664,39.5894432067871,,,,,,,,,,,,,,,,
,3875295649.24934,1.80076913833618,-48466.955078125,,,,,,,,,,,,,-0.155581830185517,1.8586994646944E-5,-0.000188235676214074,10,2,,80,2,3315,,,-0.150202362121934,-0.00187322596664655,-0.000914614531211555,0.000329814967699349,,,,0.0380956656163593,39.995735168457,1.99776885305463,1.75849497318268,1.80044484138489,1.8010196685791,-48519.35546875,-48414.5546875,0.0574685484170914,1,6,3,0,23.3230000458956,1,20.7254578368443,1.12014770507812,43.0107536315918,39.5894432067871,,,,,,,,,,,,,,,,
,3875295790.70953,1.80106525421143,-55541.537109375,,,,,,,,,,,,,-0.179161137524596,2.33279061661744E-5,-0.000196746928194204,10,2,,80,2,3384,,,-0.173068918290398,-0.00230466247615867,-0.00105352629907429,0.000381003483198583,,,,0.0438964473101473,39.995735168457,1.99779049148806,1.75663256645203,1.8007630109787,1.80140221118927,-55594.015625,-55489.05859375,0.0573814995586872,1,6,3,0,23.3230000458956,1,20.7297832288464,1.119384765625,43.49951171875,39.5894432067871,,,,,,,,,,,,,,,,
,3875295932.17189,1.80058271884918,-62614.078125,,,,,,,,,,,,,-0.204443050565666,2.58402026686031E-5,-0.000212037436286239,10,2,,80,2,3453,,,-0.19761885540432,-0.0028039588956977,-0.00120260484982282,0.000435996946180239,,,,0.0501226958746897,39.995735168457,1.99773346703028,1.75454270839691,1.80052042007446,1.80063796043396,-62664.17578125,-62563.98046875,0.0573819130659103,1,6,3,0,23.3230000458956,1,20.7252971714874,1.11679077148438,43.49951171875,38.6119270324707,,,,,,,,,,,,,,,,
,3875296073.63776,1.80061757564545,-69687.78515625,,,,,,,,,,,,,-0.232657989363606,2.80742962592555E-5,-0.000174737177720486,10,2,,80,2,3522,,,-0.225049677452102,-0.00333193303265424,-0.00136921112425625,0.000497437140438706,,,,0.0570808137722853,39.995735168457,1.99772953694673,1.7527357339859,1.8005450963974,1.80071437358856,-69740.234375,-69635.3359375,0.0572853982448578,1,6,3,0,23.3230000458956,1,20.7283611496328,1.11862182617188,43.49951171875,39.5894432067871,,,,,,,,,,,,,,,,
,3875296215.09425,1.80087404251099,-76763.09765625,,,,,,,,,,,,,-0.264374812448391,3.0056569602377E-5,-0.000176916143356409,10,2,,80,2,3591,,,-0.255920039530052,-0.00398963352154173,-0.00155662593897432,0.000566784001421183,,,,0.0649102933391869,39.995735168457,1.99770868244793,1.75061106681824,1.80074608325958,1.80100953578949,-76815.625,-76710.5703125,0.0571086332201958,1,6,3,0,23.3230000458956,1,20.7243652820612,1.12556457519531,43.49951171875,39.5894432067871,,,,,,,,,,,,,,,,
,3875296356.60273,1.80115451812744,-83912.9609375,,,,,,,,,,,,,-0.295015795962322,2.99361131776773E-5,-9.2534903767359E-5,10,2,,80,2,3660,,,-0.285809972818574,-0.00459176377771302,-0.00173824303783476,0.000633777235634625,,,,0.0724950224470557,39.995735168457,1.99779983992307,1.74841463565826,1.80097472667694,1.80142533779144,-83966.125,-83859.796875,0.0570989586412907,1,6,3,0,23.3230000458956,1,20.7222320130148,1.11869812011719,43.49951171875,39.1006851196289,,,,,,,,,,,,,,,,
,3875296498.06108,1.80109028816223,-91067.2109375,,,,,,,,,,,,,-0.323444695394438,2.32653266722844E-5,3.4637848894811E-5,10,2,,80,2,3729,,,-0.313615590451917,-0.00515262393267128,-0.00190708483569324,0.000695926835760474,,,,0.0795443172280393,39.995735168457,1.99770483217021,1.74535250663757,1.80094933509827,1.80128014087677,-91120.265625,-91014.15625,0.0568422041833401,1,6,3,0,23.3230000458956,1,20.7169901199432,1.11907958984375,43.49951171875,39.5894432067871,,,,,,,,,,,,,,,,
,3875296639.51254,1.80116539001465,-98217.15234375,,,,,,,,,,,,,-0.349987410462206,2.67584027238785E-5,0.00018332479935147,10,2,,80,2,3798,,,-0.339648670322802,-0.00568778568375546,-0.00206533609889448,0.000754062202759087,,,,0.086150617194105,39.995735168457,1.99776310334412,1.74205529689789,1.80105519294739,1.80127096176147,-98267.7578125,-98166.546875,0.0566554367542267,1,6,3,0,23.3230000458956,1,20.7083404631155,1.1181640625,43.49951171875,39.1006851196289,,,,,,,,,,,,,,,,
,3875296780.99291,1.80131826400757,-105368.23046875,,,,,,,,,,,,,-0.375105048211636,2.99948724885863E-5,0.000365724936382471,10,2,,80,2,3867,,,-0.36435341694516,-0.00618466091336875,-0.00221537705510855,0.000809460587333888,,,,0.0924172463108691,39.995735168457,1.99776946320557,1.73827767372131,1.80115795135498,1.80146181583405,-105421.21875,-105315.2421875,0.0566684901714325,1,6,3,0,23.3230000458956,1,20.7093643732651,1.12548828125,43.0107536315918,39.1006851196289,,,,,,,,,,,,,,,,
,3875296922.45952,1.80158412456512,-112521.08984375,,,,,,,,,,,,,-0.398909114453294,2.69768824358127E-5,0.000580575458947527,10,2,,80,2,3936,,,-0.387834562293883,-0.00663900630622313,-0.00235820864327252,0.000862402666825801,,,,0.0983862622790114,39.995735168457,1.99802671617729,1.73408257961273,1.80131566524506,1.80185925960541,-112574.15625,-112468.0234375,0.0564947947859764,1,6,3,0,23.3230000458956,1,20.7172854741478,1.1187744140625,43.49951171875,39.5894432067871,,,,,,,,,,,,,,,,
,3875297063.90808,1.80142502784729,-119670.41015625,,,,,,,,,,,,,-0.421666009453441,2.86065401174859E-5,0.000807054760848549,10,2,,80,2,4005,,,-0.410346601104999,-0.00706914823667254,-0.0024947733618319,0.000912340066861361,,,,0.104085305934012,39.995735168457,1.99776042337175,1.73010444641113,1.80120444297791,1.80179047584534,-119721.1484375,-119619.671875,0.0562812685966492,1,6,3,0,23.3230000458956,1,20.7109408818498,1.11770629882812,43.49951171875,39.5894432067871,,,,,,,,,,,,,,,,
,3875297205.39948,1.80161285400391,-126826.1484375,,,,,,,,,,,,,-0.443772204501986,3.18652289913187E-5,0.000986281994273581,10,2,,80,2,4074,,,-0.432271171727662,-0.00753472600393976,-0.00262782187201083,0.000961824145633727,,,,0.109647269601578,39.995735168457,1.99776996435277,1.72508263587952,1.80136585235596,1.80183911323547,-126879.15625,-126773.140625,0.0562229417264462,1,6,3,0,23.3230000458956,1,20.7152217927682,1.11831665039062,43.49951171875,39.5894432067871,,,,,,,,,,,,,,,,
,3875297346.86849,1.8021160364151,-133976.2265625,,,,,,,,,,,,,-0.464860719563537,3.29792733151123E-5,0.00122478582920647,10,2,,80,2,4143,,,-0.453248546989144,-0.00791999798865081,-0.00275495136156678,0.0010083777597174,,,,0.11495213920278,39.995735168457,1.99748111673052,1.72074091434479,1.80192029476166,1.80230176448822,-134026.6875,-133925.765625,0.0560382716357708,1,6,3,0,23.3230000458956,1,20.713149299863,1.11763000488281,43.49951171875,39.5894432067871,,,,,,,,,,,,,,,,
,3875297488.32957,1.80142298340797,-139999.7890625,,,,,,,,,,,,,-0.482074581101627,3.37071258786467E-5,0.00136576411100769,10,2,,80,2,4212,,,-0.470412509498441,-0.00828714702661856,-0.00285930675454438,0.00104715023189783,,,,0.11931357002272,39.995735168457,1.99762958084906,1.71459352970123,1.80089378356934,1.80172538757324,-139999.796875,-139999.78125,0.0557561554014683,1,4,3,0,23.3230000458956,1,20.7151397364313,1.11907958984375,43.49951171875,39.5894432067871,,,,,,,,,,,,,,,,
,3875297629.79463,1.79895868301392,-138091.3125,,,,,,,,,,,,,-0.477347847532728,4.26011137064805E-5,0.0012885667045229,10,2,,80,2,4281,,,-0.465680179771869,-0.00821761663017273,-0.00283061736263335,0.00103609578218311,,,,0.118108765631572,39.995735168457,1.99755502230203,1.7136162519455,1.79862749576569,1.79921090602875,-138143.359375,-138039.265625,0.0557536110281944,1,6,3,0,23.3230000458956,1,20.7036624145365,1.11808776855469,43.49951171875,38.6119270324707,,,,,,,,,,,,,,,,
,3875297771.26822,1.79784289002419,-131080.27734375,,,,,,,,,,,,,-0.458957487941113,3.62629813316129E-5,0.00106855074448138,10,2,,80,2,4350,,,-0.447317150821323,-0.00787393709011033,-0.00271896715275943,0.000995142851024866,,,,0.113448684811002,39.995735168457,1.99751231372094,1.71801364421844,1.79766178131104,1.79810678958893,-131129.890625,-131030.6640625,0.0559875965118408,1,6,3,0,23.3230000458956,1,20.7045896457283,1.12602233886719,43.49951171875,40.5669593811035,,,,,,,,,,,,,,,,
,3875297912.7202,1.79823067188263,-124071.18359375,,,,,,,,,,,,,-0.439989084067647,2.98699810653185E-5,0.000936372517878087,10,2,,80,2,4419,,,-0.428428607397387,-0.00742658729898357,-0.00260453158989549,0.000952871690969914,,,,0.108668681157506,39.995735168457,1.99771918789806,1.72340309619904,1.79805052280426,1.79833436012268,-124120.703125,-124021.6640625,0.056151270866394,1,6,3,0,23.3230000458956,1,20.7124242872641,1.11885070800781,43.49951171875,39.1006851196289,,,,,,,,,,,,,,,,
,3875298054.22138,1.79838523864746,-117054.3359375,,,,,,,,,,,,,-0.420231788094467,5.40090159729334E-5,0.000742675869058591,10,2,,80,2,4488,,,-0.408809226094006,-0.00702037470892283,-0.00248535396531224,0.00090878875926137,,,,0.103690327902405,39.995735168457,1.99767423870563,1.72790467739105,1.79814541339874,1.79860651493073,-117106.3671875,-117002.3046875,0.056275237351656,1,6,3,0,23.3230000458956,1,20.7118955752648,1.116943359375,43.49951171875,39.5894432067871,,,,,,,,,,,,,,,,
,3875298195.66642,1.79859060049057,-110042.12109375,,,,,,,,,,,,,-0.399663921786841,2.91097900980172E-5,0.000524755674855406,10,2,,80,2,4557,,,-0.388442899843191,-0.00662316895490805,-0.00236158422194421,0.000862849992699921,,,,0.0985176487884282,39.995735168457,1.99752915001368,1.73209679126739,1.79829263687134,1.79891979694366,-110091.7109375,-109992.53125,0.0565308257937431,1,6,3,0,23.3230000458956,1,20.7043102530776,1.11801147460938,43.9882698059082,39.5894432067871,,,,,,,,,,,,,,,,
,3875298337.13795,1.79872283935547,-103026.87109375,,,,,,,,,,,,,-0.378136213360029,2.79232317470505E-5,0.000308480648284347,10,2,,80,2,4626,,,-0.367187957068641,-0.00621176382125291,-0.00223257252946496,0.000815883453469724,,,,0.0931372696233039,39.995735168457,1.99777670468559,1.73633015155792,1.79859900474548,1.79886043071747,-103076.5390625,-102977.203125,0.0566845536231995,1,6,3,0,23.3230000458956,1,20.7158102808832,1.11778259277344,43.9882698059082,39.5894432067871,,,,,,,,,,,,,,,,
,3875298478.60175,1.79829411506653,-96010.6640625,,,,,,,,,,,,,-0.355268040288828,3.17904349438732E-5,0.000130503505217695,10,2,,80,2,4695,,,-0.34467896469404,-0.00574992247829692,-0.00209573679603636,0.000764854077715427,,,,0.0874147632642094,39.995735168457,1.99748560914943,1.74018847942352,1.79781770706177,1.7985919713974,-96060.15625,-95961.171875,0.0568143241107464,1,6,3,0,23.3230000458956,1,20.7045940329035,1.11885070800781,45.9433059692383,39.5894432067871,,,,,,,,,,,,,,,,
,3875298620.06004,1.79872264862061,-88997.06640625,,,,,,,,,,,,,-0.330494213393189,2.58765328955452E-5,7.24451935416939E-6,10,2,,80,2,4764,,,-0.320371856430148,-0.0052198107112743,-0.00194819690659642,0.000710168736986816,,,,0.0812493893044897,39.995735168457,1.99748120949595,1.74386703968048,1.79856181144714,1.798832654953,-89049.171875,-88944.9609375,0.0569069609045982,1,6,3,0,23.3230000458956,1,20.7050822184783,1.11900329589844,43.9882698059082,39.5894432067871,,,,,,,,,,,,,,,,
,3875298761.55873,1.7989209651947,-81983.0234375,,,,,,,,,,,,,-0.303467154125923,2.11230790581561E-5,-0.000126554293844961,10,2,,80,2,4833,,,-0.293932821565617,-0.00468797265850072,-0.00178765947930515,0.00065098877530545,,,,0.0745450819946401,39.995735168457,1.99752389956026,1.74719595909119,1.79874312877655,1.79910433292389,-82032.609375,-81933.4375,0.0570915080606937,1,6,3,0,23.3230000458956,1,20.706107155918,1.11862182617188,44.4770278930664,39.5894432067871,,,,,,,,,,,,,,,,
,3875298903.03184,1.79905372858047,-74965.921875,,,,,,,,,,,,,-0.273970006048941,2.56013145878933E-5,-0.000170313921551145,10,2,,80,2,4902,,,-0.265157301357446,-0.0040637198546063,-0.00161308865062892,0.000586744339670986,,,,0.0672568297858424,39.995735168457,1.9978249119835,1.74917995929718,1.79895222187042,1.79913890361786,-75015.5234375,-74916.3203125,0.0570849701762199,1,6,3,0,23.3230000458956,1,20.7207025799553,1.12007141113281,43.9882698059082,40.0782012939453,,,,,,,,,,,,,,,,
,3875299044.47497,1.7989860534668,-67952.44140625,,,,,,,,,,,,,-0.243562156387247,2.22852129991732E-5,-0.000200992288468617,10,2,,80,2,4971,,,-0.235555664429682,-0.00345353924086487,-0.00143339124042541,0.000520395406056196,,,,0.0597515740174567,39.995735168457,1.99794262301692,1.75194609165192,1.79889667034149,1.79905021190643,-68004.5,-67900.3828125,0.0571726113557816,1,6,3,0,23.3230000458956,1,20.7239542560156,1.12907409667969,43.9882698059082,39.5894432067871,,,,,,,,,,,,,,,,
,3875299185.94616,1.79881899356842,-60935.771484375,,,,,,,,,,,,,-0.223576320588352,1.80552804028053E-5,-0.000216655311652443,10,2,,80,2,5040,,,-0.216079517375682,-0.00300386250536804,-0.00131522957235575,0.000476360146421939,,,,0.054810464563174,39.995735168457,1.99794836073302,1.75377345085144,1.79843461513519,1.79922544956207,-60987.85546875,-60883.6875,0.0572061277925968,1,6,3,0,23.3230000458956,1,20.7237129023239,1.11793518066406,43.9882698059082,39.5894432067871,,,,,,,,,,,,,,,,
,3875299327.43299,1.79922020435333,-53918.896484375,,,,,,,,,,,,,-0.206235342898309,2.0976541312263E-5,-0.000242055451380907,10,2,,80,2,5109,,,-0.199194306128494,-0.00262424310907571,-0.00121271295938641,0.000438119895989075,,,,0.0505233156984538,39.995735168457,1.99780827199897,1.75615286827087,1.79900169372559,1.79929423332214,-53971.01171875,-53866.78125,0.0573784001171589,1,6,3,0,23.3230000458956,1,20.719006128843,1.11923217773438,43.49951171875,40.0782012939453,,,,,,,,,,,,,,,,
,3875299468.86695,1.79905876517296,-46904.64453125,,,,,,,,,,,,,-0.189137851594676,1.96129127557516E-5,-0.000204713065529747,10,2,,80,2,5178,,,-0.182575944320814,-0.00221468133644959,-0.0011119683040306,0.000400641176383942,,,,0.0463114461270447,39.995735168457,1.9979897620686,1.75848865509033,1.79889833927155,1.79917526245117,-46954.5546875,-46854.734375,0.0573993548750877,1,6,3,0,23.3230000458956,1,20.7294682186676,1.11824035644531,43.9882698059082,40.0782012939453,,,,,,,,,,,,,,,,
,3875299610.36549,1.79906663894653,-39887.61328125,,,,,,,,,,,,,-0.172261458032886,2.0388887225007E-5,-0.000183576007051001,10,2,,80,2,5247,,,-0.166199091592914,-0.00185280157046437,-0.00101255322806537,0.000363678525900468,,,,0.0421558860235666,39.995735168457,1.99793846931833,1.76114141941071,1.79883193969727,1.7993311882019,-39937.046875,-39838.1796875,0.0574620254337788,1,6,3,0,23.3230000458956,1,20.7284403591774,1.11854553222656,44.4770278930664,40.0782012939453,,,,,,,,,,,,,,,,
,3875299751.83376,1.79854369163513,-32841.8359375,,,,,,,,,,,,,-0.154966834343307,1.52594377156255E-5,-0.000152698872577744,10,2,,80,2,5316,,,-0.149444383526988,-0.00150883367332699,-0.000910788250621408,0.000325912551488727,,,,0.0379028398801698,39.995735168457,1.99779434055774,1.76471638679504,1.79847931861877,1.7986159324646,-32894.23828125,-32789.43359375,0.0576711259782314,1,6,3,0,23.3230000458956,1,20.7209647966964,1.11709594726562,44.4770278930664,40.0782012939453,,,,,,,,,,,,,,,,
,3875299893.27711,1.79800841808319,-25787.3017578125,,,,,,,,,,,,,-0.136888417295802,1.53777542070535E-5,-4.9059815470338E-5,10,2,,80,2,5385,,,-0.131957955419668,-0.00112256789432106,-0.000804717827122658,0.00028674557688646,,,,0.0334731357461922,39.995735168457,1.99812231282735,1.76950073242187,1.79787933826447,1.79815304279327,-25837.080078125,-25737.5234375,0.0578175261616707,1,6,3,0,23.3230000458956,1,20.7355315911311,1.12594604492188,43.9882698059082,39.5894432067871,,,,,,,,,,,,,,,,
,3875300034.74979,1.79651243686676,-18731.40234375,,,,,,,,,,,,,-0.117617156390543,1.44626179308217E-5,2.2990818207736E-5,10,2,,80,2,5454,,,-0.113342586341553,-0.000795339738172335,-0.000691512017510831,0.000245181581703946,,,,0.0287486181091353,39.995735168457,1.99793740224616,1.77697062492371,1.79644072055817,1.79657542705536,-18781.28515625,-18681.51953125,0.0580704174935818,1,6,3,0,23.3230000458956,1,20.7307547514982,1.11885070800781,43.9882698059082,40.0782012939453,,,,,,,,,,,,,,,,
,3875300176.20564,1.79608798027039,-11677.8637695313,,,,,,,,,,,,,-0.0965749138566588,1.46181921552689E-5,7.1531505432962E-5,10,2,,80,2,5523,,,-0.0930392810250168,-0.000519691386871052,-0.000567938142921776,0.000200485766981728,,,,0.0235997616077693,39.995735168457,1.99803169670831,1.78701186180115,1.79600787162781,1.79617345333099,-11730.2734375,-11625.4541015625,0.058367446064949,1,6,3,0,23.3230000458956,1,20.733717265413,1.12129211425781,43.9882698059082,40.5669593811035,,,,,,,,,,,,,,,,
,3875300317.68389,1.79784159660339,-4614.439453125,,,,,,,,,,,,,-0.0735934616823207,1.26704653096417E-5,9.27609663927696E-5,10,2,,80,2,5592,,,-0.0708839220905621,-0.000302782439657381,-0.000432861532317474,0.000152120759594254,,,,0.0179778136051975,39.995735168457,1.99781941139914,1.79717183113098,1.79770040512085,1.79798352718353,-4666.9990234375,-4561.8798828125,0.0587366707623005,1,6,3,0,23.3230000458956,1,20.7286907197184,1.12777709960938,43.9882698059082,40.0782012939453,,,,,,,,,,,,,,,,
,3875300459.22486,1.8008044719696,2458.77502441406,,,,,,,,,,,,,-0.0493779648050351,1.14242493066326E-5,0.000103470126966826,1,2,,80,2,5661,,,-0.0475577215540661,-0.000153553792048162,-0.000290547934127972,0.000101805009762757,,,,0.0120625602553535,39.995735168457,1.99808305042462,1.79756247997284,1.80061852931976,1.80098021030426,2408.72436523438,2508.82568359375,0.0587890595197678,1,6,3,0,23.3230000458956,1,20.7353382727797,1.11915588378906,43.9882698059082,39.1006851196289,,,,,,,,,,,,,,,,
,3875300600.67384,1.80260283946991,9532.76416015625,,,,,,,,,,,,,-0.0255715109034834,1.09089920536012E-5,3.91750921636514E-5,1,2,,80,2,5730,,,-0.0246336449318451,-0.000111840749036508,-0.000150411506183445,5.28997843503021E-5,,,,0.00624694362287697,39.995735168457,1.99775952433329,1.79212272167206,1.80246734619141,1.80270028114319,9480.2099609375,9585.318359375,0.0585454367101192,1,6,3,0,23.3230000458956,1,20.7270596545808,1.11793518066406,44.4770278930664,40.5669593811035,,,,,,,,,,,,,,,,
,3875300742.14075,1.80344104766846,16606.1103515625,,,,,,,,,,,,,-0.00321156418917971,1.0900164418051E-5,1.56104978946732E-6,1,2,,80,2,5799,,,-0.00309457061543814,-1.99690600910226E-5,-1.88844460353721E-5,6.68423763272585E-6,,,,0.000785135994339521,39.995735168457,1.99801428817836,1.78371739387512,1.80338227748871,1.80353546142578,16556.11328125,16656.107421875,0.058318305760622,1,6,3,0,23.3230000458956,1,20.7323308466398,1.12869262695312,43.9882698059082,40.0782012939453,,,,,,,,,,,,,,,,
,3875300883.60841,1.8003014922142,23693.666015625,,,,,,,,,,,,,0.0831970283420793,1.17576134225562E-5,-1.83516723842366E-5,1,2,,80,2,5868,,,0.0801921682824689,0.000613202326749968,0.00048916699597612,-0.000173824897501618,,,,0.0203401713121072,39.995735168457,1.99805395973638,1.77187943458557,1.8001172542572,1.80050194263458,23643.576171875,23743.755859375,0.0578438341617584,5,6,3,0,23.3230000458956,1,20.7348919734271,1.12564086914062,43.9882698059082,41.5444793701172,,,,,,,,,,,,,,,,
,3875301027.15626,1.80145102739334,30892.298828125,,,,,,,,,,,,,0.10162613697076,1.31180012226028E-5,8.53348996118971E-5,10,2,,80,2,5938,,,0.0979932260108099,0.000948872363086748,0.00059725868050009,-0.000213524777791463,,,,0.0248534754264361,39.995735168457,1.99772483851483,1.76775693893433,1.80121982097626,1.80169761180878,30839.673828125,30944.923828125,0.0576759874820709,1,6,3,0,23.3230000458956,1,20.727995405199,1.11923217773438,43.9882698059082,39.5894432067871,,,,,,,,,,,,,,,,
,3875301168.61313,1.80144815444946,37987.673828125,,,,,,,,,,,,,0.119309842100464,1.35560533258587E-5,0.000123100453399177,10,2,,80,2,6007,,,0.11509606142505,0.00124901525729736,0.000701222976204008,-0.000251604797085747,,,,0.0291915032428365,39.995735168457,1.99774056419981,1.76320147514343,1.80141150951386,1.80148482322693,37935.11328125,38040.234375,0.0575282610952854,1,6,3,0,23.3230000458956,1,20.7270716818188,1.11892700195312,43.49951171875,40.0782012939453,,,,,,,,,,,,,,,,
,3875301310.11649,1.80117180347443,45081.943359375,,,,,,,,,,,,,0.139014759770124,1.92562088932734E-5,0.000149846680154159,10,2,,80,2,6076,,,0.134173045736172,0.00159341046048279,0.000817231950350106,-0.000294350204057991,,,,0.0340355094439074,39.995735168457,1.99806500006898,1.76014149188995,1.80080556869507,1.80140316486359,45029.28125,45134.60546875,0.057466696947813,1,6,3,0,23.3230000458956,1,20.7379777232333,1.12693786621094,43.9882698059082,39.5894432067871,,,,,,,,,,,,,,,,
,3875301451.57098,1.80051238536835,52172.86328125,,,,,,,,,,,,,0.16289259070607,1.77459552833894E-5,0.000200838650207706,10,2,,80,2,6145,,,0.157307917984578,0.00204469613355204,0.000957742042373866,-0.000346082379110158,,,,0.0399022134876329,39.995735168457,1.99794465571036,1.75788879394531,1.80039143562317,1.80068266391754,52120.19140625,52225.53515625,0.0572529621422291,1,6,3,0,23.3230000458956,1,20.7331488334067,1.1181640625,43.9882698059082,40.0782012939453,,,,,,,,,,,,,,,,
,3875301593.04521,1.80038397312164,59268.58984375,,,,,,,,,,,,,0.18911403689949,2.14438299991705E-5,0.000207328755020843,10,2,,80,2,6214,,,0.182744347677458,0.00252366748847734,0.00111232325434685,-0.000403002719394863,,,,0.0463558885916363,39.995735168457,1.99802491757111,1.75553131103516,1.80024468898773,1.80045163631439,59215.9296875,59321.25,0.0571551024913788,1,6,3,0,23.3230000458956,1,20.7350190052881,1.12617492675781,43.49951171875,39.5894432067871,,,,,,,,,,,,,,,,
,3875301734.48972,1.80106517672539,66360.7890625,,,,,,,,,,,,,0.216527330736218,2.46957599068519E-5,0.000224440681177198,10,2,,80,2,6283,,,0.209375759823437,0.00307165439714055,0.00127397524192929,-0.000462840893305838,,,,0.0531098360477489,39.995735168457,1.99793569584363,1.75364482402802,1.80096852779388,1.80124914646149,66310.6953125,66410.8828125,0.0571787841618061,1,6,3,0,23.3230000458956,1,20.7362069561525,1.11885070800781,43.49951171875,40.0782012939453,,,,,,,,,,,,,,,,
,3875301875.95805,1.80091008543968,73457.0859375,,,,,,,,,,,,,0.248790110719636,2.88342315442659E-5,0.000154287824347783,10,2,,80,2,6352,,,0.240748813256489,0.00364510171003685,0.00146461674012244,-0.000532950274646282,,,,0.0610689894431883,39.995735168457,1.99794984876509,1.75156855583191,1.80088436603546,1.80093467235565,73406.9921875,73507.1796875,0.057024173438549,1,6,3,0,23.3230000458956,1,20.7385919881115,1.11740112304688,44.4770278930664,39.5894432067871,,,,,,,,,,,,,,,,
,3875302017.4644,1.80083818435669,80591.48046875,,,,,,,,,,,,,0.280826078039583,3.10338896397377E-5,8.43014836187555E-5,10,2,,80,2,6421,,,0.271961157486795,0.00426203447510889,0.00165423809085041,-0.00060287001542747,,,,0.0689880986576988,39.995735168457,1.99797515060233,1.74901187419891,1.80063235759735,1.80101728439331,80540.765625,80642.1953125,0.0569095127284527,1,6,3,0,23.3230000458956,1,20.7363086283098,1.11900329589844,43.49951171875,40.0782012939453,,,,,,,,,,,,,,,,
,3875302158.8957,1.80114126205444,87762.42578125,,,,,,,,,,,,,0.310661253139521,1.80620853323258E-5,2.62255902008632E-6,10,2,,80,2,6490,,,0.301102563910683,0.00487453533794757,0.00183119426947087,-0.000668297929223627,,,,0.076380441012225,39.995735168457,1.99796037391742,1.74654912948608,1.80095398426056,1.80130338668823,87709.2265625,87815.625,0.0567177124321461,1,6,3,0,23.3230000458956,1,20.7325724726444,1.11824035644531,43.49951171875,39.5894432067871,,,,,,,,,,,,,,,,
,3875302300.38164,1.80134377479553,94936.76953125,,,,,,,,,,,,,0.338175086071296,3.40538610319233E-5,-0.000129801542802455,10,2,,80,2,6559,,,0.328052633267286,0.00543132342806395,0.00199477840214968,-0.000728686456568539,,,,0.0832129644777994,39.995735168457,1.99785119702557,1.74343657493591,1.80124759674072,1.80141294002533,94883.5,94990.0390625,0.0566613711416721,1,6,3,0,23.3230000458956,1,20.7289744719696,1.11946105957031,43.9882698059082,39.5894432067871,,,,,,,,,,,,,,,,
,3875302441.83284,1.80130164623261,102108.10546875,,,,,,,,,,,,,0.364031454265391,3.22977672745468E-5,-0.000302694703085887,10,2,,80,2,6628,,,0.353450865164465,0.00594322204741427,0.0021489926148206,-0.000785635726060718,,,,0.0896538866452124,39.995735168457,1.99781803116785,1.73975872993469,1.80103194713593,1.80157458782196,102057.359375,102158.8515625,0.056512787938118,1,6,3,0,23.3230000458956,1,20.7286344185557,1.11968994140625,43.49951171875,39.1006851196289,,,,,,,,,,,,,,,,
,3875302583.30148,1.80140500068665,109283.10546875,,,,,,,,,,,,,0.388542790775478,3.0036052062249E-5,-0.000470867833051987,10,2,,80,2,6697,,,0.377596425822407,0.00645162818541856,0.00229554018005729,-0.000839760876260698,,,,0.0957744124270333,39.995735168457,1.99773658287551,1.73594391345978,1.80124914646149,1.80149817466736,109232.109375,109334.1015625,0.056269071996212,1,6,3,0,23.3230000458956,1,20.7252048704312,1.11785888671875,43.49951171875,38.1231689453125,,,,,,,,,,,,,,,,
,3875302724.7617,1.80145600438118,116453.94921875,,,,,,,,,,,,,0.411816292303636,3.72173246932132E-5,-0.000697980358831922,10,2,,80,2,6766,,,0.400590432029023,0.00688932669273012,0.00243530631996691,-0.000891066156327724,,,,0.101608786242622,39.995735168457,1.99776142201859,1.73183178901672,1.80126476287842,1.80164504051209,116403.2890625,116504.609375,0.0561571195721626,1,6,3,0,23.3230000458956,1,20.7224404889861,1.11862182617188,43.9882698059082,39.5894432067871,,,,,,,,,,,,,,,,
,3875302866.27326,1.80157146453857,123630.76171875,,,,,,,,,,,,,0.434408262016809,2.97996259360944E-5,-0.000915277964306899,10,2,,80,2,6835,,,0.422969562478664,0.00732773250492366,0.00257123121991754,-0.00094120972789824,,,,0.107286401905708,39.995735168457,1.99776311421804,1.72766351699829,1.80145013332367,1.80180835723877,123577.421875,123684.1015625,0.0559326149523258,1,6,3,0,23.3230000458956,1,20.7232354576815,1.11785888671875,43.9882698059082,39.5894432067871,,,,,,,,,,,,,,,,
,3875303007.71489,1.80170657634735,130803.921875,,,,,,,,,,,,,0.456024983130263,2.43591673610682E-5,-0.00111671787655431,10,2,,80,2,6904,,,0.444443713419329,0.0077619883225645,0.0027014990337193,-0.000989013118669391,,,,0.112724181258892,39.995735168457,1.99757997985961,1.72270369529724,1.80162799358368,1.80187153816223,130753.2109375,130854.6328125,0.0556761287152767,1,6,3,0,23.3230000458956,1,20.71742878538,1.12045288085938,43.49951171875,40.0782012939453,,,,,,,,,,,,,,,,
,3875303149.191,1.80188400745392,137979.1484375,,,,,,,,,,,,,0.4767165942228,3.37995795300088E-5,-0.00138230299219776,10,2,,80,2,6973,,,0.465059284809414,0.00811062781979668,0.00282691558822989,-0.00103494327049702,,,,0.117958303412413,39.995735168457,1.99766203258914,1.71767163276672,1.80176877975464,1.80213844776154,137928.578125,138029.71875,0.0555513426661491,1,6,3,0,23.3230000458956,1,20.7191084982514,1.11785888671875,44.4770278930664,39.5894432067871,,,,,,,,,,,,,,,,
,3875303290.65809,1.8004125058651,140000.4375,,,,,,,,,,,,,0.482642512135339,2.36763598709619E-5,-0.00145187015198536,10,2,,80,2,7042,,,0.470968428190188,0.00821447898325192,0.00286281923763454,-0.00104785978328437,,,,0.119453707562743,39.995735168457,1.99759815232834,1.71499943733215,1.80035436153412,1.800461769104,140000.421875,140000.453125,0.0554088577628136,1,4,3,0,23.3230000458956,1,20.7149889672152,1.11747741699219,42.5219955444336,40.0782012939453,,,,,,,,,,,,,,,,
,3875303309.1034,1.80021994113922,140000.4765625,,,,,,,,,,,,,0.482651420301854,2.19787207560711E-5,-0.00143634506008686,10,2,,80,2,7051,,,0.470976812935921,0.00822980641309926,0.00286278012208641,-0.00104796781670302,,,,0.119453886691423,39.995735168457,1.99756085984967,1.71474957466126,1.79988408088684,1.80060696601868,140000.46875,140000.484375,0.0553336851298809,1,4,3,0,23.3230000458956,1,20.715302086597,1.11862182617188,43.9882698059082,39.5894432067871,,,,,,,,,,,,,,,,