File: MPMS/NiCl2pym/NiCl2pym_2-300K_FC.rso.dat
[Header]
TITLE,MPMS RSO Measurement
BYAPP,MPMS Measurement,1.1,Summary
FILEOPENTIME, 1626373528.781000 7/15/2021, 7:25:28 PM

INFO, APPNAME, MPMS MultiVu Application, Revision 1.61,  Build 082

INFO, NAME, NiCl2pym
INFO, WEIGHT, 12.300
INFO, AREA, 1.000
INFO, LENGTH, 1.000
INFO, SHAPE, -
INFO, COMMENT, 10.7 mg eicosane
INFO, SEQUENCE FILE: JP_ZFC_MH_FC_210715_NiCl2pym.seq


INFO, BACKGROUND DATA FILE:, None


STARTUPAXIS,X,4,LINEAR,AUTO,0.000000,0.000000
STARTUPAXIS,Y1,5,LINEAR,AUTO,0.000000,0.000000


STARTUPGROUP,Longitudinal
FIELDGROUP,Longitudinal,1,2,3,4,5,6,7,8,9,10,11,19,20,21,22,23,35
FIELDGROUP,Transverse,1,2,3,4,12,13,14,15,16,17,18,24,25,26,27,28,35

PLOT_APPEARANCE,ALL,HORZ_GRID_ON,VERT_GRID_ON,MARKERS_AND_LINES

[Data]
Time,Comment,Field (Oe),Temperature (K),Long Moment (emu),Long Scan Std Dev,Long Offset (cm),Long Offset Std Dev,Long Algorithm,Long Reg Fit,Long Reg Factor,Trans Moment (emu),Trans Scan Std Dev,Trans Offset (cm),Trans Offset Std Dev,Trans Algorithm,Trans Reg Fit,Trans Reg Factor,Long Moment [w/o ABS] (emu),Long Scan Std Dev [w/o ABS],Long Offset [w/o ABS] (cm),Long Offset Std Dev [w/o ABS],Long Reg Fit [w/o ABS],Trans Moment [w/o ABS] (emu),Trans Scan Std Dev [w/o ABS],Trans Offset [w/o ABS] (cm),Trans Offset Std Dev [w/o ABS],Trans Reg Fit [w/o ABS],RSO Position (deg),Amplitude (cm),Frequency,Cycles to Average,Scans per Measurement,Delta Temp (K),Error,EC Comp. Running,Using ABS,
1626373528.781,,1.000000e+002,3.000094e+002,2.793169e-005,1.317760e-008,1.251404e-001,2.391981e-004,3,9.664696e-001,1.825000e+000,,,,,,,,,,,,,,,,,,0,5.000000e+000,1.000000e+000,4,4,1.980591e-002,0,,0,
1626374036.817,,1.000000e+002,2.902460e+002,2.896459e-005,1.418113e-008,1.231618e-001,6.607720e-005,3,9.672169e-001,1.825000e+000,,,,,,,,,,,,,,,,,,0,5.000000e+000,1.000000e+000,4,4,5.529785e-002,0,,0,
1626374281.258,,1.000000e+002,2.794945e+002,3.020603e-005,9.445273e-009,1.123287e-001,5.281075e-005,3,9.692295e-001,1.825000e+000,,,,,,,,,,,,,,,,,,0,5.000000e+000,1.000000e+000,4,4,3.656006e-001,0,,0,
1626374501.347,,1.000000e+002,2.695732e+002,3.140585e-005,1.266572e-008,1.028322e-001,1.361483e-004,3,9.707466e-001,1.825000e+000,,,,,,,,,,,,,,,,,,0,5.000000e+000,1.000000e+000,4,4,3.224792e-001,0,,0,
1626374725.074,,1.000000e+002,2.596001e+002,3.272638e-005,1.466539e-008,9.454934e-002,5.271683e-005,3,9.721683e-001,1.825000e+000,,,,,,,,,,,,,,,,,,0,5.000000e+000,1.000000e+000,4,4,2.756042e-001,0,,0,
1626374945.462,,1.000000e+002,2.495972e+002,3.412396e-005,1.452770e-008,8.714539e-002,2.734123e-004,3,9.736469e-001,1.825000e+000,,,,,,,,,,,,,,,,,,0,5.000000e+000,1.000000e+000,4,4,2.277069e-001,0,,0,
1626375169.719,,1.000000e+002,2.396222e+002,3.567495e-005,1.560303e-008,8.052073e-002,5.470085e-005,3,9.747975e-001,1.825000e+000,,,,,,,,,,,,,,,,,,0,5.000000e+000,1.000000e+000,4,4,2.773132e-001,0,,0,
1626375395.099,,1.000000e+002,2.296238e+002,3.733645e-005,9.503351e-009,7.426593e-002,3.851771e-005,3,9.765556e-001,1.825000e+000,,,,,,,,,,,,,,,,,,0,5.000000e+000,1.000000e+000,4,4,2.428894e-001,0,,0,
1626375619.384,,1.000000e+002,2.196189e+002,3.914685e-005,2.060713e-008,6.796357e-002,2.009886e-004,3,9.778810e-001,1.825000e+000,,,,,,,,,,,,,,,,,,0,5.000000e+000,1.000000e+000,4,4,2.477875e-001,0,,0,
1626375845.512,,1.000000e+002,2.096242e+002,4.114566e-005,2.036266e-008,6.211484e-002,1.001877e-004,3,9.789319e-001,1.825000e+000,,,,,,,,,,,,,,,,,,0,5.000000e+000,1.000000e+000,4,4,2.489014e-001,0,,0,
1626376076.457,,1.000000e+002,1.996508e+002,4.336793e-005,1.909403e-008,5.658817e-002,1.105397e-004,3,9.802107e-001,1.825000e+000,,,,,,,,,,,,,,,,,,0,5.000000e+000,1.000000e+000,4,4,2.214050e-001,0,,0,
1626376308.200,,1.000000e+002,1.896664e+002,4.582851e-005,1.089750e-008,5.096711e-002,9.003775e-005,3,9.813123e-001,1.825000e+000,,,,,,,,,,,,,,,,,,0,5.000000e+000,1.000000e+000,4,4,2.653046e-001,0,,0,
1626376546.541,,1.000000e+002,1.796962e+002,4.857660e-005,1.705055e-008,4.593011e-002,1.471090e-004,3,9.825011e-001,1.825000e+000,,,,,,,,,,,,,,,,,,0,5.000000e+000,1.000000e+000,4,4,2.106934e-001,0,,0,
1626376787.645,,1.000000e+002,1.697176e+002,5.163863e-005,1.185300e-008,4.161648e-002,8.306275e-005,3,9.838158e-001,1.825000e+000,,,,,,,,,,,,,,,,,,0,5.000000e+000,1.000000e+000,4,4,2.315063e-001,0,,0,
1626377038.203,,1.000000e+002,1.597971e+002,5.507697e-005,1.203531e-008,3.727966e-002,1.371758e-004,3,9.849209e-001,1.825000e+000,,,,,,,,,,,,,,,,,,0,5.000000e+000,1.000000e+000,4,4,2.359924e-001,0,,0,
1626377294.672,,1.000000e+002,1.498702e+002,5.902226e-005,1.748433e-008,3.297662e-002,1.007001e-004,3,9.858030e-001,1.825000e+000,,,,,,,,,,,,,,,,,,0,5.000000e+000,1.000000e+000,4,4,1.893005e-001,0,,0,
1626377555.571,,1.000000e+002,1.399206e+002,6.351306e-005,8.670551e-009,2.859461e-002,7.922041e-005,3,9.869438e-001,1.825000e+000,,,,,,,,,,,,,,,,,,0,5.000000e+000,1.000000e+000,4,4,1.999969e-001,0,,0,
1626377820.588,,1.000000e+002,1.299731e+002,6.869865e-005,1.416023e-008,2.459280e-002,1.796525e-004,3,9.879050e-001,1.825000e+000,,,,,,,,,,,,,,,,,,0,5.000000e+000,1.000000e+000,4,4,1.811981e-001,0,,0,
1626378085.449,,1.000000e+002,1.200076e+002,7.475457e-005,1.298692e-008,2.068432e-002,1.334319e-004,3,9.887816e-001,1.825000e+000,,,,,,,,,,,,,,,,,,0,5.000000e+000,1.000000e+000,4,4,1.365967e-001,0,,0,
1626378488.171,,1.000000e+002,1.100679e+002,8.175073e-005,2.873981e-008,1.663760e-002,9.757062e-005,3,9.897081e-001,1.825000e+000,,,,,,,,,,,,,,,,,,0,5.000000e+000,1.000000e+000,4,4,4.040527e-002,0,,0,
1626378800.333,,1.000000e+002,9.995020e+001,9.048719e-005,2.118356e-008,1.317124e-002,1.924167e-004,3,9.905545e-001,1.825000e+000,,,,,,,,,,,,,,,,,,0,5.000000e+000,1.000000e+000,4,4,1.263275e-001,0,,0,
1626379023.557,,1.000000e+002,9.495772e+001,9.538316e-005,4.839521e-008,1.118182e-002,1.439586e-004,3,9.909613e-001,1.825000e+000,,,,,,,,,,,,,,,,,,0,5.000000e+000,1.000000e+000,4,4,1.942444e-001,0,,0,
1626379243.116,,1.000000e+002,8.995789e+001,1.008376e-004,5.785394e-008,9.682750e-003,5.222467e-005,3,9.912939e-001,1.825000e+000,,,,,,,,,,,,,,,,,,0,5.000000e+000,1.000000e+000,4,4,1.843338e-001,0,,0,
1626379578.804,,1.000000e+002,8.506615e+001,1.065783e-004,3.356771e-008,7.965157e-003,8.708957e-005,3,9.916727e-001,1.825000e+000,,,,,,,,,,,,,,,,,,0,5.000000e+000,1.000000e+000,4,4,2.323151e-002,0,,0,
1626379911.699,,1.000000e+002,8.006867e+001,1.132469e-004,1.809964e-008,6.255153e-003,1.778302e-004,3,9.919432e-001,1.825000e+000,,,,,,,,,,,,,,,,,,0,5.000000e+000,1.000000e+000,4,4,2.376556e-002,0,,0,
1626380232.985,,1.000000e+002,7.506493e+001,1.206755e-004,3.115560e-008,4.752132e-003,4.344319e-004,3,9.923402e-001,1.825000e+000,,,,,,,,,,,,,,,,,,0,5.000000e+000,1.000000e+000,4,4,2.756500e-002,0,,0,
1626380538.815,,1.000000e+002,7.006870e+001,1.292856e-004,3.012671e-008,3.793591e-003,3.148503e-004,3,9.926400e-001,1.825000e+000,,,,,,,,,,,,,,,,,,0,5.000000e+000,1.000000e+000,4,4,2.067566e-002,0,,0,
1626380771.870,,1.000000e+002,6.509997e+001,1.389073e-004,5.351558e-009,3.343487e-003,8.390410e-006,3,9.928245e-001,1.825000e+000,,,,,,,,,,,,,,,,,,0,5.000000e+000,1.000000e+000,4,4,2.000427e-002,0,,0,
1626381048.353,,1.000000e+002,6.005950e+001,1.497916e-004,2.535430e-008,3.161338e-003,7.713011e-005,3,9.927841e-001,1.825000e+000,,,,,,,,,,,,,,,,,,0,5.000000e+000,1.000000e+000,4,4,2.405930e-002,0,,0,
1626381265.057,,1.000000e+002,5.508670e+001,1.622729e-004,1.060113e-008,1.933459e-003,1.031776e-004,3,9.928516e-001,1.825000e+000,,,,,,,,,,,,,,,,,,0,5.000000e+000,1.000000e+000,4,4,1.744080e-002,0,,0,
1626381569.482,,1.000000e+002,5.001431e+001,1.767392e-004,2.946376e-008,4.256988e-004,1.313253e-004,3,9.930929e-001,1.825000e+000,,,,,,,,,,,,,,,,,,0,5.000000e+000,1.000000e+000,4,4,7.289886e-003,0,,0,
1626381760.352,,1.000000e+002,4.806437e+001,1.828679e-004,3.776108e-008,5.669441e-005,1.579732e-004,3,9.932015e-001,1.825000e+000,,,,,,,,,,,,,,,,,,0,5.000000e+000,1.000000e+000,4,4,2.143860e-002,0,,0,
1626381959.228,,1.000000e+002,4.606413e+001,1.894565e-004,4.092856e-008,-4.848616e-004,6.181448e-005,3,9.932090e-001,1.825000e+000,,,,,,,,,,,,,,,,,,0,5.000000e+000,1.000000e+000,4,4,3.013992e-002,0,,0,
1626382160.504,,1.000000e+002,4.405878e+001,1.965021e-004,3.341184e-008,-1.249134e-003,8.108942e-005,3,9.932997e-001,1.825000e+000,,,,,,,,,,,,,,,,,,0,5.000000e+000,1.000000e+000,4,4,2.671051e-002,0,,0,
1626382370.236,,1.000000e+002,4.204557e+001,2.039783e-004,4.235673e-008,-1.785271e-003,1.534117e-004,3,9.932997e-001,1.825000e+000,,,,,,,,,,,,,,,,,,0,5.000000e+000,1.000000e+000,4,4,2.616882e-002,0,,0,
1626382573.867,,1.000000e+002,4.004631e+001,2.118745e-004,4.287420e-008,-2.148412e-003,4.718158e-005,3,9.933889e-001,1.825000e+000,,,,,,,,,,,,,,,,,,0,5.000000e+000,1.000000e+000,4,4,2.626801e-002,0,,0,
1626382781.180,,1.000000e+002,3.804083e+001,2.201941e-004,5.076125e-008,-2.595133e-003,1.397388e-004,3,9.933966e-001,1.825000e+000,,,,,,,,,,,,,,,,,,0,5.000000e+000,1.000000e+000,4,4,2.677155e-002,0,,0,
1626382990.413,,1.000000e+002,3.603413e+001,2.290003e-004,3.532457e-008,-3.151073e-003,1.119150e-004,3,9.934598e-001,1.825000e+000,,,,,,,,,,,,,,,,,,0,5.000000e+000,1.000000e+000,4,4,2.281952e-002,0,,0,
1626383203.295,,1.000000e+002,3.402985e+001,2.382775e-004,2.032687e-008,-3.414373e-003,3.601470e-005,3,9.934981e-001,1.825000e+000,,,,,,,,,,,,,,,,,,0,5.000000e+000,1.000000e+000,4,4,1.898956e-002,0,,0,
1626383420.202,,1.000000e+002,3.202529e+001,2.481028e-004,4.761993e-008,-3.801513e-003,3.700038e-005,3,9.935616e-001,1.825000e+000,,,,,,,,,,,,,,,,,,0,5.000000e+000,1.000000e+000,4,4,1.823807e-002,0,,0,
1626383640.479,,1.000000e+002,3.001970e+001,2.584186e-004,2.622929e-008,-4.081735e-003,9.512898e-005,3,9.935319e-001,1.825000e+000,,,,,,,,,,,,,,,,,,0,5.000000e+000,1.000000e+000,4,4,1.388168e-002,0,,0,
1626383860.599,,1.000000e+002,2.801676e+001,2.693016e-004,1.367803e-008,-4.654131e-003,2.872574e-004,3,9.936663e-001,1.825000e+000,,,,,,,,,,,,,,,,,,0,5.000000e+000,1.000000e+000,4,4,1.316071e-002,0,,0,
1626384078.088,,1.000000e+002,2.600669e+001,2.809336e-004,2.166393e-008,-4.725021e-003,7.093912e-005,3,9.936634e-001,1.825000e+000,,,,,,,,,,,,,,,,,,0,5.000000e+000,1.000000e+000,4,4,4.400253e-003,0,,0,
1626384266.088,,1.000000e+002,2.498553e+001,2.871378e-004,7.822166e-008,-4.816086e-003,8.558040e-005,3,9.936469e-001,1.825000e+000,,,,,,,,,,,,,,,,,,0,5.000000e+000,1.000000e+000,4,4,3.343964e-002,0,,0,
1626384467.629,,1.000000e+002,2.451471e+001,2.900509e-004,1.039811e-007,-4.780946e-003,8.696396e-005,3,9.935879e-001,1.825000e+000,,,,,,,,,,,,,,,,,,0,5.000000e+000,1.000000e+000,4,4,4.881096e-002,0,,0,
1626384675.253,,1.000000e+002,2.401440e+001,2.932535e-004,1.067389e-007,-4.744893e-003,4.825857e-005,3,9.936501e-001,1.825000e+000,,,,,,,,,,,,,,,,,,0,5.000000e+000,1.000000e+000,4,4,4.923058e-002,0,,0,
1626384883.471,,1.000000e+002,2.351016e+001,2.965628e-004,9.854230e-008,-4.689344e-003,8.732819e-005,3,9.936169e-001,1.825000e+000,,,,,,,,,,,,,,,,,,0,5.000000e+000,1.000000e+000,4,4,4.220963e-002,0,,0,
1626385090.269,,1.000000e+002,2.300900e+001,2.999768e-004,1.035405e-007,-4.815979e-003,1.301971e-004,3,9.936522e-001,1.825000e+000,,,,,,,,,,,,,,,,,,0,5.000000e+000,1.000000e+000,4,4,3.561974e-002,0,,0,
1626385295.039,,1.000000e+002,2.250825e+001,3.035300e-004,9.812150e-008,-4.895722e-003,1.156377e-004,3,9.936916e-001,1.825000e+000,,,,,,,,,,,,,,,,,,0,5.000000e+000,1.000000e+000,4,4,3.350067e-002,0,,0,
1626385499.762,,1.000000e+002,2.200780e+001,3.072329e-004,1.022767e-007,-5.133631e-003,1.280162e-004,3,9.936478e-001,1.825000e+000,,,,,,,,,,,,,,,,,,0,5.000000e+000,1.000000e+000,4,4,3.276062e-002,0,,0,
1626385705.843,,1.000000e+002,2.150566e+001,3.111716e-004,6.479316e-008,-5.282333e-003,3.452681e-004,3,9.936681e-001,1.825000e+000,,,,,,,,,,,,,,,,,,0,5.000000e+000,1.000000e+000,4,4,2.952003e-002,0,,0,
1626385910.664,,1.000000e+002,2.100378e+001,3.152760e-004,3.683913e-008,-4.973803e-003,9.390048e-005,3,9.936890e-001,1.825000e+000,,,,,,,,,,,,,,,,,,0,5.000000e+000,1.000000e+000,4,4,1.999092e-002,0,,0,
1626386110.957,,1.000000e+002,2.050368e+001,3.197385e-004,6.719378e-008,-5.208684e-003,8.974743e-005,3,9.936932e-001,1.825000e+000,,,,,,,,,,,,,,,,,,0,5.000000e+000,1.000000e+000,4,4,1.794815e-002,0,,0,
1626386310.423,,1.000000e+002,2.000360e+001,3.247156e-004,8.546334e-008,-5.394340e-003,9.824510e-005,3,9.937040e-001,1.825000e+000,,,,,,,,,,,,,,,,,,0,5.000000e+000,1.000000e+000,4,4,1.655960e-002,0,,0,
1626386511.230,,1.000000e+002,1.950252e+001,3.302369e-004,4.807674e-008,-5.548402e-003,2.297760e-004,3,9.937195e-001,1.825000e+000,,,,,,,,,,,,,,,,,,0,5.000000e+000,1.000000e+000,4,4,1.169014e-002,0,,0,
1626386708.734,,1.000000e+002,1.900187e+001,3.364966e-004,5.153410e-008,-5.338099e-003,1.609588e-004,3,9.937342e-001,1.825000e+000,,,,,,,,,,,,,,,,,,0,5.000000e+000,1.000000e+000,4,4,9.660721e-003,0,,0,
1626386904.440,,1.000000e+002,1.850169e+001,3.437547e-004,5.870269e-008,-5.989696e-003,2.267323e-004,3,9.937205e-001,1.825000e+000,,,,,,,,,,,,,,,,,,0,5.000000e+000,1.000000e+000,4,4,7.329941e-003,0,,0,
1626387099.101,,1.000000e+002,1.800184e+001,3.523880e-004,4.999982e-008,-6.076818e-003,2.673280e-004,3,9.937357e-001,1.825000e+000,,,,,,,,,,,,,,,,,,0,5.000000e+000,1.000000e+000,4,4,5.649567e-003,0,,0,
1626387292.624,,1.000000e+002,1.750181e+001,3.626705e-004,4.425024e-008,-5.766968e-003,1.732903e-004,3,9.937099e-001,1.825000e+000,,,,,,,,,,,,,,,,,,0,5.000000e+000,1.000000e+000,4,4,3.688812e-003,0,,0,
1626387487.240,,1.000000e+002,1.700137e+001,3.745790e-004,3.623777e-008,-5.813227e-003,2.271474e-004,3,9.937183e-001,1.825000e+000,,,,,,,,,,,,,,,,,,0,5.000000e+000,1.000000e+000,4,4,1.939774e-003,0,,0,
1626387679.751,,1.000000e+002,1.650134e+001,3.863595e-004,3.377318e-008,-5.705379e-003,1.004727e-004,3,9.937325e-001,1.825000e+000,,,,,,,,,,,,,,,,,,0,5.000000e+000,1.000000e+000,4,4,2.189636e-003,0,,0,
1626387868.500,,1.000000e+002,1.600140e+001,3.899167e-004,3.092374e-008,-5.547983e-003,6.901743e-005,3,9.937218e-001,1.825000e+000,,,,,,,,,,,,,,,,,,0,5.000000e+000,1.000000e+000,4,4,2.410889e-003,0,,0,
1626388060.759,,1.000000e+002,1.550125e+001,3.739473e-004,6.006943e-008,-5.909264e-003,2.878642e-004,3,9.937178e-001,1.825000e+000,,,,,,,,,,,,,,,,,,0,5.000000e+000,1.000000e+000,4,4,6.399155e-004,0,,0,
1626388250.241,,1.000000e+002,1.500123e+001,3.476896e-004,2.010358e-008,-5.978544e-003,1.962039e-004,3,9.936692e-001,1.825000e+000,,,,,,,,,,,,,,,,,,0,5.000000e+000,1.000000e+000,4,4,1.500130e-003,0,,0,
1626388438.383,,1.000000e+002,1.450104e+001,3.240551e-004,1.516740e-008,-5.481419e-003,1.230988e-004,3,9.936711e-001,1.825000e+000,,,,,,,,,,,,,,,,,,0,5.000000e+000,1.000000e+000,4,4,1.410484e-003,0,,0,
1626388613.045,,1.000000e+002,1.402536e+001,3.072828e-004,6.979541e-008,-5.601400e-003,1.608874e-004,3,9.936765e-001,1.825000e+000,,,,,,,,,,,,,,,,,,0,5.000000e+000,1.000000e+000,4,4,6.609917e-003,0,,0,
1626388791.030,,1.000000e+002,1.351882e+001,2.947485e-004,4.804637e-008,-5.946339e-003,7.596095e-005,3,9.937064e-001,1.825000e+000,,,,,,,,,,,,,,,,,,0,5.000000e+000,1.000000e+000,4,4,4.899979e-003,0,,0,
1626388967.641,,1.000000e+002,1.301244e+001,2.859255e-004,4.864387e-008,-5.850541e-003,4.257337e-004,3,9.936617e-001,1.825000e+000,,,,,,,,,,,,,,,,,,0,5.000000e+000,1.000000e+000,4,4,5.530357e-003,0,,0,
1626389143.661,,1.000000e+002,1.250552e+001,2.796267e-004,3.319341e-008,-5.993566e-003,1.688484e-004,3,9.936297e-001,1.825000e+000,,,,,,,,,,,,,,,,,,0,5.000000e+000,1.000000e+000,4,4,1.820564e-003,0,,0,
1626389316.543,,1.000000e+002,1.200281e+001,2.750757e-004,1.043098e-008,-6.075364e-003,2.718034e-004,3,9.936384e-001,1.825000e+000,,,,,,,,,,,,,,,,,,0,5.000000e+000,1.000000e+000,4,4,2.160072e-003,0,,0,
1626389515.311,,1.000000e+002,1.152687e+001,2.716642e-004,2.748387e-008,-5.848728e-003,3.583457e-004,3,9.937044e-001,1.825000e+000,,,,,,,,,,,,,,,,,,0,5.000000e+000,1.000000e+000,4,4,2.470016e-003,0,,0,
1626389713.872,,1.000000e+002,1.101854e+001,2.690210e-004,4.928755e-008,-5.933224e-003,1.770174e-004,3,9.936405e-001,1.825000e+000,,,,,,,,,,,,,,,,,,0,5.000000e+000,1.000000e+000,4,4,2.820015e-003,0,,0,
1626389911.341,,1.000000e+002,1.051027e+001,2.671304e-004,3.192332e-008,-5.727208e-003,7.250398e-005,3,9.936459e-001,1.825000e+000,,,,,,,,,,,,,,,,,,0,5.000000e+000,1.000000e+000,4,4,3.060341e-003,0,,0,
1626390105.566,,1.000000e+002,1.000166e+001,2.656901e-004,1.026246e-008,-5.190282e-003,1.368127e-004,3,9.936075e-001,1.825000e+000,,,,,,,,,,,,,,,,,,0,5.000000e+000,1.000000e+000,4,4,2.063751e-003,0,,0,
1626390295.110,,1.000000e+002,9.502029e+000,2.648747e-004,1.297441e-008,-5.790603e-003,5.218518e-004,3,9.936513e-001,1.825000e+000,,,,,,,,,,,,,,,,,,0,5.000000e+000,1.000000e+000,4,4,3.623009e-003,0,,0,
1626390484.362,,1.000000e+002,9.001783e+000,2.645098e-004,5.077028e-008,-6.036531e-003,1.932200e-004,3,9.936689e-001,1.825000e+000,,,,,,,,,,,,,,,,,,0,5.000000e+000,1.000000e+000,4,4,2.880096e-003,0,,0,
1626390672.346,,1.000000e+002,8.501714e+000,2.638811e-004,1.426701e-006,-9.938588e-003,8.861352e-003,3,9.727675e-001,1.825000e+000,,,,,,,,,,,,,,,,,,0,5.000000e+000,1.000000e+000,4,4,3.080368e-003,0,,0,
1626390856.322,,1.000000e+002,8.002378e+000,2.650587e-004,2.214662e-008,-5.492520e-003,2.372988e-004,3,9.936568e-001,1.825000e+000,,,,,,,,,,,,,,,,,,0,5.000000e+000,1.000000e+000,4,4,2.910614e-003,0,,0,
1626391040.673,,1.000000e+002,7.502073e+000,2.660019e-004,2.842689e-008,-5.710457e-003,2.013042e-004,3,9.936169e-001,1.825000e+000,,,,,,,,,,,,,,,,,,0,5.000000e+000,1.000000e+000,4,4,2.699852e-003,0,,0,
1626391222.342,,1.000000e+002,7.002505e+000,2.674707e-004,1.348100e-008,-5.190564e-003,1.509435e-004,3,9.936672e-001,1.825000e+000,,,,,,,,,,,,,,,,,,0,5.000000e+000,1.000000e+000,4,4,4.573822e-003,0,,0,
1626391403.150,,1.000000e+002,6.502483e+000,2.694736e-004,1.073541e-008,-5.949776e-003,2.099968e-004,3,9.937071e-001,1.825000e+000,,,,,,,,,,,,,,,,,,0,5.000000e+000,1.000000e+000,4,4,3.637314e-003,0,,0,
1626391530.684,,1.000000e+002,6.010522e+000,2.720166e-004,3.914154e-008,-5.869032e-003,2.473495e-004,3,9.936720e-001,1.825000e+000,,,,,,,,,,,,,,,,,,0,5.000000e+000,1.000000e+000,4,4,8.380413e-003,0,,0,
1626391731.148,,1.000000e+002,5.752463e+000,2.736574e-004,1.827340e-008,-5.790787e-003,8.380433e-005,3,9.936836e-001,1.825000e+000,,,,,,,,,,,,,,,,,,0,5.000000e+000,1.000000e+000,4,4,3.992081e-003,0,,0,
1626391927.541,,1.000000e+002,5.502955e+000,2.754547e-004,2.287945e-008,-6.176523e-003,2.638292e-004,3,9.937070e-001,1.825000e+000,,,,,,,,,,,,,,,,,,0,5.000000e+000,1.000000e+000,4,4,3.636837e-003,0,,0,
1626392120.925,,1.000000e+002,5.254663e+000,2.773974e-004,1.186783e-008,-6.084775e-003,2.233225e-004,3,9.937407e-001,1.825000e+000,,,,,,,,,,,,,,,,,,0,5.000000e+000,1.000000e+000,4,4,5.105019e-003,0,,0,
1626392310.469,,1.000000e+002,5.007407e+000,2.795246e-004,5.090349e-008,-5.683675e-003,4.272315e-004,3,9.937667e-001,1.825000e+000,,,,,,,,,,,,,,,,,,0,5.000000e+000,1.000000e+000,4,4,5.053043e-003,0,,0,
1626392494.240,,1.000000e+002,4.752302e+000,2.820041e-004,4.055959e-008,-5.451635e-003,1.889490e-004,3,9.937180e-001,1.825000e+000,,,,,,,,,,,,,,,,,,0,5.000000e+000,1.000000e+000,4,4,4.374027e-003,0,,0,
1626392670.790,,1.000000e+002,4.502466e+000,2.847177e-004,5.426162e-008,-5.572048e-003,7.823235e-005,3,9.937785e-001,1.825000e+000,,,,,,,,,,,,,,,,,,0,5.000000e+000,1.000000e+000,4,4,5.223274e-003,0,,0,
1626392851.930,,1.000000e+002,4.249512e+000,2.879812e-004,4.451171e-008,-5.382711e-003,5.391570e-005,3,9.937401e-001,1.825000e+000,,,,,,,,,,,,,,,,,,0,5.000000e+000,1.000000e+000,4,4,4.504204e-003,0,,0,
1626393000.367,,1.000000e+002,4.000186e+000,2.912518e-004,2.987393e-008,-5.303859e-003,7.072451e-005,3,9.937377e-001,1.825000e+000,,,,,,,,,,,,,,,,,,0,5.000000e+000,1.000000e+000,4,4,1.181293e-002,0,,0,
1626393148.619,,1.000000e+002,3.750382e+000,2.951930e-004,4.898132e-008,-5.109745e-003,6.340926e-005,3,9.937372e-001,1.825000e+000,,,,,,,,,,,,,,,,,,0,5.000000e+000,1.000000e+000,4,4,8.071899e-003,0,,0,
1626393297.338,,1.000000e+002,3.500268e+000,2.995270e-004,2.607161e-008,-5.135711e-003,2.019435e-004,3,9.937926e-001,1.825000e+000,,,,,,,,,,,,,,,,,,0,5.000000e+000,1.000000e+000,4,4,7.400036e-003,0,,0,
1626393445.449,,1.000000e+002,3.249554e+000,3.043242e-004,4.108208e-008,-5.326058e-003,1.600766e-004,3,9.937440e-001,1.825000e+000,,,,,,,,,,,,,,,,,,0,5.000000e+000,1.000000e+000,4,4,7.853985e-003,0,,0,
1626393624.385,,1.000000e+002,3.002276e+000,3.096416e-004,3.696204e-008,-5.149045e-003,1.773515e-004,3,9.937381e-001,1.825000e+000,,,,,,,,,,,,,,,,,,0,5.000000e+000,1.000000e+000,4,4,5.902052e-003,0,,0,
1626393815.274,,1.000000e+002,2.752458e+000,3.157461e-004,2.383674e-008,-5.037310e-003,1.520470e-004,3,9.937353e-001,1.825000e+000,,,,,,,,,,,,,,,,,,0,5.000000e+000,1.000000e+000,4,4,5.179882e-003,0,,0,
1626394016.893,,1.000000e+002,2.502410e+000,3.225764e-004,3.867604e-008,-4.887940e-003,1.233681e-004,3,9.937974e-001,1.825000e+000,,,,,,,,,,,,,,,,,,0,5.000000e+000,1.000000e+000,4,4,5.479097e-003,0,,0,
1626394237.201,,1.000000e+002,2.251742e+000,3.303817e-004,4.207047e-008,-5.223129e-003,2.784207e-004,3,9.937155e-001,1.825000e+000,,,,,,,,,,,,,,,,,,0,5.000000e+000,1.000000e+000,4,4,4.874945e-003,0,,0,
1626394536.335,,1.000000e+002,2.000369e+000,3.395270e-004,6.254334e-008,-5.164318e-003,1.985107e-004,3,9.938090e-001,1.825000e+000,,,,,,,,,,,,,,,,,,0,5.000000e+000,1.000000e+000,4,4,4.908085e-003,0,,0,