File: MPMS/NiCl2pym/NiCl2pym_MvH_4K_14T.dat
[Header]
; ACMS II Data File (default extension .dat)
; Copyright (c) 2014, Quantum Design, Inc. All rights reserved.
TITLE,
FILEOPENTIME,3875304880.337,10/19/2022,1:35 am
BYAPP,ACMS II,1.0,1.2
INFO,DYNACOOL ACMS II Option Release 1.0.8 Build 33,APPNAME
INFO,Quantum Design Linear Motor Servo Controller,MOTOR_MODULE_NAME
INFO,3101-100 K0,MOTOR_HW_VERSION
INFO,MMC794,MOTOR_SERIAL_NUMBER
INFO,SRV No X-over 01.03.11,MOTOR_SOFTWARE_VERSION
INFO,ACMS,ACMS_MODULE_NAME
INFO,3101-430 A0,ACMS_HW_VERSION
INFO,ACMSII028,ACMS_SERIAL_NUMBER
INFO,00.14.14,ACMS_SOFTWARE_VERSION
INFO,WF046,COIL_SERIAL_NUMBER
INFO,0,MOMENT_UNITS
INFO,NiCl2pym,SAMPLE_MATERIAL
INFO,7.3mg cling film,SAMPLE_COMMENT
INFO,17.2,SAMPLE_MASS
INFO,,SAMPLE_VOLUME
INFO,,SAMPLE_MOLECULAR_WEIGHT
INFO,,SAMPLE_SIZE
INFO,,SAMPLE_SHAPE
DATATYPE,COMMENT,1
DATATYPE,TIME,2
STARTUPAXIS,X,2
STARTUPAXIS,Y1,5
STARTUPGROUP, AC
FIELDGROUP, AC, 2,3,4,5,6,7,8,9,10,11,12,13,14,15,16,20,21,22,23,24,25,35,43,44,45,46,47,48,49
FIELDGROUP, DC, 2,3,4,17,18,19,20,21,23,24,25,35,36,37,43,44,45,46,47,48,49,50,51
FIELDGROUP, Diagnostic, 26,27,28,29,30,31,32,33,34,38,39,40,41,42,52,53,54,55,56,57,58,59,60,61,62,63,64,65,66,67,68,69
[Data]
Comment,Time Stamp (sec),Temperature (K),Magnetic Field (Oe),AC Moment (emu),AC Std. Dev. (emu),AC Phase (deg),AC Phase Std. Dev. (deg),AC Suscept. (emu/Oe),AC Suscept. Std. Dev. (emu/Oe),AC X'  (emu/Oe),AC X" (emu/Oe),AC X' Std. Dev. (emu/Oe),AC X" Std. Dev. (emu/Oe),AC Drive (Oe),AC Frequency (Hz),DC Moment (emu),DC Std. Err. (emu),DC Quad. Moment (emu),Range (mV),"AC=1 DC=2 Locate=3",Measure Type,Measure Count,Measure Time (sec),Measure Number,AC X' Raw (emu/Oe),AC X" Raw (emu/Oe),DC M. Raw' (emu),DC M. Raw" (emu),Coil InPhase (V),Coil Quadrature (V),Null Status,Trim Ratio,Trim Phase (deg.),Max. Signal (mV),Motor Frequency (Hz),Motor Ampl. (mm),System Temp. (K),Min. Temperature (K),Max. Temperature (K),Min. Field (Oe),Max. Field (Oe),Pressure (Torr),Temp. Status (code),Field Status (code),Chamber Status (code),Measure Status (code),Center Position (mm),Transport Action,Motor Lag (deg),Motor Current (amps),Motor Heatsink Temp. (C),Motor Board Temp. (C),QMap 01,QMap 02,QMap 03,QMap 04,QMap 05,QMap 06,QMap 07,QMap 08,QMap 09,QMap 10,QMap 11,QMap 12,QMap 13,QMap 14,QMap 15,QMap 16
sample offset = 27.08 mm,3875305492.00159,4.00122489929199,0.27568706870079,,,,,,,,,,,,,0.0455139880919358,2.64579358503197E-6,-6.42966187404913E-5,1,2,,80,2,1,,,0.04383409505923,0.000163365672926996,0.000267756957327947,-9.38827652134933E-5,,,,0.0111173834743087,39.995735168457,1.9979104348368,4.00276041030884,4.00086641311646,4.00150775909424,0.266793936491013,0.284580200910568,0.124335296452045,1,4,3,4,23.3230000458956,1,20.7188957636465,1.11976623535156,30.7917900085449,32.2580642700195,,,,,,,,,,,,,,,,
,3875305637.9876,4.0002875328064,1538.14892578125,,,,,,,,,,,,,0.0491909231093329,9.57155491499002E-6,-0.00011136408081127,1,2,,80,2,69,,,0.0473767201374535,0.00014122619661844,0.000289427494863048,-0.00010130674490938,,,,0.0120147102658079,39.995735168457,1.99774820206348,4.000168800354,4.00019454956055,4.00035047531128,1485.69812011719,1590.59973144531,0.12595197558403,1,6,3,4,23.3230000458956,1,20.730905751136,1.12945556640625,40.0782012939453,32.7468223571777,,,,,,,,,,,,,,,,
,3875305783.98748,4.00082731246948,8835.734375,,,,,,,,,,,,,0.0701587456342884,1.11762696514885E-5,-0.000121397654606432,1,2,,80,2,137,,,0.067584173778354,0.000287993000800207,0.000412702007452026,-0.000145061552757397,,,,0.0171401413036736,39.995735168457,1.99781338999145,3.99783563613892,4.00073766708374,4.00088024139404,8783.166015625,8888.302734375,0.125981256365776,1,6,3,4,23.3230000458956,1,20.732426202125,1.11984252929688,41.5444793701172,34.7018585205078,,,,,,,,,,,,,,,,
,3875305929.62672,4.0006344795227,16118.8193359375,,,,,,,,,,,,,0.0913447881733212,1.19295594757911E-5,-9.74339300663803E-5,1,2,,80,2,205,,,0.0880158259030755,0.000511398124854515,0.000537144194822758,-0.000189739221241325,,,,0.0223201678327096,39.995735168457,1.99768468353817,3.99576497077942,4.00057363510132,4.00072717666626,16063.78515625,16173.853515625,0.125994592905045,1,6,3,4,23.3230000458956,1,20.7326024367611,1.12648010253906,42.0332374572754,36.6568908691406,,,,,,,,,,,,,,,,
,3875306073.01365,4.00013933181763,23297.6005859375,,,,,,,,,,,,,0.112985766982283,1.45000937815785E-5,-5.68839252523161E-5,1,2,,80,2,273,,,0.108903153389825,0.000796173564181171,0.000664302730001509,-0.000235731218708679,,,,0.0276177437512923,39.995735168457,1.99774248364102,3.99396419525146,4.00003337860107,4.00024509429932,23244.943359375,23350.2578125,0.125927001237869,1,6,3,4,23.3230000458956,1,20.7290138944895,1.12136840820312,42.5219955444336,37.1456527709961,,,,,,,,,,,,,,,,
,3875306214.49115,4.00002489089966,30390.7607421875,,,,,,,,,,,,,0.135423858873154,1.62143503682791E-5,7.45210729363105E-5,10,2,,80,2,342,,,0.130579316482237,0.00121764282049375,0.00079603266203776,-0.000284325273241848,,,,0.0331206255233586,39.995735168457,1.9979420974727,3.9935314655304,3.99998807907105,4.00008583068848,30340.833984375,30440.6875,0.125784486532211,1,6,3,4,23.3230000458956,1,20.7317382363997,1.12510681152344,42.5219955444336,37.6344108581543,,,,,,,,,,,,,,,,
,3875306353.93828,3.99943852424622,37383.263671875,,,,,,,,,,,,,0.156123193062206,1.33173638405711E-5,0.000136263305869744,10,2,,80,2,410,,,0.15060344871345,0.00159783063665504,0.000917671015486121,-0.000329136993968859,,,,0.0381993240169123,39.995735168457,1.99791868006424,3.9937641620636,3.9993166923523,3.99954509735107,37330.609375,37435.91796875,0.125840991735458,1,6,3,4,23.3230000458956,1,20.7337013077347,1.1297607421875,42.5219955444336,38.1231689453125,,,,,,,,,,,,,,,,
,3875306493.36936,3.99924068450928,44377.2265625,,,,,,,,,,,,,0.175527792988307,2.11033440421029E-5,0.000167395009535192,10,2,,80,2,478,,,0.169405691263178,0.00197436892917439,0.00103185349144042,-0.000371285277651623,,,,0.0429681692041786,39.995735168457,1.99788532594768,3.99510169029236,3.99912166595459,3.99942779541016,44324.53125,44429.921875,0.125906482338905,1,6,3,4,23.3230000458956,1,20.7325939085503,1.11839294433594,43.0107536315918,38.1231689453125,,,,,,,,,,,,,,,,
,3875306632.77976,3.99884557723999,51365.18359375,,,,,,,,,,,,,0.194385850135234,2.16421799703424E-5,0.000186210160824848,10,2,,80,2,546,,,0.187709506883813,0.00236770065603265,0.00114290916826576,-0.000412330206017941,,,,0.047607080467892,39.995735168457,1.99770525582354,3.99761414527893,3.99877047538757,3.99888157844543,51315.0703125,51415.296875,0.126026406884193,1,6,3,4,23.3230000458956,1,20.7257769614388,1.11747741699219,43.0107536315918,38.6119270324707,,,,,,,,,,,,,,,,
,3875306772.17933,3.9987916469574,58357.53125,,,,,,,,,,,,,0.213170580426264,2.05909873498231E-5,0.000186276169426506,10,2,,80,2,614,,,0.205974215898134,0.00277383636049189,0.0012536981375888,-0.000453490240033716,,,,0.052238280226814,39.995735168457,1.99761867264369,4.00134420394897,3.99872851371765,3.99891543388367,58304.875,58410.1875,0.126060783863068,1,6,3,4,23.3230000458956,1,20.7250203653559,1.12716674804688,43.9882698059082,38.6119270324707,,,,,,,,,,,,,,,,
,3875306911.59983,3.9984471321106,65349.181640625,,,,,,,,,,,,,0.232219275510126,2.00753268828322E-5,0.000191604470795294,10,2,,80,2,682,,,0.224527853509486,0.00321741725613989,0.00136623776052147,-0.000495608372148126,,,,0.0569461979423886,39.995735168457,1.99768584227083,4.00496530532837,3.99828004837036,3.99857783317566,65299.21875,65399.14453125,0.126240789890289,1,6,3,4,23.3230000458956,1,20.7278703067739,1.11968994140625,43.49951171875,38.6119270324707,,,,,,,,,,,,,,,,
,3875307051.00157,3.99853711128235,72337.3984375,,,,,,,,,,,,,0.256129159567778,2.6993431719919E-5,0.000160057680348827,10,2,,80,2,750,,,0.247821628578013,0.00371932703692943,0.00150762021075934,-0.000547932460904121,,,,0.0628523491635596,39.995735168457,1.99763025687076,4.00821924209595,3.99825239181519,3.99883723258972,72284.71875,72390.078125,0.126320332288742,1,6,3,4,23.3230000458956,1,20.7238308435065,1.12739562988281,43.49951171875,38.6119270324707,,,,,,,,,,,,,,,,
,3875307190.4422,3.99885401725769,79357.30859375,,,,,,,,,,,,,0.28438147578962,2.26026247615063E-5,8.06655654771051E-5,10,2,,80,2,818,,,0.275366782885089,0.00427118357195932,0.001674918923527,-0.000609706970863044,,,,0.0698397926537049,39.995735168457,1.99766346979377,4.01188325881958,3.99876475334167,3.99892115592957,79303.9453125,79410.671875,0.126394405961037,1,6,3,4,23.3230000458956,1,20.7243678910936,1.12701416015625,43.49951171875,39.1006851196289,,,,,,,,,,,,,,,,
,3875307329.86333,3.99876141548157,86424.359375,,,,,,,,,,,,,0.311995905138565,2.60998930346527E-5,-2.88280360285277E-5,10,2,,80,2,886,,,0.302349666801285,0.00481968426184577,0.00183866359293461,-0.000670035718940198,,,,0.0766771611553366,39.995735168457,1.9974866583959,4.01579332351685,3.99856400489807,3.99898505210876,86371.0390625,86477.6796875,0.126454308629036,1,6,3,4,23.3230000458956,1,20.7196110724243,1.1199951171875,43.49951171875,39.1006851196289,,,,,,,,,,,,,,,,
,3875307469.28567,3.99890713691711,93494.10546875,,,,,,,,,,,,,0.338262089364283,2.74107304593551E-5,-0.000140180704351144,10,2,,80,2,954,,,0.328080014962781,0.0053729915131092,0.00199478282593191,-0.000727932318113744,,,,0.0832016086631521,39.995735168457,1.99744140191325,4.0185112953186,3.99882626533508,3.99902701377869,93443.453125,93544.7578125,0.126582339406013,1,6,3,4,23.3230000458956,1,20.7200838364842,1.11885070800781,43.49951171875,39.5894432067871,,,,,,,,,,,,,,,,
,3875307608.70477,3.99907493591309,100562.34375,,,,,,,,,,,,,0.36325270753698,2.19784782128849E-5,-0.000336383712986821,10,2,,80,2,1022,,,0.352627324530736,0.00584396202587234,0.00214393599890172,-0.000782865914516151,,,,0.0894302189603658,39.995735168457,1.9974958242489,4.02089929580688,3.99889588356018,3.99921607971191,100511.6875,100613,0.126633390784264,1,6,3,4,23.3230000458956,1,20.7207893385459,1.12022399902344,43.49951171875,39.5894432067871,,,,,,,,,,,,,,,,
,3875307748.11686,3.99964303970337,107629.69140625,,,,,,,,,,,,,0.387038606941566,2.09292815030133E-5,-0.000541091348235144,10,2,,80,2,1090,,,0.37605633314309,0.00630068464351846,0.00228640297427773,-0.000835484883282334,,,,0.0953813941822673,39.995735168457,1.99768054134258,4.0229640007019,3.99945020675659,3.99994945526123,107579.0078125,107680.375,0.126647904515266,1,6,3,4,23.3230000458956,1,20.7235557033822,1.12007141113281,43.9882698059082,39.1006851196289,,,,,,,,,,,,,,,,
,3875307887.50985,3.99986410140991,114700.640625,,,,,,,,,,,,,0.409863225967489,5.60800385780837E-5,-0.000714478043246736,10,2,,80,2,1158,,,0.398599851736277,0.0067799178087989,0.00242319749668241,-0.000886399473529309,,,,0.101101223524116,39.995735168457,1.99769737212946,4.02439641952515,3.99978160858154,3.99995470046997,114647.46875,114753.8125,0.1267259567976,1,6,3,4,23.3230000458956,1,20.7283191051497,1.12052917480469,43.49951171875,39.5894432067871,,,,,,,,,,,,,,,,
,3875308026.95788,3.99993524551392,121771.265625,,,,,,,,,,,,,0.431916578410325,2.67129366025533E-5,-0.000925098532956738,10,2,,80,2,1226,,,0.420440530127782,0.00721284625243293,0.0025556436739862,-0.000935528078116477,,,,0.106636671247593,39.995735168457,1.99760441689902,4.02429580688477,3.99983215332031,4.0001220703125,121720.5,121822.03125,0.126651287078857,1,6,3,4,23.3230000458956,1,20.7333971007696,1.11900329589844,44.9657897949219,39.5894432067871,,,,,,,,,,,,,,,,
,3875308166.37309,4.00046539306641,128838.87109375,,,,,,,,,,,,,0.453004452531385,3.31631092703191E-5,-0.00109726007640004,10,2,,80,2,1294,,,0.441384279465169,0.00766449774932051,0.00268261367455125,-0.000982488272711635,,,,0.111940711198632,39.995735168457,1.99745901933457,4.02378177642822,4.00038433074951,4.00053739547729,128788.1015625,128889.640625,0.126732990145683,1,6,3,4,23.3230000458956,1,20.7304732185477,1.12617492675781,43.9882698059082,38.6119270324707,,,,,,,,,,,,,,,,
,3875308305.79274,4.00071001052856,135910.8671875,,,,,,,,,,,,,0.473223529280787,3.37910628785883E-5,-0.00130935896804501,10,2,,80,2,1362,,,0.46152311138078,0.0080561081086141,0.00280464603565633,-0.00102768419310451,,,,0.117039717231008,39.995735168457,1.99730726680443,4.02208375930786,4.00065994262695,4.0007905960083,135857.65625,135964.078125,0.126587435603142,1,6,3,4,23.3230000458956,1,20.7343220418397,1.11900329589844,43.9882698059082,39.5894432067871,,,,,,,,,,,,,,,,
,3875308445.19276,4.00013427734375,140000.5703125,,,,,,,,,,,,,0.48468118917589,3.35419492248378E-5,-0.00142676930689791,10,2,,80,2,1430,,,0.472957401954638,0.00827966044883149,0.0028740530833602,-0.00105309044010937,,,,0.119936110507457,39.995735168457,1.99724369425786,4.02061128616333,3.99999094009399,4.00041770935059,140000.5625,140000.578125,0.12642028927803,1,4,3,4,23.3230000458956,1,20.7309627297202,1.11869812011719,43.9882698059082,40.0782012939453,,,,,,,,,,,,,,,,
,3875308584.6168,3.99904127120972,136371.3125,,,,,,,,,,,,,0.474840316611604,3.42193578987182E-5,-0.00135060404755894,10,2,,80,2,1498,,,0.463129127847111,0.00806054072225482,0.00281436881050467,-0.00103070121258497,,,,0.11743873136423,39.995735168457,1.99715423748798,4.02080917358398,3.99845290184021,3.99926948547363,136321.90625,136420.71875,0.126593664288521,1,6,3,4,23.3230000458956,1,20.7274473180525,1.11824035644531,43.9882698059082,39.5894432067871,,,,,,,,,,,,,,,,
,3875308724.01914,3.99924068450928,129474.7109375,,,,,,,,,,,,,0.455604611132793,3.50270019386917E-5,-0.0011345590958866,10,2,,80,2,1566,,,0.44395593568678,0.00769730538541016,0.00269785337150097,-0.000988084357231855,,,,0.112577385140596,39.995735168457,1.99716784948262,4.02223539352417,3.99920511245728,3.99929428100586,129425.265625,129524.15625,0.126738891005516,1,6,3,4,23.3230000458956,1,20.7322762712415,1.12083435058594,43.9882698059082,40.0782012939453,,,,,,,,,,,,,,,,
,3875308863.45822,3.99970664978027,122576.609375,,,,,,,,,,,,,0.435539556234332,3.26760464812012E-5,-0.00092425251288121,10,2,,80,2,1634,,,0.424012223844118,0.00730733206800358,0.00257643661461771,-0.000943556718993932,,,,0.107510354506864,39.995735168457,1.99698038411428,4.02405309677124,3.99966764450073,3.99976253509521,122524.8046875,122628.4140625,0.126847892999649,1,6,3,4,23.3230000458956,1,20.7370897646813,1.1199951171875,43.49951171875,39.5894432067871,,,,,,,,,,,,,,,,
,3875309002.88074,3.99993305206299,115678.6875,,,,,,,,,,,,,0.414559646201137,5.07029266489543E-5,-0.000655756199357528,10,2,,80,2,1702,,,0.403217455906765,0.00695527313948675,0.00245023355819285,-0.000897215446457267,,,,0.102241534666297,39.995735168457,1.99707428750138,4.02434825897217,3.99986028671265,3.99997425079346,115629.09375,115728.28125,0.126850232481956,1,6,3,4,23.3230000458956,1,20.7336671433142,1.11892700195312,43.49951171875,39.5894432067871,,,,,,,,,,,,,,,,
,3875309142.30121,4.00027141571045,108782.4453125,,,,,,,,,,,,,0.392647803912582,3.10159909934682E-5,-0.000517032900257105,10,2,,80,2,1770,,,0.381562161624852,0.00646269096360479,0.00231873919256032,-0.000848356168717146,,,,0.0967446868230723,39.995735168457,1.99697014393792,4.02392244338989,4.00014972686768,4.00043678283691,108732.859375,108832.03125,0.12690070271492,1,6,3,4,23.3230000458956,1,20.7360818992024,1.12060546875,43.49951171875,39.5894432067871,,,,,,,,,,,,,,,,
,3875309281.7042,4.00057582855225,101888.765625,,,,,,,,,,,,,0.369719700660174,2.08188110881011E-5,-0.000309868783387425,10,2,,80,2,1838,,,0.358964120432181,0.00602608704426312,0.00218162033706903,-0.000797950953710824,,,,0.091020052771767,39.995735168457,1.9970989943541,4.02291345596313,4.00050926208496,4.00067949295044,101836.7421875,101940.7890625,0.126901775598526,1,6,3,4,23.3230000458956,1,20.7391713239702,1.12808227539062,43.49951171875,39.5894432067871,,,,,,,,,,,,,,,,
,3875309421.12898,4.00085792541504,94989.51953125,,,,,,,,,,,,,0.345677043038241,2.54634980407609E-5,-0.000155860180130331,10,2,,80,2,1906,,,0.335332726811128,0.0055311711032431,0.00203805253840983,-0.000744719058275223,,,,0.0850200358041941,39.995735168457,1.9969290856674,4.02098178863525,4.00069952011108,4.00106430053711,94939.859375,95039.1796875,0.126938790082932,1,6,3,4,23.3230000458956,1,20.7380804117129,1.12770080566406,43.49951171875,39.5894432067871,,,,,,,,,,,,,,,,
,3875309560.52752,4.00097160339355,88090.203125,,,,,,,,,,,,,0.320252234985653,1.96338586193433E-5,-6.00605932954248E-5,10,2,,80,2,1974,,,0.310411482190582,0.00497550593624858,0.00188716093543917,-0.000688535452354699,,,,0.0787114583537776,39.995735168457,1.99719936944406,4.01850843429565,4.00031423568726,4.00148010253906,88038.359375,88142.046875,0.126797795295715,1,6,3,4,23.3230000458956,1,20.7367224802048,1.12060546875,43.9882698059082,38.1231689453125,,,,,,,,,,,,,,,,
,3875309699.96532,4.00133981704712,81191.95703125,,,,,,,,,,,,,0.293326374627621,2.25124232439238E-5,6.14159495416008E-5,10,2,,80,2,2042,,,0.284086451057193,0.00444602144299654,0.00172724365256727,-0.000629490707069635,,,,0.0720319385491055,39.995735168457,1.99709577546585,4.01594400405884,4.00122594833374,4.00144386291504,81142.5625,81241.3515625,0.126806527376175,1,6,3,4,23.3230000458956,1,20.7379519358609,1.12838745117188,43.9882698059082,40.5669593811035,,,,,,,,,,,,,,,,
,3875309839.38326,4.00136489868164,74296.24609375,,,,,,,,,,,,,0.265259285482127,2.16837316861307E-5,0.000112679450588406,10,2,,80,2,2110,,,0.256709327914698,0.00386285080115838,0.00156111025717109,-0.000568000483326614,,,,0.0650914012494474,39.995735168457,1.9971357734248,4.01229667663574,4.00126218795776,4.00146627426147,74246.8984375,74345.59375,0.12663546204567,1,6,3,4,23.3230000458956,1,20.7419094823217,1.11923217773438,43.49951171875,39.5894432067871,,,,,,,,,,,,,,,,
,3875309978.80407,4.0014066696167,67397.25,,,,,,,,,,,,,0.239119103646744,1.98243696926435E-5,0.000161793905028235,10,2,,80,2,2178,,,0.231246402462742,0.00333973709726226,0.00140657427255064,-0.000510819721966982,,,,0.0586351527198643,39.995735168457,1.99715967904986,4.00850105285645,4.00134372711182,4.00158929824829,67345.3203125,67449.1796875,0.126525908708572,1,6,3,4,23.3230000458956,1,20.7422623033883,1.119384765625,43.9882698059082,39.5894432067871,,,,,,,,,,,,,,,,
,3875310118.2182,4.00144996643066,60499.189453125,,,,,,,,,,,,,0.220424062011846,2.13345534515773E-5,0.000203191300564301,10,2,,80,2,2246,,,0.213024534129837,0.00293914018260205,0.0012960082385689,-0.000469735823571682,,,,0.0540135992187445,39.995735168457,1.99713370717998,4.00536584854126,4.00138521194458,4.00151062011719,60449.765625,60548.61328125,0.12649393081665,1,6,3,4,23.3230000458956,1,20.7428827610488,1.11991882324219,42.5219955444336,39.5894432067871,,,,,,,,,,,,,,,,
,3875310257.62526,4.00099515914917,53604.130859375,,,,,,,,,,,,,0.202354050711605,2.06708347563585E-5,0.000220128694575612,10,2,,80,2,2314,,,0.195440554038769,0.00254972975377826,0.00118925177957863,-0.000430090993177146,,,,0.0495514890445268,39.995735168457,1.99701215503092,4.00182104110718,4.00094985961914,4.00102806091309,53554.765625,53653.49609375,0.126422092318535,1,6,3,4,23.3230000458956,1,20.7453976518661,1.1199951171875,43.49951171875,39.5894432067871,,,,,,,,,,,,,,,,
,3875310397.04181,4.00101976394653,46708.95703125,,,,,,,,,,,,,0.184467873905945,2.08543375883854E-5,0.000185655035792812,10,2,,80,2,2382,,,0.178065511325386,0.00214167726501437,0.0010837857844308,-0.000390674278605729,,,,0.0451400862833046,39.995735168457,1.99676193060411,3.99852609634399,4.00081872940063,4.00144672393799,46659.6875,46758.2265625,0.126451134681702,1,6,3,4,23.3230000458956,1,20.7441138148796,1.1212158203125,43.9882698059082,39.5894432067871,,,,,,,,,,,,,,,,
,3875310536.48858,4.00068464279175,39812.052734375,,,,,,,,,,,,,0.166701100363618,1.87131828364682E-5,0.000135230554078981,10,2,,80,2,2450,,,0.160834061589277,0.00175038285929841,0.000979319564066827,-0.000351774709997699,,,,0.0407724685344424,39.995735168457,1.99682275444797,3.99737858772278,4.00064086914063,4.00078821182251,39760.1875,39863.91796875,0.126401051878929,1,6,3,4,23.3230000458956,1,20.7453127235891,1.12998962402344,43.49951171875,39.5894432067871,,,,,,,,,,,,,,,,
,3875310675.89669,4.00024461746216,32886.599609375,,,,,,,,,,,,,0.148647515387181,1.67156588399294E-5,8.85422364528032E-5,10,2,,80,2,2518,,,0.143351231400275,0.00139232638611585,0.00087325117783621,-0.000312535761622712,,,,0.0363417082887827,39.995735168457,1.99690109746952,3.99572849273682,4.00019454956055,4.00028657913208,32834.4921875,32938.70703125,0.126388192176819,1,6,3,4,23.3230000458956,1,20.7461583994085,1.11976623535156,43.9882698059082,39.5894432067871,,,,,,,,,,,,,,,,
,3875310815.30089,3.99970111846924,25950.66015625,,,,,,,,,,,,,0.130200751314014,1.54888903401989E-5,2.82100980335094E-5,10,2,,80,2,2586,,,0.125512452643119,0.00105271428817214,0.000764949654694647,-0.000272639736067504,,,,0.0318202795742609,39.995735168457,1.99694525620862,3.99557614326477,3.99961471557617,3.9997706413269,25900.7734375,26000.546875,0.126369997859001,1,6,3,4,23.3230000458956,1,20.7466934267459,1.12052917480469,44.4770278930664,39.5894432067871,,,,,,,,,,,,,,,,
,3875310954.72471,3.99959850311279,19017.251953125,,,,,,,,,,,,,0.111238673105577,1.40195614391727E-5,-2.66421314229916E-5,10,2,,80,2,2654,,,0.107197359132339,0.000751479630150757,0.00065366830676794,-0.000231997299124487,,,,0.02717816231416,39.995735168457,1.99706919010126,3.99635887145996,3.99955081939697,3.99969530105591,18967.51953125,19066.984375,0.126396685838699,1,6,3,4,23.3230000458956,1,20.749331150904,1.12205505371094,43.49951171875,39.5894432067871,,,,,,,,,,,,,,,,
,3875311094.13018,3.99922442436218,12085.046875,,,,,,,,,,,,,0.0915702524090754,1.10609338725783E-5,-8.22723361675964E-5,10,2,,80,2,2722,,,0.0882192566642292,0.000483191347332525,0.000538204563781619,-0.000190089238458313,,,,0.0223654925724358,39.995735168457,1.99697110830923,3.99790406227112,3.99917697906494,3.99926328659058,12035.2451171875,12134.8486328125,0.126377433538437,1,6,3,4,23.3230000458956,1,20.7493658640849,1.11900329589844,43.0107536315918,40.0782012939453,,,,,,,,,,,,,,,,
,3875311233.57819,3.99951219558716,5141.94604492188,,,,,,,,,,,,,0.0702126522732102,1.15208226243998E-5,-0.000103753657183415,10,2,,80,2,2790,,,0.0676286416421383,0.000277850701431728,0.000412766879890114,-0.000145145982969552,,,,0.0171436387491104,39.995735168457,1.99688654484914,3.99923586845398,3.99935579299927,3.99957847595215,5091.6455078125,5192.24658203125,0.126487210392952,1,6,3,4,23.3230000458956,1,20.7487927686339,1.12785339355469,43.49951171875,39.5894432067871,,,,,,,,,,,,,,,,
,3875311373.0701,4.00029063224793,-1806.01605224609,,,,,,,,,,,,,0.0442672144739206,1.34973576801041E-5,-9.34082127742016E-5,1,2,,80,2,2858,,,0.0426347989286876,0.000134601272666322,0.000260314205661416,-9.12771429284476E-5,,,,0.0108083177892895,39.995735168457,1.99700565702949,4.00015068054199,4.00026941299438,4.00030565261841,-1858.4443359375,-1753.58776855469,0.126500815153122,1,6,3,4,23.3230000458956,1,20.7523296041628,1.12037658691406,43.49951171875,39.5894432067871,,,,,,,,,,,,,,,,
,3875311512.4652,4.00087966918945,-8756.75439453125,,,,,,,,,,,,,0.00902651256038927,1.82511078919749E-5,-1.60910045347431E-5,1,2,,80,2,2926,,,0.0086952530288139,3.6519018346691E-5,5.30758188688196E-5,-1.86680827027885E-5,,,,0.00220407819620257,39.995735168457,1.99712879733147,3.9977126121521,4.00077152252197,4.00099182128906,-8809.2265625,-8704.2822265625,0.126469194889069,1,6,3,4,23.3230000458956,1,20.7478019030106,1.12007141113281,43.49951171875,39.5894432067871,,,,,,,,,,,,,,,,
,3875311651.87252,4.00079765319824,-15710.6044921875,,,,,,,,,,,,,-0.0301604956925113,1.65831260143658E-5,2.89557014372464E-5,1,2,,80,2,2994,,,-0.0290608238973586,-0.000170446574038889,-0.000177272784640081,6.26942128292285E-5,,,,0.00736754708208154,39.995735168457,1.99703268965289,3.99538087844849,4.00067090988159,4.00086641311646,-15760.7060546875,-15660.5029296875,0.126348122954369,1,6,3,4,23.3230000458956,1,20.7509787272421,1.12968444824219,43.49951171875,39.5894432067871,,,,,,,,,,,,,,,,
,3875311791.30424,4.00084133148193,-22673.064453125,,,,,,,,,,,,,-0.0615052698150306,1.57219235437412E-5,2.66768758742832E-5,1,2,,80,2,3062,,,-0.0592809869359283,-0.000432592844821923,-0.000361445127055049,0.000128412488265894,,,,0.0150295109225029,39.995735168457,1.99707820348451,3.9943528175354,4.00076627731323,4.00092220306396,-22725.654296875,-22620.474609375,0.126314967870712,1,6,3,4,23.3230000458956,1,20.7511624226846,1.12831115722656,43.49951171875,39.1006851196289,,,,,,,,,,,,,,,,
,3875311932.78337,3.99997770786285,-29746.1337890625,,,,,,,,,,,,,-0.0924684441367987,1.6805494886527E-5,-4.90217418552624E-5,10,2,,80,2,3131,,,-0.089157245551126,-0.000821730455693146,-0.000543240632396191,0.000194157910300419,,,,0.0226049020526554,39.995735168457,1.99705225244194,3.99325561523438,3.99980688095093,4.00009393692017,-29796.12109375,-29696.146484375,0.126298025250435,1,6,3,4,23.3230000458956,1,20.7495737701429,1.13052368164062,43.49951171875,39.5894432067871,,,,,,,,,,,,,,,,
,3875312072.19681,3.99971466064453,-36720.384765625,,,,,,,,,,,,,-0.127076412244992,1.9913109742922E-5,-9.53393187982775E-5,10,2,,80,2,3199,,,-0.122578382498707,-0.00127426288668702,-0.000746558478567749,0.00026786295347847,,,,0.0310786309206833,39.995735168457,1.99705673872374,3.99359059333801,3.99966192245483,3.99977397918701,-36773.0390625,-36667.73046875,0.12631943821907,1,6,3,4,23.3230000458956,1,20.7526356150529,1.12266540527344,43.49951171875,39.5894432067871,,,,,,,,,,,,,,,,
,3875312211.6417,3.99919166564941,-43690.8984375,,,,,,,,,,,,,-0.158963696648309,1.57810227350917E-5,-0.00016739075502265,10,2,,80,2,3267,,,-0.153411316302887,-0.00178872069083483,-0.000933901232201606,0.000336390512529761,,,,0.0388941093553737,39.995735168457,1.99696927915926,3.99508166313171,3.99909639358521,3.99926090240479,-43743.30078125,-43638.49609375,0.126364931464195,1,6,3,4,23.3230000458956,1,20.7513608133418,1.12129211425781,43.49951171875,39.1006851196289,,,,,,,,,,,,,,,,
,3875312351.0566,3.9990002155304,-50663.509765625,,,,,,,,,,,,,-0.184314602569725,2.06068026594539E-5,-0.000210265150210499,10,2,,80,2,3335,,,-0.177973483506818,-0.00226050008485337,-0.00108311441726983,0.000391447742003948,,,,0.0451255175672415,39.995735168457,1.99714705919118,3.99729871749878,3.99878191947937,3.99914932250977,-50713.46484375,-50613.5546875,0.126292198896408,1,6,3,4,23.3230000458956,1,20.7530362106389,1.12091064453125,43.49951171875,39.1006851196289,,,,,,,,,,,,,,,,
,3875312490.49014,3.99893450736999,-57636.9140625,,,,,,,,,,,,,-0.206575873921677,2.18361575959655E-5,-0.000209383883329497,10,2,,80,2,3403,,,-0.19958881678186,-0.00269667525694925,-0.00121419422794133,0.000439931522123516,,,,0.0506012403556266,39.995735168457,1.99693701090696,4.000648021698,3.99879860877991,3.99902701377869,-57689.296875,-57584.53125,0.126276776194572,1,6,3,4,23.3230000458956,1,20.752971662669,1.12129211425781,43.9882698059082,39.5894432067871,,,,,,,,,,,,,,,,
,3875312629.87468,3.99862952232361,-64606.513671875,,,,,,,,,,,,,-0.227446462546429,2.54067221797341E-5,-0.000178927946619182,10,2,,80,2,3471,,,-0.21989732774282,-0.00312163664246919,-0.00133754417765886,0.000485730852233246,,,,0.0557569854314241,39.995735168457,1.99715967962353,4.00392580032349,3.99854207038879,3.99873661994934,-64659,-64554.02734375,0.126392364501953,1,6,3,4,23.3230000458956,1,20.7556419727765,1.13136291503906,43.49951171875,39.1006851196289,,,,,,,,,,,,,,,,
,3875312769.29303,3.99878716468811,-71580.02734375,,,,,,,,,,,,,-0.251513743460989,2.53914271849734E-5,-0.000137643627525847,10,2,,80,2,3539,,,-0.243336997474236,-0.00361037718892393,-0.00147968751844019,0.000538399268407375,,,,0.0616965713330481,39.995735168457,1.9970113038804,4.00803470611572,3.99864745140076,3.99892687797546,-71630.109375,-71529.9453125,0.126468628644943,1,6,3,4,23.3230000458956,1,20.7547937403292,1.12091064453125,43.0107536315918,39.1006851196289,,,,,,,,,,,,,,,,
,3875312908.71728,3.99884867668152,-78565.265625,,,,,,,,,,,,,-0.280307924896375,2.87417432545889E-5,-7.70237748609026E-5,10,2,,80,2,3607,,,-0.271398705126447,-0.00418194523358008,-0.00165012979414314,0.000601281179115176,,,,0.0688153469072016,39.995735168457,1.99709550976427,4.01169538497925,3.99863696098328,3.9990770816803,-78618.296875,-78512.234375,0.126608774065971,1,6,3,4,23.3230000458956,1,20.7485440348465,1.11846923828125,43.49951171875,39.1006851196289,,,,,,,,,,,,,,,,
,3875313048.15108,3.99870686531067,-85616.1015625,,,,,,,,,,,,,-0.308419151116955,1.99257525762361E-5,-1.17111467704214E-5,10,2,,80,2,3675,,,-0.29885492919647,-0.00477610248522436,-0.0018166049849242,0.00066301430342719,,,,0.0757718938319337,39.995735168457,1.99694649004216,4.01612615585327,3.99855589866638,3.99889302253723,-85668.984375,-85563.21875,0.126811042428017,1,6,3,4,23.3230000458956,1,20.74559923445,1.12098693847656,43.49951171875,39.5894432067871,,,,,,,,,,,,,,,,
,3875313187.57112,3.99899220466614,-92663.77734375,,,,,,,,,,,,,-0.335001122727681,2.98629343248514E-5,0.000116595473964547,10,2,,80,2,3743,,,-0.324884352508132,-0.00531412682305918,-0.00197450164705515,0.000721340416930616,,,,0.0823675941026117,39.995735168457,1.99683089578391,4.01777935028076,3.99896311759949,3.99905753135681,-92716.8515625,-92610.703125,0.126767605543137,1,6,3,4,23.3230000458956,1,20.7419506712943,1.11915588378906,43.49951171875,39.5894432067871,,,,,,,,,,,,,,,,
,3875313326.97526,3.99944372177124,-99710.2109375,,,,,,,,,,,,,-0.360229665289297,2.5917211782384E-5,0.000265596291431311,10,2,,80,2,3811,,,-0.349654468916184,-0.00583186058799492,-0.00212505459785461,0.000777073029894382,,,,0.0886576139592608,39.995735168457,1.99705777765049,4.02066373825073,3.99929714202881,3.9995813369751,-99763.2578125,-99657.1640625,0.126843437552452,1,6,3,4,23.3230000458956,1,20.7409063902928,1.12197875976562,43.9882698059082,39.1006851196289,,,,,,,,,,,,,,,,
,3875313466.39912,3.99947805404663,-106756.61328125,,,,,,,,,,,,,-0.384204300565715,2.56754974535033E-5,0.000466683064090536,10,2,,80,2,3879,,,-0.373259581948498,-0.00629321423431299,-0.00226802239194512,0.000829538388643414,,,,0.0946246060994934,39.995735168457,1.99666014076089,4.02237367630005,3.99945259094238,3.99950313568115,-106809.5546875,-106703.671875,0.126861393451691,1,6,3,4,23.3230000458956,1,20.7346708964754,1.12060546875,43.49951171875,39.5894432067871,,,,,,,,,,,,,,,,
,3875313605.80332,3.99963312149048,-113805.5703125,,,,,,,,,,,,,-0.407081703209548,2.28358882385526E-5,0.000688514098127128,10,2,,80,2,3947,,,-0.395848232119082,-0.00672479229888044,-0.00240537873469293,0.000880123174283654,,,,0.100360570600858,39.995735168457,1.99683717606238,4.02376508712769,3.99958944320679,3.99966764450073,-113856.0859375,-113755.0546875,0.126891270279884,1,6,3,4,23.3230000458956,1,20.7346022147589,1.12113952636719,43.49951171875,39.5894432067871,,,,,,,,,,,,,,,,
,3875313745.24904,3.99996328353882,-120857.1875,,,,,,,,,,,,,-0.428900300999856,5.4129141191364E-5,0.000841950891964933,10,2,,80,2,4015,,,-0.417452574462134,-0.00720813948728249,-0.00253657414577901,0.000928802997805178,,,,0.105844051204163,39.995735168457,1.99693571054924,4.02385330200195,3.99989652633667,4.00005531311035,-120907.484375,-120806.890625,0.126964241266251,1,6,3,4,23.3230000458956,1,20.7321001997209,1.12251281738281,43.49951171875,39.5894432067871,,,,,,,,,,,,,,,,
,3875313884.6713,4.00018405914307,-127903.27734375,,,,,,,,,,,,,-0.450091390523479,3.11437600865586E-5,0.00107749150964219,10,2,,80,2,4083,,,-0.438491083709583,-0.00759960034097115,-0.00266428082250059,0.000975605042185634,,,,0.111174266258515,39.995735168457,1.99684371228703,4.02418518066406,4.0001163482666,4.00030565261841,-127953.7109375,-127852.84375,0.126833230257034,1,6,3,4,23.3230000458956,1,20.7291842258213,1.12045288085938,43.0107536315918,39.1006851196289,,,,,,,,,,,,,,,,
,3875314024.07455,4.00041246414185,-134950.9296875,,,,,,,,,,,,,-0.470343625866356,2.83981295690141E-5,0.00128746743212885,10,2,,80,2,4151,,,-0.458655339692358,-0.00799395611532514,-0.0027871907223016,0.0010199622483924,,,,0.116294689439431,39.995735168457,1.9969735307763,4.02241992950439,4.000319480896,4.00050401687622,-135001.453125,-134900.40625,0.126840516924858,1,6,3,4,23.3230000458956,1,20.7117981416845,1.12106323242188,43.49951171875,39.5894432067871,,,,,,,,,,,,,,,,
,3875314163.47837,4.00062818527222,-139999.625,,,,,,,,,,,,,-0.484441844073218,3.4659789416446E-5,0.00144184517249685,10,2,,80,2,4219,,,-0.472724101532801,-0.00826014904693367,-0.00287293735891581,0.00105121289379895,,,,0.119870195474604,39.995735168457,1.99712229089411,4.02086114883423,4.00040626525879,4.00116443634033,-139999.625,-139999.625,0.126761361956596,1,4,3,4,23.3230000458956,1,20.7070035468917,1.12037658691406,43.9882698059082,39.5894432067871,,,,,,,,,,,,,,,,
,3875314302.90391,3.99966316223145,-137247.8671875,,,,,,,,,,,,,-0.477034949839434,3.68461825402172E-5,0.00136328757913659,10,2,,80,2,4287,,,-0.465324232481135,-0.00811564815980412,-0.0028280618134886,0.00103467865847051,,,,0.11799580972698,39.995735168457,1.99716657433806,4.02109527587891,3.99948072433472,3.99981021881103,-137299.90625,-137195.828125,0.1268001049757,1,6,3,4,23.3230000458956,1,20.7068340855194,1.12724304199219,43.9882698059082,39.5894432067871,,,,,,,,,,,,,,,,
,3875314442.31714,3.99923973083496,-130338.61328125,,,,,,,,,,,,,-0.457880965406962,3.461541573862E-5,0.00113371444811842,10,2,,80,2,4355,,,-0.446225331631329,-0.00776777264423001,-0.00271195080131292,0.000992067507468164,,,,0.11314808592799,39.995735168457,1.99710941082572,4.0223240852356,3.99919414520264,3.99931955337524,-130390.6953125,-130286.53125,0.126905709505081,1,6,3,4,23.3230000458956,1,20.7062968139444,1.12068176269531,43.49951171875,39.5894432067871,,,,,,,,,,,,,,,,
,3875314581.75949,3.99991683959961,-123423.4765625,,,,,,,,,,,,,-0.437888280020528,3.55759104480119E-5,0.000930009067837785,10,2,,80,2,4423,,,-0.426346581881636,-0.00737273677710773,-0.00259094010107219,0.000947506341617554,,,,0.108095854689751,39.995735168457,1.99688331972624,4.02413558959961,3.99986028671265,4.00000476837158,-123475.3984375,-123371.5546875,0.126984834671021,1,6,3,4,23.3230000458956,1,20.7071473166242,1.12030029296875,43.9882698059082,40.0782012939453,,,,,,,,,,,,,,,,
,3875314721.16132,4.00026626586914,-116513.3984375,,,,,,,,,,,,,-0.416883625870337,2.85948169538214E-5,0.000695473235135997,10,2,,80,2,4491,,,-0.405522775247692,-0.00698685364890433,-0.00246475334279239,0.000901293999049813,,,,0.102830394774461,39.995735168457,1.99716749896171,4.02456045150757,4.00016069412231,4.00042581558228,-116565.2734375,-116461.5234375,0.127099022269249,1,6,3,4,23.3230000458956,1,20.7094382041159,1.11930847167969,43.9882698059082,39.5894432067871,,,,,,,,,,,,,,,,
,3875314860.58187,4.00015473365784,-109603.1796875,,,,,,,,,,,,,-0.39510509445932,3.59581058062938E-5,0.000538734794379161,10,2,,80,2,4559,,,-0.383990903238453,-0.00651330034931791,-0.00233382545411587,0.000852879718877375,,,,0.0973614752963084,39.995735168457,1.99697424059414,4.0241756439209,4.00006341934204,4.0002589225769,-109655.2578125,-109551.1015625,0.127052620053291,1,6,3,4,23.3230000458956,1,20.7130995061733,1.11991882324219,43.9882698059082,40.0782012939453,,,,,,,,,,,,,,,,
,3875314999.99789,4.00036945343018,-102688.8984375,,,,,,,,,,,,,-0.372398288442109,3.4505266592846E-5,0.000339270889298273,10,2,,80,2,4627,,,-0.361601569517168,-0.00607133016487747,-0.00219803187064826,0.000802838185336441,,,,0.0916907553904573,39.995735168457,1.99712001352698,4.02298545837402,4.00024747848511,4.00051784515381,-102738.546875,-102639.25,0.127076148986816,1,6,3,4,23.3230000458956,1,20.7133682416544,1.11946105957031,43.9882698059082,39.5894432067871,,,,,,,,,,,,,,,,
,3875315139.3991,4.00108528137207,-95776.5078125,,,,,,,,,,,,,-0.348489751898641,3.21080704006754E-5,0.000150166772686143,10,2,,80,2,4695,,,-0.338093566584235,-0.00561055013750923,-0.0020552386995405,0.00075021805241704,,,,0.0857277882737287,39.995735168457,1.99707989218462,4.02085971832275,4.00081634521484,4.00146865844727,-95826.140625,-95726.875,0.126976743340492,1,6,3,4,23.3230000458956,1,20.7131380317308,1.12762451171875,43.9882698059082,39.5894432067871,,,,,,,,,,,,,,,,
,3875315278.83107,4.0007737159729,-88864.95703125,,,,,,,,,,,,,-0.323106669709897,2.40394105421337E-5,3.39460080008735E-5,10,2,,80,2,4763,,,-0.313206279096671,-0.00507253334870311,-0.00190436001867056,0.0006943010375835,,,,0.0794220622337436,39.995735168457,1.99724109791625,4.01866149902344,4.00069952011108,4.00089693069458,-88914.5,-88815.4140625,0.126890301704407,1,6,3,4,23.3230000458956,1,20.7136396864786,1.12892150878906,43.9882698059082,39.5894432067871,,,,,,,,,,,,,,,,
,3875315418.27308,4.00100517272949,-81947.046875,,,,,,,,,,,,,-0.296278299164292,2.4283217779084E-5,-5.73808031426677E-5,10,2,,80,2,4831,,,-0.286969794265088,-0.00451161941644104,-0.00174510374199599,0.000635475269518793,,,,0.0727700362218915,39.995735168457,1.99728181901619,4.01585340499878,4.00096130371094,4.00105571746826,-81996.65625,-81897.4375,0.126903370022774,1,6,3,4,23.3230000458956,1,20.7186620391069,1.11923217773438,43.9882698059082,40.0782012939453,,,,,,,,,,,,,,,,
,3875315557.67221,4.00109827518463,-75034.9140625,,,,,,,,,,,,,-0.268217938637431,2.14874251526049E-5,-0.000152804029528331,10,2,,80,2,4899,,,-0.259592492746318,-0.00396711288399253,-0.00157883658539504,0.000574280100408942,,,,0.0658281372197779,39.995735168457,1.9973079083343,4.01273012161255,4.0010027885437,4.00118684768677,-75084.546875,-74985.28125,0.126855969429016,1,6,3,4,23.3230000458956,1,20.7230278103879,1.11915588378906,45.4545478820801,39.5894432067871,,,,,,,,,,,,,,,,
,3875315697.07516,4.00151567459106,-68125.03515625,,,,,,,,,,,,,-0.24131656698445,1.86424000280345E-5,-0.000185578511759067,10,2,,80,2,4967,,,-0.233388229231756,-0.00341373321972271,-0.00141981348861009,0.000515430059749633,,,,0.0591844417571834,39.995735168457,1.99736733638725,4.00914239883423,4.00138807296753,4.00159978866577,-68177.1171875,-68072.953125,0.126657366752625,1,6,3,4,23.3230000458956,1,20.724644194678,1.12648010253906,44.4770278930664,40.0782012939453,,,,,,,,,,,,,,,,
,3875315836.49847,4.00140514373779,-61209.3203125,,,,,,,,,,,,,-0.222286387696239,1.76490863205063E-5,-0.000208195496353038,10,2,,80,2,5035,,,-0.214838519358096,-0.00298733254369085,-0.00130721123423427,0.000473320251330733,,,,0.0544741721291774,39.995735168457,1.99715340283592,4.00563192367554,4.00134038925171,4.00149965286255,-61258.93359375,-61159.70703125,0.126586005091667,1,6,3,4,23.3230000458956,1,20.7182602090864,1.11907958984375,43.9882698059082,40.0782012939453,,,,,,,,,,,,,,,,
,3875315975.90351,4.00143089294434,-54293.748046875,,,,,,,,,,,,,-0.204130999729436,1.90930322756198E-5,-0.00018639755511645,10,2,,80,2,5103,,,-0.197168870073482,-0.00255611305471548,-0.001200026483275,0.000433362321928143,,,,0.0499930069675728,39.995735168457,1.99711330380727,4.00190448760986,4.00124835968018,4.00152730941772,-54345.8515625,-54241.64453125,0.126542672514915,1,6,3,4,23.3230000458956,1,20.7236865408046,1.1273193359375,44.4770278930664,40.0782012939453,,,,,,,,,,,,,,,,
,3875316115.32853,4.00102844238281,-47378.859375,,,,,,,,,,,,,-0.186222317808237,1.60786002708006E-5,-0.000193560951521198,10,2,,80,2,5171,,,-0.179768388622528,-0.00218457264472131,-0.00109448458533734,0.000394292786950246,,,,0.0455826701622177,39.995735168457,1.99724166043185,3.99890470504761,4.00098609924316,4.00108623504639,-47428.421875,-47329.296875,0.126359328627586,1,6,3,4,23.3230000458956,1,20.7259388389905,1.11839294433594,44.4770278930664,40.0782012939453,,,,,,,,,,,,,,,,
,3875316254.76204,4.00039300918579,-40465.7109375,,,,,,,,,,,,,-0.168392377956406,1.67841085367047E-5,-0.00017669059644977,10,2,,80,2,5239,,,-0.162472846769793,-0.00182155568087312,-0.00098955852445215,0.000355550058884546,,,,0.0412006473082282,39.995735168457,1.99741756475287,3.99672508239746,4.00033950805664,4.00045394897461,-40515.28125,-40416.140625,0.126372635364532,1,6,3,4,23.3230000458956,1,20.7315046170415,1.11968994140625,43.9882698059082,40.5669593811035,,,,,,,,,,,,,,,,
,3875316394.16415,4.00049543380737,-33525.005859375,,,,,,,,,,,,,-0.150327406481972,1.7414143395477E-5,-0.000119791655668662,10,2,,80,2,5307,,,-0.144976703308459,-0.00145001886032561,-0.000883319764398038,0.000316190649755299,,,,0.0367610212140722,39.995735168457,1.99731895623328,3.99567151069641,4.00046443939209,4.00053215026855,-33574.76171875,-33475.25,0.126330554485321,1,6,3,4,23.3230000458956,1,20.7325515151344,1.1175537109375,43.9882698059082,40.0782012939453,,,,,,,,,,,,,,,,
,3875316533.58339,3.99992790222168,-26573.9501953125,,,,,,,,,,,,,-0.131885735887868,1.46254340135288E-5,-5.26098254753244E-5,10,2,,80,2,5375,,,-0.127140792098504,-0.00110025761649864,-0.000774999905843288,0.000276258942903951,,,,0.0322381684115502,39.995735168457,1.99730448909118,3.99527335166931,3.99987077713013,3.99996328353882,-26623.92578125,-26523.974609375,0.126360490918159,1,6,3,4,23.3230000458956,1,20.7338604036364,1.12060546875,43.9882698059082,40.0782012939453,,,,,,,,,,,,,,,,
,3875316673.00837,3.9993166923523,-19619.5732421875,,,,,,,,,,,,,-0.112925700772688,1.47393590233685E-5,1.55876565459663E-5,10,2,,80,2,5443,,,-0.108825955553548,-0.000782485278772012,-0.000663659709971398,0.000235477942624129,,,,0.0275923202505857,39.995735168457,1.99718955672522,3.99587297439575,3.99924421310425,3.99938631057739,-19671.94921875,-19567.197265625,0.126291885972023,1,6,3,4,23.3230000458956,1,20.7339987231233,1.119384765625,43.9882698059082,40.5669593811035,,,,,,,,,,,,,,,,
,3875316812.43486,3.99926862716675,-12665.9760742187,,,,,,,,,,,,,-0.0932632666714534,1.19563010161035E-5,6.20277229243337E-5,10,2,,80,2,5511,,,-0.0898520801719099,-0.000519458664681439,-0.000548273150343448,0.000193697327631526,,,,0.0227843415787446,39.995735168457,1.99742802754365,3.99734997749329,3.99913835525513,3.99936962127686,-12715.8095703125,-12616.142578125,0.126357138156891,1,6,3,4,23.3230000458956,1,20.7367694346088,1.11968994140625,43.9882698059082,40.0782012939453,,,,,,,,,,,,,,,,
,3875316951.82532,3.99956169128418,-5709.06982421875,,,,,,,,,,,,,-0.0720376740308531,1.20003413367507E-5,9.97379901272421E-5,10,2,,80,2,5579,,,-0.0693875334100616,-0.00029566936618261,-0.000423614663304761,0.000148904247907922,,,,0.017594026095365,39.995735168457,1.9973433949069,3.99925065040588,3.99941635131836,3.99973440170288,-5759.0751953125,-5659.064453125,0.126395478844643,1,6,3,4,23.3230000458956,1,20.7332733898685,1.12808227539062,43.9882698059082,40.0782012939453,,,,,,,,,,,,,,,,
,3875317091.32094,4.00011930465698,1260.96722412109,,,,,,,,,,,,,-0.0466097503960002,1.36245308294286E-5,9.72640914758077E-5,1,2,,80,2,5647,,,-0.0448904594299799,-0.000140765075971451,-0.000274171674391255,9.60511169978417E-5,,,,0.0113822767013518,39.995735168457,1.99744292944088,4.00005149841309,4.00000476837158,4.0002646446228,1210.9697265625,1310.96472167969,0.126320526003838,1,6,3,4,23.3230000458956,1,20.7377246127893,1.11946105957031,43.9882698059082,40.0782012939453,,,,,,,,,,,,,,,,
,3875317230.72489,4.00111446380615,8231.61181640625,,,,,,,,,,,,,-0.012003333972019,1.76827782782519E-5,1.88931570474231E-5,1,2,,80,2,5715,,,-0.0115626236868442,-5.028212238833E-5,-7.05844795447774E-5,2.48189862759318E-5,,,,0.00293151549671706,39.995735168457,1.99724161869825,3.99793243408203,4.0010085105896,4.00127077102661,8181.7509765625,8281.47265625,0.126343667507172,1,6,3,4,23.3230000458956,1,20.7339836776311,1.11923217773438,44.4770278930664,40.0782012939453,,,,,,,,,,,,,,,,
,3875317370.14636,4.00082502365112,15204.6030273438,,,,,,,,,,,,,0.0276480664518625,1.69989080600624E-5,-3.16002857078471E-5,1,2,,80,2,5783,,,0.0266394903289491,0.000149671812291967,0.000162561089382507,-5.73989054828417E-5,,,,0.00675428997587378,39.995735168457,1.99740764714512,3.995521068573,4.0007905960083,4.00091075897217,15152.1435546875,15257.0625,0.126152411103249,1,6,3,4,23.3230000458956,1,20.7361717380729,1.11930847167969,43.9882698059082,39.5894432067871,,,,,,,,,,,,,,,,
,3875317509.56267,4.00038206577301,22185.8095703125,,,,,,,,,,,,,0.0594325042060953,1.6001840097396E-5,-3.24581408827813E-5,1,2,,80,2,5851,,,0.057281872096379,0.000407856322651553,0.000349333189660683,-0.000123957666801289,,,,0.0145233374968779,39.995735168457,1.99725131768188,3.99414563179016,4.00033140182495,4.0004620552063,22135.64453125,22235.974609375,0.126118615269661,1,6,3,4,23.3230000458956,1,20.7392097914318,1.12106323242188,43.9882698059082,40.0782012939453,,,,,,,,,,,,,,,,
,3875317651.05787,4.0000244140625,29278.8095703125,,,,,,,,,,,,,0.0904001594456581,1.6883771355459E-5,6.35152557758422E-5,10,2,,80,2,5920,,,0.0871605662254634,0.000812797885341443,0.000531168887391686,-0.000189810991287231,,,,0.0221014358042453,39.995735168457,1.99737314829846,3.9933934211731,3.99990463256836,4.00012445449829,29226.1640625,29331.455078125,0.126044243574142,1,6,3,4,23.3230000458956,1,20.7402504349867,1.1199951171875,44.4770278930664,40.0782012939453,,,,,,,,,,,,,,,,
,3875317790.47351,3.99945373535156,36271.072265625,,,,,,,,,,,,,0.124838403301488,2.06337722057803E-5,0.000107814791078335,10,2,,80,2,5988,,,0.120415912170699,0.0012579732246451,0.000733566004782915,-0.00026308509404771,,,,0.0305356345163133,39.995735168457,1.99744885131153,3.99342274665833,3.99938917160034,3.99955606460571,36220.9453125,36321.19921875,0.126002997159958,1,6,3,4,23.3230000458956,1,20.7416494235873,1.12030029296875,43.9882698059082,40.0782012939453,,,,,,,,,,,,,,,,
,3875317929.89868,3.99924564361572,43261.328125,,,,,,,,,,,,,0.157287379299129,1.57844914112485E-5,0.0001704090181703,10,2,,80,2,6056,,,0.151788687904749,0.0017654440571626,0.000924297957681119,-0.000332754396367818,,,,0.0384919155438223,39.995735168457,1.99745268615326,3.99467158317566,3.99916839599609,3.99936103820801,43211.3671875,43311.2890625,0.125969707965851,1,6,3,4,23.3230000458956,1,20.7432915637484,1.12014770507812,43.9882698059082,40.0782012939453,,,,,,,,,,,,,,,,
,3875318069.31795,3.99883794784546,50253.724609375,,,,,,,,,,,,,0.183013621378899,1.79295028413434E-5,0.000200520608727205,10,2,,80,2,6124,,,0.176711424506682,0.00222665456348063,0.00107571901753545,-0.00038857341860421,,,,0.0448149039737907,39.995735168457,1.99756959369987,3.9967942237854,3.99870038032532,3.9989960193634,50201.07421875,50306.375,0.126021787524223,1,6,3,4,23.3230000458956,1,20.7493159475933,1.11976623535156,43.9882698059082,39.5894432067871,,,,,,,,,,,,,,,,
,3875318208.73753,3.99867262840271,57243.953125,,,,,,,,,,,,,0.205444944734956,1.86971969229668E-5,0.000198015297901332,10,2,,80,2,6192,,,0.198489274921938,0.0026615778242392,0.00120784249156714,-0.000437357753980905,,,,0.050333645803058,39.995735168457,1.99736328350801,4.00042629241943,3.99858689308167,3.99876809120178,57191.01953125,57296.88671875,0.126108080148697,1,6,3,4,23.3230000458956,1,20.7473911617198,1.12838745117188,43.9882698059082,39.1006851196289,,,,,,,,,,,,,,,,
,3875318348.14649,3.99871544837952,64236.701171875,,,,,,,,,,,,,0.226489114373408,2.02023491633829E-5,0.000182611522919781,10,2,,80,2,6260,,,0.21896385423735,0.00310224491427541,0.00133206078317016,-0.000483415497001261,,,,0.0555240513697351,39.995735168457,1.99729959216558,4.00382566452026,3.99857258796692,3.99885678291321,64186.56640625,64286.8359375,0.126125633716583,1,6,3,4,23.3230000458956,1,20.7449329291561,1.11930847167969,43.49951171875,39.5894432067871,,,,,,,,,,,,,,,,
,3875318487.56384,3.99881744384766,71226.48828125,,,,,,,,,,,,,0.250218057476311,2.36721776981451E-5,0.000174477600040284,10,2,,80,2,6328,,,0.24207405049881,0.00361736905282593,0.00147234601899982,-0.000535679224412888,,,,0.0613893205003631,39.995735168457,1.99745615091083,4.00769376754761,3.99869561195374,3.99896311759949,71176.4375,71276.5390625,0.126225680112839,1,6,3,4,23.3230000458956,1,20.7470292733189,1.12930297851562,43.9882698059082,39.5894432067871,,,,,,,,,,,,,,,,
,3875318626.98304,3.99861788749695,78232.546875,,,,,,,,,,,,,0.279066079841174,3.24013919510398E-5,0.000104563734133934,10,2,,80,2,6396,,,0.270186056813732,0.00417964304180544,0.00164303963538259,-0.000598713173530996,,,,0.0685188738680958,39.995735168457,1.99745189844809,4.01130628585815,3.99858117103577,3.99865031242371,78179.3984375,78285.6953125,0.126266375184059,1,6,3,4,23.3230000458956,1,20.7455488707605,1.11854553222656,43.49951171875,40.0782012939453,,,,,,,,,,,,,,,,
,3875318766.41092,3.99903655052185,85301.8203125,,,,,,,,,,,,,0.307366177801887,3.21044926721377E-5,-2.12468277581063E-5,10,2,,80,2,6464,,,0.297824326507493,0.00471727555468877,0.00181084603536874,-0.000660688441712409,,,,0.0755283380157251,39.995735168457,1.99744071046061,4.01476144790649,3.99901032447815,3.99907422065735,85251.171875,85352.46875,0.126380100846291,1,6,3,4,23.3230000458956,1,20.7474914039722,1.12052917480469,43.9882698059082,40.0782012939453,,,,,,,,,,,,,,,,
,3875318905.82231,3.99883027076721,92370.22265625,,,,,,,,,,,,,0.334170390393503,2.37062470090086E-5,-0.000126759525389192,10,2,,80,2,6532,,,0.324067451640251,0.00528066207999608,0.00197001779451966,-0.000719475909136236,,,,0.0821774004686999,39.995735168457,1.99725642943931,4.01782178878784,3.99873185157776,3.99895739555359,92319.453125,92420.9921875,0.126448065042496,1,6,3,4,23.3230000458956,1,20.7396936344619,1.12846374511719,43.49951171875,39.5894432067871,,,,,,,,,,,,,,,,
,3875319045.22587,3.99915108680725,99438.36328125,,,,,,,,,,,,,0.359506800404961,2.89273571054246E-5,-0.000270215319520712,10,2,,80,2,6600,,,0.348941133251415,0.0058057214327876,0.00212108856067061,-0.000775562366470695,,,,0.0884920376236478,39.995735168457,1.99739647740122,4.0205397605896,3.99907183647156,3.9992356300354,99387.5859375,99489.140625,0.126480504870415,1,6,3,4,23.3230000458956,1,20.7418051769419,1.12754821777344,43.9882698059082,40.0782012939453,,,,,,,,,,,,,,,,
,3875319184.63868,3.99951114654541,106505,,,,,,,,,,,,,0.38363164236912,3.10770423877282E-5,-0.000450278860868835,10,2,,80,2,6668,,,0.3726910053365,0.00629047042705161,0.00226514227688313,-0.000828733202069998,,,,0.0945082659328681,39.995735168457,1.99725062115522,4.02275562286377,3.99938344955444,3.99992990493774,106454.25,106555.75,0.12647807598114,1,6,3,4,23.3230000458956,1,20.7391570211396,1.12068176269531,43.9882698059082,40.0782012939453,,,,,,,,,,,,,,,,
,3875319324.07117,3.99963140487671,113576.09375,,,,,,,,,,,,,0.406593122978468,2.99423135259622E-5,-0.000643162870862917,10,2,,80,2,6736,,,0.395360524972079,0.0067523678628471,0.00240269093774259,-0.000879464030731469,,,,0.10025213028795,39.995735168457,1.99715777858924,4.02358198165894,3.99951457977295,3.99970960617065,113522.90625,113629.28125,0.12650041282177,1,6,3,4,23.3230000458956,1,20.7362270968969,1.12060546875,43.9882698059082,39.5894432067871,,,,,,,,,,,,,,,,
,3875319463.50823,3.9999755859375,120647.1640625,,,,,,,,,,,,,0.428441509016487,2.10320915293394E-5,-0.000847685090903575,10,2,,80,2,6804,,,0.416994599620744,0.00718726648957266,0.00253399694338441,-0.000928003166336566,,,,0.105737264073211,39.995735168457,1.99714019299969,4.02423763275146,3.99992990493774,4.00010585784912,120596.453125,120697.875,0.126488283276558,1,6,3,4,23.3230000458956,1,20.7367490486864,1.12930297851562,43.9882698059082,39.5894432067871,,,,,,,,,,,,,,,,
,3875319602.91703,4.00016822814941,127717.58984375,,,,,,,,,,,,,0.449919243031907,2.62168876796465E-5,-0.00106902792758742,10,2,,80,2,6872,,,0.438312389194517,0.00759893394042907,0.00266339536756277,-0.000975593633484095,,,,0.111139353392664,39.995735168457,1.99707483588872,4.02332544326782,4.00008010864258,4.00026941299438,127664.28125,127770.8984375,0.12644499540329,1,6,3,4,23.3230000458956,1,20.734800326808,1.11946105957031,43.9882698059082,39.1006851196289,,,,,,,,,,,,,,,,
,3875319742.3343,4.00057423114777,134786.5390625,,,,,,,,,,,,,0.470287022532701,2.46714417484838E-5,-0.00127015207643764,10,2,,80,2,6940,,,0.458589738913286,0.00800510987905551,0.00278667127713561,-0.00102095678448677,,,,0.116287786057619,39.995735168457,1.99716458991972,4.02251958847046,4.00042009353638,4.00088882446289,134733.234375,134839.84375,0.126276344060898,1,6,3,4,23.3230000458956,1,20.7317393885484,1.12045288085938,43.49951171875,40.0782012939453,,,,,,,,,,,,,,,,
,3875319881.74734,4.00048017501831,140000.5703125,,,,,,,,,,,,,0.484889754686753,2.99836930555621E-5,-0.00146078196821588,10,2,,80,2,7008,,,0.473161589016933,0.00825063443996196,0.00287499441765249,-0.0010533060412854,,,,0.11997434183102,39.995735168457,1.99700346545774,4.02037572860718,4.00030326843262,4.00057697296143,140000.515625,140000.625,0.126296073198318,1,4,3,4,23.3230000458956,1,20.7326370444443,1.12045288085938,43.9882698059082,39.5894432067871,,,,,,,,,,,,,,,,
,3875319965.79738,3.99990863800049,140000.25,,,,,,,,,,,,,0.484900076720673,3.09593466033627E-5,-0.00147222487050156,10,2,,80,2,7049,,,0.473171868882715,0.00823966651588373,0.00287497625686228,-0.00105300126597285,,,,0.119969534676178,39.995735168457,1.99687849173715,4.0205454826355,3.99980163574219,4.00004100799561,140000.25,140000.25,0.126243829727173,1,4,3,4,23.3230000458956,1,20.7287480497109,1.12007141113281,43.49951171875,40.0782012939453,,,,,,,,,,,,,,,,