File: MPMS/NiCl2pym/NiCl2pym_MvH_8K_14T.dat
[Header]
; ACMS II Data File (default extension .dat)
; Copyright (c) 2014, Quantum Design, Inc. All rights reserved.
TITLE,
FILEOPENTIME,3875321536.371,10/19/2022,6:13 am
BYAPP,ACMS II,1.0,1.2
INFO,DYNACOOL ACMS II Option Release 1.0.8 Build 33,APPNAME
INFO,Quantum Design Linear Motor Servo Controller,MOTOR_MODULE_NAME
INFO,3101-100 K0,MOTOR_HW_VERSION
INFO,MMC794,MOTOR_SERIAL_NUMBER
INFO,SRV No X-over 01.03.11,MOTOR_SOFTWARE_VERSION
INFO,ACMS,ACMS_MODULE_NAME
INFO,3101-430 A0,ACMS_HW_VERSION
INFO,ACMSII028,ACMS_SERIAL_NUMBER
INFO,00.14.14,ACMS_SOFTWARE_VERSION
INFO,WF046,COIL_SERIAL_NUMBER
INFO,0,MOMENT_UNITS
INFO,NiCl2pym,SAMPLE_MATERIAL
INFO,7.3mg cling film,SAMPLE_COMMENT
INFO,17.2,SAMPLE_MASS
INFO,,SAMPLE_VOLUME
INFO,,SAMPLE_MOLECULAR_WEIGHT
INFO,,SAMPLE_SIZE
INFO,,SAMPLE_SHAPE
DATATYPE,COMMENT,1
DATATYPE,TIME,2
STARTUPAXIS,X,2
STARTUPAXIS,Y1,5
STARTUPGROUP, AC
FIELDGROUP, AC, 2,3,4,5,6,7,8,9,10,11,12,13,14,15,16,20,21,22,23,24,25,35,43,44,45,46,47,48,49
FIELDGROUP, DC, 2,3,4,17,18,19,20,21,23,24,25,35,36,37,43,44,45,46,47,48,49,50,51
FIELDGROUP, Diagnostic, 26,27,28,29,30,31,32,33,34,38,39,40,41,42,52,53,54,55,56,57,58,59,60,61,62,63,64,65,66,67,68,69
[Data]
Comment,Time Stamp (sec),Temperature (K),Magnetic Field (Oe),AC Moment (emu),AC Std. Dev. (emu),AC Phase (deg),AC Phase Std. Dev. (deg),AC Suscept. (emu/Oe),AC Suscept. Std. Dev. (emu/Oe),AC X'  (emu/Oe),AC X" (emu/Oe),AC X' Std. Dev. (emu/Oe),AC X" Std. Dev. (emu/Oe),AC Drive (Oe),AC Frequency (Hz),DC Moment (emu),DC Std. Err. (emu),DC Quad. Moment (emu),Range (mV),"AC=1 DC=2 Locate=3",Measure Type,Measure Count,Measure Time (sec),Measure Number,AC X' Raw (emu/Oe),AC X" Raw (emu/Oe),DC M. Raw' (emu),DC M. Raw" (emu),Coil InPhase (V),Coil Quadrature (V),Null Status,Trim Ratio,Trim Phase (deg.),Max. Signal (mV),Motor Frequency (Hz),Motor Ampl. (mm),System Temp. (K),Min. Temperature (K),Max. Temperature (K),Min. Field (Oe),Max. Field (Oe),Pressure (Torr),Temp. Status (code),Field Status (code),Chamber Status (code),Measure Status (code),Center Position (mm),Transport Action,Motor Lag (deg),Motor Current (amps),Motor Heatsink Temp. (C),Motor Board Temp. (C),QMap 01,QMap 02,QMap 03,QMap 04,QMap 05,QMap 06,QMap 07,QMap 08,QMap 09,QMap 10,QMap 11,QMap 12,QMap 13,QMap 14,QMap 15,QMap 16
sample offset = 27.08 mm,3875322234.97637,8.00001029968262,0.373511552810669,,,,,,,,,,,,,0.0033509789537163,8.82117762861396E-7,-5.7148225454078E-6,1,2,,80,2,1,,,0.00322729580671074,1.10830714233671E-5,1.98286943486892E-5,-6.942680101929E-6,,,,0.000822262696989131,39.995735168457,2.00953354776118,7.9994158744812,7.99991416931152,8.00007438659668,0.373511552810669,0.373511552810669,0.237230494618416,1,4,3,4,23.3230000458956,1,20.7104690063213,1.12770080566406,31.7693061828613,31.7693061828613,,,,,,,,,,,,,,,,
,3875322380.92242,8.00056266784668,1532.85510253906,,,,,,,,,,,,,0.00717723743623735,9.21137332416457E-6,-1.65703743925844E-5,1,2,,80,2,69,,,0.00691252404767227,2.02928250352748E-5,4.22135526605416E-5,-1.47662531162496E-5,,,,0.00175227544557004,39.995735168457,1.99685330074735,7.99819231033325,8.00048637390137,8.00062561035156,1480.4609375,1585.24926757813,0.238774612545967,1,6,3,4,23.3230000458956,1,20.7219761056473,1.12014770507812,39.5894432067871,32.7468223571777,,,,,,,,,,,,,,,,
,3875322526.92723,8.0010929107666,8830.43505859375,,,,,,,,,,,,,0.0267406805084422,9.44981675741032E-6,-4.64224514921173E-5,1,2,,80,2,137,,,0.0257593473544198,0.00010960461609527,0.000157236660015769,-5.52358869754244E-5,,,,0.0065298324817774,39.995735168457,1.99687214524229,7.99524784088135,8.00076675415039,8.00139427185059,8777.826171875,8883.0439453125,0.239094465970993,1,6,3,4,23.3230000458956,1,20.7225450162206,1.11984252929688,41.5444793701172,34.7018585205078,,,,,,,,,,,,,,,,
,3875322672.58665,8.00092277526855,16116.2963867188,,,,,,,,,,,,,0.0600852522321198,2.11539711499087E-5,-6.34363057344427E-5,1,2,,80,2,205,,,0.0578954018560811,0.000337001421638786,0.00035319579183124,-0.0001247166946996,,,,0.0146762068601828,39.995735168457,1.99685536100565,7.99224328994751,8.00077056884766,8.00101470947266,16063.7919921875,16168.80078125,0.239117503166199,1,6,3,4,23.3230000458956,1,20.7254864962541,1.12129211425781,42.0332374572754,36.1681327819824,,,,,,,,,,,,,,,,
,3875322815.98012,8.00020313262939,23297.748046875,,,,,,,,,,,,,0.0978890510067201,1.55685510890836E-5,-5.03811893690978E-5,1,2,,80,2,273,,,0.0943517898290384,0.000688734470474486,0.000575245474465191,-0.000204128577024676,,,,0.0239156205684279,39.995735168457,1.99669467793064,7.99108266830444,8.00001716613769,8.00037384033203,23245.06640625,23350.4296875,0.239224463701248,1,6,3,4,23.3230000458956,1,20.7296359546715,1.12007141113281,42.5219955444336,36.6568908691406,,,,,,,,,,,,,,,,
,3875322955.38598,7.99955787658691,30287.6923828125,,,,,,,,,,,,,0.123765212209196,1.21125837203293E-5,-1.03473971197826E-5,1,2,,80,2,341,,,0.119337482520333,0.00103547812018349,0.000727228703908622,-0.000259168882621452,,,,0.0302483441670271,39.995735168457,1.99667231283401,7.99223232269287,7.99944496154785,7.99971580505371,30235.064453125,30340.3203125,0.239224404096603,1,6,3,4,23.3230000458956,1,20.7282494000956,1.12159729003906,42.5219955444336,37.6344108581543,,,,,,,,,,,,,,,,
,3875323096.90758,7.99890251159668,37385.453125,,,,,,,,,,,,,0.146118391063132,1.79796051777419E-5,0.000118264378482808,10,2,,80,2,410,,,0.140952236685885,0.00148653831990992,0.000858423358295113,-0.000307711976347491,,,,0.035730736724505,39.995735168457,1.99673972341325,7.99431228637695,7.99868202209473,7.99913787841797,37335.3984375,37435.5078125,0.23945763707161,1,6,3,4,23.3230000458956,1,20.7269724401588,1.12030029296875,43.49951171875,38.1231689453125,,,,,,,,,,,,,,,,
,3875323236.31848,7.99858856201172,44373.849609375,,,,,,,,,,,,,0.166696674511341,1.94902735457911E-5,0.000171285507277812,10,2,,80,2,478,,,0.160882147280958,0.00188683965407321,0.000979321892373264,-0.000352245173417032,,,,0.0407790137627903,39.995735168457,1.99650903366069,7.99801158905029,7.9984188079834,7.99870300292969,44323.6484375,44424.05078125,0.239474147558212,1,6,3,4,23.3230000458956,1,20.7212403406704,1.11946105957031,43.0107536315918,37.6344108581543,,,,,,,,,,,,,,,,
,3875323375.75051,7.99818868637085,51367.24609375,,,,,,,,,,,,,0.186831433410834,2.25828710487848E-5,0.000182619454451827,10,2,,80,2,546,,,0.180414238172519,0.00227925248415738,0.00109787425026298,-0.000395980954635888,,,,0.0457300228553735,39.995735168457,1.99649695999822,8.00215244293213,7.99803018569946,7.99835586547852,51314.65234375,51419.83984375,0.239605829119682,1,6,3,4,23.3230000458956,1,20.7199376061453,1.12762451171875,43.0107536315918,38.6119270324707,,,,,,,,,,,,,,,,
,3875323515.15284,7.99775629043579,58357.169921875,,,,,,,,,,,,,0.206950645228655,2.23215878252176E-5,0.000150579907847746,10,2,,80,2,614,,,0.199964281945971,0.00266364683858881,0.00121652591042221,-0.000439721072325483,,,,0.0506848107892599,39.995735168457,1.99645469139957,8.00810623168945,7.99771165847778,7.99779748916626,58304.49609375,58409.84375,0.239742502570152,1,6,3,4,23.3230000458956,1,20.7199410760564,1.12075805664062,43.0107536315918,38.6119270324707,,,,,,,,,,,,,,,,
,3875323654.56041,7.99798727035522,65346.83203125,,,,,,,,,,,,,0.227669731134581,2.42186904799083E-5,0.000191639198406389,10,2,,80,2,682,,,0.220128524770771,0.00315797370246598,0.00133863161318004,-0.000485420750919729,,,,0.0557928397021021,39.995735168457,1.99632315622842,8.01418876647949,7.99794244766235,7.99807786941528,65294.37890625,65399.28515625,0.239851444959641,1,6,3,4,23.3230000458956,1,20.7203759456075,1.12190246582031,43.49951171875,39.1006851196289,,,,,,,,,,,,,,,,
,3875323793.97149,7.99748125076294,72339.9609375,,,,,,,,,,,,,0.252401539790483,2.96121190948494E-5,0.000135439909211635,10,2,,80,2,750,,,0.244214877372863,0.00364370342953277,0.00148487475235015,-0.000539330882020295,,,,0.0618994562835948,39.995735168457,1.99637834891622,8.02097129821777,7.99735307693481,7.99758386611938,72289.7734375,72390.1484375,0.240083649754524,1,6,3,4,23.3230000458956,1,20.7174558474539,1.12159729003906,43.49951171875,39.1006851196289,,,,,,,,,,,,,,,,
,3875323933.41611,7.99755296707153,79355.63671875,,,,,,,,,,,,,0.279964606924177,2.61309385837465E-5,7.37155447571936E-5,10,2,,80,2,818,,,0.271089502164064,0.00419926811323923,0.00164786993991584,-0.000599518185481429,,,,0.0687070079640973,39.995735168457,1.99624701572299,8.0272102355957,7.99743127822876,7.99766206741333,79304.8203125,79406.453125,0.24025921523571,1,6,3,4,23.3230000458956,1,20.7150332741061,1.12205505371094,43.49951171875,39.1006851196289,,,,,,,,,,,,,,,,
,3875324072.82972,7.99770288467407,86427.71484375,,,,,,,,,,,,,0.307220991863985,2.30347816598119E-5,-3.55995789258577E-5,10,2,,80,2,886,,,0.29772210907289,0.00473903659346836,0.00180965778417885,-0.000659116718452424,,,,0.0754629290119403,39.995735168457,1.99638415636763,8.03473567962647,7.99761438369751,7.9977879524231,86376.9375,86478.4921875,0.240428403019905,1,6,3,4,23.3230000458956,1,20.7111838109387,1.12014770507812,43.49951171875,39.1006851196289,,,,,,,,,,,,,,,,
,3875324212.24056,7.99786462783814,93496.2109375,,,,,,,,,,,,,0.333458002306811,2.1759360676928E-5,-0.000166160726623494,10,2,,80,2,954,,,0.323420528342761,0.00526961719850903,0.00196574116125703,-0.000716909766197205,,,,0.0819838891078101,39.995735168457,1.99656234840994,8.04051876068115,7.99779939651489,7.99795007705688,93445.5,93546.921875,0.24059396982193,1,6,3,4,23.3230000458956,1,20.7139519183038,1.11946105957031,43.9882698059082,39.1006851196289,,,,,,,,,,,,,,,,
,3875324351.6603,7.99789590835571,100564.51953125,,,,,,,,,,,,,0.358757160688846,2.69893505188531E-5,-0.000316960684874911,10,2,,80,2,1022,,,0.348262522973819,0.00578651647328418,0.00211638864129782,-0.000772455881815404,,,,0.0882757455323972,39.995735168457,1.99640976918989,8.04754543304443,7.99774980545044,7.99810075759888,100513.8125,100615.2265625,0.240725666284561,1,6,3,4,23.3230000458956,1,20.7099549127115,1.12045288085938,43.49951171875,39.5894432067871,,,,,,,,,,,,,,,,
,3875324491.07621,7.99792795181274,107633.9921875,,,,,,,,,,,,,0.382995036991719,2.46632530390233E-5,-0.00054558473716082,10,2,,80,2,1090,,,0.372127255731145,0.00622513515575349,0.00226130336523056,-0.000825488998088986,,,,0.0943230630804239,39.995735168457,1.9963465775234,8.05331707000732,7.99789667129517,7.99795007705688,107580.765625,107687.21875,0.240875646471977,1,6,3,4,23.3230000458956,1,20.7066281279996,1.12129211425781,44.9657897949219,38.6119270324707,,,,,,,,,,,,,,,,
,3875324630.48578,7.99821603298187,114702.796875,,,,,,,,,,,,,0.40617234311919,3.12073937348738E-5,-0.000747804947846262,10,2,,80,2,1158,,,0.395010566916275,0.0066802561780079,0.00240004784427583,-0.000876870297361165,,,,0.10012080795609,39.995735168457,1.99627700348243,8.0587100982666,7.99802255630493,7.99860763549805,114649.5390625,114756.0546875,0.240913525223732,1,6,3,4,23.3230000458956,1,20.7115729695131,1.11930847167969,43.49951171875,39.5894432067871,,,,,,,,,,,,,,,,
,3875324769.92604,7.99867324829102,121773.40234375,,,,,,,,,,,,,0.428617070644014,6.60628342226856E-5,-0.000923494105457252,10,2,,80,2,1226,,,0.417228206466712,0.00715248361877344,0.00253503560088575,-0.000926762935705483,,,,0.10576008013281,39.995735168457,1.99641451698392,8.06321239471436,7.99855613708496,7.99883270263672,121722.6484375,121824.15625,0.240988567471504,1,6,3,4,23.3230000458956,1,20.7097735541871,1.1199951171875,43.49951171875,39.5894432067871,,,,,,,,,,,,,,,,
,3875324909.34299,7.99839897155762,128840.55078125,,,,,,,,,,,,,0.450257647505426,3.60848716974656E-5,-0.00113959638272378,10,2,,80,2,1294,,,0.438708235774366,0.00757033033843474,0.0026654361281544,-0.000974643102381378,,,,0.111202748732421,39.995735168457,1.99637771982026,8.06629848480225,7.99834442138672,7.99855995178223,128789.8671875,128891.234375,0.241218358278275,1,6,3,4,23.3230000458956,1,20.7072412448421,1.12014770507812,43.49951171875,39.5894432067871,,,,,,,,,,,,,,,,
,3875325048.7545,7.99895782470703,135912.5234375,,,,,,,,,,,,,0.471150477751416,3.34282310635264E-5,-0.00134087113401451,10,2,,80,2,1362,,,0.459501376275787,0.00798452388025883,0.00279125734232366,-0.00102103978861123,,,,0.116457398324226,39.995735168457,1.99609150508049,8.06989288330078,7.99884414672852,7.99904060363769,135859.296875,135965.75,0.24108025431633,1,6,3,4,23.3230000458956,1,20.7073782658293,1.12159729003906,43.9882698059082,39.5894432067871,,,,,,,,,,,,,,,,
,3875325188.15269,7.99969062805176,140000.609375,,,,,,,,,,,,,0.482859507193439,3.39010130466078E-5,-0.00152583715588394,10,2,,80,2,1430,,,0.471181074495619,0.00814663026020143,0.00286211422644556,-0.00104668759740889,,,,0.119409414892727,39.995735168457,1.99596643013268,8.07180976867676,7.99956512451172,7.99979209899902,140000.609375,140000.609375,0.24120557308197,1,4,3,4,23.3230000458956,1,20.7075483557741,1.12129211425781,43.49951171875,39.5894432067871,,,,,,,,,,,,,,,,
,3875325327.56994,8.0009334564209,136379.4609375,,,,,,,,,,,,,0.472354308509506,4.72081047411047E-5,-0.00137146557054162,10,2,,80,2,1498,,,0.460704707590075,0.00799130832823311,0.00279888953082263,-0.00102372153196484,,,,0.116774779476929,39.995735168457,1.99630217259425,8.07204627990723,8.00079536437988,8.00101852416992,136327.5625,136431.359375,0.241406247019768,1,6,3,4,23.3230000458956,1,20.7071464541129,1.12060546875,43.9882698059082,39.1006851196289,,,,,,,,,,,,,,,,
,3875325466.97541,8.00116729736328,129483.2734375,,,,,,,,,,,,,0.452067825842861,3.28619052350143E-5,-0.0011233589862829,10,2,,80,2,1566,,,0.44050928885879,0.00764012378497334,0.00267662201076746,-0.000979504780843854,,,,0.111679968659096,39.995735168457,1.99675054018967,8.06853675842285,8.00103759765625,8.00123405456543,129431.3359375,129535.2109375,0.241394937038422,1,6,3,4,23.3230000458956,1,20.716771975016,1.12007141113281,43.49951171875,40.5669593811035,,,,,,,,,,,,,,,,
,3875325606.43107,8.00144529342651,122583.5078125,,,,,,,,,,,,,0.431003868566577,5.73153612858589E-5,-0.000977989601922834,10,2,,80,2,1634,,,0.41959744882132,0.00716975480070259,0.00254939310252666,-0.000931733346078545,,,,0.106355408947812,39.995735168457,1.99631419871731,8.06649875640869,8.00139808654785,8.00151824951172,122531.515625,122635.5,0.241433098912239,1,6,3,4,23.3230000458956,1,20.7074402720808,1.12007141113281,43.9882698059082,39.5894432067871,,,,,,,,,,,,,,,,
,3875325745.84183,8.00149965286255,115687.79296875,,,,,,,,,,,,,0.409105351683174,3.68257833356512E-5,-0.000766511927096962,10,2,,80,2,1702,,,0.397914376155353,0.00674793610019077,0.00241784076206386,-0.000883075583260506,,,,0.100858958564513,39.995735168457,1.99632139614779,8.06243419647217,8.00144386291504,8.00160980224609,115635.75,115739.8359375,0.241486087441444,1,6,3,4,23.3230000458956,1,20.7027224902894,1.12075805664062,43.49951171875,38.6119270324707,,,,,,,,,,,,,,,,
,3875325885.27149,8.00184059143066,108791.109375,,,,,,,,,,,,,0.386674670699258,2.88442554363095E-5,-0.000542478691289789,10,2,,80,2,1770,,,0.375758041601248,0.00633228883957603,0.00228335987776518,-0.000833785161375999,,,,0.0952461787827673,39.995735168457,1.99640686799786,8.05793190002441,8.001708984375,8.00196838378906,108738.96875,108843.25,0.24136658012867,1,6,3,4,23.3230000458956,1,20.7049646099616,1.11946105957031,43.49951171875,39.5894432067871,,,,,,,,,,,,,,,,
,3875326024.65703,8.0020076751709,101895.39453125,,,,,,,,,,,,,0.363211046393534,2.69825358028735E-5,-0.000375455972931593,10,2,,80,2,1838,,,0.352645723031025,0.00585124443767646,0.0021432691719383,-0.000782026094384491,,,,0.0893937854386814,39.995735168457,1.99656916360619,8.0521297454834,8.00181770324707,8.00213241577148,101843.3671875,101947.421875,0.241316437721252,1,6,3,4,23.3230000458956,1,20.7055887320056,1.11968994140625,43.9882698059082,39.5894432067871,,,,,,,,,,,,,,,,
,3875326164.09275,8.00190887451172,94994.4140625,,,,,,,,,,,,,0.338888235401186,2.26320876345971E-5,-0.000172430573271401,10,2,,80,2,1906,,,0.328747035408401,0.00540365830747709,0.00199829367920756,-0.00072879996150732,,,,0.0833423933169143,39.995735168457,1.99674580651217,8.04671573638916,8.00179672241211,8.00201225280762,94942.265625,95046.5625,0.241329371929169,1,6,3,4,23.3230000458956,1,20.7061796448514,1.11862182617188,43.49951171875,40.0782012939453,,,,,,,,,,,,,,,,
,3875326303.50303,8.00218486785889,88097.86328125,,,,,,,,,,,,,0.313473862990819,1.88695203216806E-5,-8.3081846619385E-5,10,2,,80,2,1974,,,0.303841537650046,0.00484689993273346,0.00184708775486797,-0.000672485679388046,,,,0.0770206404892617,39.995735168457,1.99654809961135,8.04053211212158,8.00203704833984,8.00225830078125,88045.8046875,88149.921875,0.241182252764702,1,6,3,4,23.3230000458956,1,20.7019863184543,1.12007141113281,43.49951171875,39.5894432067871,,,,,,,,,,,,,,,,
,3875326442.92726,8.00226631164551,81201.6328125,,,,,,,,,,,,,0.287210585592328,2.69420867421E-5,-4.05999063514329E-6,10,2,,80,2,2042,,,0.278164103520339,0.00429145803879916,0.00169118645135313,-0.000614806194789708,,,,0.0705077266940057,39.995735168457,1.99644343189078,8.03447246551514,8.00217247009277,8.00245094299316,81149.625,81253.640625,0.24102146923542,1,6,3,4,23.3230000458956,1,20.7045186176351,1.11991882324219,43.9882698059082,39.5894432067871,,,,,,,,,,,,,,,,
,3875326582.34679,8.00226249694824,74303.41796875,,,,,,,,,,,,,0.260219504827308,2.35154830839163E-5,9.20310193894872E-5,10,2,,80,2,2110,,,0.251832019633706,0.00377176364166242,0.00153131317347288,-0.000555937818717211,,,,0.0638325811747891,39.995735168457,1.99643159123187,8.02791595458984,8.00210952758789,8.0023136138916,74253.8046875,74353.03125,0.240996673703194,1,6,3,4,23.3230000458956,1,20.7055742107553,1.12060546875,43.49951171875,39.5894432067871,,,,,,,,,,,,,,,,
,3875326721.7645,8.00217742919922,67405.18359375,,,,,,,,,,,,,0.23445965224186,2.24985672235102E-5,0.000137033547244616,10,2,,80,2,2178,,,0.226740441507445,0.00325398801845572,0.00137896637897938,-0.000499774643685669,,,,0.0574709619944143,39.995735168457,1.99638154779984,8.02074813842773,8.00208282470703,8.00222778320312,67353.328125,67457.0390625,0.240805953741074,1,6,3,4,23.3230000458956,1,20.7100764173121,1.12022399902344,43.9882698059082,39.5894432067871,,,,,,,,,,,,,,,,
,3875326861.16429,8.00232887268066,60512.841796875,,,,,,,,,,,,,0.213548991447872,1.65394515776113E-5,0.000174547043944011,10,2,,80,2,2246,,,0.206380446469654,0.00282627818684325,0.00125556299462914,-0.000454143853858113,,,,0.0523151540491493,39.995735168457,1.99661192561276,8.01510238647461,8.00224876403809,8.00238990783691,60463.4296875,60562.25390625,0.240566492080688,1,6,3,4,23.3230000458956,1,20.7111372851995,1.11923217773438,43.49951171875,39.5894432067871,,,,,,,,,,,,,,,,
,3875327000.59851,8.00205516815186,53615.71875,,,,,,,,,,,,,0.193820574742781,1.98732313823062E-5,0.000184536319670257,10,2,,80,2,2314,,,0.187198799845352,0.00241708467066717,0.00113905058242381,-0.000411028013331816,,,,0.0474479895874214,39.995735168457,1.99640480957791,8.00942134857178,8.00200271606445,8.00209045410156,53563.8515625,53667.5859375,0.240428924560547,1,6,3,4,23.3230000458956,1,20.7126934207941,1.12113952636719,43.49951171875,40.5669593811035,,,,,,,,,,,,,,,,
,3875327140.00147,8.00175285339356,46717.484375,,,,,,,,,,,,,0.174395003645845,1.85927966205167E-5,0.000194407830073935,10,2,,80,2,2382,,,0.168341867926763,0.00204316054219776,0.00102461350616068,-0.000368840584997088,,,,0.0426690311907348,39.995735168457,1.9964589793361,8.00354480743408,8.00165748596191,8.00184059143066,46668.0703125,46766.8984375,0.240373402833939,1,6,3,4,23.3230000458956,1,20.712906596906,1.1181640625,44.4770278930664,39.5894432067871,,,,,,,,,,,,,,,,
,3875327279.43293,8.00168952941895,39823.283203125,,,,,,,,,,,,,0.155041336185878,1.30052327754906E-5,0.000137193816059405,10,2,,80,2,2450,,,0.149584415256207,0.00163920412530066,0.00091089541092515,-0.000326709123328328,,,,0.0379177586434245,39.995735168457,1.99664159486988,7.99889230728149,8.00151443481445,8.00180816650391,39773.91796875,39872.6484375,0.240415796637535,1,6,3,4,23.3230000458956,1,20.7138435539822,1.12014770507812,43.49951171875,39.5894432067871,,,,,,,,,,,,,,,,
,3875327418.84687,8.00117225646973,32895.330078125,,,,,,,,,,,,,0.135315217607155,1.7824719866458E-5,7.88081438207746E-5,10,2,,80,2,2518,,,0.130493825936478,0.00126587402309666,0.000794966996181756,-0.000284041481791064,,,,0.0330774027255027,39.995735168457,1.99661351206592,7.99595022201538,8.00111389160156,8.00123023986816,32843.140625,32947.51953125,0.240188106894493,1,6,3,4,23.3230000458956,1,20.7164030393485,1.12167358398438,43.49951171875,39.5894432067871,,,,,,,,,,,,,,,,
,3875327558.2838,8.00071792602539,25962.197265625,,,,,,,,,,,,,0.114514836763541,1.50770876503747E-5,1.47434825041319E-5,10,2,,80,2,2586,,,0.110391320214788,0.000916354218982576,0.000672861642669886,-0.000239402317674831,,,,0.0279841667270028,39.995735168457,1.99675834509234,7.9934344291687,8.00057411193848,8.00089073181152,25909.6328125,26014.76171875,0.2401192933321,1,6,3,4,23.3230000458956,1,20.7202164196514,1.12037658691406,43.9882698059082,39.5894432067871,,,,,,,,,,,,,,,,
,3875327697.69349,8.00010261535645,19026.8828125,,,,,,,,,,,,,0.0905634748484058,1.53175672304519E-5,-2.18051452495602E-5,10,2,,80,2,2654,,,0.0872731839906055,0.00061180500685383,0.000532175065018237,-0.000188553938642144,,,,0.0221230387344909,39.995735168457,1.99667941670274,7.99290609359741,8.00001716613769,8.00019454956055,18977.23046875,19076.53515625,0.240076005458832,1,6,3,4,23.3230000458956,1,20.7183960075726,1.119384765625,43.9882698059082,38.6119270324707,,,,,,,,,,,,,,,,
,3875327837.17105,7.99935722351074,12091.4912109375,,,,,,,,,,,,,0.05446244166416,2.33219659980475E-5,-7.56798587964646E-5,1,2,,80,2,2722,,,0.0524694869888677,0.000261655634601433,0.000320171850034967,-0.000112704154162202,,,,0.0132989229597345,39.995735168457,1.99665450411974,7.99291181564331,7.9992561340332,7.99946784973145,12039.341796875,12143.640625,0.240150988101959,1,6,3,4,23.3230000458956,1,20.7173278230925,1.12136840820312,43.9882698059082,40.0782012939453,,,,,,,,,,,,,,,,
,3875327976.58287,7.99899139404297,5152.95166015625,,,,,,,,,,,,,0.0196305076915131,9.19986711186186E-6,-4.26540829901103E-5,1,2,,80,2,2790,,,0.0189081003710114,6.45611660018914E-5,0.000115454196929932,-4.04406855523121E-5,,,,0.00479304987432205,39.995735168457,1.99690206397906,7.99564075469971,7.99880981445313,7.99913024902344,5100.31396484375,5205.58935546875,0.24010257422924,1,6,3,4,23.3230000458956,1,20.7188302769756,1.12014770507812,43.9882698059082,39.5894432067871,,,,,,,,,,,,,,,,
,3875328116.00538,8.00021362304687,-1795.59088134766,,,,,,,,,,,,,-0.00137135998407355,1.24031041743108E-5,6.92867621941378E-7,1,2,,80,2,2858,,,-0.00132077548575077,-6.2883088927881E-6,-8.06027219368843E-6,2.83566942016478E-6,,,,0.000334888134296963,39.995735168457,1.99673552889826,7.99830770492554,8.0001335144043,8.00029373168945,-1845.15502929687,-1746.02673339844,0.240217804908752,1,6,3,4,23.3230000458956,1,20.7198972055078,1.11984252929688,43.49951171875,39.5894432067871,,,,,,,,,,,,,,,,
,3875328255.41619,8.0012001991272,-8749.0693359375,,,,,,,,,,,,,-0.0255169115352794,9.8143149989063E-6,4.28885728899331E-5,1,2,,80,2,2926,,,-0.0245804164404476,-0.000105716651453064,-0.000150046093040146,5.27188167325221E-5,,,,0.00623124201837242,39.995735168457,1.9969874121115,7.99502754211426,8.00107002258301,8.00126838684082,-8801.4248046875,-8696.7138671875,0.240148544311523,1,6,3,4,23.3230000458956,1,20.7229449241875,1.12075805664062,43.9882698059082,40.0782012939453,,,,,,,,,,,,,,,,
,3875328394.82463,8.00074882507324,-15702.8627929687,,,,,,,,,,,,,-0.0568246984525251,2.06662274755873E-5,6.03098724992361E-5,1,2,,80,2,2994,,,-0.0547527601764056,-0.000315535002949799,-0.000333996838890016,0.000117903473437764,,,,0.0138776407327325,39.995735168457,1.99662564665716,7.9921727180481,8.00062561035156,8.00118255615234,-15752.7705078125,-15652.955078125,0.239999890327454,1,6,3,4,23.3230000458956,1,20.7236373993882,1.12136840820312,43.49951171875,39.5894432067871,,,,,,,,,,,,,,,,
,3875328534.22993,8.00023031234741,-22660.787109375,,,,,,,,,,,,,-0.0947344459584665,1.63536413468723E-5,5.42326559922566E-5,1,2,,80,2,3062,,,-0.0913083485307908,-0.000653489337663765,-0.000556699524167925,0.000197382280020975,,,,0.0231424309793834,39.995735168457,1.99654001697327,7.99124336242676,8.00014877319336,8.00030517578125,-22713.251953125,-22608.322265625,0.239903494715691,1,6,3,4,23.3230000458956,1,20.7227108521937,1.11976623535156,43.49951171875,39.5894432067871,,,,,,,,,,,,,,,,
,3875328675.76432,7.99961280822754,-29738.080078125,,,,,,,,,,,,,-0.121667243452203,1.54104451857477E-5,-4.96021895901796E-5,10,2,,80,2,3131,,,-0.117310338683569,-0.00106671152444428,-0.000714794616214931,0.00025498861214146,,,,0.0297364664585581,39.995735168457,1.99666042921002,7.99177408218384,7.99943733215332,7.999755859375,-29788.21875,-29687.94140625,0.239975064992905,1,6,3,4,23.3230000458956,1,20.7222539805628,1.12091064453125,43.49951171875,40.0782012939453,,,,,,,,,,,,,,,,
,3875328815.17611,7.99894371032715,-36712.416015625,,,,,,,,,,,,,-0.14390668431013,1.70643795961334E-5,-0.000101405288971327,10,2,,80,2,3199,,,-0.138812679723458,-0.00143654440337607,-0.000845419010147452,0.000302831962471828,,,,0.0351869642802882,39.995735168457,1.99663887730173,7.99439764022827,7.99871826171875,7.99911117553711,-36765.10546875,-36659.7265625,0.240005791187286,1,6,3,4,23.3230000458956,1,20.7251725514254,1.12274169921875,43.49951171875,39.1006851196289,,,,,,,,,,,,,,,,
,3875328954.58966,7.99856567382813,-43684.8515625,,,,,,,,,,,,,-0.164598645530068,1.66912735503181E-5,-0.000168895422532863,10,2,,80,2,3267,,,-0.158849150303729,-0.00184771683451408,-0.000966974766924977,0.00034777433029376,,,,0.0402641957442283,39.995735168457,1.99655074818416,7.99787282943726,7.99831581115723,7.99870681762695,-43734.99609375,-43634.70703125,0.240112826228142,1,6,3,4,23.3230000458956,1,20.7251876244218,1.11923217773438,43.49951171875,39.1006851196289,,,,,,,,,,,,,,,,
,3875329093.98789,7.99811754226685,-50652.111328125,,,,,,,,,,,,,-0.184749179613739,2.22622786296725E-5,-0.000172347816848531,10,2,,80,2,3335,,,-0.178393070188196,-0.00222845588887681,-0.00108559615910053,0.000391443900298327,,,,0.0452165675307042,39.995735168457,1.99647547911709,8.00174903869629,7.99803018569946,7.99818658828735,-50704.73828125,-50599.484375,0.240107968449593,1,6,3,4,23.3230000458956,1,20.7229781105253,1.12091064453125,43.49951171875,39.1006851196289,,,,,,,,,,,,,,,,
,3875329233.42114,7.99800968170166,-57626.009765625,,,,,,,,,,,,,-0.204839671494209,2.43374409643161E-5,-0.000200051626418417,10,2,,80,2,3403,,,-0.197910901935617,-0.00266640052723713,-0.00120411079842597,0.000435580470366403,,,,0.050171392885741,39.995735168457,1.99676972095791,8.00695991516113,7.99791955947876,7.99811601638794,-57676.03125,-57575.98828125,0.240218833088875,1,6,3,4,23.3230000458956,1,20.7258256577613,1.12159729003906,43.49951171875,38.6119270324707,,,,,,,,,,,,,,,,
,3875329372.81589,7.99764261245727,-64596.03125,,,,,,,,,,,,,-0.225409840928161,2.40388886408095E-5,-0.000164526605896845,10,2,,80,2,3471,,,-0.217927879797441,-0.00308100779927706,-0.00132551044225693,0.000480457238154486,,,,0.0552428604169843,39.995735168457,1.99663062098127,8.01359176635742,7.99754571914673,7.99793100357056,-64646.0859375,-64545.9765625,0.240425631403923,1,6,3,4,23.3230000458956,1,20.7244593681815,1.1199951171875,43.49951171875,39.1006851196289,,,,,,,,,,,,,,,,
,3875329512.26475,7.99761552810669,-71569.078125,,,,,,,,,,,,,-0.249460388889235,2.52773108854028E-5,-0.000127055563582876,10,2,,80,2,3539,,,-0.241349847119983,-0.00357140838546,-0.00146755063906312,0.000532993290107697,,,,0.0611767587800815,39.995735168457,1.99649536146152,8.02017211914062,7.9974045753479,7.99786233901978,-71621.640625,-71516.515625,0.240506216883659,1,6,3,4,23.3230000458956,1,20.7229103804604,1.12052917480469,43.49951171875,40.0782012939453,,,,,,,,,,,,,,,,
,3875329651.67297,7.99778451919556,-78558.86328125,,,,,,,,,,,,,-0.27687290360714,3.10280540519873E-5,-6.83773838677467E-5,10,2,,80,2,3607,,,-0.26807233337841,-0.00412302772783718,-0.0016296060057357,0.000592920696362853,,,,0.067947211075112,39.995735168457,1.99636546717098,8.02682590484619,7.99768877029419,7.99790239334106,-78609.484375,-78508.2421875,0.240697368979454,1,6,3,4,23.3230000458956,1,20.7228027085869,1.12060546875,43.49951171875,39.5894432067871,,,,,,,,,,,,,,,,
,3875329791.09805,7.99734582901001,-85605.37890625,,,,,,,,,,,,,-0.304137261832736,3.1278760219377E-5,2.88729140417262E-5,10,2,,80,2,3675,,,-0.294705585897162,-0.00467026012205669,-0.0017911302857101,0.000652627786621451,,,,0.0746946191710427,39.995735168457,1.99626244341664,8.033203125,7.99724626541138,7.9974160194397,-85655.6328125,-85555.125,0.240736946463585,1,6,3,4,23.3230000458956,1,20.7225386037115,1.12152099609375,43.49951171875,39.1006851196289,,,,,,,,,,,,,,,,
,3875329930.50844,7.99785089492798,-92652.3984375,,,,,,,,,,,,,-0.330437781561029,2.78102150945645E-5,0.000148666177474338,10,2,,80,2,3743,,,-0.320458386873092,-0.00520869892297204,-0.00194738665595651,0.00071029068203643,,,,0.0812205691782181,39.995735168457,1.99622088781514,8.03997230529785,7.99781847000122,7.99786615371704,-92702.90625,-92601.890625,0.240954220294952,1,6,3,4,23.3230000458956,1,20.7181573790901,1.12037658691406,43.9882698059082,39.5894432067871,,,,,,,,,,,,,,,,
,3875330069.91215,7.99773073196411,-99699.79296875,,,,,,,,,,,,,-0.355744967593279,2.56008261203874E-5,0.000326525859716766,10,2,,80,2,3811,,,-0.345301483867146,-0.00569654010680368,-0.00209827511571348,0.000765612989198417,,,,0.0875174945996644,39.995735168457,1.99622486383989,8.04635906219482,7.99765062332153,7.99781084060669,-99750.296875,-99649.2890625,0.241120412945747,1,6,3,4,23.3230000458956,1,20.711136521416,1.12045288085938,43.49951171875,39.1006851196289,,,,,,,,,,,,,,,,
,3875330209.33187,7.99805307388306,-106749.140625,,,,,,,,,,,,,-0.379977386613259,2.41746453137741E-5,0.000506653035254991,10,2,,80,2,3879,,,-0.369152896019665,-0.00617989578141688,-0.00224270578473806,0.000818916247226298,,,,0.0935499444462833,39.995735168457,1.99593282873245,8.05262184143066,7.99796915054321,7.99815034866333,-106802.0234375,-106696.2578125,0.241252839565277,1,6,3,4,23.3230000458956,1,20.7108031491268,1.11968994140625,43.49951171875,39.1006851196289,,,,,,,,,,,,,,,,
,3875330348.76865,7.99823598861694,-113798.11328125,,,,,,,,,,,,,-0.40326466019418,2.65120576516729E-5,0.000680370960846583,10,2,,80,2,3947,,,-0.392135447898963,-0.0066631198472466,-0.00238223909400403,0.000870245159603655,,,,0.0993753132592061,39.995735168457,1.99594993552557,8.05817222595215,7.99816560745239,7.99836158752441,-113848.5546875,-113747.671875,0.241356939077377,1,6,3,4,23.3230000458956,1,20.7044567999246,1.12022399902344,43.49951171875,39.1006851196289,,,,,,,,,,,,,,,,
,3875330488.17684,7.99878692626953,-120847.515625,,,,,,,,,,,,,-0.425380900422811,3.96206512995351E-5,0.00082327834765578,10,2,,80,2,4015,,,-0.414025662320878,-0.00716012323895657,-0.00251498608849943,0.000919484125915915,,,,0.104924057744127,39.995735168457,1.99594218025698,8.06238842010498,7.99868202209473,7.99892234802246,-120900.328125,-120794.703125,0.241370156407356,1,6,3,4,23.3230000458956,1,20.7021447710519,1.12037658691406,43.49951171875,39.5894432067871,,,,,,,,,,,,,,,,
,3875330627.60831,7.99860687255859,-127893.2109375,,,,,,,,,,,,,-0.447175705467976,7.40162531428325E-5,0.00111150728192156,10,2,,80,2,4083,,,-0.435650014018339,-0.0075101188637412,-0.00264678336679935,0.000967235944699496,,,,0.110417558938024,39.995735168457,1.99617658719086,8.06614208221436,7.99849891662598,7.99871826171875,-127946.203125,-127840.21875,0.241497039794922,1,6,3,4,23.3230000458956,1,20.6970179743513,1.12052917480469,45.4545478820801,39.5894432067871,,,,,,,,,,,,,,,,
,3875330767.01245,7.99909744262695,-134940.078125,,,,,,,,,,,,,-0.468110998455359,3.70470901972723E-5,0.00134031964255369,10,2,,80,2,4151,,,-0.456477921491967,-0.00789819907957279,-0.00277309818193316,0.00101344764698297,,,,0.115687771027661,39.995735168457,1.99602094137249,8.06973075866699,7.99897193908691,7.99918746948242,-134993.109375,-134887.046875,0.241554543375969,1,6,3,4,23.3230000458956,1,20.6943127450209,1.12022399902344,43.9882698059082,39.5894432067871,,,,,,,,,,,,,,,,
,3875330906.42423,7.9997257232666,-139999.7265625,,,,,,,,,,,,,-0.482616242485253,2.9115089406333E-5,0.00143560945871048,10,2,,80,2,4219,,,-0.470941852742283,-0.00822979246429892,-0.00286042992956936,0.0010458417236805,,,,0.119337533786455,39.995735168457,1.99574172311483,8.0722599029541,7.99962615966797,7.99979209899902,-139999.75,-139999.703125,0.241597816348076,1,4,3,4,23.3230000458956,1,20.6928684412627,1.12045288085938,43.49951171875,39.5894432067871,,,,,,,,,,,,,,,,
,3875331045.83572,8.00056505203247,-137296.09375,,,,,,,,,,,,,-0.474793161670455,3.95093707953205E-5,0.00139002210995896,10,2,,80,2,4287,,,-0.463140334635231,-0.00804648061471755,-0.00281343678943813,0.00102821679320186,,,,0.117369883502802,39.995735168457,1.99592636653328,8.07201194763184,8.00036430358887,8.00112152099609,-137345.671875,-137246.515625,0.241778030991554,1,6,3,4,23.3230000458956,1,20.6907181897697,1.12091064453125,43.49951171875,39.5894432067871,,,,,,,,,,,,,,,,
,3875331185.27306,8.00088233947754,-130386.91015625,,,,,,,,,,,,,-0.454526636624363,3.77808477755072E-5,0.00124493440395598,10,2,,80,2,4355,,,-0.442960808834757,-0.00759579098038293,-0.00269077951088548,0.00098266324494034,,,,0.112242832781937,39.995735168457,1.99570124941212,8.06968879699707,8.00079345703125,8.00093269348145,-130436.484375,-130337.3359375,0.241789951920509,1,6,3,4,23.3230000458956,1,20.690014760871,1.121826171875,43.49951171875,39.5894432067871,,,,,,,,,,,,,,,,
,3875331324.69872,8.00119400024414,-123472.03515625,,,,,,,,,,,,,-0.433499125606142,5.64629866178533E-5,0.00102673178001734,10,2,,80,2,4423,,,-0.422077120978699,-0.00719708695333596,-0.00256375689059496,0.000936177908442914,,,,0.106943130193774,39.995735168457,1.99554897619912,8.06640529632568,8.00113487243652,8.00124931335449,-123521.578125,-123422.4921875,0.24178159236908,1,6,3,4,23.3230000458956,1,20.6936087445057,1.12037658691406,43.9882698059082,40.0782012939453,,,,,,,,,,,,,,,,
,3875331464.0987,8.00122299194336,-116564.41015625,,,,,,,,,,,,,-0.411688667780294,3.55086780666495E-5,0.000739960042684626,10,2,,80,2,4491,,,-0.400472363681415,-0.00684973103606148,-0.00243277475237846,0.000888514856342226,,,,0.101481880039862,39.995735168457,1.99580063857164,8.06292057037353,8.00107955932617,8.00135993957519,-116616.46875,-116512.3515625,0.241787448525429,1,6,3,4,23.3230000458956,1,20.694053230999,1.12060546875,43.9882698059082,39.5894432067871,,,,,,,,,,,,,,,,
,3875331603.51452,8.00183792114258,-109648.4453125,,,,,,,,,,,,,-0.389335255864622,3.95330346645806E-5,0.000612755266153581,10,2,,80,2,4559,,,-0.378386391448808,-0.00634011088623586,-0.00229879654943943,0.000838744803331792,,,,0.0958815170829759,39.995735168457,1.99574073107114,8.05805587768555,8.00179672241211,8.00190162658691,-109700.40625,-109596.484375,0.241742566227913,1,6,3,4,23.3230000458956,1,20.6955919221448,1.12197875976562,43.9882698059082,40.0782012939453,,,,,,,,,,,,,,,,
,3875331742.93669,8.00215301513672,-102736.64453125,,,,,,,,,,,,,-0.366070376107352,3.26654671310738E-5,0.000391664305687105,10,2,,80,2,4627,,,-0.355459651306687,-0.00591331456512047,-0.00215954519808292,0.000787555181887001,,,,0.0900684581377698,39.995735168457,1.99566120201865,8.05334949493408,8.00199127197266,8.00226783752441,-102788.7421875,-102684.546875,0.24147430062294,1,6,3,4,23.3230000458956,1,20.6935184898084,1.12083435058594,43.9882698059082,40.0782012939453,,,,,,,,,,,,,,,,
,3875331882.34306,8.00225563049316,-95825.17578125,,,,,,,,,,,,,-0.34171027314554,3.10516741216014E-5,0.000235426168862409,10,2,,80,2,4695,,,-0.331519199894999,-0.00541751205767971,-0.00201438926160336,0.000734147615730762,,,,0.0840076401614979,39.995735168457,1.99581239228684,8.04743766784668,8.00214958190918,8.00235939025879,-95877.234375,-95773.1171875,0.241454094648361,1,6,3,4,23.3230000458956,1,20.6985389390435,1.12106323242188,43.9882698059082,39.5894432067871,,,,,,,,,,,,,,,,
,3875332021.77904,8.0020565032959,-88910.9765625,,,,,,,,,,,,,-0.316488053647583,2.50751973572556E-5,0.000106657307271827,10,2,,80,2,4763,,,-0.306792768933247,-0.00489901676960169,-0.00186448451131582,0.000678665935993195,,,,0.0777446383053949,39.995735168457,1.99589708714227,8.04082298278809,8.00195121765137,8.00218200683594,-88960.46875,-88861.484375,0.241314113140106,1,6,3,4,23.3230000458956,1,20.6968795066968,1.12258911132812,43.9882698059082,39.1006851196289,,,,,,,,,,,,,,,,
,3875332161.19336,8.00213479995727,-81998.10546875,,,,,,,,,,,,,-0.290177872944304,2.97691348818756E-5,-1.05594909048322E-5,10,2,,80,2,4831,,,-0.281062859628604,-0.00437618519826118,-0.00170832115691155,0.000621058279648423,,,,0.0712222347617057,39.995735168457,1.99586259014306,8.03493022918701,8.00207328796387,8.00221252441406,-82047.71875,-81948.4921875,0.241259664297104,1,6,3,4,23.3230000458956,1,20.6970469619097,1.12045288085938,44.4770278930664,40.5669593811035,,,,,,,,,,,,,,,,
,3875332300.60582,8.00246095657349,-75082.6953125,,,,,,,,,,,,,-0.263230168205745,2.22566313704104E-5,-0.000102741181056017,10,2,,80,2,4899,,,-0.254766663478535,-0.00384912273192114,-0.00154886790551245,0.000562319532036781,,,,0.0645643500493446,39.995735168457,1.99604861087862,8.02750492095947,8.00229454040527,8.00258445739746,-75134.78125,-75030.609375,0.241079851984978,1,6,3,4,23.3230000458956,1,20.6983418512707,1.11968994140625,43.49951171875,39.5894432067871,,,,,,,,,,,,,,,,
,3875332440.03579,8.0022891998291,-68166.953125,,,,,,,,,,,,,-0.236996539494658,2.2696703833908E-5,-0.000148759398847037,10,2,,80,2,4967,,,-0.229211161336697,-0.00332144568621311,-0.00139380455948412,0.000505200179759413,,,,0.0580897932987865,39.995735168457,1.99612423439206,8.0215482711792,8.0022144317627,8.00234794616699,-68216.5546875,-68117.3515625,0.240899235010147,1,6,3,4,23.3230000458956,1,20.7038150808952,1.12045288085938,44.4770278930664,40.0782012939453,,,,,,,,,,,,,,,,
,3875332579.44657,8.00234746932983,-61256.6015625,,,,,,,,,,,,,-0.215668394274765,2.00739503351582E-5,-0.00016842069126226,10,2,,80,2,5035,,,-0.208443257519477,-0.00286723760442034,-0.00126768345944583,0.000458440539659932,,,,0.052819619387347,39.995735168457,1.99587342086071,8.01564693450928,8.00220108032227,8.0024356842041,-61308.7109375,-61204.4921875,0.240660101175308,1,6,3,4,23.3230000458956,1,20.7041528764594,1.12075805664062,44.4770278930664,40.0782012939453,,,,,,,,,,,,,,,,
,3875332718.85218,8.0021369934082,-54340.998046875,,,,,,,,,,,,,-0.195863448823336,1.8868257407296E-5,-0.000175647676073938,10,2,,80,2,5103,,,-0.189183781658411,-0.0024507027343761,-0.00115106557495892,0.000415217509726062,,,,0.0479468413353061,39.995735168457,1.99620890686434,8.00856590270996,8.00190162658691,8.00223541259766,-54395.546875,-54286.44921875,0.2406175583601,1,6,3,4,23.3230000458956,1,20.70383844754,1.12335205078125,45.4545478820801,40.0782012939453,,,,,,,,,,,,,,,,
,3875332858.30119,8.00178070068359,-47426.18359375,,,,,,,,,,,,,-0.176395184707096,1.53219031396954E-5,-0.000185281349592496,10,2,,80,2,5171,,,-0.1702821586946,-0.00207226497522983,-0.0010362776229158,0.000373052229406312,,,,0.0431556674999029,39.995735168457,1.99617930312136,8.00341510772705,8.00173187255859,8.00183296203613,-47478.27734375,-47374.08984375,0.240363240242004,1,6,3,4,23.3230000458956,1,20.711663880038,1.11984252929688,43.9882698059082,40.0782012939453,,,,,,,,,,,,,,,,
,3875332997.6957,8.00142440795898,-40512.9765625,,,,,,,,,,,,,-0.156974982746271,1.5680237913549E-5,-0.000143288046362626,10,2,,80,2,5239,,,-0.151457266953873,-0.00167837068294743,-0.000922099919989705,0.000330750655848533,,,,0.0383837511371484,39.995735168457,1.99621108352781,7.99987173080444,8.00129508972168,8.00156974792481,-40565.0390625,-40460.9140625,0.240307241678238,1,6,3,4,23.3230000458956,1,20.7080487924638,1.12022399902344,43.9882698059082,40.0782012939453,,,,,,,,,,,,,,,,
,3875333137.11301,8.00096473693848,-33572.001953125,,,,,,,,,,,,,-0.137258627394982,1.63449300722234E-5,-8.24412483699234E-5,10,2,,80,2,5307,,,-0.132373491280085,-0.00129884075758207,-0.000806241587270051,0.000288130948320031,,,,0.0335468680808817,39.995735168457,1.9962133973145,7.9956545829773,8.00082588195801,8.00112915039063,-33624.2734375,-33519.73046875,0.240228995680809,1,6,3,4,23.3230000458956,1,20.7138745993196,1.12083435058594,44.9657897949219,40.0782012939453,,,,,,,,,,,,,,,,
,3875333276.5312,8.00080394744873,-26618.548828125,,,,,,,,,,,,,-0.116563562942311,1.6477405994204E-5,-3.62569830120885E-5,10,2,,80,2,5375,,,-0.11237003591061,-0.000963239013605621,-0.000684778555296361,0.000243830159888603,,,,0.0284813713608716,39.995735168457,1.99650146995658,7.99407768249512,8.00076293945313,8.00086784362793,-26668.357421875,-26568.740234375,0.240154176950455,1,6,3,4,23.3230000458956,1,20.7186359078716,1.12091064453125,44.4770278930664,40.0782012939453,,,,,,,,,,,,,,,,
,3875333415.94092,8.00007476806641,-19663.8828125,,,,,,,,,,,,,-0.0930145408534655,1.56060614185843E-5,2.79614177004893E-5,10,2,,80,2,5443,,,-0.0896378014367822,-0.000630462800249206,-0.000546453753486276,0.000193577332538553,,,,0.0227150272150349,39.995735168457,1.99611238997683,7.99194097518921,8.00004768371582,8.00011253356934,-19716.23828125,-19611.52734375,0.240162238478661,1,6,3,4,23.3230000458956,1,20.7137436169865,1.12136840820312,43.9882698059082,40.0782012939453,,,,,,,,,,,,,,,,
,3875333555.43738,7.99946784973145,-12707.1362304687,,,,,,,,,,,,,-0.0587904510983005,2.20178571197066E-5,8.41602973173582E-5,1,2,,80,2,5511,,,-0.0566404084308802,-0.000284325015436133,-0.000345540436683223,0.000121665885671973,,,,0.0143532414970236,39.995735168457,1.99622422803401,7.99304819107056,7.99936103820801,7.99957275390625,-12759.4541015625,-12654.818359375,0.24013264477253,1,6,3,4,23.3230000458956,1,20.7201129751713,1.12068176269531,43.9882698059082,41.055721282959,,,,,,,,,,,,,,,,
,3875333694.84237,7.99883918762207,-5753.34887695313,,,,,,,,,,,,,-0.0213743040811147,9.64072736817266E-6,4.42193828046451E-5,1,2,,80,2,5579,,,-0.0205880507269742,-7.3736712497499E-5,-0.000125660968478769,4.40312796854414E-5,,,,0.00521649801631647,39.995735168457,1.99614765874287,7.99528074264526,7.99873161315918,7.99897193908691,-5803.2783203125,-5703.41943359375,0.240133732557297,1,6,3,4,23.3230000458956,1,20.7155209621249,1.121826171875,43.9882698059082,40.0782012939453,,,,,,,,,,,,,,,,
,3875333834.2732,7.99945831298828,1216.28863525391,,,,,,,,,,,,,-0.000915926996659872,1.22705869808619E-5,1.28170320359055E-6,1,2,,80,2,5647,,,-0.000882135853040685,-3.36946371801898E-6,-5.38392805538024E-6,1.88794035693718E-6,,,,0.000223906060421652,39.995735168457,1.996214122507,7.99808073043823,7.99909973144531,7.99966430664062,1166.25146484375,1266.32580566406,0.240145564079285,1,6,3,4,23.3230000458956,1,20.7153903064628,1.12060546875,44.4770278930664,40.5669593811035,,,,,,,,,,,,,,,,
,3875333973.68097,8.00151062011719,8186.9072265625,,,,,,,,,,,,,0.0238432611818547,1.04351537679352E-5,-4.51992071757573E-5,1,2,,80,2,5715,,,0.0229678131117227,9.23747306180323E-5,0.000140141331939958,-4.91844402858987E-5,,,,0.00581918288916201,39.995735168457,1.99585316471369,7.9957447052002,8.00139427185059,8.00163650512695,8137.0224609375,8236.7919921875,0.240064159035683,1,6,3,4,23.3230000458956,1,20.7191517444383,1.12144470214844,43.9882698059082,40.0782012939453,,,,,,,,,,,,,,,,
,3875334113.08658,8.0008243560791,15157.4375,,,,,,,,,,,,,0.0535445739597511,1.96149399382678E-5,-6.23556115339416E-5,1,2,,80,2,5783,,,0.0515911402325252,0.000288439642709779,0.000314679171424359,-0.000111008579551708,,,,0.013073954813853,39.995735168457,1.99626893407608,7.99274015426636,8.00071334838867,8.00101470947266,15107.412109375,15207.462890625,0.239909157156944,1,6,3,4,23.3230000458956,1,20.7212517998697,1.11968994140625,44.4770278930664,40.5669593811035,,,,,,,,,,,,,,,,
,3875334252.51317,8.00016288757324,22138.89453125,,,,,,,,,,,,,0.0924328893943605,1.80544377614624E-5,-5.77086126392957E-5,1,2,,80,2,5851,,,0.0890878019287547,0.000626798485267498,0.000543090223800391,-0.000192457446246408,,,,0.0225751658767094,39.995735168457,1.99615731237719,7.9911584854126,8.00010299682617,8.00024032592773,22086.201171875,22191.587890625,0.239734515547752,1,6,3,4,23.3230000458956,1,20.7203255220671,1.1212158203125,45.9433059692383,40.5669593811035,,,,,,,,,,,,,,,,
,3875334394.02491,7.9993371963501,29234.4013671875,,,,,,,,,,,,,0.119988117764476,1.50196498626352E-5,5.49863447045598E-5,10,2,,80,2,5920,,,0.115687962442009,0.00104985395886884,0.000704742793459445,-0.000251349643804133,,,,0.0293172437291048,39.995735168457,1.99612947480076,7.99156904220581,7.99910545349121,7.99944877624512,29181.76171875,29287.041015625,0.239745855331421,1,6,3,4,23.3230000458956,1,20.7194607668261,1.11991882324219,43.9882698059082,40.0782012939453,,,,,,,,,,,,,,,,
,3875334533.4329,7.99910278320313,36223.84375,,,,,,,,,,,,,0.142464771303409,1.52842803988047E-5,0.000107738547370007,10,2,,80,2,5988,,,0.137417339038632,0.00141993167023666,0.000836691586300731,-0.000299652019748464,,,,0.0348229128620015,39.995735168457,1.99603744640301,7.99383735656738,7.99889945983887,7.99921417236328,36171.20703125,36276.48046875,0.23975433409214,1,6,3,4,23.3230000458956,1,20.722816095357,1.12785339355469,43.9882698059082,40.0782012939453,,,,,,,,,,,,,,,,
,3875334672.84343,7.99880905151367,43217.51953125,,,,,,,,,,,,,0.163306271815385,1.36422023218594E-5,0.000136769277991262,10,2,,80,2,6056,,,0.157596797542714,0.00179328555170839,0.000959182332735509,-0.000344686151947826,,,,0.0399359890452002,39.995735168457,1.99600308593121,7.99762678146362,7.99869728088379,7.99892807006836,43167.375,43267.6640625,0.23983296751976,1,6,3,4,23.3230000458956,1,20.7245703908042,1.1199951171875,43.9882698059082,40.0782012939453,,,,,,,,,,,,,,,,
,3875334812.25392,7.99800157546997,50207.708984375,,,,,,,,,,,,,0.183535397444952,1.68189503517778E-5,0.000157198475993716,10,2,,80,2,6124,,,0.177214755577691,0.00218949947463755,0.00107817212119699,-0.000388707965612412,,,,0.0449072892058287,39.995735168457,1.99596278062421,8.0013484954834,7.99791193008423,7.99817705154419,50157.55859375,50257.859375,0.239820271730423,1,6,3,4,23.3230000458956,1,20.72803946613,1.12159729003906,43.9882698059082,40.0782012939453,,,,,,,,,,,,,,,,
,3875334951.66851,7.99780054092407,57197.392578125,,,,,,,,,,,,,0.203687127843622,2.04599757781607E-5,0.000183519311911502,10,2,,80,2,6192,,,0.196789974820302,0.0026252027270093,0.00119705440010875,-0.000432788830948994,,,,0.0498750510235326,39.995735168457,1.99623889267616,8.00718879699707,7.99774217605591,7.99793100357056,57146.88671875,57247.8984375,0.239932224154472,1,6,3,4,23.3230000458956,1,20.7233046482307,1.12167358398438,45.4545478820801,39.5894432067871,,,,,,,,,,,,,,,,
,3875335091.09299,7.99770975112915,64190.208984375,,,,,,,,,,,,,0.224266985999495,2.19382737313536E-5,0.000160362270239815,10,2,,80,2,6260,,,0.21681448173046,0.00305071143918945,0.00131859502289444,-0.000477817578939721,,,,0.0549529998234067,39.995735168457,1.99634426446502,8.01295280456543,7.9976372718811,7.99779939651489,64137.49609375,64242.921875,0.240026444196701,1,6,3,4,23.3230000458956,1,20.7231957097956,1.12335205078125,44.4770278930664,39.5894432067871,,,,,,,,,,,,,,,,
,3875335230.53587,7.99749231338501,71182.94921875,,,,,,,,,,,,,0.248064112036974,2.26677958950875E-5,0.000146195471865715,10,2,,80,2,6328,,,0.239989094528087,0.00355900327106451,0.00145914161112159,-0.000529909855686128,,,,0.0608255830707656,39.995735168457,1.99629228830803,8.01987743377686,7.99743127822876,7.99753427505493,71132.8671875,71233.03125,0.240116402506828,1,6,3,4,23.3230000458956,1,20.7200453116944,1.12228393554688,43.9882698059082,40.0782012939453,,,,,,,,,,,,,,,,
,3875335369.93766,7.99759874343872,78186.1328125,,,,,,,,,,,,,0.275528163647293,2.67159385536097E-5,7.51463591577914E-5,10,2,,80,2,6396,,,0.266759322403038,0.00409796467282236,0.00162146345246583,-0.000589883187785745,,,,0.0676064568965015,39.995735168457,1.99613304233731,8.02640724182129,7.99749231338501,7.99768114089966,78135.421875,78236.84375,0.24019268155098,1,6,3,4,23.3230000458956,1,20.7215109454662,1.12030029296875,44.4770278930664,38.6119270324707,,,,,,,,,,,,,,,,
,3875335509.35129,7.99770402908325,85255.72265625,,,,,,,,,,,,,0.302927424415771,2.90412806191635E-5,-4.22870742498671E-5,10,2,,80,2,6464,,,0.293521644961111,0.00462692216113611,0.00178402767051011,-0.000649781432002783,,,,0.0743948658542084,39.995735168457,1.99627650438383,8.03319454193115,7.99757623672485,7.9977650642395,85202.546875,85308.8984375,0.240475505590439,1,6,3,4,23.3230000458956,1,20.7200081648328,1.12030029296875,43.49951171875,40.0782012939453,,,,,,,,,,,,,,,,
,3875335648.7567,7.997691822052,92320.85546875,,,,,,,,,,,,,0.32939798018963,2.95654239145142E-5,-0.000145551055930919,10,2,,80,2,6532,,,0.319437226988357,0.00518357443276884,0.00194128102157265,-0.000707875937223434,,,,0.0809636360586448,39.995735168457,1.99626324729453,8.03949356079102,7.99756479263306,7.99780702590942,92270.2890625,92371.421875,0.240463957190514,1,6,3,4,23.3230000458956,1,20.7147949112285,1.12060546875,43.9882698059082,39.5894432067871,,,,,,,,,,,,,,,,
,3875335788.17927,7.99781236648559,99393.86328125,,,,,,,,,,,,,0.354790886480417,3.33454516646119E-5,-0.000334513898405328,10,2,,80,2,6600,,,0.344362479061973,0.00566217906335725,0.00209248275496066,-0.000763538584578782,,,,0.0872769904631295,39.995735168457,1.99615465464653,8.04627799987793,7.99761056900024,7.99797677993774,99343.1484375,99444.578125,0.240606278181076,1,6,3,4,23.3230000458956,1,20.7152200446191,1.12205505371094,43.9882698059082,39.5894432067871,,,,,,,,,,,,,,,,
,3875335927.58029,7.99809503555298,106461.4921875,,,,,,,,,,,,,0.379208389976528,3.4324839227947E-5,-0.000494344742663775,10,2,,80,2,6668,,,0.368392097343237,0.00616860306887329,0.00223841890692711,-0.000817411404568702,,,,0.093372000302753,39.995735168457,1.99625654256899,8.0520486831665,7.99801874160767,7.99816560745239,106410.7578125,106512.2265625,0.240672260522842,1,6,3,4,23.3230000458956,1,20.7119449869119,1.12037658691406,43.9882698059082,39.5894432067871,,,,,,,,,,,,,,,,
,3875336067.02763,7.99835968017578,113529.96875,,,,,,,,,,,,,0.402660349578454,3.36742211383788E-5,-0.000652934065207823,10,2,,80,2,6736,,,0.391533679979944,0.00666996937431567,0.00237857108004391,-0.000869196897838265,,,,0.099226212748893,39.995735168457,1.99601867546895,8.05778884887695,7.99828147888184,7.99847221374512,113479.328125,113580.609375,0.240686371922493,1,6,3,4,23.3230000458956,1,20.7081575637603,1.11984252929688,43.9882698059082,40.0782012939453,,,,,,,,,,,,,,,,
,3875336206.44359,7.99871301651001,120600.734375,,,,,,,,,,,,,0.425167091128054,3.20996194151897E-5,-0.000856211614701582,10,2,,80,2,6804,,,0.413804714270921,0.00711624777340972,0.00251391297206283,-0.000918999197892845,,,,0.104876415014032,39.995735168457,1.99614002922647,8.06235122680664,7.99856758117676,7.99881172180176,120547.4765625,120653.9921875,0.240804523229599,1,6,3,4,23.3230000458956,1,20.7058275293884,1.12052917480469,43.9882698059082,40.5669593811035,,,,,,,,,,,,,,,,
,3875336345.86434,7.99873504638672,127670.99609375,,,,,,,,,,,,,0.446825355250196,6.30253680817218E-5,-0.0010835383531536,10,2,,80,2,6872,,,0.435295302952652,0.00752397145355441,0.00264465855434537,-0.000966991297900677,,,,0.110334207217743,39.995735168457,1.99633086686515,8.06562805175781,7.99867057800293,7.99881172180176,127620.46875,127721.5234375,0.240927308797836,1,6,3,4,23.3230000458956,1,20.7045546200056,1.11930847167969,43.9882698059082,40.0782012939453,,,,,,,,,,,,,,,,
,3875336485.27367,7.99873809814453,134742.625,,,,,,,,,,,,,0.467870228253787,3.97292693116435E-5,-0.00131890920338927,10,2,,80,2,6940,,,0.456230697750249,0.00790882308669824,0.00277144508436322,-0.00101347465533763,,,,0.115626494542516,39.995735168457,1.99605836326059,8.06895065307617,7.99866676330566,7.99881172180176,134689.375,134795.875,0.240884631872177,1,6,3,4,23.3230000458956,1,20.703951720988,1.11976623535156,43.9882698059082,39.5894432067871,,,,,,,,,,,,,,,,
,3875336624.68368,7.99960975646973,140000.4609375,,,,,,,,,,,,,0.482982110651669,3.26198163327807E-5,-0.00152643925736869,10,2,,80,2,7008,,,0.471300707698913,0.00814848541069033,0.0028627784922719,-0.00104662962257862,,,,0.119434880632488,39.995735168457,1.99585260907448,8.07229804992676,7.99937629699707,7.99974250793457,140000.453125,140000.46875,0.240971595048904,1,4,3,4,23.3230000458956,1,20.7022622769775,1.12236022949219,43.9882698059082,40.0782012939453,,,,,,,,,,,,,,,,
,3875336710.78585,7.99976959228516,140000.4921875,,,,,,,,,,,,,0.48298747084124,3.48718139313622E-5,-0.00151243632369613,10,2,,80,2,7050,,,0.47130566036597,0.00816225656940264,0.00286304135806859,-0.0010469356784597,,,,0.119448369237393,39.995735168457,1.9960660759042,8.07194900512695,7.99968719482422,7.9998607635498,140000.484375,140000.5,0.240969687700272,1,4,3,4,23.3230000458956,1,20.7043051876711,1.12045288085938,43.9882698059082,40.0782012939453,,,,,,,,,,,,,,,,