File: MPMS/FeCl2pym/FeCl2pym_2-300K_FC.rso.dat
[Header]
TITLE,MPMS RSO Measurement
BYAPP,MPMS Measurement,1.1,Summary
FILEOPENTIME, 1612974808.117000 2/10/2021, 4:33:28 PM

INFO, APPNAME, MPMS MultiVu Application, Revision 1.61,  Build 082

INFO, NAME, Fecl2pym_muciwe2
INFO, WEIGHT, 4.500
INFO, AREA, 1.000
INFO, LENGTH, 1.000
INFO, SHAPE, 0
INFO, COMMENT, eicosane 5.9
INFO, SEQUENCE FILE: JP_ZFC_FC_MH_210210.seq


INFO, BACKGROUND DATA FILE:, None


STARTUPAXIS,X,4,LINEAR,AUTO,0.000000,0.000000
STARTUPAXIS,Y1,5,LINEAR,AUTO,0.000000,0.000000


STARTUPGROUP,Longitudinal
FIELDGROUP,Longitudinal,1,2,3,4,5,6,7,8,9,10,11,19,20,21,22,23,35
FIELDGROUP,Transverse,1,2,3,4,12,13,14,15,16,17,18,24,25,26,27,28,35

PLOT_APPEARANCE,ALL,HORZ_GRID_ON,VERT_GRID_ON,MARKERS_AND_LINES

[Data]
Time,Comment,Field (Oe),Temperature (K),Long Moment (emu),Long Scan Std Dev,Long Offset (cm),Long Offset Std Dev,Long Algorithm,Long Reg Fit,Long Reg Factor,Trans Moment (emu),Trans Scan Std Dev,Trans Offset (cm),Trans Offset Std Dev,Trans Algorithm,Trans Reg Fit,Trans Reg Factor,Long Moment [w/o ABS] (emu),Long Scan Std Dev [w/o ABS],Long Offset [w/o ABS] (cm),Long Offset Std Dev [w/o ABS],Long Reg Fit [w/o ABS],Trans Moment [w/o ABS] (emu),Trans Scan Std Dev [w/o ABS],Trans Offset [w/o ABS] (cm),Trans Offset Std Dev [w/o ABS],Trans Reg Fit [w/o ABS],RSO Position (deg),Amplitude (cm),Frequency,Cycles to Average,Scans per Measurement,Delta Temp (K),Error,EC Comp. Running,Using ABS,
1612974808.117,,1.000000e+002,3.000110e+002,3.040820e-005,1.399376e-008,1.724725e-001,3.085551e-004,3,9.836779e-001,1.825000e+000,,,,,,,,,,,,,,,,,,0,5.000000e+000,1.000000e+000,4,4,1.980591e-002,0,,0,
1612975312.263,,1.000000e+002,2.902741e+002,3.177120e-005,4.199191e-007,1.702174e-001,4.735386e-004,3,9.605387e-001,1.825000e+000,,,,,,,,,,,,,,,,,,0,5.000000e+000,1.000000e+000,4,4,6.469727e-002,0,,0,
1612975546.388,,1.000000e+002,2.794341e+002,3.292569e-005,1.594212e-008,1.559495e-001,1.677013e-003,3,9.851370e-001,1.825000e+000,,,,,,,,,,,,,,,,,,0,5.000000e+000,1.000000e+000,4,4,3.572998e-001,0,,0,
1612975758.502,,1.000000e+002,2.695833e+002,3.421070e-005,1.024172e-008,1.458732e-001,1.546818e-004,3,9.855396e-001,1.825000e+000,,,,,,,,,,,,,,,,,,0,5.000000e+000,1.000000e+000,4,4,3.070068e-001,0,,0,
1612975974.063,,1.000000e+002,2.595840e+002,3.562343e-005,8.572541e-009,1.373673e-001,2.579138e-004,3,9.861715e-001,1.825000e+000,,,,,,,,,,,,,,,,,,0,5.000000e+000,1.000000e+000,4,4,2.396240e-001,0,,0,
1612976186.707,,1.000000e+002,2.495844e+002,3.713422e-005,5.951203e-009,1.303387e-001,7.172925e-005,3,9.866086e-001,1.825000e+000,,,,,,,,,,,,,,,,,,0,5.000000e+000,1.000000e+000,4,4,2.480011e-001,0,,0,
1612976402.268,,1.000000e+002,2.395940e+002,3.874669e-005,1.588616e-008,1.244020e-001,2.641901e-004,3,9.874427e-001,1.825000e+000,,,,,,,,,,,,,,,,,,0,5.000000e+000,1.000000e+000,4,4,2.528076e-001,0,,0,
1612976618.641,,1.000000e+002,2.296154e+002,4.051509e-005,1.005776e-008,1.186618e-001,2.528236e-004,3,9.876987e-001,1.825000e+000,,,,,,,,,,,,,,,,,,0,5.000000e+000,1.000000e+000,4,4,2.317963e-001,0,,0,
1612976834.233,,1.000000e+002,2.196245e+002,4.242984e-005,1.044939e-008,1.130265e-001,1.536784e-004,3,9.880773e-001,1.825000e+000,,,,,,,,,,,,,,,,,,0,5.000000e+000,1.000000e+000,4,4,2.635040e-001,0,,0,
1612977052.711,,1.000000e+002,2.096337e+002,4.451616e-005,9.743697e-009,1.077058e-001,1.314323e-004,3,9.883528e-001,1.825000e+000,,,,,,,,,,,,,,,,,,0,5.000000e+000,1.000000e+000,4,4,2.445068e-001,0,,0,
1612977271.720,,1.000000e+002,1.996366e+002,4.682246e-005,9.481568e-009,1.025384e-001,4.937144e-005,3,9.887211e-001,1.825000e+000,,,,,,,,,,,,,,,,,,0,5.000000e+000,1.000000e+000,4,4,2.299957e-001,0,,0,
1612977493.350,,1.000000e+002,1.896505e+002,4.933648e-005,1.816243e-008,9.765493e-002,8.194758e-005,3,9.889330e-001,1.825000e+000,,,,,,,,,,,,,,,,,,0,5.000000e+000,1.000000e+000,4,4,2.232056e-001,0,,0,
1612977717.522,,1.000000e+002,1.796909e+002,5.212578e-005,8.420687e-009,9.299421e-002,1.799994e-004,3,9.889423e-001,1.825000e+000,,,,,,,,,,,,,,,,,,0,5.000000e+000,1.000000e+000,4,4,1.936035e-001,0,,0,
1612977943.691,,1.000000e+002,1.696852e+002,5.524358e-005,1.930820e-008,8.855698e-002,1.075223e-004,3,9.892199e-001,1.825000e+000,,,,,,,,,,,,,,,,,,0,5.000000e+000,1.000000e+000,4,4,2.193909e-001,0,,0,
1612978173.058,,1.000000e+002,1.597067e+002,5.871480e-005,1.652902e-008,8.436940e-002,8.740403e-005,3,9.894136e-001,1.825000e+000,,,,,,,,,,,,,,,,,,0,5.000000e+000,1.000000e+000,4,4,2.388000e-001,0,,0,
1612978409.368,,1.000000e+002,1.497622e+002,6.261125e-005,2.815112e-008,8.022390e-002,9.936937e-005,3,9.892749e-001,1.825000e+000,,,,,,,,,,,,,,,,,,0,5.000000e+000,1.000000e+000,4,4,2.424927e-001,0,,0,
1612978652.603,,1.000000e+002,1.398501e+002,6.701874e-005,1.568679e-008,7.645913e-002,9.135475e-005,3,9.893473e-001,1.825000e+000,,,,,,,,,,,,,,,,,,0,5.000000e+000,1.000000e+000,4,4,2.084961e-001,0,,0,
1612978903.967,,1.000000e+002,1.299271e+002,7.204920e-005,1.778012e-008,7.280760e-002,5.374214e-005,3,9.892916e-001,1.825000e+000,,,,,,,,,,,,,,,,,,0,5.000000e+000,1.000000e+000,4,4,1.774139e-001,0,,0,
1612979180.617,,1.000000e+002,1.200797e+002,7.780619e-005,1.977495e-008,6.927460e-002,3.130032e-005,3,9.891561e-001,1.825000e+000,,,,,,,,,,,,,,,,,,0,5.000000e+000,1.000000e+000,4,4,6.369781e-002,0,,0,
1612979464.398,,1.000000e+002,1.101026e+002,8.462041e-005,2.400842e-008,6.602169e-002,5.693470e-005,3,9.890080e-001,1.825000e+000,,,,,,,,,,,,,,,,,,0,5.000000e+000,1.000000e+000,4,4,3.779602e-002,0,,0,
1612979755.322,,1.000000e+002,9.995931e+001,9.283432e-005,1.763528e-008,6.281102e-002,8.735526e-005,3,9.888397e-001,1.825000e+000,,,,,,,,,,,,,,,,,,0,5.000000e+000,1.000000e+000,4,4,1.197205e-001,0,,0,
1612980111.237,,1.000000e+002,9.508064e+001,9.726151e-005,3.292287e-008,6.088298e-002,5.489890e-005,3,9.887883e-001,1.825000e+000,,,,,,,,,,,,,,,,,,0,5.000000e+000,1.000000e+000,4,4,2.873993e-002,0,,0,
1612980465.326,,1.000000e+002,9.008181e+001,1.023950e-004,2.935330e-008,5.931341e-002,2.453994e-005,3,9.886979e-001,1.825000e+000,,,,,,,,,,,,,,,,,,0,5.000000e+000,1.000000e+000,4,4,2.776337e-002,0,,0,
1612980809.791,,1.000000e+002,8.508027e+001,1.081057e-004,3.284159e-008,5.780494e-002,3.092798e-005,3,9.885958e-001,1.825000e+000,,,,,,,,,,,,,,,,,,0,5.000000e+000,1.000000e+000,4,4,2.656555e-002,0,,0,
1612981141.260,,1.000000e+002,8.007718e+001,1.144705e-004,1.735741e-008,5.647552e-002,2.271410e-005,3,9.884787e-001,1.825000e+000,,,,,,,,,,,,,,,,,,0,5.000000e+000,1.000000e+000,4,4,2.824402e-002,0,,0,
1612981458.658,,1.000000e+002,7.507906e+001,1.216132e-004,3.499785e-008,5.513626e-002,5.243965e-005,3,9.883320e-001,1.825000e+000,,,,,,,,,,,,,,,,,,0,5.000000e+000,1.000000e+000,4,4,3.024292e-002,0,,0,
1612981764.544,,1.000000e+002,7.007681e+001,1.299092e-004,2.492653e-008,5.393726e-002,3.944436e-005,3,9.881506e-001,1.825000e+000,,,,,,,,,,,,,,,,,,0,5.000000e+000,1.000000e+000,4,4,4.368591e-002,0,,0,
1612981994.691,,1.000000e+002,6.512272e+001,1.392709e-004,2.947881e-008,5.273223e-002,8.000300e-005,3,9.880764e-001,1.825000e+000,,,,,,,,,,,,,,,,,,0,5.000000e+000,1.000000e+000,4,4,1.602936e-002,0,,0,
1612982215.104,,1.000000e+002,6.011238e+001,1.501304e-004,1.965254e-008,5.163690e-002,1.870623e-005,3,9.879609e-001,1.825000e+000,,,,,,,,,,,,,,,,,,0,5.000000e+000,1.000000e+000,4,4,2.584839e-002,0,,0,
1612982473.471,,1.000000e+002,5.506189e+001,1.630263e-004,3.673653e-008,5.051168e-002,4.762884e-005,3,9.878231e-001,1.825000e+000,,,,,,,,,,,,,,,,,,0,5.000000e+000,1.000000e+000,4,4,2.470016e-002,0,,0,
1612982767.001,,1.000000e+002,5.001361e+001,1.785815e-004,1.297860e-008,4.947745e-002,2.278963e-005,3,9.876749e-001,1.825000e+000,,,,,,,,,,,,,,,,,,0,5.000000e+000,1.000000e+000,4,4,3.650665e-003,0,,0,
1612982973.748,,1.000000e+002,4.807873e+001,1.853572e-004,4.542498e-008,4.898987e-002,3.719000e-005,3,9.875585e-001,1.825000e+000,,,,,,,,,,,,,,,,,,0,5.000000e+000,1.000000e+000,4,4,3.956223e-002,0,,0,
1612983186.502,,1.000000e+002,4.607111e+001,1.930156e-004,5.058082e-008,4.864603e-002,5.585670e-005,3,9.875913e-001,1.825000e+000,,,,,,,,,,,,,,,,,,0,5.000000e+000,1.000000e+000,4,4,3.955078e-002,0,,0,
1612983402.078,,1.000000e+002,4.406575e+001,2.013722e-004,5.091573e-008,4.833008e-002,4.922010e-005,3,9.874424e-001,1.825000e+000,,,,,,,,,,,,,,,,,,0,5.000000e+000,1.000000e+000,4,4,3.820801e-002,0,,0,
1612983627.468,,1.000000e+002,4.204905e+001,2.106614e-004,4.807523e-008,4.791671e-002,3.621299e-005,3,9.874228e-001,1.825000e+000,,,,,,,,,,,,,,,,,,0,5.000000e+000,1.000000e+000,4,4,3.231049e-002,0,,0,
1612983848.302,,1.000000e+002,4.004988e+001,2.207727e-004,6.499112e-008,4.759274e-002,2.596182e-005,3,9.873738e-001,1.825000e+000,,,,,,,,,,,,,,,,,,0,5.000000e+000,1.000000e+000,4,4,3.586960e-002,0,,0,
1612984071.975,,1.000000e+002,3.804320e+001,2.320221e-004,5.700888e-008,4.729287e-002,4.744482e-005,3,9.872576e-001,1.825000e+000,,,,,,,,,,,,,,,,,,0,5.000000e+000,1.000000e+000,4,4,2.896118e-002,0,,0,
1612984299.236,,1.000000e+002,3.603785e+001,2.445664e-004,7.049785e-008,4.703986e-002,6.653398e-005,3,9.871860e-001,1.825000e+000,,,,,,,,,,,,,,,,,,0,5.000000e+000,1.000000e+000,4,4,2.611160e-002,0,,0,
1612984531.240,,1.000000e+002,3.401762e+001,2.587920e-004,4.374713e-008,4.670649e-002,2.581142e-005,3,9.871711e-001,1.825000e+000,,,,,,,,,,,,,,,,,,0,5.000000e+000,1.000000e+000,4,4,1.023102e-002,0,,0,
1612984761.059,,1.000000e+002,3.202753e+001,2.746750e-004,5.249796e-008,4.648934e-002,1.999760e-005,3,9.870513e-001,1.825000e+000,,,,,,,,,,,,,,,,,,0,5.000000e+000,1.000000e+000,4,4,1.826096e-002,0,,0,
1612984983.094,,1.000000e+002,3.001900e+001,2.930067e-004,4.380503e-008,4.635981e-002,4.771605e-005,3,9.869879e-001,1.825000e+000,,,,,,,,,,,,,,,,,,0,5.000000e+000,1.000000e+000,4,4,1.041985e-002,0,,0,
1612985195.473,,1.000000e+002,2.801412e+001,3.140927e-004,4.268090e-008,4.611300e-002,2.576884e-005,3,9.869348e-001,1.825000e+000,,,,,,,,,,,,,,,,,,0,5.000000e+000,1.000000e+000,4,4,1.012039e-002,0,,0,
1612985403.702,,1.000000e+002,2.600747e+001,3.387909e-004,4.093536e-008,4.601021e-002,4.742746e-005,3,9.868218e-001,1.825000e+000,,,,,,,,,,,,,,,,,,0,5.000000e+000,1.000000e+000,4,4,6.160736e-003,0,,0,
1612985603.882,,1.000000e+002,2.498559e+001,3.530025e-004,2.298664e-007,4.590209e-002,3.018982e-005,3,9.868371e-001,1.825000e+000,,,,,,,,,,,,,,,,,,0,5.000000e+000,1.000000e+000,4,4,4.000092e-002,0,,0,
1612985786.527,,1.000000e+002,2.401287e+001,3.677940e-004,1.760565e-007,4.594620e-002,1.955160e-005,3,9.867935e-001,1.825000e+000,,,,,,,,,,,,,,,,,,0,5.000000e+000,1.000000e+000,4,4,3.107071e-002,0,,0,
1612985973.712,,1.000000e+002,2.300726e+001,3.844851e-004,2.007339e-007,4.588180e-002,5.769315e-005,3,9.867213e-001,1.825000e+000,,,,,,,,,,,,,,,,,,0,5.000000e+000,1.000000e+000,4,4,3.146935e-002,0,,0,
1612986157.215,,1.000000e+002,2.200567e+001,4.027815e-004,1.507111e-007,4.576970e-002,1.534648e-005,3,9.867232e-001,1.825000e+000,,,,,,,,,,,,,,,,,,0,5.000000e+000,1.000000e+000,4,4,2.378082e-002,0,,0,
1612986347.114,,1.000000e+002,2.100106e+001,4.230759e-004,7.349735e-008,4.574203e-002,4.121723e-005,3,9.867138e-001,1.825000e+000,,,,,,,,,,,,,,,,,,0,5.000000e+000,1.000000e+000,4,4,8.230209e-003,0,,0,
1612986528.246,,1.000000e+002,2.000303e+001,4.455805e-004,8.428735e-008,4.579304e-002,1.841477e-005,3,9.866227e-001,1.825000e+000,,,,,,,,,,,,,,,,,,0,5.000000e+000,1.000000e+000,4,4,8.020401e-003,0,,0,
1612986707.521,,1.000000e+002,1.900287e+001,4.709008e-004,7.017329e-008,4.572856e-002,3.151038e-005,3,9.865731e-001,1.825000e+000,,,,,,,,,,,,,,,,,,0,5.000000e+000,1.000000e+000,4,4,5.321503e-003,0,,0,
1612986883.880,,1.000000e+002,1.800293e+001,4.996553e-004,4.657265e-008,4.577245e-002,2.456312e-005,3,9.865344e-001,1.825000e+000,,,,,,,,,,,,,,,,,,0,5.000000e+000,1.000000e+000,4,4,2.170563e-003,0,,0,
1612987061.564,,1.000000e+002,1.700262e+001,5.326729e-004,3.268858e-008,4.573046e-002,6.573203e-005,3,9.864737e-001,1.825000e+000,,,,,,,,,,,,,,,,,,0,5.000000e+000,1.000000e+000,4,4,1.161575e-003,0,,0,
1612987238.453,,1.000000e+002,1.600258e+001,5.711661e-004,1.975068e-008,4.563467e-002,1.403452e-005,3,9.864607e-001,1.825000e+000,,,,,,,,,,,,,,,,,,0,5.000000e+000,1.000000e+000,4,4,6.904602e-004,0,,0,
1612987415.560,,1.000000e+002,1.500260e+001,6.178715e-004,4.265487e-008,4.566045e-002,4.115412e-005,3,9.863881e-001,1.825000e+000,,,,,,,,,,,,,,,,,,0,5.000000e+000,1.000000e+000,4,4,2.110481e-003,0,,0,
1612987540.204,,1.000000e+002,1.451024e+001,6.450224e-004,2.556356e-007,4.565382e-002,1.212999e-005,3,9.863462e-001,1.825000e+000,,,,,,,,,,,,,,,,,,0,5.000000e+000,1.000000e+000,4,4,1.156044e-002,0,,0,
1612987711.290,,1.000000e+002,1.402627e+001,6.752342e-004,1.661117e-007,4.567051e-002,6.622616e-005,3,9.863148e-001,1.825000e+000,,,,,,,,,,,,,,,,,,0,5.000000e+000,1.000000e+000,4,4,9.479523e-003,0,,0,
1612987887.118,,1.000000e+002,1.351900e+001,7.118888e-004,1.948585e-007,4.565849e-002,6.185083e-005,3,9.862822e-001,1.825000e+000,,,,,,,,,,,,,,,,,,0,5.000000e+000,1.000000e+000,4,4,9.360313e-003,0,,0,
1612988063.476,,1.000000e+002,1.301413e+001,7.558760e-004,3.420142e-007,4.561116e-002,2.743596e-005,3,9.862455e-001,1.825000e+000,,,,,,,,,,,,,,,,,,0,5.000000e+000,1.000000e+000,4,4,8.709908e-003,0,,0,
1612988246.464,,1.000000e+002,1.250807e+001,8.115853e-004,4.491569e-008,4.570651e-002,3.894494e-005,3,9.861593e-001,1.825000e+000,,,,,,,,,,,,,,,,,,0,5.000000e+000,1.000000e+000,4,4,1.810074e-003,0,,0,
1612988417.253,,1.000000e+002,1.200372e+001,8.846117e-004,2.257087e-007,4.562054e-002,1.934339e-005,3,9.860886e-001,1.825000e+000,,,,,,,,,,,,,,,,,,0,5.000000e+000,1.000000e+000,4,4,2.099991e-003,0,,0,
1612988615.093,,1.000000e+002,1.152881e+001,9.818930e-004,5.225900e-007,4.560827e-002,1.121127e-005,3,9.860238e-001,1.825000e+000,,,,,,,,,,,,,,,,,,0,5.000000e+000,1.000000e+000,4,4,6.649971e-003,0,,0,
1612988816.380,,1.000000e+002,1.102032e+001,1.132692e-003,7.610658e-007,4.566942e-002,1.985623e-005,3,9.859099e-001,1.825000e+000,,,,,,,,,,,,,,,,,,0,5.000000e+000,1.000000e+000,4,4,7.240295e-003,0,,0,
1612989013.642,,1.000000e+002,1.051205e+001,1.312066e-003,6.311124e-007,4.556822e-002,2.337253e-005,3,9.858211e-001,1.825000e+000,,,,,,,,,,,,,,,,,,0,5.000000e+000,1.000000e+000,4,4,6.070137e-003,0,,0,
1612989208.081,,1.000000e+002,1.000385e+001,1.302384e-003,6.612293e-007,4.550944e-002,4.212782e-005,3,9.857891e-001,1.825000e+000,,,,,,,,,,,,,,,,,,0,5.000000e+000,1.000000e+000,4,4,7.425308e-003,0,,0,
1612989397.434,,1.000000e+002,9.503778e+000,1.114469e-003,1.123258e-006,4.539566e-002,1.865998e-005,3,9.858452e-001,1.825000e+000,,,,,,,,,,,,,,,,,,0,5.000000e+000,1.000000e+000,4,4,5.437851e-003,0,,0,
1612989586.741,,1.000000e+002,9.003912e+000,8.692769e-004,1.096457e-006,4.520264e-002,4.521971e-005,3,9.859572e-001,1.825000e+000,,,,,,,,,,,,,,,,,,0,5.000000e+000,1.000000e+000,4,4,6.083488e-003,0,,0,
1612989775.033,,1.000000e+002,8.503761e+000,6.819707e-004,7.309988e-007,4.501754e-002,3.742048e-005,3,9.860605e-001,1.825000e+000,,,,,,,,,,,,,,,,,,0,5.000000e+000,1.000000e+000,4,4,5.748749e-003,0,,0,
1612989961.469,,1.000000e+002,8.004351e+000,5.563475e-004,4.461174e-007,4.486598e-002,2.200077e-005,3,9.861017e-001,1.825000e+000,,,,,,,,,,,,,,,,,,0,5.000000e+000,1.000000e+000,4,4,7.775307e-003,0,,0,
1612990147.858,,1.000000e+002,7.504712e+000,4.762039e-004,2.950535e-007,4.467796e-002,1.548104e-005,3,9.862046e-001,1.825000e+000,,,,,,,,,,,,,,,,,,0,5.000000e+000,1.000000e+000,4,4,6.865978e-003,0,,0,
1612990332.203,,1.000000e+002,7.005068e+000,4.217052e-004,2.384225e-007,4.445428e-002,5.918293e-005,3,9.863100e-001,1.825000e+000,,,,,,,,,,,,,,,,,,0,5.000000e+000,1.000000e+000,4,4,7.575035e-003,0,,0,
1612990513.070,,1.000000e+002,6.505137e+000,3.832283e-004,1.505645e-007,4.428918e-002,3.293629e-005,3,9.863234e-001,1.825000e+000,,,,,,,,,,,,,,,,,,0,5.000000e+000,1.000000e+000,4,4,6.701946e-003,0,,0,
1612990634.314,,1.000000e+002,6.012675e+000,3.575768e-004,9.108893e-008,4.438777e-002,3.130660e-005,3,9.863870e-001,1.825000e+000,,,,,,,,,,,,,,,,,,0,5.000000e+000,1.000000e+000,4,4,9.817123e-003,0,,0,
1612990839.267,,1.000000e+002,5.754721e+000,3.470058e-004,1.186928e-007,4.448501e-002,4.664600e-005,3,9.863698e-001,1.825000e+000,,,,,,,,,,,,,,,,,,0,5.000000e+000,1.000000e+000,4,4,7.787228e-003,0,,0,
1612991047.168,,1.000000e+002,5.504592e+000,3.380908e-004,3.495179e-008,4.439367e-002,3.272579e-005,3,9.864073e-001,1.825000e+000,,,,,,,,,,,,,,,,,,0,5.000000e+000,1.000000e+000,4,4,6.072044e-003,0,,0,
1612991244.212,,1.000000e+002,5.257432e+000,3.305803e-004,6.997931e-008,4.445805e-002,1.751364e-005,3,9.864233e-001,1.825000e+000,,,,,,,,,,,,,,,,,,0,5.000000e+000,1.000000e+000,4,4,6.935120e-003,0,,0,
1612991434.891,,1.000000e+002,5.009175e+000,3.244209e-004,7.906505e-008,4.433629e-002,2.686601e-005,3,9.864708e-001,1.825000e+000,,,,,,,,,,,,,,,,,,0,5.000000e+000,1.000000e+000,4,4,1.163435e-002,0,,0,
1612991620.266,,1.000000e+002,4.754485e+000,3.193769e-004,5.263718e-008,4.428815e-002,4.877258e-005,3,9.864402e-001,1.825000e+000,,,,,,,,,,,,,,,,,,0,5.000000e+000,1.000000e+000,4,4,6.258965e-003,0,,0,
1612991801.133,,1.000000e+002,4.505899e+000,3.155574e-004,4.265285e-008,4.434410e-002,4.151401e-005,3,9.864572e-001,1.825000e+000,,,,,,,,,,,,,,,,,,0,5.000000e+000,1.000000e+000,4,4,7.380962e-003,0,,0,
1612991980.144,,1.000000e+002,4.251606e+000,3.124396e-004,7.205107e-008,4.430128e-002,3.399923e-005,3,9.864050e-001,1.825000e+000,,,,,,,,,,,,,,,,,,0,5.000000e+000,1.000000e+000,4,4,7.445335e-003,0,,0,
1612992126.487,,1.000000e+002,4.003087e+000,3.104432e-004,4.170416e-008,4.427765e-002,2.419202e-005,3,9.864256e-001,1.825000e+000,,,,,,,,,,,,,,,,,,0,5.000000e+000,1.000000e+000,4,4,1.437402e-002,0,,0,
1612992273.939,,1.000000e+002,3.754245e+000,3.091029e-004,2.831884e-008,4.426606e-002,3.499286e-005,3,9.863521e-001,1.825000e+000,,,,,,,,,,,,,,,,,,0,5.000000e+000,1.000000e+000,4,4,1.256800e-002,0,,0,
1612992422.451,,1.000000e+002,3.500670e+000,3.083674e-004,1.780928e-008,4.431631e-002,6.305409e-006,3,9.863063e-001,1.825000e+000,,,,,,,,,,,,,,,,,,0,5.000000e+000,1.000000e+000,4,4,7.159948e-003,0,,0,
1612992570.121,,1.000000e+002,3.249023e+000,3.082042e-004,8.356939e-009,4.429691e-002,3.239327e-005,3,9.863474e-001,1.825000e+000,,,,,,,,,,,,,,,,,,0,5.000000e+000,1.000000e+000,4,4,7.761002e-003,0,,0,
1612992749.147,,1.000000e+002,3.002052e+000,3.084664e-004,7.259583e-009,4.434134e-002,5.317627e-005,3,9.862738e-001,1.825000e+000,,,,,,,,,,,,,,,,,,0,5.000000e+000,1.000000e+000,4,4,5.646944e-003,0,,0,
1612992939.296,,1.000000e+002,2.752403e+000,3.090258e-004,8.297349e-009,4.429523e-002,1.243992e-005,3,9.862625e-001,1.825000e+000,,,,,,,,,,,,,,,,,,0,5.000000e+000,1.000000e+000,4,4,5.594015e-003,0,,0,
1612993138.539,,1.000000e+002,2.502755e+000,3.098393e-004,1.782607e-008,4.439687e-002,3.796745e-005,3,9.861591e-001,1.825000e+000,,,,,,,,,,,,,,,,,,0,5.000000e+000,1.000000e+000,4,4,6.294966e-003,0,,0,
1612993353.352,,1.000000e+002,2.252580e+000,3.107567e-004,1.844450e-008,4.434165e-002,2.492636e-005,3,9.861515e-001,1.825000e+000,,,,,,,,,,,,,,,,,,0,5.000000e+000,1.000000e+000,4,4,6.853104e-003,0,,0,
1612993636.320,,1.000000e+002,2.000180e+000,3.118242e-004,1.081407e-008,4.439901e-002,4.144365e-005,3,9.860206e-001,1.825000e+000,,,,,,,,,,,,,,,,,,0,5.000000e+000,1.000000e+000,4,4,6.374121e-003,0,,0,