File: MPMS/FeCl2pym/FeCl2pym_MH.rso.dat
[Header]
TITLE,MPMS RSO Measurement
BYAPP,MPMS Measurement,1.1,Summary
FILEOPENTIME, 1613000610.827000 2/10/2021, 11:43:30 PM

INFO, APPNAME, MPMS MultiVu Application, Revision 1.61,  Build 082

INFO, NAME, Fecl2pym_muciwe2
INFO, WEIGHT, 4.500
INFO, AREA, 1.000
INFO, LENGTH, 1.000
INFO, SHAPE, 0
INFO, COMMENT, eicosane 5.9
INFO, SEQUENCE FILE: JP_ZFC_FC_MH_210210.seq


INFO, BACKGROUND DATA FILE:, None


STARTUPAXIS,X,4,LINEAR,AUTO,0.000000,0.000000
STARTUPAXIS,Y1,5,LINEAR,AUTO,0.000000,0.000000


STARTUPGROUP,Longitudinal
FIELDGROUP,Longitudinal,1,2,3,4,5,6,7,8,9,10,11,19,20,21,22,23,35
FIELDGROUP,Transverse,1,2,3,4,12,13,14,15,16,17,18,24,25,26,27,28,35

PLOT_APPEARANCE,ALL,HORZ_GRID_ON,VERT_GRID_ON,MARKERS_AND_LINES

[Data]
Time,Comment,Field (Oe),Temperature (K),Long Moment (emu),Long Scan Std Dev,Long Offset (cm),Long Offset Std Dev,Long Algorithm,Long Reg Fit,Long Reg Factor,Trans Moment (emu),Trans Scan Std Dev,Trans Offset (cm),Trans Offset Std Dev,Trans Algorithm,Trans Reg Fit,Trans Reg Factor,Long Moment [w/o ABS] (emu),Long Scan Std Dev [w/o ABS],Long Offset [w/o ABS] (cm),Long Offset Std Dev [w/o ABS],Long Reg Fit [w/o ABS],Trans Moment [w/o ABS] (emu),Trans Scan Std Dev [w/o ABS],Trans Offset [w/o ABS] (cm),Trans Offset Std Dev [w/o ABS],Trans Reg Fit [w/o ABS],RSO Position (deg),Amplitude (cm),Frequency,Cycles to Average,Scans per Measurement,Delta Temp (K),Error,EC Comp. Running,Using ABS,
1613000610.827,,0.000000e+000,2.001093e+000,-1.902381e-005,4.975009e-008,0.000000e+000,0.000000e+000,2,9.288695e-001,1.825000e+000,,,,,,,,,,,,,,,,,,0,3.000000e+000,1.000000e+000,4,4,1.568079e-003,0,,0,
1613000663.649,,1.005871e+002,2.002428e+000,2.572251e-004,3.946725e-007,0.000000e+000,0.000000e+000,2,9.571793e-001,1.825000e+000,,,,,,,,,,,,,,,,,,0,3.000000e+000,1.000000e+000,4,4,3.340244e-004,0,,0,
1613000704.755,,2.030075e+002,2.002070e+000,5.334566e-004,1.042295e-006,0.000000e+000,0.000000e+000,2,9.565612e-001,1.825000e+000,,,,,,,,,,,,,,,,,,0,3.000000e+000,1.000000e+000,4,4,4.589558e-004,0,,0,
1613000761.165,,3.053435e+002,2.000755e+000,8.126830e-004,1.007236e-006,0.000000e+000,0.000000e+000,2,9.565474e-001,1.825000e+000,,,,,,,,,,,,,,,,,,0,3.000000e+000,1.000000e+000,4,4,8.320808e-004,0,,0,
1613000802.271,,4.059939e+002,1.999550e+000,1.085646e-003,1.728881e-006,0.000000e+000,0.000000e+000,2,9.563338e-001,1.825000e+000,,,,,,,,,,,,,,,,,,0,3.000000e+000,1.000000e+000,4,4,5.519390e-004,0,,0,
1613000843.580,,5.062965e+002,1.998889e+000,1.360097e-003,2.375770e-006,0.000000e+000,0.000000e+000,2,9.560704e-001,1.825000e+000,,,,,,,,,,,,,,,,,,0,3.000000e+000,1.000000e+000,4,4,1.519918e-004,0,,0,
1613000885.154,,6.065465e+002,1.998772e+000,1.636663e-003,3.257446e-006,0.000000e+000,0.000000e+000,2,9.562061e-001,1.825000e+000,,,,,,,,,,,,,,,,,,0,3.000000e+000,1.000000e+000,4,4,3.730059e-004,0,,0,
1613000926.728,,7.068594e+002,1.999067e+000,1.915382e-003,4.161298e-006,0.000000e+000,0.000000e+000,2,9.561970e-001,1.825000e+000,,,,,,,,,,,,,,,,,,0,3.000000e+000,1.000000e+000,4,4,6.070137e-004,0,,0,
1613000976.274,,8.062142e+002,1.999795e+000,2.195790e-003,3.567864e-006,0.000000e+000,0.000000e+000,2,9.560075e-001,1.825000e+000,,,,,,,,,,,,,,,,,,0,3.000000e+000,1.000000e+000,4,4,6.920099e-004,0,,0,
1613001017.848,,9.063905e+002,2.000394e+000,2.477387e-003,5.424645e-006,0.000000e+000,0.000000e+000,2,9.559014e-001,1.825000e+000,,,,,,,,,,,,,,,,,,0,3.000000e+000,1.000000e+000,4,4,6.370544e-004,0,,0,
1613001059.952,,1.006166e+003,2.000869e+000,2.761248e-003,4.747120e-006,0.000000e+000,0.000000e+000,2,9.561526e-001,1.825000e+000,,,,,,,,,,,,,,,,,,0,3.000000e+000,1.000000e+000,4,4,4.019737e-004,0,,0,
1613001155.300,,2.016589e+003,2.000716e+000,6.401074e-003,6.478449e-005,0.000000e+000,0.000000e+000,2,9.559608e-001,1.825000e+000,,,,,,,,,,,,,,,,,,0,3.000000e+000,1.000000e+000,4,4,8.296967e-005,0,,0,
1613001199.791,,3.017719e+003,2.000389e+000,1.567410e-002,6.956506e-004,0.000000e+000,0.000000e+000,2,9.563239e-001,1.825000e+000,,,,,,,,,,,,,,,,,,0,3.000000e+000,1.000000e+000,4,4,1.111031e-004,0,,0,
1613001256.419,,4.017374e+003,1.999939e+000,2.820444e-002,4.127521e-004,0.000000e+000,0.000000e+000,2,9.564540e-001,1.825000e+000,,,,,,,,,,,,,,,,,,0,3.000000e+000,1.000000e+000,4,4,1.928806e-004,0,,0,
1613001300.193,,5.018714e+003,1.999742e+000,3.767419e-002,8.551034e-004,0.000000e+000,0.000000e+000,2,9.561470e-001,1.825000e+000,,,,,,,,,,,,,,,,,,0,3.000000e+000,1.000000e+000,4,4,1.379251e-004,0,,0,
1613001344.684,,6.018791e+003,1.999699e+000,4.867796e-002,9.887433e-004,0.000000e+000,0.000000e+000,2,9.558045e-001,1.825000e+000,,,,,,,,,,,,,,,,,,0,3.000000e+000,1.000000e+000,4,4,3.039837e-004,0,,0,
1613001389.659,,7.022663e+003,1.999790e+000,5.847356e-002,7.823755e-004,0.000000e+000,0.000000e+000,2,9.553214e-001,1.825000e+000,,,,,,,,,,,,,,,,,,0,3.000000e+000,1.000000e+000,4,4,3.039837e-004,0,,0,
1613001434.634,,8.023370e+003,1.999941e+000,6.636181e-002,5.493551e-004,0.000000e+000,0.000000e+000,2,9.552959e-001,1.825000e+000,,,,,,,,,,,,,,,,,,0,3.000000e+000,1.000000e+000,4,4,3.600121e-004,0,,0,
1613001479.609,,9.025976e+003,2.000040e+000,7.290155e-002,3.938961e-004,0.000000e+000,0.000000e+000,2,9.551483e-001,1.825000e+000,,,,,,,,,,,,,,,,,,0,3.000000e+000,1.000000e+000,4,4,3.050566e-004,0,,0,
1613001523.304,,1.002710e+004,2.000067e+000,7.862814e-002,2.930439e-004,0.000000e+000,0.000000e+000,2,9.548527e-001,1.825000e+000,,,,,,,,,,,,,,,,,,0,3.000000e+000,1.000000e+000,4,4,2.359152e-004,0,,0,
1613001626.639,,1.504012e+004,1.999832e+000,1.073372e-001,6.562914e-005,0.000000e+000,0.000000e+000,2,9.545380e-001,1.825000e+000,,,,,,,,,,,,,,,,,,0,3.000000e+000,1.000000e+000,4,4,6.359816e-004,0,,0,
1613001686.122,,2.006000e+004,2.000027e+000,1.612605e-001,2.340186e-005,0.000000e+000,0.000000e+000,2,9.542777e-001,1.825000e+000,,,,,,,,,,,,,,,,,,0,3.000000e+000,1.000000e+000,4,4,6.089211e-004,0,,0,
1613001746.478,,2.507829e+004,2.000223e+000,2.052111e-001,1.328761e-005,0.000000e+000,0.000000e+000,2,9.538873e-001,1.825000e+000,,,,,,,,,,,,,,,,,,0,3.000000e+000,1.000000e+000,4,4,4.301071e-004,0,,0,
1613001806.398,,3.009501e+004,2.000230e+000,2.362800e-001,1.373238e-005,0.000000e+000,0.000000e+000,2,9.532871e-001,1.825000e+000,,,,,,,,,,,,,,,,,,0,3.000000e+000,1.000000e+000,4,4,4.019737e-004,0,,0,
1613001865.959,,3.511330e+004,2.000199e+000,2.601901e-001,2.451618e-005,0.000000e+000,0.000000e+000,2,9.531076e-001,1.825000e+000,,,,,,,,,,,,,,,,,,0,3.000000e+000,1.000000e+000,4,4,3.740788e-004,0,,0,
1613001926.237,,4.012738e+004,2.000129e+000,2.797546e-001,2.956627e-005,0.000000e+000,0.000000e+000,2,9.526538e-001,1.825000e+000,,,,,,,,,,,,,,,,,,0,3.000000e+000,1.000000e+000,4,4,3.460646e-004,0,,0,
1613001985.439,,4.514673e+004,2.000085e+000,2.965075e-001,2.279343e-005,0.000000e+000,0.000000e+000,2,9.522422e-001,1.825000e+000,,,,,,,,,,,,,,,,,,0,3.000000e+000,1.000000e+000,4,4,3.740788e-004,0,,0,
1613002045.047,,5.016607e+004,2.000136e+000,3.113644e-001,1.900949e-005,0.000000e+000,0.000000e+000,2,9.518130e-001,1.825000e+000,,,,,,,,,,,,,,,,,,0,3.000000e+000,1.000000e+000,4,4,4.850626e-004,0,,0,
1613002125.606,,5.012919e+004,2.000171e+000,3.114517e-001,1.824791e-005,0.000000e+000,0.000000e+000,2,9.516857e-001,1.825000e+000,,,,,,,,,,,,,,,,,,0,3.000000e+000,1.000000e+000,4,4,4.850626e-004,0,,0,
1613002186.087,,4.511512e+004,2.000233e+000,2.987844e-001,2.835805e-005,0.000000e+000,0.000000e+000,2,9.517798e-001,1.825000e+000,,,,,,,,,,,,,,,,,,0,3.000000e+000,1.000000e+000,4,4,3.600121e-004,0,,0,
1613002246.506,,4.009577e+004,2.000202e+000,2.839624e-001,2.546676e-005,0.000000e+000,0.000000e+000,2,9.522299e-001,1.825000e+000,,,,,,,,,,,,,,,,,,0,3.000000e+000,1.000000e+000,4,4,3.739595e-004,0,,0,
1613002306.753,,3.507959e+004,2.000057e+000,2.660332e-001,2.443239e-005,0.000000e+000,0.000000e+000,2,9.524814e-001,1.825000e+000,,,,,,,,,,,,,,,,,,0,3.000000e+000,1.000000e+000,4,4,4.979372e-004,0,,0,
1613002366.361,,3.006708e+004,2.000001e+000,2.431941e-001,2.520086e-005,0.000000e+000,0.000000e+000,2,9.526420e-001,1.825000e+000,,,,,,,,,,,,,,,,,,0,3.000000e+000,1.000000e+000,4,4,2.630949e-004,0,,0,
1613002425.454,,2.505196e+004,2.000003e+000,2.120757e-001,2.438603e-005,0.000000e+000,0.000000e+000,2,9.527405e-001,1.825000e+000,,,,,,,,,,,,,,,,,,0,3.000000e+000,1.000000e+000,4,4,5.540848e-004,0,,0,
1613002485.015,,2.003366e+004,2.000102e+000,1.661457e-001,2.742324e-005,0.000000e+000,0.000000e+000,2,9.531797e-001,1.825000e+000,,,,,,,,,,,,,,,,,,0,3.000000e+000,1.000000e+000,4,4,4.301071e-004,0,,0,
1613002544.435,,1.501958e+004,2.000154e+000,1.098618e-001,2.004314e-005,0.000000e+000,0.000000e+000,2,9.530199e-001,1.825000e+000,,,,,,,,,,,,,,,,,,0,3.000000e+000,1.000000e+000,4,4,4.558563e-004,0,,0,
1613002642.450,,1.002752e+004,1.999998e+000,8.592312e-002,3.891888e-005,0.000000e+000,0.000000e+000,2,9.532037e-001,1.825000e+000,,,,,,,,,,,,,,,,,,0,3.000000e+000,1.000000e+000,4,4,6.229877e-004,0,,0,
1613002687.519,,9.026181e+003,2.000237e+000,8.248762e-002,3.808347e-005,0.000000e+000,0.000000e+000,2,9.533607e-001,1.825000e+000,,,,,,,,,,,,,,,,,,0,3.000000e+000,1.000000e+000,4,4,3.190041e-004,0,,0,
1613002732.540,,8.022525e+003,2.000325e+000,7.920361e-002,3.213098e-005,0.000000e+000,0.000000e+000,2,9.535411e-001,1.825000e+000,,,,,,,,,,,,,,,,,,0,3.000000e+000,1.000000e+000,4,4,1.940727e-004,0,,0,
1613002776.766,,7.019919e+003,2.000295e+000,7.603345e-002,3.959920e-005,0.000000e+000,0.000000e+000,2,9.534532e-001,1.825000e+000,,,,,,,,,,,,,,,,,,0,3.000000e+000,1.000000e+000,4,4,1.518726e-004,0,,0,
1613002821.523,,6.015103e+003,2.000214e+000,7.289910e-002,3.802282e-005,0.000000e+000,0.000000e+000,2,9.534605e-001,1.825000e+000,,,,,,,,,,,,,,,,,,0,3.000000e+000,1.000000e+000,4,4,1.940727e-004,0,,0,
1613002865.437,,5.013552e+003,2.000115e+000,6.978278e-002,4.227191e-005,0.000000e+000,0.000000e+000,2,9.537836e-001,1.825000e+000,,,,,,,,,,,,,,,,,,0,3.000000e+000,1.000000e+000,4,4,1.800060e-004,0,,0,
1613002909.429,,4.010209e+003,2.000053e+000,6.658909e-002,5.925557e-005,0.000000e+000,0.000000e+000,2,9.538728e-001,1.825000e+000,,,,,,,,,,,,,,,,,,0,3.000000e+000,1.000000e+000,4,4,2.770424e-004,0,,0,
1613002954.669,,3.008552e+003,2.000010e+000,6.320485e-002,8.147366e-005,0.000000e+000,0.000000e+000,2,9.539010e-001,1.825000e+000,,,,,,,,,,,,,,,,,,0,3.000000e+000,1.000000e+000,4,4,2.489090e-004,0,,0,
1613002998.895,,2.004051e+003,2.000029e+000,5.926206e-002,1.469067e-004,0.000000e+000,0.000000e+000,2,9.538417e-001,1.825000e+000,,,,,,,,,,,,,,,,,,0,3.000000e+000,1.000000e+000,4,4,2.628565e-004,0,,0,
1613003082.090,,1.003490e+003,1.999911e+000,5.282779e-002,3.899673e-004,0.000000e+000,0.000000e+000,2,9.542657e-001,1.825000e+000,,,,,,,,,,,,,,,,,,0,3.000000e+000,1.000000e+000,4,4,4.009008e-004,0,,0,
1613003123.617,,9.031870e+002,2.000129e+000,5.128266e-002,2.599820e-004,0.000000e+000,0.000000e+000,2,9.544630e-001,1.825000e+000,,,,,,,,,,,,,,,,,,0,3.000000e+000,1.000000e+000,4,4,3.459454e-004,0,,0,
1613003173.725,,8.027794e+002,2.000311e+000,4.973336e-002,2.100029e-004,0.000000e+000,0.000000e+000,2,9.544749e-001,1.825000e+000,,,,,,,,,,,,,,,,,,0,3.000000e+000,1.000000e+000,4,4,3.051758e-004,0,,0,
1613003215.580,,7.025402e+002,2.000296e+000,4.845842e-002,2.450361e-004,0.000000e+000,0.000000e+000,2,9.543005e-001,1.825000e+000,,,,,,,,,,,,,,,,,,0,3.000000e+000,1.000000e+000,4,4,2.069473e-004,0,,0,
1613003256.623,,6.020581e+002,2.000252e+000,4.706904e-002,2.790273e-004,0.000000e+000,0.000000e+000,2,9.545308e-001,1.825000e+000,,,,,,,,,,,,,,,,,,0,3.000000e+000,1.000000e+000,4,4,1.788139e-004,0,,0,
1613003297.932,,5.019135e+002,2.000149e+000,4.553593e-002,3.201429e-004,0.000000e+000,0.000000e+000,2,9.546905e-001,1.825000e+000,,,,,,,,,,,,,,,,,,0,3.000000e+000,1.000000e+000,4,4,1.380444e-004,0,,0,
1613003338.976,,4.016109e+002,2.000093e+000,4.386434e-002,3.530094e-004,0.000000e+000,0.000000e+000,2,9.547656e-001,1.825000e+000,,,,,,,,,,,,,,,,,,0,3.000000e+000,1.000000e+000,4,4,2.210140e-004,0,,0,
1613003380.035,,3.014031e+002,2.000046e+000,4.204015e-002,3.909294e-004,0.000000e+000,0.000000e+000,2,9.545673e-001,1.825000e+000,,,,,,,,,,,,,,,,,,0,3.000000e+000,1.000000e+000,4,4,1.529455e-004,0,,0,
1613003421.344,,2.009530e+002,2.000036e+000,4.007811e-002,4.158222e-004,0.000000e+000,0.000000e+000,2,9.546211e-001,1.825000e+000,,,,,,,,,,,,,,,,,,0,3.000000e+000,1.000000e+000,4,4,3.321171e-004,0,,0,
1613003462.622,,1.007451e+002,2.000059e+000,3.803374e-002,4.334428e-004,0.000000e+000,0.000000e+000,2,9.546864e-001,1.825000e+000,,,,,,,,,,,,,,,,,,0,3.000000e+000,1.000000e+000,4,4,2.361536e-004,0,,0,
1613003503.665,,2.212558e-001,2.000039e+000,3.570542e-002,4.513563e-004,0.000000e+000,0.000000e+000,2,9.540698e-001,1.825000e+000,,,,,,,,,,,,,,,,,,0,3.000000e+000,1.000000e+000,4,4,1.530647e-004,0,,0,
1613003582.367,,2.317918e-001,1.999871e+000,3.360751e-002,1.936307e-004,0.000000e+000,0.000000e+000,2,9.541397e-001,1.825000e+000,,,,,,,,,,,,,,,,,,0,3.000000e+000,1.000000e+000,4,4,4.149675e-004,0,,0,
1613003630.306,,-1.007978e+002,2.000005e+000,3.192891e-002,2.748331e-004,0.000000e+000,0.000000e+000,2,9.536390e-001,1.825000e+000,,,,,,,,,,,,,,,,,,0,3.000000e+000,1.000000e+000,4,4,3.460646e-004,0,,0,
1613003672.582,,-2.010057e+002,2.000152e+000,3.035477e-002,3.365048e-004,0.000000e+000,0.000000e+000,2,9.533427e-001,1.825000e+000,,,,,,,,,,,,,,,,,,0,3.000000e+000,1.000000e+000,4,4,3.049374e-004,0,,0,
1613003713.751,,-3.018983e+002,2.000261e+000,2.861546e-002,3.862102e-004,0.000000e+000,0.000000e+000,2,9.534520e-001,1.825000e+000,,,,,,,,,,,,,,,,,,0,3.000000e+000,1.000000e+000,4,4,2.629757e-004,0,,0,
1613003754.732,,-4.026223e+002,2.000269e+000,2.675556e-002,3.975139e-004,0.000000e+000,0.000000e+000,2,9.534611e-001,1.825000e+000,,,,,,,,,,,,,,,,,,0,3.000000e+000,1.000000e+000,4,4,1.239777e-004,0,,0,
1613003804.356,,-5.033676e+002,2.000261e+000,2.454300e-002,3.681686e-004,0.000000e+000,0.000000e+000,2,9.532466e-001,1.825000e+000,,,,,,,,,,,,,,,,,,0,3.000000e+000,1.000000e+000,4,4,6.890297e-005,0,,0,
1613003845.134,,-6.038704e+002,2.000154e+000,2.276686e-002,3.758480e-004,0.000000e+000,0.000000e+000,2,9.528209e-001,1.825000e+000,,,,,,,,,,,,,,,,,,0,3.000000e+000,1.000000e+000,4,4,1.800060e-004,0,,0,
1613003886.131,,-7.046050e+002,2.000091e+000,2.097968e-002,3.672437e-004,0.000000e+000,0.000000e+000,2,9.527392e-001,1.825000e+000,,,,,,,,,,,,,,,,,,0,3.000000e+000,1.000000e+000,4,4,1.111031e-004,0,,0,
1613003927.674,,-8.049285e+002,1.999989e+000,1.921222e-002,3.641778e-004,0.000000e+000,0.000000e+000,2,9.526539e-001,1.825000e+000,,,,,,,,,,,,,,,,,,0,3.000000e+000,1.000000e+000,4,4,2.629757e-004,0,,0,
1613003967.985,,-9.054417e+002,2.000012e+000,1.746495e-002,3.889286e-004,0.000000e+000,0.000000e+000,2,9.523160e-001,1.825000e+000,,,,,,,,,,,,,,,,,,0,3.000000e+000,1.000000e+000,4,4,2.210140e-004,0,,0,
1613004009.169,,-1.005787e+003,1.999964e+000,1.561511e-002,3.956041e-004,0.000000e+000,0.000000e+000,2,9.519743e-001,1.825000e+000,,,,,,,,,,,,,,,,,,0,3.000000e+000,1.000000e+000,4,4,1.519918e-004,0,,0,
1613004161.144,,-5.036941e+003,2.000175e+000,-4.405976e-002,7.404240e-004,0.000000e+000,0.000000e+000,2,9.550709e-001,1.825000e+000,,,,,,,,,,,,,,,,,,0,3.000000e+000,1.000000e+000,4,4,4.010201e-004,0,,0,
1613004190.254,,-6.028483e+003,2.000170e+000,-5.292082e-002,0.000000e+000,0.000000e+000,0.000000e+000,2,9.546764e-001,1.825000e+000,,,,,,,,,,,,,,,,,,0,3.000000e+000,1.000000e+000,4,1,8.296967e-005,1,,0,
1613004234.277,,-7.030034e+003,2.000326e+000,-6.242119e-002,6.378415e-004,0.000000e+000,0.000000e+000,2,9.545045e-001,1.825000e+000,,,,,,,,,,,,,,,,,,0,3.000000e+000,1.000000e+000,4,3,2.079010e-004,1,,0,
1613004278.488,,-8.027164e+003,2.000332e+000,-6.957877e-002,4.674305e-004,0.000000e+000,0.000000e+000,2,9.541186e-001,1.825000e+000,,,,,,,,,,,,,,,,,,0,3.000000e+000,1.000000e+000,4,4,1.111031e-004,0,,0,
1613004305.710,,-9.028079e+003,2.000184e+000,-7.503080e-002,0.000000e+000,0.000000e+000,0.000000e+000,2,9.538182e-001,1.825000e+000,,,,,,,,,,,,,,,,,,0,3.000000e+000,1.000000e+000,4,1,8.296967e-005,1,,0,
1613004350.185,,-1.002816e+004,2.000131e+000,-8.060718e-002,2.417812e-004,0.000000e+000,0.000000e+000,2,9.539106e-001,1.825000e+000,,,,,,,,,,,,,,,,,,0,3.000000e+000,1.000000e+000,4,4,2.350807e-004,0,,0,
1613004448.247,,-1.504224e+004,1.999737e+000,-1.084659e-001,5.012473e-005,0.000000e+000,0.000000e+000,2,9.536614e-001,1.825000e+000,,,,,,,,,,,,,,,,,,0,3.000000e+000,1.000000e+000,4,4,5.389452e-004,0,,0,
1613004508.136,,-2.005632e+004,2.000018e+000,-1.647011e-001,1.952284e-005,0.000000e+000,0.000000e+000,2,9.533017e-001,1.825000e+000,,,,,,,,,,,,,,,,,,0,3.000000e+000,1.000000e+000,4,4,5.118847e-004,0,,0,
1613004567.166,,-2.507197e+004,2.000231e+000,-2.097441e-001,1.431031e-005,0.000000e+000,0.000000e+000,2,9.529873e-001,1.825000e+000,,,,,,,,,,,,,,,,,,0,3.000000e+000,1.000000e+000,4,4,4.429817e-004,0,,0,
1613004627.039,,-3.008974e+004,2.000317e+000,-2.405836e-001,1.969138e-005,0.000000e+000,0.000000e+000,2,9.524521e-001,1.825000e+000,,,,,,,,,,,,,,,,,,0,3.000000e+000,1.000000e+000,4,4,3.728867e-004,0,,0,
1613004679.361,,-3.510382e+004,2.000148e+000,-2.636368e-001,3.757392e-005,0.000000e+000,0.000000e+000,2,9.520605e-001,1.825000e+000,,,,,,,,,,,,,,,,,,0,3.000000e+000,1.000000e+000,4,2,2.770424e-004,1,,0,
1613004738.907,,-4.012421e+004,2.000100e+000,-2.822080e-001,3.153616e-005,0.000000e+000,0.000000e+000,2,9.514934e-001,1.825000e+000,,,,,,,,,,,,,,,,,,0,3.000000e+000,1.000000e+000,4,4,2.629757e-004,0,,0,
1613004797.719,,-4.514673e+004,2.000071e+000,-2.978175e-001,2.746633e-005,0.000000e+000,0.000000e+000,2,9.512339e-001,1.825000e+000,,,,,,,,,,,,,,,,,,0,3.000000e+000,1.000000e+000,4,4,2.629757e-004,0,,0,
1613004857.592,,-5.016607e+004,2.000064e+000,-3.113734e-001,1.851539e-005,0.000000e+000,0.000000e+000,2,9.509341e-001,1.825000e+000,,,,,,,,,,,,,,,,,,0,3.000000e+000,1.000000e+000,4,4,2.900362e-004,0,,0,
1613004938.166,,-5.012814e+004,1.999958e+000,-3.114054e-001,1.835774e-005,0.000000e+000,0.000000e+000,2,9.508664e-001,1.825000e+000,,,,,,,,,,,,,,,,,,0,3.000000e+000,1.000000e+000,4,4,3.600121e-004,0,,0,
1613004998.569,,-4.511406e+004,2.000031e+000,-2.987445e-001,1.094504e-005,0.000000e+000,0.000000e+000,2,9.511863e-001,1.825000e+000,,,,,,,,,,,,,,,,,,0,3.000000e+000,1.000000e+000,4,4,4.429817e-004,0,,0,
1613005058.988,,-4.009577e+004,2.000138e+000,-2.839296e-001,1.765058e-005,0.000000e+000,0.000000e+000,2,9.514829e-001,1.825000e+000,,,,,,,,,,,,,,,,,,0,3.000000e+000,1.000000e+000,4,4,3.870726e-004,0,,0,
1613005119.142,,-3.507853e+004,2.000214e+000,-2.659969e-001,2.215751e-005,0.000000e+000,0.000000e+000,2,9.515590e-001,1.825000e+000,,,,,,,,,,,,,,,,,,0,3.000000e+000,1.000000e+000,4,4,3.190041e-004,0,,0,
1613005178.749,,-3.006656e+004,2.000219e+000,-2.431642e-001,2.456866e-005,0.000000e+000,0.000000e+000,2,9.516283e-001,1.825000e+000,,,,,,,,,,,,,,,,,,0,3.000000e+000,1.000000e+000,4,4,4.019737e-004,0,,0,
1613005238.310,,-2.505195e+004,2.000159e+000,-2.120910e-001,2.638492e-005,0.000000e+000,0.000000e+000,2,9.521185e-001,1.825000e+000,,,,,,,,,,,,,,,,,,0,3.000000e+000,1.000000e+000,4,4,3.870726e-004,0,,0,
1613005297.606,,-2.003313e+004,2.000143e+000,-1.661860e-001,1.362378e-005,0.000000e+000,0.000000e+000,2,9.524931e-001,1.825000e+000,,,,,,,,,,,,,,,,,,0,3.000000e+000,1.000000e+000,4,4,3.459454e-004,0,,0,
1613005357.214,,-1.501906e+004,2.000012e+000,-1.099081e-001,2.497341e-005,0.000000e+000,0.000000e+000,2,9.524967e-001,1.825000e+000,,,,,,,,,,,,,,,,,,0,3.000000e+000,1.000000e+000,4,4,2.909899e-004,0,,0,
1613005456.336,,-1.002689e+004,1.999934e+000,-8.595960e-002,3.759855e-005,0.000000e+000,0.000000e+000,2,9.526241e-001,1.825000e+000,,,,,,,,,,,,,,,,,,0,3.000000e+000,1.000000e+000,4,4,5.389452e-004,0,,0,
1613005500.297,,-9.025548e+003,2.000207e+000,-8.251473e-002,3.351731e-005,0.000000e+000,0.000000e+000,2,9.525812e-001,1.825000e+000,,,,,,,,,,,,,,,,,,0,3.000000e+000,1.000000e+000,4,4,3.321171e-004,0,,0,
1613005545.803,,-8.021893e+003,2.000380e+000,-7.923233e-002,2.457934e-005,0.000000e+000,0.000000e+000,2,9.528113e-001,1.825000e+000,,,,,,,,,,,,,,,,,,0,3.000000e+000,1.000000e+000,4,4,1.940727e-004,0,,0,
1613005590.824,,-7.019500e+003,2.000403e+000,-7.606784e-002,4.139809e-005,0.000000e+000,0.000000e+000,2,9.531307e-001,1.825000e+000,,,,,,,,,,,,,,,,,,0,3.000000e+000,1.000000e+000,4,4,2.629757e-004,0,,0,
1613005635.815,,-6.014681e+003,2.000332e+000,-7.293185e-002,3.736372e-005,0.000000e+000,0.000000e+000,2,9.530791e-001,1.825000e+000,,,,,,,,,,,,,,,,,,0,3.000000e+000,1.000000e+000,4,4,2.219677e-004,0,,0,
1613005679.729,,-5.013025e+003,2.000223e+000,-6.981907e-002,4.886687e-005,0.000000e+000,0.000000e+000,2,9.530810e-001,1.825000e+000,,,,,,,,,,,,,,,,,,0,3.000000e+000,1.000000e+000,4,4,2.629757e-004,0,,0,
1613005724.220,,-4.010209e+003,2.000083e+000,-6.662476e-002,6.171908e-005,0.000000e+000,0.000000e+000,2,9.531705e-001,1.825000e+000,,,,,,,,,,,,,,,,,,0,3.000000e+000,1.000000e+000,4,4,9.703636e-005,0,,0,
1613005769.569,,-3.008131e+003,2.000009e+000,-6.324602e-002,8.442286e-005,0.000000e+000,0.000000e+000,2,9.534303e-001,1.825000e+000,,,,,,,,,,,,,,,,,,0,3.000000e+000,1.000000e+000,4,4,1.530647e-004,0,,0,
1613005814.544,,-2.003629e+003,1.999931e+000,-5.930132e-002,1.497308e-004,0.000000e+000,0.000000e+000,2,9.535406e-001,1.825000e+000,,,,,,,,,,,,,,,,,,0,3.000000e+000,1.000000e+000,4,4,2.759695e-004,0,,0,
1613005898.238,,-1.003490e+003,1.999683e+000,-5.288329e-002,3.930351e-004,0.000000e+000,0.000000e+000,2,9.537457e-001,1.825000e+000,,,,,,,,,,,,,,,,,,0,3.000000e+000,1.000000e+000,4,4,2.909899e-004,0,,0,
1613005939.532,,-9.032084e+002,1.999851e+000,-5.132792e-002,2.550152e-004,0.000000e+000,0.000000e+000,2,9.537957e-001,1.825000e+000,,,,,,,,,,,,,,,,,,0,3.000000e+000,1.000000e+000,4,4,3.600121e-004,0,,0,
1613005988.563,,-8.028422e+002,2.000135e+000,-4.980049e-002,2.051020e-004,0.000000e+000,0.000000e+000,2,9.539754e-001,1.825000e+000,,,,,,,,,,,,,,,,,,0,3.000000e+000,1.000000e+000,4,4,2.491474e-004,0,,0,
1613006029.825,,-7.026030e+002,2.000327e+000,-4.853293e-002,2.472520e-004,0.000000e+000,0.000000e+000,2,9.539515e-001,1.825000e+000,,,,,,,,,,,,,,,,,,0,3.000000e+000,1.000000e+000,4,4,2.899170e-004,0,,0,
1613006070.603,,-6.021213e+002,2.000330e+000,-4.713605e-002,2.843301e-004,0.000000e+000,0.000000e+000,2,9.538894e-001,1.825000e+000,,,,,,,,,,,,,,,,,,0,3.000000e+000,1.000000e+000,4,4,1.251698e-004,0,,0,
1613006111.631,,-5.019873e+002,2.000304e+000,-4.559493e-002,3.247933e-004,0.000000e+000,0.000000e+000,2,9.539948e-001,1.825000e+000,,,,,,,,,,,,,,,,,,0,3.000000e+000,1.000000e+000,4,4,1.800060e-004,0,,0,
1613006152.675,,-4.016741e+002,2.000293e+000,-4.391854e-002,3.540273e-004,0.000000e+000,0.000000e+000,2,9.541389e-001,1.825000e+000,,,,,,,,,,,,,,,,,,0,3.000000e+000,1.000000e+000,4,4,1.518726e-004,0,,0,
1613006193.453,,-3.014452e+002,2.000161e+000,-4.212062e-002,4.016281e-004,0.000000e+000,0.000000e+000,2,9.541143e-001,1.825000e+000,,,,,,,,,,,,,,,,,,0,3.000000e+000,1.000000e+000,4,4,1.940727e-004,0,,0,
1613006236.041,,-2.010267e+002,2.000017e+000,-4.011239e-002,4.182133e-004,0.000000e+000,0.000000e+000,2,9.541122e-001,1.825000e+000,,,,,,,,,,,,,,,,,,0,3.000000e+000,1.000000e+000,4,4,1.380444e-004,0,,0,
1613006277.615,,-1.008084e+002,1.999984e+000,-3.806634e-002,4.401822e-004,0.000000e+000,0.000000e+000,2,9.539453e-001,1.825000e+000,,,,,,,,,,,,,,,,,,0,3.000000e+000,1.000000e+000,4,4,2.069473e-004,0,,0,
1613006318.924,,-2.950077e-001,1.999949e+000,-3.590021e-002,4.450879e-004,0.000000e+000,0.000000e+000,2,9.539593e-001,1.825000e+000,,,,,,,,,,,,,,,,,,0,3.000000e+000,1.000000e+000,4,4,1.518726e-004,0,,0,
1613006397.923,,-2.844717e-001,1.999783e+000,-3.379910e-002,1.933882e-004,0.000000e+000,0.000000e+000,2,9.540565e-001,1.825000e+000,,,,,,,,,,,,,,,,,,0,3.000000e+000,1.000000e+000,4,4,4.559755e-004,0,,0,
1613006445.066,,1.008084e+002,2.000074e+000,-3.232437e-002,2.760894e-004,0.000000e+000,0.000000e+000,2,9.538929e-001,1.825000e+000,,,,,,,,,,,,,,,,,,0,3.000000e+000,1.000000e+000,4,4,2.361536e-004,0,,0,
1613006486.687,,2.021436e+002,2.000240e+000,-3.073990e-002,3.396841e-004,0.000000e+000,0.000000e+000,2,9.536296e-001,1.825000e+000,,,,,,,,,,,,,,,,,,0,3.000000e+000,1.000000e+000,4,4,2.360344e-004,0,,0,
1613006528.027,,3.050380e+002,2.000360e+000,-2.895387e-002,3.897541e-004,0.000000e+000,0.000000e+000,2,9.534541e-001,1.825000e+000,,,,,,,,,,,,,,,,,,0,3.000000e+000,1.000000e+000,4,4,2.770424e-004,0,,0,
1613006569.554,,4.072161e+002,2.000340e+000,-2.701965e-002,4.112490e-004,0.000000e+000,0.000000e+000,2,9.534988e-001,1.825000e+000,,,,,,,,,,,,,,,,,,0,3.000000e+000,1.000000e+000,4,4,8.320808e-005,0,,0,
1613006620.114,,5.075292e+002,2.000320e+000,-2.484727e-002,5.260548e-004,0.000000e+000,0.000000e+000,2,9.534969e-001,1.825000e+000,,,,,,,,,,,,,,,,,,0,3.000000e+000,1.000000e+000,4,4,1.389980e-004,0,,0,
1613006661.470,,6.077581e+002,2.000183e+000,-2.296792e-002,3.708805e-004,0.000000e+000,0.000000e+000,2,9.531483e-001,1.825000e+000,,,,,,,,,,,,,,,,,,0,3.000000e+000,1.000000e+000,4,4,4.196167e-005,0,,0,
1613006702.498,,7.091984e+002,2.000102e+000,-2.119971e-002,3.655866e-004,0.000000e+000,0.000000e+000,2,9.528930e-001,1.825000e+000,,,,,,,,,,,,,,,,,,0,3.000000e+000,1.000000e+000,4,4,1.671314e-004,0,,0,
1613006743.541,,8.085739e+002,2.000058e+000,-1.945386e-002,3.695112e-004,0.000000e+000,0.000000e+000,2,9.526492e-001,1.825000e+000,,,,,,,,,,,,,,,,,,0,3.000000e+000,1.000000e+000,4,4,1.670122e-004,0,,0,
1613006785.022,,9.086660e+002,2.000013e+000,-1.768049e-002,3.712425e-004,0.000000e+000,0.000000e+000,2,9.527451e-001,1.825000e+000,,,,,,,,,,,,,,,,,,0,3.000000e+000,1.000000e+000,4,4,1.789331e-004,0,,0,
1613006826.736,,1.007662e+003,1.999972e+000,-1.584664e-002,3.946830e-004,0.000000e+000,0.000000e+000,2,9.524111e-001,1.825000e+000,,,,,,,,,,,,,,,,,,0,3.000000e+000,1.000000e+000,4,4,1.800060e-004,0,,0,
1613006928.667,,2.019539e+003,1.999917e+000,-2.927358e-004,1.274577e-003,0.000000e+000,0.000000e+000,2,9.465832e-001,1.825000e+000,,,,,,,,,,,,,,,,,,0,3.000000e+000,1.000000e+000,4,4,4.709959e-004,0,,0,
1613006984.531,,3.020774e+003,2.000234e+000,1.753158e-002,9.013216e-004,0.000000e+000,0.000000e+000,2,9.564716e-001,1.825000e+000,,,,,,,,,,,,,,,,,,0,3.000000e+000,1.000000e+000,4,4,2.489090e-004,0,,0,
1613007028.445,,4.020745e+003,2.000308e+000,3.156145e-002,1.094142e-003,0.000000e+000,0.000000e+000,2,9.555982e-001,1.825000e+000,,,,,,,,,,,,,,,,,,0,3.000000e+000,1.000000e+000,4,4,2.770424e-004,0,,0,
1613007080.393,,5.021875e+003,2.000382e+000,4.387810e-002,7.074105e-004,0.000000e+000,0.000000e+000,2,9.550722e-001,1.825000e+000,,,,,,,,,,,,,,,,,,0,3.000000e+000,1.000000e+000,4,4,1.380444e-004,0,,0,
1613007119.190,,6.034488e+003,2.000211e+000,4.033767e-002,1.970350e-002,0.000000e+000,0.000000e+000,2,4.773186e-001,1.825000e+000,,,,,,,,,,,,,,,,,,0,3.000000e+000,1.000000e+000,4,2,2.813339e-005,1,,0,
1613007162.870,,7.024769e+003,2.000157e+000,6.257337e-002,6.553445e-004,0.000000e+000,0.000000e+000,2,9.543160e-001,1.825000e+000,,,,,,,,,,,,,,,,,,0,3.000000e+000,1.000000e+000,4,4,9.703636e-005,0,,0,
1613007206.831,,8.025054e+003,2.000040e+000,6.952151e-002,4.573761e-004,0.000000e+000,0.000000e+000,2,9.542556e-001,1.825000e+000,,,,,,,,,,,,,,,,,,0,3.000000e+000,1.000000e+000,4,4,2.349615e-004,0,,0,
1613007251.276,,9.027446e+003,2.000000e+000,7.538321e-002,3.236950e-004,0.000000e+000,0.000000e+000,2,9.541065e-001,1.825000e+000,,,,,,,,,,,,,,,,,,0,3.000000e+000,1.000000e+000,4,4,2.630949e-004,0,,0,
1613007295.564,,1.002837e+004,1.999994e+000,8.062239e-002,2.327764e-004,0.000000e+000,0.000000e+000,2,9.539693e-001,1.825000e+000,,,,,,,,,,,,,,,,,,0,3.000000e+000,1.000000e+000,4,4,2.349615e-004,0,,0,
1613007393.423,,1.503697e+004,1.999830e+000,1.084406e-001,4.799429e-005,0.000000e+000,0.000000e+000,2,9.536176e-001,1.825000e+000,,,,,,,,,,,,,,,,,,0,3.000000e+000,1.000000e+000,4,4,3.598928e-004,0,,0,
1613007452.765,,2.005789e+004,2.000006e+000,1.648771e-001,5.648720e-006,0.000000e+000,0.000000e+000,2,9.533442e-001,1.825000e+000,,,,,,,,,,,,,,,,,,0,3.000000e+000,1.000000e+000,4,4,4.150867e-004,0,,0,
1613007543.729,,3.009448e+004,2.000187e+000,2.408624e-001,1.430215e-005,0.000000e+000,0.000000e+000,2,9.526151e-001,1.825000e+000,,,,,,,,,,,,,,,,,,0,3.000000e+000,1.000000e+000,4,4,4.429817e-004,0,,0,
1613007603.337,,3.511224e+004,2.000327e+000,2.638860e-001,1.880411e-005,0.000000e+000,0.000000e+000,2,9.521527e-001,1.825000e+000,,,,,,,,,,,,,,,,,,0,3.000000e+000,1.000000e+000,4,4,2.348423e-004,0,,0,
1613007663.163,,4.012632e+004,2.000323e+000,2.824306e-001,7.930536e-006,0.000000e+000,0.000000e+000,2,9.517177e-001,1.825000e+000,,,,,,,,,,,,,,,,,,0,3.000000e+000,1.000000e+000,4,4,2.758503e-004,0,,0,
1613007723.239,,4.514672e+004,2.000152e+000,2.979846e-001,1.165705e-005,0.000000e+000,0.000000e+000,2,9.510002e-001,1.825000e+000,,,,,,,,,,,,,,,,,,0,3.000000e+000,1.000000e+000,4,4,1.659393e-004,0,,0,
1613007782.176,,5.016607e+004,2.000076e+000,3.114499e-001,1.450308e-005,0.000000e+000,0.000000e+000,2,9.506981e-001,1.825000e+000,,,,,,,,,,,,,,,,,,0,3.000000e+000,1.000000e+000,4,4,2.210140e-004,0,,0,