File: MPMS/FeCl2pym/FeCl2pym_2-300K_ZFC.rso.dat
[Header]
TITLE,MPMS RSO Measurement
BYAPP,MPMS Measurement,1.1,Summary
FILEOPENTIME, 1612956253.086000 2/10/2021, 11:24:13 AM

INFO, APPNAME, MPMS MultiVu Application, Revision 1.61,  Build 082

INFO, NAME, Fecl2pym_muciwe2
INFO, WEIGHT, 4.500
INFO, AREA, 1.000
INFO, LENGTH, 1.000
INFO, SHAPE, 0
INFO, COMMENT, eicosane 5.9
INFO, SEQUENCE FILE: JP_ZFC_FC_MH_210210.seq


INFO, BACKGROUND DATA FILE:, None


STARTUPAXIS,X,4,LINEAR,AUTO,0.000000,0.000000
STARTUPAXIS,Y1,5,LINEAR,AUTO,0.000000,0.000000


STARTUPGROUP,Longitudinal
FIELDGROUP,Longitudinal,1,2,3,4,5,6,7,8,9,10,11,19,20,21,22,23,35
FIELDGROUP,Transverse,1,2,3,4,12,13,14,15,16,17,18,24,25,26,27,28,35

PLOT_APPEARANCE,ALL,HORZ_GRID_ON,VERT_GRID_ON,MARKERS_AND_LINES

[Data]
Time,Comment,Field (Oe),Temperature (K),Long Moment (emu),Long Scan Std Dev,Long Offset (cm),Long Offset Std Dev,Long Algorithm,Long Reg Fit,Long Reg Factor,Trans Moment (emu),Trans Scan Std Dev,Trans Offset (cm),Trans Offset Std Dev,Trans Algorithm,Trans Reg Fit,Trans Reg Factor,Long Moment [w/o ABS] (emu),Long Scan Std Dev [w/o ABS],Long Offset [w/o ABS] (cm),Long Offset Std Dev [w/o ABS],Long Reg Fit [w/o ABS],Trans Moment [w/o ABS] (emu),Trans Scan Std Dev [w/o ABS],Trans Offset [w/o ABS] (cm),Trans Offset Std Dev [w/o ABS],Trans Reg Fit [w/o ABS],RSO Position (deg),Amplitude (cm),Frequency,Cycles to Average,Scans per Measurement,Delta Temp (K),Error,EC Comp. Running,Using ABS,
1612956253.086,,1.000000e+002,2.006449e+000,2.614592e-004,2.706673e-008,4.619946e-002,4.044242e-005,3,9.873105e-001,1.825000e+000,,,,,,,,,,,,,,,,,,0,5.000000e+000,1.000000e+000,4,4,3.018141e-003,0,,0,
1612956403.454,,1.000000e+002,2.262870e+000,2.621457e-004,1.376376e-007,4.638711e-002,1.872593e-005,3,9.873966e-001,1.825000e+000,,,,,,,,,,,,,,,,,,0,5.000000e+000,1.000000e+000,4,4,1.337695e-002,0,,0,
1612956585.351,,1.000000e+002,2.508122e+000,2.638908e-004,5.918397e-008,4.643485e-002,5.577569e-005,3,9.874153e-001,1.825000e+000,,,,,,,,,,,,,,,,,,0,5.000000e+000,1.000000e+000,4,4,1.133895e-002,0,,0,
1612956779.508,,1.000000e+002,2.755697e+000,2.653954e-004,4.402661e-008,4.650305e-002,3.745827e-005,3,9.875059e-001,1.825000e+000,,,,,,,,,,,,,,,,,,0,5.000000e+000,1.000000e+000,4,4,8.323193e-003,0,,0,
1612957001.466,,1.000000e+002,3.003023e+000,2.671859e-004,6.497683e-008,4.656419e-002,5.200971e-005,3,9.875109e-001,1.825000e+000,,,,,,,,,,,,,,,,,,0,5.000000e+000,1.000000e+000,4,4,6.208181e-003,0,,0,
1612957265.949,,1.000000e+002,3.252877e+000,2.695944e-004,6.092910e-008,4.657699e-002,3.246752e-005,3,9.875168e-001,1.825000e+000,,,,,,,,,,,,,,,,,,0,5.000000e+000,1.000000e+000,4,4,6.632090e-003,0,,0,
1612957463.772,,1.000000e+002,3.538342e+000,2.719869e-004,2.049382e-007,4.666138e-002,1.328718e-005,3,9.875684e-001,1.825000e+000,,,,,,,,,,,,,,,,,,0,5.000000e+000,1.000000e+000,4,4,3.683400e-002,0,,0,
1612957662.985,,1.000000e+002,3.764894e+000,2.756506e-004,1.560562e-007,4.673864e-002,3.618023e-005,3,9.875478e-001,1.825000e+000,,,,,,,,,,,,,,,,,,0,5.000000e+000,1.000000e+000,4,4,1.581407e-002,0,,0,
1612957900.074,,1.000000e+002,3.949809e+000,2.794894e-004,2.332780e-006,4.676390e-002,2.431080e-005,3,9.875655e-001,1.825000e+000,,,,,,,,,,,,,,,,,,0,5.000000e+000,1.000000e+000,4,4,2.446620e-001,0,,0,
1612958267.111,,1.000000e+002,4.257853e+000,2.871433e-004,1.453061e-007,4.676114e-002,2.038444e-005,3,9.875114e-001,1.825000e+000,,,,,,,,,,,,,,,,,,0,5.000000e+000,1.000000e+000,4,4,1.486397e-002,0,,0,
1612958430.428,,1.000000e+002,4.507059e+000,2.929776e-004,2.817931e-007,4.681551e-002,1.728028e-005,3,9.875278e-001,1.825000e+000,,,,,,,,,,,,,,,,,,0,5.000000e+000,1.000000e+000,4,4,9.130955e-003,0,,0,
1612958583.137,,1.000000e+002,4.755788e+000,3.006403e-004,3.504659e-007,4.688118e-002,4.626747e-005,3,9.874479e-001,1.825000e+000,,,,,,,,,,,,,,,,,,0,5.000000e+000,1.000000e+000,4,4,6.732941e-003,0,,0,
1612958737.749,,1.000000e+002,5.004407e+000,3.096793e-004,3.399959e-007,4.693938e-002,3.280235e-005,3,9.873657e-001,1.825000e+000,,,,,,,,,,,,,,,,,,0,5.000000e+000,1.000000e+000,4,4,6.673813e-003,0,,0,
1612958890.239,,1.000000e+002,5.253015e+000,3.199527e-004,4.311005e-007,4.704339e-002,2.376713e-005,3,9.873773e-001,1.825000e+000,,,,,,,,,,,,,,,,,,0,5.000000e+000,1.000000e+000,4,4,1.595402e-002,0,,0,
1612959042.792,,1.000000e+002,5.507681e+000,3.310349e-004,4.279293e-007,4.710935e-002,3.219177e-005,3,9.873106e-001,1.825000e+000,,,,,,,,,,,,,,,,,,0,5.000000e+000,1.000000e+000,4,4,1.549578e-002,0,,0,
1612959196.343,,1.000000e+002,5.755011e+000,3.425669e-004,2.783156e-007,4.707841e-002,2.358710e-005,3,9.872610e-001,1.825000e+000,,,,,,,,,,,,,,,,,,0,5.000000e+000,1.000000e+000,4,4,7.263184e-003,0,,0,
1612959350.424,,1.000000e+002,6.005045e+000,3.547438e-004,3.092682e-007,4.701540e-002,1.834637e-005,3,9.872229e-001,1.825000e+000,,,,,,,,,,,,,,,,,,0,5.000000e+000,1.000000e+000,4,4,1.048565e-002,0,,0,
1612959461.496,,1.000000e+002,6.504992e+000,3.824016e-004,3.597320e-007,4.684477e-002,2.413807e-005,3,9.871088e-001,1.825000e+000,,,,,,,,,,,,,,,,,,0,5.000000e+000,1.000000e+000,4,4,9.471893e-003,0,,0,
1612959615.328,,1.000000e+002,7.004320e+000,4.217790e-004,4.871172e-007,4.695622e-002,4.020932e-005,3,9.869612e-001,1.825000e+000,,,,,,,,,,,,,,,,,,0,5.000000e+000,1.000000e+000,4,4,9.513855e-003,0,,0,
1612959771.531,,1.000000e+002,7.505260e+000,4.761374e-004,6.053386e-007,4.707416e-002,8.363737e-005,3,9.869356e-001,1.825000e+000,,,,,,,,,,,,,,,,,,0,5.000000e+000,1.000000e+000,4,4,1.311398e-002,0,,0,
1612959926.096,,1.000000e+002,8.004839e+000,5.549254e-004,8.511991e-007,4.715243e-002,4.445929e-005,3,9.868116e-001,1.825000e+000,,,,,,,,,,,,,,,,,,0,5.000000e+000,1.000000e+000,4,4,1.214695e-002,0,,0,
1612960082.034,,1.000000e+002,8.505563e+000,6.769306e-004,1.373091e-006,4.729019e-002,7.445836e-005,3,9.866736e-001,1.825000e+000,,,,,,,,,,,,,,,,,,0,5.000000e+000,1.000000e+000,4,4,8.139610e-003,0,,0,
1612960237.177,,1.000000e+002,9.004414e+000,8.611678e-004,1.709868e-006,4.741812e-002,5.956874e-005,3,9.865080e-001,1.825000e+000,,,,,,,,,,,,,,,,,,0,5.000000e+000,1.000000e+000,4,4,1.217270e-002,0,,0,
1612960405.672,,1.000000e+002,9.504031e+000,1.106472e-003,1.749789e-007,4.749849e-002,3.032719e-005,3,9.863383e-001,1.825000e+000,,,,,,,,,,,,,,,,,,0,5.000000e+000,1.000000e+000,4,4,4.716873e-003,0,,0,
1612960561.345,,1.000000e+002,1.000499e+001,1.295946e-003,1.008638e-006,4.759041e-002,2.708548e-005,3,9.862789e-001,1.825000e+000,,,,,,,,,,,,,,,,,,0,5.000000e+000,1.000000e+000,4,4,9.486198e-003,0,,0,
1612960717.548,,1.000000e+002,1.051201e+001,1.313076e-003,6.933056e-007,4.770508e-002,2.439553e-005,3,9.863256e-001,1.825000e+000,,,,,,,,,,,,,,,,,,0,5.000000e+000,1.000000e+000,4,4,9.789467e-003,0,,0,
1612960872.956,,1.000000e+002,1.101904e+001,1.136190e-003,1.055262e-006,4.778605e-002,1.953504e-005,3,9.864430e-001,1.825000e+000,,,,,,,,,,,,,,,,,,0,5.000000e+000,1.000000e+000,4,4,9.320259e-003,0,,0,
1612961028.129,,1.000000e+002,1.152504e+001,9.841421e-004,9.820573e-007,4.786674e-002,3.199912e-005,3,9.865592e-001,1.825000e+000,,,,,,,,,,,,,,,,,,0,5.000000e+000,1.000000e+000,4,4,9.909630e-003,0,,0,
1612961189.137,,1.000000e+002,1.200535e+001,8.836836e-004,1.362692e-007,4.788276e-002,5.500955e-005,3,9.866669e-001,1.825000e+000,,,,,,,,,,,,,,,,,,0,5.000000e+000,1.000000e+000,4,4,6.449699e-003,0,,0,
1612961345.028,,1.000000e+002,1.251081e+001,8.094775e-004,4.732202e-007,4.791842e-002,3.514258e-005,3,9.867607e-001,1.825000e+000,,,,,,,,,,,,,,,,,,0,5.000000e+000,1.000000e+000,4,4,4.709244e-003,0,,0,
1612961499.063,,1.000000e+002,1.301406e+001,7.544857e-004,1.120629e-007,4.795308e-002,1.669189e-005,3,9.868320e-001,1.825000e+000,,,,,,,,,,,,,,,,,,0,5.000000e+000,1.000000e+000,4,4,5.120277e-003,0,,0,
1612961651.818,,1.000000e+002,1.351988e+001,7.104687e-004,2.955027e-007,4.791095e-002,3.422865e-005,3,9.868528e-001,1.825000e+000,,,,,,,,,,,,,,,,,,0,5.000000e+000,1.000000e+000,4,4,1.379013e-002,0,,0,
1612961804.231,,1.000000e+002,1.402835e+001,6.737376e-004,4.035947e-007,4.797405e-002,7.848183e-005,3,9.869131e-001,1.825000e+000,,,,,,,,,,,,,,,,,,0,5.000000e+000,1.000000e+000,4,4,1.854038e-002,0,,0,
1612961955.239,,1.000000e+002,1.450380e+001,6.439164e-004,9.753070e-008,4.804630e-002,9.162765e-005,3,9.869782e-001,1.825000e+000,,,,,,,,,,,,,,,,,,0,5.000000e+000,1.000000e+000,4,4,9.009361e-003,0,,0,
1612962060.211,,1.000000e+002,1.500178e+001,6.163988e-004,1.450604e-007,4.805927e-002,1.354572e-005,3,9.870265e-001,1.825000e+000,,,,,,,,,,,,,,,,,,0,5.000000e+000,1.000000e+000,4,4,1.086044e-002,0,,0,
1612962218.006,,1.000000e+002,1.600245e+001,5.697305e-004,8.090561e-008,4.814641e-002,2.567974e-005,3,9.870754e-001,1.825000e+000,,,,,,,,,,,,,,,,,,0,5.000000e+000,1.000000e+000,4,4,8.929253e-003,0,,0,
1612962375.488,,1.000000e+002,1.700228e+001,5.310822e-004,7.106952e-008,4.818305e-002,3.096449e-005,3,9.871365e-001,1.825000e+000,,,,,,,,,,,,,,,,,,0,5.000000e+000,1.000000e+000,4,4,7.759094e-003,0,,0,
1612962539.912,,1.000000e+002,1.800342e+001,4.980272e-004,2.461698e-008,4.821912e-002,2.940226e-005,3,9.871776e-001,1.825000e+000,,,,,,,,,,,,,,,,,,0,5.000000e+000,1.000000e+000,4,4,2.609253e-003,0,,0,
1612962697.972,,1.000000e+002,1.900221e+001,4.693181e-004,8.656388e-008,4.827598e-002,2.332372e-005,3,9.872518e-001,1.825000e+000,,,,,,,,,,,,,,,,,,0,5.000000e+000,1.000000e+000,4,4,7.728577e-003,0,,0,
1612962853.941,,1.000000e+002,2.000169e+001,4.439018e-004,5.315887e-008,4.829434e-002,4.304308e-005,3,9.873619e-001,1.825000e+000,,,,,,,,,,,,,,,,,,0,5.000000e+000,1.000000e+000,4,4,5.340576e-003,0,,0,
1612963011.735,,1.000000e+002,2.100128e+001,4.213589e-004,3.439697e-008,4.839474e-002,3.959599e-005,3,9.873748e-001,1.825000e+000,,,,,,,,,,,,,,,,,,0,5.000000e+000,1.000000e+000,4,4,2.359390e-003,0,,0,
1612963167.626,,1.000000e+002,2.200141e+001,4.011667e-004,1.352113e-008,4.845550e-002,3.794195e-005,3,9.873902e-001,1.825000e+000,,,,,,,,,,,,,,,,,,0,5.000000e+000,1.000000e+000,4,4,1.930237e-003,0,,0,
1612963326.434,,1.000000e+002,2.300114e+001,3.828292e-004,2.640724e-008,4.857348e-002,1.196489e-005,3,9.874820e-001,1.825000e+000,,,,,,,,,,,,,,,,,,0,5.000000e+000,1.000000e+000,4,4,6.290436e-003,0,,0,
1612963483.698,,1.000000e+002,2.400189e+001,3.661722e-004,7.226975e-008,4.860882e-002,3.048698e-005,3,9.875101e-001,1.825000e+000,,,,,,,,,,,,,,,,,,0,5.000000e+000,1.000000e+000,4,4,1.136017e-002,0,,0,
1612963642.023,,1.000000e+002,2.500315e+001,3.509870e-004,9.567936e-008,4.867765e-002,3.346659e-005,3,9.875603e-001,1.825000e+000,,,,,,,,,,,,,,,,,,0,5.000000e+000,1.000000e+000,4,4,1.881027e-002,0,,0,
1612964973.064,,1.000000e+002,2.600208e+001,3.370812e-004,1.218700e-008,4.890290e-002,3.531467e-005,3,9.875759e-001,1.825000e+000,,,,,,,,,,,,,,,,,,0,5.000000e+000,1.000000e+000,4,4,2.641678e-003,0,,0,
1612965132.715,,1.000000e+002,2.801007e+001,3.123462e-004,3.450118e-008,4.899558e-002,3.950687e-005,3,9.877210e-001,1.825000e+000,,,,,,,,,,,,,,,,,,0,5.000000e+000,1.000000e+000,4,4,6.078720e-003,0,,0,
1612965301.335,,1.000000e+002,3.001091e+001,2.912313e-004,2.980181e-008,4.923352e-002,4.070325e-005,3,9.877869e-001,1.825000e+000,,,,,,,,,,,,,,,,,,0,5.000000e+000,1.000000e+000,4,4,8.081436e-003,0,,0,
1612965465.027,,1.000000e+002,3.201434e+001,2.729563e-004,1.843785e-008,4.949280e-002,2.474840e-005,3,9.879193e-001,1.825000e+000,,,,,,,,,,,,,,,,,,0,5.000000e+000,1.000000e+000,4,4,1.042175e-002,0,,0,
1612965628.702,,1.000000e+002,3.401744e+001,2.569199e-004,3.051474e-008,4.971816e-002,2.241719e-005,3,9.879248e-001,1.825000e+000,,,,,,,,,,,,,,,,,,0,5.000000e+000,1.000000e+000,4,4,1.169968e-002,0,,0,
1612965795.732,,1.000000e+002,3.602072e+001,2.428372e-004,2.174036e-008,4.999199e-002,5.079386e-005,3,9.880201e-001,1.825000e+000,,,,,,,,,,,,,,,,,,0,5.000000e+000,1.000000e+000,4,4,1.630020e-002,0,,0,
1612965963.619,,1.000000e+002,3.802447e+001,2.303193e-004,3.175815e-008,5.025250e-002,3.890564e-005,3,9.880735e-001,1.825000e+000,,,,,,,,,,,,,,,,,,0,5.000000e+000,1.000000e+000,4,4,1.447296e-002,0,,0,
1612966133.613,,1.000000e+002,4.002863e+001,2.191341e-004,3.524316e-008,5.058914e-002,1.680842e-005,3,9.881347e-001,1.825000e+000,,,,,,,,,,,,,,,,,,0,5.000000e+000,1.000000e+000,4,4,1.393890e-002,0,,0,
1612966306.523,,1.000000e+002,4.202962e+001,2.089941e-004,3.631435e-008,5.096699e-002,3.036344e-005,3,9.881987e-001,1.825000e+000,,,,,,,,,,,,,,,,,,0,5.000000e+000,1.000000e+000,4,4,1.963043e-002,0,,0,
1612966478.857,,1.000000e+002,4.403533e+001,1.997880e-004,3.190473e-008,5.141750e-002,2.553506e-005,3,9.882340e-001,1.825000e+000,,,,,,,,,,,,,,,,,,0,5.000000e+000,1.000000e+000,4,4,2.385330e-002,0,,0,
1612966652.079,,1.000000e+002,4.603835e+001,1.914049e-004,3.926845e-008,5.170793e-002,6.882381e-005,3,9.882885e-001,1.825000e+000,,,,,,,,,,,,,,,,,,0,5.000000e+000,1.000000e+000,4,4,2.286148e-002,0,,0,
1612966823.399,,1.000000e+002,4.804471e+001,1.837745e-004,3.532171e-008,5.217959e-002,4.010230e-005,3,9.883751e-001,1.825000e+000,,,,,,,,,,,,,,,,,,0,5.000000e+000,1.000000e+000,4,4,2.258301e-002,0,,0,
1612967004.000,,1.000000e+002,5.004052e+001,1.767801e-004,2.617320e-008,5.253749e-002,7.947697e-005,3,9.884570e-001,1.825000e+000,,,,,,,,,,,,,,,,,,0,5.000000e+000,1.000000e+000,4,4,2.797699e-002,0,,0,
1612967198.923,,1.000000e+002,5.504990e+001,1.612800e-004,2.837102e-008,5.326313e-002,5.842045e-005,3,9.886292e-001,1.825000e+000,,,,,,,,,,,,,,,,,,0,5.000000e+000,1.000000e+000,4,4,3.050995e-002,0,,0,
1612967400.694,,1.000000e+002,6.007685e+001,1.483504e-004,2.216333e-008,5.398037e-002,3.015352e-005,3,9.886088e-001,1.825000e+000,,,,,,,,,,,,,,,,,,0,5.000000e+000,1.000000e+000,4,4,4.132080e-002,0,,0,
1612967605.647,,1.000000e+002,6.508918e+001,1.374895e-004,2.112041e-008,5.510580e-002,5.819076e-005,3,9.888170e-001,1.825000e+000,,,,,,,,,,,,,,,,,,0,5.000000e+000,1.000000e+000,4,4,4.002380e-002,0,,0,
1612967813.299,,1.000000e+002,7.010067e+001,1.280911e-004,3.350594e-008,5.626063e-002,7.953293e-005,3,9.889221e-001,1.825000e+000,,,,,,,,,,,,,,,,,,0,5.000000e+000,1.000000e+000,4,4,5.064392e-002,0,,0,
1612968023.072,,1.000000e+002,7.511405e+001,1.199524e-004,2.805156e-008,5.751039e-002,5.301568e-005,3,9.890286e-001,1.825000e+000,,,,,,,,,,,,,,,,,,0,5.000000e+000,1.000000e+000,4,4,7.106018e-002,0,,0,
1612968232.581,,1.000000e+002,8.012637e+001,1.128484e-004,4.155340e-008,5.881883e-002,6.910914e-005,3,9.891871e-001,1.825000e+000,,,,,,,,,,,,,,,,,,0,5.000000e+000,1.000000e+000,4,4,7.735443e-002,0,,0,
1612968443.899,,1.000000e+002,8.514222e+001,1.065258e-004,2.650644e-008,6.013790e-002,7.346828e-005,3,9.893254e-001,1.825000e+000,,,,,,,,,,,,,,,,,,0,5.000000e+000,1.000000e+000,4,4,7.987976e-002,0,,0,
1612968656.543,,1.000000e+002,9.015796e+001,1.008541e-004,2.854986e-008,6.147944e-002,9.004013e-005,3,9.893644e-001,1.825000e+000,,,,,,,,,,,,,,,,,,0,5.000000e+000,1.000000e+000,4,4,8.896637e-002,0,,0,
1612968869.717,,1.000000e+002,9.517126e+001,9.578137e-005,2.853842e-008,6.291910e-002,1.407697e-004,3,9.893910e-001,1.825000e+000,,,,,,,,,,,,,,,,,,0,5.000000e+000,1.000000e+000,4,4,9.456635e-002,0,,0,
1612969081.706,,1.000000e+002,1.001699e+002,9.121544e-005,3.176166e-008,6.424396e-002,6.322506e-005,3,9.895678e-001,1.825000e+000,,,,,,,,,,,,,,,,,,0,5.000000e+000,1.000000e+000,4,4,9.070587e-002,0,,0,
1612969345.034,,1.000000e+002,1.102127e+002,8.321607e-005,3.583119e-008,6.711648e-002,3.597821e-005,3,9.896163e-001,1.825000e+000,,,,,,,,,,,,,,,,,,0,5.000000e+000,1.000000e+000,4,4,1.353989e-001,0,,0,
1612969607.333,,1.000000e+002,1.202403e+002,7.637010e-005,3.034011e-008,7.019784e-002,5.588596e-005,3,9.897102e-001,1.825000e+000,,,,,,,,,,,,,,,,,,0,5.000000e+000,1.000000e+000,4,4,1.436005e-001,0,,0,
1612969865.077,,1.000000e+002,1.302663e+002,7.063085e-005,2.500612e-008,7.351451e-002,1.370241e-004,3,9.896937e-001,1.825000e+000,,,,,,,,,,,,,,,,,,0,5.000000e+000,1.000000e+000,4,4,1.596985e-001,0,,0,
1612970120.153,,1.000000e+002,1.402907e+002,6.565776e-005,3.802811e-008,7.683102e-002,6.064447e-005,3,9.896679e-001,1.825000e+000,,,,,,,,,,,,,,,,,,0,5.000000e+000,1.000000e+000,4,4,1.840057e-001,0,,0,
1612970371.859,,1.000000e+002,1.503183e+002,6.132167e-005,2.652032e-008,8.053589e-002,6.085895e-005,3,9.896350e-001,1.825000e+000,,,,,,,,,,,,,,,,,,0,5.000000e+000,1.000000e+000,4,4,2.052002e-001,0,,0,
1612970638.417,,1.000000e+002,1.602467e+002,5.756020e-005,4.350785e-008,8.400056e-002,7.557838e-005,3,9.894716e-001,1.825000e+000,,,,,,,,,,,,,,,,,,0,5.000000e+000,1.000000e+000,4,4,1.932983e-001,0,,0,
1612970886.364,,1.000000e+002,1.703508e+002,5.414431e-005,3.087386e-008,8.797973e-002,1.664521e-004,3,9.892812e-001,1.825000e+000,,,,,,,,,,,,,,,,,,0,5.000000e+000,1.000000e+000,4,4,2.427979e-001,0,,0,
1612971132.158,,1.000000e+002,1.803753e+002,5.113010e-005,3.158939e-008,9.184574e-002,1.043748e-004,3,9.891204e-001,1.825000e+000,,,,,,,,,,,,,,,,,,0,5.000000e+000,1.000000e+000,4,4,2.438049e-001,0,,0,
1612971376.376,,1.000000e+002,1.903949e+002,4.843698e-005,2.833091e-008,9.623250e-002,3.626346e-005,3,9.889016e-001,1.825000e+000,,,,,,,,,,,,,,,,,,0,5.000000e+000,1.000000e+000,4,4,2.714081e-001,0,,0,
1612971618.723,,1.000000e+002,2.003990e+002,4.600385e-005,2.906119e-008,1.004580e-001,1.306801e-004,3,9.883416e-001,1.825000e+000,,,,,,,,,,,,,,,,,,0,5.000000e+000,1.000000e+000,4,4,2.662048e-001,0,,0,
1612971859.353,,1.000000e+002,2.104186e+002,4.379404e-005,2.689896e-008,1.051500e-001,6.562581e-005,3,9.880446e-001,1.825000e+000,,,,,,,,,,,,,,,,,,0,5.000000e+000,1.000000e+000,4,4,3.126984e-001,0,,0,
1612972098.517,,1.000000e+002,2.204328e+002,4.177509e-005,2.521829e-008,1.098361e-001,1.428320e-004,3,9.877254e-001,1.825000e+000,,,,,,,,,,,,,,,,,,0,5.000000e+000,1.000000e+000,4,4,3.227997e-001,0,,0,
1612972336.885,,1.000000e+002,2.304390e+002,3.993399e-005,1.947562e-008,1.146995e-001,2.022749e-004,3,9.872927e-001,1.825000e+000,,,,,,,,,,,,,,,,,,0,5.000000e+000,1.000000e+000,4,4,3.189087e-001,0,,0,
1612972574.817,,1.000000e+002,2.404589e+002,3.823607e-005,2.814112e-008,1.199242e-001,2.511327e-004,3,9.866301e-001,1.825000e+000,,,,,,,,,,,,,,,,,,0,5.000000e+000,1.000000e+000,4,4,3.540955e-001,0,,0,
1612972810.596,,1.000000e+002,2.504724e+002,3.667086e-005,1.942519e-008,1.256149e-001,1.508209e-004,3,9.859295e-001,1.825000e+000,,,,,,,,,,,,,,,,,,0,5.000000e+000,1.000000e+000,4,4,3.713074e-001,0,,0,
1612973047.373,,1.000000e+002,2.604756e+002,3.520884e-005,3.286499e-008,1.315115e-001,2.177284e-004,3,9.855631e-001,1.825000e+000,,,,,,,,,,,,,,,,,,0,5.000000e+000,1.000000e+000,4,4,3.802185e-001,0,,0,
1612973284.244,,1.000000e+002,2.704720e+002,3.384841e-005,1.755732e-008,1.383989e-001,1.958165e-004,3,9.849481e-001,1.825000e+000,,,,,,,,,,,,,,,,,,0,5.000000e+000,1.000000e+000,4,4,3.963928e-001,0,,0,
1612973521.583,,1.000000e+002,2.804976e+002,3.262739e-005,2.349950e-008,1.444145e-001,2.981618e-004,3,9.844528e-001,1.825000e+000,,,,,,,,,,,,,,,,,,0,5.000000e+000,1.000000e+000,4,4,3.945923e-001,0,,0,
1612973758.937,,1.000000e+002,2.904820e+002,3.145534e-005,2.342344e-008,1.543766e-001,2.910732e-004,3,9.841542e-001,1.825000e+000,,,,,,,,,,,,,,,,,,0,5.000000e+000,1.000000e+000,4,4,4.067993e-001,0,,0,
1612973996.869,,1.000000e+002,3.004788e+002,3.035035e-005,1.235040e-008,1.671291e-001,4.857026e-004,3,9.833931e-001,1.825000e+000,,,,,,,,,,,,,,,,,,0,5.000000e+000,1.000000e+000,4,4,3.977966e-001,0,,0,